Workbook
Name Linking_1: #REF!
Name Linking_10: #REF!
Name Linking_11: #REF!
Name Linking_12: #REF!
Name Linking_13: 'Financial Summary'!$E$11:$W$63
Name Linking_14: #REF!
Name Linking_15: Assumptions!$N$515:$T$522
Name Linking_2: #REF!
Name Linking_3: 'Valuation - DCF'!$B$5:$AA$55
Name Linking_4: 'Financial Summary'!$E$11:$V$69
Name Linking_5: 'Financial Summary'!$E$11:$V$63
Name Linking_6: #REF!
Name Linking_7: #REF!
Name Linking_8: 'Financial Summary'!$E$11:$V$64
Name Linking_9: #REF!
Name ValidDateTable: #REF!

Sheet CircularReferenceAlert
B2: This workbook contains formulas which intentionally use circular reference calculation. These calculations can be resolved as intended by the originating analyst by applying the following settings in the File >> Options >> Formulas:
B5: 1) Select the Enable iterative calculation check box
B6: 2) Set Maximum Iterations = 100
B7: 3) Set Maximum Change = 0.001
B9: Failure to apply these settings can result in incorrect calculation or unexpected termination of your Microsoft Excel session.

Sheet ImportantDisclosures
A2: 1 Austin Road West
A3: Kowloon
A4: Hong Kong
A5: Tel: +852 2848 5200
A7: Authors: Melinda Baxter
A8: Date: 02 Feb 2026
A10: Ticker: GYG.AX
A11: Stock Rating: Overweight
A12: Industry: Australia Consumer
A13: Industry View: In-Line
A14: Price as of 02 Feb 2026: 22.18
A15: Target Price: 31.20
... A134: Equal-weight and Not-Rated to hold and Underweight to sell recommendations, respectively.
B136: Coverage Universe | D136: Investment Banking Clients (IBC) | G136: Other Material Investment Services Clients (MISC)
A137: Stock Rating Category | B137: Count | C137: % of Total | D137: Count | E137: % of Total IBC | F137: % of Rating Category | G137: Count | H137: % of Total Other MISC
A138: Overweight/Buy | B138: 1520 | C138: 0.41 | D138: 425 | E138: 0.48 | F138: 0.28 | G138: 685 | H138: 0.42
A139: Equal-weight/Hold | B139: 1579 | C139: 0.43 | D139: 375 | E139: 0.42 | F139: 0.24 | G139: 713 | H139: 0.44
A140: Not-Rated/Hold | B140: 4 | C140: 0 | D140: 1 | E140: 0 | F140: 0.25 | G140: 1 | H140: 0
A141: Underweight/Sell | B141: 592 | C141: 0.16 | D141: 89 | E141: 0.1 | F141: 0.15 | G141: 232 | H141: 0.14
A142: Total | B142: 3695 | D142: 890 | G142: 1631
A144: Data include common stock and ADRs currently assigned ratings. Investment Banking Clients are companies
A145: from whom Morgan Stanley received investment banking compensation in the last 12 months. Due to rounding
A146: off of decimals, the percentages provided in the "% of total" column may not add up to exactly 100
A147: percent.
A149: Analyst Stock Ratings
A151: Overweight (O). The stock's total return is expected to exceed the average total return of the analyst's
A152: industry (or industry team's) coverage universe, on a risk-adjusted basis, over the next 12-18 months.
A154: Equal-weight (E). The stock's total return is expected to be in line with the average total return of
A155: the analyst's industry (or industry team's) coverage universe, on a risk-adjusted basis, over the next
A156: 12-18 months.
A158: Not-Rated (NR). Currently the analyst does not have adequate conviction about the stock's total return
A159: relative to the average total return of the analyst's industry (or industry team's) coverage universe,
... A436: © Copyright 2026 Morgan Stanley

Sheet MENU
B3: Morgan Stanley
B5: Guzman y Gomez
A6: GYG-AU | B6: GYG.AX
B15: Contents
B16: Financial Summary
B17: Assumptions
B18: Financial Statements
B19: Valuation
B21: Last close | C21: =TODAY() -> 46055 | E21: 23.7
B23: Morgan Stanley Australian Consumer Team
B24: Melinda Baxter | D24: +612-9770 1176
B25: Mac Ross | D25: +612-9770 1579
B26: Julia de Sterke | D26: +612-9770 1658
B28: AUSTRALIAN CONSUMER RESEARCH
B29: Morgan Stanley Australia Ltd
B30: Level 39, Chifley Tower, 2 Chifley Square
B31: Sydney 2000 Australia

Sheet Financial Summary
E2: Guzman Y Gomez (GYG.AX)
E3: Financial Summary
E5: Year ended 30 June
A7: GYG-AU | E7: Share Price | F7: 23.5
E8: Mkt Cap | F8: =+F7*F9 -> 2381.7935
E9: SOI | F9: =+'Financial Statements'!L63 -> 101.35291
E11: Income Statement | O11: Balance Sheet
E12: Year ended 30 June | F12: Unit | G12: FY22 | H12: FY23 | I12: FY24 | J12: FY25 | K12: FY26e | L12: FY27e | M12: FY28e | O12: Year ended 30 June | P12: Unit | Q12: FY22 | R12: FY23 | S12: FY24 | T12: FY25 | U12: FY26e | V12: FY27e | W12: FY28e
E13: Revenue
A14: Revenue_Aust | E14: Australia | F14: A$m | G14: =VLOOKUP($A14,Assumptions!$1:$1048576,MATCH('Financial Summary'!G$12,Assumptions!$5:$5,0),FALSE) -> 168.027 | H14: =VLOOKUP($A14,Assumptions!$1:$1048576,MATCH('Financial Summary'!H$12,Assumptions!$5:$5,0),FALSE) -> 251.3815 | I14: =VLOOKUP($A14,Assumptions!$1:$1048576,MATCH('Financial Summary'!I$12,Assumptions!$5:$5,0),FALSE) -> 329.542 | J14: =VLOOKUP($A14,Assumptions!$1:$1048576,MATCH('Financial Summary'!J$12,Assumptions!$5:$5,0),FALSE) -> 424.5535 | K14: =VLOOKUP($A14,Assumptions!$1:$1048576,MATCH('Financial Summary'!K$12,Assumptions!$5:$5,0),FALSE) -> 550.06085 | L14: =VLOOKUP($A14,Assumptions!$1:$1048576,MATCH('Financial Summary'!L$12,Assumptions!$5:$5,0),FALSE) -> 665.2735 | M14: =VLOOKUP($A14,Assumptions!$1:$1048576,MATCH('Financial Summary'!M$12,Assumptions!$5:$5,0),FALSE) -> 804.50707 | O14: Cash & Cash Equivalents | P14: A$m | Q14: 0 | S14: =VLOOKUP($Y14,'Financial Statements'!$1:$1048576,MATCH('Financial Summary'!S$12,'Financial Statements'!$5:$5,0),FALSE) -> 294.48 | T14: =VLOOKUP($Y14,'Financial Statements'!$1:$1048576,MATCH('Financial Summary'!T$12,'Financial Statements'!$5:$5,0),FALSE) -> 281.743 | U14: =VLOOKUP($Y14,'Financial Statements'!$1:$1048576,MATCH('Financial Summary'!U$12,'Financial Statements'!$5:$5,0),FALSE) -> 269.57803 | V14: =VLOOKUP($Y14,'Financial Statements'!$1:$1048576,MATCH('Financial Summary'!V$12,'Financial Statements'!$5:$5,0),FALSE) -> 242.88346 | W14: =VLOOKUP($Y14,'Financial Statements'!$1:$1048576,MATCH('Financial Summary'!W$12,'Financial Statements'!$5:$5,0),FALSE) -> 233.92671 | Y14: CA_cash
A15: Revenue_SG | B15: Revenue_JP | C15: Revenue_US | E15: International | F15: A$m | G15: =VLOOKUP($A15,Assumptions!$1:$1048576,MATCH('Financial Summary'!G$12,Assumptions!$5:$5,0),FALSE)+VLOOKUP($B15,Assumptions!$1:$1048576,MATCH('Financial Summary'!G$12,Assumptions!$5:$5,0),FALSE)+VLOOKUP($C15,Assumptions!$1:$1048576,MATCH('Financial Summary'!G$12,Assumptions!$5:$5,0),FALSE) -> 3.773 | H15: =VLOOKUP($A15,Assumptions!$1:$1048576,MATCH('Financial Summary'!H$12,Assumptions!$5:$5,0),FALSE)+VLOOKUP($B15,Assumptions!$1:$1048576,MATCH('Financial Summary'!H$12,Assumptions!$5:$5,0),FALSE)+VLOOKUP($C15,Assumptions!$1:$1048576,MATCH('Financial Summary'!H$12,Assumptions!$5:$5,0),FALSE) -> 7.7185 | I15: =VLOOKUP($A15,Assumptions!$1:$1048576,MATCH('Financial Summary'!I$12,Assumptions!$5:$5,0),FALSE)+VLOOKUP($B15,Assumptions!$1:$1048576,MATCH('Financial Summary'!I$12,Assumptions!$5:$5,0),FALSE)+VLOOKUP($C15,Assumptions!$1:$1048576,MATCH('Financial Summary'!I$12,Assumptions!$5:$5,0),FALSE) -> 12.661 | J15: =VLOOKUP($A15,Assumptions!$1:$1048576,MATCH('Financial Summary'!J$12,Assumptions!$5:$5,0),FALSE)+VLOOKUP($B15,Assumptions!$1:$1048576,MATCH('Financial Summary'!J$12,Assumptions!$5:$5,0),FALSE)+VLOOKUP($C15,Assumptions!$1:$1048576,MATCH('Financial Summary'!J$12,Assumptions!$5:$5,0),FALSE) -> 11.7375 | K15: =VLOOKUP($A15,Assumptions!$1:$1048576,MATCH('Financial Summary'!K$12,Assumptions!$5:$5,0),FALSE)+VLOOKUP($B15,Assumptions!$1:$1048576,MATCH('Financial Summary'!K$12,Assumptions!$5:$5,0),FALSE)+VLOOKUP($C15,Assumptions!$1:$1048576,MATCH('Financial Summary'!K$12,Assumptions!$5:$5,0),FALSE) -> 15.667793 | L15: =VLOOKUP($A15,Assumptions!$1:$1048576,MATCH('Financial Summary'!L$12,Assumptions!$5:$5,0),FALSE)+VLOOKUP($B15,Assumptions!$1:$1048576,MATCH('Financial Summary'!L$12,Assumptions!$5:$5,0),FALSE)+VLOOKUP($C15,Assumptions!$1:$1048576,MATCH('Financial Summary'!L$12,Assumptions!$5:$5,0),FALSE) -> 21.68206 | M15: =VLOOKUP($A15,Assumptions!$1:$1048576,MATCH('Financial Summary'!M$12,Assumptions!$5:$5,0),FALSE)+VLOOKUP($B15,Assumptions!$1:$1048576,MATCH('Financial Summary'!M$12,Assumptions!$5:$5,0),FALSE)+VLOOKUP($C15,Assumptions!$1:$1048576,MATCH('Financial Summary'!M$12,Assumptions!$5:$5,0),FALSE) -> 29.174034 | O15: Current Receivables | P15: A$m | Q15: 0 | S15: =VLOOKUP($Y15,'Financial Statements'!$1:$1048576,MATCH('Financial Summary'!S$12,'Financial Statements'!$5:$5,0),FALSE) -> 26.02 | T15: =VLOOKUP($Y15,'Financial Statements'!$1:$1048576,MATCH('Financial Summary'!T$12,'Financial Statements'!$5:$5,0),FALSE) -> 24.703 | U15: =VLOOKUP($Y15,'Financial Statements'!$1:$1048576,MATCH('Financial Summary'!U$12,'Financial Statements'!$5:$5,0),FALSE) -> 32.031819 | V15: =VLOOKUP($Y15,'Financial Statements'!$1:$1048576,MATCH('Financial Summary'!V$12,'Financial Statements'!$5:$5,0),FALSE) -> 38.895744 | W15: =VLOOKUP($Y15,'Financial Statements'!$1:$1048576,MATCH('Financial Summary'!W$12,'Financial Statements'!$5:$5,0),FALSE) -> 47.203413 | Y15: CA_receivables
A16: Rev_other | E16: Other | F16: A$m | G16: =VLOOKUP($A16,Assumptions!$1:$1048576,MATCH('Financial Summary'!G$12,Assumptions!$5:$5,0),FALSE) -> 13.3 | H16: =VLOOKUP($A16,Assumptions!$1:$1048576,MATCH('Financial Summary'!H$12,Assumptions!$5:$5,0),FALSE) -> 17.7 | I16: =VLOOKUP($A16,Assumptions!$1:$1048576,MATCH('Financial Summary'!I$12,Assumptions!$5:$5,0),FALSE) -> 22.774 | J16: =VLOOKUP($A16,Assumptions!$1:$1048576,MATCH('Financial Summary'!J$12,Assumptions!$5:$5,0),FALSE) -> 32.024 | K16: =VLOOKUP($A16,Assumptions!$1:$1048576,MATCH('Financial Summary'!K$12,Assumptions!$5:$5,0),FALSE) -> 31.927277 | L16: =VLOOKUP($A16,Assumptions!$1:$1048576,MATCH('Financial Summary'!L$12,Assumptions!$5:$5,0),FALSE) -> 38.105297 | M16: =VLOOKUP($A16,Assumptions!$1:$1048576,MATCH('Financial Summary'!M$12,Assumptions!$5:$5,0),FALSE) -> 45.404292 | O16: Property, Plant, & Equipment | P16: A$m | Q16: 0 | S16: =VLOOKUP($Y16,'Financial Statements'!$1:$1048576,MATCH('Financial Summary'!S$12,'Financial Statements'!$5:$5,0),FALSE) -> 87.63 | T16: =VLOOKUP($Y16,'Financial Statements'!$1:$1048576,MATCH('Financial Summary'!T$12,'Financial Statements'!$5:$5,0),FALSE) -> 130.056 | U16: =VLOOKUP($Y16,'Financial Statements'!$1:$1048576,MATCH('Financial Summary'!U$12,'Financial Statements'!$5:$5,0),FALSE) -> 160.12529 | V16: =VLOOKUP($Y16,'Financial Statements'!$1:$1048576,MATCH('Financial Summary'!V$12,'Financial Statements'!$5:$5,0),FALSE) -> 203.13492 | W16: =VLOOKUP($Y16,'Financial Statements'!$1:$1048576,MATCH('Financial Summary'!W$12,'Financial Statements'!$5:$5,0),FALSE) -> 233.9555 | Y16: PPE
E17: Total Revenue | F17: A$m | G17: =SUM(G14:G16) -> 185.1 | H17: =SUM(H14:H16) -> 276.8 | I17: =SUM(I14:I16) -> 364.977 | J17: =SUM(J14:J16) -> 468.315 | K17: =SUM(K14:K16) -> 597.65592 | L17: =SUM(L14:L16) -> 725.06085 | M17: =SUM(M14:M16) -> 879.08539 | O17: Intangibles | P17: A$m | Q17: 0 | S17: =VLOOKUP($Y17,'Financial Statements'!$1:$1048576,MATCH('Financial Summary'!S$12,'Financial Statements'!$5:$5,0),FALSE) -> 10.586 | T17: =VLOOKUP($Y17,'Financial Statements'!$1:$1048576,MATCH('Financial Summary'!T$12,'Financial Statements'!$5:$5,0),FALSE) -> 18.305 | U17: =VLOOKUP($Y17,'Financial Statements'!$1:$1048576,MATCH('Financial Summary'!U$12,'Financial Statements'!$5:$5,0),FALSE) -> 16.571153 | V17: =VLOOKUP($Y17,'Financial Statements'!$1:$1048576,MATCH('Financial Summary'!V$12,'Financial Statements'!$5:$5,0),FALSE) -> 18.657356 | W17: =VLOOKUP($Y17,'Financial Statements'!$1:$1048576,MATCH('Financial Summary'!W$12,'Financial Statements'!$5:$5,0),FALSE) -> 21.950918 | Y17: Intangibles_BS
E18: % change | F18: % | H18: =H17/G17-1 -> 0.49540789 | I18: =I17/H17-1 -> 0.31855853 | J18: =J17/I17-1 -> 0.28313565 | K18: =K17/J17-1 -> 0.27618359 | L18: =L17/K17-1 -> 0.21317439 | M18: =M17/L17-1 -> 0.21242981 | O18: Other Assets | P18: A$m | Q18: 0 | S18: =S19-S14-S15-S16-S17 -> 243.081 | T18: =T19-T14-T15-T16-T17 -> 328.391 | U18: =U19-U14-U15-U16-U17 -> 367.16967 | V18: =V19-V14-V15-V16-V17 -> 424.43339 | W18: =W19-W14-W15-W16-W17 -> 480.2017
E19: 3yr CAGR | M19: =+(M17/J17)^(0.333333333333333)-1 -> 0.23357151 | O19: Total Assets | P19: A$m | Q19: 0 | S19: =VLOOKUP($Y19,'Financial Statements'!$1:$1048576,MATCH('Financial Summary'!S$12,'Financial Statements'!$5:$5,0),FALSE) -> 661.797 | T19: =VLOOKUP($Y19,'Financial Statements'!$1:$1048576,MATCH('Financial Summary'!T$12,'Financial Statements'!$5:$5,0),FALSE) -> 783.198 | U19: =VLOOKUP($Y19,'Financial Statements'!$1:$1048576,MATCH('Financial Summary'!U$12,'Financial Statements'!$5:$5,0),FALSE) -> 845.47597 | V19: =VLOOKUP($Y19,'Financial Statements'!$1:$1048576,MATCH('Financial Summary'!V$12,'Financial Statements'!$5:$5,0),FALSE) -> 928.00487 | W19: =VLOOKUP($Y19,'Financial Statements'!$1:$1048576,MATCH('Financial Summary'!W$12,'Financial Statements'!$5:$5,0),FALSE) -> 1017.2382 | Y19: Total_assets
A21: Group_Corp_restaurant_margin | E21: Corp restaurant margin | F21: A$m | G21: =VLOOKUP($A21,Assumptions!$1:$1048576,MATCH('Financial Summary'!G$12,Assumptions!$5:$5,0),FALSE) -> 19.2322 | H21: =VLOOKUP($A21,Assumptions!$1:$1048576,MATCH('Financial Summary'!H$12,Assumptions!$5:$5,0),FALSE) -> 29.76 | I21: =VLOOKUP($A21,Assumptions!$1:$1048576,MATCH('Financial Summary'!I$12,Assumptions!$5:$5,0),FALSE) -> 47.535 | J21: =VLOOKUP($A21,Assumptions!$1:$1048576,MATCH('Financial Summary'!J$12,Assumptions!$5:$5,0),FALSE) -> 59.2688 | K21: =VLOOKUP($A21,Assumptions!$1:$1048576,MATCH('Financial Summary'!K$12,Assumptions!$5:$5,0),FALSE) -> 81.905084 | L21: =VLOOKUP($A21,Assumptions!$1:$1048576,MATCH('Financial Summary'!L$12,Assumptions!$5:$5,0),FALSE) -> 107.60918 | M21: =VLOOKUP($A21,Assumptions!$1:$1048576,MATCH('Financial Summary'!M$12,Assumptions!$5:$5,0),FALSE) -> 136.27816 | O21: Current Payables | P21: A$m | Q21: 0 | S21: =VLOOKUP($Y21,'Financial Statements'!$1:$1048576,MATCH('Financial Summary'!S$12,'Financial Statements'!$5:$5,0),FALSE) -> 39.387 | T21: =VLOOKUP($Y21,'Financial Statements'!$1:$1048576,MATCH('Financial Summary'!T$12,'Financial Statements'!$5:$5,0),FALSE) -> 40.439 | U21: =VLOOKUP($Y21,'Financial Statements'!$1:$1048576,MATCH('Financial Summary'!U$12,'Financial Statements'!$5:$5,0),FALSE) -> 55.997827 | V21: =VLOOKUP($Y21,'Financial Statements'!$1:$1048576,MATCH('Financial Summary'!V$12,'Financial Statements'!$5:$5,0),FALSE) -> 68.097657 | W21: =VLOOKUP($Y21,'Financial Statements'!$1:$1048576,MATCH('Financial Summary'!W$12,'Financial Statements'!$5:$5,0),FALSE) -> 82.720269 | Y21: CL_payables
A22: Group_Franchise_rev | E22: Franchise revenue | F22: A$m | G22: =VLOOKUP($A22,Assumptions!$1:$1048576,MATCH('Financial Summary'!G$12,Assumptions!$5:$5,0),FALSE) -> 33.4 | H22: =VLOOKUP($A22,Assumptions!$1:$1048576,MATCH('Financial Summary'!H$12,Assumptions!$5:$5,0),FALSE) -> 46.8 | I22: =VLOOKUP($A22,Assumptions!$1:$1048576,MATCH('Financial Summary'!I$12,Assumptions!$5:$5,0),FALSE) -> 60.7 | J22: =VLOOKUP($A22,Assumptions!$1:$1048576,MATCH('Financial Summary'!J$12,Assumptions!$5:$5,0),FALSE) -> 78.924 | K22: =VLOOKUP($A22,Assumptions!$1:$1048576,MATCH('Financial Summary'!K$12,Assumptions!$5:$5,0),FALSE) -> 84.714638 | L22: =VLOOKUP($A22,Assumptions!$1:$1048576,MATCH('Financial Summary'!L$12,Assumptions!$5:$5,0),FALSE) -> 103.16223 | M22: =VLOOKUP($A22,Assumptions!$1:$1048576,MATCH('Financial Summary'!M$12,Assumptions!$5:$5,0),FALSE) -> 125.59537 | O22: Total Debt | P22: A$m | Q22: 0 | S22: =VLOOKUP($Y22,'Financial Statements'!$1:$1048576,MATCH('Financial Summary'!S$12,'Financial Statements'!$5:$5,0),FALSE) -> 0 | T22: =VLOOKUP($Y22,'Financial Statements'!$1:$1048576,MATCH('Financial Summary'!T$12,'Financial Statements'!$5:$5,0),FALSE) -> 0 | U22: =VLOOKUP($Y22,'Financial Statements'!$1:$1048576,MATCH('Financial Summary'!U$12,'Financial Statements'!$5:$5,0),FALSE) -> 0 | V22: =VLOOKUP($Y22,'Financial Statements'!$1:$1048576,MATCH('Financial Summary'!V$12,'Financial Statements'!$5:$5,0),FALSE) -> 0 | W22: =VLOOKUP($Y22,'Financial Statements'!$1:$1048576,MATCH('Financial Summary'!W$12,'Financial Statements'!$5:$5,0),FALSE) -> 0 | Y22: LT_borrowings
A23: Total_G&A_expense | E23: G&A expense | F23: A$m | G23: =VLOOKUP($A23,Assumptions!$1:$1048576,MATCH('Financial Summary'!G$12,Assumptions!$5:$5,0),FALSE) -> -37.2 | H23: =VLOOKUP($A23,Assumptions!$1:$1048576,MATCH('Financial Summary'!H$12,Assumptions!$5:$5,0),FALSE) -> -50.1 | I23: =VLOOKUP($A23,Assumptions!$1:$1048576,MATCH('Financial Summary'!I$12,Assumptions!$5:$5,0),FALSE) -> -69.2 | J23: =VLOOKUP($A23,Assumptions!$1:$1048576,MATCH('Financial Summary'!J$12,Assumptions!$5:$5,0),FALSE) -> -85.4 | K23: =VLOOKUP($A23,Assumptions!$1:$1048576,MATCH('Financial Summary'!K$12,Assumptions!$5:$5,0),FALSE) -> -95.042689 | L23: =VLOOKUP($A23,Assumptions!$1:$1048576,MATCH('Financial Summary'!L$12,Assumptions!$5:$5,0),FALSE) -> -104.3884 | M23: =VLOOKUP($A23,Assumptions!$1:$1048576,MATCH('Financial Summary'!M$12,Assumptions!$5:$5,0),FALSE) -> -114.7038 | O23: Other Liabilities | P23: A$m | Q23: 0 | S23: =+S24-S21-S22 -> 268.431 | T23: =+T24-T21-T22 -> 362.635 | U23: =+U24-U21-U22 -> 394.29721 | V23: =+V24-V21-V22 -> 443.82335 | W23: =+W24-W21-W22 -> 491.08215
A24: Segment_underlying_EBITDA | E24: EBITDA Segment Underlying | F24: A$m | G24: =VLOOKUP($A24,Assumptions!$1:$1048576,MATCH('Financial Summary'!G$12,Assumptions!$5:$5,0),FALSE) -> 15.4322 | H24: =VLOOKUP($A24,Assumptions!$1:$1048576,MATCH('Financial Summary'!H$12,Assumptions!$5:$5,0),FALSE) -> 26.46 | I24: =VLOOKUP($A24,Assumptions!$1:$1048576,MATCH('Financial Summary'!I$12,Assumptions!$5:$5,0),FALSE) -> 39.035 | J24: =VLOOKUP($A24,Assumptions!$1:$1048576,MATCH('Financial Summary'!J$12,Assumptions!$5:$5,0),FALSE) -> 52.7928 | K24: =VLOOKUP($A24,Assumptions!$1:$1048576,MATCH('Financial Summary'!K$12,Assumptions!$5:$5,0),FALSE) -> 71.577033 | L24: =VLOOKUP($A24,Assumptions!$1:$1048576,MATCH('Financial Summary'!L$12,Assumptions!$5:$5,0),FALSE) -> 106.38302 | M24: =VLOOKUP($A24,Assumptions!$1:$1048576,MATCH('Financial Summary'!M$12,Assumptions!$5:$5,0),FALSE) -> 147.16973 | O24: Total Liabilities | P24: A$m | Q24: 0 | S24: =VLOOKUP($Y24,'Financial Statements'!$1:$1048576,MATCH('Financial Summary'!S$12,'Financial Statements'!$5:$5,0),FALSE) -> 307.818 | T24: =VLOOKUP($Y24,'Financial Statements'!$1:$1048576,MATCH('Financial Summary'!T$12,'Financial Statements'!$5:$5,0),FALSE) -> 403.074 | U24: =VLOOKUP($Y24,'Financial Statements'!$1:$1048576,MATCH('Financial Summary'!U$12,'Financial Statements'!$5:$5,0),FALSE) -> 450.29504 | V24: =VLOOKUP($Y24,'Financial Statements'!$1:$1048576,MATCH('Financial Summary'!V$12,'Financial Statements'!$5:$5,0),FALSE) -> 511.92101 | W24: =VLOOKUP($Y24,'Financial Statements'!$1:$1048576,MATCH('Financial Summary'!W$12,'Financial Statements'!$5:$5,0),FALSE) -> 573.80242 | Y24: Total_liabilities | AC24: =_xlfn.RRI(2,K24,M24) -> 0.4339117
E25: % change | H25: =H24/G24-1 -> 0.71459675 | I25: =I24/H24-1 -> 0.47524565 | J25: =J24/I24-1 -> 0.3524478 | K25: =K24/J24-1 -> 0.35581051 | L25: =L24/K24-1 -> 0.48627307 | M25: =M24/L24-1 -> 0.38339501
E26: 3yr CAGR | M26: =+(M24/J24)^(0.333333333333333)-1 -> 0.40739046 | O26: Net Assets | P26: A$m | Q26: 0 | S26: =VLOOKUP($Y26,'Financial Statements'!$1:$1048576,MATCH('Financial Summary'!S$12,'Financial Statements'!$5:$5,0),FALSE) -> 353.979 | T26: =VLOOKUP($Y26,'Financial Statements'!$1:$1048576,MATCH('Financial Summary'!T$12,'Financial Statements'!$5:$5,0),FALSE) -> 380.124 | U26: =VLOOKUP($Y26,'Financial Statements'!$1:$1048576,MATCH('Financial Summary'!U$12,'Financial Statements'!$5:$5,0),FALSE) -> 395.18093 | V26: =VLOOKUP($Y26,'Financial Statements'!$1:$1048576,MATCH('Financial Summary'!V$12,'Financial Statements'!$5:$5,0),FALSE) -> 416.08387 | W26: =VLOOKUP($Y26,'Financial Statements'!$1:$1048576,MATCH('Financial Summary'!W$12,'Financial Statements'!$5:$5,0),FALSE) -> 443.43583 | Y26: Net_assets
O27: Net Debt (cash) | P27: A$m | Q27: 0 | S27: =VLOOKUP($Y27,Assumptions!$1:$1048576,MATCH('Financial Summary'!S$12,Assumptions!$5:$5,0),FALSE) -> -294.48 | T27: =VLOOKUP($Y27,Assumptions!$1:$1048576,MATCH('Financial Summary'!T$12,Assumptions!$5:$5,0),FALSE) -> -281.743 | U27: =VLOOKUP($Y27,Assumptions!$1:$1048576,MATCH('Financial Summary'!U$12,Assumptions!$5:$5,0),FALSE) -> -269.57803 | V27: =VLOOKUP($Y27,Assumptions!$1:$1048576,MATCH('Financial Summary'!V$12,Assumptions!$5:$5,0),FALSE) -> -242.88346 | W27: =VLOOKUP($Y27,Assumptions!$1:$1048576,MATCH('Financial Summary'!W$12,Assumptions!$5:$5,0),FALSE) -> -233.92671 | Y27: Net_Debt
A28: EBITDA_Normalised | E28: EBITDA Normalised | F28: A$m | G28: =VLOOKUP($A$28,'Financial Statements'!$1:$1048576,MATCH('Financial Summary'!G$12,'Financial Statements'!$5:$5,0),FALSE) -> 21.6 | H28: =VLOOKUP($A$28,'Financial Statements'!$1:$1048576,MATCH('Financial Summary'!H$12,'Financial Statements'!$5:$5,0),FALSE) -> 29.3 | I28: =VLOOKUP($A$28,'Financial Statements'!$1:$1048576,MATCH('Financial Summary'!I$12,'Financial Statements'!$5:$5,0),FALSE) -> 44.759 | J28: =VLOOKUP($A$28,'Financial Statements'!$1:$1048576,MATCH('Financial Summary'!J$12,'Financial Statements'!$5:$5,0),FALSE) -> 65.428 | K28: =VLOOKUP($A$28,'Financial Statements'!$1:$1048576,MATCH('Financial Summary'!K$12,'Financial Statements'!$5:$5,0),FALSE) -> 85.352441 | L28: =VLOOKUP($A$28,'Financial Statements'!$1:$1048576,MATCH('Financial Summary'!L$12,'Financial Statements'!$5:$5,0),FALSE) -> 125.68896 | M28: =VLOOKUP($A$28,'Financial Statements'!$1:$1048576,MATCH('Financial Summary'!M$12,'Financial Statements'!$5:$5,0),FALSE) -> 171.73704 | O28: Capital Employed | P28: A$m | Q28: 0 | S28: =+S26+S27 -> 59.499 | T28: =+T26+T27 -> 98.381 | U28: =+U26+U27 -> 125.6029 | V28: =+V26+V27 -> 173.20041 | W28: =+W26+W27 -> 209.50912
A30: Total_D&A | E30: Total D&A | F30: A$m | G30: =VLOOKUP($A30,'Financial Statements'!$1:$1048576,MATCH('Financial Summary'!G$12,'Financial Statements'!$5:$5,0),FALSE) -> -14.4 | H30: =VLOOKUP($A30,'Financial Statements'!$1:$1048576,MATCH('Financial Summary'!H$12,'Financial Statements'!$5:$5,0),FALSE) -> -25.5 | I30: =VLOOKUP($A30,'Financial Statements'!$1:$1048576,MATCH('Financial Summary'!I$12,'Financial Statements'!$5:$5,0),FALSE) -> -31.123 | J30: =VLOOKUP($A30,'Financial Statements'!$1:$1048576,MATCH('Financial Summary'!J$12,'Financial Statements'!$5:$5,0),FALSE) -> -39.681 | K30: =VLOOKUP($A30,'Financial Statements'!$1:$1048576,MATCH('Financial Summary'!K$12,'Financial Statements'!$5:$5,0),FALSE) -> -48.678845 | L30: =VLOOKUP($A30,'Financial Statements'!$1:$1048576,MATCH('Financial Summary'!L$12,'Financial Statements'!$5:$5,0),FALSE) -> -58.461202 | M30: =VLOOKUP($A30,'Financial Statements'!$1:$1048576,MATCH('Financial Summary'!M$12,'Financial Statements'!$5:$5,0),FALSE) -> -69.478955 | O30: Cash Flow Statement
E31: Total EBIT | F31: A$m | G31: =VLOOKUP($A32,'Financial Statements'!$1:$1048576,MATCH('Financial Summary'!G$12,'Financial Statements'!$5:$5,0),FALSE) -> 7.2 | H31: =VLOOKUP($A32,'Financial Statements'!$1:$1048576,MATCH('Financial Summary'!H$12,'Financial Statements'!$5:$5,0),FALSE) -> 3.8 | I31: =VLOOKUP($A32,'Financial Statements'!$1:$1048576,MATCH('Financial Summary'!I$12,'Financial Statements'!$5:$5,0),FALSE) -> 13.636 | J31: =VLOOKUP($A32,'Financial Statements'!$1:$1048576,MATCH('Financial Summary'!J$12,'Financial Statements'!$5:$5,0),FALSE) -> 25.747 | K31: =VLOOKUP($A32,'Financial Statements'!$1:$1048576,MATCH('Financial Summary'!K$12,'Financial Statements'!$5:$5,0),FALSE) -> 36.673596 | L31: =VLOOKUP($A32,'Financial Statements'!$1:$1048576,MATCH('Financial Summary'!L$12,'Financial Statements'!$5:$5,0),FALSE) -> 67.227753 | M31: =VLOOKUP($A32,'Financial Statements'!$1:$1048576,MATCH('Financial Summary'!M$12,'Financial Statements'!$5:$5,0),FALSE) -> 102.25809 | O31: Year ended 30 June | P31: Unit | Q31: FY22 | R31: FY23 | S31: FY24 | T31: FY25 | U31: FY26e | V31: FY27e | W31: FY28e
A32: Total_EBIT | E32: % change | F32: % | H32: =H31/G31-1 -> -0.47222222 | I32: =I31/H31-1 -> 2.5884211 | J32: =J31/I31-1 -> 0.88816368 | K32: =K31/J31-1 -> 0.42438327 | L32: =L31/K31-1 -> 0.83313775 | M32: =M31/L31-1 -> 0.52106956 | O32: EBIT | P32: A$m | Q32: =VLOOKUP($Y32,'Financial Statements'!$1:$1048576,MATCH('Financial Summary'!Q$31,'Financial Statements'!$5:$5,0),FALSE) -> 7.2 | S32: =VLOOKUP($Y32,'Financial Statements'!$1:$1048576,MATCH('Financial Summary'!S$31,'Financial Statements'!$5:$5,0),FALSE) -> 13.6 | T32: =VLOOKUP($Y32,'Financial Statements'!$1:$1048576,MATCH('Financial Summary'!T$31,'Financial Statements'!$5:$5,0),FALSE) -> 25.4 | U32: =VLOOKUP($Y32,'Financial Statements'!$1:$1048576,MATCH('Financial Summary'!U$31,'Financial Statements'!$5:$5,0),FALSE) -> 36.673596 | V32: =VLOOKUP($Y32,'Financial Statements'!$1:$1048576,MATCH('Financial Summary'!V$31,'Financial Statements'!$5:$5,0),FALSE) -> 67.227753 | W32: =VLOOKUP($Y32,'Financial Statements'!$1:$1048576,MATCH('Financial Summary'!W$31,'Financial Statements'!$5:$5,0),FALSE) -> 102.25809 | Y32: CF_EBIT
E33: 3yr CAGR | M33: =+(M31/J31)^(0.333333333333333)-1 -> 0.58364201 | O33: D&A | P33: A$m | Q33: =VLOOKUP($Y33,'Financial Statements'!$1:$1048576,MATCH('Financial Summary'!Q$31,'Financial Statements'!$5:$5,0),FALSE) -> 14.5 | S33: =VLOOKUP($Y33,'Financial Statements'!$1:$1048576,MATCH('Financial Summary'!S$31,'Financial Statements'!$5:$5,0),FALSE) -> 31.123 | T33: =VLOOKUP($Y33,'Financial Statements'!$1:$1048576,MATCH('Financial Summary'!T$31,'Financial Statements'!$5:$5,0),FALSE) -> 39.681 | U33: =VLOOKUP($Y33,'Financial Statements'!$1:$1048576,MATCH('Financial Summary'!U$31,'Financial Statements'!$5:$5,0),FALSE) -> 48.678845 | V33: =VLOOKUP($Y33,'Financial Statements'!$1:$1048576,MATCH('Financial Summary'!V$31,'Financial Statements'!$5:$5,0),FALSE) -> 58.461202 | W33: =VLOOKUP($Y33,'Financial Statements'!$1:$1048576,MATCH('Financial Summary'!W$31,'Financial Statements'!$5:$5,0),FALSE) -> 69.478955 | Y33: CF_D&A
O34: (Inc)/dec in working cap | P34: A$m | Q34: =VLOOKUP($Y34,'Financial Statements'!$1:$1048576,MATCH('Financial Summary'!Q$31,'Financial Statements'!$5:$5,0),FALSE) -> -1.1 | S34: =VLOOKUP($Y34,'Financial Statements'!$1:$1048576,MATCH('Financial Summary'!S$31,'Financial Statements'!$5:$5,0),FALSE) -> 10.541 | T34: =VLOOKUP($Y34,'Financial Statements'!$1:$1048576,MATCH('Financial Summary'!T$31,'Financial Statements'!$5:$5,0),FALSE) -> 10.734 | U34: =VLOOKUP($Y34,'Financial Statements'!$1:$1048576,MATCH('Financial Summary'!U$31,'Financial Statements'!$5:$5,0),FALSE) -> 6.7829699 | V34: =VLOOKUP($Y34,'Financial Statements'!$1:$1048576,MATCH('Financial Summary'!V$31,'Financial Statements'!$5:$5,0),FALSE) -> 4.1105691 | W34: =VLOOKUP($Y34,'Financial Statements'!$1:$1048576,MATCH('Financial Summary'!W$31,'Financial Statements'!$5:$5,0),FALSE) -> 4.9549784 | Y34: Chg_working_Cap
A35: Total_Net_Int | E35: Net Interest Expense | F35: A$m | G35: =VLOOKUP($A35,'Financial Statements'!$1:$1048576,MATCH('Financial Summary'!G$12,'Financial Statements'!$5:$5,0),FALSE) -> -1.6 | H35: =VLOOKUP($A35,'Financial Statements'!$1:$1048576,MATCH('Financial Summary'!H$12,'Financial Statements'!$5:$5,0),FALSE) -> 3.9 | I35: =VLOOKUP($A35,'Financial Statements'!$1:$1048576,MATCH('Financial Summary'!I$12,'Financial Statements'!$5:$5,0),FALSE) -> 2.617 | J35: =VLOOKUP($A35,'Financial Statements'!$1:$1048576,MATCH('Financial Summary'!J$12,'Financial Statements'!$5:$5,0),FALSE) -> 3.772 | K35: =VLOOKUP($A35,'Financial Statements'!$1:$1048576,MATCH('Financial Summary'!K$12,'Financial Statements'!$5:$5,0),FALSE) -> 2.2553574 | L35: =VLOOKUP($A35,'Financial Statements'!$1:$1048576,MATCH('Financial Summary'!L$12,'Financial Statements'!$5:$5,0),FALSE) -> -0.92870741 | M35: =VLOOKUP($A35,'Financial Statements'!$1:$1048576,MATCH('Financial Summary'!M$12,'Financial Statements'!$5:$5,0),FALSE) -> -4.8335596 | O35: Income Tax | P35: A$m | Q35: =VLOOKUP($Y35,'Financial Statements'!$1:$1048576,MATCH('Financial Summary'!Q$31,'Financial Statements'!$5:$5,0),FALSE) -> -0.1 | S35: =VLOOKUP($Y35,'Financial Statements'!$1:$1048576,MATCH('Financial Summary'!S$31,'Financial Statements'!$5:$5,0),FALSE) -> -6.502 | T35: =VLOOKUP($Y35,'Financial Statements'!$1:$1048576,MATCH('Financial Summary'!T$31,'Financial Statements'!$5:$5,0),FALSE) -> -19.389 | U35: =VLOOKUP($Y35,'Financial Statements'!$1:$1048576,MATCH('Financial Summary'!U$31,'Financial Statements'!$5:$5,0),FALSE) -> -17.447821 | V35: =VLOOKUP($Y35,'Financial Statements'!$1:$1048576,MATCH('Financial Summary'!V$31,'Financial Statements'!$5:$5,0),FALSE) -> -24.023059 | W35: =VLOOKUP($Y35,'Financial Statements'!$1:$1048576,MATCH('Financial Summary'!W$31,'Financial Statements'!$5:$5,0),FALSE) -> -32.20864 | Y35: CF_Income_tax
A36: PBT | E36: Profit Before Tax | F36: A$m | G36: =VLOOKUP($A36,'Financial Statements'!$1:$1048576,MATCH('Financial Summary'!G$12,'Financial Statements'!$5:$5,0),FALSE) -> 5.6 | H36: =VLOOKUP($A36,'Financial Statements'!$1:$1048576,MATCH('Financial Summary'!H$12,'Financial Statements'!$5:$5,0),FALSE) -> 7.7 | I36: =VLOOKUP($A36,'Financial Statements'!$1:$1048576,MATCH('Financial Summary'!I$12,'Financial Statements'!$5:$5,0),FALSE) -> 16.253 | J36: =VLOOKUP($A36,'Financial Statements'!$1:$1048576,MATCH('Financial Summary'!J$12,'Financial Statements'!$5:$5,0),FALSE) -> 29.519 | K36: =VLOOKUP($A36,'Financial Statements'!$1:$1048576,MATCH('Financial Summary'!K$12,'Financial Statements'!$5:$5,0),FALSE) -> 38.928953 | L36: =VLOOKUP($A36,'Financial Statements'!$1:$1048576,MATCH('Financial Summary'!L$12,'Financial Statements'!$5:$5,0),FALSE) -> 66.299046 | M36: =VLOOKUP($A36,'Financial Statements'!$1:$1048576,MATCH('Financial Summary'!M$12,'Financial Statements'!$5:$5,0),FALSE) -> 97.42453 | O36: Other | P36: A$m | Q36: =+Q37-Q32-Q33-Q34-Q35 -> -0.3 | S36: =+S37-S32-S33-S34-S35 -> 7.538 | T36: =+T37-T32-T33-T34-T35 -> 0.901 | U36: =+U37-U32-U33-U34-U35 -> 9.018 | V36: =+V37-V32-V33-V34-V35 -> 9.018 | W36: =+W37-W32-W33-W34-W35 -> 9.018
A37: Tax_expense | E37: Income Tax | F37: A$m | G37: =VLOOKUP($A37,'Financial Statements'!$1:$1048576,MATCH('Financial Summary'!G$12,'Financial Statements'!$5:$5,0),FALSE) -> -2.4 | H37: =VLOOKUP($A37,'Financial Statements'!$1:$1048576,MATCH('Financial Summary'!H$12,'Financial Statements'!$5:$5,0),FALSE) -> -4.7 | I37: =VLOOKUP($A37,'Financial Statements'!$1:$1048576,MATCH('Financial Summary'!I$12,'Financial Statements'!$5:$5,0),FALSE) -> -10.6 | J37: =VLOOKUP($A37,'Financial Statements'!$1:$1048576,MATCH('Financial Summary'!J$12,'Financial Statements'!$5:$5,0),FALSE) -> -14.7 | K37: =VLOOKUP($A37,'Financial Statements'!$1:$1048576,MATCH('Financial Summary'!K$12,'Financial Statements'!$5:$5,0),FALSE) -> -17.447821 | L37: =VLOOKUP($A37,'Financial Statements'!$1:$1048576,MATCH('Financial Summary'!L$12,'Financial Statements'!$5:$5,0),FALSE) -> -24.023059 | M37: =VLOOKUP($A37,'Financial Statements'!$1:$1048576,MATCH('Financial Summary'!M$12,'Financial Statements'!$5:$5,0),FALSE) -> -32.20864 | O37: Operating cash flow | P37: A$m | Q37: =VLOOKUP($Y37,'Financial Statements'!$1:$1048576,MATCH('Financial Summary'!Q$31,'Financial Statements'!$5:$5,0),FALSE) -> 20.2 | S37: =VLOOKUP($Y37,'Financial Statements'!$1:$1048576,MATCH('Financial Summary'!S$31,'Financial Statements'!$5:$5,0),FALSE) -> 56.3 | T37: =VLOOKUP($Y37,'Financial Statements'!$1:$1048576,MATCH('Financial Summary'!T$31,'Financial Statements'!$5:$5,0),FALSE) -> 57.327 | U37: =VLOOKUP($Y37,'Financial Statements'!$1:$1048576,MATCH('Financial Summary'!U$31,'Financial Statements'!$5:$5,0),FALSE) -> 83.70559 | V37: =VLOOKUP($Y37,'Financial Statements'!$1:$1048576,MATCH('Financial Summary'!V$31,'Financial Statements'!$5:$5,0),FALSE) -> 114.79447 | W37: =VLOOKUP($Y37,'Financial Statements'!$1:$1048576,MATCH('Financial Summary'!W$31,'Financial Statements'!$5:$5,0),FALSE) -> 153.50138 | Y37: OCF
A38: NPAT_underlying | E38: NPAT (Underlying) | F38: A$m | G38: =VLOOKUP($A38,'Financial Statements'!$1:$1048576,MATCH('Financial Summary'!G$12,'Financial Statements'!$5:$5,0),FALSE) -> 3.2 | H38: =VLOOKUP($A38,'Financial Statements'!$1:$1048576,MATCH('Financial Summary'!H$12,'Financial Statements'!$5:$5,0),FALSE) -> 3 | I38: =VLOOKUP($A38,'Financial Statements'!$1:$1048576,MATCH('Financial Summary'!I$12,'Financial Statements'!$5:$5,0),FALSE) -> 5.653 | J38: =VLOOKUP($A38,'Financial Statements'!$1:$1048576,MATCH('Financial Summary'!J$12,'Financial Statements'!$5:$5,0),FALSE) -> 14.819 | K38: =VLOOKUP($A38,'Financial Statements'!$1:$1048576,MATCH('Financial Summary'!K$12,'Financial Statements'!$5:$5,0),FALSE) -> 21.481133 | L38: =VLOOKUP($A38,'Financial Statements'!$1:$1048576,MATCH('Financial Summary'!L$12,'Financial Statements'!$5:$5,0),FALSE) -> 42.275987 | M38: =VLOOKUP($A38,'Financial Statements'!$1:$1048576,MATCH('Financial Summary'!M$12,'Financial Statements'!$5:$5,0),FALSE) -> 65.215889 | O38: Purchase of PPE | P38: A$m | Q38: =VLOOKUP($Y38,'Financial Statements'!$1:$1048576,MATCH('Financial Summary'!Q$31,'Financial Statements'!$5:$5,0),FALSE) -> -19.4 | S38: =VLOOKUP($Y38,'Financial Statements'!$1:$1048576,MATCH('Financial Summary'!S$31,'Financial Statements'!$5:$5,0),FALSE) -> -33.496 | T38: =VLOOKUP($Y38,'Financial Statements'!$1:$1048576,MATCH('Financial Summary'!T$31,'Financial Statements'!$5:$5,0),FALSE) -> -61.326 | U38: =VLOOKUP($Y38,'Financial Statements'!$1:$1048576,MATCH('Financial Summary'!U$31,'Financial Statements'!$5:$5,0),FALSE) -> -54.749065 | V38: =VLOOKUP($Y38,'Financial Statements'!$1:$1048576,MATCH('Financial Summary'!V$31,'Financial Statements'!$5:$5,0),FALSE) -> -73.021702 | W38: =VLOOKUP($Y38,'Financial Statements'!$1:$1048576,MATCH('Financial Summary'!W$31,'Financial Statements'!$5:$5,0),FALSE) -> -66.566951 | Y38: CF_PPE
E39: % change | H39: =H38/G38-1 -> -0.0625 | I39: =I38/H38-1 -> 0.88433333 | J39: =J38/I38-1 -> 1.6214399 | K39: =K38/J38-1 -> 0.44956694 | L39: =L38/K38-1 -> 0.96805205 | M39: =M38/L38-1 -> 0.54262252 | O39: Payments for Intangibles | P39: A$m | Q39: =VLOOKUP($Y39,'Financial Statements'!$1:$1048576,MATCH('Financial Summary'!Q$31,'Financial Statements'!$5:$5,0),FALSE) -> -7 | S39: =VLOOKUP($Y39,'Financial Statements'!$1:$1048576,MATCH('Financial Summary'!S$31,'Financial Statements'!$5:$5,0),FALSE) -> -0.063 | T39: =VLOOKUP($Y39,'Financial Statements'!$1:$1048576,MATCH('Financial Summary'!T$31,'Financial Statements'!$5:$5,0),FALSE) -> -0.037 | U39: =VLOOKUP($Y39,'Financial Statements'!$1:$1048576,MATCH('Financial Summary'!U$31,'Financial Statements'!$5:$5,0),FALSE) -> -5.6572864 | V39: =VLOOKUP($Y39,'Financial Statements'!$1:$1048576,MATCH('Financial Summary'!V$31,'Financial Statements'!$5:$5,0),FALSE) -> -10.304333 | W39: =VLOOKUP($Y39,'Financial Statements'!$1:$1048576,MATCH('Financial Summary'!W$31,'Financial Statements'!$5:$5,0),FALSE) -> -12.505216 | Y39: CF_Intangibles
E40: 3yr CAGR | M40: =+(M38/J38)^(0.333333333333333)-1 -> 0.63874548 | O40: Other investing | P40: A$m | Q40: =Q41-Q38-Q39 -> -5.3 | S40: =S41-S38-S39 -> -278.259 | T40: =T41-T38-T39 -> 26.812 | U40: =U41-U38-U39 -> 0 | V40: =V41-V38-V39 -> 0 | W40: =W41-W38-W39 -> 0
O41: Total Investing Cash Flows | P41: A$m | Q41: =VLOOKUP($Y41,'Financial Statements'!$1:$1048576,MATCH('Financial Summary'!Q$31,'Financial Statements'!$5:$5,0),FALSE) -> -31.7 | S41: =VLOOKUP($Y41,'Financial Statements'!$1:$1048576,MATCH('Financial Summary'!S$31,'Financial Statements'!$5:$5,0),FALSE) -> -311.818 | T41: =VLOOKUP($Y41,'Financial Statements'!$1:$1048576,MATCH('Financial Summary'!T$31,'Financial Statements'!$5:$5,0),FALSE) -> -34.551 | U41: =VLOOKUP($Y41,'Financial Statements'!$1:$1048576,MATCH('Financial Summary'!U$31,'Financial Statements'!$5:$5,0),FALSE) -> -60.406351 | V41: =VLOOKUP($Y41,'Financial Statements'!$1:$1048576,MATCH('Financial Summary'!V$31,'Financial Statements'!$5:$5,0),FALSE) -> -83.326036 | W41: =VLOOKUP($Y41,'Financial Statements'!$1:$1048576,MATCH('Financial Summary'!W$31,'Financial Statements'!$5:$5,0),FALSE) -> -79.072168 | Y41: Net_CF_Investing
E42: Significant Items | F42: A$m | G42: =+G43-G38 -> 0.7 | H42: =+H43-H38 -> -5.3 | I42: =+I43-I38 -> -19.401 | J42: =+J43-J38 -> -0.343 | K42: =+K43-K38 -> 0 | L42: =+L43-L38 -> -8.1712415e-13 | M42: =+M43-M38 -> -6.2527761e-12 | O42: Dividends paid | P42: A$m | Q42: =VLOOKUP($Y42,'Financial Statements'!$1:$1048576,MATCH('Financial Summary'!Q$31,'Financial Statements'!$5:$5,0),FALSE) -> 0 | S42: =VLOOKUP($Y42,'Financial Statements'!$1:$1048576,MATCH('Financial Summary'!S$31,'Financial Statements'!$5:$5,0),FALSE) -> 0 | T42: =VLOOKUP($Y42,'Financial Statements'!$1:$1048576,MATCH('Financial Summary'!T$31,'Financial Statements'!$5:$5,0),FALSE) -> 0 | U42: =VLOOKUP($Y42,'Financial Statements'!$1:$1048576,MATCH('Financial Summary'!U$31,'Financial Statements'!$5:$5,0),FALSE) -> -15.4422 | V42: =VLOOKUP($Y42,'Financial Statements'!$1:$1048576,MATCH('Financial Summary'!V$31,'Financial Statements'!$5:$5,0),FALSE) -> -30.391054 | W42: =VLOOKUP($Y42,'Financial Statements'!$1:$1048576,MATCH('Financial Summary'!W$31,'Financial Statements'!$5:$5,0),FALSE) -> -46.881924 | Y42: Div_paid
A43: NPAT_reported | E43: Reported NPAT | F43: A$m | G43: =VLOOKUP($A43,'Financial Statements'!$1:$1048576,MATCH('Financial Summary'!G$12,'Financial Statements'!$5:$5,0),FALSE) -> 3.9 | H43: =VLOOKUP($A43,'Financial Statements'!$1:$1048576,MATCH('Financial Summary'!H$12,'Financial Statements'!$5:$5,0),FALSE) -> -2.3 | I43: =VLOOKUP($A43,'Financial Statements'!$1:$1048576,MATCH('Financial Summary'!I$12,'Financial Statements'!$5:$5,0),FALSE) -> -13.748 | J43: =VLOOKUP($A43,'Financial Statements'!$1:$1048576,MATCH('Financial Summary'!J$12,'Financial Statements'!$5:$5,0),FALSE) -> 14.476 | K43: =VLOOKUP($A43,'Financial Statements'!$1:$1048576,MATCH('Financial Summary'!K$12,'Financial Statements'!$5:$5,0),FALSE) -> 21.481133 | L43: =VLOOKUP($A43,'Financial Statements'!$1:$1048576,MATCH('Financial Summary'!L$12,'Financial Statements'!$5:$5,0),FALSE) -> 42.275987 | M43: =VLOOKUP($A43,'Financial Statements'!$1:$1048576,MATCH('Financial Summary'!M$12,'Financial Statements'!$5:$5,0),FALSE) -> 65.215889 | O43: Net borrowings | P43: A$m | Q43: =VLOOKUP($Y43,'Financial Statements'!$1:$1048576,MATCH('Financial Summary'!Q$31,'Financial Statements'!$5:$5,0),FALSE)+VLOOKUP($Z$43,'Financial Statements'!$1:$1048576,MATCH('Financial Summary'!Q$12,'Financial Statements'!$5:$5,0),FALSE) -> 0 | S43: =VLOOKUP($Y43,'Financial Statements'!$1:$1048576,MATCH('Financial Summary'!S$31,'Financial Statements'!$5:$5,0),FALSE)+VLOOKUP($Z$43,'Financial Statements'!$1:$1048576,MATCH('Financial Summary'!S$12,'Financial Statements'!$5:$5,0),FALSE) -> -3 | T43: =VLOOKUP($Y43,'Financial Statements'!$1:$1048576,MATCH('Financial Summary'!T$31,'Financial Statements'!$5:$5,0),FALSE)+VLOOKUP($Z$43,'Financial Statements'!$1:$1048576,MATCH('Financial Summary'!T$12,'Financial Statements'!$5:$5,0),FALSE) -> 0 | U43: =VLOOKUP($Y43,'Financial Statements'!$1:$1048576,MATCH('Financial Summary'!U$31,'Financial Statements'!$5:$5,0),FALSE)+VLOOKUP($Z$43,'Financial Statements'!$1:$1048576,MATCH('Financial Summary'!U$12,'Financial Statements'!$5:$5,0),FALSE) -> 0 | V43: =VLOOKUP($Y43,'Financial Statements'!$1:$1048576,MATCH('Financial Summary'!V$31,'Financial Statements'!$5:$5,0),FALSE)+VLOOKUP($Z$43,'Financial Statements'!$1:$1048576,MATCH('Financial Summary'!V$12,'Financial Statements'!$5:$5,0),FALSE) -> 0 | W43: =VLOOKUP($Y43,'Financial Statements'!$1:$1048576,MATCH('Financial Summary'!W$31,'Financial Statements'!$5:$5,0),FALSE)+VLOOKUP($Z$43,'Financial Statements'!$1:$1048576,MATCH('Financial Summary'!W$12,'Financial Statements'!$5:$5,0),FALSE) -> 0 | Y43: Proceeds_borrowing | Z43: Repayment_borrowings
A44: EPS_underlying_diluted | E44: EPS (Underlying, Diluted) | F44: Cents | G44: =VLOOKUP($A44,'Financial Statements'!$1:$1048576,MATCH('Financial Summary'!G$12,'Financial Statements'!$5:$5,0),FALSE) -> 0 | H44: na | I44: =VLOOKUP($A44,'Financial Statements'!$1:$1048576,MATCH('Financial Summary'!I$12,'Financial Statements'!$5:$5,0),FALSE) -> 5.0682905 | J44: =VLOOKUP($A44,'Financial Statements'!$1:$1048576,MATCH('Financial Summary'!J$12,'Financial Statements'!$5:$5,0),FALSE) -> 13.992731 | K44: =VLOOKUP($A44,'Financial Statements'!$1:$1048576,MATCH('Financial Summary'!K$12,'Financial Statements'!$5:$5,0),FALSE) -> 20.283401 | L44: =VLOOKUP($A44,'Financial Statements'!$1:$1048576,MATCH('Financial Summary'!L$12,'Financial Statements'!$5:$5,0),FALSE) -> 39.918788 | M44: =VLOOKUP($A44,'Financial Statements'!$1:$1048576,MATCH('Financial Summary'!M$12,'Financial Statements'!$5:$5,0),FALSE) -> 61.579621 | O44: Other financing | P44: A$m | Q44: =+Q45-Q42-Q43 -> 1.8 | S44: =+S45-S42-S43 -> 257.934 | T44: =+T45-T42-T43 -> 0.679 | U44: =+U45-U42-U43 -> -20.022005 | V44: =+V45-V42-V43 -> -27.771951 | W44: =+W45-W42-W43 -> -36.504038
E45: % change | F45: % | G45: na | H45: =IFERROR(H44/G44-1,"na") -> na | I45: =IFERROR(I44/H44-1,"na") -> na | J45: =IFERROR(J44/I44-1,"na") -> 1.7608384 | K45: =IFERROR(K44/J44-1,"na") -> 0.44956694 | L45: =IFERROR(L44/K44-1,"na") -> 0.96805205 | M45: =IFERROR(M44/L44-1,"na") -> 0.54262252 | O45: Total Financing Cash Flows | P45: A$m | Q45: =VLOOKUP($Y45,'Financial Statements'!$1:$1048576,MATCH('Financial Summary'!Q$31,'Financial Statements'!$5:$5,0),FALSE) -> 1.8 | S45: =VLOOKUP($Y45,'Financial Statements'!$1:$1048576,MATCH('Financial Summary'!S$31,'Financial Statements'!$5:$5,0),FALSE) -> 254.934 | T45: =VLOOKUP($Y45,'Financial Statements'!$1:$1048576,MATCH('Financial Summary'!T$31,'Financial Statements'!$5:$5,0),FALSE) -> 0.679 | U45: =VLOOKUP($Y45,'Financial Statements'!$1:$1048576,MATCH('Financial Summary'!U$31,'Financial Statements'!$5:$5,0),FALSE) -> -35.464206 | V45: =VLOOKUP($Y45,'Financial Statements'!$1:$1048576,MATCH('Financial Summary'!V$31,'Financial Statements'!$5:$5,0),FALSE) -> -58.163005 | W45: =VLOOKUP($Y45,'Financial Statements'!$1:$1048576,MATCH('Financial Summary'!W$31,'Financial Statements'!$5:$5,0),FALSE) -> -83.385961 | Y45: Net_CF_Financing
E46: 3yr CAGR | M46: =+(M44/J44)^(0.333333333333333)-1 -> 0.63874548 | O46: Net change in cash | P46: A$m | Q46: =VLOOKUP($Y46,'Financial Statements'!$1:$1048576,MATCH('Financial Summary'!Q$31,'Financial Statements'!$5:$5,0),FALSE) -> -9.7 | S46: =VLOOKUP($Y46,'Financial Statements'!$1:$1048576,MATCH('Financial Summary'!S$31,'Financial Statements'!$5:$5,0),FALSE) -> -0.584 | T46: =VLOOKUP($Y46,'Financial Statements'!$1:$1048576,MATCH('Financial Summary'!T$31,'Financial Statements'!$5:$5,0),FALSE) -> 23.455 | U46: =VLOOKUP($Y46,'Financial Statements'!$1:$1048576,MATCH('Financial Summary'!U$31,'Financial Statements'!$5:$5,0),FALSE) -> -12.164966 | V46: =VLOOKUP($Y46,'Financial Statements'!$1:$1048576,MATCH('Financial Summary'!V$31,'Financial Statements'!$5:$5,0),FALSE) -> -26.694575 | W46: =VLOOKUP($Y46,'Financial Statements'!$1:$1048576,MATCH('Financial Summary'!W$31,'Financial Statements'!$5:$5,0),FALSE) -> -8.9567467 | Y46: Net_chg_Cash
...

Sheet Financial Statements
B2: Guzman Y Gomez (GYG.AX)
B3: Financial statements
F4: Pro forma | G4: Pro forma | H4: Pro forma | I4: Pro forma | J4: Pro forma
B5: Year ended 30 June | C5: unit | D5: FY20 | E5: FY21 | F5: FY22 | G5: 1H23 | H5: 2H23 | I5: FY23 | J5: 1H24 | K5: 2H24 | L5: FY24 | M5: 1H25 | N5: 2H25 | O5: FY25 | P5: 1H26e | Q5: 2H26e | R5: FY26e | S5: 1H27e | T5: 2H27e | U5: FY27e | V5: 1H28e | W5: 2H28e | X5: FY28e | Y5: 1H29e | Z5: 2H29e | AA5: FY29e | AB5: =+Assumptions!AB5 -> 1H30e | AC5: =+Assumptions!AC5 -> 2H30e | AD5: =+Assumptions!AD5 -> FY30e | AE5: =+Assumptions!AE5 -> 1H31e | AF5: =+Assumptions!AF5 -> 2H31e | AG5: =+Assumptions!AG5 -> FY31e | AH5: =+Assumptions!AH5 -> 1H32e | AI5: =+Assumptions!AI5 -> 2H32e | ... AP5: =+Assumptions!AP5 -> FY34e | AQ5: 1H35e | AR5: 2H35e | AS5: FY35e | AT5: 1H36e | AU5: 2H36e | AV5: FY36e
A7: l | B7: Income Statement
B9: Revenue
B10: Australia | C10: A$m | F10: =+Assumptions!F18 -> 168.027 | G10: =+Assumptions!G18 -> 119.344 | H10: =+Assumptions!H18 -> 132.0375 | I10: =+Assumptions!I18 -> 251.3815 | J10: =+Assumptions!J18 -> 161.968 | K10: =+Assumptions!K18 -> 167.574 | L10: =+Assumptions!L18 -> 329.542 | M10: =+Assumptions!M18 -> 207.992 | ... AV10: =+Assumptions!AV18 -> 2216.8064
B11: Singapore | C11: A$m | F11: =+Assumptions!F19 -> 1.099 | G11: =+Assumptions!G19 -> 0.7525 | H11: =+Assumptions!H19 -> 0.756 | I11: =+Assumptions!I19 -> 1.5085 | J11: =+Assumptions!J19 -> 0.777 | K11: =+Assumptions!K19 -> 0.847 | L11: =+Assumptions!L19 -> 1.624 | M11: =+Assumptions!M19 -> 1.057 | ... AV11: =+Assumptions!AV19 -> 4.9336368
B12: Japan | C12: A$m | F12: =+Assumptions!F20 -> 0.174 | G12: =+Assumptions!G20 -> 0.096 | H12: =+Assumptions!H20 -> 0.114 | I12: =+Assumptions!I20 -> 0.21 | J12: =+Assumptions!J20 -> 0.126 | K12: =+Assumptions!K20 -> 0.111 | L12: =+Assumptions!L20 -> 0.237 | M12: =+Assumptions!M20 -> 0.138 | ... AV12: =+Assumptions!AV20 -> 0.90244992
B13: US | C13: A$m | F13: =+Assumptions!F21 -> 2.5 | G13: =+Assumptions!G21 -> 1.5 | H13: =+Assumptions!H21 -> 4.5 | I13: =+Assumptions!I21 -> 6 | J13: =+Assumptions!J21 -> 5.6 | K13: =+Assumptions!K21 -> 5.2 | L13: =+Assumptions!L21 -> 10.8 | M13: =+Assumptions!M21 -> 3.336 | ... AV13: =+Assumptions!AV21 -> 37.702678
A14: Other_revenue | B14: Other | C14: A$m | F14: =+Assumptions!F178 -> 13.3 | G14: =+Assumptions!G178 -> 8.7 | H14: =+Assumptions!H178 -> 9 | I14: =+Assumptions!I178 -> 17.7 | J14: =+Assumptions!J178 -> 11.7 | K14: =+Assumptions!K178 -> 11.074 | L14: =+Assumptions!L178 -> 22.774 | M14: =+Assumptions!M178 -> 14.711 | ... AV14: =+Assumptions!AV178 -> 122.41357
A15: Total_revenue | B15: Total revenue | C15: A$m | F15: =SUM(F10:F14) -> 185.1 | G15: =SUM(G10:G14) -> 130.3925 | H15: =SUM(H10:H14) -> 146.4075 | I15: =SUM(I10:I14) -> 276.8 | J15: =SUM(J10:J14) -> 180.171 | K15: =SUM(K10:K14) -> 184.806 | L15: =SUM(L10:L14) -> 364.977 | M15: =SUM(M10:M14) -> 227.234 | ... AV15: =SUM(AV10:AV14) -> 2382.7588
B16: % change | C16: % | I16: =I15/F15-1 -> 0.49540789 | J16: =J15/G15-1 -> 0.38175892 | K16: =K15/H15-1 -> 0.2622714 | L16: =L15/I15-1 -> 0.31855853 | M16: =M15/J15-1 -> 0.26121296 | N16: =N15/K15-1 -> 0.30450851 | O16: =O15/L15-1 -> 0.28313565 | P16: =P15/M15-1 -> 0.25576302 | ... AV16: =AV15/AS15-1 -> 0.087430324
A18: Total_COGS | B18: Cost of food and packaging | C18: A$m | F18: =Assumptions!F208 -> -44.2 | G18: =Assumptions!G208 -> -32.9 | H18: =Assumptions!H208 -> -37.5 | I18: =Assumptions!I208 -> -70.4 | J18: =Assumptions!J208 -> -43.2 | K18: =Assumptions!K208 -> -44.38 | L18: =Assumptions!L208 -> -87.58 | M18: =Assumptions!M208 -> -55.071 | N18: =Assumptions!N208 -> -58.877 | O18: =+M18+N18 -> -113.948 | P18: -74.560761 | Q18: -83.228511 | R18: =+P18+Q18 -> -157.78927 | S18: -90.509341 | T18: -101.37453 | U18: =+S18+T18 -> -191.88387 | V18: -110.54825 | W18: -122.53885 | X18: =+V18+W18 -> -233.0871 | Y18: -130.43738 | Z18: -143.82866 | AA18: =+Y18+Z18 -> -274.26604 | AB18: -151.42874 | AC18: -165.47742 | AD18: =+AB18+AC18 -> -316.90616 | AE18: -173.50019 | AF18: -189.09403 | AG18: =+AE18+AF18 -> -362.59422 | AH18: -197.40082 | AI18: -214.66039 | AJ18: =+AH18+AI18 -> -412.06122 | AK18: -223.25829 | AL18: -242.31212 | AM18: =+AK18+AL18 -> -465.5704 | AN18: -246.21344 | AO18: -265.79388 | AP18: =+AN18+AO18 -> -512.00732 | AQ18: -268.41787 | AR18: -289.43619 | AS18: =+AQ18+AR18 -> -557.85407 | AT18: -291.73876 | AU18: -314.26401 | AV18: =+AT18+AU18 -> -606.00277
B19: % change | C19: % | I19: =I18/F18-1 -> 0.59276018 | J19: =J18/G18-1 -> 0.31306991 | K19: =K18/H18-1 -> 0.18346667 | L19: =L18/I18-1 -> 0.24403409 | M19: =M18/J18-1 -> 0.27479167 | N19: =N18/K18-1 -> 0.32665615 | O19: =O18/L18-1 -> 0.3010733 | P19: =P18/M18-1 -> 0.35390243 | ... AV19: =AV18/AS18-1 -> 0.086310575
B21: Gross Profit | C21: A$m | F21: =F15+F18 -> 140.9 | G21: =G15+G18 -> 97.4925 | H21: =H15+H18 -> 108.9075 | I21: =I15+I18 -> 206.4 | J21: =J15+J18 -> 136.971 | K21: =K15+K18 -> 140.426 | L21: =L15+L18 -> 277.397 | M21: =M15+M18 -> 172.163 | ... AV21: =AV15+AV18 -> 1776.756
B22: % change | C22: % | I22: =I21/F21-1 -> 0.4648687 | J22: =J21/G21-1 -> 0.40493884 | K22: =K21/H21-1 -> 0.28940615 | L22: =L21/I21-1 -> 0.34397771 | M22: =M21/J21-1 -> 0.2569303 | N22: =N21/K21-1 -> 0.29750901 | O22: =O21/L21-1 -> 0.27747236 | P22: =P21/M21-1 -> 0.22437046 | ... AV22: =AV21/AS21-1 -> 0.087812768
B23: % margin | C23: % | I23: =+I21/I15 -> 0.74566474 | J23: =+J21/J15 -> 0.76022778 | K23: =+K21/K15 -> 0.75985628 | L23: =+L21/L15 -> 0.76003967 | M23: =+M21/M15 -> 0.7576463 | N23: =+N21/N15 -> 0.75577918 | O23: =+O21/O15 -> 0.75668514 | P23: =+P21/P15 -> 0.73870606 | ... AV23: =+AV21/AV15 -> 0.74567179
A25: Total_OpEx | B25: Total OPEX | C25: A$m | F25: =+Assumptions!F211+Assumptions!F214+Assumptions!F217+Assumptions!F220 -> -119.3 | G25: =+Assumptions!G211+Assumptions!G214+Assumptions!G217+Assumptions!G220 -> -82.9 | H25: =+Assumptions!H211+Assumptions!H214+Assumptions!H217+Assumptions!H220 -> -94.2 | I25: =+Assumptions!I211+Assumptions!I214+Assumptions!I217+Assumptions!I220 -> -177.1 | J25: =+Assumptions!J211+Assumptions!J214+Assumptions!J217+Assumptions!J220 -> -111.4 | K25: =+Assumptions!K211+Assumptions!K214+Assumptions!K217+Assumptions!K220 -> -121.238 | L25: =+Assumptions!L211+Assumptions!L214+Assumptions!L217+Assumptions!L220 -> -232.638 | M25: =+Assumptions!M211+Assumptions!M214+Assumptions!M217+Assumptions!M220 -> -140.481 | ... O25: =+Assumptions!O211+Assumptions!O214+Assumptions!O217+Assumptions!O220 -> -288.939 | P25: =+P29-P21 -> -170.2608 | Q25: =+Q29-Q21 -> -184.09856 | R25: =+R29-R21 -> -354.5142 | S25: =+S29-S21 -> -195.6952 | T25: =+T29-T21 -> -211.56317 | U25: =+U29-U21 -> -407.48803 | V25: =+V29-V21 -> -227.18235 | W25: =+W29-W21 -> -246.63372 | ... AV25: =+AV29-AV21 -> -1138.4828
B26: % change | I26: =I25/F25-1 -> 0.48449288 | J26: =J25/G25-1 -> 0.3437877 | K26: =K25/H25-1 -> 0.2870276 | L26: =L25/I25-1 -> 0.31359684 | M26: =M25/J25-1 -> 0.26105027 | N26: =N25/K25-1 -> 0.22451707 | O26: =O25/L25-1 -> 0.24201119 | P26: =P25/M25-1 -> 0.21198454 | ... AV26: =AV25/AS25-1 -> 0.083778392
A29: EBITDA_Normalised | B29: EBITDA (normalised) | C29: A$m | F29: =+F21+F25 -> 21.6 | G29: =+G21+G25 -> 14.5925 | H29: =+H21+H25 -> 14.7075 | I29: =+I21+I25 -> 29.3 | J29: =+J21+J25 -> 25.571 | K29: =+K21+K25 -> 19.188 | L29: =+L21+L25 -> 44.759 | M29: =+M21+M25 -> 31.682 | ... O29: =+O21+O25 -> 65.428 | P29: =+Assumptions!P285 -> 40.530492 | Q29: =+Assumptions!Q285 -> 44.821949 | R29: =+Assumptions!R285 -> 85.352441 | S29: =+Assumptions!S285 -> 57.927654 | T29: =+Assumptions!T285 -> 67.761302 | U29: =+Assumptions!U285 -> 125.68896 | V29: =+Assumptions!V285 -> 84.192956 | W29: =+Assumptions!W285 -> 87.544088 | ... AV29: =+Assumptions!AV285 -> 638.27316
B30: % change | I30: =I29/F29-1 -> 0.35648148 | J30: =J29/G29-1 -> 0.75233853 | K30: =K29/H29-1 -> 0.30464049 | L30: =L29/I29-1 -> 0.52761092 | M30: =M29/J29-1 -> 0.23898166 | N30: =N29/K29-1 -> 0.75870336 | O30: =O29/L29-1 -> 0.46178422 | P30: =P29/M29-1 -> 0.27929084 | ... AV30: =AV29/AS29-1 -> 0.095083918
B31: % margin | I31: =I29/I$15 -> 0.1058526 | J31: =J29/J$15 -> 0.14192628 | K31: =K29/K$15 -> 0.1038278 | L31: =L29/L$15 -> 0.12263512 | M31: =M29/M$15 -> 0.13942456 | N31: =N29/N$15 -> 0.13997785 | O31: =O29/O$15 -> 0.13970938 | P31: =P29/P$15 -> 0.1420368 | ... AV31: =AV29/AV$15 -> 0.2678715
B33: Depreciation | C33: A$m | F33: =-Assumptions!F341+Assumptions!F357 -> -12 | G33: =-Assumptions!G341+Assumptions!G357 -> -9.35 | H33: =-Assumptions!H341+Assumptions!H357 -> -9.35 | I33: =-Assumptions!I341+Assumptions!I357 -> -18.7 | J33: =-Assumptions!J341 -> -6.48 | K33: =-Assumptions!K341+Assumptions!K357 -> -12.1035 | L33: =-Assumptions!L341+Assumptions!L357 -> -24.207 | M33: =-Assumptions!M341+Assumptions!M357 -> -15.575 | N33: =-Assumptions!N341+Assumptions!N357 -> -17.595 | O33: =-Assumptions!O341+Assumptions!O357 -> -33.17 | P33: =-Assumptions!P341+Assumptions!P357 -> -20.026861 | Q33: =-Assumptions!Q341+Assumptions!Q357 -> -21.26085 | R33: =-Assumptions!R341+Assumptions!R357 -> -41.287711 | ... AV33: =-Assumptions!AV341+Assumptions!AV357 -> -145.39073
B34: Amortisation | C34: A$m | F34: =Assumptions!F371 -> -2.4 | G34: =Assumptions!G371 -> -3.2 | H34: =Assumptions!H371 -> -3.6 | I34: =Assumptions!I371 -> -6.8 | J34: =Assumptions!J371 -> -3.8 | K34: =Assumptions!K371 -> -3.116 | L34: =Assumptions!L371 -> -6.916 | M34: =Assumptions!M371 -> -3.505 | ... AV34: =Assumptions!AV371 -> -18.821343
A35: Total_D&A | B35: D&A | C35: A$m | F35: =+F33+F34 -> -14.4 | G35: =+G33+G34 -> -12.55 | H35: =+H33+H34 -> -12.95 | I35: =+I33+I34 -> -25.5 | J35: =+J33+J34 -> -10.28 | K35: =+K33+K34 -> -15.2195 | L35: =+L33+L34 -> -31.123 | M35: =+M33+M34 -> -19.08 | ... AV35: =+AV33+AV34 -> -164.21207
A38: Total_EBIT | B38: EBIT | C38: A$m | F38: =+F29+F35 -> 7.2 | G38: =+G29+G35 -> 2.0425 | H38: =+H29+H35 -> 1.7575 | I38: =+I29+I35 -> 3.8 | J38: =+J29+J35 -> 15.291 | K38: =+K29+K35 -> 3.9685 | L38: =+L29+L35 -> 13.636 | M38: =+M29+M35 -> 12.602 | ... AV38: =+AV29+AV35 -> 474.06108
B39: % change | I39: =I38/F38-1 -> -0.47222222 | J39: =J38/G38-1 -> 6.4864137 | K39: =K38/H38-1 -> 1.258037 | L39: =L38/I38-1 -> 2.5884211 | M39: =M38/J38-1 -> -0.17585508 | N39: =N38/K38-1 -> 2.3123346 | O39: =O38/L38-1 -> 0.88816368 | P39: =P38/M38-1 -> 0.3406151 | ... AV39: =AV38/AS38-1 -> 0.10324529
A40: Total_EBIT_margin | B40: % margin | I40: =I38/I$15 -> 0.013728324 | J40: =J38/J$15 -> 0.084869374 | K40: =K38/K$15 -> 0.02147387 | L40: =L38/L$15 -> 0.037361258 | M40: =M38/M$15 -> 0.05545825 | N40: =N38/N$15 -> 0.054525243 | O40: =O38/O$15 -> 0.054977953 | P40: =P38/P$15 -> 0.059205572 | ... AV40: =AV38/AV$15 -> 0.19895471
B42: Finance income | C42: A$m | F42: =+Assumptions!F472 -> 4.4 | G42: =+Assumptions!G472 -> 0 | H42: =+Assumptions!H472 -> 0 | I42: =+Assumptions!I472 -> 12.4 | J42: =+Assumptions!J472 -> 8.1705 | K42: =+Assumptions!K472 -> 8.1705 | L42: =+Assumptions!L472 -> 16.341 | M42: =+Assumptions!M472 -> 11.445 | ... AV42: =+Assumptions!AV472 -> 43.379628
B43: Finance costs | C43: A$m | F43: =+Assumptions!F473 -> -6 | G43: =+Assumptions!G473 -> 0 | H43: =+Assumptions!H473 -> 0 | I43: =+Assumptions!I473 -> -8.5 | J43: =+Assumptions!J473 -> -6.862 | K43: =+Assumptions!K473 -> -6.862 | L43: =+Assumptions!L473 -> -13.724 | M43: =+Assumptions!M473 -> -8.752 | ... AV43: =+Assumptions!AV473 -> -38.591694
A44: Total_Net_Int | B44: Net interest expense | C44: A$m | F44: =+F42+F43 -> -1.6 | G44: =+G42+G43 -> 0 | H44: =+H42+H43 -> 0 | I44: =+I42+I43 -> 3.9 | J44: =+J42+J43 -> 1.3085 | K44: =+K42+K43 -> 1.3085 | L44: =+L42+L43 -> 2.617 | M44: =+M42+M43 -> 2.693 | ... AV44: =+AV42+AV43 -> 4.7879344
A47: PBT | B47: Profit before tax | C47: A$m | F47: =F38+F44 -> 5.6 | G47: =G38+G44 -> 2.0425 | H47: =H38+H44 -> 1.7575 | I47: =I38+I44 -> 7.7 | J47: =J38+J44 -> 16.5995 | K47: =K38+K44 -> 5.277 | L47: =L38+L44 -> 16.253 | M47: =M38+M44 -> 15.295 | ... AV47: =AV38+AV44 -> 478.84902
A50: Tax_expense | B50: Income tax expense | C50: A$m | F50: =Assumptions!F307 -> -2.4 | G50: =Assumptions!G307 -> -2.3 | H50: =Assumptions!H307 -> -2.4 | I50: =Assumptions!I307 -> -4.7 | J50: =Assumptions!J307 -> -6.2 | K50: =Assumptions!K307 -> -4.4 | L50: =Assumptions!L307 -> -10.6 | M50: =Assumptions!M307 -> -7.9 | ... AV50: =Assumptions!AV307 -> -139.60805
A54: NPAT_underlying | B54: NPAT (underlying) | C54: A$m | F54: =F47+F50 -> 3.2 | G54: =G47+G50 -> -0.2575 | H54: =H47+H50 -> -0.6425 | I54: =I47+I50 -> 3 | J54: =J47+J50 -> 10.3995 | K54: =K47+K50 -> 0.877 | L54: =L47+L50 -> 5.653 | M54: =M47+M50 -> 7.395 | ... AV54: =AV47+AV50 -> 339.24097
A55: NRI_post_tax | B55: NRI (post tax) | C55: A$m | F55: =+F56-F54 -> 0.7 | G55: =+G56-G54 -> 1.1575 | H55: =+H56-H54 -> -2.5575 | I55: =+I56-I54 -> -5.3 | J55: =+J56-J54 -> -6.5995 | K55: =+K56-K54 -> -18.425 | L55: =+L56-L54 -> -19.401 | M55: =+M56-M54 -> -0.094 | ... O55: =+O56-O54 -> -0.343 | P55: 0 | Q55: =+P55 -> 0 | R55: =+Q55 -> 0 | S55: =+R55 -> 0 | T55: =+S55 -> 0 | U55: =+T55 -> 0 | V55: =+U55 -> 0 | W55: =+V55 -> 0 | X55: =+W55 -> 0 | ... AV55: =+AU55 -> 0
A56: NPAT_reported | B56: NPAT (reported) | C56: A$m | F56: 3.9 | G56: 0.9 | H56: =+I56-G56 -> -3.2 | I56: -2.3 | J56: 3.8 | K56: =+L56-J56 -> -17.548 | L56: -13.748 | M56: 7.301 | N56: =+O56-M56 -> 7.175 | O56: 14.476 | P56: =+P54+P55 -> 9.794725 | Q56: =+Q54+Q55 -> 11.686408 | R56: =+R54+R55 -> 21.481133 | S56: =+S54+S55 -> 18.267106 | T56: =+T54+T55 -> 24.008881 | U56: =+U54+U55 -> 42.275987 | V56: =+V54+V55 -> 32.066723 | W56: =+W54+W55 -> 33.149166 | ... AV56: =+AV54+AV55 -> 339.24097
B58: Underlying EPS (Basic) | C58: c | I58: =(I54/I63)*100 -> 2.9599544 | J58: =(J54/J63)*100 -> 10.260682 | K58: =+L58-J58 -> -4.6831411 | L58: =(L54/L63)*100 -> 5.5775407 | M58: =(M54/M63)*100 -> 7.2901496 | N58: =(N54/N63)*100 -> 6.9948893 | O58: =(O54/O63)*100 -> 14.598618 | P58: =(P54/P63)*100 -> 9.6490621 | Q58: =(Q54/Q63)*100 -> 11.512612 | R58: =(R54/R63)*100 -> 21.161674 | S58: =(S54/S63)*100 -> 17.995445 | ... AV58: =(AV54/AV63)*100 -> 334.19592
A59: EPS_underlying_diluted | B59: Underlying EPS (Diluted) (Modelware) | C59: c | I59: =(I54/I64)*100 -> 2.9599544 | J59: =(J54/J64)*100 -> 10.260682 | K59: =+L59-J59 -> -5.1923913 | L59: =(L54/L64)*100 -> 5.0682905 | M59: =(M54/M64)*100 -> 6.9675656 | N59: =(N54/N64)*100 -> 6.9948893 | O59: =(O54/O64)*100 -> 13.992731 | P59: =(P54/P64)*100 -> 9.2485967 | Q59: =(Q54/Q64)*100 -> 11.034804 | R59: =(R54/R64)*100 -> 20.283401 | S59: =(S54/S64)*100 -> 17.24858 | ... AV59: =(AV54/AV64)*100 -> 320.32578
B60: Reported EPS (Basic) | C60: c | I60: =(+I56/I63)*100 -> -2.2692983 | J60: =(+J56/J63)*100 -> 3.7492755 | K60: =+L60-J60 -> -17.31376 | L60: =(+L56/L63)*100 -> -13.564484 | M60: =(+M56/M63)*100 -> 7.1974824 | N60: =(+N56/N63)*100 -> 6.7602817 | O60: =(+O56/O63)*100 -> 14.260719 | P60: =(+P56/P63)*100 -> 9.6490621 | Q60: =(+Q56/Q63)*100 -> 11.512612 | R60: =(+R56/R63)*100 -> 21.161674 | S60: =(+S56/S63)*100 -> 17.995445 | ... AV60: =(+AV56/AV63)*100 -> 334.19592
...

Sheet Assumptions
B2: Guzman Y Gomez (GYG.AX)
B3: Assumptions
F4: Pro forma | G4: Pro forma | H4: Pro forma | I4: Pro forma | J4: Pro forma
B5: Year ended 30 June | C5: unit | D5: FY20 | E5: FY21 | F5: FY22 | G5: 1H23 | H5: 2H23 | I5: FY23 | J5: 1H24 | K5: 2H24 | L5: FY24 | M5: 1H25 | N5: 2H25 | O5: FY25 | P5: 1H26e | Q5: 2H26e | R5: FY26e | S5: 1H27e | T5: 2H27e | U5: FY27e | V5: 1H28e | W5: 2H28e | X5: FY28e | Y5: 1H29e | Z5: 2H29e | AA5: FY29e | AB5: 1H30e | AC5: 2H30e | AD5: FY30e | AE5: 1H31e | AF5: 2H31e | AG5: FY31e | AH5: 1H32e | AI5: 2H32e | AJ5: FY32e | AK5: 1H33e | AL5: 2H33e | AM5: FY33e | AN5: 1H34e | AO5: 2H34e | AP5: FY34e | AQ5: 1H35e | AR5: 2H35e | AS5: FY35e | AT5: 1H36e | AU5: 2H36e | AV5: FY36e
A7: l | B7: Summary
B9: Network Sales
B10: Aust (Corp + Franchise) | C10: A$m | F10: 535.4 | G10: 334.9 | H10: =I10-G10 -> 368 | I10: 702.9 | J10: 438.6 | K10: =L10-J10 -> 456 | L10: 894.6 | M10: 538.2 | N10: =O10-M10 -> 556.4 | O10: 1094.6 | P10: =+P68+P89 -> 636.45455 | Q10: =+Q68+Q89 -> 678.15481 | R10: =+R68+R89 -> 1314.6094 | S10: =+S68+S89 -> 750.19698 | T10: =+T68+T89 -> 823.67023 | U10: =+U68+U89 -> 1573.8672 | V10: =+V68+V89 -> 895.52982 | W10: =+W68+W89 -> 983.49275 | ... AV10: =+AV68+AV89 -> 4976.458 | BF10: =(AD10/O10)^(1/5)-1 -> 0.18870886
