Workbook

Sheet Value
B2: Valuation | C2: AFG.AX
I3: DDM | J3: Units
C4: Current Price = | D4: 2.35 | I4: Risk Free Rate | J4: % | K4: 0.04 | M4: 0.04
C5: Shares Outstanding = | D5: #VALUE! | I5: Beta | J5: x | K5: 1.2
C6: AS51 Index | I6: Market Premium | J6: % | K6: 0.06
C7: TARGET Relative Forward PE | I7: Ke | J7: % | K7: =K4+K5*K6 -> 0.112
C8: TARGET Forward PE | I8: ROE | J8: % p.a. | K8: 0.2
C9: PE Price Target = | E9: #VALUE! | I9: LT Payout Ratio | J9: % p.a. | K9: 0.7
I10: LT growth rate | J10: % p.a. | K10: =(1-K9)*K8 -> 0.06
J11: Dividend Discount Model | K11: =Annual!D308 -> 4.1462997 | L11: =K11/D4-1 -> 0.76438285 | N11: 4.1559
J12: SOTP | N12: =N11-K11 -> 0.0096002524
N13: =N12*E27 -> 2.5997483
B14: Notes | C14: Units | I14: Implied 12M PE Ratio | J14: x
B15: Actual Values | C15: 1000 | D15: (hard coded) | I15: Implied12M EV/EBITDA Ratio | J15: x
B16: Formula | C16: 1000 | I16: EV- market
B17: Manual entry (assumption) | C17: 1000 | D17: (usually from guidance given by management) | I17: ND/EV
C19: Actual ---> | E19: Forecast ----->
C20: 2024 | D20: 2025 | E20: 2026 | F20: 2027 | G20: 2028 | J20: Actual ---> | L20: Forecast -----> | Q20: Actual ---> | S20: Forecast ----->
B21: PE | J21: 2024 | K21: 2025 | L21: 2026 | M21: 2027 | N21: 2028 | Q21: 2024 | R21: 2025 | S21: 2026 | T21: 2027 | U21: 2028
B22: Consensus | D22: =$D$4/D28 -> 18.182286 | E22: =$D$4/E28 -> 14.110421 | F22: =$D$4/F28 -> 12.226321 | G22: =$D$4/G28 -> 11.048264 | I22: NPAT(AUDm) | P22: EBITDA (AUDm)
B23: Blackwattle | D23: =$D$4/D29 -> 18.518 | E23: =$D$4/E29 -> 13.262767 | F23: =$D$4/F29 -> 11.518222 | G23: =$D$4/G29 -> 10.187802 | I23: Consensus | K23: ='Vs cons'!E12 -> 35 | L23: ='Vs cons'!F12 -> 45.1 | M23: ='Vs cons'!G12 -> 52.05 | N23: ='Vs cons'!H12 -> 57.6 | P23: Consensus | R23: ='Vs cons'!E24 -> 55.25 | S23: ='Vs cons'!F24 -> 73.1 | T23: ='Vs cons'!G24 -> 83.7 | U23: ='Vs cons'!H24 -> 91.65
B24: Difference | E24: =E23/E22 -> 0.93992708 | H24: =Annual!A90 -> Statutory NPAT | I24: Blackwattle | J24: =INDEX(Annual!$A:$Y,MATCH(Value!$H24,Annual!$A:$A,0),MATCH(Value!J$21,Annual!$A$1:$Y$1,0)) -> 29 | K24: =INDEX(Annual!$A:$Y,MATCH(Value!$H24,Annual!$A:$A,0),MATCH(Value!K$21,Annual!$A$1:$Y$1,0)) -> 35 | L24: =INDEX(Annual!$A:$Y,MATCH(Value!$H24,Annual!$A:$A,0),MATCH(Value!L$21,Annual!$A$1:$Y$1,0)) -> 48.868385 | M24: =INDEX(Annual!$A:$Y,MATCH(Value!$H24,Annual!$A:$A,0),MATCH(Value!M$21,Annual!$A$1:$Y$1,0)) -> 56.269968 | N24: =INDEX(Annual!$A:$Y,MATCH(Value!$H24,Annual!$A:$A,0),MATCH(Value!N$21,Annual!$A$1:$Y$1,0)) -> 63.618239 | O24: EBITDA-Underlying EBITDA | P24: Blackwattle | Q24: =INDEX(Annual!$A:$Y,MATCH($O24,Annual!$A:$A,0),MATCH(Value!Q$21,Annual!$A$1:$Y$1,0)) -> 47.4 | R24: =INDEX(Annual!$A:$Y,MATCH($O24,Annual!$A:$A,0),MATCH(Value!R$21,Annual!$A$1:$Y$1,0)) -> 56.2 | S24: =INDEX(Annual!$A:$Y,MATCH($O24,Annual!$A:$A,0),MATCH(Value!S$21,Annual!$A$1:$Y$1,0)) -> 80.14594 | T24: =INDEX(Annual!$A:$Y,MATCH($O24,Annual!$A:$A,0),MATCH(Value!T$21,Annual!$A$1:$Y$1,0)) -> 93.116027 | U24: =INDEX(Annual!$A:$Y,MATCH($O24,Annual!$A:$A,0),MATCH(Value!U$21,Annual!$A$1:$Y$1,0)) -> 106.2139
I25: Difference | K25: =K24/K23-1 -> 0 | L25: =L24/L23-1 -> 0.083556201 | M25: =M24/M23-1 -> 0.081075265 | N25: =N24/N23-1 -> 0.10448331 | P25: Difference | R25: =R24/R23-1 -> 0.01719457 | S25: =S24/S23-1 -> 0.096387688 | T25: =T24/T23-1 -> 0.11249733 | U25: =U24/U23-1 -> 0.15890781
B26: EPS (Acps) | R26: =R23-R28 -> -64.75 | S26: =S23-S28 -> -63.3 | T26: =T23-T28 -> -67
A27: YE Basic Shares Outstanding | B27: Shares Outstanding | C27: =INDEX(Annual!$A:$Y,MATCH($A27,Annual!$A:$A,0),MATCH(C$20,Annual!$A$1:$Y$1,0)) -> 270.8 | D27: =INDEX(Annual!$A:$Y,MATCH($A27,Annual!$A:$A,0),MATCH(D$20,Annual!$A$1:$Y$1,0)) -> 270.8 | E27: =INDEX(Annual!$A:$Y,MATCH($A27,Annual!$A:$A,0),MATCH(E$20,Annual!$A$1:$Y$1,0)) -> 270.8 | F27: =INDEX(Annual!$A:$Y,MATCH($A27,Annual!$A:$A,0),MATCH(F$20,Annual!$A$1:$Y$1,0)) -> 270.8 | G27: =INDEX(Annual!$A:$Y,MATCH($A27,Annual!$A:$A,0),MATCH(G$20,Annual!$A$1:$Y$1,0)) -> 270.8 | I27: PBT (AUDm) | P27: GP (AUDm) | R27: =R24-R29 -> -63.8 | S27: =S24-S29 -> -65.287351 | T27: =T24-T29 -> -72.228102
B28: Consensus | D28: =K23/D27 -> 0.12924668 | E28: =L23/E27 -> 0.16654357 | F28: =M23/F27 -> 0.19220827 | G28: =N23/G27 -> 0.2127031 | I28: Consensus | P28: Consensus | R28: ='Vs cons'!E29 -> 120 | S28: ='Vs cons'!F29 -> 136.4 | T28: ='Vs cons'!G29 -> 150.7 | U28: ='Vs cons'!H29 -> 161.9
A29: EPS | B29: Blackwattle | C29: =INDEX(Annual!$A:$Y,MATCH($A29,Annual!$A:$A,0),MATCH(C$20,Annual!$A$1:$Y$1,0)) -> 0.1058008 | D29: =INDEX(Annual!$A:$Y,MATCH($A29,Annual!$A:$A,0),MATCH(D$20,Annual!$A$1:$Y$1,0)) -> 0.12690355 | E29: =INDEX(Annual!$A:$Y,MATCH($A29,Annual!$A:$A,0),MATCH(E$20,Annual!$A$1:$Y$1,0)) -> 0.17718776 | F29: =INDEX(Annual!$A:$Y,MATCH($A29,Annual!$A:$A,0),MATCH(F$20,Annual!$A$1:$Y$1,0)) -> 0.20402454 | G29: =INDEX(Annual!$A:$Y,MATCH($A29,Annual!$A:$A,0),MATCH(G$20,Annual!$A$1:$Y$1,0)) -> 0.23066802 | H29: PBT | I29: Blackwattle | J29: =INDEX(Annual!$A:$Y,MATCH(Value!$H29,Annual!$A:$A,0),MATCH(Value!J$21,Annual!$A$1:$Y$1,0)) -> 43.9 | K29: =INDEX(Annual!$A:$Y,MATCH(Value!$H29,Annual!$A:$A,0),MATCH(Value!K$21,Annual!$A$1:$Y$1,0)) -> 48.6 | L29: =INDEX(Annual!$A:$Y,MATCH(Value!$H29,Annual!$A:$A,0),MATCH(Value!L$21,Annual!$A$1:$Y$1,0)) -> 69.573249 | M29: =INDEX(Annual!$A:$Y,MATCH(Value!$H29,Annual!$A:$A,0),MATCH(Value!M$21,Annual!$A$1:$Y$1,0)) -> 80.11634 | N29: =INDEX(Annual!$A:$Y,MATCH(Value!$H29,Annual!$A:$A,0),MATCH(Value!N$21,Annual!$A$1:$Y$1,0)) -> 90.585207 | O29: =Annual!A19 -> GP-Gross Profit | P29: Blackwattle | Q29: =INDEX(Annual!$A:$Y,MATCH($O29,Annual!$A:$A,0),MATCH(Value!Q$21,Annual!$A$1:$Y$1,0)) -> 104.7 | R29: =INDEX(Annual!$A:$Y,MATCH($O29,Annual!$A:$A,0),MATCH(Value!R$21,Annual!$A$1:$Y$1,0)) -> 120 | S29: =INDEX(Annual!$A:$Y,MATCH($O29,Annual!$A:$A,0),MATCH(Value!S$21,Annual!$A$1:$Y$1,0)) -> 145.43329 | T29: =INDEX(Annual!$A:$Y,MATCH($O29,Annual!$A:$A,0),MATCH(Value!T$21,Annual!$A$1:$Y$1,0)) -> 165.34413 | U29: =INDEX(Annual!$A:$Y,MATCH($O29,Annual!$A:$A,0),MATCH(Value!U$21,Annual!$A$1:$Y$1,0)) -> 184.71041
B30: Difference | D30: =D29/D28-1 -> -0.018129079 | E30: =E29/E28-1 -> 0.063912325 | F30: =F29/F28-1 -> 0.061476366 | G30: =G29/G28-1 -> 0.084460046 | I30: Difference | P30: Difference | R30: =R29/R28-1 -> 0 | S30: =S29/S28-1 -> 0.066226476 | T30: =T29/T28-1 -> 0.097174044 | U30: =U29/U28-1 -> 0.14089199
B32: DPS (Acps) | I32: EBIT (AUDm) | P32: EV / EBITDA
B33: Consensus | I33: Consensus | K33: ='Vs cons'!E34 -> 44.75 | L33: ='Vs cons'!F34 -> 60.5 | M33: ='Vs cons'!G34 -> 71.1 | N33: ='Vs cons'!H34 -> 78.95 | P33: Consensus | Q33: =(INDEX(Annual!$A:$Y,MATCH($O34,Annual!$A:$A,0),MATCH(Value!Q$21,Annual!$A$1:$Y$1,0))+$D$4*C27)/Q23 -> #DIV/0! | R33: =(INDEX(Annual!$A:$Y,MATCH($O34,Annual!$A:$A,0),MATCH(Value!R$21,Annual!$A$1:$Y$1,0))+$D$4*D27)/R23 -> 11.300995 | S33: =(INDEX(Annual!$A:$Y,MATCH($O34,Annual!$A:$A,0),MATCH(Value!S$21,Annual!$A$1:$Y$1,0))+$D$4*E27)/S23 -> 8.611909 | T33: =(INDEX(Annual!$A:$Y,MATCH($O34,Annual!$A:$A,0),MATCH(Value!T$21,Annual!$A$1:$Y$1,0))+$D$4*F27)/T23 -> 7.7164297 | U33: =(INDEX(Annual!$A:$Y,MATCH($O34,Annual!$A:$A,0),MATCH(Value!U$21,Annual!$A$1:$Y$1,0))+$D$4*G27)/U23 -> 7.2280181
A34: Dividends | B34: Blackwattle | H34: EBIT | I34: Blackwattle | J34: =INDEX(Annual!$A:$Y,MATCH(Value!$H34,Annual!$A:$A,0),MATCH(Value!J$21,Annual!$A$1:$Y$1,0)) -> 40 | K34: =INDEX(Annual!$A:$Y,MATCH(Value!$H34,Annual!$A:$A,0),MATCH(Value!K$21,Annual!$A$1:$Y$1,0)) -> 45.7 | L34: =INDEX(Annual!$A:$Y,MATCH(Value!$H34,Annual!$A:$A,0),MATCH(Value!L$21,Annual!$A$1:$Y$1,0)) -> 65.879614 | M34: =INDEX(Annual!$A:$Y,MATCH(Value!$H34,Annual!$A:$A,0),MATCH(Value!M$21,Annual!$A$1:$Y$1,0)) -> 77.021133 | N34: =INDEX(Annual!$A:$Y,MATCH(Value!$H34,Annual!$A:$A,0),MATCH(Value!N$21,Annual!$A$1:$Y$1,0)) -> 88.406108 | O34: Net debt | P34: Blackwattle | Q34: =(INDEX(Annual!$A:$Y,MATCH($O34,Annual!$A:$A,0),MATCH(Value!Q$21,Annual!$A$1:$Y$1,0))+$D$4*C27)/Q24 -> 12.98903 | R34: =(INDEX(Annual!$A:$Y,MATCH($O34,Annual!$A:$A,0),MATCH(Value!R$21,Annual!$A$1:$Y$1,0))+$D$4*D27)/R24 -> 11.109964 | S34: =(INDEX(Annual!$A:$Y,MATCH($O34,Annual!$A:$A,0),MATCH(Value!S$21,Annual!$A$1:$Y$1,0))+$D$4*E27)/S24 -> 7.8548027 | T34: =(INDEX(Annual!$A:$Y,MATCH($O34,Annual!$A:$A,0),MATCH(Value!T$21,Annual!$A$1:$Y$1,0))+$D$4*F27)/T24 -> 6.9361332 | U34: =(INDEX(Annual!$A:$Y,MATCH($O34,Annual!$A:$A,0),MATCH(Value!U$21,Annual!$A$1:$Y$1,0))+$D$4*G27)/U24 -> 6.2369224
B35: Dividend Yield | I35: Difference | J35: =J34/J33-1 -> #DIV/0! | K35: =K34/K33-1 -> 0.02122905 | L35: =L34/L33-1 -> 0.088919247 | M35: =M34/M33-1 -> 0.083278946 | N35: =N34/N33-1 -> 0.11977337 | P35: Difference
B37: FY24 | C37: Consensus | D37: Blackwattle | E37: % Diff | F37: OLD | G37: % Diff
B38: EBITDA | C38: Please sign in | D38: 81 | E38: #VALUE! | G38: #DIV/0! | J38: PE | L38: EV/EBITDA | N38: EV/Sales | O38: EBITDA Growth | P38: EBITDA margin | Q38: Revenue Growth | R38: EBIT margin | S38: Rule of 40 | T38: Market Cap | U38: Dividend Yield | V38: Stock
B39: D&A | C39: #VALUE! | D39: 15 | E39: #VALUE! | G39: #DIV/0! | J39: FY1 | K39: FY2 | L39: FY1 | M39: FY2 | N39: NTM | O39: FY0-3 CAGR | P39: FY1 | Q39: 3yr CAGR | R39: FY3 | S39: FY3 | T39: AUDm | U39: NTM | V39: Code
B40: EBIT | C40: Please sign in | D40: 66 | E40: #VALUE! | G40: #DIV/0! | I40: #NAME? | J40: #NAME? | K40: #NAME? | L40: #NAME? | M40: #NAME? | N40: #NAME? | O40: #NAME? | P40: #VALUE! | Q40: #VALUE! | R40: #VALUE! | S40: #VALUE! | T40: #NAME? | U40: #NAME? | V40: AFG.AX
B41: Net Interest | C41: #VALUE! | D41: -2 | E41: #VALUE! | G41: #DIV/0!
B42: PBT | C42: Please sign in | D42: 69 | E42: #VALUE! | G42: #DIV/0! | I42: Global Cloud Services
B43: Tax | C43: #VALUE! | D43: 16 | E43: #VALUE! | G43: #DIV/0! | I43: #NAME? | J43: #NAME? | K43: #NAME? | L43: #NAME? | M43: #NAME? | N43: #NAME? | O43: #NAME? | P43: #VALUE! | Q43: #VALUE! | R43: #VALUE! | S43: #VALUE! | T43: #NAME? | U43: #NAME? | V43: PANW.O
B44: Tax Rate | C44: #VALUE! | D44: 0.24 | E44: #VALUE! | G44: #DIV/0! | I44: #NAME? | J44: #NAME? | K44: #NAME? | L44: #NAME? | M44: #NAME? | N44: #NAME? | O44: #NAME? | P44: #VALUE! | Q44: #VALUE! | R44: #VALUE! | S44: #VALUE! | T44: #NAME? | U44: #NAME? | V44: FTNT.O
...

Sheet Annual
B1: AFG Model Summary | D1: 2015 | E1: 2016 | F1: 2017 | G1: 2018 | H1: 2019 | I1: 2020 | J1: 2021 | K1: 2022 | L1: 2023 | M1: 2024 | N1: 2025 | O1: 2026 | P1: 2027 | Q1: 2028 | R1: 2029 | S1: 2030 | T1: 2031 | U1: 2032 | V1: 2033 | W1: 2034 | X1: 2035 | Z1: Earnings changes=> | AA1: 2025 | AC1: 2026 | AE1: 2027
E2: Actual ----------> | O2: Forecast -----> | AA2: Forecast -----> | AB2: Forecast -----> | AD2: Forecast -----> | AF2: Forecast ----->
C3: Units | D3: Source | E3: FY16A | F3: FY17A | G3: FY18A | H3: FY19A | I3: FY20A | J3: FY21A | K3: FY22A | L3: FY23A | M3: FY24A | N3: FY25A | O3: FY26E | P3: FY27E | Q3: FY28E | R3: FY29E | S3: FY30E | T3: FY31E | U3: FY32E | V3: FY33E | W3: FY34E | X3: FY35E | AA3: FY25E | AB3: FY24E | AC3: FY26E | AD3: FY24E | AE3: FY27E | AF3: FY24E
B4: P &L | D4: =DATE(D1,6,30) -> 42185 | E4: =DATE(E1,6,30) -> 42551 | F4: =DATE(F1,6,30) -> 42916 | G4: =DATE(G1,6,30) -> 43281 | H4: =DATE(H1,6,30) -> 43646 | I4: =DATE(I1,6,30) -> 44012 | J4: =DATE(J1,6,30) -> 44377 | K4: =DATE(K1,6,30) -> 44742 | ... X4: =DATE(X1,6,30) -> 49490
B6: Revenue | Q6: =Q9/Q7 -> 0.1056794 | R6: =R9/R7 -> 0.15990013 | S6: =S9/S7 -> 0.21711165 | T6: =T9/T7 -> 0.27829394 | U6: =U9/U7 -> 0.34259988 | V6: =V9/V7 -> 0.41024248 | W6: =W9/W7 -> 0.48144627 | X6: =X9/X7 -> 0.55644814
A7: Rev-Commission revenue and other income | B7: Commission revenue and other income | C7: AUDm | F7: 527 | G7: 551.1 | H7: 569.7 | I7: 589.3 | J7: 656.8 | K7: 820.1 | L7: 742.8 | M7: 799.2 | N7: 911.3 | O7: =INDEX(Segments!$A:$AJ,MATCH(Annual!$A7,Segments!$A:$A,0),MATCH("1H"&RIGHT(Annual!O$1,2),Segments!$A$3:$AJ$3,0))+INDEX(Segments!$A:$AJ,MATCH(Annual!$A7,Segments!$A:$A,0),MATCH("2H"&RIGHT(Annual!O$1,2),Segments!$A$3:$AJ$3,0)) -> 1066.3765 | P7: =INDEX(Segments!$A:$AJ,MATCH(Annual!$A7,Segments!$A:$A,0),MATCH("1H"&RIGHT(Annual!P$1,2),Segments!$A$3:$AJ$3,0))+INDEX(Segments!$A:$AJ,MATCH(Annual!$A7,Segments!$A:$A,0),MATCH("2H"&RIGHT(Annual!P$1,2),Segments!$A$3:$AJ$3,0)) -> 1176.6975 | Q7: =INDEX(Segments!$A:$AJ,MATCH(Annual!$A7,Segments!$A:$A,0),MATCH("1H"&RIGHT(Annual!Q$1,2),Segments!$A$3:$AJ$3,0))+INDEX(Segments!$A:$AJ,MATCH(Annual!$A7,Segments!$A:$A,0),MATCH("2H"&RIGHT(Annual!Q$1,2),Segments!$A$3:$AJ$3,0)) -> 1257.0466 | R7: =INDEX(Segments!$A:$AJ,MATCH(Annual!$A7,Segments!$A:$A,0),MATCH("1H"&RIGHT(Annual!R$1,2),Segments!$A$3:$AJ$3,0))+INDEX(Segments!$A:$AJ,MATCH(Annual!$A7,Segments!$A:$A,0),MATCH("2H"&RIGHT(Annual!R$1,2),Segments!$A$3:$AJ$3,0)) -> 1341.2374 | S7: =INDEX(Segments!$A:$AJ,MATCH(Annual!$A7,Segments!$A:$A,0),MATCH("1H"&RIGHT(Annual!S$1,2),Segments!$A$3:$AJ$3,0))+INDEX(Segments!$A:$AJ,MATCH(Annual!$A7,Segments!$A:$A,0),MATCH("2H"&RIGHT(Annual!S$1,2),Segments!$A$3:$AJ$3,0)) -> 1431.7949 | T7: =INDEX(Segments!$A:$AJ,MATCH(Annual!$A7,Segments!$A:$A,0),MATCH("1H"&RIGHT(Annual!T$1,2),Segments!$A$3:$AJ$3,0))+INDEX(Segments!$A:$AJ,MATCH(Annual!$A7,Segments!$A:$A,0),MATCH("2H"&RIGHT(Annual!T$1,2),Segments!$A$3:$AJ$3,0)) -> 1517.7026 | U7: =INDEX(Segments!$A:$AJ,MATCH(Annual!$A7,Segments!$A:$A,0),MATCH("1H"&RIGHT(Annual!U$1,2),Segments!$A$3:$AJ$3,0))+INDEX(Segments!$A:$AJ,MATCH(Annual!$A7,Segments!$A:$A,0),MATCH("2H"&RIGHT(Annual!U$1,2),Segments!$A$3:$AJ$3,0)) -> 1608.7648 | V7: =INDEX(Segments!$A:$AJ,MATCH(Annual!$A7,Segments!$A:$A,0),MATCH("1H"&RIGHT(Annual!V$1,2),Segments!$A$3:$AJ$3,0))+INDEX(Segments!$A:$AJ,MATCH(Annual!$A7,Segments!$A:$A,0),MATCH("2H"&RIGHT(Annual!V$1,2),Segments!$A$3:$AJ$3,0)) -> 1705.2907 | ... X7: =INDEX(Segments!$A:$AJ,MATCH(Annual!$A7,Segments!$A:$A,0),MATCH("1H"&RIGHT(Annual!X$1,2),Segments!$A$3:$AJ$3,0))+INDEX(Segments!$A:$AJ,MATCH(Annual!$A7,Segments!$A:$A,0),MATCH("2H"&RIGHT(Annual!X$1,2),Segments!$A$3:$AJ$3,0)) -> 1916.0646 | AA7: 90.2 | AB7: 821.1 | AC7: 127.4 | AD7: 958.6 | AE7: 155.1 | AF7: 1043.2
A8: Rev-Securitisation interest income | B8: Securitisation interest income | C8: AUDm | F8: 46.3 | G8: 52.3 | H8: 73.1 | I8: 85.7 | J8: 90.2 | K8: 108.8 | L8: 260 | M8: 278.6 | N8: 324.2 | O8: =INDEX(Segments!$A:$AJ,MATCH(Annual!$A8,Segments!$A:$A,0),MATCH("1H"&RIGHT(Annual!O$1,2),Segments!$A$3:$AJ$3,0))+INDEX(Segments!$A:$AJ,MATCH(Annual!$A8,Segments!$A:$A,0),MATCH("2H"&RIGHT(Annual!O$1,2),Segments!$A$3:$AJ$3,0)) -> 386.7516 | P8: =INDEX(Segments!$A:$AJ,MATCH(Annual!$A8,Segments!$A:$A,0),MATCH("1H"&RIGHT(Annual!P$1,2),Segments!$A$3:$AJ$3,0))+INDEX(Segments!$A:$AJ,MATCH(Annual!$A8,Segments!$A:$A,0),MATCH("2H"&RIGHT(Annual!P$1,2),Segments!$A$3:$AJ$3,0)) -> 425.42676 | Q8: =INDEX(Segments!$A:$AJ,MATCH(Annual!$A8,Segments!$A:$A,0),MATCH("1H"&RIGHT(Annual!Q$1,2),Segments!$A$3:$AJ$3,0))+INDEX(Segments!$A:$AJ,MATCH(Annual!$A8,Segments!$A:$A,0),MATCH("2H"&RIGHT(Annual!Q$1,2),Segments!$A$3:$AJ$3,0)) -> 450.95237 | R8: =INDEX(Segments!$A:$AJ,MATCH(Annual!$A8,Segments!$A:$A,0),MATCH("1H"&RIGHT(Annual!R$1,2),Segments!$A$3:$AJ$3,0))+INDEX(Segments!$A:$AJ,MATCH(Annual!$A8,Segments!$A:$A,0),MATCH("2H"&RIGHT(Annual!R$1,2),Segments!$A$3:$AJ$3,0)) -> 478.00951 | S8: =INDEX(Segments!$A:$AJ,MATCH(Annual!$A8,Segments!$A:$A,0),MATCH("1H"&RIGHT(Annual!S$1,2),Segments!$A$3:$AJ$3,0))+INDEX(Segments!$A:$AJ,MATCH(Annual!$A8,Segments!$A:$A,0),MATCH("2H"&RIGHT(Annual!S$1,2),Segments!$A$3:$AJ$3,0)) -> 506.69008 | T8: =INDEX(Segments!$A:$AJ,MATCH(Annual!$A8,Segments!$A:$A,0),MATCH("1H"&RIGHT(Annual!T$1,2),Segments!$A$3:$AJ$3,0))+INDEX(Segments!$A:$AJ,MATCH(Annual!$A8,Segments!$A:$A,0),MATCH("2H"&RIGHT(Annual!T$1,2),Segments!$A$3:$AJ$3,0)) -> 537.09148 | U8: =INDEX(Segments!$A:$AJ,MATCH(Annual!$A8,Segments!$A:$A,0),MATCH("1H"&RIGHT(Annual!U$1,2),Segments!$A$3:$AJ$3,0))+INDEX(Segments!$A:$AJ,MATCH(Annual!$A8,Segments!$A:$A,0),MATCH("2H"&RIGHT(Annual!U$1,2),Segments!$A$3:$AJ$3,0)) -> 569.31697 | V8: =INDEX(Segments!$A:$AJ,MATCH(Annual!$A8,Segments!$A:$A,0),MATCH("1H"&RIGHT(Annual!V$1,2),Segments!$A$3:$AJ$3,0))+INDEX(Segments!$A:$AJ,MATCH(Annual!$A8,Segments!$A:$A,0),MATCH("2H"&RIGHT(Annual!V$1,2),Segments!$A$3:$AJ$3,0)) -> 603.47599 | ... X8: =INDEX(Segments!$A:$AJ,MATCH(Annual!$A8,Segments!$A:$A,0),MATCH("1H"&RIGHT(Annual!X$1,2),Segments!$A$3:$AJ$3,0))+INDEX(Segments!$A:$AJ,MATCH(Annual!$A8,Segments!$A:$A,0),MATCH("2H"&RIGHT(Annual!X$1,2),Segments!$A$3:$AJ$3,0)) -> 678.06562 | AA8: 26.4 | AB8: 297.8 | AC8: 31.6 | AD8: 357.4 | AE8: 39.5 | AF8: 388.4
A9: Rev-Other | B9: Other | C9: AUDm | D9: AR | O9: =INDEX(Segments!$A:$AJ,MATCH(Annual!$A9,Segments!$A:$A,0),MATCH("1H"&RIGHT(Annual!O$1,2),Segments!$A$3:$AJ$3,0))+INDEX(Segments!$A:$AJ,MATCH(Annual!$A9,Segments!$A:$A,0),MATCH("2H"&RIGHT(Annual!O$1,2),Segments!$A$3:$AJ$3,0)) -> 21.623033 | P9: =INDEX(Segments!$A:$AJ,MATCH(Annual!$A9,Segments!$A:$A,0),MATCH("1H"&RIGHT(Annual!P$1,2),Segments!$A$3:$AJ$3,0))+INDEX(Segments!$A:$AJ,MATCH(Annual!$A9,Segments!$A:$A,0),MATCH("2H"&RIGHT(Annual!P$1,2),Segments!$A$3:$AJ$3,0)) -> 61.651305 | Q9: =INDEX(Segments!$A:$AJ,MATCH(Annual!$A9,Segments!$A:$A,0),MATCH("1H"&RIGHT(Annual!Q$1,2),Segments!$A$3:$AJ$3,0))+INDEX(Segments!$A:$AJ,MATCH(Annual!$A9,Segments!$A:$A,0),MATCH("2H"&RIGHT(Annual!Q$1,2),Segments!$A$3:$AJ$3,0)) -> 132.84393 | R9: =INDEX(Segments!$A:$AJ,MATCH(Annual!$A9,Segments!$A:$A,0),MATCH("1H"&RIGHT(Annual!R$1,2),Segments!$A$3:$AJ$3,0))+INDEX(Segments!$A:$AJ,MATCH(Annual!$A9,Segments!$A:$A,0),MATCH("2H"&RIGHT(Annual!R$1,2),Segments!$A$3:$AJ$3,0)) -> 214.46404 | S9: =INDEX(Segments!$A:$AJ,MATCH(Annual!$A9,Segments!$A:$A,0),MATCH("1H"&RIGHT(Annual!S$1,2),Segments!$A$3:$AJ$3,0))+INDEX(Segments!$A:$AJ,MATCH(Annual!$A9,Segments!$A:$A,0),MATCH("2H"&RIGHT(Annual!S$1,2),Segments!$A$3:$AJ$3,0)) -> 310.85937 | T9: =INDEX(Segments!$A:$AJ,MATCH(Annual!$A9,Segments!$A:$A,0),MATCH("1H"&RIGHT(Annual!T$1,2),Segments!$A$3:$AJ$3,0))+INDEX(Segments!$A:$AJ,MATCH(Annual!$A9,Segments!$A:$A,0),MATCH("2H"&RIGHT(Annual!T$1,2),Segments!$A$3:$AJ$3,0)) -> 422.36745 | U9: =INDEX(Segments!$A:$AJ,MATCH(Annual!$A9,Segments!$A:$A,0),MATCH("1H"&RIGHT(Annual!U$1,2),Segments!$A$3:$AJ$3,0))+INDEX(Segments!$A:$AJ,MATCH(Annual!$A9,Segments!$A:$A,0),MATCH("2H"&RIGHT(Annual!U$1,2),Segments!$A$3:$AJ$3,0)) -> 551.16262 | V9: =INDEX(Segments!$A:$AJ,MATCH(Annual!$A9,Segments!$A:$A,0),MATCH("1H"&RIGHT(Annual!V$1,2),Segments!$A$3:$AJ$3,0))+INDEX(Segments!$A:$AJ,MATCH(Annual!$A9,Segments!$A:$A,0),MATCH("2H"&RIGHT(Annual!V$1,2),Segments!$A$3:$AJ$3,0)) -> 699.58267 | ... X9: =INDEX(Segments!$A:$AJ,MATCH(Annual!$A9,Segments!$A:$A,0),MATCH("1H"&RIGHT(Annual!X$1,2),Segments!$A$3:$AJ$3,0))+INDEX(Segments!$A:$AJ,MATCH(Annual!$A9,Segments!$A:$A,0),MATCH("2H"&RIGHT(Annual!X$1,2),Segments!$A$3:$AJ$3,0)) -> 1066.1906 | AA9: 0.7 | AB9: -0.7 | AC9: 0.7 | AD9: 43.3 | AE9: 0.7 | AF9: 128.2
A10: Rev-Total Revenue | B10: Total Revenue | C10: AUDm | F10: =SUM(F7:F9) -> 573.3 | G10: =SUM(G7:G9) -> 603.4 | H10: =SUM(H7:H9) -> 642.8 | I10: =SUM(I7:I9) -> 675 | J10: =SUM(J7:J9) -> 747 | K10: =SUM(K7:K9) -> 928.9 | L10: =SUM(L7:L9) -> 1002.8 | M10: =SUM(M7:M9) -> 1077.8 | N10: =SUM(N7:N9) -> 1235.5 | O10: =INDEX(Segments!$A:$AJ,MATCH(Annual!$A10,Segments!$A:$A,0),MATCH("1H"&RIGHT(Annual!O$1,2),Segments!$A$3:$AJ$3,0))+INDEX(Segments!$A:$AJ,MATCH(Annual!$A10,Segments!$A:$A,0),MATCH("2H"&RIGHT(Annual!O$1,2),Segments!$A$3:$AJ$3,0)) -> 1474.7512 | P10: =INDEX(Segments!$A:$AJ,MATCH(Annual!$A10,Segments!$A:$A,0),MATCH("1H"&RIGHT(Annual!P$1,2),Segments!$A$3:$AJ$3,0))+INDEX(Segments!$A:$AJ,MATCH(Annual!$A10,Segments!$A:$A,0),MATCH("2H"&RIGHT(Annual!P$1,2),Segments!$A$3:$AJ$3,0)) -> 1663.7755 | Q10: =INDEX(Segments!$A:$AJ,MATCH(Annual!$A10,Segments!$A:$A,0),MATCH("1H"&RIGHT(Annual!Q$1,2),Segments!$A$3:$AJ$3,0))+INDEX(Segments!$A:$AJ,MATCH(Annual!$A10,Segments!$A:$A,0),MATCH("2H"&RIGHT(Annual!Q$1,2),Segments!$A$3:$AJ$3,0)) -> 1840.8429 | R10: =INDEX(Segments!$A:$AJ,MATCH(Annual!$A10,Segments!$A:$A,0),MATCH("1H"&RIGHT(Annual!R$1,2),Segments!$A$3:$AJ$3,0))+INDEX(Segments!$A:$AJ,MATCH(Annual!$A10,Segments!$A:$A,0),MATCH("2H"&RIGHT(Annual!R$1,2),Segments!$A$3:$AJ$3,0)) -> 2033.711 | S10: =INDEX(Segments!$A:$AJ,MATCH(Annual!$A10,Segments!$A:$A,0),MATCH("1H"&RIGHT(Annual!S$1,2),Segments!$A$3:$AJ$3,0))+INDEX(Segments!$A:$AJ,MATCH(Annual!$A10,Segments!$A:$A,0),MATCH("2H"&RIGHT(Annual!S$1,2),Segments!$A$3:$AJ$3,0)) -> 2249.3444 | T10: =INDEX(Segments!$A:$AJ,MATCH(Annual!$A10,Segments!$A:$A,0),MATCH("1H"&RIGHT(Annual!T$1,2),Segments!$A$3:$AJ$3,0))+INDEX(Segments!$A:$AJ,MATCH(Annual!$A10,Segments!$A:$A,0),MATCH("2H"&RIGHT(Annual!T$1,2),Segments!$A$3:$AJ$3,0)) -> 2477.1616 | U10: =INDEX(Segments!$A:$AJ,MATCH(Annual!$A10,Segments!$A:$A,0),MATCH("1H"&RIGHT(Annual!U$1,2),Segments!$A$3:$AJ$3,0))+INDEX(Segments!$A:$AJ,MATCH(Annual!$A10,Segments!$A:$A,0),MATCH("2H"&RIGHT(Annual!U$1,2),Segments!$A$3:$AJ$3,0)) -> 2729.2444 | V10: =INDEX(Segments!$A:$AJ,MATCH(Annual!$A10,Segments!$A:$A,0),MATCH("1H"&RIGHT(Annual!V$1,2),Segments!$A$3:$AJ$3,0))+INDEX(Segments!$A:$AJ,MATCH(Annual!$A10,Segments!$A:$A,0),MATCH("2H"&RIGHT(Annual!V$1,2),Segments!$A$3:$AJ$3,0)) -> 3008.3494 | ... X10: =INDEX(Segments!$A:$AJ,MATCH(Annual!$A10,Segments!$A:$A,0),MATCH("1H"&RIGHT(Annual!X$1,2),Segments!$A$3:$AJ$3,0))+INDEX(Segments!$A:$AJ,MATCH(Annual!$A10,Segments!$A:$A,0),MATCH("2H"&RIGHT(Annual!X$1,2),Segments!$A$3:$AJ$3,0)) -> 3660.3208 | AA10: 117.3 | AB10: 1118.2 | AC10: 159.7 | AD10: 1359.4 | AE10: 195.3 | AF10: 1559.9
B11: Growth | C11: % YoY | G11: =G10/F10-1 -> 0.052503053 | H11: =H10/G10-1 -> 0.065296652 | I11: =I10/H10-1 -> 0.050093342 | J11: =J10/I10-1 -> 0.10666667 | K11: =K10/J10-1 -> 0.24350736 | L11: =L10/K10-1 -> 0.079556465 | M11: =M10/L10-1 -> 0.074790586 | N11: =N10/M10-1 -> 0.14631657 | ... X11: =X10/W10-1 -> 0.10331752 | AA11: 0.15 | AB11: -0.01 | AC11: 0.36 | AD11: -0.13 | AE11: 0.22 | AF11: -0.07
B13: COGS
A14: DC-Commission and other cost of sales | B14: Commission and other cost of sales | C14: AUDm | D14: AR | F14: -474.6 | G14: -493.9 | H14: -514.1 | I14: -531.1 | J14: -598.1 | K14: -741 | L14: -679.1 | M14: -726.5 | N14: -832.6 | O14: =INDEX(Segments!$A:$AJ,MATCH(Annual!$A14,Segments!$A:$A,0),MATCH("1H"&RIGHT(Annual!O$1,2),Segments!$A$3:$AJ$3,0))+INDEX(Segments!$A:$AJ,MATCH(Annual!$A14,Segments!$A:$A,0),MATCH("2H"&RIGHT(Annual!O$1,2),Segments!$A$3:$AJ$3,0)) -> -960.57358 | P14: =INDEX(Segments!$A:$AJ,MATCH(Annual!$A14,Segments!$A:$A,0),MATCH("1H"&RIGHT(Annual!P$1,2),Segments!$A$3:$AJ$3,0))+INDEX(Segments!$A:$AJ,MATCH(Annual!$A14,Segments!$A:$A,0),MATCH("2H"&RIGHT(Annual!P$1,2),Segments!$A$3:$AJ$3,0)) -> -1059.9486 | Q14: =INDEX(Segments!$A:$AJ,MATCH(Annual!$A14,Segments!$A:$A,0),MATCH("1H"&RIGHT(Annual!Q$1,2),Segments!$A$3:$AJ$3,0))+INDEX(Segments!$A:$AJ,MATCH(Annual!$A14,Segments!$A:$A,0),MATCH("2H"&RIGHT(Annual!Q$1,2),Segments!$A$3:$AJ$3,0)) -> -1132.3253 | R14: =INDEX(Segments!$A:$AJ,MATCH(Annual!$A14,Segments!$A:$A,0),MATCH("1H"&RIGHT(Annual!R$1,2),Segments!$A$3:$AJ$3,0))+INDEX(Segments!$A:$AJ,MATCH(Annual!$A14,Segments!$A:$A,0),MATCH("2H"&RIGHT(Annual!R$1,2),Segments!$A$3:$AJ$3,0)) -> -1208.1626 | S14: =INDEX(Segments!$A:$AJ,MATCH(Annual!$A14,Segments!$A:$A,0),MATCH("1H"&RIGHT(Annual!S$1,2),Segments!$A$3:$AJ$3,0))+INDEX(Segments!$A:$AJ,MATCH(Annual!$A14,Segments!$A:$A,0),MATCH("2H"&RIGHT(Annual!S$1,2),Segments!$A$3:$AJ$3,0)) -> -1289.7347 | T14: =INDEX(Segments!$A:$AJ,MATCH(Annual!$A14,Segments!$A:$A,0),MATCH("1H"&RIGHT(Annual!T$1,2),Segments!$A$3:$AJ$3,0))+INDEX(Segments!$A:$AJ,MATCH(Annual!$A14,Segments!$A:$A,0),MATCH("2H"&RIGHT(Annual!T$1,2),Segments!$A$3:$AJ$3,0)) -> -1367.1188 | U14: =INDEX(Segments!$A:$AJ,MATCH(Annual!$A14,Segments!$A:$A,0),MATCH("1H"&RIGHT(Annual!U$1,2),Segments!$A$3:$AJ$3,0))+INDEX(Segments!$A:$AJ,MATCH(Annual!$A14,Segments!$A:$A,0),MATCH("2H"&RIGHT(Annual!U$1,2),Segments!$A$3:$AJ$3,0)) -> -1449.146 | V14: =INDEX(Segments!$A:$AJ,MATCH(Annual!$A14,Segments!$A:$A,0),MATCH("1H"&RIGHT(Annual!V$1,2),Segments!$A$3:$AJ$3,0))+INDEX(Segments!$A:$AJ,MATCH(Annual!$A14,Segments!$A:$A,0),MATCH("2H"&RIGHT(Annual!V$1,2),Segments!$A$3:$AJ$3,0)) -> -1536.0947 | ... X14: =INDEX(Segments!$A:$AJ,MATCH(Annual!$A14,Segments!$A:$A,0),MATCH("1H"&RIGHT(Annual!X$1,2),Segments!$A$3:$AJ$3,0))+INDEX(Segments!$A:$AJ,MATCH(Annual!$A14,Segments!$A:$A,0),MATCH("2H"&RIGHT(Annual!X$1,2),Segments!$A$3:$AJ$3,0)) -> -1725.956
A15: DC-Securitisation and interest expense | B15: Securitisation and interest expense | C15: AUDm | F15: -31.7 | G15: -36.9 | H15: -53.5 | I15: -53.3 | J15: -46.5 | K15: -57.7 | L15: -210.6 | M15: -246.6 | N15: -282.9 | O15: =INDEX(Segments!$A:$AJ,MATCH(Annual!$A15,Segments!$A:$A,0),MATCH("1H"&RIGHT(Annual!O$1,2),Segments!$A$3:$AJ$3,0))+INDEX(Segments!$A:$AJ,MATCH(Annual!$A15,Segments!$A:$A,0),MATCH("2H"&RIGHT(Annual!O$1,2),Segments!$A$3:$AJ$3,0)) -> -349.79161 | P15: =INDEX(Segments!$A:$AJ,MATCH(Annual!$A15,Segments!$A:$A,0),MATCH("1H"&RIGHT(Annual!P$1,2),Segments!$A$3:$AJ$3,0))+INDEX(Segments!$A:$AJ,MATCH(Annual!$A15,Segments!$A:$A,0),MATCH("2H"&RIGHT(Annual!P$1,2),Segments!$A$3:$AJ$3,0)) -> -384.37204 | Q15: =INDEX(Segments!$A:$AJ,MATCH(Annual!$A15,Segments!$A:$A,0),MATCH("1H"&RIGHT(Annual!Q$1,2),Segments!$A$3:$AJ$3,0))+INDEX(Segments!$A:$AJ,MATCH(Annual!$A15,Segments!$A:$A,0),MATCH("2H"&RIGHT(Annual!Q$1,2),Segments!$A$3:$AJ$3,0)) -> -407.06753 | R15: =INDEX(Segments!$A:$AJ,MATCH(Annual!$A15,Segments!$A:$A,0),MATCH("1H"&RIGHT(Annual!R$1,2),Segments!$A$3:$AJ$3,0))+INDEX(Segments!$A:$AJ,MATCH(Annual!$A15,Segments!$A:$A,0),MATCH("2H"&RIGHT(Annual!R$1,2),Segments!$A$3:$AJ$3,0)) -> -431.49158 | S15: =INDEX(Segments!$A:$AJ,MATCH(Annual!$A15,Segments!$A:$A,0),MATCH("1H"&RIGHT(Annual!S$1,2),Segments!$A$3:$AJ$3,0))+INDEX(Segments!$A:$AJ,MATCH(Annual!$A15,Segments!$A:$A,0),MATCH("2H"&RIGHT(Annual!S$1,2),Segments!$A$3:$AJ$3,0)) -> -457.38108 | T15: =INDEX(Segments!$A:$AJ,MATCH(Annual!$A15,Segments!$A:$A,0),MATCH("1H"&RIGHT(Annual!T$1,2),Segments!$A$3:$AJ$3,0))+INDEX(Segments!$A:$AJ,MATCH(Annual!$A15,Segments!$A:$A,0),MATCH("2H"&RIGHT(Annual!T$1,2),Segments!$A$3:$AJ$3,0)) -> -484.82394 | U15: =INDEX(Segments!$A:$AJ,MATCH(Annual!$A15,Segments!$A:$A,0),MATCH("1H"&RIGHT(Annual!U$1,2),Segments!$A$3:$AJ$3,0))+INDEX(Segments!$A:$AJ,MATCH(Annual!$A15,Segments!$A:$A,0),MATCH("2H"&RIGHT(Annual!U$1,2),Segments!$A$3:$AJ$3,0)) -> -513.91338 | V15: =INDEX(Segments!$A:$AJ,MATCH(Annual!$A15,Segments!$A:$A,0),MATCH("1H"&RIGHT(Annual!V$1,2),Segments!$A$3:$AJ$3,0))+INDEX(Segments!$A:$AJ,MATCH(Annual!$A15,Segments!$A:$A,0),MATCH("2H"&RIGHT(Annual!V$1,2),Segments!$A$3:$AJ$3,0)) -> -544.74818 | ... X15: =INDEX(Segments!$A:$AJ,MATCH(Annual!$A15,Segments!$A:$A,0),MATCH("1H"&RIGHT(Annual!X$1,2),Segments!$A$3:$AJ$3,0))+INDEX(Segments!$A:$AJ,MATCH(Annual!$A15,Segments!$A:$A,0),MATCH("2H"&RIGHT(Annual!X$1,2),Segments!$A$3:$AJ$3,0)) -> -612.07906
A16: DC-Other | B16: Other | C16: AUDm | O16: =INDEX(Segments!$A:$AJ,MATCH(Annual!$A16,Segments!$A:$A,0),MATCH("1H"&RIGHT(Annual!O$1,2),Segments!$A$3:$AJ$3,0))+INDEX(Segments!$A:$AJ,MATCH(Annual!$A16,Segments!$A:$A,0),MATCH("2H"&RIGHT(Annual!O$1,2),Segments!$A$3:$AJ$3,0)) -> -18.9527 | P16: =INDEX(Segments!$A:$AJ,MATCH(Annual!$A16,Segments!$A:$A,0),MATCH("1H"&RIGHT(Annual!P$1,2),Segments!$A$3:$AJ$3,0))+INDEX(Segments!$A:$AJ,MATCH(Annual!$A16,Segments!$A:$A,0),MATCH("2H"&RIGHT(Annual!P$1,2),Segments!$A$3:$AJ$3,0)) -> -54.110758 | Q16: =INDEX(Segments!$A:$AJ,MATCH(Annual!$A16,Segments!$A:$A,0),MATCH("1H"&RIGHT(Annual!Q$1,2),Segments!$A$3:$AJ$3,0))+INDEX(Segments!$A:$AJ,MATCH(Annual!$A16,Segments!$A:$A,0),MATCH("2H"&RIGHT(Annual!Q$1,2),Segments!$A$3:$AJ$3,0)) -> -116.73964 | R16: =INDEX(Segments!$A:$AJ,MATCH(Annual!$A16,Segments!$A:$A,0),MATCH("1H"&RIGHT(Annual!R$1,2),Segments!$A$3:$AJ$3,0))+INDEX(Segments!$A:$AJ,MATCH(Annual!$A16,Segments!$A:$A,0),MATCH("2H"&RIGHT(Annual!R$1,2),Segments!$A$3:$AJ$3,0)) -> -188.6191 | S16: =INDEX(Segments!$A:$AJ,MATCH(Annual!$A16,Segments!$A:$A,0),MATCH("1H"&RIGHT(Annual!S$1,2),Segments!$A$3:$AJ$3,0))+INDEX(Segments!$A:$AJ,MATCH(Annual!$A16,Segments!$A:$A,0),MATCH("2H"&RIGHT(Annual!S$1,2),Segments!$A$3:$AJ$3,0)) -> -273.59138 | T16: =INDEX(Segments!$A:$AJ,MATCH(Annual!$A16,Segments!$A:$A,0),MATCH("1H"&RIGHT(Annual!T$1,2),Segments!$A$3:$AJ$3,0))+INDEX(Segments!$A:$AJ,MATCH(Annual!$A16,Segments!$A:$A,0),MATCH("2H"&RIGHT(Annual!T$1,2),Segments!$A$3:$AJ$3,0)) -> -371.94953 | U16: =INDEX(Segments!$A:$AJ,MATCH(Annual!$A16,Segments!$A:$A,0),MATCH("1H"&RIGHT(Annual!U$1,2),Segments!$A$3:$AJ$3,0))+INDEX(Segments!$A:$AJ,MATCH(Annual!$A16,Segments!$A:$A,0),MATCH("2H"&RIGHT(Annual!U$1,2),Segments!$A$3:$AJ$3,0)) -> -485.63895 | V16: =INDEX(Segments!$A:$AJ,MATCH(Annual!$A16,Segments!$A:$A,0),MATCH("1H"&RIGHT(Annual!V$1,2),Segments!$A$3:$AJ$3,0))+INDEX(Segments!$A:$AJ,MATCH(Annual!$A16,Segments!$A:$A,0),MATCH("2H"&RIGHT(Annual!V$1,2),Segments!$A$3:$AJ$3,0)) -> -616.73956 | ... X16: =INDEX(Segments!$A:$AJ,MATCH(Annual!$A16,Segments!$A:$A,0),MATCH("1H"&RIGHT(Annual!X$1,2),Segments!$A$3:$AJ$3,0))+INDEX(Segments!$A:$AJ,MATCH(Annual!$A16,Segments!$A:$A,0),MATCH("2H"&RIGHT(Annual!X$1,2),Segments!$A$3:$AJ$3,0)) -> -940.86902
A17: DC-Total COGS | B17: Total COGS | C17: AUDm | F17: =SUM(F14:F16) -> -506.3 | G17: =SUM(G14:G16) -> -530.8 | H17: =SUM(H14:H16) -> -567.6 | I17: =SUM(I14:I16) -> -584.4 | J17: =SUM(J14:J16) -> -644.6 | K17: =SUM(K14:K16) -> -798.7 | L17: =SUM(L14:L16) -> -889.7 | M17: =SUM(M14:M16) -> -973.1 | N17: =SUM(N14:N16) -> -1115.5 | O17: =INDEX(Segments!$A:$AJ,MATCH(Annual!$A17,Segments!$A:$A,0),MATCH("1H"&RIGHT(Annual!O$1,2),Segments!$A$3:$AJ$3,0))+INDEX(Segments!$A:$AJ,MATCH(Annual!$A17,Segments!$A:$A,0),MATCH("2H"&RIGHT(Annual!O$1,2),Segments!$A$3:$AJ$3,0)) -> -1329.3179 | P17: =INDEX(Segments!$A:$AJ,MATCH(Annual!$A17,Segments!$A:$A,0),MATCH("1H"&RIGHT(Annual!P$1,2),Segments!$A$3:$AJ$3,0))+INDEX(Segments!$A:$AJ,MATCH(Annual!$A17,Segments!$A:$A,0),MATCH("2H"&RIGHT(Annual!P$1,2),Segments!$A$3:$AJ$3,0)) -> -1498.4314 | Q17: =INDEX(Segments!$A:$AJ,MATCH(Annual!$A17,Segments!$A:$A,0),MATCH("1H"&RIGHT(Annual!Q$1,2),Segments!$A$3:$AJ$3,0))+INDEX(Segments!$A:$AJ,MATCH(Annual!$A17,Segments!$A:$A,0),MATCH("2H"&RIGHT(Annual!Q$1,2),Segments!$A$3:$AJ$3,0)) -> -1656.1325 | R17: =INDEX(Segments!$A:$AJ,MATCH(Annual!$A17,Segments!$A:$A,0),MATCH("1H"&RIGHT(Annual!R$1,2),Segments!$A$3:$AJ$3,0))+INDEX(Segments!$A:$AJ,MATCH(Annual!$A17,Segments!$A:$A,0),MATCH("2H"&RIGHT(Annual!R$1,2),Segments!$A$3:$AJ$3,0)) -> -1828.2733 | S17: =INDEX(Segments!$A:$AJ,MATCH(Annual!$A17,Segments!$A:$A,0),MATCH("1H"&RIGHT(Annual!S$1,2),Segments!$A$3:$AJ$3,0))+INDEX(Segments!$A:$AJ,MATCH(Annual!$A17,Segments!$A:$A,0),MATCH("2H"&RIGHT(Annual!S$1,2),Segments!$A$3:$AJ$3,0)) -> -2020.7072 | T17: =INDEX(Segments!$A:$AJ,MATCH(Annual!$A17,Segments!$A:$A,0),MATCH("1H"&RIGHT(Annual!T$1,2),Segments!$A$3:$AJ$3,0))+INDEX(Segments!$A:$AJ,MATCH(Annual!$A17,Segments!$A:$A,0),MATCH("2H"&RIGHT(Annual!T$1,2),Segments!$A$3:$AJ$3,0)) -> -2223.8923 | U17: =INDEX(Segments!$A:$AJ,MATCH(Annual!$A17,Segments!$A:$A,0),MATCH("1H"&RIGHT(Annual!U$1,2),Segments!$A$3:$AJ$3,0))+INDEX(Segments!$A:$AJ,MATCH(Annual!$A17,Segments!$A:$A,0),MATCH("2H"&RIGHT(Annual!U$1,2),Segments!$A$3:$AJ$3,0)) -> -2448.6983 | V17: =INDEX(Segments!$A:$AJ,MATCH(Annual!$A17,Segments!$A:$A,0),MATCH("1H"&RIGHT(Annual!V$1,2),Segments!$A$3:$AJ$3,0))+INDEX(Segments!$A:$AJ,MATCH(Annual!$A17,Segments!$A:$A,0),MATCH("2H"&RIGHT(Annual!V$1,2),Segments!$A$3:$AJ$3,0)) -> -2697.5825 | ... X17: =INDEX(Segments!$A:$AJ,MATCH(Annual!$A17,Segments!$A:$A,0),MATCH("1H"&RIGHT(Annual!X$1,2),Segments!$A$3:$AJ$3,0))+INDEX(Segments!$A:$AJ,MATCH(Annual!$A17,Segments!$A:$A,0),MATCH("2H"&RIGHT(Annual!X$1,2),Segments!$A$3:$AJ$3,0)) -> -3278.9041 | AA17: -29.3 | AB17: -1086.2 | AC17: -39.9 | AD17: -1329 | AE17: -48.8 | AF17: -1529.9
A19: GP-Gross Profit | B19: Gross Profit | C19: AUDm | F19: =F10+F17 -> 67 | G19: =G10+G17 -> 72.6 | H19: =H10+H17 -> 75.2 | I19: =I10+I17 -> 90.6 | J19: =J10+J17 -> 102.4 | K19: =K10+K17 -> 130.2 | L19: =L10+L17 -> 113.1 | M19: =M10+M17 -> 104.7 | N19: =N10+N17 -> 120 | O19: =INDEX(Segments!$A:$AJ,MATCH(Annual!$A19,Segments!$A:$A,0),MATCH("1H"&RIGHT(Annual!O$1,2),Segments!$A$3:$AJ$3,0))+INDEX(Segments!$A:$AJ,MATCH(Annual!$A19,Segments!$A:$A,0),MATCH("2H"&RIGHT(Annual!O$1,2),Segments!$A$3:$AJ$3,0)) -> 145.43329 | P19: =INDEX(Segments!$A:$AJ,MATCH(Annual!$A19,Segments!$A:$A,0),MATCH("1H"&RIGHT(Annual!P$1,2),Segments!$A$3:$AJ$3,0))+INDEX(Segments!$A:$AJ,MATCH(Annual!$A19,Segments!$A:$A,0),MATCH("2H"&RIGHT(Annual!P$1,2),Segments!$A$3:$AJ$3,0)) -> 165.34413 | Q19: =INDEX(Segments!$A:$AJ,MATCH(Annual!$A19,Segments!$A:$A,0),MATCH("1H"&RIGHT(Annual!Q$1,2),Segments!$A$3:$AJ$3,0))+INDEX(Segments!$A:$AJ,MATCH(Annual!$A19,Segments!$A:$A,0),MATCH("2H"&RIGHT(Annual!Q$1,2),Segments!$A$3:$AJ$3,0)) -> 184.71041 | R19: =INDEX(Segments!$A:$AJ,MATCH(Annual!$A19,Segments!$A:$A,0),MATCH("1H"&RIGHT(Annual!R$1,2),Segments!$A$3:$AJ$3,0))+INDEX(Segments!$A:$AJ,MATCH(Annual!$A19,Segments!$A:$A,0),MATCH("2H"&RIGHT(Annual!R$1,2),Segments!$A$3:$AJ$3,0)) -> 205.43773 | S19: =INDEX(Segments!$A:$AJ,MATCH(Annual!$A19,Segments!$A:$A,0),MATCH("1H"&RIGHT(Annual!S$1,2),Segments!$A$3:$AJ$3,0))+INDEX(Segments!$A:$AJ,MATCH(Annual!$A19,Segments!$A:$A,0),MATCH("2H"&RIGHT(Annual!S$1,2),Segments!$A$3:$AJ$3,0)) -> 228.63719 | T19: =INDEX(Segments!$A:$AJ,MATCH(Annual!$A19,Segments!$A:$A,0),MATCH("1H"&RIGHT(Annual!T$1,2),Segments!$A$3:$AJ$3,0))+INDEX(Segments!$A:$AJ,MATCH(Annual!$A19,Segments!$A:$A,0),MATCH("2H"&RIGHT(Annual!T$1,2),Segments!$A$3:$AJ$3,0)) -> 253.26928 | U19: =INDEX(Segments!$A:$AJ,MATCH(Annual!$A19,Segments!$A:$A,0),MATCH("1H"&RIGHT(Annual!U$1,2),Segments!$A$3:$AJ$3,0))+INDEX(Segments!$A:$AJ,MATCH(Annual!$A19,Segments!$A:$A,0),MATCH("2H"&RIGHT(Annual!U$1,2),Segments!$A$3:$AJ$3,0)) -> 280.54611 | V19: =INDEX(Segments!$A:$AJ,MATCH(Annual!$A19,Segments!$A:$A,0),MATCH("1H"&RIGHT(Annual!V$1,2),Segments!$A$3:$AJ$3,0))+INDEX(Segments!$A:$AJ,MATCH(Annual!$A19,Segments!$A:$A,0),MATCH("2H"&RIGHT(Annual!V$1,2),Segments!$A$3:$AJ$3,0)) -> 310.7669 | ... X19: =INDEX(Segments!$A:$AJ,MATCH(Annual!$A19,Segments!$A:$A,0),MATCH("1H"&RIGHT(Annual!X$1,2),Segments!$A$3:$AJ$3,0))+INDEX(Segments!$A:$AJ,MATCH(Annual!$A19,Segments!$A:$A,0),MATCH("2H"&RIGHT(Annual!X$1,2),Segments!$A$3:$AJ$3,0)) -> 381.41673 | AA19: -29.3 | AB19: 149.3 | AC19: -39.9 | AD19: 190.1 | AE19: -48.8 | AF19: 225.2
A20: DC-Other income | B20: Other income | C20: AUDm | D20: AR | F20: 16.7 | G20: 13.4 | H20: 15.1 | I20: 14.5 | J20: 14.4 | K20: 20.4 | L20: 21.9 | M20: 17.3 | N20: 19.2 | O20: =INDEX(Segments!$A:$AJ,MATCH(Annual!$A20,Segments!$A:$A,0),MATCH("1H"&RIGHT(Annual!O$1,2),Segments!$A$3:$AJ$3,0))+INDEX(Segments!$A:$AJ,MATCH(Annual!$A20,Segments!$A:$A,0),MATCH("2H"&RIGHT(Annual!O$1,2),Segments!$A$3:$AJ$3,0)) -> 20.352 | P20: =INDEX(Segments!$A:$AJ,MATCH(Annual!$A20,Segments!$A:$A,0),MATCH("1H"&RIGHT(Annual!P$1,2),Segments!$A$3:$AJ$3,0))+INDEX(Segments!$A:$AJ,MATCH(Annual!$A20,Segments!$A:$A,0),MATCH("2H"&RIGHT(Annual!P$1,2),Segments!$A$3:$AJ$3,0)) -> 21.404718 | Q20: =INDEX(Segments!$A:$AJ,MATCH(Annual!$A20,Segments!$A:$A,0),MATCH("1H"&RIGHT(Annual!Q$1,2),Segments!$A$3:$AJ$3,0))+INDEX(Segments!$A:$AJ,MATCH(Annual!$A20,Segments!$A:$A,0),MATCH("2H"&RIGHT(Annual!Q$1,2),Segments!$A$3:$AJ$3,0)) -> 22.135438 | R20: =INDEX(Segments!$A:$AJ,MATCH(Annual!$A20,Segments!$A:$A,0),MATCH("1H"&RIGHT(Annual!R$1,2),Segments!$A$3:$AJ$3,0))+INDEX(Segments!$A:$AJ,MATCH(Annual!$A20,Segments!$A:$A,0),MATCH("2H"&RIGHT(Annual!R$1,2),Segments!$A$3:$AJ$3,0)) -> 22.876635 | S20: =INDEX(Segments!$A:$AJ,MATCH(Annual!$A20,Segments!$A:$A,0),MATCH("1H"&RIGHT(Annual!S$1,2),Segments!$A$3:$AJ$3,0))+INDEX(Segments!$A:$AJ,MATCH(Annual!$A20,Segments!$A:$A,0),MATCH("2H"&RIGHT(Annual!S$1,2),Segments!$A$3:$AJ$3,0)) -> 23.648855 | T20: =INDEX(Segments!$A:$AJ,MATCH(Annual!$A20,Segments!$A:$A,0),MATCH("1H"&RIGHT(Annual!T$1,2),Segments!$A$3:$AJ$3,0))+INDEX(Segments!$A:$AJ,MATCH(Annual!$A20,Segments!$A:$A,0),MATCH("2H"&RIGHT(Annual!T$1,2),Segments!$A$3:$AJ$3,0)) -> 24.35832 | U20: =INDEX(Segments!$A:$AJ,MATCH(Annual!$A20,Segments!$A:$A,0),MATCH("1H"&RIGHT(Annual!U$1,2),Segments!$A$3:$AJ$3,0))+INDEX(Segments!$A:$AJ,MATCH(Annual!$A20,Segments!$A:$A,0),MATCH("2H"&RIGHT(Annual!U$1,2),Segments!$A$3:$AJ$3,0)) -> 25.08907 | V20: =INDEX(Segments!$A:$AJ,MATCH(Annual!$A20,Segments!$A:$A,0),MATCH("1H"&RIGHT(Annual!V$1,2),Segments!$A$3:$AJ$3,0))+INDEX(Segments!$A:$AJ,MATCH(Annual!$A20,Segments!$A:$A,0),MATCH("2H"&RIGHT(Annual!V$1,2),Segments!$A$3:$AJ$3,0)) -> 25.841742 | ... X20: =INDEX(Segments!$A:$AJ,MATCH(Annual!$A20,Segments!$A:$A,0),MATCH("1H"&RIGHT(Annual!X$1,2),Segments!$A$3:$AJ$3,0))+INDEX(Segments!$A:$AJ,MATCH(Annual!$A20,Segments!$A:$A,0),MATCH("2H"&RIGHT(Annual!X$1,2),Segments!$A$3:$AJ$3,0)) -> 27.415504
A21: DC-Gross Profit inc Other income | B21: Gross Profit inc Other income | C21: AUDm | F21: =F19+F20 -> 83.7 | G21: =G19+G20 -> 86 | H21: =H19+H20 -> 90.3 | I21: =I19+I20 -> 105.1 | J21: =J19+J20 -> 116.8 | K21: =K19+K20 -> 150.6 | L21: =L19+L20 -> 135 | M21: =M19+M20 -> 122 | N21: =N19+N20 -> 139.2 | O21: =INDEX(Segments!$A:$AJ,MATCH(Annual!$A21,Segments!$A:$A,0),MATCH("1H"&RIGHT(Annual!O$1,2),Segments!$A$3:$AJ$3,0))+INDEX(Segments!$A:$AJ,MATCH(Annual!$A21,Segments!$A:$A,0),MATCH("2H"&RIGHT(Annual!O$1,2),Segments!$A$3:$AJ$3,0)) -> 165.78529 | P21: =INDEX(Segments!$A:$AJ,MATCH(Annual!$A21,Segments!$A:$A,0),MATCH("1H"&RIGHT(Annual!P$1,2),Segments!$A$3:$AJ$3,0))+INDEX(Segments!$A:$AJ,MATCH(Annual!$A21,Segments!$A:$A,0),MATCH("2H"&RIGHT(Annual!P$1,2),Segments!$A$3:$AJ$3,0)) -> 186.74885 | Q21: =INDEX(Segments!$A:$AJ,MATCH(Annual!$A21,Segments!$A:$A,0),MATCH("1H"&RIGHT(Annual!Q$1,2),Segments!$A$3:$AJ$3,0))+INDEX(Segments!$A:$AJ,MATCH(Annual!$A21,Segments!$A:$A,0),MATCH("2H"&RIGHT(Annual!Q$1,2),Segments!$A$3:$AJ$3,0)) -> 206.84585 | R21: =INDEX(Segments!$A:$AJ,MATCH(Annual!$A21,Segments!$A:$A,0),MATCH("1H"&RIGHT(Annual!R$1,2),Segments!$A$3:$AJ$3,0))+INDEX(Segments!$A:$AJ,MATCH(Annual!$A21,Segments!$A:$A,0),MATCH("2H"&RIGHT(Annual!R$1,2),Segments!$A$3:$AJ$3,0)) -> 228.31437 | S21: =INDEX(Segments!$A:$AJ,MATCH(Annual!$A21,Segments!$A:$A,0),MATCH("1H"&RIGHT(Annual!S$1,2),Segments!$A$3:$AJ$3,0))+INDEX(Segments!$A:$AJ,MATCH(Annual!$A21,Segments!$A:$A,0),MATCH("2H"&RIGHT(Annual!S$1,2),Segments!$A$3:$AJ$3,0)) -> 252.28604 | T21: =INDEX(Segments!$A:$AJ,MATCH(Annual!$A21,Segments!$A:$A,0),MATCH("1H"&RIGHT(Annual!T$1,2),Segments!$A$3:$AJ$3,0))+INDEX(Segments!$A:$AJ,MATCH(Annual!$A21,Segments!$A:$A,0),MATCH("2H"&RIGHT(Annual!T$1,2),Segments!$A$3:$AJ$3,0)) -> 277.6276 | U21: =INDEX(Segments!$A:$AJ,MATCH(Annual!$A21,Segments!$A:$A,0),MATCH("1H"&RIGHT(Annual!U$1,2),Segments!$A$3:$AJ$3,0))+INDEX(Segments!$A:$AJ,MATCH(Annual!$A21,Segments!$A:$A,0),MATCH("2H"&RIGHT(Annual!U$1,2),Segments!$A$3:$AJ$3,0)) -> 305.63518 | V21: =INDEX(Segments!$A:$AJ,MATCH(Annual!$A21,Segments!$A:$A,0),MATCH("1H"&RIGHT(Annual!V$1,2),Segments!$A$3:$AJ$3,0))+INDEX(Segments!$A:$AJ,MATCH(Annual!$A21,Segments!$A:$A,0),MATCH("2H"&RIGHT(Annual!V$1,2),Segments!$A$3:$AJ$3,0)) -> 336.60864 | ... X21: =INDEX(Segments!$A:$AJ,MATCH(Annual!$A21,Segments!$A:$A,0),MATCH("1H"&RIGHT(Annual!X$1,2),Segments!$A$3:$AJ$3,0))+INDEX(Segments!$A:$AJ,MATCH(Annual!$A21,Segments!$A:$A,0),MATCH("2H"&RIGHT(Annual!X$1,2),Segments!$A$3:$AJ$3,0)) -> 408.83223 | AA21: -29.3 | AB21: 168.5 | AC21: -39.9 | AD21: 212.9 | AE21: -48.8 | AF21: 250.5
A22: DC-Trail book adjustment | B22: Trail book adjustment | C22: AUDm | F22: =F29-F21 -> -19.9 | G22: =G29-G21 -> -7.5 | H22: =H29-H21 -> -6.3 | I22: =I29-I21 -> -2.6 | J22: =J29-J21 -> -2.4 | K22: =K29-K21 -> -8 | L22: =L29-L21 -> 9.2 | M22: =M29-M21 -> 5 | N22: =N29-N21 -> 3.6 | O22: =INDEX(Segments!$A:$AJ,MATCH(Annual!$A22,Segments!$A:$A,0),MATCH("1H"&RIGHT(Annual!O$1,2),Segments!$A$3:$AJ$3,0))+INDEX(Segments!$A:$AJ,MATCH(Annual!$A22,Segments!$A:$A,0),MATCH("2H"&RIGHT(Annual!O$1,2),Segments!$A$3:$AJ$3,0)) -> 4.1885885 | P22: =INDEX(Segments!$A:$AJ,MATCH(Annual!$A22,Segments!$A:$A,0),MATCH("1H"&RIGHT(Annual!P$1,2),Segments!$A$3:$AJ$3,0))+INDEX(Segments!$A:$AJ,MATCH(Annual!$A22,Segments!$A:$A,0),MATCH("2H"&RIGHT(Annual!P$1,2),Segments!$A$3:$AJ$3,0)) -> 4.6219517 | Q22: =INDEX(Segments!$A:$AJ,MATCH(Annual!$A22,Segments!$A:$A,0),MATCH("1H"&RIGHT(Annual!Q$1,2),Segments!$A$3:$AJ$3,0))+INDEX(Segments!$A:$AJ,MATCH(Annual!$A22,Segments!$A:$A,0),MATCH("2H"&RIGHT(Annual!Q$1,2),Segments!$A$3:$AJ$3,0)) -> 4.9376531 | R22: =INDEX(Segments!$A:$AJ,MATCH(Annual!$A22,Segments!$A:$A,0),MATCH("1H"&RIGHT(Annual!R$1,2),Segments!$A$3:$AJ$3,0))+INDEX(Segments!$A:$AJ,MATCH(Annual!$A22,Segments!$A:$A,0),MATCH("2H"&RIGHT(Annual!R$1,2),Segments!$A$3:$AJ$3,0)) -> 5.2684399 | S22: =INDEX(Segments!$A:$AJ,MATCH(Annual!$A22,Segments!$A:$A,0),MATCH("1H"&RIGHT(Annual!S$1,2),Segments!$A$3:$AJ$3,0))+INDEX(Segments!$A:$AJ,MATCH(Annual!$A22,Segments!$A:$A,0),MATCH("2H"&RIGHT(Annual!S$1,2),Segments!$A$3:$AJ$3,0)) -> 5.6242532 | T22: =INDEX(Segments!$A:$AJ,MATCH(Annual!$A22,Segments!$A:$A,0),MATCH("1H"&RIGHT(Annual!T$1,2),Segments!$A$3:$AJ$3,0))+INDEX(Segments!$A:$AJ,MATCH(Annual!$A22,Segments!$A:$A,0),MATCH("2H"&RIGHT(Annual!T$1,2),Segments!$A$3:$AJ$3,0)) -> 5.9617084 | U22: =INDEX(Segments!$A:$AJ,MATCH(Annual!$A22,Segments!$A:$A,0),MATCH("1H"&RIGHT(Annual!U$1,2),Segments!$A$3:$AJ$3,0))+INDEX(Segments!$A:$AJ,MATCH(Annual!$A22,Segments!$A:$A,0),MATCH("2H"&RIGHT(Annual!U$1,2),Segments!$A$3:$AJ$3,0)) -> 6.3194109 | V22: =INDEX(Segments!$A:$AJ,MATCH(Annual!$A22,Segments!$A:$A,0),MATCH("1H"&RIGHT(Annual!V$1,2),Segments!$A$3:$AJ$3,0))+INDEX(Segments!$A:$AJ,MATCH(Annual!$A22,Segments!$A:$A,0),MATCH("2H"&RIGHT(Annual!V$1,2),Segments!$A$3:$AJ$3,0)) -> 6.6985755 | ... X22: =INDEX(Segments!$A:$AJ,MATCH(Annual!$A22,Segments!$A:$A,0),MATCH("1H"&RIGHT(Annual!X$1,2),Segments!$A$3:$AJ$3,0))+INDEX(Segments!$A:$AJ,MATCH(Annual!$A22,Segments!$A:$A,0),MATCH("2H"&RIGHT(Annual!X$1,2),Segments!$A$3:$AJ$3,0)) -> 7.5265195
G23: =G20/F20-1 -> -0.19760479 | N23: =N19/M19-1 -> 0.14613181 | O23: =O19/N19-1 -> 0.21194409
B24: Gross Profit by segment | N24: =N25/N29 -> 0.79341737
A25: GP-Distribution | B25: Distribution | C25: AUDm | D25: Preso | J25: NR | K25: 101.8 | L25: 105.8 | M25: 104.4 | N25: 113.3 | O25: =INDEX(Segments!$A:$AJ,MATCH(Annual!$A25,Segments!$A:$A,0),MATCH("1H"&RIGHT(Annual!O$1,2),Segments!$A$3:$AJ$3,0))+INDEX(Segments!$A:$AJ,MATCH(Annual!$A25,Segments!$A:$A,0),MATCH("2H"&RIGHT(Annual!O$1,2),Segments!$A$3:$AJ$3,0)) -> 130.34356 | P25: =INDEX(Segments!$A:$AJ,MATCH(Annual!$A25,Segments!$A:$A,0),MATCH("1H"&RIGHT(Annual!P$1,2),Segments!$A$3:$AJ$3,0))+INDEX(Segments!$A:$AJ,MATCH(Annual!$A25,Segments!$A:$A,0),MATCH("2H"&RIGHT(Annual!P$1,2),Segments!$A$3:$AJ$3,0)) -> 142.77553 | Q25: =INDEX(Segments!$A:$AJ,MATCH(Annual!$A25,Segments!$A:$A,0),MATCH("1H"&RIGHT(Annual!Q$1,2),Segments!$A$3:$AJ$3,0))+INDEX(Segments!$A:$AJ,MATCH(Annual!$A25,Segments!$A:$A,0),MATCH("2H"&RIGHT(Annual!Q$1,2),Segments!$A$3:$AJ$3,0)) -> 151.79438 | R25: =INDEX(Segments!$A:$AJ,MATCH(Annual!$A25,Segments!$A:$A,0),MATCH("1H"&RIGHT(Annual!R$1,2),Segments!$A$3:$AJ$3,0))+INDEX(Segments!$A:$AJ,MATCH(Annual!$A25,Segments!$A:$A,0),MATCH("2H"&RIGHT(Annual!R$1,2),Segments!$A$3:$AJ$3,0)) -> 161.21994 | S25: =INDEX(Segments!$A:$AJ,MATCH(Annual!$A25,Segments!$A:$A,0),MATCH("1H"&RIGHT(Annual!S$1,2),Segments!$A$3:$AJ$3,0))+INDEX(Segments!$A:$AJ,MATCH(Annual!$A25,Segments!$A:$A,0),MATCH("2H"&RIGHT(Annual!S$1,2),Segments!$A$3:$AJ$3,0)) -> 171.33331 | T25: =INDEX(Segments!$A:$AJ,MATCH(Annual!$A25,Segments!$A:$A,0),MATCH("1H"&RIGHT(Annual!T$1,2),Segments!$A$3:$AJ$3,0))+INDEX(Segments!$A:$AJ,MATCH(Annual!$A25,Segments!$A:$A,0),MATCH("2H"&RIGHT(Annual!T$1,2),Segments!$A$3:$AJ$3,0)) -> 180.90384 | U25: =INDEX(Segments!$A:$AJ,MATCH(Annual!$A25,Segments!$A:$A,0),MATCH("1H"&RIGHT(Annual!U$1,2),Segments!$A$3:$AJ$3,0))+INDEX(Segments!$A:$AJ,MATCH(Annual!$A25,Segments!$A:$A,0),MATCH("2H"&RIGHT(Annual!U$1,2),Segments!$A$3:$AJ$3,0)) -> 191.02732 | V25: =INDEX(Segments!$A:$AJ,MATCH(Annual!$A25,Segments!$A:$A,0),MATCH("1H"&RIGHT(Annual!V$1,2),Segments!$A$3:$AJ$3,0))+INDEX(Segments!$A:$AJ,MATCH(Annual!$A25,Segments!$A:$A,0),MATCH("2H"&RIGHT(Annual!V$1,2),Segments!$A$3:$AJ$3,0)) -> 201.73629 | ... X25: =INDEX(Segments!$A:$AJ,MATCH(Annual!$A25,Segments!$A:$A,0),MATCH("1H"&RIGHT(Annual!X$1,2),Segments!$A$3:$AJ$3,0))+INDEX(Segments!$A:$AJ,MATCH(Annual!$A25,Segments!$A:$A,0),MATCH("2H"&RIGHT(Annual!X$1,2),Segments!$A$3:$AJ$3,0)) -> 225.05062 | AA25: -28.6 | AB25: 141.9 | AC25: 0 | AD25: 135 | AE25: 0 | AF25: 149
A26: GP-Manufacturing | B26: Manufacturing | C26: AUDm | J26: NR | K26: 40.8 | L26: 38.4 | M26: 22.6 | N26: 29.5 | O26: =INDEX(Segments!$A:$AJ,MATCH(Annual!$A26,Segments!$A:$A,0),MATCH("1H"&RIGHT(Annual!O$1,2),Segments!$A$3:$AJ$3,0))+INDEX(Segments!$A:$AJ,MATCH(Annual!$A26,Segments!$A:$A,0),MATCH("2H"&RIGHT(Annual!O$1,2),Segments!$A$3:$AJ$3,0)) -> 36.959988 | P26: =INDEX(Segments!$A:$AJ,MATCH(Annual!$A26,Segments!$A:$A,0),MATCH("1H"&RIGHT(Annual!P$1,2),Segments!$A$3:$AJ$3,0))+INDEX(Segments!$A:$AJ,MATCH(Annual!$A26,Segments!$A:$A,0),MATCH("2H"&RIGHT(Annual!P$1,2),Segments!$A$3:$AJ$3,0)) -> 41.054718 | Q26: =INDEX(Segments!$A:$AJ,MATCH(Annual!$A26,Segments!$A:$A,0),MATCH("1H"&RIGHT(Annual!Q$1,2),Segments!$A$3:$AJ$3,0))+INDEX(Segments!$A:$AJ,MATCH(Annual!$A26,Segments!$A:$A,0),MATCH("2H"&RIGHT(Annual!Q$1,2),Segments!$A$3:$AJ$3,0)) -> 43.884834 | R26: =INDEX(Segments!$A:$AJ,MATCH(Annual!$A26,Segments!$A:$A,0),MATCH("1H"&RIGHT(Annual!R$1,2),Segments!$A$3:$AJ$3,0))+INDEX(Segments!$A:$AJ,MATCH(Annual!$A26,Segments!$A:$A,0),MATCH("2H"&RIGHT(Annual!R$1,2),Segments!$A$3:$AJ$3,0)) -> 46.517924 | S26: =INDEX(Segments!$A:$AJ,MATCH(Annual!$A26,Segments!$A:$A,0),MATCH("1H"&RIGHT(Annual!S$1,2),Segments!$A$3:$AJ$3,0))+INDEX(Segments!$A:$AJ,MATCH(Annual!$A26,Segments!$A:$A,0),MATCH("2H"&RIGHT(Annual!S$1,2),Segments!$A$3:$AJ$3,0)) -> 49.308999 | T26: =INDEX(Segments!$A:$AJ,MATCH(Annual!$A26,Segments!$A:$A,0),MATCH("1H"&RIGHT(Annual!T$1,2),Segments!$A$3:$AJ$3,0))+INDEX(Segments!$A:$AJ,MATCH(Annual!$A26,Segments!$A:$A,0),MATCH("2H"&RIGHT(Annual!T$1,2),Segments!$A$3:$AJ$3,0)) -> 52.267539 | U26: =INDEX(Segments!$A:$AJ,MATCH(Annual!$A26,Segments!$A:$A,0),MATCH("1H"&RIGHT(Annual!U$1,2),Segments!$A$3:$AJ$3,0))+INDEX(Segments!$A:$AJ,MATCH(Annual!$A26,Segments!$A:$A,0),MATCH("2H"&RIGHT(Annual!U$1,2),Segments!$A$3:$AJ$3,0)) -> 55.403591 | V26: =INDEX(Segments!$A:$AJ,MATCH(Annual!$A26,Segments!$A:$A,0),MATCH("1H"&RIGHT(Annual!V$1,2),Segments!$A$3:$AJ$3,0))+INDEX(Segments!$A:$AJ,MATCH(Annual!$A26,Segments!$A:$A,0),MATCH("2H"&RIGHT(Annual!V$1,2),Segments!$A$3:$AJ$3,0)) -> 58.727807 | ... X26: =INDEX(Segments!$A:$AJ,MATCH(Annual!$A26,Segments!$A:$A,0),MATCH("1H"&RIGHT(Annual!X$1,2),Segments!$A$3:$AJ$3,0))+INDEX(Segments!$A:$AJ,MATCH(Annual!$A26,Segments!$A:$A,0),MATCH("2H"&RIGHT(Annual!X$1,2),Segments!$A$3:$AJ$3,0)) -> 65.986564 | AA26: -6.9 | AB26: 36.4 | AC26: 0 | AD26: 36.8 | AE26: 0 | AF26: 41.3
A27: GP-Central | B27: Central | C27: AUDm | O27: =INDEX(Segments!$A:$AJ,MATCH(Annual!$A27,Segments!$A:$A,0),MATCH("1H"&RIGHT(Annual!O$1,2),Segments!$A$3:$AJ$3,0))+INDEX(Segments!$A:$AJ,MATCH(Annual!$A27,Segments!$A:$A,0),MATCH("2H"&RIGHT(Annual!O$1,2),Segments!$A$3:$AJ$3,0)) -> 0 | P27: =INDEX(Segments!$A:$AJ,MATCH(Annual!$A27,Segments!$A:$A,0),MATCH("1H"&RIGHT(Annual!P$1,2),Segments!$A$3:$AJ$3,0))+INDEX(Segments!$A:$AJ,MATCH(Annual!$A27,Segments!$A:$A,0),MATCH("2H"&RIGHT(Annual!P$1,2),Segments!$A$3:$AJ$3,0)) -> 0 | Q27: =INDEX(Segments!$A:$AJ,MATCH(Annual!$A27,Segments!$A:$A,0),MATCH("1H"&RIGHT(Annual!Q$1,2),Segments!$A$3:$AJ$3,0))+INDEX(Segments!$A:$AJ,MATCH(Annual!$A27,Segments!$A:$A,0),MATCH("2H"&RIGHT(Annual!Q$1,2),Segments!$A$3:$AJ$3,0)) -> 0 | R27: =INDEX(Segments!$A:$AJ,MATCH(Annual!$A27,Segments!$A:$A,0),MATCH("1H"&RIGHT(Annual!R$1,2),Segments!$A$3:$AJ$3,0))+INDEX(Segments!$A:$AJ,MATCH(Annual!$A27,Segments!$A:$A,0),MATCH("2H"&RIGHT(Annual!R$1,2),Segments!$A$3:$AJ$3,0)) -> 0 | S27: =INDEX(Segments!$A:$AJ,MATCH(Annual!$A27,Segments!$A:$A,0),MATCH("1H"&RIGHT(Annual!S$1,2),Segments!$A$3:$AJ$3,0))+INDEX(Segments!$A:$AJ,MATCH(Annual!$A27,Segments!$A:$A,0),MATCH("2H"&RIGHT(Annual!S$1,2),Segments!$A$3:$AJ$3,0)) -> 0 | T27: =INDEX(Segments!$A:$AJ,MATCH(Annual!$A27,Segments!$A:$A,0),MATCH("1H"&RIGHT(Annual!T$1,2),Segments!$A$3:$AJ$3,0))+INDEX(Segments!$A:$AJ,MATCH(Annual!$A27,Segments!$A:$A,0),MATCH("2H"&RIGHT(Annual!T$1,2),Segments!$A$3:$AJ$3,0)) -> 0 | U27: =INDEX(Segments!$A:$AJ,MATCH(Annual!$A27,Segments!$A:$A,0),MATCH("1H"&RIGHT(Annual!U$1,2),Segments!$A$3:$AJ$3,0))+INDEX(Segments!$A:$AJ,MATCH(Annual!$A27,Segments!$A:$A,0),MATCH("2H"&RIGHT(Annual!U$1,2),Segments!$A$3:$AJ$3,0)) -> 0 | V27: =INDEX(Segments!$A:$AJ,MATCH(Annual!$A27,Segments!$A:$A,0),MATCH("1H"&RIGHT(Annual!V$1,2),Segments!$A$3:$AJ$3,0))+INDEX(Segments!$A:$AJ,MATCH(Annual!$A27,Segments!$A:$A,0),MATCH("2H"&RIGHT(Annual!V$1,2),Segments!$A$3:$AJ$3,0)) -> 0 | ... X27: =INDEX(Segments!$A:$AJ,MATCH(Annual!$A27,Segments!$A:$A,0),MATCH("1H"&RIGHT(Annual!X$1,2),Segments!$A$3:$AJ$3,0))+INDEX(Segments!$A:$AJ,MATCH(Annual!$A27,Segments!$A:$A,0),MATCH("2H"&RIGHT(Annual!X$1,2),Segments!$A$3:$AJ$3,0)) -> 0 | AA27: -6.9 | AB27: 6.9 | AC27: 0 | AD27: 0 | AE27: 0 | AF27: 0
A28: GP-Inorganic- forecast | B28: Inorganic- forecast | O28: =INDEX(Segments!$A:$AJ,MATCH(Annual!$A28,Segments!$A:$A,0),MATCH("1H"&RIGHT(Annual!O$1,2),Segments!$A$3:$AJ$3,0))+INDEX(Segments!$A:$AJ,MATCH(Annual!$A28,Segments!$A:$A,0),MATCH("2H"&RIGHT(Annual!O$1,2),Segments!$A$3:$AJ$3,0)) -> 2.6703328 | P28: =INDEX(Segments!$A:$AJ,MATCH(Annual!$A28,Segments!$A:$A,0),MATCH("1H"&RIGHT(Annual!P$1,2),Segments!$A$3:$AJ$3,0))+INDEX(Segments!$A:$AJ,MATCH(Annual!$A28,Segments!$A:$A,0),MATCH("2H"&RIGHT(Annual!P$1,2),Segments!$A$3:$AJ$3,0)) -> 7.5405477 | Q28: =INDEX(Segments!$A:$AJ,MATCH(Annual!$A28,Segments!$A:$A,0),MATCH("1H"&RIGHT(Annual!Q$1,2),Segments!$A$3:$AJ$3,0))+INDEX(Segments!$A:$AJ,MATCH(Annual!$A28,Segments!$A:$A,0),MATCH("2H"&RIGHT(Annual!Q$1,2),Segments!$A$3:$AJ$3,0)) -> 16.10429 | R28: =INDEX(Segments!$A:$AJ,MATCH(Annual!$A28,Segments!$A:$A,0),MATCH("1H"&RIGHT(Annual!R$1,2),Segments!$A$3:$AJ$3,0))+INDEX(Segments!$A:$AJ,MATCH(Annual!$A28,Segments!$A:$A,0),MATCH("2H"&RIGHT(Annual!R$1,2),Segments!$A$3:$AJ$3,0)) -> 25.844945 | S28: =INDEX(Segments!$A:$AJ,MATCH(Annual!$A28,Segments!$A:$A,0),MATCH("1H"&RIGHT(Annual!S$1,2),Segments!$A$3:$AJ$3,0))+INDEX(Segments!$A:$AJ,MATCH(Annual!$A28,Segments!$A:$A,0),MATCH("2H"&RIGHT(Annual!S$1,2),Segments!$A$3:$AJ$3,0)) -> 37.267985 | T28: =INDEX(Segments!$A:$AJ,MATCH(Annual!$A28,Segments!$A:$A,0),MATCH("1H"&RIGHT(Annual!T$1,2),Segments!$A$3:$AJ$3,0))+INDEX(Segments!$A:$AJ,MATCH(Annual!$A28,Segments!$A:$A,0),MATCH("2H"&RIGHT(Annual!T$1,2),Segments!$A$3:$AJ$3,0)) -> 50.417923 | U28: =INDEX(Segments!$A:$AJ,MATCH(Annual!$A28,Segments!$A:$A,0),MATCH("1H"&RIGHT(Annual!U$1,2),Segments!$A$3:$AJ$3,0))+INDEX(Segments!$A:$AJ,MATCH(Annual!$A28,Segments!$A:$A,0),MATCH("2H"&RIGHT(Annual!U$1,2),Segments!$A$3:$AJ$3,0)) -> 65.523674 | V28: =INDEX(Segments!$A:$AJ,MATCH(Annual!$A28,Segments!$A:$A,0),MATCH("1H"&RIGHT(Annual!V$1,2),Segments!$A$3:$AJ$3,0))+INDEX(Segments!$A:$AJ,MATCH(Annual!$A28,Segments!$A:$A,0),MATCH("2H"&RIGHT(Annual!V$1,2),Segments!$A$3:$AJ$3,0)) -> 82.843116 | ... X28: =INDEX(Segments!$A:$AJ,MATCH(Annual!$A28,Segments!$A:$A,0),MATCH("1H"&RIGHT(Annual!X$1,2),Segments!$A$3:$AJ$3,0))+INDEX(Segments!$A:$AJ,MATCH(Annual!$A28,Segments!$A:$A,0),MATCH("2H"&RIGHT(Annual!X$1,2),Segments!$A$3:$AJ$3,0)) -> 125.32157
A29: GP-Gross Profit and Other income excluding trail book adjustment | B29: Gross Profit and Other income excluding trail book adjustment | C29: AUDm | D29: Preso | F29: 63.8 | G29: 78.5 | H29: 84 | I29: 102.5 | J29: 114.4 | K29: =SUM(K25:K28) -> 142.6 | L29: =SUM(L25:L28) -> 144.2 | M29: =SUM(M25:M28) -> 127 | N29: =SUM(N25:N28) -> 142.8 | O29: =INDEX(Segments!$A:$AJ,MATCH(Annual!$A29,Segments!$A:$A,0),MATCH("1H"&RIGHT(Annual!O$1,2),Segments!$A$3:$AJ$3,0))+INDEX(Segments!$A:$AJ,MATCH(Annual!$A29,Segments!$A:$A,0),MATCH("2H"&RIGHT(Annual!O$1,2),Segments!$A$3:$AJ$3,0)) -> 169.97388 | P29: =INDEX(Segments!$A:$AJ,MATCH(Annual!$A29,Segments!$A:$A,0),MATCH("1H"&RIGHT(Annual!P$1,2),Segments!$A$3:$AJ$3,0))+INDEX(Segments!$A:$AJ,MATCH(Annual!$A29,Segments!$A:$A,0),MATCH("2H"&RIGHT(Annual!P$1,2),Segments!$A$3:$AJ$3,0)) -> 191.3708 | Q29: =INDEX(Segments!$A:$AJ,MATCH(Annual!$A29,Segments!$A:$A,0),MATCH("1H"&RIGHT(Annual!Q$1,2),Segments!$A$3:$AJ$3,0))+INDEX(Segments!$A:$AJ,MATCH(Annual!$A29,Segments!$A:$A,0),MATCH("2H"&RIGHT(Annual!Q$1,2),Segments!$A$3:$AJ$3,0)) -> 211.78351 | R29: =INDEX(Segments!$A:$AJ,MATCH(Annual!$A29,Segments!$A:$A,0),MATCH("1H"&RIGHT(Annual!R$1,2),Segments!$A$3:$AJ$3,0))+INDEX(Segments!$A:$AJ,MATCH(Annual!$A29,Segments!$A:$A,0),MATCH("2H"&RIGHT(Annual!R$1,2),Segments!$A$3:$AJ$3,0)) -> 233.58281 | S29: =INDEX(Segments!$A:$AJ,MATCH(Annual!$A29,Segments!$A:$A,0),MATCH("1H"&RIGHT(Annual!S$1,2),Segments!$A$3:$AJ$3,0))+INDEX(Segments!$A:$AJ,MATCH(Annual!$A29,Segments!$A:$A,0),MATCH("2H"&RIGHT(Annual!S$1,2),Segments!$A$3:$AJ$3,0)) -> 257.91029 | T29: =INDEX(Segments!$A:$AJ,MATCH(Annual!$A29,Segments!$A:$A,0),MATCH("1H"&RIGHT(Annual!T$1,2),Segments!$A$3:$AJ$3,0))+INDEX(Segments!$A:$AJ,MATCH(Annual!$A29,Segments!$A:$A,0),MATCH("2H"&RIGHT(Annual!T$1,2),Segments!$A$3:$AJ$3,0)) -> 283.5893 | U29: =INDEX(Segments!$A:$AJ,MATCH(Annual!$A29,Segments!$A:$A,0),MATCH("1H"&RIGHT(Annual!U$1,2),Segments!$A$3:$AJ$3,0))+INDEX(Segments!$A:$AJ,MATCH(Annual!$A29,Segments!$A:$A,0),MATCH("2H"&RIGHT(Annual!U$1,2),Segments!$A$3:$AJ$3,0)) -> 311.95459 | V29: =INDEX(Segments!$A:$AJ,MATCH(Annual!$A29,Segments!$A:$A,0),MATCH("1H"&RIGHT(Annual!V$1,2),Segments!$A$3:$AJ$3,0))+INDEX(Segments!$A:$AJ,MATCH(Annual!$A29,Segments!$A:$A,0),MATCH("2H"&RIGHT(Annual!V$1,2),Segments!$A$3:$AJ$3,0)) -> 343.30721 | ... X29: =INDEX(Segments!$A:$AJ,MATCH(Annual!$A29,Segments!$A:$A,0),MATCH("1H"&RIGHT(Annual!X$1,2),Segments!$A$3:$AJ$3,0))+INDEX(Segments!$A:$AJ,MATCH(Annual!$A29,Segments!$A:$A,0),MATCH("2H"&RIGHT(Annual!X$1,2),Segments!$A$3:$AJ$3,0)) -> 416.35875 | AA29: 18 | AB29: 124.8 | AC29: 46.3 | AD29: 131.1 | AE29: 61.9 | AF29: 144.5
B30: Growth | C30: % YoY | G30: =G29/F29-1 -> 0.23040752 | H30: =H29/G29-1 -> 0.070063694 | I30: =I29/H29-1 -> 0.2202381 | J30: =J29/I29-1 -> 0.11609756 | K30: =K29/J29-1 -> 0.2465035 | L30: =L29/K29-1 -> 0.011220196 | M30: =M29/L29-1 -> -0.11927878 | N30: =N29/M29-1 -> 0.12440945 | ... X30: =X29/W29-1 -> 0.10152655 | AA30: 0 | AC30: 0.1 | AE30: 0.2 | AF30: 0
A32: Number of acquired brokers | B32: Number of acquired brokers | C32: # | N32: 2 | O32: =INDEX(Segments!$A:$AJ,MATCH(Annual!$A32,Segments!$A:$A,0),MATCH("1H"&RIGHT(Annual!O$1,2),Segments!$A$3:$AJ$3,0))+INDEX(Segments!$A:$AJ,MATCH(Annual!$A32,Segments!$A:$A,0),MATCH("2H"&RIGHT(Annual!O$1,2),Segments!$A$3:$AJ$3,0)) -> 4 | P32: =INDEX(Segments!$A:$AJ,MATCH(Annual!$A32,Segments!$A:$A,0),MATCH("1H"&RIGHT(Annual!P$1,2),Segments!$A$3:$AJ$3,0))+INDEX(Segments!$A:$AJ,MATCH(Annual!$A32,Segments!$A:$A,0),MATCH("2H"&RIGHT(Annual!P$1,2),Segments!$A$3:$AJ$3,0)) -> 8 | Q32: =INDEX(Segments!$A:$AJ,MATCH(Annual!$A32,Segments!$A:$A,0),MATCH("1H"&RIGHT(Annual!Q$1,2),Segments!$A$3:$AJ$3,0))+INDEX(Segments!$A:$AJ,MATCH(Annual!$A32,Segments!$A:$A,0),MATCH("2H"&RIGHT(Annual!Q$1,2),Segments!$A$3:$AJ$3,0)) -> 8.56 | R32: =INDEX(Segments!$A:$AJ,MATCH(Annual!$A32,Segments!$A:$A,0),MATCH("1H"&RIGHT(Annual!R$1,2),Segments!$A$3:$AJ$3,0))+INDEX(Segments!$A:$AJ,MATCH(Annual!$A32,Segments!$A:$A,0),MATCH("2H"&RIGHT(Annual!R$1,2),Segments!$A$3:$AJ$3,0)) -> 9.1592 | S32: =INDEX(Segments!$A:$AJ,MATCH(Annual!$A32,Segments!$A:$A,0),MATCH("1H"&RIGHT(Annual!S$1,2),Segments!$A$3:$AJ$3,0))+INDEX(Segments!$A:$AJ,MATCH(Annual!$A32,Segments!$A:$A,0),MATCH("2H"&RIGHT(Annual!S$1,2),Segments!$A$3:$AJ$3,0)) -> 9.800344 | T32: =INDEX(Segments!$A:$AJ,MATCH(Annual!$A32,Segments!$A:$A,0),MATCH("1H"&RIGHT(Annual!T$1,2),Segments!$A$3:$AJ$3,0))+INDEX(Segments!$A:$AJ,MATCH(Annual!$A32,Segments!$A:$A,0),MATCH("2H"&RIGHT(Annual!T$1,2),Segments!$A$3:$AJ$3,0)) -> 10.486368 | U32: =INDEX(Segments!$A:$AJ,MATCH(Annual!$A32,Segments!$A:$A,0),MATCH("1H"&RIGHT(Annual!U$1,2),Segments!$A$3:$AJ$3,0))+INDEX(Segments!$A:$AJ,MATCH(Annual!$A32,Segments!$A:$A,0),MATCH("2H"&RIGHT(Annual!U$1,2),Segments!$A$3:$AJ$3,0)) -> 11.220414 | V32: =INDEX(Segments!$A:$AJ,MATCH(Annual!$A32,Segments!$A:$A,0),MATCH("1H"&RIGHT(Annual!V$1,2),Segments!$A$3:$AJ$3,0))+INDEX(Segments!$A:$AJ,MATCH(Annual!$A32,Segments!$A:$A,0),MATCH("2H"&RIGHT(Annual!V$1,2),Segments!$A$3:$AJ$3,0)) -> 12.005843 | ... X32: =INDEX(Segments!$A:$AJ,MATCH(Annual!$A32,Segments!$A:$A,0),MATCH("1H"&RIGHT(Annual!X$1,2),Segments!$A$3:$AJ$3,0))+INDEX(Segments!$A:$AJ,MATCH(Annual!$A32,Segments!$A:$A,0),MATCH("2H"&RIGHT(Annual!X$1,2),Segments!$A$3:$AJ$3,0)) -> 13.745489
A33: Number of acquired brokers cumulative | B33: Number of acquired brokers cumulative | C33: # | N33: =INDEX(Segments!$A:$AJ,MATCH(Annual!$A33,Segments!$A:$A,0),MATCH("2H"&RIGHT(Annual!N$1,2),Segments!$A$3:$AJ$3,0)) -> 2 | O33: =INDEX(Segments!$A:$AJ,MATCH(Annual!$A33,Segments!$A:$A,0),MATCH("2H"&RIGHT(Annual!O$1,2),Segments!$A$3:$AJ$3,0)) -> 6 | P33: =INDEX(Segments!$A:$AJ,MATCH(Annual!$A33,Segments!$A:$A,0),MATCH("2H"&RIGHT(Annual!P$1,2),Segments!$A$3:$AJ$3,0)) -> 14 | Q33: =INDEX(Segments!$A:$AJ,MATCH(Annual!$A33,Segments!$A:$A,0),MATCH("2H"&RIGHT(Annual!Q$1,2),Segments!$A$3:$AJ$3,0)) -> 22.56 | R33: =INDEX(Segments!$A:$AJ,MATCH(Annual!$A33,Segments!$A:$A,0),MATCH("2H"&RIGHT(Annual!R$1,2),Segments!$A$3:$AJ$3,0)) -> 31.7192 | S33: =INDEX(Segments!$A:$AJ,MATCH(Annual!$A33,Segments!$A:$A,0),MATCH("2H"&RIGHT(Annual!S$1,2),Segments!$A$3:$AJ$3,0)) -> 41.519544 | T33: =INDEX(Segments!$A:$AJ,MATCH(Annual!$A33,Segments!$A:$A,0),MATCH("2H"&RIGHT(Annual!T$1,2),Segments!$A$3:$AJ$3,0)) -> 52.005912 | U33: =INDEX(Segments!$A:$AJ,MATCH(Annual!$A33,Segments!$A:$A,0),MATCH("2H"&RIGHT(Annual!U$1,2),Segments!$A$3:$AJ$3,0)) -> 63.226326 | ... X33: =INDEX(Segments!$A:$AJ,MATCH(Annual!$A33,Segments!$A:$A,0),MATCH("2H"&RIGHT(Annual!X$1,2),Segments!$A$3:$AJ$3,0)) -> 101.82391
B34: FY29 Aspiration | R34: 35
A35: EBITDA per acquired broker | B35: EBITDA per acquired broker | C35: AUDm | N35: =0.85/2 -> 0.425 | O35: =INDEX(Segments!$A:$AJ,MATCH(Annual!$A35,Segments!$A:$A,0),MATCH("2H"&RIGHT(Annual!O$1,2),Segments!$A$3:$AJ$3,0)) -> 0.48875 | P35: =INDEX(Segments!$A:$AJ,MATCH(Annual!$A35,Segments!$A:$A,0),MATCH("2H"&RIGHT(Annual!P$1,2),Segments!$A$3:$AJ$3,0)) -> 0.537625 | Q35: =INDEX(Segments!$A:$AJ,MATCH(Annual!$A35,Segments!$A:$A,0),MATCH("2H"&RIGHT(Annual!Q$1,2),Segments!$A$3:$AJ$3,0)) -> 0.5698825 | R35: =INDEX(Segments!$A:$AJ,MATCH(Annual!$A35,Segments!$A:$A,0),MATCH("2H"&RIGHT(Annual!R$1,2),Segments!$A$3:$AJ$3,0)) -> 0.60407545 | S35: =INDEX(Segments!$A:$AJ,MATCH(Annual!$A35,Segments!$A:$A,0),MATCH("2H"&RIGHT(Annual!S$1,2),Segments!$A$3:$AJ$3,0)) -> 0.64031998 | T35: =INDEX(Segments!$A:$AJ,MATCH(Annual!$A35,Segments!$A:$A,0),MATCH("2H"&RIGHT(Annual!T$1,2),Segments!$A$3:$AJ$3,0)) -> 0.67873918 | U35: =INDEX(Segments!$A:$AJ,MATCH(Annual!$A35,Segments!$A:$A,0),MATCH("2H"&RIGHT(Annual!U$1,2),Segments!$A$3:$AJ$3,0)) -> 0.71946353 | V35: =INDEX(Segments!$A:$AJ,MATCH(Annual!$A35,Segments!$A:$A,0),MATCH("2H"&RIGHT(Annual!V$1,2),Segments!$A$3:$AJ$3,0)) -> 0.76263134 | ... X35: =INDEX(Segments!$A:$AJ,MATCH(Annual!$A35,Segments!$A:$A,0),MATCH("2H"&RIGHT(Annual!X$1,2),Segments!$A$3:$AJ$3,0)) -> 0.85689257
N36: =6/6.5/2 -> 0.46153846
B37: Operating Expenses
A38: Opex-Distribution | B38: Distribution | C38: AUDm | D38: AR | M38: =M47-M25 -> -42.8 | N38: =N47-N25 -> -45.4 | AA38: -28.6 | AB38: -16.8 | AC38: 0 | AD38: 0 | AE38: 0 | AF38: 0
A39: Opex-Manuracturing | B39: Manuracturing | C39: AUDm | M39: =M48-M26 -> -12.1 | N39: =N48-N26 -> -13.4 | AA39: -6.9 | AB39: -6.5 | AC39: 0 | AD39: 0 | AE39: 0 | AF39: 0
A40: Opex-Central | B40: Central | C40: AUDm | M40: =M49-M27 -> -24.7 | N40: =N49-N27 -> -27.8 | AA40: 0 | AB40: -27.8 | AC40: 0 | AD40: 0 | AE40: 0 | AF40: 0
