Workbook
Name A_ALL_COL.AX: #REF!
Name Abnormals_PostTAX: #REF!
Name AEndDrinks_Sales: #REF!
Name Continuing_sales: #REF!
Name DCF_INF: #REF!
Name DPS: #REF!
Name E_ALL_COL.AX: #REF!
Name EPS_Pre_Goodwill: #REF!
Name L_ALL_COL.AX: #REF!
Name NET_PROFIT: #REF!
Name NPAT_post_Abn: #REF!
Name Sales_Aust_FL: #REF!
Name Sales_NZ_FL: #REF!
Name TOTAL_SALES: #REF!
Name V_ALL_COL.AX: #REF!

Sheet __FDSCACHE__
B1: This sheet contains FactSet XML data for use with this workbook's =FDS codes. Modifying the worksheet's contents may damage the workbook's =FDS functionality.

Sheet Cover
B5: Coles Group (COL.AX)
B6: Rating | C6: Neutral
B7: Target Price/ Target price period/ Upside/downside to target price | C7: A$23/ 12 Month/ 5.7%
B8: M&A probability (1 = high, 3 = low) | C8: 3
B9: Market Cap (US$ mn) (price as of ______):
B10: Current shares outstanding (mn):
B11: Currency: | C11: AUD
B12: Current Publication Date: | C12: 46066
B13: Previous Publication Date:
B15: Team Contacts:
B16: Lead Analyst
B17: Peter Marks, peter.marks@gs.com, +61 2 9321 8846, Goldman Sachs Australia Pty Ltd
B18: Consumer Team
B19: James Leigh, james.leigh@gs.com, +61 2 , Goldman Sachs Australia Pty Ltd
B20: Consumer Team
B21: Rayanne Haidar, rayanne.haidar@gs.com +61 2 9321 8739, Goldman Sachs Australia Pty Ltd

Sheet Summary
D1: Coles Group (COL.AX)
D6: Goldman Sachs | Coles Group | COL-AU
D8: Price target | F8: =Valuation!$E$26 -> 23
D9: Current share price | F9: 21.76
D10: Upside / downside | F10: =F8/F9-1 -> 0.056985294
D11: Recommendation | F11: NEUTRAL
A13: Col C | B13: Col K | D13: P&L | E13: FY23 | F13: FY24 | G13: FY25 | H13: FY26E | I13: FY27E | J13: FY28E | L13: Balance sheet | M13: =E$13 -> FY23 | N13: =F$13 -> FY24 | O13: =G$13 -> FY25 | P13: =H$13 -> FY26E | Q13: =I$13 -> FY27E | R13: =J$13 -> FY28E
A14: - | B14: Cash | D14: Sales | L14: Cash | M14: =VLOOKUP($B14,BS!$1:$1048576,MATCH(Summary!M$13,CF!$3:$3,0),FALSE) -> 597 | N14: =VLOOKUP($B14,BS!$1:$1048576,MATCH(Summary!N$13,CF!$3:$3,0),FALSE) -> 675 | O14: =VLOOKUP($B14,BS!$1:$1048576,MATCH(Summary!O$13,CF!$3:$3,0),FALSE) -> 705 | P14: =VLOOKUP($B14,BS!$1:$1048576,MATCH(Summary!P$13,CF!$3:$3,0),FALSE) -> 737.00077 | Q14: =VLOOKUP($B14,BS!$1:$1048576,MATCH(Summary!Q$13,CF!$3:$3,0),FALSE) -> 781.50581 | R14: =VLOOKUP($B14,BS!$1:$1048576,MATCH(Summary!R$13,CF!$3:$3,0),FALSE) -> 852.91405
A15: Food Sales | B15: TR | D15: Food | E15: =VLOOKUP($A15,Model!$1:$1048576,MATCH(Summary!E$13,Model!$3:$3,0),FALSE) -> 36746 | F15: =VLOOKUP($A15,Model!$1:$1048576,MATCH(Summary!F$13,Model!$3:$3,0),FALSE) -> 39042 | G15: =VLOOKUP($A15,Model!$1:$1048576,MATCH(Summary!G$13,Model!$3:$3,0),FALSE) -> 39987 | H15: =VLOOKUP($A15,Model!$1:$1048576,MATCH(Summary!H$13,Model!$3:$3,0),FALSE) -> 41681.565 | I15: =VLOOKUP($A15,Model!$1:$1048576,MATCH(Summary!I$13,Model!$3:$3,0),FALSE) -> 43506.93 | J15: =VLOOKUP($A15,Model!$1:$1048576,MATCH(Summary!J$13,Model!$3:$3,0),FALSE) -> 45404.069 | L15: Trade receivables | M15: =VLOOKUP($B15,BS!$1:$1048576,MATCH(Summary!M$13,CF!$3:$3,0),FALSE) -> 605 | N15: =VLOOKUP($B15,BS!$1:$1048576,MATCH(Summary!N$13,CF!$3:$3,0),FALSE) -> 496 | O15: =VLOOKUP($B15,BS!$1:$1048576,MATCH(Summary!O$13,CF!$3:$3,0),FALSE) -> 487 | P15: =VLOOKUP($B15,BS!$1:$1048576,MATCH(Summary!P$13,CF!$3:$3,0),FALSE) -> 503.09134 | Q15: =VLOOKUP($B15,BS!$1:$1048576,MATCH(Summary!Q$13,CF!$3:$3,0),FALSE) -> 518.65139 | R15: =VLOOKUP($B15,BS!$1:$1048576,MATCH(Summary!R$13,CF!$3:$3,0),FALSE) -> 540.50588
A16: Liquor Sales | B16: Inventory | D16: Liquor | E16: =VLOOKUP($A16,Model!$1:$1048576,MATCH(Summary!E$13,Model!$3:$3,0),FALSE) -> 3610 | F16: =VLOOKUP($A16,Model!$1:$1048576,MATCH(Summary!F$13,Model!$3:$3,0),FALSE) -> 3692 | G16: =VLOOKUP($A16,Model!$1:$1048576,MATCH(Summary!G$13,Model!$3:$3,0),FALSE) -> 3667 | H16: =VLOOKUP($A16,Model!$1:$1048576,MATCH(Summary!H$13,Model!$3:$3,0),FALSE) -> 3636.7032 | I16: =VLOOKUP($A16,Model!$1:$1048576,MATCH(Summary!I$13,Model!$3:$3,0),FALSE) -> 3727.6207 | J16: =VLOOKUP($A16,Model!$1:$1048576,MATCH(Summary!J$13,Model!$3:$3,0),FALSE) -> 3820.8113 | L16: Inventories | M16: =VLOOKUP($B16,BS!$1:$1048576,MATCH(Summary!M$13,CF!$3:$3,0),FALSE) -> 2323 | N16: =VLOOKUP($B16,BS!$1:$1048576,MATCH(Summary!N$13,CF!$3:$3,0),FALSE) -> 2703 | O16: =VLOOKUP($B16,BS!$1:$1048576,MATCH(Summary!O$13,CF!$3:$3,0),FALSE) -> 2733 | P16: =VLOOKUP($B16,BS!$1:$1048576,MATCH(Summary!P$13,CF!$3:$3,0),FALSE) -> 2823.3032 | Q16: =VLOOKUP($B16,BS!$1:$1048576,MATCH(Summary!Q$13,CF!$3:$3,0),FALSE) -> 2910.6247 | R16: =VLOOKUP($B16,BS!$1:$1048576,MATCH(Summary!R$13,CF!$3:$3,0),FALSE) -> 3033.2702
A17: Corporate/Other Sales | D17: Corporate / Other | E17: =VLOOKUP($A17,Model!$1:$1048576,MATCH(Summary!E$13,Model!$3:$3,0),FALSE) -> 127 | F17: =VLOOKUP($A17,Model!$1:$1048576,MATCH(Summary!F$13,Model!$3:$3,0),FALSE) -> 837 | G17: =VLOOKUP($A17,Model!$1:$1048576,MATCH(Summary!G$13,Model!$3:$3,0),FALSE) -> 698 | H17: =VLOOKUP($A17,Model!$1:$1048576,MATCH(Summary!H$13,Model!$3:$3,0),FALSE) -> 499.2 | I17: =VLOOKUP($A17,Model!$1:$1048576,MATCH(Summary!I$13,Model!$3:$3,0),FALSE) -> 0 | J17: =VLOOKUP($A17,Model!$1:$1048576,MATCH(Summary!J$13,Model!$3:$3,0),FALSE) -> 0 | L17: Other current assets | M17: =M18-SUM(M14:M16) -> 227 | N17: =N18-SUM(N14:N16) -> 112 | O17: =O18-SUM(O14:O16) -> 253 | P17: =P18-SUM(P14:P16) -> 253 | Q17: =Q18-SUM(Q14:Q16) -> 253 | R17: =R18-SUM(R14:R16) -> 253
A18: Total Sales | B18: CA | D18: Total sales | E18: =VLOOKUP($A18,Model!$1:$1048576,MATCH(Summary!E$13,Model!$3:$3,0),FALSE) -> 40483 | F18: =VLOOKUP($A18,Model!$1:$1048576,MATCH(Summary!F$13,Model!$3:$3,0),FALSE) -> 43571 | G18: =VLOOKUP($A18,Model!$1:$1048576,MATCH(Summary!G$13,Model!$3:$3,0),FALSE) -> 44352 | H18: =VLOOKUP($A18,Model!$1:$1048576,MATCH(Summary!H$13,Model!$3:$3,0),FALSE) -> 45817.469 | I18: =VLOOKUP($A18,Model!$1:$1048576,MATCH(Summary!I$13,Model!$3:$3,0),FALSE) -> 47234.551 | J18: =VLOOKUP($A18,Model!$1:$1048576,MATCH(Summary!J$13,Model!$3:$3,0),FALSE) -> 49224.881 | L18: Current assets | M18: =VLOOKUP($B18,BS!$1:$1048576,MATCH(Summary!M$13,CF!$3:$3,0),FALSE) -> 3752 | N18: =VLOOKUP($B18,BS!$1:$1048576,MATCH(Summary!N$13,CF!$3:$3,0),FALSE) -> 3986 | O18: =VLOOKUP($B18,BS!$1:$1048576,MATCH(Summary!O$13,CF!$3:$3,0),FALSE) -> 4178 | P18: =VLOOKUP($B18,BS!$1:$1048576,MATCH(Summary!P$13,CF!$3:$3,0),FALSE) -> 4316.3953 | Q18: =VLOOKUP($B18,BS!$1:$1048576,MATCH(Summary!Q$13,CF!$3:$3,0),FALSE) -> 4463.7819 | R18: =VLOOKUP($B18,BS!$1:$1048576,MATCH(Summary!R$13,CF!$3:$3,0),FALSE) -> 4679.6901
A19: EBITDA | B19: Fixed Assets | D19: EBITDA | E19: =VLOOKUP($A19,PL!$1:$1048576,MATCH(Summary!E$13,PL!$3:$3,0),FALSE) -> 3382 | F19: =VLOOKUP($A19,PL!$1:$1048576,MATCH(Summary!F$13,PL!$3:$3,0),FALSE) -> 3659 | G19: =VLOOKUP($A19,PL!$1:$1048576,MATCH(Summary!G$13,PL!$3:$3,0),FALSE) -> 3941 | H19: =VLOOKUP($A19,PL!$1:$1048576,MATCH(Summary!H$13,PL!$3:$3,0),FALSE) -> 4356.119 | I19: =VLOOKUP($A19,PL!$1:$1048576,MATCH(Summary!I$13,PL!$3:$3,0),FALSE) -> 4637.2421 | J19: =VLOOKUP($A19,PL!$1:$1048576,MATCH(Summary!J$13,PL!$3:$3,0),FALSE) -> 4872.858 | L19: PPE | M19: =VLOOKUP($B19,BS!$1:$1048576,MATCH(Summary!M$13,CF!$3:$3,0),FALSE) -> 4985 | N19: =VLOOKUP($B19,BS!$1:$1048576,MATCH(Summary!N$13,CF!$3:$3,0),FALSE) -> 5619 | O19: =VLOOKUP($B19,BS!$1:$1048576,MATCH(Summary!O$13,CF!$3:$3,0),FALSE) -> 5866 | P19: =VLOOKUP($B19,BS!$1:$1048576,MATCH(Summary!P$13,CF!$3:$3,0),FALSE) -> 6072.925 | Q19: =VLOOKUP($B19,BS!$1:$1048576,MATCH(Summary!Q$13,CF!$3:$3,0),FALSE) -> 6271.353 | R19: =VLOOKUP($B19,BS!$1:$1048576,MATCH(Summary!R$13,CF!$3:$3,0),FALSE) -> 6460.4169
A20: D&A | B20: ROU | D20: D&A | E20: =VLOOKUP($A20,PL!$1:$1048576,MATCH(Summary!E$13,PL!$3:$3,0),FALSE) -> -1523 | F20: =VLOOKUP($A20,PL!$1:$1048576,MATCH(Summary!F$13,PL!$3:$3,0),FALSE) -> -1602 | G20: =VLOOKUP($A20,PL!$1:$1048576,MATCH(Summary!G$13,PL!$3:$3,0),FALSE) -> -1829 | H20: =VLOOKUP($A20,PL!$1:$1048576,MATCH(Summary!H$13,PL!$3:$3,0),FALSE) -> -1947.885 | I20: =VLOOKUP($A20,PL!$1:$1048576,MATCH(Summary!I$13,PL!$3:$3,0),FALSE) -> -2025.8004 | J20: =VLOOKUP($A20,PL!$1:$1048576,MATCH(Summary!J$13,PL!$3:$3,0),FALSE) -> -2106.8324 | L20: RoU Assets | M20: =VLOOKUP($B20,BS!$1:$1048576,MATCH(Summary!M$13,CF!$3:$3,0),FALSE) -> 6507 | N20: =VLOOKUP($B20,BS!$1:$1048576,MATCH(Summary!N$13,CF!$3:$3,0),FALSE) -> 7048 | O20: =VLOOKUP($B20,BS!$1:$1048576,MATCH(Summary!O$13,CF!$3:$3,0),FALSE) -> 6942 | P20: =VLOOKUP($B20,BS!$1:$1048576,MATCH(Summary!P$13,CF!$3:$3,0),FALSE) -> 6987.19 | Q20: =VLOOKUP($B20,BS!$1:$1048576,MATCH(Summary!Q$13,CF!$3:$3,0),FALSE) -> 7048.9616 | R20: =VLOOKUP($B20,BS!$1:$1048576,MATCH(Summary!R$13,CF!$3:$3,0),FALSE) -> 7128.6453
B21: Intangibles | D21: EBIT | L21: Intangibles | M21: =VLOOKUP($B21,BS!$1:$1048576,MATCH(Summary!M$13,CF!$3:$3,0),FALSE) -> 2035 | N21: =VLOOKUP($B21,BS!$1:$1048576,MATCH(Summary!N$13,CF!$3:$3,0),FALSE) -> 2203 | O21: =VLOOKUP($B21,BS!$1:$1048576,MATCH(Summary!O$13,CF!$3:$3,0),FALSE) -> 2246 | P21: =VLOOKUP($B21,BS!$1:$1048576,MATCH(Summary!P$13,CF!$3:$3,0),FALSE) -> 2246 | Q21: =VLOOKUP($B21,BS!$1:$1048576,MATCH(Summary!Q$13,CF!$3:$3,0),FALSE) -> 2246 | R21: =VLOOKUP($B21,BS!$1:$1048576,MATCH(Summary!R$13,CF!$3:$3,0),FALSE) -> 2246
A22: Food EBIT | D22: Food | E22: =VLOOKUP($A22,Model!$1:$1048576,MATCH(Summary!E$13,Model!$3:$3,0),FALSE) -> 1765 | F22: =VLOOKUP($A22,Model!$1:$1048576,MATCH(Summary!F$13,Model!$3:$3,0),FALSE) -> 2018 | G22: =VLOOKUP($A22,Model!$1:$1048576,MATCH(Summary!G$13,Model!$3:$3,0),FALSE) -> 2108 | H22: =VLOOKUP($A22,Model!$1:$1048576,MATCH(Summary!H$13,Model!$3:$3,0),FALSE) -> 2430.6327 | I22: =VLOOKUP($A22,Model!$1:$1048576,MATCH(Summary!I$13,Model!$3:$3,0),FALSE) -> 2618.7813 | J22: =VLOOKUP($A22,Model!$1:$1048576,MATCH(Summary!J$13,Model!$3:$3,0),FALSE) -> 2771.5222 | L22: Other non current assets | M22: =M23-SUM(M19:M21) -> 1013 | N22: =N23-SUM(N19:N21) -> 1014 | O22: =O23-SUM(O19:O21) -> 1062 | P22: =P23-SUM(P19:P21) -> 1062 | Q22: =Q23-SUM(Q19:Q21) -> 1062 | R22: =R23-SUM(R19:R21) -> 1062
A23: Liquor EBIT | B23: NCA | D23: Liquor | E23: =VLOOKUP($A23,Model!$1:$1048576,MATCH(Summary!E$13,Model!$3:$3,0),FALSE) -> 157 | F23: =VLOOKUP($A23,Model!$1:$1048576,MATCH(Summary!F$13,Model!$3:$3,0),FALSE) -> 133 | G23: =VLOOKUP($A23,Model!$1:$1048576,MATCH(Summary!G$13,Model!$3:$3,0),FALSE) -> 113 | H23: =VLOOKUP($A23,Model!$1:$1048576,MATCH(Summary!H$13,Model!$3:$3,0),FALSE) -> 86.374645 | I23: =VLOOKUP($A23,Model!$1:$1048576,MATCH(Summary!I$13,Model!$3:$3,0),FALSE) -> 111.17674 | J23: =VLOOKUP($A23,Model!$1:$1048576,MATCH(Summary!J$13,Model!$3:$3,0),FALSE) -> 116.42514 | L23: Non-current assets | M23: =VLOOKUP($B23,BS!$1:$1048576,MATCH(Summary!M$13,CF!$3:$3,0),FALSE) -> 14540 | N23: =VLOOKUP($B23,BS!$1:$1048576,MATCH(Summary!N$13,CF!$3:$3,0),FALSE) -> 15884 | O23: =VLOOKUP($B23,BS!$1:$1048576,MATCH(Summary!O$13,CF!$3:$3,0),FALSE) -> 16116 | P23: =VLOOKUP($B23,BS!$1:$1048576,MATCH(Summary!P$13,CF!$3:$3,0),FALSE) -> 16368.115 | Q23: =VLOOKUP($B23,BS!$1:$1048576,MATCH(Summary!Q$13,CF!$3:$3,0),FALSE) -> 16628.315 | R23: =VLOOKUP($B23,BS!$1:$1048576,MATCH(Summary!R$13,CF!$3:$3,0),FALSE) -> 16897.062
A24: Corporate/Other EBIT | B24: TP | D24: Corporate / Other | E24: =VLOOKUP($A24,Model!$1:$1048576,MATCH(Summary!E$13,Model!$3:$3,0),FALSE) -> -63 | F24: =VLOOKUP($A24,Model!$1:$1048576,MATCH(Summary!F$13,Model!$3:$3,0),FALSE) -> -94 | G24: =VLOOKUP($A24,Model!$1:$1048576,MATCH(Summary!G$13,Model!$3:$3,0),FALSE) -> -109 | H24: =VLOOKUP($A24,Model!$1:$1048576,MATCH(Summary!H$13,Model!$3:$3,0),FALSE) -> -108.77332 | I24: =VLOOKUP($A24,Model!$1:$1048576,MATCH(Summary!I$13,Model!$3:$3,0),FALSE) -> -118.5163 | J24: =VLOOKUP($A24,Model!$1:$1048576,MATCH(Summary!J$13,Model!$3:$3,0),FALSE) -> -121.92179 | L24: Trade payables | M24: =VLOOKUP($B24,BS!$1:$1048576,MATCH(Summary!M$13,CF!$3:$3,0),FALSE) -> 4434 | N24: =VLOOKUP($B24,BS!$1:$1048576,MATCH(Summary!N$13,CF!$3:$3,0),FALSE) -> 4584 | O24: =VLOOKUP($B24,BS!$1:$1048576,MATCH(Summary!O$13,CF!$3:$3,0),FALSE) -> 4637 | P24: =VLOOKUP($B24,BS!$1:$1048576,MATCH(Summary!P$13,CF!$3:$3,0),FALSE) -> 4790.2147 | Q24: =VLOOKUP($B24,BS!$1:$1048576,MATCH(Summary!Q$13,CF!$3:$3,0),FALSE) -> 4938.3706 | R24: =VLOOKUP($B24,BS!$1:$1048576,MATCH(Summary!R$13,CF!$3:$3,0),FALSE) -> 5146.4595
A25: Total EBIT | B25: C Borrowings | D25: Total EBIT | E25: =VLOOKUP($A25,Model!$1:$1048576,MATCH(Summary!E$13,Model!$3:$3,0),FALSE) -> 1859 | F25: =VLOOKUP($A25,Model!$1:$1048576,MATCH(Summary!F$13,Model!$3:$3,0),FALSE) -> 2057 | G25: =VLOOKUP($A25,Model!$1:$1048576,MATCH(Summary!G$13,Model!$3:$3,0),FALSE) -> 2112 | H25: =VLOOKUP($A25,Model!$1:$1048576,MATCH(Summary!H$13,Model!$3:$3,0),FALSE) -> 2408.234 | I25: =VLOOKUP($A25,Model!$1:$1048576,MATCH(Summary!I$13,Model!$3:$3,0),FALSE) -> 2611.4417 | J25: =VLOOKUP($A25,Model!$1:$1048576,MATCH(Summary!J$13,Model!$3:$3,0),FALSE) -> 2766.0256 | L25: Borrowings | M25: =VLOOKUP($B25,BS!$1:$1048576,MATCH(Summary!M$13,CF!$3:$3,0),FALSE) -> 0 | N25: =VLOOKUP($B25,BS!$1:$1048576,MATCH(Summary!N$13,CF!$3:$3,0),FALSE) -> 0 | O25: =VLOOKUP($B25,BS!$1:$1048576,MATCH(Summary!O$13,CF!$3:$3,0),FALSE) -> 150 | P25: =VLOOKUP($B25,BS!$1:$1048576,MATCH(Summary!P$13,CF!$3:$3,0),FALSE) -> 150 | Q25: =VLOOKUP($B25,BS!$1:$1048576,MATCH(Summary!Q$13,CF!$3:$3,0),FALSE) -> 150 | R25: =VLOOKUP($B25,BS!$1:$1048576,MATCH(Summary!R$13,CF!$3:$3,0),FALSE) -> 150
A26: Net Interest | D26: Net interest | E26: =VLOOKUP($A26,PL!$1:$1048576,MATCH(Summary!E$13,PL!$3:$3,0),FALSE) -> -394 | F26: =VLOOKUP($A26,PL!$1:$1048576,MATCH(Summary!F$13,PL!$3:$3,0),FALSE) -> -442 | G26: =VLOOKUP($A26,PL!$1:$1048576,MATCH(Summary!G$13,PL!$3:$3,0),FALSE) -> -541 | H26: =VLOOKUP($A26,PL!$1:$1048576,MATCH(Summary!H$13,PL!$3:$3,0),FALSE) -> -552.75 | I26: =VLOOKUP($A26,PL!$1:$1048576,MATCH(Summary!I$13,PL!$3:$3,0),FALSE) -> -565.8825 | J26: =VLOOKUP($A26,PL!$1:$1048576,MATCH(Summary!J$13,PL!$3:$3,0),FALSE) -> -579.40898 | L26: Other current liabilities | M26: =M27-SUM(M24:M25) -> 1974 | N26: =N27-SUM(N24:N25) -> 2187 | O26: =O27-SUM(O24:O25) -> 2069 | P26: =P27-SUM(P24:P25) -> 2069 | Q26: =Q27-SUM(Q24:Q25) -> 2069 | R26: =R27-SUM(R24:R25) -> 2069
A27: PBT | B27: CL | D27: PBT | E27: =VLOOKUP($A27,PL!$1:$1048576,MATCH(Summary!E$13,PL!$3:$3,0),FALSE) -> 1465 | F27: =VLOOKUP($A27,PL!$1:$1048576,MATCH(Summary!F$13,PL!$3:$3,0),FALSE) -> 1615 | G27: =VLOOKUP($A27,PL!$1:$1048576,MATCH(Summary!G$13,PL!$3:$3,0),FALSE) -> 1571 | H27: =VLOOKUP($A27,PL!$1:$1048576,MATCH(Summary!H$13,PL!$3:$3,0),FALSE) -> 1855.484 | I27: =VLOOKUP($A27,PL!$1:$1048576,MATCH(Summary!I$13,PL!$3:$3,0),FALSE) -> 2045.5592 | J27: =VLOOKUP($A27,PL!$1:$1048576,MATCH(Summary!J$13,PL!$3:$3,0),FALSE) -> 2186.6166 | L27: Current liabilities | M27: =VLOOKUP($B27,BS!$1:$1048576,MATCH(Summary!M$13,CF!$3:$3,0),FALSE) -> 6408 | N27: =VLOOKUP($B27,BS!$1:$1048576,MATCH(Summary!N$13,CF!$3:$3,0),FALSE) -> 6771 | O27: =VLOOKUP($B27,BS!$1:$1048576,MATCH(Summary!O$13,CF!$3:$3,0),FALSE) -> 6856 | P27: =VLOOKUP($B27,BS!$1:$1048576,MATCH(Summary!P$13,CF!$3:$3,0),FALSE) -> 7009.2147 | Q27: =VLOOKUP($B27,BS!$1:$1048576,MATCH(Summary!Q$13,CF!$3:$3,0),FALSE) -> 7157.3706 | R27: =VLOOKUP($B27,BS!$1:$1048576,MATCH(Summary!R$13,CF!$3:$3,0),FALSE) -> 7365.4595
A28: Tax | B28: NC Lease | D28: Tax | E28: =VLOOKUP($A28,PL!$1:$1048576,MATCH(Summary!E$13,PL!$3:$3,0),FALSE) -> -423 | F28: =VLOOKUP($A28,PL!$1:$1048576,MATCH(Summary!F$13,PL!$3:$3,0),FALSE) -> -487 | G28: =VLOOKUP($A28,PL!$1:$1048576,MATCH(Summary!G$13,PL!$3:$3,0),FALSE) -> -467 | H28: =VLOOKUP($A28,PL!$1:$1048576,MATCH(Summary!H$13,PL!$3:$3,0),FALSE) -> -556.64521 | I28: =VLOOKUP($A28,PL!$1:$1048576,MATCH(Summary!I$13,PL!$3:$3,0),FALSE) -> -613.66776 | J28: =VLOOKUP($A28,PL!$1:$1048576,MATCH(Summary!J$13,PL!$3:$3,0),FALSE) -> -655.98498 | L28: Lease liabilities | M28: =VLOOKUP($B28,BS!$1:$1048576,MATCH(Summary!M$13,CF!$3:$3,0),FALSE) -> 7029 | N28: =VLOOKUP($B28,BS!$1:$1048576,MATCH(Summary!N$13,CF!$3:$3,0),FALSE) -> 7506 | O28: =VLOOKUP($B28,BS!$1:$1048576,MATCH(Summary!O$13,CF!$3:$3,0),FALSE) -> 7415 | P28: =VLOOKUP($B28,BS!$1:$1048576,MATCH(Summary!P$13,CF!$3:$3,0),FALSE) -> 7458.45 | Q28: =VLOOKUP($B28,BS!$1:$1048576,MATCH(Summary!Q$13,CF!$3:$3,0),FALSE) -> 7504.0725 | R28: =VLOOKUP($B28,BS!$1:$1048576,MATCH(Summary!R$13,CF!$3:$3,0),FALSE) -> 7551.9761
A29: NPAT | B29: NC Borrowings | D29: NPAT | E29: =VLOOKUP($A29,PL!$1:$1048576,MATCH(Summary!E$13,PL!$3:$3,0),FALSE) -> 1042 | F29: =VLOOKUP($A29,PL!$1:$1048576,MATCH(Summary!F$13,PL!$3:$3,0),FALSE) -> 1128 | G29: =VLOOKUP($A29,PL!$1:$1048576,MATCH(Summary!G$13,PL!$3:$3,0),FALSE) -> 1104 | H29: =VLOOKUP($A29,PL!$1:$1048576,MATCH(Summary!H$13,PL!$3:$3,0),FALSE) -> 1298.8388 | I29: =VLOOKUP($A29,PL!$1:$1048576,MATCH(Summary!I$13,PL!$3:$3,0),FALSE) -> 1431.8914 | J29: =VLOOKUP($A29,PL!$1:$1048576,MATCH(Summary!J$13,PL!$3:$3,0),FALSE) -> 1530.6316 | L29: Borrowings | M29: =VLOOKUP($B29,BS!$1:$1048576,MATCH(Summary!M$13,CF!$3:$3,0),FALSE) -> 1118 | N29: =VLOOKUP($B29,BS!$1:$1048576,MATCH(Summary!N$13,CF!$3:$3,0),FALSE) -> 1652 | O29: =VLOOKUP($B29,BS!$1:$1048576,MATCH(Summary!O$13,CF!$3:$3,0),FALSE) -> 1834 | P29: =VLOOKUP($B29,BS!$1:$1048576,MATCH(Summary!P$13,CF!$3:$3,0),FALSE) -> 1834 | Q29: =VLOOKUP($B29,BS!$1:$1048576,MATCH(Summary!Q$13,CF!$3:$3,0),FALSE) -> 1834 | R29: =VLOOKUP($B29,BS!$1:$1048576,MATCH(Summary!R$13,CF!$3:$3,0),FALSE) -> 1834
A30: Shares Diluted | D30: Shares (m) | E30: =VLOOKUP($A30,PL!$1:$1048576,MATCH(Summary!E$13,PL!$3:$3,0),FALSE) -> 1338 | F30: =VLOOKUP($A30,PL!$1:$1048576,MATCH(Summary!F$13,PL!$3:$3,0),FALSE) -> 1338 | G30: =VLOOKUP($A30,PL!$1:$1048576,MATCH(Summary!G$13,PL!$3:$3,0),FALSE) -> 1340 | H30: =VLOOKUP($A30,PL!$1:$1048576,MATCH(Summary!H$13,PL!$3:$3,0),FALSE) -> 1342 | I30: =VLOOKUP($A30,PL!$1:$1048576,MATCH(Summary!I$13,PL!$3:$3,0),FALSE) -> 1344 | J30: =VLOOKUP($A30,PL!$1:$1048576,MATCH(Summary!J$13,PL!$3:$3,0),FALSE) -> 1346 | L30: Other non-current liabilities | M30: =M31-SUM(M28:M29) -> 381 | N30: =N31-SUM(N28:N29) -> 324 | O30: =O31-SUM(O28:O29) -> 383 | P30: =P31-SUM(P28:P29) -> 383 | Q30: =Q31-SUM(Q28:Q29) -> 383 | R30: =R31-SUM(R28:R29) -> 383
A31: EPS | B31: NCL | D31: EPS | E31: =VLOOKUP($A31,PL!$1:$1048576,MATCH(Summary!E$13,PL!$3:$3,0),FALSE) -> 0.77877429 | F31: =VLOOKUP($A31,PL!$1:$1048576,MATCH(Summary!F$13,PL!$3:$3,0),FALSE) -> 0.84304933 | G31: =VLOOKUP($A31,PL!$1:$1048576,MATCH(Summary!G$13,PL!$3:$3,0),FALSE) -> 0.8238806 | H31: =VLOOKUP($A31,PL!$1:$1048576,MATCH(Summary!H$13,PL!$3:$3,0),FALSE) -> 0.96783816 | I31: =VLOOKUP($A31,PL!$1:$1048576,MATCH(Summary!I$13,PL!$3:$3,0),FALSE) -> 1.0653954 | J31: =VLOOKUP($A31,PL!$1:$1048576,MATCH(Summary!J$13,PL!$3:$3,0),FALSE) -> 1.1371706 | L31: Non-current liabilities | M31: =VLOOKUP($B31,BS!$1:$1048576,MATCH(Summary!M$13,CF!$3:$3,0),FALSE) -> 8528 | N31: =VLOOKUP($B31,BS!$1:$1048576,MATCH(Summary!N$13,CF!$3:$3,0),FALSE) -> 9482 | O31: =VLOOKUP($B31,BS!$1:$1048576,MATCH(Summary!O$13,CF!$3:$3,0),FALSE) -> 9632 | P31: =VLOOKUP($B31,BS!$1:$1048576,MATCH(Summary!P$13,CF!$3:$3,0),FALSE) -> 9675.45 | Q31: =VLOOKUP($B31,BS!$1:$1048576,MATCH(Summary!Q$13,CF!$3:$3,0),FALSE) -> 9721.0725 | R31: =VLOOKUP($B31,BS!$1:$1048576,MATCH(Summary!R$13,CF!$3:$3,0),FALSE) -> 9768.9761
A32: DPS | B32: Contributed Equity | D32: DPS | E32: =VLOOKUP($A32,PL!$1:$1048576,MATCH(Summary!E$13,PL!$3:$3,0),FALSE) -> 0.66 | F32: =VLOOKUP($A32,PL!$1:$1048576,MATCH(Summary!F$13,PL!$3:$3,0),FALSE) -> 0.68 | G32: =VLOOKUP($A32,PL!$1:$1048576,MATCH(Summary!G$13,PL!$3:$3,0),FALSE) -> 0.69 | H32: =VLOOKUP($A32,PL!$1:$1048576,MATCH(Summary!H$13,PL!$3:$3,0),FALSE) -> 0.82266244 | I32: =VLOOKUP($A32,PL!$1:$1048576,MATCH(Summary!I$13,PL!$3:$3,0),FALSE) -> 0.9055861 | J32: =VLOOKUP($A32,PL!$1:$1048576,MATCH(Summary!J$13,PL!$3:$3,0),FALSE) -> 0.96659501 | L32: Contributed equity | M32: =VLOOKUP($B32,BS!$1:$1048576,MATCH(Summary!M$13,CF!$3:$3,0),FALSE) -> 1644 | N32: =VLOOKUP($B32,BS!$1:$1048576,MATCH(Summary!N$13,CF!$3:$3,0),FALSE) -> 1672 | O32: =VLOOKUP($B32,BS!$1:$1048576,MATCH(Summary!O$13,CF!$3:$3,0),FALSE) -> 1704 | P32: =VLOOKUP($B32,BS!$1:$1048576,MATCH(Summary!P$13,CF!$3:$3,0),FALSE) -> 1704 | Q32: =VLOOKUP($B32,BS!$1:$1048576,MATCH(Summary!Q$13,CF!$3:$3,0),FALSE) -> 1704 | R32: =VLOOKUP($B32,BS!$1:$1048576,MATCH(Summary!R$13,CF!$3:$3,0),FALSE) -> 1704
B33: Reserves | L33: Reserves | M33: =VLOOKUP($B33,BS!$1:$1048576,MATCH(Summary!M$13,CF!$3:$3,0),FALSE) -> 104 | N33: =VLOOKUP($B33,BS!$1:$1048576,MATCH(Summary!N$13,CF!$3:$3,0),FALSE) -> 103 | O33: =VLOOKUP($B33,BS!$1:$1048576,MATCH(Summary!O$13,CF!$3:$3,0),FALSE) -> 106 | P33: =VLOOKUP($B33,BS!$1:$1048576,MATCH(Summary!P$13,CF!$3:$3,0),FALSE) -> 106 | Q33: =VLOOKUP($B33,BS!$1:$1048576,MATCH(Summary!Q$13,CF!$3:$3,0),FALSE) -> 106 | R33: =VLOOKUP($B33,BS!$1:$1048576,MATCH(Summary!R$13,CF!$3:$3,0),FALSE) -> 106
B34: Retained Profits | D34: Cash flow | E34: FY23 | F34: FY24 | G34: FY25 | H34: FY26E | I34: FY27E | J34: FY28E | L34: Retained Profits | M34: =VLOOKUP($B34,BS!$1:$1048576,MATCH(Summary!M$13,CF!$3:$3,0),FALSE) -> 1608 | N34: =VLOOKUP($B34,BS!$1:$1048576,MATCH(Summary!N$13,CF!$3:$3,0),FALSE) -> 1842 | O34: =VLOOKUP($B34,BS!$1:$1048576,MATCH(Summary!O$13,CF!$3:$3,0),FALSE) -> 1996 | P34: =VLOOKUP($B34,BS!$1:$1048576,MATCH(Summary!P$13,CF!$3:$3,0),FALSE) -> 2189.8456 | Q34: =VLOOKUP($B34,BS!$1:$1048576,MATCH(Summary!Q$13,CF!$3:$3,0),FALSE) -> 2403.6534 | R34: =VLOOKUP($B34,BS!$1:$1048576,MATCH(Summary!R$13,CF!$3:$3,0),FALSE) -> 2632.3167
A35: EBIT | B35: Total Equity | D35: EBIT | E35: =VLOOKUP($A35,CF!$1:$1048576,MATCH(Summary!E$13,CF!$3:$3,0),FALSE) -> 1859 | F35: =VLOOKUP($A35,CF!$1:$1048576,MATCH(Summary!F$13,CF!$3:$3,0),FALSE) -> 2057 | G35: =VLOOKUP($A35,CF!$1:$1048576,MATCH(Summary!G$13,CF!$3:$3,0),FALSE) -> 2112 | H35: =VLOOKUP($A35,CF!$1:$1048576,MATCH(Summary!H$13,CF!$3:$3,0),FALSE) -> 2408.234 | I35: =VLOOKUP($A35,CF!$1:$1048576,MATCH(Summary!I$13,CF!$3:$3,0),FALSE) -> 2611.4417 | J35: =VLOOKUP($A35,CF!$1:$1048576,MATCH(Summary!J$13,CF!$3:$3,0),FALSE) -> 2766.0256 | L35: Total Equity | M35: =VLOOKUP($B35,BS!$1:$1048576,MATCH(Summary!M$13,CF!$3:$3,0),FALSE) -> 3356 | N35: =VLOOKUP($B35,BS!$1:$1048576,MATCH(Summary!N$13,CF!$3:$3,0),FALSE) -> 3617 | O35: =VLOOKUP($B35,BS!$1:$1048576,MATCH(Summary!O$13,CF!$3:$3,0),FALSE) -> 3806 | P35: =VLOOKUP($B35,BS!$1:$1048576,MATCH(Summary!P$13,CF!$3:$3,0),FALSE) -> 3999.8456 | Q35: =VLOOKUP($B35,BS!$1:$1048576,MATCH(Summary!Q$13,CF!$3:$3,0),FALSE) -> 4213.6534 | R35: =VLOOKUP($B35,BS!$1:$1048576,MATCH(Summary!R$13,CF!$3:$3,0),FALSE) -> 4442.3167
A36: D&A | B36: Net Debt | D36: D&A | E36: =VLOOKUP($A36,CF!$1:$1048576,MATCH(Summary!E$13,CF!$3:$3,0),FALSE) -> 1523 | F36: =VLOOKUP($A36,CF!$1:$1048576,MATCH(Summary!F$13,CF!$3:$3,0),FALSE) -> 1602 | G36: =VLOOKUP($A36,CF!$1:$1048576,MATCH(Summary!G$13,CF!$3:$3,0),FALSE) -> 1829 | H36: =VLOOKUP($A36,CF!$1:$1048576,MATCH(Summary!H$13,CF!$3:$3,0),FALSE) -> 1947.885 | I36: =VLOOKUP($A36,CF!$1:$1048576,MATCH(Summary!I$13,CF!$3:$3,0),FALSE) -> 2025.8004 | J36: =VLOOKUP($A36,CF!$1:$1048576,MATCH(Summary!J$13,CF!$3:$3,0),FALSE) -> 2106.8324 | L36: Net debt ex leases | M36: =VLOOKUP($B36,BS!$1:$1048576,MATCH(Summary!M$13,CF!$3:$3,0),FALSE) -> 521 | N36: =VLOOKUP($B36,BS!$1:$1048576,MATCH(Summary!N$13,CF!$3:$3,0),FALSE) -> 977 | O36: =VLOOKUP($B36,BS!$1:$1048576,MATCH(Summary!O$13,CF!$3:$3,0),FALSE) -> 1279 | P36: =VLOOKUP($B36,BS!$1:$1048576,MATCH(Summary!P$13,CF!$3:$3,0),FALSE) -> 1246.9992 | Q36: =VLOOKUP($B36,BS!$1:$1048576,MATCH(Summary!Q$13,CF!$3:$3,0),FALSE) -> 1202.4942 | R36: =VLOOKUP($B36,BS!$1:$1048576,MATCH(Summary!R$13,CF!$3:$3,0),FALSE) -> 1131.086
A37: Net interest | D37: Net interest | E37: =VLOOKUP($A37,CF!$1:$1048576,MATCH(Summary!E$13,CF!$3:$3,0),FALSE) -> -394 | F37: =VLOOKUP($A37,CF!$1:$1048576,MATCH(Summary!F$13,CF!$3:$3,0),FALSE) -> -442 | G37: =VLOOKUP($A37,CF!$1:$1048576,MATCH(Summary!G$13,CF!$3:$3,0),FALSE) -> -541 | H37: =VLOOKUP($A37,CF!$1:$1048576,MATCH(Summary!H$13,CF!$3:$3,0),FALSE) -> -552.75 | I37: =VLOOKUP($A37,CF!$1:$1048576,MATCH(Summary!I$13,CF!$3:$3,0),FALSE) -> -565.8825 | J37: =VLOOKUP($A37,CF!$1:$1048576,MATCH(Summary!J$13,CF!$3:$3,0),FALSE) -> -579.40898 | L37: Divisional key metrics | M37: =E$13 -> FY23 | N37: =F$13 -> FY24 | O37: =G$13 -> FY25 | P37: =H$13 -> FY26E | Q37: =I$13 -> FY27E | R37: =J$13 -> FY28E
A38: Tax | B38: Food Comp | D38: Tax | E38: =VLOOKUP($A38,CF!$1:$1048576,MATCH(Summary!E$13,CF!$3:$3,0),FALSE) -> -423 | F38: =VLOOKUP($A38,CF!$1:$1048576,MATCH(Summary!F$13,CF!$3:$3,0),FALSE) -> -487 | G38: =VLOOKUP($A38,CF!$1:$1048576,MATCH(Summary!G$13,CF!$3:$3,0),FALSE) -> -467 | H38: =VLOOKUP($A38,CF!$1:$1048576,MATCH(Summary!H$13,CF!$3:$3,0),FALSE) -> -556.64521 | I38: =VLOOKUP($A38,CF!$1:$1048576,MATCH(Summary!I$13,CF!$3:$3,0),FALSE) -> -613.66776 | J38: =VLOOKUP($A38,CF!$1:$1048576,MATCH(Summary!J$13,CF!$3:$3,0),FALSE) -> -655.98498 | L38: Food LFL Sales Growth | M38: =VLOOKUP($B38,Model!$1:$1048576,MATCH(Summary!M$13,CF!$3:$3,0),FALSE) -> 0.058 | N38: =VLOOKUP($B38,Model!$1:$1048576,MATCH(Summary!N$13,CF!$3:$3,0),FALSE) -> 0.034 | O38: =VLOOKUP($B38,Model!$1:$1048576,MATCH(Summary!O$13,CF!$3:$3,0),FALSE) -> 0.037 | P38: =VLOOKUP($B38,Model!$1:$1048576,MATCH(Summary!P$13,CF!$3:$3,0),FALSE) -> 0.03875 | Q38: =VLOOKUP($B38,Model!$1:$1048576,MATCH(Summary!Q$13,CF!$3:$3,0),FALSE) -> 0.035 | R38: =VLOOKUP($B38,Model!$1:$1048576,MATCH(Summary!R$13,CF!$3:$3,0),FALSE) -> 0.035
A39: Chg WC | B39: Food EBIT Margin | D39: Change in net working capital | E39: =VLOOKUP($A39,CF!$1:$1048576,MATCH(Summary!E$13,CF!$3:$3,0),FALSE) -> 89 | F39: =VLOOKUP($A39,CF!$1:$1048576,MATCH(Summary!F$13,CF!$3:$3,0),FALSE) -> -121 | G39: =VLOOKUP($A39,CF!$1:$1048576,MATCH(Summary!G$13,CF!$3:$3,0),FALSE) -> 32 | H39: =VLOOKUP($A39,CF!$1:$1048576,MATCH(Summary!H$13,CF!$3:$3,0),FALSE) -> 46.820186 | I39: =VLOOKUP($A39,CF!$1:$1048576,MATCH(Summary!I$13,CF!$3:$3,0),FALSE) -> 45.274309 | J39: =VLOOKUP($A39,CF!$1:$1048576,MATCH(Summary!J$13,CF!$3:$3,0),FALSE) -> 63.588944 | L39: Food EBIT Margin | M39: =VLOOKUP($B39,Model!$1:$1048576,MATCH(Summary!M$13,CF!$3:$3,0),FALSE) -> 0.048032439 | N39: =VLOOKUP($B39,Model!$1:$1048576,MATCH(Summary!N$13,CF!$3:$3,0),FALSE) -> 0.051687926 | O39: =VLOOKUP($B39,Model!$1:$1048576,MATCH(Summary!O$13,CF!$3:$3,0),FALSE) -> 0.052717133 | P39: =VLOOKUP($B39,Model!$1:$1048576,MATCH(Summary!P$13,CF!$3:$3,0),FALSE) -> 0.058314333 | Q39: =VLOOKUP($B39,Model!$1:$1048576,MATCH(Summary!Q$13,CF!$3:$3,0),FALSE) -> 0.060192278 | R39: =VLOOKUP($B39,Model!$1:$1048576,MATCH(Summary!R$13,CF!$3:$3,0),FALSE) -> 0.061041274
A40: Other | B40: Liquor Comp | D40: Other | E40: =VLOOKUP($A40,CF!$1:$1048576,MATCH(Summary!E$13,CF!$3:$3,0),FALSE) -> 153 | F40: =VLOOKUP($A40,CF!$1:$1048576,MATCH(Summary!F$13,CF!$3:$3,0),FALSE) -> 184 | G40: =VLOOKUP($A40,CF!$1:$1048576,MATCH(Summary!G$13,CF!$3:$3,0),FALSE) -> -29 | H40: =VLOOKUP($A40,CF!$1:$1048576,MATCH(Summary!H$13,CF!$3:$3,0),FALSE) -> 0 | I40: =VLOOKUP($A40,CF!$1:$1048576,MATCH(Summary!I$13,CF!$3:$3,0),FALSE) -> 0 | J40: =VLOOKUP($A40,CF!$1:$1048576,MATCH(Summary!J$13,CF!$3:$3,0),FALSE) -> 0 | L40: Liquor LFL Sales Growth | M40: =VLOOKUP($B40,Model!$1:$1048576,MATCH(Summary!M$13,CF!$3:$3,0),FALSE) -> 0.007 | N40: =VLOOKUP($B40,Model!$1:$1048576,MATCH(Summary!N$13,CF!$3:$3,0),FALSE) -> -0.01 | O40: =VLOOKUP($B40,Model!$1:$1048576,MATCH(Summary!O$13,CF!$3:$3,0),FALSE) -> -0.013 | P40: =VLOOKUP($B40,Model!$1:$1048576,MATCH(Summary!P$13,CF!$3:$3,0),FALSE) -> -0.01125 | Q40: =VLOOKUP($B40,Model!$1:$1048576,MATCH(Summary!Q$13,CF!$3:$3,0),FALSE) -> 0.025 | R40: =VLOOKUP($B40,Model!$1:$1048576,MATCH(Summary!R$13,CF!$3:$3,0),FALSE) -> 0.025
A41: OCF | B41: Liquor EBIT Margin | D41: Operating cashflow | E41: =VLOOKUP($A41,CF!$1:$1048576,MATCH(Summary!E$13,CF!$3:$3,0),FALSE) -> 2807 | F41: =VLOOKUP($A41,CF!$1:$1048576,MATCH(Summary!F$13,CF!$3:$3,0),FALSE) -> 2793 | G41: =VLOOKUP($A41,CF!$1:$1048576,MATCH(Summary!G$13,CF!$3:$3,0),FALSE) -> 2936 | H41: =VLOOKUP($A41,CF!$1:$1048576,MATCH(Summary!H$13,CF!$3:$3,0),FALSE) -> 3293.544 | I41: =VLOOKUP($A41,CF!$1:$1048576,MATCH(Summary!I$13,CF!$3:$3,0),FALSE) -> 3502.9661 | J41: =VLOOKUP($A41,CF!$1:$1048576,MATCH(Summary!J$13,CF!$3:$3,0),FALSE) -> 3701.053 | L41: Liquor EBIT Margin | M41: =VLOOKUP($B41,Model!$1:$1048576,MATCH(Summary!M$13,CF!$3:$3,0),FALSE) -> 0.043490305 | N41: =VLOOKUP($B41,Model!$1:$1048576,MATCH(Summary!N$13,CF!$3:$3,0),FALSE) -> 0.036023835 | O41: =VLOOKUP($B41,Model!$1:$1048576,MATCH(Summary!O$13,CF!$3:$3,0),FALSE) -> 0.03081538 | P41: =VLOOKUP($B41,Model!$1:$1048576,MATCH(Summary!P$13,CF!$3:$3,0),FALSE) -> 0.02375081 | Q41: =VLOOKUP($B41,Model!$1:$1048576,MATCH(Summary!Q$13,CF!$3:$3,0),FALSE) -> 0.02982512 | R41: =VLOOKUP($B41,Model!$1:$1048576,MATCH(Summary!R$13,CF!$3:$3,0),FALSE) -> 0.030471315
A42: Capex | D42: Capex | E42: =VLOOKUP($A42,CF!$1:$1048576,MATCH(Summary!E$13,CF!$3:$3,0),FALSE) -> -1514 | F42: =VLOOKUP($A42,CF!$1:$1048576,MATCH(Summary!F$13,CF!$3:$3,0),FALSE) -> -1671 | G42: =VLOOKUP($A42,CF!$1:$1048576,MATCH(Summary!G$13,CF!$3:$3,0),FALSE) -> -1487 | H42: =VLOOKUP($A42,CF!$1:$1048576,MATCH(Summary!H$13,CF!$3:$3,0),FALSE) -> -1200 | I42: =VLOOKUP($A42,CF!$1:$1048576,MATCH(Summary!I$13,CF!$3:$3,0),FALSE) -> -1236 | J42: =VLOOKUP($A42,CF!$1:$1048576,MATCH(Summary!J$13,CF!$3:$3,0),FALSE) -> -1273.08 | L42: Group key metrics | M42: =E$13 -> FY23 | N42: =F$13 -> FY24 | O42: =G$13 -> FY25 | P42: =H$13 -> FY26E | Q42: =I$13 -> FY27E | R42: =J$13 -> FY28E
A43: Acquisitions | B43: Total Sales Growth | D43: Acquisitions | E43: =VLOOKUP($A43,CF!$1:$1048576,MATCH(Summary!E$13,CF!$3:$3,0),FALSE) -> -14 | F43: =VLOOKUP($A43,CF!$1:$1048576,MATCH(Summary!F$13,CF!$3:$3,0),FALSE) -> -23 | G43: =VLOOKUP($A43,CF!$1:$1048576,MATCH(Summary!G$13,CF!$3:$3,0),FALSE) -> -20 | H43: =VLOOKUP($A43,CF!$1:$1048576,MATCH(Summary!H$13,CF!$3:$3,0),FALSE) -> 0 | I43: =VLOOKUP($A43,CF!$1:$1048576,MATCH(Summary!I$13,CF!$3:$3,0),FALSE) -> 0 | J43: =VLOOKUP($A43,CF!$1:$1048576,MATCH(Summary!J$13,CF!$3:$3,0),FALSE) -> 0 | L43: Sales Growth | M43: =VLOOKUP($B43,PL!$1:$1048576,MATCH(Summary!M$13,CF!$3:$3,0),FALSE) -> 0.058738918 | N43: =VLOOKUP($B43,PL!$1:$1048576,MATCH(Summary!N$13,CF!$3:$3,0),FALSE) -> 0.076278932 | O43: =VLOOKUP($B43,PL!$1:$1048576,MATCH(Summary!O$13,CF!$3:$3,0),FALSE) -> 0.017924766 | P43: =VLOOKUP($B43,PL!$1:$1048576,MATCH(Summary!P$13,CF!$3:$3,0),FALSE) -> 0.033041769 | Q43: =VLOOKUP($B43,PL!$1:$1048576,MATCH(Summary!Q$13,CF!$3:$3,0),FALSE) -> 0.030928873 | R43: =VLOOKUP($B43,PL!$1:$1048576,MATCH(Summary!R$13,CF!$3:$3,0),FALSE) -> 0.042137152
A44: Proceeds PPE | B44: Total EBIT Growth | D44: Proceeds from asset sales | E44: =VLOOKUP($A44,CF!$1:$1048576,MATCH(Summary!E$13,CF!$3:$3,0),FALSE) -> 248 | F44: =VLOOKUP($A44,CF!$1:$1048576,MATCH(Summary!F$13,CF!$3:$3,0),FALSE) -> 255 | G44: =VLOOKUP($A44,CF!$1:$1048576,MATCH(Summary!G$13,CF!$3:$3,0),FALSE) -> 205 | H44: =VLOOKUP($A44,CF!$1:$1048576,MATCH(Summary!H$13,CF!$3:$3,0),FALSE) -> 0 | I44: =VLOOKUP($A44,CF!$1:$1048576,MATCH(Summary!I$13,CF!$3:$3,0),FALSE) -> 0 | J44: =VLOOKUP($A44,CF!$1:$1048576,MATCH(Summary!J$13,CF!$3:$3,0),FALSE) -> 0 | L44: EBIT Growth | M44: =VLOOKUP($B44,PL!$1:$1048576,MATCH(Summary!M$13,CF!$3:$3,0),FALSE) -> 0.017515052 | N44: =VLOOKUP($B44,PL!$1:$1048576,MATCH(Summary!N$13,CF!$3:$3,0),FALSE) -> 0.10650888 | O44: =VLOOKUP($B44,PL!$1:$1048576,MATCH(Summary!O$13,CF!$3:$3,0),FALSE) -> 0.026737968 | P44: =VLOOKUP($B44,PL!$1:$1048576,MATCH(Summary!P$13,CF!$3:$3,0),FALSE) -> 0.14026232 | Q44: =VLOOKUP($B44,PL!$1:$1048576,MATCH(Summary!Q$13,CF!$3:$3,0),FALSE) -> 0.084380366 | R44: =VLOOKUP($B44,PL!$1:$1048576,MATCH(Summary!R$13,CF!$3:$3,0),FALSE) -> 0.059194848
A45: Lease Repayment | B45: NPAT Growth | D45: Lease repayments | E45: =VLOOKUP($A45,CF!$1:$1048576,MATCH(Summary!E$13,CF!$3:$3,0),FALSE) -> -907 | F45: =VLOOKUP($A45,CF!$1:$1048576,MATCH(Summary!F$13,CF!$3:$3,0),FALSE) -> -834 | G45: =VLOOKUP($A45,CF!$1:$1048576,MATCH(Summary!G$13,CF!$3:$3,0),FALSE) -> -911 | H45: =VLOOKUP($A45,CF!$1:$1048576,MATCH(Summary!H$13,CF!$3:$3,0),FALSE) -> -956.55 | I45: =VLOOKUP($A45,CF!$1:$1048576,MATCH(Summary!I$13,CF!$3:$3,0),FALSE) -> -1004.3775 | J45: =VLOOKUP($A45,CF!$1:$1048576,MATCH(Summary!J$13,CF!$3:$3,0),FALSE) -> -1054.5964 | L45: NPAT Growth | M45: =VLOOKUP($B45,PL!$1:$1048576,MATCH(Summary!M$13,CF!$3:$3,0),FALSE) -> -0.0028708134 | N45: =VLOOKUP($B45,PL!$1:$1048576,MATCH(Summary!N$13,CF!$3:$3,0),FALSE) -> 0.082533589 | O45: =VLOOKUP($B45,PL!$1:$1048576,MATCH(Summary!O$13,CF!$3:$3,0),FALSE) -> -0.021276596 | P45: =VLOOKUP($B45,PL!$1:$1048576,MATCH(Summary!P$13,CF!$3:$3,0),FALSE) -> 0.17648443 | Q45: =VLOOKUP($B45,PL!$1:$1048576,MATCH(Summary!Q$13,CF!$3:$3,0),FALSE) -> 0.10243967 | R45: =VLOOKUP($B45,PL!$1:$1048576,MATCH(Summary!R$13,CF!$3:$3,0),FALSE) -> 0.068957877
A46: Other investing | D46: Other investing | E46: =VLOOKUP($A46,CF!$1:$1048576,MATCH(Summary!E$13,CF!$3:$3,0),FALSE) -> 266 | F46: =VLOOKUP($A46,CF!$1:$1048576,MATCH(Summary!F$13,CF!$3:$3,0),FALSE) -> -97 | G46: =VLOOKUP($A46,CF!$1:$1048576,MATCH(Summary!G$13,CF!$3:$3,0),FALSE) -> -82 | H46: =VLOOKUP($A46,CF!$1:$1048576,MATCH(Summary!H$13,CF!$3:$3,0),FALSE) -> 0 | I46: =VLOOKUP($A46,CF!$1:$1048576,MATCH(Summary!I$13,CF!$3:$3,0),FALSE) -> 0 | J46: =VLOOKUP($A46,CF!$1:$1048576,MATCH(Summary!J$13,CF!$3:$3,0),FALSE) -> 0 | L46: EPS Growth | M46: =VLOOKUP($B47,PL!$1:$1048576,MATCH(Summary!M$13,CF!$3:$3,0),FALSE) -> -0.0080874833 | N46: =VLOOKUP($B47,PL!$1:$1048576,MATCH(Summary!N$13,CF!$3:$3,0),FALSE) -> 0.082533589 | O46: =VLOOKUP($B47,PL!$1:$1048576,MATCH(Summary!O$13,CF!$3:$3,0),FALSE) -> -0.022737377 | P46: =VLOOKUP($B47,PL!$1:$1048576,MATCH(Summary!P$13,CF!$3:$3,0),FALSE) -> 0.1747311 | Q46: =VLOOKUP($B47,PL!$1:$1048576,MATCH(Summary!Q$13,CF!$3:$3,0),FALSE) -> 0.10079913 | R46: =VLOOKUP($B47,PL!$1:$1048576,MATCH(Summary!R$13,CF!$3:$3,0),FALSE) -> 0.067369529
...

Sheet Model
B1: Coles Group (COL.AX)
B2: A$M
C3: FY17 | D3: FY18 | E3: FY19 | F3: FY20 | G3: FY21 | H3: FY22 | I3: FY23 | J3: FY24 | K3: FY25 | L3: FY26E | M3: FY27E | N3: FY28E | O3: FY29E | P3: FY30E | S3: 1H17 | T3: 2H17 | U3: 1H18 | V3: 2H18 | W3: 1H19 | X3: 2H19 | Y3: 1H20 | Z3: 2H20 | AA3: 1H21 | AB3: 2H21 | AC3: 1H22 | AD3: 2H22 | AE3: 1H23 | AF3: 2H23 | AG3: 1H24 | AH3: 2H24 | AI3: 1H25 | AJ3: 2H25 | AK3: 1H26E | AL3: 2H26E
B4: Model Summary
B6: Sales
A7: Food Sales | B7: Food | C7: =C23 -> 29754 | D7: =D23 -> 29919 | E7: =E23 -> 30890 | F7: =F23 -> 32993 | G7: =G23 -> 33868 | H7: =H23 -> 34624 | I7: =I23 -> 36746 | J7: =J23 -> 39042 | ... P7: =P23 -> 49424.403 | U7: =U23 -> 15525 | V7: =V23 -> 14394 | W7: =W23 -> 16069 | X7: =X23 -> 14821 | Y7: =Y23 -> 16593 | Z7: =Z23 -> 16400 | AA7: =AA23 -> 17812 | AB7: =AB23 -> 16056 | ... AL7: =AL23 -> 20175.977
A8: Liquor Sales | B8: Liquor | C8: =C93 -> 3223 | D8: =D93 -> 3314 | E8: =E93 -> 3063 | F8: =F93 -> 3308 | G8: =G93 -> 3525 | H8: =H93 -> 3613 | I8: =I93 -> 3610 | J8: =J93 -> 3692 | ... P8: =P93 -> 4014.2398 | U8: =U93 -> 1721 | V8: =V93 -> 1593 | W8: =W93 -> 1637 | X8: =X93 -> 1426 | Y8: =Y93 -> 1691 | Z8: =Z93 -> 1617 | AA8: =AA93 -> 1946 | AB8: =AB93 -> 1579 | ... AL8: =AL93 -> 1651.7412
B9: Coles Express (Divested FY23) | C9: 6133 | D9: 5761 | E9: 1048 | F9: 1107 | G9: 1192 | U9: 2992 | V9: =D9-U9 -> 2769 | W9: 547 | X9: =E9-W9 -> 501 | Y9: 572 | Z9: =F9-Y9 -> 535 | AA9: 632 | AB9: =G9-AA9 -> 560
A10: Corporate/Other Sales | B10: Corporate / Other | C10: =C153 -> 16 | D10: =D153 -> 13 | E10: =E153 -> 0 | F10: =F153 -> 0 | G10: =G153 -> 0 | H10: =H153 -> 0 | I10: =I153 -> 127 | J10: =J153 -> 837 | ... P10: =P153 -> 0 | U10: =U153 -> 8 | V10: =V153 -> 5 | W10: =W153 -> 13 | X10: =X153 -> -13 | Y10: =Y153 -> 0 | Z10: =Z153 -> 0 | AA10: =AA153 -> 0 | AB10: =AB153 -> 0 | ... AL10: =AL153 -> 177.6
A11: Total Sales | B11: Group Sales from Continuing Ops. | C11: 39125 | D11: =SUM(D7:D10) -> 39007 | E11: =SUM(E7:E10) -> 35001 | F11: =SUM(F7:F10) -> 37408 | G11: =SUM(G7:G10) -> 38585 | H11: =SUM(H7:H10) -> 38237 | I11: =SUM(I7:I10) -> 40483 | J11: =SUM(J7:J10) -> 43571 | K11: =SUM(K7:K10) -> 44352 | ... P11: =SUM(P7:P10) -> 53438.643 | U11: =SUM(U7:U10) -> 20246 | V11: =SUM(V7:V10) -> 18761 | W11: =SUM(W7:W10) -> 18266 | X11: =SUM(X7:X10) -> 16735 | Y11: =SUM(Y7:Y10) -> 18856 | Z11: =SUM(Z7:Z10) -> 18552 | AA11: =SUM(AA7:AA10) -> 20390 | AB11: =SUM(AB7:AB10) -> 18195 | ... AL11: =SUM(AL7:AL10) -> 22005.318
B12: Discontinued Ops | C12: 0 | D12: 0 | E12: 0 | F12: 0 | G12: 0 | H12: 1132 | I12: 988 | J12: 0 | K12: 0 | U12: 0 | V12: =D12-U12 -> 0 | W12: 0 | X12: =E12-W12 -> 0 | Y12: 0 | Z12: =F12-Y12 -> 0 | AA12: 0 | AB12: =G12-AA12 -> 0 | AC12: 578 | AD12: =H12-AC12 -> 554 | AE12: 578 | AF12: =I12-AE12 -> 410 | AG12: 0 | AH12: =J12-AG12 -> 0 | AI12: 0 | AJ12: =K12-AI12 -> 0
B13: Total Group Sales (Reported) | C13: =C11+C12 -> 39125 | D13: =D11+D12 -> 39007 | E13: =E11+E12 -> 35001 | F13: =F11+F12 -> 37408 | G13: =G11+G12 -> 38585 | H13: =H11+H12 -> 39369 | I13: =I11+I12 -> 41471 | J13: =J11+J12 -> 43571 | K13: =K11+K12 -> 44352 | U13: =SUM(U11:U12) -> 20246 | V13: =SUM(V11:V12) -> 18761 | W13: =SUM(W11:W12) -> 18266 | X13: =SUM(X11:X12) -> 16735 | Y13: =SUM(Y11:Y12) -> 18856 | Z13: =SUM(Z11:Z12) -> 18552 | AA13: =SUM(AA11:AA12) -> 20390 | AB13: =SUM(AB11:AB12) -> 18195 | ... AJ13: =SUM(AJ11:AJ12) -> 21317
B15: EBIT
A16: Food EBIT | B16: Food | C16: =C50 -> 1186 | D16: =D50 -> 1157 | E16: =E50 -> 1183 | F16: =F50 -> 1618 | G16: =G50 -> 1702 | H16: =H50 -> 1715 | I16: =I50 -> 1765 | J16: =J50 -> 2018 | ... P16: =P50 -> 2994.765 | U16: =U50 -> 600 | V16: =V50 -> 557 | W16: =W50 -> 602 | X16: =X50 -> 581 | Y16: =Y50 -> 789 | Z16: =Z50 -> 829 | AA16: =AA50 -> 903 | AB16: =AB50 -> 799 | ... AL16: =AL50 -> 1186.2023
A17: Liquor EBIT | B17: Liquor | C17: =C119 -> 138 | D17: =D119 -> 130 | E17: =E119 -> 120 | F17: =F119 -> 138 | G17: =G119 -> 165 | H17: =H119 -> 163 | I17: =I119 -> 157 | J17: =J119 -> 133 | ... P17: =P119 -> 143.50449 | U17: =U119 -> 80 | V17: =V119 -> 50 | W17: =W119 -> 74 | X17: =X119 -> 46 | Y17: =Y119 -> 76 | Z17: =Z119 -> 62 | AA17: =AA119 -> 104 | AB17: =AB119 -> 61 | ... AL17: =AL119 -> 38.929383
B18: Coles Express (Divested FY23) | C18: 190 | D18: 133 | E18: 50 | F18: 33 | G18: 67 | U18: 84 | V18: =D18-U18 -> 49 | W18: 51 | X18: =E18-W18 -> -1 | Y18: 28 | Z18: =F18-Y18 -> 5 | AA18: 32 | AB18: =G18-AA18 -> 35
A19: Corporate/Other EBIT | B19: Corporate / Other | C19: =C166 -> 0 | D19: =D166 -> -25 | E19: =E166 -> -28 | F19: =F166 -> -27 | G19: =G166 -> -61 | H19: =H166 -> -51 | I19: =I166 -> -63 | J19: =J166 -> -94 | ... P19: =P166 -> -129.04233 | U19: =U166 -> 15 | V19: =V166 -> -40 | W19: =W166 -> -5 | X19: =X166 -> -23 | Y19: =Y166 -> 17 | Z19: =Z166 -> -44 | AA19: =AA166 -> -19 | AB19: =AB166 -> -42 | ... AL19: =AL166 -> -68.543324
A20: Total EBIT | B20: Group EBIT | C20: =SUM(C16:C19) -> 1514 | D20: =SUM(D16:D19) -> 1395 | E20: =SUM(E16:E19) -> 1325 | F20: =SUM(F16:F19) -> 1762 | G20: =SUM(G16:G19) -> 1873 | H20: =SUM(H16:H19) -> 1827 | I20: =SUM(I16:I19) -> 1859 | J20: =SUM(J16:J19) -> 2057 | ... P20: =SUM(P16:P19) -> 3009.2272 | U20: =SUM(U16:U19) -> 779 | V20: =SUM(V16:V19) -> 616 | W20: =SUM(W16:W19) -> 722 | X20: =SUM(X16:X19) -> 603 | Y20: =SUM(Y16:Y19) -> 910 | Z20: =SUM(Z16:Z19) -> 852 | AA20: =SUM(AA16:AA19) -> 1020 | AB20: =SUM(AB16:AB19) -> 853 | ... AL20: =SUM(AL16:AL19) -> 1156.5883
B22: Food
B23: Sales | C23: 29754 | D23: 29919 | E23: 30890 | F23: 32993 | G23: 33868 | H23: 34624 | I23: 36746 | J23: 39042 | K23: 39987 | L23: =K23*(1+L24) -> 41681.565 | M23: =L23*(1+M24) -> 43506.93 | N23: =M23*(1+N24) -> 45404.069 | O23: =N23*(1+O24) -> 47375.642 | P23: =O23*(1+P24) -> 49424.403 | U23: 15525 | V23: =D23-U23 -> 14394 | W23: 16069 | X23: =E23-W23 -> 14821 | Y23: 16593 | Z23: =F23-Y23 -> 16400 | AA23: 17812 | AB23: =G23-AA23 -> 16056 | AC23: 18016 | AD23: =H23-AC23 -> 16608 | AE23: 18857 | AF23: =I23-AE23 -> 17889 | AG23: 19778 | AH23: =J23-AG23 -> 19264 | AI23: 20629 | AJ23: =K23-AI23 -> 19358 | AK23: =AI23*(1+AK24) -> 21505.588 | AL23: =L23-AK23 -> 20175.977
A24: Food Growth | B24: Growth % | D24: =D23/C23-1 -> 0.0055454729 | E24: =E23/D23-1 -> 0.032454293 | F24: =F23/E23-1 -> 0.068080285 | G24: =G23/F23-1 -> 0.026520777 | H24: =H23/G23-1 -> 0.022321956 | I24: =I23/H23-1 -> 0.061286969 | J24: =J23/I23-1 -> 0.062482991 | K24: =K23/J23-1 -> 0.024204703 | L24: =SUM(L26:L28) -> 0.042377907 | M24: =SUM(M26:M28) -> 0.043793103 | N24: =SUM(N26:N28) -> 0.043605442 | O24: =SUM(O26:O28) -> 0.043422819 | P24: =SUM(P26:P28) -> 0.043245033 | W24: =W23/U23-1 -> 0.035040258 | X24: =X23/V23-1 -> 0.029665138 | Y24: =Y23/W23-1 -> 0.032609372 | Z24: =Z23/X23-1 -> 0.10653802 | AA24: =AA23/Y23-1 -> 0.073464714 | AB24: =AB23/Z23-1 -> -0.02097561 | AC24: =AC23/AA23-1 -> 0.011452953 | AD24: =AD23/AB23-1 -> 0.034379671 | ... AJ24: =AJ23/AH23-1 -> 0.0048795681 | AK24: =SUM(AK26:AK28) -> 0.042493007 | AL24: =AL23/AJ23-1 -> 0.04225525
A25: Food Growth ex Tobacco | B25: Growth ex Tobacco % | I25: 0.074 | J25: 0.057 | K25: 0.057
A26: Food Comp | B26: LFL Sales Growth % | D26: 0.011 | E26: 0.027 | F26: 0.059 | G26: 0.025 | H26: 0.026 | I26: 0.058 | J26: 0.034 | K26: 0.037 | L26: =VLOOKUP($A26,Quarterly!$1:$1048576,MATCH(Model!L$3,Quarterly!$3:$3,0),FALSE) -> 0.03875 | M26: 0.035 | N26: 0.035 | O26: 0.035 | P26: 0.035 | U26: 0.009 | V26: =D26 -> 0.011 | W26: 0.032 | X26: 0.022 | Y26: 0.02 | Z26: 0.1 | AA26: 0.072 | AB26: -0.022 | AC26: 0.015 | AD26: 0.038 | AE26: 0.049 | AF26: 0.067 | AG26: 0.04 | AH26: 0.026 | AI26: 0.034 | AJ26: 0.041 | AK26: =VLOOKUP($A26,Quarterly!$1:$1048576,MATCH(Model!AK$3,Quarterly!$3:$3,0),FALSE) -> 0.0405 | AL26: =VLOOKUP($A26,Quarterly!$1:$1048576,MATCH(Model!AL$3,Quarterly!$3:$3,0),FALSE) -> 0.037
B27: Store Growth % | E27: =E66/D66-1 -> 0.014833127 | F27: =F66/E66-1 -> 0.0036540804 | G27: =G66/F66-1 -> 0.012135922 | H27: =H66/G66-1 -> 0.0011990408 | I27: =I66/H66-1 -> 0.013173653 | J27: =J66/I66-1 -> 0.011820331 | K27: =K66/J66-1 -> 0.0046728972 | L27: =L66/K66-1 -> 0.011627907 | ... P27: =P66/O66-1 -> 0.013245033 | Y27: =Y66/W66-1 -> 0.0085784314 | Z27: =Z66/X66-1 -> 0.0036540804 | AA27: =AA66/Y66-1 -> 0.012150668 | AB27: =AB66/Z66-1 -> 0.012135922 | AC27: =AC66/AA66-1 -> 0.0024009604 | AD27: =AD66/AB66-1 -> 0.0011990408 | AE27: =AE66/AC66-1 -> 0.0083832335 | AF27: =AF66/AD66-1 -> 0.013173653 | ... AL27: =AL66/AJ66-1 -> 0.011627907
B28: Other | E28: =E24-SUM(E26:E27) -> -0.0093788341 | F28: =F24-SUM(F26:F27) -> 0.0054262045 | G28: =G24-SUM(G26:G27) -> -0.010615145 | H28: =H24-SUM(H26:H27) -> -0.0048770849 | I28: =I24-SUM(I26:I27) -> -0.0098866841 | J28: =J24-SUM(J26:J27) -> 0.01666266 | K28: =K24-SUM(K26:K27) -> -0.017468195 | L28: -0.008 | M28: -0.005 | N28: -0.005 | O28: -0.005 | P28: -0.005 | Y28: =Y24-SUM(Y26:Y27) -> 0.0040309407 | Z28: =Z24-SUM(Z26:Z27) -> 0.00288394 | AA28: =AA24-SUM(AA26:AA27) -> -0.010685954 | AB28: =AB24-SUM(AB26:AB27) -> -0.011111532 | AC28: =AC24-SUM(AC26:AC27) -> -0.0059480073 | AD28: =AD24-SUM(AD26:AD27) -> -0.0048193696 | AE28: =AE24-SUM(AE26:AE27) -> -0.010702505 | AF28: =AF24-SUM(AF26:AF27) -> -0.0030421498 | ... AJ28: =AJ24-SUM(AJ26:AJ27) -> -0.040793329 | AK28: -0.005 | AL28: =AL24-SUM(AL26:AL27) -> -0.0063726572
A30: Food GP | B30: Gross Profit | D30: =D32*D23 -> 7360.074 | E30: =E32*E23 -> 7660.72 | F30: =F32*F23 -> 8413.215 | G30: =G32*G23 -> 8771.812 | H30: =H32*H23 -> 9106.112 | I30: =I32*I23 -> 9700.944 | J30: =J32*J23 -> 10424.214 | K30: =K32*K23 -> 10996.425 | ... P30: =P32*P23 -> 13967.336 | U30: =U32*U23 -> 3726 | V30: =D30-U30 -> 3634.074 | W30: =W32*W23 -> 3920.836 | X30: =E30-W30 -> 3739.884 | Y30: =Y32*Y23 -> 4164.843 | Z30: =F30-Y30 -> 4248.372 | AA30: =AA32*AA23 -> 4613.308 | AB30: =G30-AA30 -> 4158.504 | AC30: =AC32*AC23 -> 4702.176 | AD30: =H30-AC30 -> 4403.936 | AE30: =AE32*AE23 -> 4997.105 | AF30: =I30-AE30 -> 4703.839 | AG30: =AG32*AG23 -> 5260.948 | AH30: =J30-AG30 -> 5163.266 | AI30: =AI32*AI23 -> 5672.975 | AJ30: =K30-AI30 -> 5323.45 | AK30: =AK32*AK23 -> 6025.8658 | AL30: =L30-AK30 -> 5649.1406
B31: Growth % | E31: =E30/D30-1 -> 0.040848231 | F31: =F30/E30-1 -> 0.098227712 | G31: =G30/F30-1 -> 0.042623064 | H31: =H30/G30-1 -> 0.038110712 | I31: =I30/H30-1 -> 0.06532228 | J31: =J30/I30-1 -> 0.074556662 | K31: =K30/J30-1 -> 0.054892484 | L31: =L30/K30-1 -> 0.061709279 | ... P31: =P30/O30-1 -> 0.043245033 | W31: =W30/U30-1 -> 0.052290929 | X31: =X30/V30-1 -> 0.029116083 | Y31: =Y30/W30-1 -> 0.062233411 | Z31: =Z30/X30-1 -> 0.13596358 | AA31: =AA30/Y30-1 -> 0.10767873 | AB31: =AB30/Z30-1 -> -0.021153515 | AC31: =AC30/AA30-1 -> 0.019263401 | AD31: =AD30/AB30-1 -> 0.059019301 | ... AJ31: =AJ30/AH30-1 -> 0.031023774 | AK31: =AK30/AJ30-1 -> 0.13194748 | AL31: =AL30/AJ30-1 -> 0.061180369
A32: Food GPM | B32: Gross Margin | D32: 0.246 | E32: 0.248 | F32: 0.255 | G32: 0.259 | H32: 0.263 | I32: 0.264 | J32: 0.267 | K32: 0.275 | L32: =K32+L33 -> 0.2801 | M32: =L32+M33 -> 0.2821 | N32: =M32+N33 -> 0.2826 | O32: =N32+O33 -> 0.2826 | P32: =O32+P33 -> 0.2826 | U32: 0.24 | V32: =V30/V23 -> 0.25247145 | W32: 0.244 | X32: =X30/X23 -> 0.25233682 | Y32: 0.251 | Z32: =Z30/Z23 -> 0.25904707 | AA32: 0.259 | AB32: =AB30/AB23 -> 0.259 | AC32: 0.261 | AD32: =AD30/AD23 -> 0.26516956 | AE32: 0.265 | AF32: =AF30/AF23 -> 0.26294589 | AG32: 0.266 | AH32: =AH30/AH23 -> 0.26802668 | AI32: 0.275 | AJ32: =AJ30/AJ23 -> 0.275 | AK32: =AI32+AK33 -> 0.2802 | AL32: =AL30/AL23 -> 0.27999341
B33: Change YoY % | E33: 0.002 | F33: 0.003 | G33: 0.0035 | H33: 0.0042 | I33: 0.0005 | J33: 0.005 | K33: 0.0079 | L33: 0.0051 | M33: 0.002 | N33: 0.0005 | O33: 0 | P33: 0 | V33: =V32-T32 -> 0.25247145 | W33: =W32-U32 -> 0.004 | X33: =X32-V32 -> -0.00013462706 | Y33: =Y32-W32 -> 0.007 | Z33: =Z32-X32 -> 0.0067102538 | AA33: =AA32-Y32 -> 0.008 | AB33: =AB32-Z32 -> -4.7073171e-05 | AC33: =AC32-AA32 -> 0.002 | ... AF33: =AF32-AD32 -> -0.0022236683 | AG33: 0.0007 | AH33: =AH32-AF32 -> 0.0050807934 | AI33: 0.0088 | AJ33: =AJ32-AH32 -> 0.0069733181 | AK33: 0.0052 | AL33: =AL32-AJ32 -> 0.0049934099
B35: CODB | G35: =G40-G30 -> -5770.812 | H35: =H40-H30 -> -6084.112 | I35: =I40-I30 -> -6543.944 | J35: =J40-J30 -> -6937.214 | K35: =K40-K30 -> -7208.425 | L35: =K35*(1+L36) -> -7438.3738 | M35: =L35*(1+M36) -> -7758.2238 | N35: =M35*(1+N36) -> -8068.5528 | O35: =N35*(1+O36) -> -8415.5006 | P35: =O35*(1+P36) -> -8777.3671 | U35: =U40-U30 -> -2835 | V35: =V40-V30 -> -2811.074 | W35: =W40-W30 -> -3033.836 | X35: =X40-X30 -> -2891.884 | Y35: =Y40-Y30 -> -2743.843 | Z35: =Z40-Z30 -> -2802.372 | AA35: =AA40-AA30 -> -3058.308 | AB35: =AB40-AB30 -> -2712.504 | ... AJ35: =AJ40-AJ30 -> -3470.45 | AK35: =AI35*(1+AK36) -> -3859.0854 | AL35: =L35-AK35 -> -3579.2884
B36: Growth % | H36: =H35/G35-1 -> 0.054290453 | I36: =I35/H35-1 -> 0.075579148 | J36: =J35/I35-1 -> 0.060096786 | K36: =K35/J35-1 -> 0.039095089 | L36: 0.0319 | M36: 0.043 | N36: 0.04 | O36: 0.043 | P36: 0.043 | W36: =W35/U35-1 -> 0.070136155 | X36: =X35/V35-1 -> 0.02874702 | Y36: =Y35/W35-1 -> -0.095586248 | Z36: =Z35/X35-1 -> -0.030952832 | AA36: =AA35/Y35-1 -> 0.1146075 | AB36: =AB35/Z35-1 -> -0.032068548 | AC36: =AC35/AA35-1 -> 0.030038832 | AD36: =AD35/AB35-1 -> 0.081633797 | ... AJ36: =AJ35/AH35-1 -> 0.018842921 | AK36: 0.0324 | AL36: =AL35/AJ35-1 -> 0.031361457
B37: % of Sales | G37: =G35/G23 -> -0.17039128 | H37: =H35/H23 -> -0.1757195 | I37: =I35/I23 -> -0.17808589 | J37: =J35/J23 -> -0.17768593 | K37: =K35/K23 -> -0.18026921 | L37: =L35/L23 -> -0.17845716 | M37: =M35/M23 -> -0.17832156 | N37: =N35/N23 -> -0.1777055 | ... P37: =P35/P23 -> -0.17759177 | U37: =U35/U23 -> -0.1826087 | V37: =V35/V23 -> -0.19529485 | W37: =W35/W23 -> -0.18880055 | X37: =X35/X23 -> -0.19512071 | Y37: =Y35/Y23 -> -0.16536148 | Z37: =Z35/Z23 -> -0.17087634 | AA37: =AA35/AA23 -> -0.1716993 | AB37: =AB35/AB23 -> -0.16894021 | ... AL37: =AL35/AL23 -> -0.17740347
B38: Change YoY % | H38: =H37-G37 -> -0.0053282171 | I38: =I37-H37 -> -0.002366386 | J38: =J37-I37 -> 0.00039995892 | K38: =K37-J37 -> -0.0025832845 | L38: =L37/K37-1 -> -0.010051927 | M38: =M37/L37-1 -> -0.00075982821 | N38: =N37/M37-1 -> -0.0034547943 | O38: =O37/N37-1 -> -0.00040522287 | P38: =P37/O37-1 -> -0.0002348759 | U38: =U37-T37 -> -0.1826087 | V38: =V37-U37 -> -0.012686149 | W38: =W37-V37 -> 0.0064942974 | X38: =X37-W37 -> -0.0063201595 | Y38: =Y37-X37 -> 0.029759229 | Z38: =Z37-Y37 -> -0.0055148637 | AA38: =AA37-Z37 -> -0.00082296238 | AB38: =AB37-AA37 -> 0.0027590946 | ... AJ38: =AJ37-AI37 -> 0.0019227083 | AK38: =AK37/AJ37-1 -> 0.00093933332 | AL38: =AL37/AK37-1 -> -0.011380778
B40: EBITDA | D40: 1714 | E40: 1735 | F40: 2867 | G40: 3001 | H40: 3022 | I40: 3157 | J40: 3487 | K40: 3788 | L40: =L30+L35 -> 4236.6327 | M40: =M30+M35 -> 4515.0813 | N40: =N30+N35 -> 4762.6372 | O40: =O30+O35 -> 4972.8559 | P40: =P30+P35 -> 5189.9693 | U40: 891 | V40: =D40-U40 -> 823 | W40: 887 | X40: =E40-W40 -> 848 | Y40: 1421 | Z40: =F40-Y40 -> 1446 | AA40: 1555 | AB40: =G40-AA40 -> 1446 | AC40: 1552 | AD40: =H40-AC40 -> 1470 | AE40: 1676 | AF40: =I40-AE40 -> 1481 | AG40: 1730 | AH40: =J40-AG40 -> 1757 | AI40: 1935 | AJ40: =K40-AI40 -> 1853 | AK40: =AK30+AK35 -> 2166.7804 | AL40: =L40-AK40 -> 2069.8523
B41: Growth % | E41: =E40/D40-1 -> 0.012252042 | F41: =F40/E40-1 -> 0.65244957 | G41: =G40/F40-1 -> 0.046738751 | H41: =H40/G40-1 -> 0.0069976674 | I41: =I40/H40-1 -> 0.044672402 | J41: =J40/I40-1 -> 0.10452962 | K41: =K40/J40-1 -> 0.086320619 | L41: =L40/K40-1 -> 0.11843524 | ... P41: =P40/O40-1 -> 0.0436597 | W41: =W40/U40-1 -> -0.0044893378 | X41: =X40/V40-1 -> 0.030376671 | Y41: =Y40/W40-1 -> 0.60202931 | Z41: =Z40/X40-1 -> 0.70518868 | AA41: =AA40/Y40-1 -> 0.094299789 | AB41: =AB40/Z40-1 -> 0 | AC41: =AC40/AA40-1 -> -0.0019292605 | AD41: =AD40/AB40-1 -> 0.01659751 | ... AL41: =AL40/AJ40-1 -> 0.11702767
B42: EBITDA Margin | D42: =D40/D23 -> 0.057288011 | E42: =E40/E23 -> 0.056167044 | F42: =F40/F23 -> 0.086897221 | G42: =G40/G23 -> 0.088608716 | H42: =H40/H23 -> 0.087280499 | I42: =I40/I23 -> 0.085914113 | J42: =J40/J23 -> 0.089314072 | K42: =K40/K23 -> 0.094730788 | ... P42: =P40/P23 -> 0.10500823 | U42: =U40/U23 -> 0.057391304 | V42: =V40/V23 -> 0.057176601 | W42: =W40/W23 -> 0.055199452 | X42: =X40/X23 -> 0.057216112 | Y42: =Y40/Y23 -> 0.085638522 | Z42: =Z40/Z23 -> 0.088170732 | AA42: =AA40/AA23 -> 0.087300696 | AB42: =AB40/AB23 -> 0.090059791 | ... AL42: =AL40/AL23 -> 0.10258994
B43: Change YoY % | D43: =D42-C42 -> 0.057288011 | E43: =E42-D42 -> -0.0011209666 | F43: =F42-E42 -> 0.030730176 | G43: =G42-F42 -> 0.0017114956 | H43: =H42-G42 -> -0.0013282171 | I43: =I42-H42 -> -0.001366386 | J43: =J42-I42 -> 0.0033999589 | K43: =K42-J42 -> 0.0054167155 | ... P43: =P42-O42 -> 4.1721825e-05 | U43: =U42-S42 -> 0.057391304 | V43: =V42-T42 -> 0.057176601 | W43: =W42-U42 -> -0.002191852 | X43: =X42-V42 -> 3.9510911e-05 | Y43: =Y42-W42 -> 0.03043907 | Z43: =Z42-X42 -> 0.030954619 | AA43: =AA42-Y42 -> 0.0016621739 | AB43: =AB42-Z42 -> 0.001889059 | ... AL43: =AL42-AJ42 -> 0.0068672406
L44: =L45-K45 -> -126
B45: D&A | D45: -557 | E45: -552 | F45: -1249 | G45: -1299 | H45: -1307 | I45: -1392 | J45: -1460 | K45: -1680 | L45: =K45*(1+L46) -> -1806 | M45: =L45*(1+M46) -> -1896.3 | N45: =M45*(1+N46) -> -1991.115 | O45: =N45*(1+O46) -> -2090.6708 | P45: =O45*(1+P46) -> -2195.2043 | U45: -291 | V45: =V50-V40 -> -266 | W45: -285 | X45: -285 | Y45: -632 | Z45: -632 | AA45: -652 | AB45: =G45-AA45 -> -647 | AC45: -656 | AD45: =H45-AC45 -> -651 | AE45: -685 | AF45: =I45-AE45 -> -707 | AG45: -723 | AH45: =J45-AG45 -> -737 | AI45: -858 | AJ45: =K45-AI45 -> -822 | AK45: =AI45*(1+AK46) -> -922.35 | AL45: =L45-AK45 -> -883.65
B46: Growth % | E46: =E45/D45-1 -> -0.0089766607 | F46: =F45/E45-1 -> 1.2626812 | G46: =G45/F45-1 -> 0.040032026 | H46: =H45/G45-1 -> 0.0061585835 | I46: =I45/H45-1 -> 0.06503443 | J46: =J45/I45-1 -> 0.048850575 | K46: =K45/J45-1 -> 0.15068493 | L46: 0.075 | M46: 0.05 | N46: 0.05 | O46: 0.05 | P46: 0.05 | W46: =W45/U45-1 -> -0.020618557 | X46: =X45/V45-1 -> 0.071428571 | Y46: =Y45/W45-1 -> 1.2175439 | Z46: =Z45/X45-1 -> 1.2175439 | AA46: =AA45/Y45-1 -> 0.03164557 | AB46: =AB45/Z45-1 -> 0.023734177 | AC46: =AC45/AA45-1 -> 0.0061349693 | AD46: =AD45/AB45-1 -> 0.0061823802 | ... AJ46: =AJ45/AH45-1 -> 0.11533243 | AK46: 0.075 | AL46: =AL45/AJ45-1 -> 0.075
...

Sheet PL
B1: Coles Group (COL.AX)
B2: A$M
C3: =Model!C3 -> FY17 | D3: =Model!D3 -> FY18 | E3: =Model!E3 -> FY19 | F3: =Model!F3 -> FY20 | G3: =Model!G3 -> FY21 | H3: =Model!H3 -> FY22 | I3: =Model!I3 -> FY23 | J3: =Model!J3 -> FY24 | K3: =Model!K3 -> FY25 | L3: FY26E | M3: FY27E | N3: FY28E | O3: FY29E | P3: FY30E | R3: =Model!S3 -> 1H17 | S3: =Model!T3 -> 2H17 | T3: =Model!U3 -> 1H18 | U3: =Model!V3 -> 2H18 | V3: =Model!W3 -> 1H19 | W3: =Model!X3 -> 2H19 | X3: =Model!Y3 -> 1H20 | Y3: =Model!Z3 -> 2H20 | ... AI3: =Model!AJ3 -> 2H25 | AJ3: 1H26E | AK3: 2H26E
B4: P&L
A5: Total Sales | B5: Sales | C5: =VLOOKUP($A$5,Model!1:1048576,MATCH(PL!C3,Model!3:3,0),FALSE) -> 39125 | D5: =VLOOKUP($A$5,Model!1:1048576,MATCH(PL!D3,Model!3:3,0),FALSE) -> 39007 | E5: =VLOOKUP($A$5,Model!1:1048576,MATCH(PL!E3,Model!3:3,0),FALSE) -> 35001 | F5: =VLOOKUP($A$5,Model!1:1048576,MATCH(PL!F3,Model!3:3,0),FALSE) -> 37408 | G5: =VLOOKUP($A$5,Model!1:1048576,MATCH(PL!G3,Model!3:3,0),FALSE) -> 38585 | H5: =VLOOKUP($A$5,Model!1:1048576,MATCH(PL!H3,Model!3:3,0),FALSE) -> 38237 | I5: =VLOOKUP($A$5,Model!1:1048576,MATCH(PL!I3,Model!3:3,0),FALSE) -> 40483 | J5: =VLOOKUP($A$5,Model!1:1048576,MATCH(PL!J3,Model!3:3,0),FALSE) -> 43571 | ... P5: =VLOOKUP($A$5,Model!1:1048576,MATCH(PL!P3,Model!3:3,0),FALSE) -> 53438.643 | T5: =VLOOKUP($A$5,Model!1:1048576,MATCH(PL!T3,Model!3:3,0),FALSE) -> 20246 | U5: =VLOOKUP($A$5,Model!1:1048576,MATCH(PL!U3,Model!3:3,0),FALSE) -> 18761 | V5: =VLOOKUP($A$5,Model!1:1048576,MATCH(PL!V3,Model!3:3,0),FALSE) -> 18266 | W5: =VLOOKUP($A$5,Model!1:1048576,MATCH(PL!W3,Model!3:3,0),FALSE) -> 16735 | X5: =VLOOKUP($A$5,Model!1:1048576,MATCH(PL!X3,Model!3:3,0),FALSE) -> 18856 | Y5: =VLOOKUP($A$5,Model!1:1048576,MATCH(PL!Y3,Model!3:3,0),FALSE) -> 18552 | Z5: =VLOOKUP($A$5,Model!1:1048576,MATCH(PL!Z3,Model!3:3,0),FALSE) -> 20390 | AA5: =VLOOKUP($A$5,Model!1:1048576,MATCH(PL!AA3,Model!3:3,0),FALSE) -> 18195 | ... AK5: =VLOOKUP($A$5,Model!1:1048576,MATCH(PL!AK3,Model!3:3,0),FALSE) -> 22005.318
A6: Total Sales Growth | B6: Growth % | D6: =D5/C5-1 -> -0.0030159744 | E6: =E5/D5-1 -> -0.10269952 | F6: =F5/E5-1 -> 0.068769464 | G6: =G5/F5-1 -> 0.031463858 | H6: =H5/G5-1 -> -0.0090190489 | I6: =I5/H5-1 -> 0.058738918 | J6: =J5/I5-1 -> 0.076278932 | K6: =K5/J5-1 -> 0.017924766 | ... P6: =P5/O5-1 -> 0.041851957 | V6: =V5/T5-1 -> -0.097797096 | W6: =W5/U5-1 -> -0.10798998 | X6: =X5/V5-1 -> 0.032300449 | Y6: =Y5/W5-1 -> 0.10857484 | Z6: =Z5/X5-1 -> 0.081353415 | AA6: =AA5/Y5-1 -> -0.019243208 | AB6: =AB5/Z5-1 -> -0.018391368 | AC6: =AC5/AA5-1 -> 0.0014839242 | ... AK6: =AK5/AI5-1 -> 0.032289641
B8: Other Revenue | D8: 211 | E8: 288.4 | F8: 376 | G8: 370 | H8: 377 | I8: 108 | J8: 113 | K8: 135 | T8: 110 | U8: =D8-T8 -> 101 | V8: 200 | W8: =E8-V8 -> 88.4 | X8: 191 | Y8: =F8-X8 -> 185 | Z8: 191 | AA8: =G8-Z8 -> 179 | AB8: 55 | AC8: =H8-AB8 -> 322 | AD8: 63 | AE8: =I8-AD8 -> 45 | AF8: 58 | AG8: =J8-AF8 -> 55 | AH8: 71 | AI8: =K8-AH8 -> 64
B9: Cost of Sales | C9: =C10-C5 -> -30129 | D9: =D10-D5 -> -29981 | E9: =E10-E5 -> -25790 | F9: =F10-F5 -> -27667 | G9: =G10-G5 -> -28426 | H9: =H10-H5 -> -28292 | I9: =I10-I5 -> -29926 | J9: =J10-J8-J5 -> -32392 | K9: =K10-K8-K5 -> -32649 | L9: =L10-L5 -> -33284.2 | M9: =M10-M5 -> -34074.072 | N9: =N10-N5 -> -35484.338 | O9: =O10-O5 -> -36963.698 | P9: =P10-P5 -> -38499.861 | T9: =T10-T5 -> -15742 | U9: =U10-U5 -> -14239 | V9: =V10-V5 -> -13652 | W9: =W10-W5 -> -12138 | X9: =X10-X5 -> -14058 | Y9: =Y10-Y5 -> -13609 | Z9: =Z10-Z5 -> -15035 | AA9: =G9-Z9 -> -13391 | AB9: =AB10-AB5 -> -14875 | AC9: =H9-AB9 -> -13417 | AD9: =AD10-AD5 -> -15363 | AE9: =AE10-AE5 -> -14563 | AF9: =AF10-AF5 -> -16487 | AG9: =AG10-AG5 -> -15792 | AH9: =AH10-AH5 -> -16914 | AI9: =AI10-AI5 -> -15600 | AJ9: =AJ10-AJ5 -> -18086.212 | AK9: =AK10-AK5 -> -15197.988
A10: Gross Profit | B10: Gross Profit Reported | C10: 8996 | D10: 9026 | E10: 9211 | F10: 9741 | G10: 10159 | H10: 9945 | I10: 10557 | J10: 11292 | K10: 11838 | L10: =Model!L30+Model!L99 -> 12533.268 | M10: =Model!M30+Model!M99 -> 13160.479 | N10: =Model!N30+Model!N99 -> 13740.543 | O10: =Model!O30+Model!O99 -> 14328.276 | P10: =Model!P30+Model!P99 -> 14938.782 | T10: 4504 | U10: =D10-T10 -> 4522 | V10: 4614 | W10: =E10-V10 -> 4597 | X10: 4798 | Y10: =F10-X10 -> 4943 | Z10: 5355 | AA10: =G10-Z10 -> 4804 | AB10: 5140 | AC10: =H10-AB10 -> 4805 | AD10: 5446 | AE10: =I10-AD10 -> 5111 | AF10: 5729 | AG10: =J10-AF10 -> 5563 | AH10: 6121 | AI10: =K10-AH10 -> 5717 | AJ10: =Model!AJ30+Model!AJ99 -> 5725.938 | AK10: =L10-AJ10 -> 6807.3304
B11: Gross Margin | C11: =C10/C5 -> 0.22992971 | D11: =D10/D5 -> 0.23139437 | E11: =E10/E5 -> 0.26316391 | F11: =F10/F5 -> 0.26039885 | G11: =G10/G5 -> 0.26328884 | H11: =H10/H5 -> 0.2600884 | I11: =I10/I5 -> 0.26077613 | J11: =J10/J5 -> 0.2591632 | K11: =K10/K5 -> 0.26691017 | T11: =T10/T5 -> 0.2224637 | U11: =U10/U5 -> 0.24103193 | V11: =V10/V5 -> 0.25260046 | W11: =W10/W5 -> 0.27469376 | X11: =X10/X5 -> 0.25445482 | Y11: =Y10/Y5 -> 0.26644028 | Z11: =Z10/Z5 -> 0.26262874 | AA11: =AA10/AA5 -> 0.26402858 | ... AI11: =AI10/AI5 -> 0.26818971
B12: Change YoY % | D12: =D11-C11 -> 0.0014646527 | E12: =E11-D11 -> 0.031769544 | F12: =F11-E11 -> -0.0027650644 | G12: =G11-F11 -> 0.0028899976 | H12: =H11-G11 -> -0.0032004468 | I12: =I11-H11 -> 0.0006877322 | J12: =J11-I11 -> -0.0016129234 | K12: =K11-J11 -> 0.0077469683 | V12: =V11-T11 -> 0.030136763 | W12: =W11-U11 -> 0.033661828 | X12: =X11-V11 -> 0.0018543556 | Y12: =Y11-W11 -> -0.0082534796 | Z12: =Z11-X11 -> 0.0081739241 | AA12: =AA11-Y11 -> -0.0024116967 | AB12: =AB11-Z11 -> -0.0058213451 | AC12: =AC11-AA11 -> -0.00033633913 | ... AI12: =AI11-AG11 -> 0.0076886541
B14: Branch & Administration Expenses
B15: Employee Expenses | D15: -4321.4 | E15: -4533 | F15: -4768 | G15: -4898 | H15: -4804 | I15: -5118 | J15: -5512 | K15: -5798
B16: Occupancy | D16: -1600.3 | E16: -1635 | F16: -652 | G16: -707 | H16: -701 | I16: -774 | J16: -898 | K16: -960
B17: D&A | D17: -649.6 | E17: -640 | F17: -1440 | G17: -1513 | H17: -1385 | I17: -1461 | J17: -1398 | K17: -1569
B18: Marketing | D18: -212.5 | E18: -213 | F18: -216 | G18: -242 | H18: -230 | I18: -234 | J18: -233 | K18: -244
B19: Impairment | D19: -49 | E19: -42 | F19: 41 | G19: 3 | H19: 11 | I19: 11 | J19: -55 | K19: -4
B20: Other store expenses | D20: 0 | E20: -651 | F20: -659 | G20: -623 | H20: -551 | I20: -668 | J20: -655 | K20: -704
B21: Other administrative expenses | D21: =(898.9)*-1 -> -898.9 | E21: -317 | F21: -387 | G21: -412 | H21: -537 | I21: -604 | J21: -621 | K21: -609
B22: Total | D22: =SUM(D15:D21) -> -7731.7 | E22: =SUM(E15:E21) -> -8031 | F22: =SUM(F15:F21) -> -8081 | G22: =SUM(G15:G21) -> -8392 | H22: =SUM(H15:H21) -> -8197 | I22: =SUM(I15:I21) -> -8848 | J22: =SUM(J15:J21) -> -9372 | K22: =SUM(K15:K21) -> -9888
A24: EBITDA | B24: EBITDA Normalised | C24: =C31-C29 -> 2157 | D24: =D31-D29 -> 2044.6 | E24: =E31-E29 -> 1964.6 | F24: =F31-F29 -> 3257 | G24: =G31-G29 -> 3432 | H24: =H31-H29 -> 3259 | I24: =I31-I29 -> 3382 | J24: =J31-J29 -> 3659 | ... P24: =P31-P29 -> 5287.9771 | T24: =T31-T29 -> 1109 | U24: =U31-U29 -> 935.6 | V24: =V31-V29 -> 1043 | W24: =W31-W29 -> 921.6 | X24: =X31-X29 -> 1665 | Y24: =Y31-Y29 -> 1592 | Z24: =Z31-Z29 -> 1802 | AA24: =AA31-AA29 -> 1630 | ... AK24: =AK31-AK29 -> 2130.0733
