Workbook
Name \0: #REF!
Name \a: #REF!
Name \b: #REF!
Name \c: #REF!
Name \d: #REF!
Name \e: #REF!
Name \f: #REF!
Name \g: #REF!
Name \h: #REF!
Name \i: #REF!
Name \j: #REF!
Name \k: #REF!
Name \l: #REF!
Name \m: #REF!
Name \p: #REF!
Name \s: #REF!
Name \u: #REF!
Name \z: #REF!
Name _: #REF!
Name _.dbf: #REF!
Name _?: #REF!
Name _??????: #REF!
Name __?: #REF!
Name __??????: #REF!
Name ___________________2010: #REF!
Name __________________2010: #REF!
Name _________________2010: #REF!
Name ________________2010: #REF!
Name _______________2010: #REF!
Name _______________KY1: #REF!
Name ______________2010: #REF!
Name ______________KY1: #REF!
Name _____________2010: #REF!
Name _____________KY1: #REF!
Name ____________2010: #REF!
Name ____________dep08: #REF!
Name ____________KY1: #REF!
Name ____________to020831: #REF!
Name ____________x2: #REF!
Name ____________X4: #REF!
Name ___________2010: #REF!
Name ___________dep08: #REF!
Name ___________KY1: #REF!
Name ___________to020831: #REF!
Name ___________x2: #REF!
Name ___________X4: #REF!
Name __________2010: #REF!
Name __________dep08: #REF!
Name __________KY1: #REF!
Name __________to020831: #REF!
Name __________x2: #REF!
Name __________X4: #REF!
Name _________2010: #REF!
Name _________dep08: #REF!
Name _________KY1: #REF!
Name _________to020831: #REF!
Name _________x2: #REF!
Name _________X4: #REF!
Name ________2010: #REF!
Name ________dep08: #REF!

Sheet Cover
D8: Mixue (2097.HK)
D10: Michelle Cheng | G10: Xinyu Ruan | J10: Carol Chen | M10: Molly Dai
D11: 852 2978 6631 | G11: 852 2978 7347 | J11: 852 2978 7999 | M11: +852 3966-4000
D12: Michelle.Cheng@gs.com | G12: xinyu.ruan@gs.com | J12: carol.chen@gs.com | M12: molly.dai@gs.com
D13: Goldman Sachs (Asia) L.L.C. | G13: Goldman Sachs (Asia) L.L.C. | J13: Goldman Sachs (Asia) L.L.C. | M13: Goldman Sachs (Asia) L.L.C.
D15: Consolidated basis | L15: Published date: | N15: =G37 -> 45897
D21: Key statistics
D22: Rating | G22: Buy
D24: Ticker | G24: 2097.HK
D26: Currency | G26: HKD
D27: 12-m target price | G27: 579
D28: Price as of | E28: 45896 | G28: 460.4
D29: Upside/downside % | G29: 0.25760209
D31: Market cap. (USD mn) | G31: 22441.048
D32: ADS outstanding (mn) | G32: 379.6188
D34: M&A probability | G34: 3
D35: Valuation methodology | G35: P/E
D37: Current publication date | G37: 45897
D38: Previous publication date | G38: 45896

Sheet IS
B4: Rmb mn | C4: 43800 | D4: 44166 | E4: 44561 | F4: 44926 | G4: 45291 | H4: 45657 | I4: 46022 | J4: 46387 | K4: =EDATE(J4,12) -> 46752 | L4: RMB/HKD | M4: 45473 | N4: =EDATE(M4,6) -> 45656 | O4: 45838 | P4: =EDATE(O4,6) -> 46021
B5: Accounting standards: IFRS | C5: 2019 | D5: =C5+1 -> 2020 | E5: 2021 | F5: 2022 | G5: 2023 | H5: 2024 | I5: 2025E | J5: 2026E | K5: 2027E | L5: 1.09 | M5: 2024 | N5: 2024 | O5: 2025E | P5: 2025E
B6: Income statement
B7: Revenue | C7: 2566.03 | D7: 4679.9973 | E7: 10350.986 | F7: 13575.577 | G7: 20302.465 | H7: 24828.874 | I7: =Driver!I384 -> 32331.616 | J7: =Driver!J384 -> 37879.877 | K7: =Driver!K384 -> 43890.622 | M7: 10677.054 | N7: =H7-M7 -> 14151.82 | O7: 14874.809 | P7: =Driver!P384 -> 17456.807
B8: yoy | D8: =D7/C7-1 -> 0.82382798 | E8: =E7/D7-1 -> 1.2117504 | F8: =F7/E7-1 -> 0.31152501 | G8: =G7/F7-1 -> 0.49551397 | H8: =H7/G7-1 -> 0.22294874 | I8: =I7/H7-1 -> 0.30217812 | J8: =J7/I7-1 -> 0.17160479 | K8: =K7/J7-1 -> 0.15867912 | O8: =O7/M7-1 -> 0.39315667 | P8: =P7/N7-1 -> 0.23353798
A9: =B9 -> Cost of sales | B9: Cost of sales | E9: -7107.124 | F9: -9728.74 | G9: -14303.498 | H9: -16768.667 | I9: =Driver!I584 -> -22194.396 | J9: =Driver!J584 -> -26071.256 | K9: =Driver!K584 -> -30188.089 | M9: -7274.359 | N9: =H9-M9 -> -9494.308 | O9: -10168.436 | P9: =Driver!P584 -> -12025.96
B10: % of company sales | E10: =E9/E7 -> -0.68661324 | F10: =F9/F7 -> -0.71663547 | G10: =G9/G7 -> -0.70452026 | H10: =H9/H7 -> -0.67536961 | I10: =I9/I7 -> -0.68646107 | J10: =J9/J7 -> -0.68826137 | K10: =K9/K7 -> -0.68780272 | M10: =M9/M7 -> -0.68130769 | N10: =N9/N7 -> -0.67088954 | O10: =O9/O7 -> -0.68360111 | P10: =P9/P7 -> -0.68889801
A11: =B11 -> Selling and distribution expenses | B11: Selling and distribution expenses | E11: -405.766 | F11: -774.431 | G11: -1318.588 | H11: -1599.474 | I11: =I166 -> -2011.6705 | J11: =J166 -> -2292.487 | K11: =K166 -> -2603.5881 | M11: -651.491 | N11: =H11-M11 -> -947.983 | O11: -913.679 | P11: =P166 -> -1097.9915
B12: % of company sales | E12: =E11/E7 -> -0.03920071 | F12: =F11/F7 -> -0.057045899 | G12: =G11/G7 -> -0.064947187 | H12: =H11/H7 -> -0.064419917 | I12: =I11/I7 -> -0.062219917 | J12: =J11/J7 -> -0.060519917 | K12: =K11/K7 -> -0.059319917 | M12: =M11/M7 -> -0.061017861 | N12: =N11/N7 -> -0.066986649 | O12: =O11/O7 -> -0.061424587 | P12: =P11/P7 -> -0.062897611
A13: =B13 -> Administrative expenses | B13: Administrative expenses | E13: -374.665 | F13: -496.506 | G13: -610.622 | H13: -755.115 | I13: =I194 -> -942.67249 | J13: =J194 -> -1031.6104 | K13: =K194 -> -1116.3023 | M13: -279.515 | N13: =H13-M13 -> -475.6 | O13: -437.65 | P13: =P194 -> -505.02249
B14: % of company sales | E14: =E13/E7 -> -0.036196069 | F14: -0.0364 | G14: =G13/G7 -> -0.030076249 | H14: =H13/H7 -> -0.030412777 | I14: =I13/I7 -> -0.029156367 | J14: =J13/J7 -> -0.027233732 | K14: =K13/K7 -> -0.025433732 | M14: =M13/M7 -> -0.026179038 | N14: =N13/N7 -> -0.033606985 | O14: =O13/O7 -> -0.029422227 | P14: =P13/P7 -> -0.028929831
A15: =B15 -> Research and development expenses | B15: Research and development expenses | E15: -17.151 | F15: -32.304 | G15: -85 | H15: -104.87 | I15: =I220 -> -104.2278 | J15: =J220 -> -114.53782 | K15: =K220 -> -123.93445 | M15: -40.327 | N15: =H15-M15 -> -64.543 | O15: -41.037 | P15: =P220 -> -63.190803
B16: % of company sales | E16: =E15/E7 -> -0.0016569436 | F16: =F15/F7 -> -0.0023795674 | G16: =G15/G7 -> -0.0041866837 | H16: =H15/H7 -> -0.0042237115 | I16: =I15/I7 -> -0.0032237115 | J16: =J15/J7 -> -0.0030237115 | K16: =K15/K7 -> -0.0028237115 | M16: =M15/M7 -> -0.0037769782 | N16: =N15/N7 -> -0.0045607561 | O16: =O15/O7 -> -0.0027588253 | P16: =P15/P7 -> -0.0036198373
A18: =B18 -> Adjusted operating profit | B18: Adjusted operating profit | E18: =E7+E9+E11+E13+E15 -> 2446.28 | F18: =F7+F9+F11+F13+F15 -> 2543.596 | G18: =G7+G9+G11+G13+G15 -> 3984.757 | H18: =H7+H9+H11+H13+H15 -> 5600.748 | I18: =I7+I9+I11+I13+I15 -> 7078.6497 | J18: =J7+J9+J11+J13+J15 -> 8369.9858 | K18: =K7+K9+K11+K13+K15 -> 9858.7079 | M18: =M7+M9+M11+M13+M15 -> 2431.362 | N18: =N7+N9+N11+N13+N15 -> 3169.386 | O18: =O7+O9+O11+O13+O15 -> 3314.007 | P18: =P7+P9+P11+P13+P15 -> 3764.6427
B19: Operating Margin | E19: =E18/E7 -> 0.23633304 | F19: =F18/F7 -> 0.18736559 | G19: =G18/G7 -> 0.19626962 | H19: =H18/H7 -> 0.22557398 | I19: =I18/I7 -> 0.21893894 | J19: =J18/J7 -> 0.22096127 | K19: =K18/K7 -> 0.22461992 | M19: =M18/M7 -> 0.22771843 | N19: =N18/N7 -> 0.22395607 | O19: =O18/O7 -> 0.22279325 | P19: =P18/P7 -> 0.21565471
A21: =B21 -> EBITDA | B21: EBITDA | E21: =E18-E314-E316 -> 2504.716 | F21: =F18-F314-F316 -> 2651.578 | G21: =G18-G314-G316 -> 4149.061 | H21: =H18-H314-H316 -> 5920.925 | I21: =I18-I314-I316 -> 7292.5092 | J21: =J18-J314-J316 -> 8736.6541 | K21: =K18-K314-K316 -> 10279.973
A23: =B23 -> Other income and gains (net) | B23: Other income and gains (net) | E23: 135.181 | F23: 127.915 | G23: 247.632 | H23: 219.547 | I23: =I155 -> 363.963 | J23: =J155 -> 450.0968 | K23: =K155 -> 548.74908 | M23: 80.889 | N23: =H23-M23 -> 138.658 | O23: 158.602 | P23: =P155 -> 205.361
A24: =B24 -> Finance costs | B24: Finance costs | E24: -5.973 | F24: -9.19 | G24: -14.697 | H24: -6.367 | I24: =I353+I357 -> -3.0212545 | J24: =J353+J357 -> -3.0212545 | K24: =K353+K357 -> -3.0212545 | M24: -4.405 | N24: =H24-M24 -> -1.962 | O24: -2.072 | P24: =I24-O24 -> -0.94925453
A25: =B25 -> (Impairment losses)/reversal of impairment losses on financial assets | B25: (Impairment losses)/reversal of impairment losses on financial assets | E25: -1.787 | F25: -4.098 | G25: 1.638 | H25: -0.329 | M25: -3.077 | N25: =H25-M25 -> 2.748 | O25: -1.101 | P25: =I25-O25 -> 1.101
A26: =B26 -> Impairment of property, plant and equipment | B26: Impairment of property, plant and equipment | E26: -14.827 | F26: 0 | G26: -65.524 | H26: 0 | N26: =H26-M26 -> 0 | P26: =I26-O26 -> 0
A27: =B27 -> Share of (losses)/profits of an associate | B27: Share of (losses)/profits of an associate | E27: 0 | F27: -0.18 | G27: 0.196 | H27: -3.016 | M27: -3.016 | N27: =H27-M27 -> 0 | O27: -1.154 | P27: =I27-O27 -> 1.154
A29: =B29 -> Profit before tax | B29: Profit before tax | C29: 600.02287 | D29: 944.39943 | E29: =E7+E9+E23+E11+E13+E15+SUM(E24:E27) -> 2558.874 | F29: =F7+F9+F23+F11+F13+F15+SUM(F24:F27) -> 2658.043 | G29: =G7+G9+G23+G11+G13+G15+SUM(G24:G27) -> 4154.002 | H29: =H7+H9+H23+H11+H13+H15+SUM(H24:H27) -> 5810.583 | I29: =I7+I9+I23+I11+I13+I15+SUM(I24:I27) -> 7439.5915 | J29: =J7+J9+J23+J11+J13+J15+SUM(J24:J27) -> 8817.0613 | K29: =K7+K9+K23+K11+K13+K15+SUM(K24:K27) -> 10404.436 | M29: =M7+M9+M23+M11+M13+M15+SUM(M24:M27) -> 2501.753 | N29: =N7+N9+N23+N11+N13+N15+SUM(N24:N27) -> 3308.83 | O29: =O7+O9+O23+O11+O13+O15+SUM(O24:O27) -> 3468.282 | P29: =P7+P9+P23+P11+P13+P15+SUM(P24:P27) -> 3971.3095
A30: =B30 -> Income tax expense | B30: Income tax expense | C30: -158.30353 | D30: -313.57961 | E30: -646.932 | F30: -644.952 | G30: -967.397 | H30: -1356.38 | I30: =I29*I31 -> -1736.6438 | J30: =J29*J31 -> -2058.1903 | K30: =K29*K31 -> -2428.7354 | M30: -614.854 | N30: =H30-M30 -> -741.526 | O30: -750.068 | P30: =I30-O30 -> -986.57583
B31: Tax rate | C31: =C30/C29 -> -0.26382916 | D31: =D30/D29 -> -0.3320413 | E31: =E30/E29 -> -0.25281901 | F31: =F30/F29 -> -0.24264167 | G31: =G30/G29 -> -0.23288313 | H31: =H30/H29 -> -0.23343269 | I31: =H31 -> -0.23343269 | J31: =I31 -> -0.23343269 | K31: =J31 -> -0.23343269 | M31: =H31 -> -0.23343269 | N31: =N30/N29 -> -0.2241052 | O31: =I31 -> -0.23343269 | P31: =P30/P29 -> -0.24842582
A32: =B32 -> Profit for the year (Before Non-Controlling Interests) | B32: Profit for the year (Before Non-Controlling Interests) | C32: =C29+C30 -> 441.71934 | D32: =D29+D30 -> 630.81982 | E32: =E30+E29 -> 1911.942 | F32: =F30+F29 -> 2013.091 | G32: =G30+G29 -> 3186.605 | H32: =H30+H29 -> 4454.203 | I32: =I30+I29 -> 5702.9477 | J32: =J30+J29 -> 6758.871 | K32: =K30+K29 -> 7975.7003 | M32: =M30+M29 -> 1886.899 | N32: =N30+N29 -> 2567.304 | O32: =O30+O29 -> 2718.214 | P32: =P30+P29 -> 2984.7337
A33: =B33 -> Non-controlling interests | B33: Non-controlling interests | C33: 3.0481697 | D33: 1.1468928 | E33: -1.581 | F33: -16.376 | G33: -49.264 | H33: -17.699 | I33: -50 | J33: =I33*(1+J75) -> -54.476979 | K33: =J33*(1+K75) -> -61.146541 | M33: -2.441 | N33: =H33-M33 -> -15.258 | O33: -25.33 | P33: =I33-O33 -> -24.67
A34: =B34 -> Profit attributed to Owners of the parent | B34: Profit attributed to Owners of the parent | C34: =SUM(C32:C33) -> 444.76751 | D34: =SUM(D32:D33) -> 631.96671 | E34: =SUM(E32:E33) -> 1910.361 | F34: =SUM(F32:F33) -> 1996.715 | G34: =SUM(G32:G33) -> 3137.341 | H34: =SUM(H32:H33) -> 4436.504 | I34: =SUM(I32:I33) -> 5652.9477 | J34: =SUM(J32:J33) -> 6704.394 | K34: =SUM(K32:K33) -> 7914.5538 | M34: =SUM(M32:M33) -> 1884.458 | N34: =SUM(N32:N33) -> 2552.046 | O34: =SUM(O32:O33) -> 2692.884 | P34: =SUM(P32:P33) -> 2960.0637
B35: NPM | C35: =C34/C7 -> 0.17332904 | D35: =D34/D7 -> 0.1350357 | E35: =E34/E7 -> 0.18455836 | F35: =F34/F7 -> 0.14708141 | G35: =G34/G7 -> 0.15453005 | H35: =H34/H7 -> 0.17868325 | I35: =I34/I7 -> 0.17484272 | J35: =J34/J7 -> 0.17699091 | K35: =K34/K7 -> 0.18032448 | M35: =M34/M7 -> 0.17649606 | N35: =N34/N7 -> 0.18033341 | O35: =O34/O7 -> 0.18103654 | P35: =P34/P7 -> 0.16956501
B36: yoy | D36: =D34/C34-1 -> 0.42089226 | E36: =E34/D34-1 -> 2.0228823 | F36: =F34/E34-1 -> 0.045202975 | G36: =G34/F34-1 -> 0.57125128 | H36: =H34/G34-1 -> 0.41409684 | I36: =I34/H34-1 -> 0.27418969 | J36: =J34/I34-1 -> 0.18599966 | K36: =K34/J34-1 -> 0.18050248
B38: Adjusted NI after minority interest | C38: =C34-C40-C41-C42 -> 444.76751 | D38: =D34-D40-D41-D42 -> 631.96671 | E38: =E34-E40-E41-E42 -> 1946.0714 | F38: =F34-F40-F41-F42 -> 2024.9231 | G38: =G34-G40-G41-G42 -> 3186.6182 | H38: =H34-H40-H41-H42 -> 4493.5145 | I38: =I34-I40-I41-I42 -> 5684.209 | J38: =J34-J40-J41-J42 -> 6724.6898 | K38: =K34-K40-K41-K42 -> 7933.681 | M38: =M34-M40-M41-M42 -> 1898.22 | N38: =N34-N40-N41-N42 -> 2595.2945 | O38: =O34-O40-O41-O42 -> 2713.6991 | P38: =P34-P40-P41-P42 -> 2970.5098
B39: Adjusted NPM | C39: =C38/C7 -> 0.17332904 | D39: =D38/D7 -> 0.1350357 | E39: =E38/E7 -> 0.18800831 | F39: =F38/F7 -> 0.14915927 | G39: =G38/G7 -> 0.15695721 | H39: =H38/H7 -> 0.18097939 | I39: =I38/I7 -> 0.17580961 | J39: =J38/J7 -> 0.17752671 | K39: =K38/K7 -> 0.18076028 | M39: =M38/M7 -> 0.177785 | N39: =N38/N7 -> 0.18338945 | O39: =O38/O7 -> 0.1824359 | P39: =P38/P7 -> 0.17016341
B40: Equity-settled share-based payment expenses | E40: =E242 -> -22.554 | F40: =F242 -> -24.981 | G40: =G242 -> -16.427 | H40: =H242 -> -15.786 | I40: =I7*I92 -> -20.556184 | J40: =J7*J92 -> -20.295736 | K40: =K7*K92 -> -19.127183 | M40: -6.521 | N40: =H40-M40 -> -9.265 | O40: -9.266 | P40: =I40-O40 -> -11.290184
B41: Listing expenses, after tax | G41: =-10.9*(1+G31) -> -8.3615739 | H41: =-59.069*(1+H31) -> -45.280365 | I41: =O41 -> -3.0394394 | J41: 0 | K41: 0 | M41: =-9.179*(1+H31) -> -7.0363214 | N41: =H41-M41 -> -38.244043 | O41: =-3.965*(1+H31) -> -3.0394394 | P41: =I41-O41 -> 0
B42: Other one-offs incl. impairment, FX | E42: =(E25+E26+E152)*(1+E31) -> -13.156363 | F42: =(F25+F26+F152)*(1+F31) -> -3.2271038 | G42: =(G25+G26+G152)*(1+G31) -> -24.488672 | H42: =(H25+H26+H152)*(1+H31) -> 4.0559077 | I42: =(I25+I26+I152)*(1+I31) -> -7.6656731 | J42: =(J25+J26+J152)*(1+J31) -> 0 | K42: =(K25+K26+K152)*(1+K31) -> 0 | M42: =(M25+M26+M152)*(1+M31) -> -0.20467347 | N42: =H42-M42 -> 4.2605811 | O42: =(O25+O26+O152)*(1+O31) -> -8.5096637 | P42: =I42-O42 -> 0.84399061
B43: yoy | D43: =D38/C38-1 -> 0.42089226 | E43: =E38/D38-1 -> 2.079389 | F43: =F38/E38-1 -> 0.040518422 | G43: =G38/F38-1 -> 0.5736984 | H43: =H38/G38-1 -> 0.41012011 | I43: =I38/H38-1 -> 0.26498068 | J43: =J38/I38-1 -> 0.1830476 | K43: =K38/J38-1 -> 0.17978394
B44: Other comprehensive income | E44: =SUM(E45:E46) -> -0.181 | F44: =SUM(F45:F46) -> -1.035 | G44: =SUM(G45:G46) -> -0.809 | H44: =SUM(H45:H46) -> -4.107
B45: Exchange differences on translation of foreign operations | E45: -0.181 | F45: -1.035 | G45: 0.131 | H45: -3.237
B46: Changes in fair value of equity investments designated at fair value through other comprehensive income | E46: 0 | F46: 0 | G46: -0.94 | H46: -0.87
B48: EPS - Basic | H48: =H38/H54 -> 11.836912 | I48: =I38/I54 -> 14.973465 | J48: =J38/J54 -> 17.714322 | K48: =K38/K54 -> 20.899073 | M48: =M38/M54 -> 5.0003319 | N48: =N38/N54 -> 6.8365804 | O48: =O38/O54 -> 7.1484845 | P48: =P38/P54 -> 7.8249809
B49: EPS - Diluted | H49: =H38/H55 -> 11.836912 | I49: =I38/I55 -> 14.973465 | J49: =J38/J55 -> 17.714322 | K49: =K38/K55 -> 20.899073 | M49: =M38/M55 -> 5.0003319 | N49: =N38/N55 -> 6.8365804 | O49: =O38/O55 -> 7.1484845 | P49: =P38/P55 -> 7.8249809
...

Sheet Driver
B2: Rmb mn | C2: 43830 | D2: =EOMONTH(C2,12) -> 44196 | E2: =EOMONTH(D2,12) -> 44561 | F2: =EOMONTH(E2,12) -> 44926 | G2: =EOMONTH(F2,12) -> 45291 | H2: =EOMONTH(G2,12) -> 45657 | I2: 45992 | J2: 46357 | K2: =EDATE(J2,12) -> 46722 | M2: 45473 | N2: =EDATE(M2,6) -> 45656 | O2: 45838 | P2: =EDATE(O2,6) -> 46021
B3: Accounting standards: IFRS | C3: 2019 | D3: =C3+1 -> 2020 | E3: =D3+1 -> 2021 | F3: =E3+1 -> 2022 | G3: =F3+1 -> 2023 | H3: =G3+1 -> 2024 | I3: 2025E | J3: 2026E | K3: 2027E | M3: 2024 | N3: 2024 | O3: 2025 | P3: 2025E
B4: Summary
B5: Total GMV (RMBbn) | E5: =E42/1000 -> 22.8 | F5: =F42/1000 -> 30.654187 | G5: =G42/1000 -> 47.848012 | H5: =H42/1000 -> 58.268246 | I5: =I42/1000 -> 78.146545 | J5: =J42/1000 -> 88.899978 | K5: =K42/1000 -> 103.57748
B6: ML China | F6: =F43/1000 -> 29.9 | G6: =G43/1000 -> 44.67 | H6: =H43/1000 -> 55.157208 | I6: =I43/1000 -> 74.867849 | J6: =J43/1000 -> 85.336029 | K6: =K43/1000 -> 99.167588
B7: Mixue | G7: =G44/1000 -> 42.74 | H7: =H44/1000 -> 52.50616 | I7: =I44/1000 -> 68.583306 | J7: =J44/1000 -> 75.50376 | K7: =K44/1000 -> 86.25536
B8: Lucky Cup | G8: =G45/1000 -> 1.93 | H8: =H45/1000 -> 2.651048 | I8: =I45/1000 -> 6.2845432 | J8: =J45/1000 -> 9.8322692 | K8: =K45/1000 -> 12.912228
B9: Overseas | F9: =F46/1000 -> 0.7541872 | G9: =G46/1000 -> 3.178012 | H9: =H46/1000 -> 3.1110382 | I9: =I46/1000 -> 3.2786957 | J9: =J46/1000 -> 3.5639492 | K9: =K46/1000 -> 4.4098947
G10: =G14/G11 -> 0.077199521
B11: Total store count (k) | E11: =E54/1000 -> 20.001 | F11: =F54/1000 -> 28.983 | G11: =G54/1000 -> 37.565 | H11: =H54/1000 -> 46.479 | I11: =I54/1000 -> 56.129 | J11: =J54/1000 -> 65.129 | K11: =K54/1000 -> 74.129
B12: ML China | E12: =E55/1000 -> 19.731 | F12: =F55/1000 -> 27.188 | G12: =G55/1000 -> 33.234 | H12: =H55/1000 -> 41.584 | I12: =I55/1000 -> 51.584 | J12: =J55/1000 -> 60.084 | K12: =K55/1000 -> 68.084
B13: Mixue | G13: =G56/1000 -> 30.334 | H13: =H56/1000 -> 37.684 | I13: =I56/1000 -> 43.084 | J13: =J56/1000 -> 48.584 | K13: =K56/1000 -> 54.084
B14: Lucky Cup | G14: =G57/1000 -> 2.9 | H14: =H57/1000 -> 3.9 | I14: =I57/1000 -> 8.5 | J14: =J57/1000 -> 11.5 | K14: =K57/1000 -> 14
B15: Overseas | E15: =E58/1000 -> 0.27 | F15: =F58/1000 -> 1.795 | G15: =G58/1000 -> 4.331 | H15: =H58/1000 -> 4.895 | I15: =I58/1000 -> 4.545 | J15: =J58/1000 -> 5.045 | K15: =K58/1000 -> 6.045
B17: Net store increase (k) | F17: =F11-E11 -> 8.982 | G17: =G11-F11 -> 8.582 | H17: =H11-G11 -> 8.914 | I17: =I11-H11 -> 9.65 | J17: =J11-I11 -> 9 | K17: =K11-J11 -> 9
B18: ML China | F18: =F12-E12 -> 7.457 | G18: =G12-F12 -> 6.046 | H18: =H12-G12 -> 8.35 | I18: =I12-H12 -> 10 | J18: =J12-I12 -> 8.5 | K18: =K12-J12 -> 8
B19: Mixue | H19: =H13-G13 -> 7.35 | I19: =I13-H13 -> 5.4 | J19: =J13-I13 -> 5.5 | K19: =K13-J13 -> 5.5
B20: Lucky Cup | H20: =H14-G14 -> 1 | I20: =I14-H14 -> 4.6 | J20: =J14-I14 -> 3 | K20: =K14-J14 -> 2.5
B21: Overseas | F21: =F15-E15 -> 1.525 | G21: =G15-F15 -> 2.536 | H21: =H15-G15 -> 0.564 | I21: =I15-H15 -> -0.35 | J21: =J15-I15 -> 0.5 | K21: =K15-J15 -> 1
B23: Average GMV per store (RMBk) | E23: =E307*1000 -> 1401.8 | F23: =F307*1000 -> 1251.6 | G23: =G307*1000 -> 1438 | H23: =H307*1000 -> 1386.6129 | I23: =I307*1000 -> 1523.2057 | J23: =J307*1000 -> 1466.2946 | K23: =K307*1000 -> 1487.5624
B24: ML China | F24: =F6*1000/AVERAGE(E55:F55)*1000 -> 1274.537 | G24: =G6*1000/AVERAGE(F55:G55)*1000 -> 1478.6005 | H24: =H6*1000/AVERAGE(G55:H55)*1000 -> 1474.4369 | I24: =I6*1000/AVERAGE(H55:I55)*1000 -> 1607.158 | J24: =J6*1000/AVERAGE(I55:J55)*1000 -> 1528.3882 | K24: =K6*1000/AVERAGE(J55:K55)*1000 -> 1547.4625
B25: Mixue | G25: =G331*1000 -> 1542.3478 | H25: =H331*1000 -> 1543.8902 | I25: =I331*1000 -> 1698.2792 | J25: =J331*1000 -> 1647.3308 | K25: =K331*1000 -> 1680.2774
B26: Lucky Cup | G26: =G332*1000 -> 772 | H26: =H332*1000 -> 779.72 | I26: =I332*1000 -> 1013.636 | J26: =J332*1000 -> 983.22692 | K26: =K332*1000 -> 1012.7237
B27: Overseas | F27: =F9*1000/AVERAGE(E58:F58)*1000 -> 730.44765 | G27: =G9*1000/AVERAGE(F58:G58)*1000 -> 1037.5488 | H27: =H9*1000/AVERAGE(G58:H58)*1000 -> 674.40673 | I27: =I9*1000/AVERAGE(H58:I58)*1000 -> 694.63893 | J27: =J9*1000/AVERAGE(I58:J58)*1000 -> 743.26365 | K27: =K9*1000/AVERAGE(J58:K58)*1000 -> 795.29211
B29: Total number of cups sold (bn) | E29: =E362/1000 -> 3.6 | F29: =F362/1000 -> 4.7 | G29: =G362/1000 -> 7.4 | H29: =H362/1000 -> 9.045284 | I29: =I362/1000 -> 12.039723 | J29: =J362/1000 -> 13.601441 | K29: =K362/1000 -> 15.789998
B30: ASP (RMB) | E30: =E351 -> 6.3333333 | F30: =F351 -> 6.5221675 | G30: =G351 -> 6.4659476 | H30: =H351 -> 6.4418372 | I30: =I351 -> 6.4907262 | J30: =J351 -> 6.5360707 | K30: =K351 -> 6.5596896
B31: Number of cups sold per day per store | E31: =E48*1000/E30/365*1000 -> 606.40231 | F31: =F48*1000/F30/365*1000 -> 525.75177 | G31: =G48*1000/G30/365*1000 -> 609.30374 | H31: =H48*1000/H30/365*1000 -> 589.72919 | I31: =I48*1000/I30/365*1000 -> 642.94289 | J31: =J48*1000/J30/365*1000 -> 614.62701 | K31: =K48*1000/K30/365*1000 -> 621.29669
B33: Total reported revenue (RMBmn) | E33: =E384 -> 10350.986 | F33: =F384 -> 13575.577 | G33: =G384 -> 20302.465 | H33: =H384 -> 24828.874 | I33: =I384 -> 32331.616 | J33: =J384 -> 37879.877 | K33: =K384 -> 43890.622
B34: By market
A35: ="Rev"&B35 -> RevML China | B35: ML China | E35: =E395 -> 10300.917 | F35: =F395 -> 13034.937 | G35: =G395 -> 18815.533 | H35: =H395 -> 23488.694 | I35: =I395 -> 30953.193 | J35: =J395 -> 36254.607 | K35: =K395 -> 41867.392
A36: ="Rev"&B36 -> RevOverseas | B36: Overseas | E36: =E401 -> 50.069 | F36: =F401 -> 540.64 | G36: =G401 -> 1486.932 | H36: =H401 -> 1340.1797 | I36: =I401 -> 1378.4231 | J36: =J401 -> 1625.2699 | K36: =K401 -> 2023.2302
B37: By revenues stream
B38: Goods | E38: =E387 -> 9457.66 | F38: =F387 -> 12551.043 | G38: =G387 -> 19160.21 | H38: =H387 -> 23452.457 | I38: =I387 -> 30545.045 | J38: =J387 -> 36043.381 | K38: =K387 -> 41932.047
B39: Equipments | E39: =E391 -> 696.944 | F39: =F391 -> 748.387 | G39: =G391 -> 736.537 | H39: =H391 -> 756.372 | I39: =I391 -> 1017.6628 | J39: =J391 -> 914.4794 | K39: =K391 -> 885.73548
B40: Franchise and related services | E40: =E392 -> 196.382 | F40: =F392 -> 276.147 | G40: =G392 -> 405.718 | H40: =H392 -> 620.045 | I40: =I392 -> 768.9089 | J40: =J392 -> 922.01627 | K40: =K392 -> 1072.8399
B42: Total GMV | E42: =E350 -> 22800 | F42: =F350 -> 30654.187 | G42: =G350 -> 47848.012 | H42: =H350 -> 58268.246 | I42: =I350 -> 78146.545 | J42: =J350 -> 88899.978 | K42: =K350 -> 103577.48
B43: ML China | E43: =E136 -> 22700 | F43: =F136 -> 29900 | G43: =G136 -> 44670 | H43: =H136 -> 55157.208 | I43: =I136 -> 74867.849 | J43: =J136 -> 85336.029 | K43: =K136 -> 99167.588
B44: Mixue | F44: =F137 -> 29150 | G44: =G137 -> 42740 | H44: =H137 -> 52506.16 | I44: =I137 -> 68583.306 | J44: =J137 -> 75503.76 | K44: =K137 -> 86255.36
B45: Lucky Cup | F45: =F138 -> 750 | G45: =G138 -> 1930 | H45: =H138 -> 2651.048 | I45: =I138 -> 6284.5432 | J45: =J138 -> 9832.2692 | K45: =K138 -> 12912.228
B46: Overseas | E46: =E139 -> 100 | F46: =F139 -> 754.1872 | G46: =G139 -> 3178.012 | H46: =H139 -> 3111.0382 | I46: =I139 -> 3278.6957 | J46: =J139 -> 3563.9492 | K46: =K139 -> 4409.8947
...

Sheet BS
A1: Rmb mn | D1: 44561 | E1: 44926 | F1: 45291 | G1: 45657 | H1: 46022 | I1: 46387 | J1: 46752 | L1: =IS!O4 -> 45838
A2: Accounting standards: IFRS | D2: 2021 | E2: 2022 | F2: 2023 | G2: 2024 | H2: 2025E | I2: 2026E | J2: 2027E | L2: 1H25
A3: Balance Sheet
A4: Assets
A5: Inventories | D5: 1251.915 | E5: 1541.156 | F5: 2231.714 | G5: 2215.352 | H5: =H70 -> 3670.6223 | I5: =I70 -> 3243.4988 | J5: =J70 -> 4762.4104 | L5: 2991.706
A6: Trade receivables | D6: 2.03 | E6: 15.41 | F6: 28.473 | G6: 25.624 | H6: =H82 -> 29.101908 | I6: =I82 -> 35.18338 | J6: =J82 -> 39.253004 | L6: 34.75
A7: Prepayments, other receivables and other assets | D7: 181.892 | E7: 304.539 | F7: 404.428 | G7: 512.505 | H7: =H86 -> 673.09064 | I7: =I86 -> 786.55438 | J7: =J86 -> 907.08404 | L7: 485.2
A8: Financial assets at fair value through profit or loss | D8: 900.237 | E8: 1865.676 | F8: 746.046 | G8: 3491.643 | H8: =G8 -> 3491.643 | I8: =H8 -> 3491.643 | J8: =I8 -> 3491.643 | L8: 5113.517
A9: Restricted cash and time deposits | D9: 61.865 | E9: 65.146 | F9: 115.62 | G9: 1315.804 | H9: =G9 -> 1315.804 | I9: =H9 -> 1315.804 | J9: =I9 -> 1315.804 | L9: 1350.469
A10: Cash and cash equivalents | D10: 2675.827 | E10: 2764.138 | F10: 5621.904 | G10: 4335.123 | H10: =CF!H69 -> 10782.547 | I10: =CF!I69 -> 16541.122 | J10: =CF!J69 -> 22068.983 | L10: 8405.472
A12: Total current assets | D12: =SUM(D5:D10) -> 5073.766 | E12: =SUM(E5:E10) -> 6556.065 | F12: =SUM(F5:F10) -> 9148.185 | G12: =SUM(G5:G10) -> 11896.051 | H12: =SUM(H5:H10) -> 19962.809 | I12: =SUM(I5:I10) -> 25413.805 | J12: =SUM(J5:J10) -> 32585.177 | L12: =SUM(L5:L10) -> 18381.114
D13: =D10+D21+D9 -> 2737.692 | E13: =E10+E21+E9 -> 2829.284 | F13: =F10+F21+F9 -> 6037.524 | G13: =G10+G21+G9 -> 7617.853
A14: Property, plant and equipment | D14: 1033.497 | E14: 1701.086 | F14: 3390.053 | G14: 5317.826 | H14: =H126 -> 7434.5976 | I14: =I126 -> 9398.5602 | J14: =J126 -> 11307.926 | L14: 5382.169
A15: Investment properties | H15: =L15 -> 17.529 | I15: =H15 -> 17.529 | J15: =I15 -> 17.529 | L15: 17.529
A16: Right-of-use assets | D16: 166.031 | E16: 445.56 | F16: 426.986 | G16: 382.189 | H16: =H164 -> 340.38708 | I16: =I164 -> 285.15739 | J16: =J164 -> 225.13402 | L16: 393.8
A17: Other intangible assets | D17: 9.029 | E17: 20.591 | F17: 25.624 | G17: 41.964 | H17: =H174 -> 53.674 | I17: =I174 -> 65.384 | J17: =J174 -> 77.094 | L17: 41.773
A18: Investment in an associate | D18: 0 | E18: 2.82 | F18: 3.016 | G18: 0 | H18: =L18 -> 103.846 | I18: =H18 -> 103.846 | J18: =I18 -> 103.846 | L18: 103.846
A19: Equity investment designated at fair value through other comprehensive income | D19: 11.4 | E19: 11.4 | F19: 10.46 | G19: 6.59 | H19: =G19 -> 6.59 | I19: =H19 -> 6.59 | J19: =I19 -> 6.59 | L19: 6.59
A20: Deferred tax assets | D20: 23.613 | E20: 41.598 | F20: 111.889 | G20: 76.005 | H20: =G20 -> 76.005 | I20: =H20 -> 76.005 | J20: =I20 -> 76.005 | L20: 106.716
A21: Restricted cash and time deposits | D21: 0 | E21: 0 | F21: 300 | G21: 1966.926 | H21: =G21 -> 1966.926 | I21: =H21 -> 1966.926 | J21: =I21 -> 1966.926 | L21: 2742.349
A22: Other non-current assets | D22: 999.047 | E22: 1166.236 | F22: 1177.353 | G22: =G24-SUM(G14:G21) -> 95.771 | H22: =G22 -> 95.771 | I22: =H22 -> 95.771 | J22: =I22 -> 95.771 | L22: =L24-SUM(L14:L21) -> 117.018
A24: Total non-current assets | D24: =SUM(D14:D22) -> 2242.617 | E24: =SUM(E14:E22) -> 3389.291 | F24: =SUM(F14:F22) -> 5445.381 | G24: 7887.271 | H24: =SUM(H14:H22) -> 10095.326 | I24: =SUM(I14:I22) -> 12015.769 | J24: =SUM(J14:J22) -> 13876.821 | L24: 8911.79
A26: Total assets | D26: =D12+D24 -> 7316.383 | E26: =E12+E24 -> 9945.356 | F26: =F12+F24 -> 14593.566 | G26: =G12+G24 -> 19783.322 | H26: =H12+H24 -> 30058.134 | I26: =I12+I24 -> 37429.574 | J26: =J12+J24 -> 46461.998 | L26: =L12+L24 -> 27292.904
A28: Liabilities
A29: Trade payables | D29: 596.681 | E29: 881.806 | F29: 1316.78 | G29: 1767.263 | H29: =H95 -> 2314.6638 | I29: =I95 -> 2480.2835 | J29: =J95 -> 3071.8195 | L29: 2507.498
A30: Other payables and accruals | D30: 600.753 | E30: 910.196 | F30: 1571.615 | G30: 2043.625 | H30: =H100 -> 2683.9638 | I30: =I100 -> 3136.4029 | J30: =J100 -> 3617.0176 | L30: 2077.385
A31: Contract liabilities | D31: 305.817 | E31: 198.305 | F31: 259.271 | G31: 359.636 | H31: =H108 -> 250.65548 | I31: =I108 -> 297.8311 | J31: =J108 -> 345.97955 | L31: 535.386
A32: Interest-bearing bank borrowings | D32: 30.03 | E32: 140.088 | F32: 259.748 | G32: 0 | H32: =G32 -> 0 | I32: =H32 -> 0 | J32: =I32 -> 0 | L32: 0
A33: Lease liabilities | D33: 50.321 | E33: 78.813 | F33: 72.065 | G33: 52.004 | H33: =G33 -> 52.004 | I33: =H33 -> 52.004 | J33: =I33 -> 52.004 | L33: 63.719
A34: Tax payables | D34: 122.576 | E34: 129.445 | F34: 254.834 | G34: 294.31 | H34: =G34*IS!I29/IS!H29 -> 376.82039 | I34: =H34*IS!J29/IS!I29 -> 446.59018 | J34: =I34*IS!K29/IS!J29 -> 526.99178 | L34: 506.549
A36: Total current liabilities | D36: =SUM(D29:D34) -> 1706.178 | E36: =SUM(E29:E34) -> 2338.653 | F36: =SUM(F29:F34) -> 3734.313 | G36: =SUM(G29:G34) -> 4516.838 | H36: =SUM(H29:H34) -> 5678.1075 | I36: =SUM(I29:I34) -> 6413.1117 | J36: =SUM(J29:J34) -> 7613.8125 | L36: =SUM(L29:L34) -> 5690.537
A38: Deferred income | D38: 2.001 | E38: 58.024 | F38: 122.407 | G38: 134.09 | H38: =G38*IS!I7/IS!H7 -> 174.60906 | I38: =H38*IS!J7/IS!I7 -> 204.57282 | J38: =I38*IS!K7/IS!J7 -> 237.03425 | L38: 141.773
A39: Lease liabilities | D39: 62.408 | E39: 62.736 | F39: 54.36 | G39: 40.548 | H39: =G39 -> 40.548 | I39: =H39 -> 40.548 | J39: =I39 -> 40.548 | L39: 47.388
A40: Deferred tax liabilities | D40: 2.559 | E40: 0.081 | F40: 1.638 | G40: 20.712 | H40: =G40 -> 20.712 | I40: =H40 -> 20.712 | J40: =I40 -> 20.712 | L40: 19.945
A41: Other payables and accruals | D41: 0 | E41: 0 | F41: 60.408 | G41: 2.492 | H41: =G41 -> 2.492 | I41: =H41 -> 2.492 | J41: =I41 -> 2.492 | L41: 3.446
A42: Other liabilities | H42: =L42 -> 5 | I42: =H42 -> 5 | J42: =I42 -> 5 | L42: 5
A43: Contract liabilities | D43: 0.527 | E43: 6.595 | F43: 24.975 | G43: 7.822 | H43: =H115 -> 9.6999499 | I43: =I115 -> 11.631432 | J43: =J115 -> 13.534104 | L43: 3.351
A45: Total non-current liabilities | D45: =SUM(D38:D43) -> 67.495 | E45: =SUM(E38:E43) -> 127.436 | F45: =SUM(F38:F43) -> 263.788 | G45: =SUM(G38:G43) -> 205.664 | H45: =SUM(H38:H43) -> 253.06101 | I45: =SUM(I38:I43) -> 284.95625 | J45: =SUM(J38:J43) -> 319.32035 | L45: =SUM(L38:L43) -> 220.903
A47: Total Liabilities | D47: =D36+D45 -> 1773.673 | E47: =E36+E45 -> 2466.089 | F47: =F36+F45 -> 3998.101 | G47: =G36+G45 -> 4722.502 | H47: =H36+H45 -> 5931.1685 | I47: =I36+I45 -> 6698.0679 | J47: =J36+J45 -> 7933.1328 | L47: =L36+L45 -> 5911.44
A49: Equity
...

Sheet CF
A1: Rmb mn | D1: 44561 | E1: 44926 | F1: 45291 | G1: 45657 | H1: 46022 | I1: 46387 | J1: 46387
A2: Accounting standards: IFRS | D2: 2021 | E2: 2022 | F2: 2023 | G2: 2024 | H2: 2025E | I2: 2026E | J2: 2027E
A3: Cash flow statement
A4: Cash flows from operating activities
A5: Profit before tax | D5: =IS!E29 -> 2558.874 | E5: =IS!F29 -> 2658.043 | F5: =IS!G29 -> 4154.002 | G5: =IS!H29 -> 5810.583 | H5: =IS!I29 -> 7439.5915 | I5: =IS!J29 -> 8817.0613 | J5: =IS!K29 -> 10404.436
A6: Finance costs | D6: 5.973 | E6: 9.19 | F6: 14.697 | G6: 6.367 | H6: =-IS!I24 -> 3.0212545 | I6: =-IS!J24 -> 3.0212545 | J6: =-IS!K24 -> 3.0212545
A7: Share of losses/(profits) of an associate | D7: 0 | E7: 0.18 | F7: -0.196 | G7: 3.016 | H7: =-IS!I27 -> 0 | I7: =-IS!J27 -> 0 | J7: =-IS!K27 -> 0
A8: Gain on disposal of a subsidiary | D8: 0 | E8: 0 | F8: -1.272 | G8: 0
A9: Interest income | D9: -38.221 | E9: -44.322 | F9: -53.801 | G9: -107.015 | H9: =-IS!I149 -> -153.59067 | I9: =-IS!J149 -> -196.91388 | J9: =-IS!K149 -> -277.53392
A10: Loss/(gain) on disposal of items of property, plant and equipment | D10: 1.156 | E10: 0.303 | F10: -0.198 | G10: 5.836 | H10: =-IS!I151 -> 0 | I10: =-IS!J151 -> 0 | J10: =-IS!K151 -> 0
A11: (Gain)/loss on early termination of leases | D11: -1.248 | E11: 3.851 | F11: -0.168 | G11: -3.424
A12: Investment income on financial assets at fair value through profit or loss | D12: -25.999 | E12: -25.644 | F12: -53.333 | G12: -45.17 | H12: =-IS!I150 -> -104.74929 | I12: =-IS!J150 -> -104.74929 | J12: =-IS!K150 -> -104.74929
A13: Depreciation of property, plant and equipment | D13: 57.239 | E13: 105.31 | F13: 160.504 | G13: 314.887 | H13: =-BS!H123 -> 208.56942 | I13: =-BS!I123 -> 361.37836 | J13: =-BS!J123 -> 415.97526
A14: Depreciation of right-of-use assets | D14: 42.363 | E14: 75.782 | F14: 103.472 | G14: 99.178 | H14: =-BS!H162 -> 129.14742 | I14: =-BS!I162 -> 151.30974 | J14: =-BS!J162 -> 175.31943
A15: Amortisation of other intangible assets | D15: 1.197 | E15: 2.672 | F15: 3.8 | G15: 5.29 | H15: =-BS!H172 -> 5.29 | I15: =-BS!I172 -> 5.29 | J15: =-BS!J172 -> 5.29
A16: Impairment of inventories | D16: 2.297 | E16: 2.076 | F16: 32.189 | G16: 36.995
A17: Impairment losses/(reversal of impairment losses) on financial assets | D17: 1.787 | E17: 4.098 | F17: -1.638 | G17: 0.329
A18: Impairment of property, plant and equipment | D18: 14.827 | E18: 0 | F18: 65.524 | G18: 0
A19: Equity-settled share-based payment expenses | D19: 22.554 | E19: 24.981 | F19: 16.427 | G19: 15.786
A20: Foreign exchange differences (net) | D20: 0.994 | E20: 0.163 | F20: -31.963 | G20: -5.62
A21: Others | H21: =BS!H33-BS!G33+BS!H39-BS!G39+BS!H42-BS!G42 -> 5 | I21: =BS!I33-BS!H33+BS!I39-BS!H39+BS!I42-BS!H42 -> 0 | J21: =BS!J33-BS!I33+BS!J39-BS!I39+BS!J42-BS!I42 -> 0
A22: Change in working capitals | D22: =SUM(D23:D31) -> -399.544 | E22: =SUM(E23:E31) -> 228.172 | F22: =SUM(F23:F31) -> 242.767 | G22: =SUM(G23:G31) -> 1076.74 | H22: =SUM(H23:H31) -> -310.9181 | I22: =SUM(I23:I31) -> 1179.227 | J22: =SUM(J23:J31) -> -303.69669
A23: Increase in inventories | D23: -842.719 | E23: -291.317 | F23: -725.819 | G23: -20.633 | H23: =BS!G5-BS!H5 -> -1455.2703 | I23: =BS!H5-BS!I5 -> 427.1235 | J23: =BS!I5-BS!J5 -> -1518.9116
A24: Decrease/(increase) in trade receivables | D24: 0.294 | E24: -14.114 | F24: -8.955 | G24: 5.064 | H24: =BS!G6-BS!H6-H12 -> 101.27138 | I24: =BS!H6-BS!I6-I12 -> 98.667817 | J24: =BS!I6-BS!J6-J12 -> 100.67967
A25: Increase in prepayments, other receivables and other assets | D25: -88.419 | E25: -62.411 | F25: 50.804 | G25: 2.314 | H25: =BS!G7-BS!H7+BS!G20-BS!H20 -> -160.58564 | I25: =BS!H7-BS!I7+BS!H20-BS!I20 -> -113.46373 | J25: =BS!I7-BS!J7+BS!I20-BS!J20 -> -120.52966
A26: (Increase)/decrease in restricted cash | D26: -57.825 | E26: 59.969 | F26: -14.633 | G26: 16.414
A27: Increase in other non-current assets | D27: 0 | E27: 0 | F27: -11.986 | G27: 3.257 | H27: =BS!G22-BS!H22 -> 0 | I27: =BS!H22-BS!I22 -> 0 | J27: =BS!I22-BS!J22 -> 0
A28: Increase in trade payables | D28: 261.205 | E28: 286.16 | F28: 466.094 | G28: 452.782 | H28: =BS!H29-BS!G29 -> 547.4008 | I28: =BS!I29-BS!H29 -> 165.61965 | J28: =BS!J29-BS!I29 -> 591.53606
A29: Increase in other payables and accruals | D29: 194.118 | E29: 295.306 | F29: 343.32 | G29: 522.647 | H29: =BS!H30-BS!G30+BS!H34-BS!G34+BS!H40-BS!G40+BS!H41-BS!G41 -> 722.84919 | I29: =BS!I30-BS!H30+BS!I34-BS!H34+BS!I40-BS!H40+BS!I41-BS!H41 -> 522.20894 | J29: =BS!J30-BS!I30+BS!J34-BS!I34+BS!J40-BS!I40+BS!J41-BS!I41 -> 561.01629
A30: Increase/(decrease) in contract liabilities | D30: 131.801 | E30: -101.444 | F30: 79.559 | G30: 83.212 | H30: =BS!H43-BS!G43+BS!H31-BS!G31 -> -107.10257 | I30: =BS!I43-BS!H43+BS!I31-BS!H31 -> 49.107109 | J30: =BS!J43-BS!I43+BS!J31-BS!I31 -> 50.051115
A31: Increase in deferred income | D31: 2.001 | E31: 56.023 | F31: 64.383 | G31: 11.683 | H31: =BS!H38-BS!G38 -> 40.519064 | I31: =BS!I38-BS!H38 -> 29.963752 | J31: =BS!J38-BS!I38 -> 32.461434
A32: Cash generated from operations | D32: =SUM(D5:D22) -> 2244.249 | E32: =SUM(E5:E22) -> 3044.855 | F32: =SUM(F5:F22) -> 4650.813 | G32: =SUM(G5:G22) -> 7213.778 | H32: =SUM(H5:H22) -> 7221.3615 | I32: =SUM(I5:I22) -> 10215.625 | J32: =SUM(J5:J22) -> 10318.062
A34: Income tax paid | D34: -590.081 | E34: -658.546 | F34: -910.742 | G34: -1280.166 | H34: =IS!I30 -> -1736.6438 | I34: =IS!J30 -> -2058.1903 | J34: =IS!K30 -> -2428.7354
A35: Interest received | D35: 38.221 | E35: 44.322 | F35: 53.801 | G35: 75.096 | H35: =-H9-H7 -> 153.59067 | I35: =-I9-I7 -> 196.91388 | J35: =-J9-J7 -> 277.53392
A36: Net cash flows generated from operating activities | D36: =D32+D34+D35 -> 1692.389 | E36: =E32+E34+E35 -> 2430.631 | F36: =F32+F34+F35 -> 3793.872 | G36: =G32+G34+G35 -> 6008.708 | H36: =H32+H34+H35 -> 5638.3084 | I36: =I32+I34+I35 -> 8354.3481 | J36: =J32+J34+J35 -> 8166.8603
E37: =E43+E44+E45 -> -939.795 | F37: =F43+F44+F45 -> 862.907 | G37: =G43+G44+G45 -> -5640.427
A38: Cash flows from investing activities
A39: Purchases of items of property, plant and equipment | D39: -944.523 | E39: -997.293 | F39: -1685.292 | G39: -1438.614 | H39: =-BS!H122-BS!H125-H10-BS!H15+BS!G15 -> -2342.87 | I39: =-BS!I122-BS!I125-I10-BS!I15+BS!H15 -> -2325.341 | J39: =-BS!J122-BS!J125-J10-BS!J15+BS!I15 -> -2325.341
A40: Proceeds from disposal of items of property, plant and equipment | D40: 5.073 | E40: 0.893 | F40: 4.753 | G40: 58.195 | H40: =-BS!H124 -> 0 | I40: =-BS!I124 -> 0 | J40: =-BS!J124 -> 0
A41: Purchases of other intangible assets | D41: -7.177 | E41: -8.723 | F41: -5.433 | G41: -9.858 | H41: =-BS!H171 -> -17 | I41: =-BS!I171 -> -17 | J41: =-BS!J171 -> -17
...
