Workbook
Name A_ALL_GYG.AX: #REF!
Name E_ALL_GYG.AX: #REF!
Name L_ALL_GYG.AX: #REF!
Name V_ALL_GYG.AX: #REF!

Sheet GYG model ->
D2: Guzman y Gomez (GYG.ASX)
D3: Australia Small & Mid Cap
B8: Goldman SMID Analysts
B10: Elijah Mayr
B11: elijah.mayr@gs.com
B12: +61 2 9321 8995
B14: Elise Bailey
B15: elise.bailey@gs.com
B16: +61 3 9679 1344

Sheet Summary
B1: =+'GYG model ->'!D2 -> Guzman y Gomez (GYG.ASX)
B2: Summary
B8: Profit & Loss | U8: Valuation data
B9: A$m June y/e | D9: =+'Income & Cash Flow'!L$4 -> FY22A | G9: =+'Income & Cash Flow'!O$4 -> FY23A | J9: =+'Income & Cash Flow'!R$4 -> FY24A | M9: =+'Income & Cash Flow'!U$4 -> FY25A | P9: =+'Income & Cash Flow'!X$4 -> FY26E | S9: =+'Income & Cash Flow'!AA$4 -> FY27E | U9: A$m June y/e | W9: =+'Income & Cash Flow'!L$4 -> FY22A | Z9: =+'Income & Cash Flow'!O$4 -> FY23A | AC9: =+'Income & Cash Flow'!R$4 -> FY24A | AF9: =+'Income & Cash Flow'!U$4 -> FY25A | AI9: =+'Income & Cash Flow'!X$4 -> FY26E | AL9: =+'Income & Cash Flow'!AA$4 -> FY27E
B10: Revenue | C10: A$m | D10: ='Income & Cash Flow'!L8 -> 171.792 | E10: ='Income & Cash Flow'!M8 -> 121.185 | F10: ='Income & Cash Flow'!N8 -> 137.859 | G10: ='Income & Cash Flow'!O8 -> 259.044 | H10: ='Income & Cash Flow'!P8 -> 167.517 | I10: ='Income & Cash Flow'!Q8 -> 174.697 | J10: ='Income & Cash Flow'!R8 -> 342.214 | K10: ='Income & Cash Flow'!S8 -> 212.419 | ... S10: ='Income & Cash Flow'!AA8 -> 641.83544 | U10: Diluted no. of shares | V10: m | W10: =+'Income & Cash Flow'!L49 -> 0 | X10: =+'Income & Cash Flow'!M49 -> 0 | Y10: =+'Income & Cash Flow'!N49 -> 0 | Z10: =+'Income & Cash Flow'!O49 -> 83.992295 | AA10: =+'Income & Cash Flow'!P49 -> 0 | AB10: =+'Income & Cash Flow'!Q49 -> 85.568408 | AC10: =+'Income & Cash Flow'!R49 -> 85.568408 | AD10: =+'Income & Cash Flow'!S49 -> 106.13463 | ... AL10: =+'Income & Cash Flow'!AA49 -> 102.86055
B11: CoGS | C11: A$m | D11: ='Income & Cash Flow'!L11 -> -44.194 | E11: ='Income & Cash Flow'!M11 -> -32.906 | F11: ='Income & Cash Flow'!N11 -> -37.522 | G11: ='Income & Cash Flow'!O11 -> -70.428 | H11: ='Income & Cash Flow'!P11 -> -43.237 | I11: ='Income & Cash Flow'!Q11 -> -44.343 | J11: ='Income & Cash Flow'!R11 -> -87.58 | K11: ='Income & Cash Flow'!S11 -> -55.071 | ... S11: ='Income & Cash Flow'!AA11 -> -147.96261 | U11: Adj. diluted EPS | V11: cps | W11: =+'Income & Cash Flow'!L51 -> 0 | X11: =+'Income & Cash Flow'!M51 -> 0 | Y11: =+'Income & Cash Flow'!N51 -> 0 | Z11: =+'Income & Cash Flow'!O51 -> 3.5717562 | AA11: =+'Income & Cash Flow'!P51 -> 0 | AB11: =+'Income & Cash Flow'!Q51 -> 2.2204457 | AC11: =+'Income & Cash Flow'!R51 -> 6.661337 | AD11: =+'Income & Cash Flow'!S51 -> 0 | ... AL11: =+'Income & Cash Flow'!AA51 -> 31.059832
B12: Opex | C12: A$m | D12: =+D13-D11-D10 -> -103.692 | E12: =+E13-E11-E10 -> -73.742 | F12: =+F13-F11-F10 -> -85.253 | G12: =+G13-G11-G10 -> -158.995 | H12: =+H13-H11-H10 -> -105.376 | I12: =+I13-I11-I10 -> -121.984 | J12: =+J13-J11-J10 -> -227.36 | K12: =+K13-K11-K10 -> -125.77 | ... S12: =+S13-S11-S10 -> -384.11485 | U12: Adj. EPS growth | V12: % | W12: =+'Income & Cash Flow'!L66 -> 0 | X12: =+'Income & Cash Flow'!M66 -> 0 | Y12: =+'Income & Cash Flow'!N66 -> 0 | Z12: =+'Income & Cash Flow'!O66 -> 0 | AA12: =+'Income & Cash Flow'!P66 -> 0 | AB12: =+'Income & Cash Flow'!Q66 -> 0 | AC12: =+'Income & Cash Flow'!R66 -> 0 | AD12: =+'Income & Cash Flow'!S66 -> 0 | ... AL12: =+'Income & Cash Flow'!AA66 -> 0.53694344
B13: Ebitda | C13: A$m | D13: =+'Income & Cash Flow'!L18 -> 23.906 | E13: =+'Income & Cash Flow'!M18 -> 14.537 | F13: =+'Income & Cash Flow'!N18 -> 15.084 | G13: =+'Income & Cash Flow'!O18 -> 29.621 | H13: =+'Income & Cash Flow'!P18 -> 18.904 | I13: =+'Income & Cash Flow'!Q18 -> 8.37 | J13: =+'Income & Cash Flow'!R18 -> 27.274 | K13: =+'Income & Cash Flow'!S18 -> 31.578 | ... S13: =+'Income & Cash Flow'!AA18 -> 109.75798 | U13: Dividends | V13: cps | W13: =+'Balance Sheet'!L179 -> 0 | X13: =+'Balance Sheet'!M179 -> 0 | Y13: =+'Balance Sheet'!N179 -> 0 | Z13: =+'Balance Sheet'!O179 -> 0 | AA13: =+'Balance Sheet'!P179 -> 0 | AB13: =+'Balance Sheet'!Q179 -> 0 | AC13: =+'Balance Sheet'!R179 -> 0 | AD13: =+'Balance Sheet'!S179 -> 0 | ... AL13: =+'Balance Sheet'!AA179 -> 0
B14: Adjustments | C14: A$m | D14: =+D15-D13 -> -2.206 | E14: =+E15-E13 -> -0.337 | F14: =+F15-F13 -> 0.016 | G14: =+G15-G13 -> -0.321 | H14: =+H15-H13 -> 5.796 | I14: =+I15-I13 -> 11.73 | J14: =+J15-J13 -> 17.526 | K14: =+K15-K13 -> 0 | ... S14: =+S15-S13 -> 0 | U14: Dividend yield | V14: % | W14: =+'Income & Cash Flow'!L154 -> 0 | X14: =+'Income & Cash Flow'!M154 -> 0 | Y14: =+'Income & Cash Flow'!N154 -> 0 | Z14: =+'Income & Cash Flow'!O154 -> 0 | AA14: =+'Income & Cash Flow'!P154 -> 0 | AB14: =+'Income & Cash Flow'!Q154 -> 0 | AC14: =+'Income & Cash Flow'!R154 -> 0 | AD14: =+'Income & Cash Flow'!S154 -> 0 | ... AL14: =+'Income & Cash Flow'!AA154 -> 0
B15: Adj. Ebitda | C15: A$m | D15: =+'Income & Cash Flow'!L20 -> 21.7 | E15: =+'Income & Cash Flow'!M20 -> 14.2 | F15: =+'Income & Cash Flow'!N20 -> 15.1 | G15: =+'Income & Cash Flow'!O20 -> 29.3 | H15: =+'Income & Cash Flow'!P20 -> 24.7 | I15: =+'Income & Cash Flow'!Q20 -> 20.1 | J15: =+'Income & Cash Flow'!R20 -> 44.8 | K15: =+'Income & Cash Flow'!S20 -> 31.578 | ... S15: =+'Income & Cash Flow'!AA20 -> 109.75798
B16: D&A&I | C16: A$m | D16: =SUM('Income & Cash Flow'!L22:L24) -> -14.46 | E16: =SUM('Income & Cash Flow'!M22:M24) -> -12.567 | F16: =SUM('Income & Cash Flow'!N22:N24) -> -12.988 | G16: =SUM('Income & Cash Flow'!O22:O24) -> -25.555 | H16: =SUM('Income & Cash Flow'!P22:P24) -> -15.9 | I16: =SUM('Income & Cash Flow'!Q22:Q24) -> -15.223 | J16: =SUM('Income & Cash Flow'!R22:R24) -> -31.123 | K16: =SUM('Income & Cash Flow'!S22:S24) -> -19.08 | ... S16: =SUM('Income & Cash Flow'!AA22:AA24) -> -57.252137 | U16: PE | V16: x | W16: =+'Income & Cash Flow'!L148 -> 0 | X16: =+'Income & Cash Flow'!M148 -> 0 | Y16: =+'Income & Cash Flow'!N148 -> 0 | Z16: =+'Income & Cash Flow'!O148 -> 0 | AA16: =+'Income & Cash Flow'!P148 -> 0 | AB16: =+'Income & Cash Flow'!Q148 -> 0 | AC16: =+'Income & Cash Flow'!R148 -> 358.03623 | AD16: =+'Income & Cash Flow'!S148 -> 0 | ... AL16: =+'Income & Cash Flow'!AA148 -> 76.78728
B17: EBIT | C17: A$m | D17: =+D16+D13 -> 9.446 | E17: =+E16+E13 -> 1.97 | F17: =+F16+F13 -> 2.096 | G17: =+G16+G13 -> 4.066 | H17: =+H16+H13 -> 3.004 | I17: =+I16+I13 -> -6.853 | J17: =+J16+J13 -> -3.849 | K17: =+K16+K13 -> 12.498 | ... S17: =+S16+S13 -> 52.505847 | U17: P/B | V17: x | W17: =+'Income & Cash Flow'!L150 -> 0 | X17: =+'Income & Cash Flow'!M150 -> 0 | Y17: =+'Income & Cash Flow'!N150 -> 0 | Z17: =+'Income & Cash Flow'!O150 -> 22.772878 | AA17: =+'Income & Cash Flow'!P150 -> 0 | AB17: =+'Income & Cash Flow'!Q150 -> 5.7653322 | AC17: =+'Income & Cash Flow'!R150 -> 5.7653322 | AD17: =+'Income & Cash Flow'!S150 -> 6.8854291 | ... AL17: =+'Income & Cash Flow'!AA150 -> 5.667487
B18: Net interest | C18: A$m | D18: =+'Income & Cash Flow'!L29+'Income & Cash Flow'!L30+'Income & Cash Flow'!L31 -> -2.835 | E18: =+'Income & Cash Flow'!M29+'Income & Cash Flow'!M30+'Income & Cash Flow'!M31 -> -1.622 | F18: =+'Income & Cash Flow'!N29+'Income & Cash Flow'!N30+'Income & Cash Flow'!N31 -> -2.288 | G18: =+'Income & Cash Flow'!O29+'Income & Cash Flow'!O30+'Income & Cash Flow'!O31 -> -3.91 | H18: =+'Income & Cash Flow'!P29+'Income & Cash Flow'!P30+'Income & Cash Flow'!P31 -> -4.083 | I18: =+'Income & Cash Flow'!Q29+'Income & Cash Flow'!Q30+'Income & Cash Flow'!Q31 -> -3.629 | J18: =+'Income & Cash Flow'!R29+'Income & Cash Flow'!R30+'Income & Cash Flow'!R31 -> -7.712 | K18: =+'Income & Cash Flow'!S29+'Income & Cash Flow'!S30+'Income & Cash Flow'!S31 -> 2.693 | ... S18: =+'Income & Cash Flow'!AA29+'Income & Cash Flow'!AA30+'Income & Cash Flow'!AA31 -> -6.8653998 | U18: EV / Ebitda | V18: x | W18: =+'Income & Cash Flow'!L143 -> 95.793605 | X18: =+'Income & Cash Flow'!M143 -> 0 | Y18: =+'Income & Cash Flow'!N143 -> 0 | Z18: =+'Income & Cash Flow'!O143 -> 73.427619 | AA18: =+'Income & Cash Flow'!P143 -> 7.9938462 | AB18: =+'Income & Cash Flow'!Q143 -> 98.79724 | AC18: =+'Income & Cash Flow'!R143 -> 44.32644 | AD18: =+'Income & Cash Flow'!S143 -> 80.149248 | ... AL18: =+'Income & Cash Flow'!AA143 -> 22.843579
B19: Pre-tax profit | C19: A$m | D19: =+D18+D17 -> 6.611 | E19: =+E18+E17 -> 0.348 | F19: =+F18+F17 -> -0.192 | G19: =+G18+G17 -> 0.156 | H19: =+H18+H17 -> -1.079 | I19: =+I18+I17 -> -10.482 | J19: =+J18+J17 -> -11.561 | K19: =+K18+K17 -> 15.191 | ... S19: =+S18+S17 -> 45.640447 | U19: EV / Ebit | V19: x | W19: =+'Income & Cash Flow'!L144 -> 288.71128 | X19: =+'Income & Cash Flow'!M144 -> 0 | Y19: =+'Income & Cash Flow'!N144 -> 0 | Z19: =+'Income & Cash Flow'!O144 -> 581.46736 | AA19: =+'Income & Cash Flow'!P144 -> 22.437273 | AB19: =+'Income & Cash Flow'!Q144 -> 413.71344 | AC19: =+'Income & Cash Flow'!R144 -> 146.01651 | AD19: =+'Income & Cash Flow'!S144 -> 202.50864 | ... AL19: =+'Income & Cash Flow'!AA144 -> 47.752114
B20: Tax | C20: A$m | D20: =+'Income & Cash Flow'!L38 -> -2.7 | E20: =+'Income & Cash Flow'!M38 -> -1.469 | F20: =+'Income & Cash Flow'!N38 -> -0.954 | G20: =+'Income & Cash Flow'!O38 -> -2.423 | H20: =+'Income & Cash Flow'!P38 -> -2.881 | I20: =+'Income & Cash Flow'!Q38 -> 0.694 | J20: =+'Income & Cash Flow'!R38 -> -2.187 | K20: =+'Income & Cash Flow'!S38 -> -7.89 | ... S20: =+'Income & Cash Flow'!AA38 -> -13.692134 | U20: Price / NTA | V20: x | W20: =+'Income & Cash Flow'!L151 -> 0 | X20: =+'Income & Cash Flow'!M151 -> 0 | Y20: =+'Income & Cash Flow'!N151 -> 0 | Z20: =+'Income & Cash Flow'!O151 -> 6.4765078 | AA20: =+'Income & Cash Flow'!P151 -> 0 | AB20: =+'Income & Cash Flow'!Q151 -> 3.1338637 | AC20: =+'Income & Cash Flow'!R151 -> 3.1338637 | AD20: =+'Income & Cash Flow'!S151 -> 3.7455623 | ... AL20: =+'Income & Cash Flow'!AA151 -> 2.8242601
B21: Reported NPAT | C21: A$m | D21: =+D20+D19 -> 3.911 | E21: =+E20+E19 -> -1.121 | F21: =+F20+F19 -> -1.146 | G21: =+G20+G19 -> -2.267 | H21: =+H20+H19 -> -3.96 | I21: =+I20+I19 -> -9.788 | J21: =+J20+J19 -> -13.748 | K21: =+K20+K19 -> 7.301 | ... S21: =+S20+S19 -> 31.948313
B22: Adjustments | C22: A$m | D22: =+D23-D21 -> -0.711 | E22: =+E23-E21 -> 2.021 | F22: =+F23-F21 -> 3.246 | G22: =+G23-G21 -> 5.267 | H22: =+H23-H21 -> 7.76 | I22: =+I23-I21 -> 11.688 | J22: =+J23-J21 -> 19.448 | K22: =+K23-K21 -> 0 | ... S22: =+S23-S21 -> 0 | U22: Net debt (ex-leases) | V22: A$m | W22: =+'Balance Sheet'!L60 -> -51.069 | X22: =+'Balance Sheet'!M60 -> 0 | Y22: =+'Balance Sheet'!N60 -> 0 | Z22: =+'Balance Sheet'!O60 -> -33.504 | AA22: =+'Balance Sheet'!P60 -> -10.619 | AB22: =+'Balance Sheet'!Q60 -> -294.48 | AC22: =+'Balance Sheet'!R60 -> -294.48 | AD22: =+'Balance Sheet'!S60 -> -274.493 | ... AL22: =+'Balance Sheet'!AA60 -> -296.67325
B23: Adj. NPAT | C23: A$m | D23: =+'Income & Cash Flow'!L42 -> 3.2 | E23: =+'Income & Cash Flow'!M42 -> 0.9 | F23: =+'Income & Cash Flow'!N42 -> 2.1 | G23: =+'Income & Cash Flow'!O42 -> 3 | H23: =+'Income & Cash Flow'!P42 -> 3.8 | I23: =+'Income & Cash Flow'!Q42 -> 1.9 | J23: =+'Income & Cash Flow'!R42 -> 5.7 | K23: =+'Income & Cash Flow'!S42 -> 7.301 | ... S23: =+'Income & Cash Flow'!AA42 -> 31.948313 | U23: Net debt / Ebitda | V23: x | W23: =+'Balance Sheet'!L64 -> -2.3534101 | X23: =+'Balance Sheet'!M64 -> 0 | Y23: =+'Balance Sheet'!N64 -> 0 | Z23: =+'Balance Sheet'!O64 -> -1.1434812 | AA23: =+'Balance Sheet'!P64 -> -0.42991903 | AB23: =+'Balance Sheet'!Q64 -> -14.650746 | AC23: =+'Balance Sheet'!R64 -> -6.5732143 | AD23: =+'Balance Sheet'!S64 -> -8.6925391 | ... AL23: =+'Balance Sheet'!AA64 -> -2.7029764
U24: Ebitda / Interest | V24: x | W24: =+'Balance Sheet'!L54 -> 7.654321 | X24: =+'Balance Sheet'!M54 -> 0 | Y24: =+'Balance Sheet'!N54 -> 0 | Z24: =+'Balance Sheet'!O54 -> 7.4936061 | AA24: =+'Balance Sheet'!P54 -> 6.0494734 | AB24: =+'Balance Sheet'!Q54 -> 5.5387159 | AC24: =+'Balance Sheet'!R54 -> 5.8091286 | AD24: =+'Balance Sheet'!S54 -> -11.725956 | ... AL24: =+'Balance Sheet'!AA54 -> 15.987122
B25: Profitability ratios
B26: A$m June y/e | D26: =+'Income & Cash Flow'!L$4 -> FY22A | G26: =+'Income & Cash Flow'!O$4 -> FY23A | J26: =+'Income & Cash Flow'!R$4 -> FY24A | M26: =+'Income & Cash Flow'!U$4 -> FY25A | P26: =+'Income & Cash Flow'!X$4 -> FY26E | S26: =+'Income & Cash Flow'!AA$4 -> FY27E | U26: Segmental analysis
B27: Sales growth | C27: % | G27: =+'Income & Cash Flow'!O56 -> 0.50789327 | H27: =+'Income & Cash Flow'!P56 -> 0.38232455 | I27: =+'Income & Cash Flow'!Q56 -> 0.26721505 | J27: =+'Income & Cash Flow'!R56 -> 0.32106515 | K27: =+'Income & Cash Flow'!S56 -> 0.26804444 | L27: =+'Income & Cash Flow'!T56 -> 0.2797186 | M27: =+'Income & Cash Flow'!U56 -> 0.27400399 | N27: =+'Income & Cash Flow'!V56 -> 0.24864904 | ... S27: =+'Income & Cash Flow'!AA56 -> 0.1911543 | U27: A$m June y/e | W27: =+'Income & Cash Flow'!L$4 -> FY22A | Z27: =+'Income & Cash Flow'!O$4 -> FY23A | AC27: =+'Income & Cash Flow'!R$4 -> FY24A | AF27: =+'Income & Cash Flow'!U$4 -> FY25A | AI27: =+'Income & Cash Flow'!X$4 -> FY26E | AL27: =+'Income & Cash Flow'!AA$4 -> FY27E
B28: Adj. Ebitda growth | C28: % | G28: =+'Income & Cash Flow'!O59 -> 0.35023041 | H28: =+'Income & Cash Flow'!P59 -> 0.73943662 | I28: =+'Income & Cash Flow'!Q59 -> 0.33112583 | J28: =+'Income & Cash Flow'!R59 -> 0.52901024 | K28: =+'Income & Cash Flow'!S59 -> 0.27846154 | L28: =+'Income & Cash Flow'!T59 -> 0.66870647 | M28: =+'Income & Cash Flow'!U59 -> 0.45354911 | N28: =+'Income & Cash Flow'!V59 -> 0.34386748 | ... S28: =+'Income & Cash Flow'!AA59 -> 0.32199265 | U28: Australia network | V28: A$m | W28: =+Segments!L10 -> 535.4 | X28: =+Segments!M10 -> 334.9 | Y28: =+Segments!N10 -> 368 | Z28: =+Segments!O10 -> 702.9 | AA28: =+Segments!P10 -> 438.6 | AB28: =+Segments!Q10 -> 456 | AC28: =+Segments!R10 -> 894.6 | AD28: =+Segments!S10 -> 538.24 | ... AL28: =+Segments!AA10 -> 1501.9638
B29: Adj. NPAT growth | C29: % | G29: =+'Income & Cash Flow'!O63 -> -0.0625 | H29: =+'Income & Cash Flow'!P63 -> 3.2222222 | I29: =+'Income & Cash Flow'!Q63 -> -0.095238095 | J29: =+'Income & Cash Flow'!R63 -> 0.9 | K29: =+'Income & Cash Flow'!S63 -> 0.92131579 | L29: =+'Income & Cash Flow'!T63 -> 2.7763158 | M29: =+'Income & Cash Flow'!U63 -> 1.5396491 | N29: =+'Income & Cash Flow'!V63 -> 0.49350195 | ... S29: =+'Income & Cash Flow'!AA63 -> 0.53694344 | U29: Singapore master | V29: A$m | W29: =+Segments!L11 -> 31.4 | X29: =+Segments!M11 -> 21.5 | Y29: =+Segments!N11 -> 21.6 | Z29: =+Segments!O11 -> 43.1 | AA29: =+Segments!P11 -> 22.2 | AB29: =+Segments!Q11 -> 24.2 | AC29: =+Segments!R11 -> 46.4 | AD29: =+Segments!S11 -> 30.194 | ... AL29: =+Segments!AA11 -> 85.56575
U30: Japan master | V30: A$m | W30: =+Segments!L12 -> 5.8 | X30: =+Segments!M12 -> 3.2 | Y30: =+Segments!N12 -> 3.8 | Z30: =+Segments!O12 -> 7 | AA30: =+Segments!P12 -> 4.2 | AB30: =+Segments!Q12 -> 3.7 | AC30: =+Segments!R12 -> 7.9 | AD30: =+Segments!S12 -> 4.606 | ... AL30: =+Segments!AA12 -> 14.266867
B31: Adj. Ebitda margin | C31: % | D31: =+'Income & Cash Flow'!L80 -> 0.12631554 | E31: =+'Income & Cash Flow'!M80 -> 0.11717622 | F31: =+'Income & Cash Flow'!N80 -> 0.1095322 | G31: =+'Income & Cash Flow'!O80 -> 0.1131082 | H31: =+'Income & Cash Flow'!P80 -> 0.14744772 | I31: =+'Income & Cash Flow'!Q80 -> 0.11505635 | J31: =+'Income & Cash Flow'!R80 -> 0.13091224 | K31: =+'Income & Cash Flow'!S80 -> 0.14865902 | ... S31: =+'Income & Cash Flow'!AA80 -> 0.17100642 | U31: USA corporate | V31: A$m | W31: =+Segments!L13 -> 2.5 | X31: =+Segments!M13 -> 1.5 | Y31: =+Segments!N13 -> 4.5 | Z31: =+Segments!O13 -> 6 | AA31: =+Segments!P13 -> 5.6 | AB31: =+Segments!Q13 -> 5.234 | AC31: =+Segments!R13 -> 10.834 | AD31: =+Segments!S13 -> 4.907 | ... AL31: =+Segments!AA13 -> 19.490138
B32: Adj. NPAT margin | C32: % | D32: =+'Income & Cash Flow'!L81 -> 0.018627177 | E32: =+'Income & Cash Flow'!M81 -> 0.0074266617 | F32: =+'Income & Cash Flow'!N81 -> 0.015232955 | G32: =+'Income & Cash Flow'!O81 -> 0.011581044 | H32: =+'Income & Cash Flow'!P81 -> 0.022684265 | I32: =+'Income & Cash Flow'!Q81 -> 0.010875974 | J32: =+'Income & Cash Flow'!R81 -> 0.016656244 | K32: =+'Income & Cash Flow'!S81 -> 0.034370748 | ... S32: =+'Income & Cash Flow'!AA81 -> 0.049776486 | U32: Network sales | V32: A$m | W32: =SUM(W28:W31) -> 575.1 | X32: =SUM(X28:X31) -> 361.1 | Y32: =SUM(Y28:Y31) -> 397.9 | Z32: =SUM(Z28:Z31) -> 759 | AA32: =SUM(AA28:AA31) -> 470.6 | AB32: =SUM(AB28:AB31) -> 489.134 | AC32: =SUM(AC28:AC31) -> 959.734 | AD32: =SUM(AD28:AD31) -> 577.947 | ... AL32: =SUM(AL28:AL31) -> 1621.2865
U33: Australia corporate | V33: A$m | W33: =+Segments!L16 -> 139.217 | X33: =+Segments!M16 -> 100.639 | Y33: =+Segments!N16 -> 111.336 | Z33: =+Segments!O16 -> 211.975 | AA33: =+Segments!P16 -> 136.574 | AB33: =+Segments!Q16 -> 142.303 | AC33: =+Segments!R16 -> 278.877 | AD33: =+Segments!S16 -> 176.051 | ... AL33: =+Segments!AA16 -> 526.34527
B34: ROE | C34: % | D34: =+'Balance Sheet'!L73 -> 0.043412788 | E34: =+'Balance Sheet'!M73 -> 0 | F34: =+'Balance Sheet'!N73 -> 0 | G34: =+'Balance Sheet'!O73 -> 0.035489519 | H34: =+'Balance Sheet'!P73 -> 0.046928064 | I34: =+'Balance Sheet'!Q73 -> 0.0088792515 | J34: =+'Balance Sheet'!R73 -> 0.025795123 | K34: =+'Balance Sheet'!S73 -> 0.020235251 | ... S34: =+'Balance Sheet'!AA73 -> 0.076635781 | U34: APAC royalty | V34: A$m | W34: =+Segments!L17+Segments!L18+Segments!L19+Segments!L20 -> 29.426 | X34: =+Segments!M17+Segments!M18+Segments!M19+Segments!M20 -> 18.567 | Y34: =+Segments!N17+Segments!N18+Segments!N19+Segments!N20 -> 21.422 | Z34: =+Segments!O17+Segments!O18+Segments!O19+Segments!O20 -> 39.989 | AA34: =+Segments!P17+Segments!P18+Segments!P19+Segments!P20 -> 24.7 | AB34: =+Segments!Q17+Segments!Q18+Segments!Q19+Segments!Q20 -> 27.803 | AC34: =+Segments!R17+Segments!R18+Segments!R19+Segments!R20 -> 52.503 | AD34: =+Segments!S17+Segments!S18+Segments!S19+Segments!S20 -> 33.136 | ... AL34: =+Segments!AA17+Segments!AA18+Segments!AA19+Segments!AA20 -> 98.172727
B35: ROCE | C35: % | D35: =+'Balance Sheet'!L74 -> 0.039340715 | E35: =+'Balance Sheet'!M74 -> 0 | F35: =+'Balance Sheet'!N74 -> 0 | G35: =+'Balance Sheet'!O74 -> 0.016320517 | H35: =+'Balance Sheet'!P74 -> 0.033266045 | I35: =+'Balance Sheet'!Q74 -> 0.01131359 | J35: =+'Balance Sheet'!R74 -> 0.032553369 | K35: =+'Balance Sheet'!S74 -> 0.020713178 | ... S35: =+'Balance Sheet'!AA74 -> 0.070155979 | U35: USA corporate | V35: A$m | W35: =+Segments!L21 -> 2.5 | X35: =+Segments!M21 -> 1.5 | Y35: =+Segments!N21 -> 4.5 | Z35: =+Segments!O21 -> 6 | AA35: =+Segments!P21 -> 5.6 | AB35: =+Segments!Q21 -> 5.234 | AC35: =+Segments!R21 -> 10.834 | AD35: =+Segments!S21 -> 3.232 | ... AL35: =+Segments!AA21 -> 17.317443
B36: Cash conversion | C36: % | D36: =+'Income & Cash Flow'!L136 -> 0.90525346 | E36: =+'Income & Cash Flow'!M136 -> 0.96295775 | F36: =+'Income & Cash Flow'!N136 -> 1.4088079 | G36: =+'Income & Cash Flow'!O136 -> 1.1927304 | H36: =+'Income & Cash Flow'!P136 -> 0.57149798 | I36: =+'Income & Cash Flow'!Q136 -> 1.1268159 | J36: =+'Income & Cash Flow'!R136 -> 0.82064732 | K36: =+'Income & Cash Flow'!S136 -> 0.60782823 | ... S36: =+'Income & Cash Flow'!AA136 -> 1.004422 | U36: Group revenue | V36: A$m | W36: =SUM(W33:W35) -> 171.143 | X36: =SUM(X33:X35) -> 120.706 | Y36: =SUM(Y33:Y35) -> 137.258 | Z36: =SUM(Z33:Z35) -> 257.964 | AA36: =SUM(AA33:AA35) -> 166.874 | AB36: =SUM(AB33:AB35) -> 175.34 | AC36: =SUM(AC33:AC35) -> 342.214 | AD36: =SUM(AD33:AD35) -> 212.419 | ... AL36: =SUM(AL33:AL35) -> 641.83544
B37: FCF Conversion | C37: % | D37: =+'Income & Cash Flow'!L137 -> -0.57990783 | E37: =+'Income & Cash Flow'!M137 -> -0.55415493 | F37: =+'Income & Cash Flow'!N137 -> -0.41596026 | G37: =+'Income & Cash Flow'!O137 -> -0.48293515 | H37: =+'Income & Cash Flow'!P137 -> -0.030769231 | I37: =+'Income & Cash Flow'!Q137 -> 0.041691542 | J37: =+'Income & Cash Flow'!R137 -> 0.0017410714 | K37: =+'Income & Cash Flow'!S137 -> -0.46738235 | ... S37: =+'Income & Cash Flow'!AA137 -> 0.422232 | U37: Adj. Australia segment | V37: A$m | W37: =+Segments!L24 -> 18.3 | X37: =+Segments!M24 -> 13.4 | Y37: =+Segments!N24 -> 17.3 | Z37: =+Segments!O24 -> 30.7 | AA37: =+Segments!P24 -> 23.1 | AB37: =+Segments!Q24 -> 22.5 | AC37: =+Segments!R24 -> 45.6 | AD37: =+Segments!S24 -> 31.781 | ... AL37: =+Segments!AA24 -> 107.14617
U38: Adj. USA segment | V38: A$m | W38: =+Segments!L25 -> -2.9 | X38: =+Segments!M25 -> -1.7 | Y38: =+Segments!N25 -> -2.596 | Z38: =+Segments!O25 -> -4.296 | AA38: =+Segments!P25 -> -3.1 | AB38: =+Segments!Q25 -> -3.444 | AC38: =+Segments!R25 -> -6.544 | AD38: =+Segments!S25 -> -5.014 | ... AL38: =+Segments!AA25 -> -17.938269
B39: Cashflow Statement | U39: Adj. Segment Ebitda | V39: A$m | W39: =SUM(W37:W38) -> 15.4 | X39: =SUM(X37:X38) -> 11.7 | Y39: =SUM(Y37:Y38) -> 14.704 | Z39: =SUM(Z37:Z38) -> 26.404 | AA39: =SUM(AA37:AA38) -> 20 | AB39: =SUM(AB37:AB38) -> 19.056 | AC39: =SUM(AC37:AC38) -> 39.056 | AD39: =SUM(AD37:AD38) -> 26.767 | ... AL39: =SUM(AL37:AL38) -> 89.207897
B40: A$m June y/e | D40: =+'Income & Cash Flow'!L$4 -> FY22A | G40: =+'Income & Cash Flow'!O$4 -> FY23A | J40: =+'Income & Cash Flow'!R$4 -> FY24A | M40: =+'Income & Cash Flow'!U$4 -> FY25A | P40: =+'Income & Cash Flow'!X$4 -> FY26E | S40: =+'Income & Cash Flow'!AA$4 -> FY27E | U40: Share payments | V40: A$m | W40: =+Segments!L28 -> -1.436 | X40: =+Segments!M28 -> -2.8 | Y40: =+Segments!N28 -> -1.44 | Z40: =+Segments!O28 -> -4.24 | AA40: =+Segments!P28 -> -3.6 | AB40: =+Segments!Q28 -> -7.5 | AC40: =+Segments!R28 -> -11.1 | AD40: =+Segments!S28 -> -4.587 | ... AL40: =+Segments!AA28 -> -7
B41: Operating cash flow | C41: A$m | D41: =+'Income & Cash Flow'!L98 -> 19.644 | G41: =+'Income & Cash Flow'!O98 -> 34.947 | J41: =+'Income & Cash Flow'!R98 -> 36.765 | M41: =+'Income & Cash Flow'!U98 -> 57.327 | P41: =+'Income & Cash Flow'!X98 -> 91.663678 | S41: =+'Income & Cash Flow'!AA98 -> 110.24333 | U41: Rent and outgoings | V41: A$m | W41: =+Segments!L29 -> 8 | X41: =+Segments!M29 -> 5.7 | Y41: =+Segments!N29 -> 5.5 | Z41: =+Segments!O29 -> 11.2 | AA41: =+Segments!P29 -> 8.2 | AB41: =+Segments!Q29 -> 8.9 | AC41: =+Segments!R29 -> 17.1 | AD41: =+Segments!S29 -> 9.398 | ... AL41: =+Segments!AA29 -> 27.550087
B42: FCF | C42: A$m | D42: =+'Income & Cash Flow'!L134 -> -12.584 | G42: =+'Income & Cash Flow'!O134 -> -14.15 | J42: =+'Income & Cash Flow'!R134 -> 0.078 | M42: =+'Income & Cash Flow'!U134 -> -19.509 | P42: =+'Income & Cash Flow'!X134 -> 31.663678 | S42: =+'Income & Cash Flow'!AA134 -> 46.343333 | U42: Other | V42: A$m | W42: =+Segments!L30 -> -0.264 | X42: =+Segments!M30 -> -0.4 | Y42: =+Segments!N30 -> -3.664 | Z42: =+Segments!O30 -> -4.064 | AA42: =+Segments!P30 -> 0.1 | AB42: =+Segments!Q30 -> -0.356 | AC42: =+Segments!R30 -> -0.256 | AD42: =+Segments!S30 -> 0 | ... AL42: =+Segments!AA30 -> 0
B43: Investing cash flow | C43: A$m | D43: =+'Income & Cash Flow'!L106 -> -31.698 | G43: =+'Income & Cash Flow'!O106 -> -48.403 | J43: =+'Income & Cash Flow'!R106 -> -311.818 | M43: =+'Income & Cash Flow'!U106 -> -34.551 | P43: =+'Income & Cash Flow'!X106 -> -60 | S43: =+'Income & Cash Flow'!AA106 -> -63.9 | U43: Adj. Group Ebitda | V43: A$m | W43: =SUM(W39:W42) -> 21.7 | X43: =SUM(X39:X42) -> 14.2 | Y43: =SUM(Y39:Y42) -> 15.1 | Z43: =SUM(Z39:Z42) -> 29.3 | AA43: =SUM(AA39:AA42) -> 24.7 | AB43: =SUM(AB39:AB42) -> 20.1 | AC43: =SUM(AC39:AC42) -> 44.8 | AD43: =SUM(AD39:AD42) -> 31.578 | ... AL43: =SUM(AL39:AL42) -> 109.75798
B44: Financing cash flow | C44: A$m | D44: =+'Income & Cash Flow'!L119 -> 4.39 | G44: =+'Income & Cash Flow'!O119 -> -4.467 | J44: =+'Income & Cash Flow'!R119 -> 254.934 | M44: =+'Income & Cash Flow'!U119 -> 0.679 | P44: =+'Income & Cash Flow'!X119 -> -30.798962 | S44: =+'Income & Cash Flow'!AA119 -> -32.277803
B45: Net change in cash | C45: A$m | D45: =+D44+D43+D41 -> -7.664 | G45: =+G44+G43+G41 -> -17.923 | J45: =+J44+J43+J41 -> -20.119 | M45: =+M44+M43+M41 -> 23.455 | P45: =+P44+P43+P41 -> 0.86471543 | S45: =+S44+S43+S41 -> 14.06553 | U45: Adj. Australia margin | V45: % | W45: =+W37/SUM(W33:W34) -> 0.10851325 | X45: =+X37/SUM(X33:X34) -> 0.11241045 | Y45: =+Y37/SUM(Y33:Y34) -> 0.1303123 | Z45: =+Z37/SUM(Z33:Z34) -> 0.1218428 | AA45: =+AA37/SUM(AA33:AA34) -> 0.1432345 | AB45: =+AB37/SUM(AB33:AB34) -> 0.13227047 | AC45: =+AC37/SUM(AC33:AC34) -> 0.13760637 | AD45: =+AD37/SUM(AD33:AD34) -> 0.15192627 | ... AL45: =+AL37/SUM(AL33:AL34) -> 0.17156618
...

Sheet Income & Cash Flow
B1: =+'GYG model ->'!D2 -> Guzman y Gomez (GYG.ASX)
B2: Income & Cash Flow
O3: Pro Forma
B4: Year-end 30th June (A$m) | D4: 1H20A | E4: 2H20A | F4: FY20A | G4: 1H21A | H4: 2H21A | I4: FY21A | J4: 1H22A | K4: 2H22A | L4: FY22A | M4: 1H23A | N4: 2H23A | O4: FY23A | P4: 1H24A | Q4: 2H24A | R4: FY24A | S4: 1H25A | T4: 2H25A | U4: FY25A | V4: 1H26E | W4: 2H26E | X4: FY26E | Y4: 1H27E | Z4: 2H27E | AA4: FY27E | AB4: 1H28E | AC4: 2H28E | AD4: FY28E | AE4: 1H29E | AF4: 2H29E | AG4: FY29E | AH4: 1H30E | AI4: 2H30E | AJ4: FY30E | AK4: 1H31E | AL4: 2H31E | AM4: FY31E | AN4: 1H32E | AO4: 2H32E | AP4: FY32E | AQ4: 1H33E | AR4: 2H33E | AS4: FY33E | AT4: 1H34E | AU4: 2H34E | AV4: FY34E | AW4: 1H35E | AX4: 2H35E | AY4: FY35E
B5: Statement of Income
B6: Revenue | I6: 119.531 | L6: 171.792 | M6: 121.185 | N6: =+O6-M6 -> 137.859 | O6: 259.044 | P6: 167.517 | Q6: =+R6-P6 -> 174.697 | R6: 342.214 | S6: 212.419 | T6: =+U6-S6 -> 223.563 | U6: 435.982 | V6: =+Segments!V22 -> 265.23678 | W6: =+Segments!W22 -> 273.59806 | X6: =+Segments!X22 -> 538.83484 | Y6: =+Segments!Y22 -> 316.62802 | Z6: =+Segments!Z22 -> 325.20742 | AA6: =+Segments!AA22 -> 641.83544 | AB6: =+Segments!AB22 -> 373.19481 | AC6: =+Segments!AC22 -> 380.40127 | ... AY6: =+Segments!AY22 -> 1672.8283
B7: Other | I7: 0 | L7: 0 | M7: 0 | N7: =+O7-M7 -> 0 | O7: 0 | P7: 0 | Q7: =+R7-P7 -> 0 | R7: 0 | S7: 0 | T7: =+U7-S7 -> 0 | U7: 0 | V7: 0 | W7: 0 | X7: =+W7+V7 -> 0 | Y7: 0 | Z7: 0 | AA7: =+Z7+Y7 -> 0 | AB7: 0 | AC7: 0 | AD7: =+AC7+AB7 -> 0 | AE7: 0 | AF7: 0 | AG7: =+AF7+AE7 -> 0 | AH7: 0 | AI7: 0 | AJ7: =+AI7+AH7 -> 0 | AK7: 0 | AL7: 0 | AM7: =+AL7+AK7 -> 0 | AN7: 0 | AO7: 0 | AP7: =+AO7+AN7 -> 0 | AQ7: 0 | AR7: 0 | AS7: =+AR7+AQ7 -> 0 | AT7: 0 | AU7: 0 | AV7: =+AU7+AT7 -> 0 | AW7: 0 | AX7: 0 | AY7: =+AX7+AW7 -> 0
B8: Total revenue | I8: =I7+I6 -> 119.531 | L8: =L7+L6 -> 171.792 | M8: =M7+M6 -> 121.185 | N8: =N7+N6 -> 137.859 | O8: =O7+O6 -> 259.044 | P8: =P7+P6 -> 167.517 | Q8: =Q7+Q6 -> 174.697 | R8: =R7+R6 -> 342.214 | S8: =S7+S6 -> 212.419 | ... U8: =U7+U6 -> 435.982 | V8: =+V7+V6 -> 265.23678 | W8: =+W7+W6 -> 273.59806 | X8: =+X7+X6 -> 538.83484 | Y8: =+Y7+Y6 -> 316.62802 | Z8: =+Z7+Z6 -> 325.20742 | AA8: =+AA7+AA6 -> 641.83544 | AB8: =+AB7+AB6 -> 373.19481 | AC8: =+AC7+AC6 -> 380.40127 | ... AY8: =+AY7+AY6 -> 1672.8283
B10: Other revenue and income | I10: 11.429 | L10: 12.787 | M10: 9.792 | N10: =+O10-M10 -> 7.933 | O10: 17.725 | P10: 11.719 | Q10: =+R10-P10 -> 11.055 | R10: 22.774 | S10: 14.711 | T10: =+U10-S10 -> 17.313 | U10: 32.024 | V10: =+Segments!V259 -> 11.140007 | W10: =+Segments!W259 -> 11.650503 | X10: =+W10+V10 -> 22.790509 | Y10: =+Segments!Y259 -> 13.058918 | Z10: =+Segments!Z259 -> 13.544954 | AA10: =+Z10+Y10 -> 26.603873 | AB10: =+Segments!AB259 -> 15.010455 | AC10: =+Segments!AC259 -> 15.44467 | AD10: =+AC10+AB10 -> 30.455125 | AE10: =+Segments!AE259 -> 16.882749 | AF10: =+Segments!AF259 -> 17.296085 | AG10: =+AF10+AE10 -> 34.178834 | AH10: =+Segments!AH259 -> 18.830786 | AI10: =+Segments!AI259 -> 19.222709 | AJ10: =+AI10+AH10 -> 38.053494 | AK10: =+Segments!AK259 -> 21.318751 | AL10: =+Segments!AL259 -> 21.582391 | AM10: =+AL10+AK10 -> 42.901142 | AN10: =+Segments!AN259 -> 23.749568 | AO10: =+Segments!AO259 -> 23.979049 | AP10: =+AO10+AN10 -> 47.728617 | AQ10: =+Segments!AQ259 -> 26.326675 | AR10: =+Segments!AR259 -> 26.519699 | AS10: =+AR10+AQ10 -> 52.846373 | AT10: =+Segments!AT259 -> 29.058311 | AU10: =+Segments!AU259 -> 29.21247 | AV10: =+AU10+AT10 -> 58.270781 | AW10: =+Segments!AW259 -> 31.95319 | AX10: =+Segments!AX259 -> 32.065965 | AY10: =+AX10+AW10 -> 64.019155
B11: Cost of food and packaging | I11: -31.796 | L11: -44.194 | M11: -32.906 | N11: =+O11-M11 -> -37.522 | O11: -70.428 | P11: -43.237 | Q11: =+R11-P11 -> -44.343 | R11: -87.58 | S11: -55.071 | T11: =+U11-S11 -> -58.877 | U11: -113.948 | V11: =+Segments!V260 -> -61.957311 | W11: =+Segments!W260 -> -64.796535 | X11: =+W11+V11 -> -126.75385 | Y11: =+Segments!Y260 -> -72.629712 | Z11: =+Segments!Z260 -> -75.332896 | AA11: =+Z11+Y11 -> -147.96261 | AB11: =+Segments!AB260 -> -83.483562 | AC11: =+Segments!AC260 -> -85.898533 | AD11: =+AC11+AB11 -> -169.38209 | AE11: =+Segments!AE260 -> -93.896689 | AF11: =+Segments!AF260 -> -96.195537 | AG11: =+AF11+AE11 -> -190.09223 | AH11: =+Segments!AH260 -> -104.73107 | AI11: =+Segments!AI260 -> -106.91083 | AJ11: =+AI11+AH11 -> -211.6419 | AK11: =+Segments!AK260 -> -118.56837 | AL11: =+Segments!AL260 -> -120.03466 | AM11: =+AL11+AK11 -> -238.60304 | AN11: =+Segments!AN260 -> -132.08784 | AO11: =+Segments!AO260 -> -133.36414 | AP11: =+AO11+AN11 -> -265.45198 | AQ11: =+Segments!AQ260 -> -146.42092 | AR11: =+Segments!AR260 -> -147.49446 | AS11: =+AR11+AQ11 -> -293.91537 | AT11: =+Segments!AT260 -> -161.61344 | AU11: =+Segments!AU260 -> -162.47083 | AV11: =+AU11+AT11 -> -324.08427 | AW11: =+Segments!AW260 -> -177.71387 | AX11: =+Segments!AX260 -> -178.3411 | AY11: =+AX11+AW11 -> -356.05497
B12: Employee benefits expense | I12: -42.953 | L12: -65.13 | M12: -49.458 | N12: =+O12-M12 -> -53.711 | O12: -103.169 | P12: -67.015 | Q12: =+R12-P12 -> -86.718 | R12: -153.733 | S12: -89.003 | T12: =+U12-S12 -> -95.653 | U12: -184.656 | V12: =+Segments!V261 -> -108.75638 | W12: =+Segments!W261 -> -113.74019 | X12: =+W12+V12 -> -222.49656 | Y12: =+Segments!Y261 -> -127.49011 | Z12: =+Segments!Z261 -> -132.23512 | AA12: =+Z12+Y12 -> -259.72523 | AB12: =+Segments!AB261 -> -146.54234 | AC12: =+Segments!AC261 -> -150.78145 | AD12: =+AC12+AB12 -> -297.32379 | AE12: =+Segments!AE261 -> -164.82096 | AF12: =+Segments!AF261 -> -168.85623 | AG12: =+AF12+AE12 -> -333.67719 | AH12: =+Segments!AH261 -> -183.83903 | AI12: =+Segments!AI261 -> -187.66525 | AJ12: =+AI12+AH12 -> -371.50428 | AK12: =+Segments!AK261 -> -208.12825 | AL12: =+Segments!AL261 -> -210.70209 | AM12: =+AL12+AK12 -> -418.83034 | AN12: =+Segments!AN261 -> -231.85955 | AO12: =+Segments!AO261 -> -234.0999 | AP12: =+AO12+AN12 -> -465.95945 | AQ12: =+Segments!AQ261 -> -257.01903 | AR12: =+Segments!AR261 -> -258.90347 | AS12: =+AR12+AQ12 -> -515.9225 | AT12: =+Segments!AT261 -> -283.68714 | AU12: =+Segments!AU261 -> -285.19214 | AV12: =+AU12+AT12 -> -568.87928 | AW12: =+Segments!AW261 -> -311.94893 | AX12: =+Segments!AX261 -> -313.04992 | AY12: =+AX12+AW12 -> -624.99884
B13: Administrative expense | I13: =-61.741+42.953 -> -18.788 | L13: =-92.536+65.13 -> -27.406 | M13: =-68.504+49.458 -> -19.046 | N13: =+O13-M13 -> -22.93 | O13: =-145.145+103.169 -> -41.976 | P13: =-95.73+67.015 -> -28.715 | Q13: =+R13-P13 -> -31.88 | R13: -60.595 | S13: -25.865 | T13: =+U13-S13 -> -27.75 | U13: -53.615 | V13: =+Segments!V262 -> -42.86713 | W13: =+Segments!W262 -> -44.831537 | X13: =+W13+V13 -> -87.698668 | Y13: =+Segments!Y262 -> -50.251169 | Z13: =+Segments!Z262 -> -52.121453 | AA13: =+Z13+Y13 -> -102.37262 | AB13: =+Segments!AB262 -> -57.760749 | AC13: =+Segments!AC262 -> -59.431624 | AD13: =+AC13+AB13 -> -117.19237 | AE13: =+Segments!AE262 -> -64.965402 | AF13: =+Segments!AF262 -> -66.555933 | AG13: =+AF13+AE13 -> -131.52133 | AH13: =+Segments!AH262 -> -72.461513 | AI13: =+Segments!AI262 -> -73.969648 | AJ13: =+AI13+AH13 -> -146.43116 | AK13: =+Segments!AK262 -> -82.03529 | AL13: =+Segments!AL262 -> -83.049787 | AM13: =+AL13+AK13 -> -165.08508 | AN13: =+Segments!AN262 -> -91.389159 | AO13: =+Segments!AO262 -> -92.272209 | AP13: =+AO13+AN13 -> -183.66137 | AQ13: =+Segments!AQ262 -> -101.30595 | AR13: =+Segments!AR262 -> -102.04872 | AS13: =+AR13+AQ13 -> -203.35467 | AT13: =+Segments!AT262 -> -111.81739 | AU13: =+Segments!AU262 -> -112.41059 | AV13: =+AU13+AT13 -> -224.22798 | AW13: =+Segments!AW262 -> -122.95698 | AX13: =+Segments!AX262 -> -123.39094 | AY13: =+AX13+AW13 -> -246.34792
B14: Marketing expense | I14: -10.725 | L14: -13.987 | M14: -8.76 | N14: =+O14-M14 -> -8.82 | O14: -17.58 | P14: -10.704 | Q14: =+R14-P14 -> -7.234 | R14: -17.938 | S14: -11.302 | T14: =+U14-S14 -> -9.985 | U14: -21.287 | V14: =+Segments!V263 -> -12.690001 | W14: =+Segments!W263 -> -13.271526 | X14: =+W14+V14 -> -25.961527 | Y14: =+Segments!Y263 -> -14.875905 | Z14: =+Segments!Z263 -> -15.429567 | AA14: =+Z14+Y14 -> -30.305472 | AB14: =+Segments!AB263 -> -17.098974 | AC14: =+Segments!AC263 -> -17.593604 | AD14: =+AC14+AB14 -> -34.692578 | AE14: =+Segments!AE263 -> -19.231774 | AF14: =+Segments!AF263 -> -19.702621 | AG14: =+AF14+AE14 -> -38.934395 | AH14: =+Segments!AH263 -> -21.450856 | AI14: =+Segments!AI263 -> -21.897311 | AJ14: =+AI14+AH14 -> -43.348167 | AK14: =+Segments!AK263 -> -24.284991 | AL14: =+Segments!AL263 -> -24.585314 | AM14: =+AL14+AK14 -> -48.870305 | AN14: =+Segments!AN263 -> -27.054027 | AO14: =+Segments!AO263 -> -27.315437 | AP14: =+AO14+AN14 -> -54.369463 | AQ14: =+Segments!AQ263 -> -29.989705 | AR14: =+Segments!AR263 -> -30.209587 | AS14: =+AR14+AQ14 -> -60.199292 | AT14: =+Segments!AT263 -> -33.101415 | AU14: =+Segments!AU263 -> -33.277023 | AV14: =+AU14+AT14 -> -66.378439 | AW14: =+Segments!AW263 -> -36.39908 | AX14: =+Segments!AX263 -> -36.527547 | AY14: =+AX14+AW14 -> -72.926628
B15: Other expense | I15: =-2.088-5.957 -> -8.045 | L15: =-8.275-1.681 -> -9.956 | M15: =-5.787-0.483 -> -6.27 | N15: =+O15-M15 -> -7.725 | O15: =-11.714-2.281 -> -13.995 | P15: =-9.274-1.387 -> -10.661 | Q15: =+R15-P15 -> -7.207 | R15: -17.868 | S15: -14.311 | T15: =+U15-S15 -> -15.07 | U15: -29.381 | V15: =+Segments!V264 -> -7.6693219 | W15: =+Segments!W264 -> -8.0207723 | X15: =+W15+V15 -> -15.690094 | Y15: =+Segments!Y264 -> -8.990394 | Z15: =+Segments!Z264 -> -9.3250048 | AA15: =+Z15+Y15 -> -18.315399 | AB15: =+Segments!AB264 -> -10.333927 | AC15: =+Segments!AC264 -> -10.632861 | AD15: =+AC15+AB15 -> -20.966788 | AE15: =+Segments!AE264 -> -11.622905 | AF15: =+Segments!AF264 -> -11.907465 | AG15: =+AF15+AE15 -> -23.53037 | AH15: =+Segments!AH264 -> -12.964028 | AI15: =+Segments!AI264 -> -13.233847 | AJ15: =+AI15+AH15 -> -26.197875 | AK15: =+Segments!AK264 -> -14.676864 | AL15: =+Segments!AL264 -> -14.858367 | AM15: =+AL15+AK15 -> -29.535231 | AN15: =+Segments!AN264 -> -16.350357 | AO15: =+Segments!AO264 -> -16.508343 | AP15: =+AO15+AN15 -> -32.858699 | AQ15: =+Segments!AQ264 -> -18.124562 | AR15: =+Segments!AR264 -> -18.257449 | AS15: =+AR15+AQ15 -> -36.382011 | AT15: =+Segments!AT264 -> -20.005154 | AU15: =+Segments!AU264 -> -20.111284 | AV15: =+AU15+AT15 -> -40.116437 | AW15: =+Segments!AW264 -> -21.998129 | AX15: =+Segments!AX264 -> -22.075769 | AY15: =+AX15+AW15 -> -44.073897
B16: Opex | I16: =SUM(I10:I15) -> -100.878 | L16: =SUM(L10:L15) -> -147.886 | M16: =SUM(M10:M15) -> -106.648 | N16: =SUM(N10:N15) -> -122.775 | O16: =SUM(O10:O15) -> -229.423 | P16: =SUM(P10:P15) -> -148.613 | Q16: =SUM(Q10:Q15) -> -166.327 | R16: =SUM(R10:R15) -> -314.94 | S16: =SUM(S10:S15) -> -180.841 | ... AY16: =SUM(AY10:AY15) -> -1280.3831
B18: Reported Ebitda | I18: =+I8+I16 -> 18.653 | L18: =+L8+L16 -> 23.906 | M18: =+M8+M16 -> 14.537 | N18: =+N8+N16 -> 15.084 | O18: =+O8+O16 -> 29.621 | P18: =+P8+P16 -> 18.904 | Q18: =+Q8+Q16 -> 8.37 | R18: =+R8+R16 -> 27.274 | S18: =+S8+S16 -> 31.578 | ... U18: =+U8+U16 -> 65.119 | V18: =+Segments!V33 -> 42.436647 | W18: =+Segments!W33 -> 40.588008 | X18: =+W18+V18 -> 83.024656 | Y18: =+Segments!Y33 -> 55.449649 | Z18: =+Segments!Z33 -> 54.308335 | AA18: =+Z18+Y18 -> 109.75798 | AB18: =+Segments!AB33 -> 72.985707 | AC18: =+Segments!AC33 -> 71.507867 | AD18: =+AC18+AB18 -> 144.49357 | AE18: =+Segments!AE33 -> 91.082529 | AF18: =+Segments!AF33 -> 89.097936 | AG18: =+AF18+AE18 -> 180.18046 | AH18: =+Segments!AH33 -> 111.58203 | AI18: =+Segments!AI33 -> 107.23519 | AJ18: =+AI18+AH18 -> 218.81722 | AK18: =+Segments!AK33 -> 123.45882 | AL18: =+Segments!AL33 -> 120.37774 | AM18: =+AL18+AK18 -> 243.83656 | AN18: =+Segments!AN33 -> 140.45118 | AO18: =+Segments!AO33 -> 136.65717 | AP18: =+AO18+AN18 -> 277.10835 | AQ18: =+Segments!AQ33 -> 158.71687 | AR18: =+Segments!AR33 -> 154.15381 | AS18: =+AR18+AQ18 -> 312.87068 | AT18: =+Segments!AT33 -> 178.32926 | AU18: =+Segments!AU33 -> 172.93733 | AV18: =+AU18+AT18 -> 351.26659 | AW18: =+Segments!AW33 -> 199.36486 | AX18: =+Segments!AX33 -> 193.08033 | AY18: =+AX18+AW18 -> 392.4452
B19: Adjustments | I19: =+I20-I18 -> -2.732 | L19: =+L20-L18 -> -2.206 | M19: =+M20-M18 -> -0.337 | N19: =+N20-N18 -> 0.016 | O19: =+O20-O18 -> -0.321 | P19: =+P20-P18 -> 5.796 | Q19: =+Q20-Q18 -> 11.73 | R19: =+R20-R18 -> 17.526 | S19: =+S20-S18 -> 0 | ... U19: =+U20-U18 -> 0 | V19: =+Segments!V32 -> 0 | W19: =+Segments!W32 -> 0 | X19: =+W19+V19 -> 0 | Y19: =+Segments!Y32 -> 0 | Z19: =+Segments!Z32 -> 0 | AA19: =+Z19+Y19 -> 0 | AB19: =+Segments!AB32 -> 0 | AC19: =+Segments!AC32 -> 0 | AD19: =+AC19+AB19 -> 0 | AE19: =+Segments!AE32 -> 0 | AF19: =+Segments!AF32 -> 0 | AG19: =+AF19+AE19 -> 0 | AH19: =+Segments!AH32 -> 0 | AI19: =+Segments!AI32 -> 0 | AJ19: =+AI19+AH19 -> 0 | AK19: =+Segments!AK32 -> 0 | AL19: =+Segments!AL32 -> 0 | AM19: =+AL19+AK19 -> 0 | AN19: =+Segments!AN32 -> 0 | AO19: =+Segments!AO32 -> 0 | AP19: =+AO19+AN19 -> 0 | AQ19: =+Segments!AQ32 -> 0 | AR19: =+Segments!AR32 -> 0 | AS19: =+AR19+AQ19 -> 0 | AT19: =+Segments!AT32 -> 0 | AU19: =+Segments!AU32 -> 0 | AV19: =+AU19+AT19 -> 0 | AW19: =+Segments!AW32 -> 0 | AX19: =+Segments!AX32 -> 0 | AY19: =+AX19+AW19 -> 0
B20: Adj. Ebitda | I20: 15.921 | L20: 21.7 | M20: 14.2 | N20: =+O20-M20 -> 15.1 | O20: 29.3 | P20: 24.7 | Q20: =+R20-P20 -> 20.1 | R20: 44.8 | S20: 31.578 | T20: =+U20-S20 -> 33.541 | U20: 65.119 | V20: =+Segments!V31 -> 42.436647 | W20: =+Segments!W31 -> 40.588008 | X20: =+Segments!X31 -> 83.024656 | Y20: =+Segments!Y31 -> 55.449649 | Z20: =+Segments!Z31 -> 54.308335 | AA20: =+Segments!AA31 -> 109.75798 | AB20: =+Segments!AB31 -> 72.985707 | AC20: =+Segments!AC31 -> 71.507867 | ... AY20: =+Segments!AY31 -> 392.4452
B22: Depreciation (PPE) | I22: =-8.708-I23 -> -3.537 | L22: =-11.997-L23 -> -5.341 | M22: =-9.197-M23 -> -3.798 | N22: =+O22-M22 -> -4.592 | O22: -8.39 | P22: =-12.386-P23 -> -6.062 | Q22: =+R22-P22 -> -6.898 | R22: -12.96 | S22: -7.832 | T22: =+U22-S22 -> -11.464 | U22: -19.296 | V22: =+'Balance Sheet'!V105 -> -13.0056 | W22: =+'Balance Sheet'!W105 -> -14.70504 | X22: =+W22+V22 -> -27.71064 | Y22: =+'Balance Sheet'!Y105 -> -16.234536 | Z22: =+'Balance Sheet'!Z105 -> -17.806082 | AA22: =+Z22+Y22 -> -34.040618 | AB22: =+'Balance Sheet'!AB105 -> -19.220474 | AC22: =+'Balance Sheet'!AC105 -> -20.717077 | AD22: =+AC22+AB22 -> -39.937551 | AE22: =+'Balance Sheet'!AE105 -> -22.064019 | AF22: =+'Balance Sheet'!AF105 -> -23.515573 | AG22: =+AF22+AE22 -> -45.579592 | AH22: =+'Balance Sheet'!AH105 -> -24.821971 | AI22: =+'Balance Sheet'!AI105 -> -26.253786 | AJ22: =+AI22+AH22 -> -51.075757 | AK22: =+'Balance Sheet'!AK105 -> -27.54242 | AL22: =+'Balance Sheet'!AL105 -> -28.976171 | AM22: =+AL22+AK22 -> -56.518591 | AN22: =+'Balance Sheet'!AN105 -> -30.266547 | AO22: =+'Balance Sheet'!AO105 -> -31.721045 | AP22: =+AO22+AN22 -> -61.987593 | AQ22: =+'Balance Sheet'!AQ105 -> -33.030094 | AR22: =+'Balance Sheet'!AR105 -> -34.521918 | AS22: =+AR22+AQ22 -> -67.552011 | AT22: =+'Balance Sheet'!AT105 -> -35.864559 | AU22: =+'Balance Sheet'!AU105 -> -37.408575 | AV22: =+AU22+AT22 -> -73.273135 | AW22: =+'Balance Sheet'!AW105 -> -38.79819 | AX22: =+'Balance Sheet'!AX105 -> -40.407975 | AY22: =+AX22+AW22 -> -79.206165
B23: Depreciation (RoU) | I23: -5.171 | L23: -6.656 | M23: -5.399 | N23: =+O23-M23 -> -4.933 | O23: -10.332 | P23: -6.324 | Q23: =+R23-P23 -> -4.923 | R23: -11.247 | S23: -7.743 | T23: =+U23-S23 -> -6.131 | U23: -13.874 | V23: =+'Balance Sheet'!V127 -> -8.323725 | W23: =+'Balance Sheet'!W127 -> -6.590825 | X23: =+W23+V23 -> -14.91455 | Y23: =+'Balance Sheet'!Y127 -> -8.9480044 | Z23: =+'Balance Sheet'!Z127 -> -7.0851369 | AA23: =+Z23+Y23 -> -16.033141 | AB23: =+'Balance Sheet'!AB127 -> -9.6191047 | AC23: =+'Balance Sheet'!AC127 -> -7.6165221 | AD23: =+AC23+AB23 -> -17.235627 | AE23: =+'Balance Sheet'!AE127 -> -10.340538 | AF23: =+'Balance Sheet'!AF127 -> -8.1877613 | AG23: =+AF23+AE23 -> -18.528299 | AH23: =+'Balance Sheet'!AH127 -> -11.116078 | AI23: =+'Balance Sheet'!AI127 -> -8.8018434 | AJ23: =+AI23+AH23 -> -19.917921 | AK23: =+'Balance Sheet'!AK127 -> -11.949784 | AL23: =+'Balance Sheet'!AL127 -> -9.4619817 | AM23: =+AL23+AK23 -> -21.411765 | AN23: =+'Balance Sheet'!AN127 -> -12.846017 | AO23: =+'Balance Sheet'!AO127 -> -10.17163 | AP23: =+AO23+AN23 -> -23.017648 | AQ23: =+'Balance Sheet'!AQ127 -> -13.809469 | AR23: =+'Balance Sheet'!AR127 -> -10.934503 | AS23: =+AR23+AQ23 -> -24.743971 | AT23: =+'Balance Sheet'!AT127 -> -14.845179 | AU23: =+'Balance Sheet'!AU127 -> -11.75459 | AV23: =+AU23+AT23 -> -26.599769 | AW23: =+'Balance Sheet'!AW127 -> -15.958567 | AX23: =+'Balance Sheet'!AX127 -> -12.636185 | AY23: =+AX23+AW23 -> -28.594752
B24: Amortisation | I24: -1.4 | L24: -2.463 | M24: -3.37 | N24: =+O24-M24 -> -3.463 | O24: -6.833 | P24: -3.514 | Q24: =+R24-P24 -> -3.402 | R24: -6.916 | S24: =-1.89-1.615 -> -3.505 | T24: =+U24-S24 -> -3.006 | U24: =-3.668-2.843 -> -6.511 | V24: =+'Balance Sheet'!V117 -> -3.68025 | W24: =+'Balance Sheet'!W117 -> -3.1563 | X24: =+W24+V24 -> -6.83655 | Y24: =+'Balance Sheet'!Y117 -> -3.8642625 | Z24: =+'Balance Sheet'!Z117 -> -3.314115 | AA24: =+Z24+Y24 -> -7.1783775 | AB24: =+'Balance Sheet'!AB117 -> -4.0574756 | AC24: =+'Balance Sheet'!AC117 -> -3.4798208 | AD24: =+AC24+AB24 -> -7.5372964 | AE24: =+'Balance Sheet'!AE117 -> -4.2603494 | AF24: =+'Balance Sheet'!AF117 -> -3.6538118 | AG24: =+AF24+AE24 -> -7.9141612 | AH24: =+'Balance Sheet'!AH117 -> -4.4733669 | AI24: =+'Balance Sheet'!AI117 -> -3.8365024 | AJ24: =+AI24+AH24 -> -8.3098693 | AK24: =+'Balance Sheet'!AK117 -> -4.6970352 | AL24: =+'Balance Sheet'!AL117 -> -4.0283275 | AM24: =+AL24+AK24 -> -8.7253627 | AN24: =+'Balance Sheet'!AN117 -> -4.931887 | AO24: =+'Balance Sheet'!AO117 -> -4.2297439 | AP24: =+AO24+AN24 -> -9.1616309 | AQ24: =+'Balance Sheet'!AQ117 -> -5.1784813 | AR24: =+'Balance Sheet'!AR117 -> -4.4412311 | AS24: =+AR24+AQ24 -> -9.6197124 | AT24: =+'Balance Sheet'!AT117 -> -5.4374054 | AU24: =+'Balance Sheet'!AU117 -> -4.6632926 | AV24: =+AU24+AT24 -> -10.100698 | AW24: =+'Balance Sheet'!AW117 -> -5.7092757 | AX24: =+'Balance Sheet'!AX117 -> -4.8964572 | AY24: =+AX24+AW24 -> -10.605733
B25: Ebit | I25: =I18+SUM(I22:I24) -> 8.545 | L25: =L18+SUM(L22:L24) -> 9.446 | M25: =M18+SUM(M22:M24) -> 1.97 | N25: =N18+SUM(N22:N24) -> 2.096 | O25: =O18+SUM(O22:O24) -> 4.066 | P25: =P18+SUM(P22:P24) -> 3.004 | Q25: =Q18+SUM(Q22:Q24) -> -6.853 | R25: =R18+SUM(R22:R24) -> -3.849 | S25: =S18+SUM(S22:S24) -> 12.498 | ... AY25: =AY18+SUM(AY22:AY24) -> 274.03855
B26: Adjustments | I26: =+I27-I25 -> -4.845 | L26: =+L27-L25 -> -2.246 | M26: =+M27-M25 -> -0.37 | N26: =+N27-N25 -> 0.004 | O26: =+O27-O25 -> -0.366 | P26: =+P27-P25 -> 5.796 | Q26: =+Q27-Q25 -> 11.653 | R26: =+R27-R25 -> 17.449 | S26: =+S27-S25 -> 0 | ... U26: =+U27-U25 -> -0.038 | V26: =+V19 -> 0 | W26: =+W19 -> 0 | X26: =+X19 -> 0 | Y26: =+Y19 -> 0 | Z26: =+Z19 -> 0 | AA26: =+AA19 -> 0 | AB26: =+AB19 -> 0 | AC26: =+AC19 -> 0 | ... AY26: =+AY19 -> 0
B27: Adj. Ebit | I27: 3.7 | L27: 7.2 | M27: 1.6 | N27: =+O27-M27 -> 2.1 | O27: 3.7 | P27: 8.8 | Q27: =+R27-P27 -> 4.8 | R27: 13.6 | S27: 12.498 | T27: =+U27-S27 -> 12.902 | U27: 25.4 | V27: =+V26+V25 -> 17.427072 | W27: =+W26+W25 -> 16.135843 | X27: =+X26+X25 -> 33.562916 | Y27: =+Y26+Y25 -> 26.402846 | Z27: =+Z26+Z25 -> 26.103001 | AA27: =+AA26+AA25 -> 52.505847 | AB27: =+AB26+AB25 -> 40.088652 | AC27: =+AC26+AC25 -> 39.694447 | ... AY27: =+AY26+AY25 -> 274.03855
B29: Financial income | I29: 2.935 | L29: 3.173 | M29: 2.138 | N29: =+O29-M29 -> 2.455 | O29: 4.593 | P29: 2.327 | Q29: =+R29-P29 -> 3.685 | R29: 6.012 | S29: 11.445 | T29: =+U29-S29 -> 11.229 | U29: 22.674 | V29: =+'Balance Sheet'!V154 -> 7.5 | W29: =+'Balance Sheet'!W154 -> 7.5 | X29: =+W29+V29 -> 15 | Y29: =+'Balance Sheet'!Y154 -> 7.5 | Z29: =+'Balance Sheet'!Z154 -> 5.0858899 | AA29: =+Z29+Y29 -> 12.58589 | AB29: =+'Balance Sheet'!AB154 -> 5.1917818 | AC29: =+'Balance Sheet'!AC154 -> 5.4784885 | AD29: =+AC29+AB29 -> 10.67027 | AE29: =+'Balance Sheet'!AE154 -> 5.768177 | AF29: =+'Balance Sheet'!AF154 -> 6.2444804 | AG29: =+AF29+AE29 -> 12.012657 | AH29: =+'Balance Sheet'!AH154 -> 6.7243346 | AI29: =+'Balance Sheet'!AI154 -> 7.4203883 | AJ29: =+AI29+AH29 -> 14.144723 | AK29: =+'Balance Sheet'!AK154 -> 8.1006885 | AL29: =+'Balance Sheet'!AL154 -> 8.9495724 | AM29: =+AL29+AK29 -> 17.050261 | AN29: =+'Balance Sheet'!AN154 -> 9.7641801 | AO29: =+'Balance Sheet'!AO154 -> 10.784464 | AP29: =+AO29+AN29 -> 20.548644 | AQ29: =+'Balance Sheet'!AQ154 -> 11.775775 | AR29: =+'Balance Sheet'!AR154 -> 12.994904 | AS29: =+AR29+AQ29 -> 24.770679 | AT29: =+'Balance Sheet'!AT154 -> 14.178976 | AU29: =+'Balance Sheet'!AU154 -> 15.614541 | AV29: =+AU29+AT29 -> 29.793517 | AW29: =+'Balance Sheet'!AW154 -> 17.008675 | AX29: =+'Balance Sheet'!AX154 -> 18.679586 | AY29: =+AX29+AW29 -> 35.688261
B30: Financial expense | I30: 0 | L30: =-0.07-0.139 -> -0.209 | M30: =-0.049-0.075 -> -0.124 | N30: =+O30-M30 -> -0.18 | O30: -0.304 | P30: =-0.076-0.073 -> -0.149 | Q30: =+R30-P30 -> -0.181 | R30: -0.33 | S30: -0.066 | T30: =+U30-S30 -> -0.065 | U30: =-18.902--18.771 -> -0.131 | V30: =+'Balance Sheet'!V151 -> 0 | W30: =+'Balance Sheet'!W151 -> 0 | X30: =+W30+V30 -> 0 | Y30: =+'Balance Sheet'!Y151 -> 0 | Z30: =+'Balance Sheet'!Z151 -> 0 | AA30: =+Z30+Y30 -> 0 | AB30: =+'Balance Sheet'!AB151 -> 0 | AC30: =+'Balance Sheet'!AC151 -> 0 | AD30: =+AC30+AB30 -> 0 | AE30: =+'Balance Sheet'!AE151 -> 0 | AF30: =+'Balance Sheet'!AF151 -> 0 | AG30: =+AF30+AE30 -> 0 | AH30: =+'Balance Sheet'!AH151 -> 0 | AI30: =+'Balance Sheet'!AI151 -> 0 | AJ30: =+AI30+AH30 -> 0 | AK30: =+'Balance Sheet'!AK151 -> 0 | AL30: =+'Balance Sheet'!AL151 -> 0 | AM30: =+AL30+AK30 -> 0 | AN30: =+'Balance Sheet'!AN151 -> 0 | AO30: =+'Balance Sheet'!AO151 -> 0 | AP30: =+AO30+AN30 -> 0 | AQ30: =+'Balance Sheet'!AQ151 -> 0 | AR30: =+'Balance Sheet'!AR151 -> 0 | AS30: =+AR30+AQ30 -> 0 | AT30: =+'Balance Sheet'!AT151 -> 0 | AU30: =+'Balance Sheet'!AU151 -> 0 | AV30: =+AU30+AT30 -> 0 | AW30: =+'Balance Sheet'!AW151 -> 0 | AX30: =+'Balance Sheet'!AX151 -> 0 | AY30: =+AX30+AW30 -> 0
B31: Financial expense (leases) | I31: -5.156 | L31: -5.799 | M31: -3.636 | N31: =+O31-M31 -> -4.563 | O31: -8.199 | P31: -6.261 | Q31: =+R31-P31 -> -7.133 | R31: -13.394 | S31: -8.686 | T31: =+U31-S31 -> -10.085 | U31: =-18.771 -> -18.771 | V31: =+'Balance Sheet'!V140 -> -9.3498471 | W31: =+'Balance Sheet'!W140 -> -9.5174753 | X31: =+W31+V31 -> -18.867322 | Y31: =+'Balance Sheet'!Y140 -> -9.6394182 | Z31: =+'Balance Sheet'!Z140 -> -9.8118716 | AA31: =+Z31+Y31 -> -19.45129 | AB31: =+'Balance Sheet'!AB140 -> -9.9345549 | AC31: =+'Balance Sheet'!AC140 -> -10.110822 | AD31: =+AC31+AB31 -> -20.045377 | AE31: =+'Balance Sheet'!AE140 -> -10.232812 | AF31: =+'Balance Sheet'!AF140 -> -10.411564 | AG31: =+AF31+AE31 -> -20.644376 | AH31: =+'Balance Sheet'!AH140 -> -10.531054 | AI31: =+'Balance Sheet'!AI140 -> -10.710573 | AJ31: =+AI31+AH31 -> -21.241627 | AK31: =+'Balance Sheet'!AK140 -> -10.825312 | AL31: =+'Balance Sheet'!AL140 -> -11.003417 | AM31: =+AL31+AK31 -> -21.828729 | AN31: =+'Balance Sheet'!AN140 -> -11.110618 | AO31: =+'Balance Sheet'!AO140 -> -11.284564 | AP31: =+AO31+AN31 -> -22.395182 | AQ31: =+'Balance Sheet'!AQ140 -> -11.380801 | AR31: =+'Balance Sheet'!AR140 -> -11.547174 | AS31: =+AR31+AQ31 -> -22.927976 | AT31: =+'Balance Sheet'!AT140 -> -11.628256 | AU31: =+'Balance Sheet'!AU140 -> -11.782834 | AV31: =+AU31+AT31 -> -23.41109 | AW31: =+'Balance Sheet'!AW140 -> -11.84366 | AX31: =+'Balance Sheet'!AX140 -> -11.981254 | AY31: =+AX31+AW31 -> -23.824913
B32: Net finance | I32: =SUM(I29:I31) -> -2.221 | J32: =SUM(J29:J31) -> 0 | K32: =SUM(K29:K31) -> 0 | L32: =SUM(L29:L31) -> -2.835 | M32: =SUM(M29:M31) -> -1.622 | N32: =SUM(N29:N31) -> -2.288 | O32: =SUM(O29:O31) -> -3.91 | P32: =SUM(P29:P31) -> -4.083 | ... AY32: =SUM(AY29:AY31) -> 11.863347
B34: Pbt | I34: =+I32+I25 -> 6.324 | J34: =+J32+J25 -> 0 | K34: =+K32+K25 -> 0 | L34: =+L32+L25 -> 6.611 | M34: =+M32+M25 -> 0.348 | N34: =+N32+N25 -> -0.192 | O34: =+O32+O25 -> 0.156 | P34: =+P32+P25 -> -1.079 | ... AY34: =+AY32+AY25 -> 285.90189
B35: Adjustments | I35: =+I36-I34 -> 1.276 | L35: =+L36-L34 -> -1.011 | M35: =+M36-M34 -> 2.952 | N35: =+N36-N34 -> 4.492 | O35: =+O36-O34 -> 7.444 | P35: =+P36-P34 -> 11.179 | Q35: =+Q36-Q34 -> 16.682 | R35: =+R36-R34 -> 27.861 | S35: =+S36-S34 -> 0 | ... U35: =+U36-U34 -> -0.01 | V35: 0 | W35: 0 | X35: =+W35+V35 -> 0 | Y35: 0 | Z35: 0 | AA35: =+Z35+Y35 -> 0 | AB35: 0 | AC35: 0 | AD35: =+AC35+AB35 -> 0 | AE35: 0 | AF35: 0 | AG35: =+AF35+AE35 -> 0 | AH35: 0 | AI35: 0 | AJ35: =+AI35+AH35 -> 0 | AK35: 0 | AL35: 0 | AM35: =+AL35+AK35 -> 0 | AN35: 0 | AO35: 0 | AP35: =+AO35+AN35 -> 0 | AQ35: 0 | AR35: 0 | AS35: =+AR35+AQ35 -> 0 | AT35: 0 | AU35: 0 | AV35: =+AU35+AT35 -> 0 | AW35: 0 | AX35: 0 | AY35: =+AX35+AW35 -> 0
B36: Adj. Pbt | I36: 7.6 | L36: 5.6 | M36: 3.3 | N36: =+O36-M36 -> 4.3 | O36: 7.6 | P36: 10.1 | Q36: =+R36-P36 -> 6.2 | R36: 16.3 | S36: 15.191 | T36: =+U36-S36 -> 14.009 | U36: 29.2 | V36: =+V35+V34 -> 15.577225 | W36: =+W35+W34 -> 14.118368 | X36: =+X35+X34 -> 29.695593 | Y36: =+Y35+Y34 -> 24.263428 | Z36: =+Z35+Z34 -> 21.377019 | AA36: =+AA35+AA34 -> 45.640447 | AB36: =+AB35+AB34 -> 35.345879 | AC36: =+AC35+AC34 -> 35.062113 | ... AY36: =+AY35+AY34 -> 285.90189
B38: Tax | I38: -2.336 | L38: -2.7 | M38: -1.469 | N38: =+O38-M38 -> -0.954 | O38: -2.423 | P38: -2.881 | Q38: =+R38-P38 -> 0.694 | R38: -2.187 | S38: -7.89 | T38: =+U38-S38 -> -6.844 | U38: -14.734 | V38: =+-V34*V39 -> -4.6731676 | W38: =+-W34*W39 -> -4.2355104 | X38: =+W38+V38 -> -8.908678 | Y38: =+-Y34*Y39 -> -7.2790283 | Z38: =+-Z34*Z39 -> -6.4131058 | AA38: =+Z38+Y38 -> -13.692134 | AB38: =+-AB34*AB39 -> -10.603764 | AC38: =+-AC34*AC39 -> -10.518634 | AD38: =+AC38+AB38 -> -21.122398 | AE38: =+-AE34*AE39 -> -14.985896 | AF38: =+-AF34*AF39 -> -14.872112 | AG38: =+AF38+AE38 -> -29.858008 | AH38: =+-AH34*AH39 -> -20.209169 | AI38: =+-AI34*AI39 -> -19.515862 | AJ38: =+AI38+AH38 -> -39.725031 | AK38: =+-AK34*AK39 -> -22.963489 | AL38: =+-AL34*AL39 -> -22.757224 | AM38: =+AL38+AK38 -> -45.720713 | AN38: =+-AN34*AN39 -> -27.318089 | AO38: =+-AO34*AO39 -> -27.010394 | AP38: =+AO38+AN38 -> -54.328483 | AQ38: =+-AQ34*AQ39 -> -32.128141 | AR38: =+-AR34*AR39 -> -31.711166 | AS38: =+AR38+AQ38 -> -63.839307 | AT38: =+-AT34*AT39 -> -37.41985 | AU38: =+-AU34*AU39 -> -36.882775 | AV38: =+AU38+AT38 -> -74.302625 | AW38: =+-AW34*AW39 -> -43.219154 | AX38: =+-AX34*AX39 -> -42.551414 | AY38: =+AX38+AW38 -> -85.770568
B39: Implied tax rate | I39: =-I38/I34 -> 0.36938646 | L39: =+-L38/L34 -> 0.40841023 | M39: =+-M38/M34 -> 4.2212644 | N39: =+-N38/N34 -> -4.96875 | O39: =+-O38/O34 -> 15.532051 | P39: =+-P38/P34 -> -2.6700649 | Q39: =+-Q38/Q34 -> 0.066208739 | R39: =+-R38/R34 -> -0.18917049 | S39: =+-S38/S34 -> 0.51938648 | ... U39: =+-U38/U34 -> 0.5044163 | V39: 0.3 | W39: 0.3 | X39: =-X38/X34 -> 0.3 | Y39: 0.3 | Z39: 0.3 | AA39: =-AA38/AA34 -> 0.3 | AB39: 0.3 | AC39: 0.3 | AD39: =-AD38/AD34 -> 0.3 | AE39: 0.3 | AF39: 0.3 | AG39: =-AG38/AG34 -> 0.3 | AH39: 0.3 | AI39: 0.3 | AJ39: =-AJ38/AJ34 -> 0.3 | AK39: 0.3 | AL39: 0.3 | AM39: =-AM38/AM34 -> 0.3 | AN39: 0.3 | AO39: 0.3 | AP39: =-AP38/AP34 -> 0.3 | AQ39: 0.3 | AR39: 0.3 | AS39: =-AS38/AS34 -> 0.3 | AT39: 0.3 | AU39: 0.3 | AV39: =-AV38/AV34 -> 0.3 | AW39: 0.3 | AX39: 0.3 | AY39: =-AY38/AY34 -> 0.3
B40: Reported Npat | I40: =+I38+I34 -> 3.988 | L40: =+L38+L34 -> 3.911 | M40: =+M38+M34 -> -1.121 | N40: =+N38+N34 -> -1.146 | O40: =+O38+O34 -> -2.267 | P40: =+P38+P34 -> -3.96 | Q40: =+Q38+Q34 -> -9.788 | R40: =+R38+R34 -> -13.748 | S40: =+S38+S34 -> 7.301 | ... AY40: =+AY38+AY34 -> 200.13132
B41: Adjustments | I41: =+I42-I40 -> -3.988 | L41: =+L42-L40 -> -0.711 | M41: =+M42-M40 -> 2.021 | N41: =+N42-N40 -> 3.246 | O41: =+O42-O40 -> 5.267 | P41: =+P42-P40 -> 7.76 | Q41: =+Q42-Q40 -> 11.688 | R41: =+R42-R40 -> 19.448 | S41: =+S42-S40 -> 0 | ... U41: =+U42-U40 -> -7.8159701e-14 | V41: 0 | W41: 0 | X41: =+W41+V41 -> 0 | Y41: 0 | Z41: 0 | AA41: =+Z41+Y41 -> 0 | AB41: 0 | AC41: 0 | AD41: =+AC41+AB41 -> 0 | AE41: 0 | AF41: 0 | AG41: =+AF41+AE41 -> 0 | AH41: 0 | AI41: 0 | AJ41: =+AI41+AH41 -> 0 | AK41: 0 | AL41: 0 | AM41: =+AL41+AK41 -> 0 | AN41: 0 | AO41: 0 | AP41: =+AO41+AN41 -> 0 | AQ41: 0 | AR41: 0 | AS41: =+AR41+AQ41 -> 0 | AT41: 0 | AU41: 0 | AV41: =+AU41+AT41 -> 0 | AW41: 0 | AX41: 0 | AY41: =+AX41+AW41 -> 0
B42: Adj. Npat | L42: 3.2 | M42: 0.9 | N42: =+O42-M42 -> 2.1 | O42: 3 | P42: 3.8 | Q42: =+R42-P42 -> 1.9 | R42: 5.7 | S42: 7.301 | T42: =+U42-S42 -> 7.175 | U42: 14.476 | V42: =+V41+V40 -> 10.904058 | W42: =+W41+W40 -> 9.8828575 | X42: =+X41+X40 -> 20.786915 | Y42: =+Y41+Y40 -> 16.984399 | Z42: =+Z41+Z40 -> 14.963914 | AA42: =+AA41+AA40 -> 31.948313 | AB42: =+AB41+AB40 -> 24.742115 | AC42: =+AC41+AC40 -> 24.543479 | ... AY42: =+AY41+AY40 -> 200.13132
B44: Other comprehensive income/expense | I44: -0.009 | L44: 0.008 | M44: 0.01 | N44: =+N45-N40 -> 0.389 | O44: 0.399 | P44: -0.387 | Q44: =+Q45-Q40 -> 0.457 | R44: 0.07 | S44: 0.818 | T44: =+T45-T40 -> -1.223 | U44: -0.405 | V44: 0 | W44: 0 | X44: =+W44+V44 -> 0 | Y44: 0 | Z44: 0 | AA44: =+Z44+Y44 -> 0 | AB44: 0 | AC44: 0 | AD44: =+AC44+AB44 -> 0 | AE44: 0 | AF44: 0 | AG44: =+AF44+AE44 -> 0 | AH44: 0 | AI44: 0 | AJ44: =+AI44+AH44 -> 0 | AK44: 0 | AL44: 0 | AM44: =+AL44+AK44 -> 0 | AN44: 0 | AO44: 0 | AP44: =+AO44+AN44 -> 0 | AQ44: 0 | AR44: 0 | AS44: =+AR44+AQ44 -> 0 | AT44: 0 | AU44: 0 | AV44: =+AU44+AT44 -> 0 | AW44: 0 | AX44: 0 | AY44: =+AX44+AW44 -> 0
B45: Total comprehensive NPAT | I45: =+I40+I44 -> 3.979 | L45: =+L40+L44 -> 3.919 | M45: =+M40+M44 -> -1.111 | N45: =+O45-M45 -> -0.757 | O45: =+O40+O44 -> -1.868 | P45: =+P40+P44 -> -4.347 | Q45: =+R45-P45 -> -9.331 | R45: =+R40+R44 -> -13.678 | S45: =+S40+S44 -> 8.119 | T45: =+U45-S45 -> 5.952 | U45: =+U40+U44 -> 14.071 | V45: =+V40+V44 -> 10.904058 | W45: =+W40+W44 -> 9.8828575 | X45: =+X40+X44 -> 20.786915 | Y45: =+Y40+Y44 -> 16.984399 | Z45: =+Z40+Z44 -> 14.963914 | AA45: =+AA40+AA44 -> 31.948313 | AB45: =+AB40+AB44 -> 24.742115 | ... AY45: =+AY40+AY44 -> 200.13132
B47: Check - NPAT | I47: =ROUND(3.988-I40,3) -> 0 | L47: =ROUND(3.911-L40,3) -> 0 | M47: =ROUND(-1.121-M40,3) -> 0 | O47: =ROUND(-2.267-O40,3) -> 0 | P47: =ROUND(-3.96-P40,3) -> 0 | R47: =ROUND(-13.748-R40,3) -> 0 | S47: =ROUND(7.301-S40,3) -> 0 | U47: =ROUND(14.476-U40,3) -> 0
R48: hem
...

Sheet Balance Sheet
B1: =+'GYG model ->'!D2 -> Guzman y Gomez (GYG.ASX)
B2: Balance Sheet
B4: Year-end 30th June (A$m) | D4: =+'Income & Cash Flow'!D4 -> 1H20A | E4: =+'Income & Cash Flow'!E4 -> 2H20A | F4: =+'Income & Cash Flow'!F4 -> FY20A | G4: =+'Income & Cash Flow'!G4 -> 1H21A | H4: =+'Income & Cash Flow'!H4 -> 2H21A | I4: =+'Income & Cash Flow'!I4 -> FY21A | J4: =+'Income & Cash Flow'!J4 -> 1H22A | K4: =+'Income & Cash Flow'!K4 -> 2H22A | ... AY4: =+'Income & Cash Flow'!AY4 -> FY35E
B5: Balance Sheet
B6: Cash & equivalents | I6: 62.091 | L6: 54.427 | O6: 36.504 | P6: 13.619 | Q6: =+R6 -> 16.385 | R6: =16.385 -> 16.385 | S6: 16.882 | T6: =+U6 -> 39.675 | U6: 39.675 | V6: =+'Income & Cash Flow'!V124 -> 40.909944 | W6: =+X6 -> 40.539715 | X6: =+'Income & Cash Flow'!X124 -> 40.539715 | Y6: =+'Income & Cash Flow'!Y124 -> 48.554282 | Z6: =+AA6 -> 54.605246 | AA6: =+'Income & Cash Flow'!AA124 -> 54.605246 | AB6: =+'Income & Cash Flow'!AB124 -> 70.988486 | AC6: =+AD6 -> 87.542117 | AD6: =+'Income & Cash Flow'!AD124 -> 87.542117 | AE6: =+'Income & Cash Flow'!AE124 -> 114.75945 | AF6: =+AG6 -> 142.17969 | AG6: =+'Income & Cash Flow'!AG124 -> 142.17969 | AH6: =+'Income & Cash Flow'!AH124 -> 181.95419 | AI6: =+AJ6 -> 220.82849 | AJ6: =+'Income & Cash Flow'!AJ124 -> 220.82849 | AK6: =+'Income & Cash Flow'!AK124 -> 269.33614 | AL6: =+AM6 -> 315.88515 | AM6: =+'Income & Cash Flow'!AM124 -> 315.88515 | AN6: =+'Income & Cash Flow'!AN124 -> 374.18708 | AO6: =+AP6 -> 430.83343 | AP6: =+'Income & Cash Flow'!AP124 -> 430.83343 | AQ6: =+'Income & Cash Flow'!AQ124 -> 500.49796 | AR6: =+AS6 -> 568.15921 | AS6: =+'Income & Cash Flow'!AS124 -> 568.15921 | AT6: =+'Income & Cash Flow'!AT124 -> 650.1915 | AU6: =+AV6 -> 729.85629 | AV6: =+'Income & Cash Flow'!AV124 -> 729.85629 | AW6: =+'Income & Cash Flow'!AW124 -> 825.33689 | AX6: =+AY6 -> 918.06813 | AY6: =+'Income & Cash Flow'!AY124 -> 918.06813
B7: Receivables | I7: 4.993 | L7: 16.352 | O7: 23.947 | P7: 21.198 | Q7: =+R7 -> 26.02 | R7: 26.02 | S7: 18.852 | T7: =+U7 -> 24.703 | U7: 24.703 | V7: =+V79 -> 30.056948 | W7: =+X7 -> 30.530703 | X7: =+X79 -> 30.530703 | Y7: =+Y79 -> 35.880664 | Z7: =+AA7 -> 36.366779 | AA7: =+AA79 -> 36.366779 | AB7: =+AB79 -> 42.29088 | AC7: =+AD7 -> 42.699203 | AD7: =+AD79 -> 42.699203 | AE7: =+AE79 -> 48.585046 | AF7: =+AG7 -> 48.940995 | AG7: =+AG79 -> 48.940995 | AH7: =+AH79 -> 55.32315 | AI7: =+AJ7 -> 55.520988 | AJ7: =+AJ79 -> 55.520988 | AK7: =+AK79 -> 62.307826 | AL7: =+AM7 -> 62.432011 | AM7: =+AM79 -> 62.432011 | AN7: =+AN79 -> 69.742683 | AO7: =+AP7 -> 69.787763 | AP7: =+AP79 -> 69.787763 | AQ7: =+AQ79 -> 77.653388 | AR7: =+AS7 -> 77.61358 | AS7: =+AS79 -> 77.61358 | AT7: =+AT79 -> 86.066934 | AU7: =+AV7 -> 85.936118 | AV7: =+AV79 -> 85.936118 | AW7: =+AW79 -> 95.011735 | AX7: =+AY7 -> 94.783448 | AY7: =+AY79 -> 94.783448
B8: Inventories | I8: 1.652 | L8: 1.987 | O8: 2.153 | P8: 3.171 | Q8: =+R8 -> 2.825 | R8: 2.825 | S8: 4.249 | T8: =+U8 -> 3.761 | U8: 3.761 | V8: =+V83 -> 4.5761317 | W8: =+X8 -> 4.6482604 | X8: =+X83 -> 4.6482604 | Y8: =+Y83 -> 5.462785 | Z8: =+AA8 -> 5.5367953 | AA8: =+AA83 -> 5.5367953 | AB8: =+AB83 -> 6.4387322 | AC8: =+AD8 -> 6.5008987 | AD8: =+AD83 -> 6.5008987 | AE8: =+AE83 -> 7.3970108 | AF8: =+AG8 -> 7.4512036 | AG8: =+AG83 -> 7.4512036 | AH8: =+AH83 -> 8.4228785 | AI8: =+AJ8 -> 8.452999 | AJ8: =+AJ83 -> 8.452999 | AK8: =+AK83 -> 9.4862865 | AL8: =+AM8 -> 9.5051934 | AM8: =+AM83 -> 9.5051934 | AN8: =+AN83 -> 10.618234 | AO8: =+AP8 -> 10.625097 | AP8: =+AP83 -> 10.625097 | AQ8: =+AQ83 -> 11.822629 | AR8: =+AS8 -> 11.816568 | AS8: =+AS83 -> 11.816568 | AT8: =+AT83 -> 13.10358 | AU8: =+AV8 -> 13.083664 | AV8: =+AV83 -> 13.083664 | AW8: =+AW83 -> 14.465415 | AX8: =+AY8 -> 14.430658 | AY8: =+AY83 -> 14.430658
B9: Finance lease receivable | I9: 10.731 | L9: 10.898 | O9: 10.772 | P9: 10.514 | Q9: =R9 -> 11.999 | R9: 11.999 | S9: 12.25 | T9: =U9 -> 12.497 | U9: 12.497 | V9: =+U9 -> 12.497 | W9: =+X9 -> 12.497 | X9: =+V9 -> 12.497 | Y9: =+X9 -> 12.497 | Z9: =+AA9 -> 12.497 | AA9: =+Y9 -> 12.497 | AB9: =+AA9 -> 12.497 | AC9: =+AD9 -> 12.497 | AD9: =+AB9 -> 12.497 | AE9: =+AD9 -> 12.497 | AF9: =+AG9 -> 12.497 | AG9: =+AE9 -> 12.497 | AH9: =+AG9 -> 12.497 | AI9: =+AJ9 -> 12.497 | AJ9: =+AH9 -> 12.497 | AK9: =+AJ9 -> 12.497 | AL9: =+AM9 -> 12.497 | AM9: =+AK9 -> 12.497 | AN9: =+AM9 -> 12.497 | AO9: =+AP9 -> 12.497 | AP9: =+AN9 -> 12.497 | AQ9: =+AP9 -> 12.497 | AR9: =+AS9 -> 12.497 | AS9: =+AQ9 -> 12.497 | AT9: =+AS9 -> 12.497 | AU9: =+AV9 -> 12.497 | AV9: =+AT9 -> 12.497 | AW9: =+AV9 -> 12.497 | AX9: =+AY9 -> 12.497 | AY9: =+AW9 -> 12.497
