Workbook
Name africa: 0
Name africaCountries: #REF!
Name allRegions: #REF!
Name americaRegion: #REF!
Name americas: 0
Name americasStates: #REF!
Name AppVersion: "GEG-1.0"
Name asiaPacific: 1
Name asiaPacificExJapan: 1
Name asiaPacificExJapanCountries: #REF!
Name asiaPacificRegion: #REF!
Name asiaPacificStates: #REF!
Name ASSNet: CFS!ASSNet
Name ASSNet: Content!ASSNet
Name ASSNet: Drivers!ASSNet
Name ASSNet: 'P&L'!ASSNet
Name ASSNet: Summary!ASSNet
Name ASSNet: CFS!ASSNet
Name ASSOPS: CFS!ASSOPS
Name ASSOPS: Content!ASSOPS
Name ASSOPS: Drivers!ASSOPS
Name ASSOPS: 'P&L'!ASSOPS
Name ASSOPS: Summary!ASSOPS
Name ASSOPS: CFS!ASSOPS
Name ASX: CFS!ASX
Name ASX: Content!ASX
Name ASX: Drivers!ASX
Name ASX: 'P&L'!ASX
Name ASX: Summary!ASX
Name ASX: CFS!ASX
Name australasia: 1
Name BaseYear: "2005"
Name BRICS: 0
Name CapTO: OFFSET('P&L'!_1088__FDSAUDITLINK__,6,0)
Name CapTO: OFFSET(Drivers!XRange2,6,0)
Name CapTO: OFFSET([0]!_1089__FDSAUDITLINK__,6,0)
Name CapTO: OFFSET([0]!XRange2,6,0)
Name CapTO: OFFSET(CFS!_109__FDSAUDITLINK__,6,0)
Name CashTax: OFFSET('P&L'!_1088__FDSAUDITLINK__,7,0)
Name CashTax: OFFSET(Drivers!XRange2,7,0)
Name CashTax: OFFSET([0]!_1089__FDSAUDITLINK__,7,0)
Name CashTax: OFFSET([0]!XRange2,7,0)
Name CashTax: OFFSET(CFS!_109__FDSAUDITLINK__,7,0)
Name centralEasternEurope: 0
Name centralEasternEuropeCountries: #REF!
Name china: 0
Name Consol: CFS!Consol
Name Consol: Content!Consol
Name Consol: Drivers!Consol
Name Consol: 'P&L'!Consol
Name Consol: Summary!Consol
Name Consol: CFS!Consol
Name consumerDemandExposure: #REF!
Name consumersExposure: 0.95
Name countryList: "Country Mapping"
Name DB: "WIREAUPROD"
Name developedEuropeExUK: 0
Name developedEuropeExUKCountries: #REF!
Name DocType: Word
Name DocType: Word

Sheet CircularReferenceAlert
B2: This workbook contains formulas which intentionally use circular reference calculation. These calculations can be resolved as intended by the originating analyst by applying the following settings in the File >> Options >> Formulas:
B5: 1) Select the Enable iterative calculation check box
B6: 2) Set Maximum Iterations = 100
B7: 3) Set Maximum Change = 0.001
B9: Failure to apply these settings can result in incorrect calculation or unexpected termination of your Microsoft Excel session.

Sheet ImportantDisclosures
A2: 1 Austin Road West
A3: Kowloon
A4: Hong Kong
A5: Tel: +852 2848 5200
A7: Authors: Melinda Baxter,Mac Ross
A8: Date: 17 Feb 2026
A10: Ticker: JBH.AX
A11: Stock Rating: Underweight
A12: Industry: Australia Consumer
A13: Industry View: In-Line
A14: Price as of 17 Feb 2026: 88.58
A15: Target Price: 75.40
... A127: Equal-weight and Not-Rated to hold and Underweight to sell recommendations, respectively.
B129: Coverage Universe | D129: Investment Banking Clients (IBC) | G129: Other Material Investment Services Clients (MISC)
A130: Stock Rating Category | B130: Count | C130: % of Total | D130: Count | E130: % of Total IBC | F130: % of Rating Category | G130: Count | H130: % of Total Other MISC
A131: Overweight/Buy | B131: 1520 | C131: 0.41 | D131: 425 | E131: 0.48 | F131: 0.28 | G131: 685 | H131: 0.42
A132: Equal-weight/Hold | B132: 1579 | C132: 0.43 | D132: 375 | E132: 0.42 | F132: 0.24 | G132: 713 | H132: 0.44
A133: Not-Rated/Hold | B133: 4 | C133: 0 | D133: 1 | E133: 0 | F133: 0.25 | G133: 1 | H133: 0
A134: Underweight/Sell | B134: 592 | C134: 0.16 | D134: 89 | E134: 0.1 | F134: 0.15 | G134: 232 | H134: 0.14
A135: Total | B135: 3695 | D135: 890 | G135: 1631
A137: Data include common stock and ADRs currently assigned ratings. Investment Banking Clients are companies
A138: from whom Morgan Stanley received investment banking compensation in the last 12 months. Due to rounding
A139: off of decimals, the percentages provided in the "% of total" column may not add up to exactly 100
A140: percent.
A142: Analyst Stock Ratings
A144: Overweight (O). The stock's total return is expected to exceed the average total return of the analyst's
A145: industry (or industry team's) coverage universe, on a risk-adjusted basis, over the next 12-18 months.
A147: Equal-weight (E). The stock's total return is expected to be in line with the average total return of
A148: the analyst's industry (or industry team's) coverage universe, on a risk-adjusted basis, over the next
A149: 12-18 months.
A151: Not-Rated (NR). Currently the analyst does not have adequate conviction about the stock's total return
A152: relative to the average total return of the analyst's industry (or industry team's) coverage universe,
... A433: © Copyright 2026 Morgan Stanley

Sheet Content
B1: JBH Model | C1: Australian Consumer Team
C4: Melinda Baxter | D4: +61 2 97701176
C5: melinda.baxter@morganstanley.com
C7: Mac Ross | D7: +61 2 9770 1579
C8: mac.ross@morganstanley.com
C10: Julia de Sterke | D10: +61 2 9770 1658
C11: julia.de.sterke@morganstanley.com

Sheet Summary
D1: FY13 | E1: FY14 | F1: FY15 | G1: FY16 | H1: FY17 | I1: FY18 | J1: FY19 | K1: FY20 | L1: FY21 | M1: FY22 | N1: FY23 | O1: FY24 | P1: FY25 | Q1: FY26e | R1: FY27e | S1: FY28e | W1: FY13 | X1: FY14 | Y1: FY15 | Z1: FY16 | AA1: FY17 | AB1: FY18 | AC1: FY19 | AD1: FY20 | AE1: FY21 | AF1: FY22 | AG1: FY23 | AH1: FY24 | AI1: FY25 | AJ1: FY26e | AK1: FY27e | AL1: FY28e
B4: Financial Summary | M4: Last | N4: 88.1 | O4: PT | P4: 75.4 | U4: Diff to PT | AD4: =P4/N4-1 -> -0.14415437
B7: P&L | D7: 2013a | E7: 2014a | F7: 2015a | G7: 2016a | H7: 2017a | I7: 2018a | J7: 2019a | K7: 2020a | L7: 2021a | M7: 2022a | N7: 2023a | O7: 2024a | P7: 2025a | Q7: 2026e | R7: 2027e | S7: 2028e | U7: Balance Sheet | W7: =+D7 -> 2013a | X7: =+E7 -> 2014a | Y7: =+F7 -> 2015a | Z7: =+G7 -> 2016a | AA7: =+H7 -> 2017a | AB7: =+I7 -> 2018a | AC7: =+J7 -> 2019a | AD7: =+K7 -> 2020a | ... AI7: =+P7 -> 2025a | AJ7: 2026 | AK7: 2027e | AL7: 2028e
A8: JBH_Sales | B8: Revenue | C8: A$m | D8: =VLOOKUP($A$8,'P&L'!$1:$1048576,MATCH(D1,'P&L'!$4:$4,FALSE),FALSE) -> 3308.4 | E8: =VLOOKUP($A$8,'P&L'!1:1048576,MATCH(E1,'P&L'!4:4,FALSE),FALSE) -> 3483.775 | F8: =VLOOKUP($A$8,'P&L'!1:1048576,MATCH(F1,'P&L'!4:4,FALSE),FALSE) -> 3652.136 | G8: =VLOOKUP($A$8,'P&L'!1:1048576,MATCH(G1,'P&L'!4:4,FALSE),FALSE) -> 3954.467 | H8: =VLOOKUP($A$8,'P&L'!1:1048576,MATCH(H1,'P&L'!4:4,FALSE),FALSE) -> 5628 | I8: =VLOOKUP($A$8,'P&L'!1:1048576,MATCH(I1,'P&L'!4:4,FALSE),FALSE) -> 6854.3 | J8: =VLOOKUP($A$8,'P&L'!1:1048576,MATCH(J1,'P&L'!4:4,FALSE),FALSE) -> 7095.3 | K8: =VLOOKUP($A$8,'P&L'!1:1048576,MATCH(K1,'P&L'!4:4,FALSE),FALSE) -> 7918.9 | L8: =VLOOKUP($A$8,'P&L'!1:1048576,MATCH(L1,'P&L'!4:4,FALSE),FALSE) -> 8916.1 | ... S8: =VLOOKUP($A$8,'P&L'!1:1048576,MATCH(S1,'P&L'!4:4,FALSE),FALSE) -> 12107.395 | U8: Current assets | V8: A$m | W8: =VLOOKUP($AM$8,BS!1:1048576,MATCH(1:1,BS!4:4,FALSE),FALSE) -> 563.652 | X8: =VLOOKUP($AM$8,BS!1:1048576,MATCH(1:1,BS!4:4,FALSE),FALSE) -> 578.147 | Y8: =VLOOKUP($AM$8,BS!1:1048576,MATCH(1:1,BS!4:4,FALSE),FALSE) -> 616.898 | Z8: =VLOOKUP($AM$8,BS!1:1048576,MATCH(1:1,BS!4:4,FALSE),FALSE) -> 702.518 | AA8: =VLOOKUP($AM$8,BS!1:1048576,MATCH(1:1,BS!4:4,FALSE),FALSE) -> 1170.7 | AB8: =VLOOKUP($AM$8,BS!1:1048576,MATCH(1:1,BS!4:4,FALSE),FALSE) -> 1210.5 | AC8: =VLOOKUP($AM$8,BS!1:1048576,MATCH(1:1,BS!4:4,FALSE),FALSE) -> 1294.9 | AD8: =VLOOKUP($AM$8,BS!1:1048576,MATCH(1:1,BS!4:4,FALSE),FALSE) -> 1245.8 | ... AL8: =VLOOKUP($AM$8,BS!1:1048576,MATCH(1:1,BS!4:4,FALSE),FALSE) -> 2137.6458 | AM8: CA
A9: JBH_Sales_AUS | B9: JBH - Aus | C9: A$m | D9: =VLOOKUP($A$9,Drivers!$1:$1048576,MATCH(D1,Drivers!$2:$2,FALSE),FALSE) -> 3140.817 | E9: =VLOOKUP($A$9,Drivers!$1:$1048576,MATCH(E1,Drivers!$2:$2,FALSE),FALSE) -> 3292.848 | F9: =VLOOKUP($A$9,Drivers!$1:$1048576,MATCH(F1,Drivers!$2:$2,FALSE),FALSE) -> 3456.016 | G9: =VLOOKUP($A$9,Drivers!$1:$1048576,MATCH(G1,Drivers!$2:$2,FALSE),FALSE) -> 3739.358 | H9: =VLOOKUP($A$9,Drivers!$1:$1048576,MATCH(H1,Drivers!$2:$2,FALSE),FALSE) -> 4148.6 | I9: =VLOOKUP($A$9,Drivers!$1:$1048576,MATCH(I1,Drivers!$2:$2,FALSE),FALSE) -> 4539.7 | J9: =VLOOKUP($A$9,Drivers!$1:$1048576,MATCH(J1,Drivers!$2:$2,FALSE),FALSE) -> 4726 | K9: =VLOOKUP($A$9,Drivers!$1:$1048576,MATCH(K1,Drivers!$2:$2,FALSE),FALSE) -> 5318.9 | ... S9: =VLOOKUP($A$9,Drivers!$1:$1048576,MATCH(S1,Drivers!$2:$2,FALSE),FALSE) -> 8157.1784 | U9: Net plant & equipment | V9: A$m | W9: =VLOOKUP($AM$9,BS!1:1048576,MATCH(1:1,BS!4:4,FALSE),FALSE) -> 181.098 | X9: =VLOOKUP($AM$9,BS!1:1048576,MATCH(1:1,BS!4:4,FALSE),FALSE) -> 181.564 | Y9: =VLOOKUP($AM$9,BS!1:1048576,MATCH(1:1,BS!4:4,FALSE),FALSE) -> 176.208 | Z9: =VLOOKUP($AM$9,BS!1:1048576,MATCH(1:1,BS!4:4,FALSE),FALSE) -> 183.57 | AA9: =VLOOKUP($AM$9,BS!1:1048576,MATCH(1:1,BS!4:4,FALSE),FALSE) -> 208.2 | AB9: =VLOOKUP($AM$9,BS!1:1048576,MATCH(1:1,BS!4:4,FALSE),FALSE) -> 198 | AC9: =VLOOKUP($AM$9,BS!1:1048576,MATCH(1:1,BS!4:4,FALSE),FALSE) -> 191.5 | AD9: =VLOOKUP($AM$9,BS!1:1048576,MATCH(1:1,BS!4:4,FALSE),FALSE) -> 172.3 | ... AL9: =VLOOKUP($AM$9,BS!1:1048576,MATCH(1:1,BS!4:4,FALSE),FALSE) -> 279.29574 | AM9: PPE
A10: JBH_Sales_NZ_AUD | B10: JBH - NZ (A$m) | C10: A$m | D10: =VLOOKUP($A$10,Drivers!$1:$1048576,MATCH(D1,Drivers!$2:$2,FALSE),FALSE) -> 167.583 | E10: =VLOOKUP($A$10,Drivers!$1:$1048576,MATCH(E1,Drivers!$2:$2,FALSE),FALSE) -> 190.927 | F10: =VLOOKUP($A$10,Drivers!$1:$1048576,MATCH(F1,Drivers!$2:$2,FALSE),FALSE) -> 196.12 | G10: =VLOOKUP($A$10,Drivers!$1:$1048576,MATCH(G1,Drivers!$2:$2,FALSE),FALSE) -> 215.109 | H10: =VLOOKUP($A$10,Drivers!$1:$1048576,MATCH(H1,Drivers!$2:$2,FALSE),FALSE) -> 221 | I10: =VLOOKUP($A$10,Drivers!$1:$1048576,MATCH(I1,Drivers!$2:$2,FALSE),FALSE) -> 213.3 | J10: =VLOOKUP($A$10,Drivers!$1:$1048576,MATCH(J1,Drivers!$2:$2,FALSE),FALSE) -> 221.4 | K10: =VLOOKUP($A$10,Drivers!$1:$1048576,MATCH(K1,Drivers!$2:$2,FALSE),FALSE) -> 211.2 | ... S10: =VLOOKUP($A$10,Drivers!$1:$1048576,MATCH(S1,Drivers!$2:$2,FALSE),FALSE) -> 500.40116 | U10: Net intangibles | V10: A$m | W10: =VLOOKUP($AM$10,BS!1:1048576,MATCH(1:1,BS!4:4,FALSE),FALSE) -> 83.712 | X10: =VLOOKUP($AM$10,BS!1:1048576,MATCH(1:1,BS!4:4,FALSE),FALSE) -> 85.218 | Y10: =VLOOKUP($AM$10,BS!1:1048576,MATCH(1:1,BS!4:4,FALSE),FALSE) -> 84.541 | Z10: =VLOOKUP($AM$10,BS!1:1048576,MATCH(1:1,BS!4:4,FALSE),FALSE) -> 85.59 | AA10: =VLOOKUP($AM$10,BS!1:1048576,MATCH(1:1,BS!4:4,FALSE),FALSE) -> 1026.6 | AB10: =VLOOKUP($AM$10,BS!1:1048576,MATCH(1:1,BS!4:4,FALSE),FALSE) -> 1037.3 | AC10: =VLOOKUP($AM$10,BS!1:1048576,MATCH(1:1,BS!4:4,FALSE),FALSE) -> 1037.3 | AD10: =VLOOKUP($AM$10,BS!1:1048576,MATCH(1:1,BS!4:4,FALSE),FALSE) -> 1031.4 | ... AL10: =VLOOKUP($AM$10,BS!1:1048576,MATCH(1:1,BS!4:4,FALSE),FALSE) -> 1080.7 | AM10: INTANG
A11: TGG_SEG_SALES | B11: The Good Guys | C11: A$m | H11: =VLOOKUP($A$11,Drivers!$1:$1048576,MATCH(H1,Drivers!$2:$2,FALSE),FALSE) -> 1258.4 | I11: =VLOOKUP($A$11,Drivers!$1:$1048576,MATCH(I1,Drivers!$2:$2,FALSE),FALSE) -> 2101.3 | J11: =VLOOKUP($A$11,Drivers!$1:$1048576,MATCH(J1,Drivers!$2:$2,FALSE),FALSE) -> 2147.9 | K11: =VLOOKUP($A$11,Drivers!$1:$1048576,MATCH(K1,Drivers!$2:$2,FALSE),FALSE) -> 2388.8 | L11: =VLOOKUP($A$11,Drivers!$1:$1048576,MATCH(L1,Drivers!$2:$2,FALSE),FALSE) -> 2715.7 | M11: =VLOOKUP($A$11,Drivers!$1:$1048576,MATCH(M1,Drivers!$2:$2,FALSE),FALSE) -> 2789.4 | N11: =VLOOKUP($A$11,Drivers!$1:$1048576,MATCH(N1,Drivers!$2:$2,FALSE),FALSE) -> 2813 | O11: =VLOOKUP($A$11,Drivers!$1:$1048576,MATCH(O1,Drivers!$2:$2,FALSE),FALSE) -> 2679.1 | ... S11: =VLOOKUP($A$11,Drivers!$1:$1048576,MATCH(S1,Drivers!$2:$2,FALSE),FALSE) -> 3157.1451 | U11: Other non current assets | V11: A$m | W11: =W12-SUM(W8:W10) -> 14.842 | X11: =X12-SUM(X8:X10) -> 14.912 | Y11: =Y12-SUM(Y8:Y10) -> 17.366 | Z11: =Z12-SUM(Z8:Z10) -> 20.703 | AA11: =AA12-SUM(AA8:AA10) -> 46.8 | AB11: =AB12-SUM(AB8:AB10) -> 45.9 | AC11: =AC12-SUM(AC8:AC10) -> 43.5 | AD11: =AD12-SUM(AD8:AD10) -> 702.8 | ... AL11: =AL12-SUM(AL8:AL10) -> 824.9785
A12: EBITDA | B12: EBITDA | C12: A$m | D12: =VLOOKUP($A$12,'P&L'!1:1048576,MATCH(D1,'P&L'!4:4,FALSE),FALSE) -> 210.985 | E12: =VLOOKUP($A$12,'P&L'!1:1048576,MATCH(E1,'P&L'!4:4,FALSE),FALSE) -> 226.65 | F12: =VLOOKUP($A$12,'P&L'!1:1048576,MATCH(F1,'P&L'!4:4,FALSE),FALSE) -> 240.031 | G12: =VLOOKUP($A$12,'P&L'!1:1048576,MATCH(G1,'P&L'!4:4,FALSE),FALSE) -> 262.076 | H12: =VLOOKUP($A$12,'P&L'!1:1048576,MATCH(H1,'P&L'!4:4,FALSE),FALSE) -> 360.3 | I12: =VLOOKUP($A$12,'P&L'!1:1048576,MATCH(I1,'P&L'!4:4,FALSE),FALSE) -> 411.7 | J12: =VLOOKUP($A$12,'P&L'!1:1048576,MATCH(J1,'P&L'!4:4,FALSE),FALSE) -> 429.1 | K12: =VLOOKUP($A$12,'P&L'!1:1048576,MATCH(K1,'P&L'!4:4,FALSE),FALSE) -> 717.9 | ... S12: =VLOOKUP($A$12,'P&L'!1:1048576,MATCH(S1,'P&L'!4:4,FALSE),FALSE) -> 1088.2741 | U12: Total assets | V12: A$m | W12: =VLOOKUP($AM$12,BS!1:1048576,MATCH(1:1,BS!4:4,FALSE),FALSE) -> 843.304 | X12: =VLOOKUP($AM$12,BS!1:1048576,MATCH(1:1,BS!4:4,FALSE),FALSE) -> 859.841 | Y12: =VLOOKUP($AM$12,BS!1:1048576,MATCH(1:1,BS!4:4,FALSE),FALSE) -> 895.013 | Z12: =VLOOKUP($AM$12,BS!1:1048576,MATCH(1:1,BS!4:4,FALSE),FALSE) -> 992.381 | AA12: =VLOOKUP($AM$12,BS!1:1048576,MATCH(1:1,BS!4:4,FALSE),FALSE) -> 2452.3 | AB12: =VLOOKUP($AM$12,BS!1:1048576,MATCH(1:1,BS!4:4,FALSE),FALSE) -> 2491.7 | AC12: =VLOOKUP($AM$12,BS!1:1048576,MATCH(1:1,BS!4:4,FALSE),FALSE) -> 2567.2 | AD12: =VLOOKUP($AM$12,BS!1:1048576,MATCH(1:1,BS!4:4,FALSE),FALSE) -> 3152.3 | ... AL12: =VLOOKUP($AM$12,BS!1:1048576,MATCH(1:1,BS!4:4,FALSE),FALSE) -> 4322.6201 | AM12: TA
A13: TOTAL_D&A | B13: D&A | C13: A$m | D13: =VLOOKUP($A$13,'P&L'!1:1048576,MATCH(D1,'P&L'!4:4,FALSE),FALSE) -> -33.232 | E13: =VLOOKUP($A$13,'P&L'!1:1048576,MATCH(E1,'P&L'!4:4,FALSE),FALSE) -> -35.53 | F13: =VLOOKUP($A$13,'P&L'!1:1048576,MATCH(F1,'P&L'!4:4,FALSE),FALSE) -> -39.124 | G13: =VLOOKUP($A$13,'P&L'!1:1048576,MATCH(G1,'P&L'!4:4,FALSE),FALSE) -> -40.901 | H13: =VLOOKUP($A$13,'P&L'!1:1048576,MATCH(H1,'P&L'!4:4,FALSE),FALSE) -> -53.9 | I13: =VLOOKUP($A$13,'P&L'!1:1048576,MATCH(I1,'P&L'!4:4,FALSE),FALSE) -> -61.1 | J13: =VLOOKUP($A$13,'P&L'!1:1048576,MATCH(J1,'P&L'!4:4,FALSE),FALSE) -> -56.2 | K13: =VLOOKUP($A$13,'P&L'!1:1048576,MATCH(K1,'P&L'!4:4,FALSE),FALSE) -> -229.3 | ... S13: =VLOOKUP($A$13,'P&L'!1:1048576,MATCH(S1,'P&L'!4:4,FALSE),FALSE) -> -282.25135 | U13: Current liabilities | V13: A$m | W13: =VLOOKUP($AM$13,BS!1:1048576,MATCH(Summary!1:1,BS!4:4,FALSE),FALSE) -> 442.379 | X13: =VLOOKUP($AM$13,BS!1:1048576,MATCH(Summary!1:1,BS!4:4,FALSE),FALSE) -> 352.193 | Y13: =VLOOKUP($AM$13,BS!1:1048576,MATCH(Summary!1:1,BS!4:4,FALSE),FALSE) -> 380.336 | Z13: =VLOOKUP($AM$13,BS!1:1048576,MATCH(Summary!1:1,BS!4:4,FALSE),FALSE) -> 446.833 | AA13: =VLOOKUP($AM$13,BS!1:1048576,MATCH(Summary!1:1,BS!4:4,FALSE),FALSE) -> 885.8 | AB13: =VLOOKUP($AM$13,BS!1:1048576,MATCH(Summary!1:1,BS!4:4,FALSE),FALSE) -> 917.2 | AC13: =VLOOKUP($AM$13,BS!1:1048576,MATCH(Summary!1:1,BS!4:4,FALSE),FALSE) -> 945.5 | AD13: =VLOOKUP($AM$13,BS!1:1048576,MATCH(Summary!1:1,BS!4:4,FALSE),FALSE) -> 1345.9 | ... AL13: =VLOOKUP($AM$13,BS!1:1048576,MATCH(Summary!1:1,BS!4:4,FALSE),FALSE) -> 1695.7108 | AM13: CL
A14: JBH_AUS_EBIT | B14: JBH - Aus | C14: A$m | D14: =VLOOKUP($A$14,Drivers!$1:$1048576,MATCH(D1,Drivers!$2:$2,FALSE),FALSE) -> 175.853 | E14: =VLOOKUP($A$14,Drivers!$1:$1048576,MATCH(E1,Drivers!$2:$2,FALSE),FALSE) -> 188.32 | F14: =VLOOKUP($A$14,Drivers!$1:$1048576,MATCH(F1,Drivers!$2:$2,FALSE),FALSE) -> 199.447 | G14: =VLOOKUP($A$14,Drivers!$1:$1048576,MATCH(G1,Drivers!$2:$2,FALSE),FALSE) -> 220.315 | H14: =VLOOKUP($A$14,Drivers!$1:$1048576,MATCH(H1,Drivers!$2:$2,FALSE),FALSE) -> 262.4 | I14: =VLOOKUP($A$14,Drivers!$1:$1048576,MATCH(I1,Drivers!$2:$2,FALSE),FALSE) -> 292.3 | J14: =VLOOKUP($A$14,Drivers!$1:$1048576,MATCH(J1,Drivers!$2:$2,FALSE),FALSE) -> 301.7 | K14: =VLOOKUP($A$14,Drivers!$1:$1048576,MATCH(K1,Drivers!$2:$2,FALSE),FALSE) -> 391.6 | ... S14: =VLOOKUP($A$14,Drivers!$1:$1048576,MATCH(S1,Drivers!$2:$2,FALSE),FALSE) -> 601.24959 | U14: Borrowings | V14: A$m | W14: =VLOOKUP($AM$14,BS!1:1048576,MATCH(Summary!1:1,BS!4:4,FALSE),FALSE) -> 124.331 | X14: =VLOOKUP($AM$14,BS!1:1048576,MATCH(Summary!1:1,BS!4:4,FALSE),FALSE) -> 179.653 | Y14: =VLOOKUP($AM$14,BS!1:1048576,MATCH(Summary!1:1,BS!4:4,FALSE),FALSE) -> 139.461 | Z14: =VLOOKUP($AM$14,BS!1:1048576,MATCH(Summary!1:1,BS!4:4,FALSE),FALSE) -> 109.736 | AA14: =VLOOKUP($AM$14,BS!1:1048576,MATCH(Summary!1:1,BS!4:4,FALSE),FALSE) -> 558.8 | AB14: =VLOOKUP($AM$14,BS!1:1048576,MATCH(Summary!1:1,BS!4:4,FALSE),FALSE) -> 469.4 | AC14: =VLOOKUP($AM$14,BS!1:1048576,MATCH(Summary!1:1,BS!4:4,FALSE),FALSE) -> 439.1 | AD14: =VLOOKUP($AM$14,BS!1:1048576,MATCH(Summary!1:1,BS!4:4,FALSE),FALSE) -> 0 | ... AL14: =VLOOKUP($AM$14,BS!1:1048576,MATCH(Summary!1:1,BS!4:4,FALSE),FALSE) -> 0 | AM14: BORR
A15: JBH_NZ_EBIT | B15: JBH - NZ (A$m) | C15: A$m | D15: =VLOOKUP($A$15,Drivers!$1:$1048576,MATCH(D1,Drivers!$2:$2,FALSE),FALSE) -> 1.9 | E15: =VLOOKUP($A$15,Drivers!$1:$1048576,MATCH(E1,Drivers!$2:$2,FALSE),FALSE) -> 2.8 | F15: =VLOOKUP($A$15,Drivers!$1:$1048576,MATCH(F1,Drivers!$2:$2,FALSE),FALSE) -> 1.46 | G15: =VLOOKUP($A$15,Drivers!$1:$1048576,MATCH(G1,Drivers!$2:$2,FALSE),FALSE) -> 0.9 | H15: =VLOOKUP($A$15,Drivers!$1:$1048576,MATCH(H1,Drivers!$2:$2,FALSE),FALSE) -> -2.5 | I15: =VLOOKUP($A$15,Drivers!$1:$1048576,MATCH(I1,Drivers!$2:$2,FALSE),FALSE) -> -2.6 | J15: =VLOOKUP($A$15,Drivers!$1:$1048576,MATCH(J1,Drivers!$2:$2,FALSE),FALSE) -> -1.7 | K15: =VLOOKUP($A$15,Drivers!$1:$1048576,MATCH(K1,Drivers!$2:$2,FALSE),FALSE) -> -1.4 | ... S15: =VLOOKUP($A$15,Drivers!$1:$1048576,MATCH(S1,Drivers!$2:$2,FALSE),FALSE) -> 8.6730217 | U15: Other non current liabilities | V15: A$m | W15: =W16-SUM(W13:W14) -> 32.766 | X15: =X16-SUM(X13:X14) -> 33.362 | Y15: =Y16-SUM(Y13:Y14) -> 31.737 | Z15: =Z16-SUM(Z13:Z14) -> 31.11 | AA15: =AA16-SUM(AA13:AA14) -> 154.2 | AB15: =AB16-SUM(AB13:AB14) -> 157.5 | AC15: =AC16-SUM(AC13:AC14) -> 138.5 | AD15: =AD16-SUM(AD13:AD14) -> 700.7 | ... AL15: =AL16-SUM(AL13:AL14) -> 718.1
A16: TGG_SEG_EBIT | B16: The Good Guys | C16: A$m | H16: =VLOOKUP($A$16,Drivers!$1:$1048576,MATCH(H1,Drivers!$2:$2,FALSE),FALSE) -> 46.4 | I16: =VLOOKUP($A$16,Drivers!$1:$1048576,MATCH(I1,Drivers!$2:$2,FALSE),FALSE) -> 60.9 | J16: =VLOOKUP($A$16,Drivers!$1:$1048576,MATCH(J1,Drivers!$2:$2,FALSE),FALSE) -> 72.9 | K16: =VLOOKUP($A$16,Drivers!$1:$1048576,MATCH(K1,Drivers!$2:$2,FALSE),FALSE) -> 112.8 | L16: =VLOOKUP($A$16,Drivers!$1:$1048576,MATCH(L1,Drivers!$2:$2,FALSE),FALSE) -> 214.7 | M16: =VLOOKUP($A$16,Drivers!$1:$1048576,MATCH(M1,Drivers!$2:$2,FALSE),FALSE) -> 241.4 | N16: =VLOOKUP($A$16,Drivers!$1:$1048576,MATCH(N1,Drivers!$2:$2,FALSE),FALSE) -> 213 | O16: =VLOOKUP($A$16,Drivers!$1:$1048576,MATCH(O1,Drivers!$2:$2,FALSE),FALSE) -> 158.1 | ... S16: =VLOOKUP($A$16,Drivers!$1:$1048576,MATCH(S1,Drivers!$2:$2,FALSE),FALSE) -> 192.66406 | U16: Total liabilities | V16: A$m | W16: =VLOOKUP($AM$16,BS!1:1048576,MATCH(Summary!1:1,BS!4:4,FALSE),FALSE) -> 599.476 | X16: =VLOOKUP($AM$16,BS!1:1048576,MATCH(Summary!1:1,BS!4:4,FALSE),FALSE) -> 565.208 | Y16: =VLOOKUP($AM$16,BS!1:1048576,MATCH(Summary!1:1,BS!4:4,FALSE),FALSE) -> 551.534 | Z16: =VLOOKUP($AM$16,BS!1:1048576,MATCH(Summary!1:1,BS!4:4,FALSE),FALSE) -> 587.679 | AA16: =VLOOKUP($AM$16,BS!1:1048576,MATCH(Summary!1:1,BS!4:4,FALSE),FALSE) -> 1598.8 | AB16: =VLOOKUP($AM$16,BS!1:1048576,MATCH(Summary!1:1,BS!4:4,FALSE),FALSE) -> 1544.1 | AC16: =VLOOKUP($AM$16,BS!1:1048576,MATCH(Summary!1:1,BS!4:4,FALSE),FALSE) -> 1523.1 | AD16: =VLOOKUP($AM$16,BS!1:1048576,MATCH(Summary!1:1,BS!4:4,FALSE),FALSE) -> 2046.6 | ... AL16: =VLOOKUP($AM$16,BS!1:1048576,MATCH(Summary!1:1,BS!4:4,FALSE),FALSE) -> 2413.8108 | AM16: TL
A17: EBIT_NORM | B17: EBIT | C17: A$m | D17: =VLOOKUP($A$17,'P&L'!1:1048576,MATCH(D1,'P&L'!4:4,FALSE),FALSE) -> 177.753 | E17: =VLOOKUP($A$17,'P&L'!1:1048576,MATCH(E1,'P&L'!4:4,FALSE),FALSE) -> 191.12 | F17: =VLOOKUP($A$17,'P&L'!1:1048576,MATCH(F1,'P&L'!4:4,FALSE),FALSE) -> 200.907 | G17: =VLOOKUP($A$17,'P&L'!1:1048576,MATCH(G1,'P&L'!4:4,FALSE),FALSE) -> 221.175 | H17: =VLOOKUP($A$17,'P&L'!1:1048576,MATCH(H1,'P&L'!4:4,FALSE),FALSE) -> 306.4 | I17: =VLOOKUP($A$17,'P&L'!1:1048576,MATCH(I1,'P&L'!4:4,FALSE),FALSE) -> 350.6 | J17: =VLOOKUP($A$17,'P&L'!1:1048576,MATCH(J1,'P&L'!4:4,FALSE),FALSE) -> 372.9 | K17: =VLOOKUP($A$17,'P&L'!1:1048576,MATCH(K1,'P&L'!4:4,FALSE),FALSE) -> 502.9 | ... S17: =VLOOKUP($A$17,'P&L'!1:1048576,MATCH(S1,'P&L'!4:4,FALSE),FALSE) -> 806.02273 | U17: Outside equity interests | V17: A$m | W17: =VLOOKUP($AM$17,BS!1:1048576,MATCH(1:1,BS!4:4,FALSE),FALSE) -> 0.483 | X17: =VLOOKUP($AM$17,BS!1:1048576,MATCH(1:1,BS!4:4,FALSE),FALSE) -> 0 | Y17: =VLOOKUP($AM$17,BS!1:1048576,MATCH(1:1,BS!4:4,FALSE),FALSE) -> 0 | Z17: =VLOOKUP($AM$17,BS!1:1048576,MATCH(1:1,BS!4:4,FALSE),FALSE) -> 0 | AA17: =VLOOKUP($AM$17,BS!1:1048576,MATCH(1:1,BS!4:4,FALSE),FALSE) -> 0 | AB17: =VLOOKUP($AM$17,BS!1:1048576,MATCH(1:1,BS!4:4,FALSE),FALSE) -> 0 | AC17: =VLOOKUP($AM$17,BS!1:1048576,MATCH(1:1,BS!4:4,FALSE),FALSE) -> 0 | AD17: =VLOOKUP($AM$17,BS!1:1048576,MATCH(1:1,BS!4:4,FALSE),FALSE) -> 0 | ... AL17: =VLOOKUP($AM$17,BS!1:1048576,MATCH(1:1,BS!4:4,FALSE),FALSE) -> 6.9518941 | AM17: NCI
A18: NET_INT | B18: Net Interest Expense | C18: A$m | D18: =VLOOKUP($A$18,'P&L'!1:1048576,MATCH(D1,'P&L'!4:4,FALSE),FALSE) -> -9.701 | E18: =VLOOKUP($A$18,'P&L'!1:1048576,MATCH(E1,'P&L'!4:4,FALSE),FALSE) -> -8.443 | F18: =VLOOKUP($A$18,'P&L'!1:1048576,MATCH(F1,'P&L'!4:4,FALSE),FALSE) -> -5.375 | G18: =VLOOKUP($A$18,'P&L'!1:1048576,MATCH(G1,'P&L'!4:4,FALSE),FALSE) -> -3.336 | H18: =VLOOKUP($A$18,'P&L'!1:1048576,MATCH(H1,'P&L'!4:4,FALSE),FALSE) -> -9 | I18: =VLOOKUP($A$18,'P&L'!1:1048576,MATCH(I1,'P&L'!4:4,FALSE),FALSE) -> -16.1 | J18: =VLOOKUP($A$18,'P&L'!1:1048576,MATCH(J1,'P&L'!4:4,FALSE),FALSE) -> -13.6 | K18: =VLOOKUP($A$18,'P&L'!1:1048576,MATCH(K1,'P&L'!4:4,FALSE),FALSE) -> -35.3 | ... S18: =VLOOKUP($A$18,'P&L'!1:1048576,MATCH(S1,'P&L'!4:4,FALSE),FALSE) -> -37.071549 | U18: Shareholders’ funds | V18: A$m | W18: =W12-W16-W17 -> 243.345 | X18: =X12-X16-X17 -> 294.633 | Y18: =Y12-Y16-Y17 -> 343.479 | Z18: =Z12-Z16-Z17 -> 404.702 | AA18: =AA12-AA16-AA17 -> 853.5 | AB18: =AB12-AB16-AB17 -> 947.6 | AC18: =AC12-AC16-AC17 -> 1044.1 | AD18: =AD12-AD16-AD17 -> 1105.7 | ... AL18: =AL12-AL16-AL17 -> 1901.8574
A19: PBT | B19: Profit before tax | C19: A$m | D19: =VLOOKUP($A$19,'P&L'!1:1048576,MATCH(D1,'P&L'!4:4,FALSE),FALSE) -> 168.052 | E19: =VLOOKUP($A$19,'P&L'!1:1048576,MATCH(E1,'P&L'!4:4,FALSE),FALSE) -> 182.677 | F19: =VLOOKUP($A$19,'P&L'!1:1048576,MATCH(F1,'P&L'!4:4,FALSE),FALSE) -> 195.532 | G19: =VLOOKUP($A$19,'P&L'!1:1048576,MATCH(G1,'P&L'!4:4,FALSE),FALSE) -> 217.839 | H19: =VLOOKUP($A$19,'P&L'!1:1048576,MATCH(H1,'P&L'!4:4,FALSE),FALSE) -> 259.2 | I19: =VLOOKUP($A$19,'P&L'!1:1048576,MATCH(I1,'P&L'!4:4,FALSE),FALSE) -> 334.5 | J19: =VLOOKUP($A$19,'P&L'!1:1048576,MATCH(J1,'P&L'!4:4,FALSE),FALSE) -> 359.3 | K19: =VLOOKUP($A$19,'P&L'!1:1048576,MATCH(K1,'P&L'!4:4,FALSE),FALSE) -> 447.9 | ... S19: =VLOOKUP($A$19,'P&L'!1:1048576,MATCH(S1,'P&L'!4:4,FALSE),FALSE) -> 768.95118 | U19: Net debt | V19: A$m | W19: =VLOOKUP($AM$19,BS!1:1048576,MATCH(1:1,BS!4:4,FALSE),FALSE) -> 56.963 | X19: =VLOOKUP($AM$19,BS!1:1048576,MATCH(1:1,BS!4:4,FALSE),FALSE) -> 136.208 | Y19: =VLOOKUP($AM$19,BS!1:1048576,MATCH(1:1,BS!4:4,FALSE),FALSE) -> 90.33 | Z19: =VLOOKUP($AM$19,BS!1:1048576,MATCH(1:1,BS!4:4,FALSE),FALSE) -> 57.852 | AA19: =VLOOKUP($AM$19,BS!1:1048576,MATCH(1:1,BS!4:4,FALSE),FALSE) -> 486 | AB19: =VLOOKUP($AM$19,BS!1:1048576,MATCH(1:1,BS!4:4,FALSE),FALSE) -> 397.4 | AC19: =VLOOKUP($AM$19,BS!1:1048576,MATCH(1:1,BS!4:4,FALSE),FALSE) -> 319.9 | AD19: =VLOOKUP($AM$19,BS!1:1048576,MATCH(1:1,BS!4:4,FALSE),FALSE) -> -251.5 | ... AL19: =VLOOKUP($AM$19,BS!1:1048576,MATCH(1:1,BS!4:4,FALSE),FALSE) -> -401.13494 | AM19: ND
A20: TAX | B20: Income Tax | C20: A$m | D20: =VLOOKUP($A$20,'P&L'!1:1048576,MATCH(D1,'P&L'!4:4,FALSE),FALSE) -> -51.42 | E20: =VLOOKUP($A$20,'P&L'!1:1048576,MATCH(E1,'P&L'!4:4,FALSE),FALSE) -> -54.23 | F20: =VLOOKUP($A$20,'P&L'!1:1048576,MATCH(F1,'P&L'!4:4,FALSE),FALSE) -> -59.021 | G20: =VLOOKUP($A$20,'P&L'!1:1048576,MATCH(G1,'P&L'!4:4,FALSE),FALSE) -> -65.658 | H20: =VLOOKUP($A$20,'P&L'!1:1048576,MATCH(H1,'P&L'!4:4,FALSE),FALSE) -> -86.8 | I20: =VLOOKUP($A$20,'P&L'!1:1048576,MATCH(I1,'P&L'!4:4,FALSE),FALSE) -> -101.3 | J20: =VLOOKUP($A$20,'P&L'!1:1048576,MATCH(J1,'P&L'!4:4,FALSE),FALSE) -> -109.5 | K20: =VLOOKUP($A$20,'P&L'!1:1048576,MATCH(K1,'P&L'!4:4,FALSE),FALSE) -> -145.7 | ... S20: =VLOOKUP($A$20,'P&L'!1:1048576,MATCH(S1,'P&L'!4:4,FALSE),FALSE) -> -231.46367 | U20: Capital employed | V20: A$m | W20: =W18+W19 -> 300.308 | X20: =X18+X19 -> 430.841 | Y20: =Y18+Y19 -> 433.809 | Z20: =Z18+Z19 -> 462.554 | AA20: =AA18+AA19 -> 1339.5 | AB20: =AB18+AB19 -> 1345 | AC20: =AC18+AC19 -> 1364 | AD20: =AD18+AD19 -> 854.2 | ... AL20: =AL18+AL19 -> 1500.7225
A21: NPAT | B21: NPAT before sig. items | C21: A$m | D21: =VLOOKUP($A$21,'P&L'!1:1048576,MATCH(D1,'P&L'!4:4,FALSE),FALSE) -> 116.383 | E21: =VLOOKUP($A$21,'P&L'!1:1048576,MATCH(E1,'P&L'!4:4,FALSE),FALSE) -> 128.359 | F21: =VLOOKUP($A$21,'P&L'!1:1048576,MATCH(F1,'P&L'!4:4,FALSE),FALSE) -> 136.511 | G21: =VLOOKUP($A$21,'P&L'!1:1048576,MATCH(G1,'P&L'!4:4,FALSE),FALSE) -> 152.181 | H21: =VLOOKUP($A$21,'P&L'!1:1048576,MATCH(H1,'P&L'!4:4,FALSE),FALSE) -> 205.12603 | I21: =VLOOKUP($A$21,'P&L'!1:1048576,MATCH(I1,'P&L'!4:4,FALSE),FALSE) -> 233.2 | J21: =VLOOKUP($A$21,'P&L'!1:1048576,MATCH(J1,'P&L'!4:4,FALSE),FALSE) -> 249.8 | K21: =VLOOKUP($A$21,'P&L'!1:1048576,MATCH(K1,'P&L'!4:4,FALSE),FALSE) -> 326.2 | ... S21: =VLOOKUP($A$21,'P&L'!1:1048576,MATCH(S1,'P&L'!4:4,FALSE),FALSE) -> 536.8862
A22: NPAT_REPORTED | B22: Reported NPAT | C22: A$m | D22: =VLOOKUP($A$22,'P&L'!1:1048576,MATCH(D1,'P&L'!4:4,FALSE),FALSE) -> 116.383 | E22: =VLOOKUP($A$22,'P&L'!1:1048576,MATCH(E1,'P&L'!4:4,FALSE),FALSE) -> 128.359 | F22: =VLOOKUP($A$22,'P&L'!1:1048576,MATCH(F1,'P&L'!4:4,FALSE),FALSE) -> 136.511 | G22: =VLOOKUP($A$22,'P&L'!1:1048576,MATCH(G1,'P&L'!4:4,FALSE),FALSE) -> 152.181 | H22: =VLOOKUP($A$22,'P&L'!1:1048576,MATCH(H1,'P&L'!4:4,FALSE),FALSE) -> 172.4 | I22: =VLOOKUP($A$22,'P&L'!1:1048576,MATCH(I1,'P&L'!4:4,FALSE),FALSE) -> 233.2 | J22: =VLOOKUP($A$22,'P&L'!1:1048576,MATCH(J1,'P&L'!4:4,FALSE),FALSE) -> 249.8 | K22: =VLOOKUP($A$22,'P&L'!1:1048576,MATCH(K1,'P&L'!4:4,FALSE),FALSE) -> 302.2 | ... S22: =VLOOKUP($A$22,'P&L'!1:1048576,MATCH(S1,'P&L'!4:4,FALSE),FALSE) -> 536.8862 | U22: Ratio Analysis | W22: =+W7 -> 2013a | X22: =+X7 -> 2014a | Y22: =+Y7 -> 2015a | Z22: =+Z7 -> 2016a | AA22: =+AA7 -> 2017a | AB22: =+AB7 -> 2018a | AC22: =+AC7 -> 2019a | AD22: =+AD7 -> 2020a | ... AI22: =+AI7 -> 2025a | AJ22: 2026e | AK22: =+AK7 -> 2027e | AL22: =+AL7 -> 2028e
A23: Normalised EPS | B23: EPS | C23: Cents | D23: =VLOOKUP($A$23,'P&L'!1:1048576,MATCH(D1,'P&L'!4:4,FALSE),FALSE) -> 117.02312 | E23: =VLOOKUP($A$23,'P&L'!1:1048576,MATCH(E1,'P&L'!4:4,FALSE),FALSE) -> 126.88586 | F23: =VLOOKUP($A$23,'P&L'!1:1048576,MATCH(F1,'P&L'!4:4,FALSE),FALSE) -> 136.46051 | G23: =VLOOKUP($A$23,'P&L'!$1:$1048576,MATCH(G1,'P&L'!4:4,FALSE),FALSE) -> 152.12471 | H23: =VLOOKUP($A$23,'P&L'!1:1048576,MATCH(H1,'P&L'!4:4,FALSE),FALSE) -> 182.01068 | I23: =VLOOKUP($A$23,'P&L'!1:1048576,MATCH(I1,'P&L'!4:4,FALSE),FALSE) -> 201.20794 | J23: =VLOOKUP($A$23,'P&L'!1:1048576,MATCH(J1,'P&L'!4:4,FALSE),FALSE) -> 215.15935 | K23: =VLOOKUP($A$23,'P&L'!1:1048576,MATCH(K1,'P&L'!4:4,FALSE),FALSE) -> 281.2069 | L23: =VLOOKUP($A$23,'P&L'!1:1048576,MATCH(L1,'P&L'!4:4,FALSE),FALSE) -> 444.55017 | M23: =VLOOKUP($A$23,'P&L'!1:1048576,MATCH(M1,'P&L'!4:4,FALSE),FALSE) -> 480.73555 | N23: =VLOOKUP($A$23,'P&L'!1:1048576,MATCH(N1,'P&L'!4:4,FALSE),FALSE) -> 477.77778 | O23: =VLOOKUP($A$23,'P&L'!1:1048576,MATCH(O1,'P&L'!4:4,FALSE),FALSE) -> 400.73059 | ... S23: =VLOOKUP($A$23,'P&L'!1:1048576,MATCH(S1,'P&L'!4:4,FALSE),FALSE) -> 489.26157 | U23: Growth (%)
A24: DPS | B24: DPS | C24: =+C23 -> Cents | D24: =VLOOKUP($A$24,'P&L'!1:1048576,MATCH(D1,'P&L'!4:4,FALSE),FALSE) -> 72 | E24: =VLOOKUP($A$24,'P&L'!1:1048576,MATCH(E1,'P&L'!4:4,FALSE),FALSE) -> 84 | F24: =VLOOKUP($A$24,'P&L'!1:1048576,MATCH(F1,'P&L'!4:4,FALSE),FALSE) -> 90 | G24: =VLOOKUP($A$24,'P&L'!1:1048576,MATCH(G1,'P&L'!4:4,FALSE),FALSE) -> 100 | H24: =VLOOKUP($A$24,'P&L'!1:1048576,MATCH(H1,'P&L'!4:4,FALSE),FALSE) -> 118 | I24: =VLOOKUP($A$24,'P&L'!1:1048576,MATCH(I1,'P&L'!4:4,FALSE),FALSE) -> 132 | J24: =VLOOKUP($A$24,'P&L'!1:1048576,MATCH(J1,'P&L'!4:4,FALSE),FALSE) -> 142 | K24: =VLOOKUP($A$24,'P&L'!1:1048576,MATCH(K1,'P&L'!4:4,FALSE),FALSE) -> 189 | ... S24: =VLOOKUP($A$24,'P&L'!1:1048576,MATCH(S1,'P&L'!4:4,FALSE),FALSE) -> 378.10969 | U24: Revenue | V24: % | X24: =(E8/D8-1)*100 -> 5.3009007 | Y24: =(F8/E8-1)*100 -> 4.8327174 | Z24: =(G8/F8-1)*100 -> 8.2781966 | AA24: =(H8/G8-1)*100 -> 42.320065 | AB24: =(I8/H8-1)*100 -> 21.789268 | AC24: =(J8/I8-1)*100 -> 3.516041 | AD24: =(K8/J8-1)*100 -> 11.607684 | AE24: =(L8/K8-1)*100 -> 12.592658 | ... AL24: =(S8/R8-1)*100 -> 4.2020917
U25: EBIT | V25: % | X25: =(E17/D17-1)*100 -> 7.5199856 | Y25: =(F17/E17-1)*100 -> 5.1208665 | Z25: =(G17/F17-1)*100 -> 10.08825 | AA25: =(H17/G17-1)*100 -> 38.532836 | AB25: =(I17/H17-1)*100 -> 14.425587 | AC25: =(J17/I17-1)*100 -> 6.3605248 | AD25: =(K17/J17-1)*100 -> 34.861893 | AE25: =(L17/K17-1)*100 -> 47.762975 | ... AL25: =(S17/R17-1)*100 -> 4.9936418
U26: EBITDA | V26: % | X26: =(E12/D12-1)*100 -> 7.4246984 | Y26: =(F12/E12-1)*100 -> 5.9038165 | Z26: =(G12/F12-1)*100 -> 9.1842304 | AA26: =(H12/G12-1)*100 -> 37.479205 | AB26: =(I12/H12-1)*100 -> 14.26589 | AC26: =(J12/I12-1)*100 -> 4.2263784 | AD26: =(K12/J12-1)*100 -> 67.303659 | AE26: =(L12/K12-1)*100 -> 33.946232 | ... AL26: =(S12/R12-1)*100 -> 4.3448766
B27: Cash flow | D27: =+D7 -> 2013a | E27: =+E7 -> 2014a | F27: =+F7 -> 2015a | G27: =+G7 -> 2016a | H27: =+H7 -> 2017a | I27: =+I7 -> 2018a | J27: =+J7 -> 2019a | K27: =+K7 -> 2020a | ... N27: =+N7 -> 2023a | O27: 2024a | P27: 2025a | Q27: 2026e | R27: =+R7 -> 2027e | S27: =+S7 -> 2028e | U27: Normalised NPAT | V27: % | X27: =(E21/D21-1)*100 -> 10.290163 | Y27: =(F21/E21-1)*100 -> 6.3509376 | Z27: =(G21/F21-1)*100 -> 11.478928 | AA27: =(H21/G21-1)*100 -> 34.790829 | AB27: =(I21/H21-1)*100 -> 13.686205 | AC27: =(J21/I21-1)*100 -> 7.1183533 | AD27: =(K21/J21-1)*100 -> 30.584468 | AE27: =(L21/K21-1)*100 -> 57.541386 | ... AL27: =(S21/R21-1)*100 -> 5.1009225
A28: EBIT_NORM | B28: EBIT | C28: A$m | D28: =VLOOKUP($A$28,Drivers!1:1048576,MATCH(1:1,Drivers!2:2,FALSE),FALSE) -> 177.753 | E28: =VLOOKUP($A$28,Drivers!1:1048576,MATCH(1:1,Drivers!2:2,FALSE),FALSE) -> 191.12 | F28: =VLOOKUP($A$28,Drivers!1:1048576,MATCH(1:1,Drivers!2:2,FALSE),FALSE) -> 200.907 | G28: =VLOOKUP($A$28,Drivers!1:1048576,MATCH(1:1,Drivers!2:2,FALSE),FALSE) -> 221.175 | H28: =VLOOKUP($A$28,Drivers!1:1048576,MATCH(1:1,Drivers!2:2,FALSE),FALSE) -> 306.4 | I28: =VLOOKUP($A$28,Drivers!1:1048576,MATCH(1:1,Drivers!2:2,FALSE),FALSE) -> 350.6 | J28: =VLOOKUP($A$28,Drivers!1:1048576,MATCH(1:1,Drivers!2:2,FALSE),FALSE) -> 372.9 | K28: =VLOOKUP($A$28,Drivers!1:1048576,MATCH(1:1,Drivers!2:2,FALSE),FALSE) -> 502.9 | ... S28: =VLOOKUP($A$28,Drivers!1:1048576,MATCH(1:1,Drivers!2:2,FALSE),FALSE) -> 806.02273 | U28: Reported NPAT | V28: % | X28: =(E22/D22-1)*100 -> 10.290163 | Y28: =(F22/E22-1)*100 -> 6.3509376 | Z28: =(G22/F22-1)*100 -> 11.478928 | AA28: =(H22/G22-1)*100 -> 13.286153 | AB28: =(I22/H22-1)*100 -> 35.266821 | AC28: =(J22/I22-1)*100 -> 7.1183533 | AD28: =(K22/J22-1)*100 -> 20.976781 | AE28: =(L22/K22-1)*100 -> 68.596956 | ... AL28: =(S22/R22-1)*100 -> 5.1009225
A29: TOTAL_D&A | B29: D&A | C29: A$m | D29: =VLOOKUP($A$29,Drivers!1:1048576,MATCH(1:1,Drivers!2:2,FALSE),FALSE) -> 33.232 | E29: =VLOOKUP($A$29,Drivers!1:1048576,MATCH(1:1,Drivers!2:2,FALSE),FALSE) -> 35.53 | F29: =VLOOKUP($A$29,Drivers!1:1048576,MATCH(1:1,Drivers!2:2,FALSE),FALSE) -> 39.124 | G29: =VLOOKUP($A$29,Drivers!1:1048576,MATCH(1:1,Drivers!2:2,FALSE),FALSE) -> 40.901 | H29: =VLOOKUP($A$29,Drivers!1:1048576,MATCH(1:1,Drivers!2:2,FALSE),FALSE) -> 53.9 | I29: =VLOOKUP($A$29,Drivers!1:1048576,MATCH(1:1,Drivers!2:2,FALSE),FALSE) -> 61.1 | J29: =VLOOKUP($A$29,Drivers!1:1048576,MATCH(1:1,Drivers!2:2,FALSE),FALSE) -> 56.2 | K29: =VLOOKUP($A$29,Drivers!1:1048576,MATCH(1:1,Drivers!2:2,FALSE),FALSE) -> 229.3 | ... S29: =VLOOKUP($A$29,Drivers!1:1048576,MATCH(1:1,Drivers!2:2,FALSE),FALSE) -> 282.25135 | U29: EPS | V29: % | X29: =(E23/D23-1)*100 -> 8.4280261 | Y29: =(F23/E23-1)*100 -> 7.54588 | Z29: =(G23/F23-1)*100 -> 11.478928 | AA29: =(H23/G23-1)*100 -> 19.645698 | AB29: =(I23/H23-1)*100 -> 10.547328 | AC29: =(J23/I23-1)*100 -> 6.9338256 | AD29: =(K23/J23-1)*100 -> 30.69704 | AE29: =(L23/K23-1)*100 -> 58.086512 | ... AL29: =(S23/R23-1)*100 -> 5.1009225
A30: TAX | B30: Tax paid | C30: A$m | D30: =VLOOKUP($A$30,'P&L'!1:1048576,MATCH(1:1,'P&L'!4:4,FALSE),FALSE) -> -51.42 | E30: =VLOOKUP($A$30,'P&L'!1:1048576,MATCH(1:1,'P&L'!4:4,FALSE),FALSE) -> -54.23 | F30: =VLOOKUP($A$30,'P&L'!1:1048576,MATCH(1:1,'P&L'!4:4,FALSE),FALSE) -> -59.021 | G30: =VLOOKUP($A$30,'P&L'!1:1048576,MATCH(1:1,'P&L'!4:4,FALSE),FALSE) -> -65.658 | H30: =VLOOKUP($A$30,'P&L'!1:1048576,MATCH(1:1,'P&L'!4:4,FALSE),FALSE) -> -86.8 | I30: =VLOOKUP($A$30,'P&L'!1:1048576,MATCH(1:1,'P&L'!4:4,FALSE),FALSE) -> -101.3 | J30: =VLOOKUP($A$30,'P&L'!1:1048576,MATCH(1:1,'P&L'!4:4,FALSE),FALSE) -> -109.5 | K30: =VLOOKUP($A$30,'P&L'!1:1048576,MATCH(1:1,'P&L'!4:4,FALSE),FALSE) -> -145.7 | ... S30: =VLOOKUP($A$30,'P&L'!1:1048576,MATCH(1:1,'P&L'!4:4,FALSE),FALSE) -> -231.46367
A31: NET_INT | B31: Net Interest | C31: A$m | D31: =VLOOKUP($A$31,'P&L'!1:1048576,MATCH(1:1,'P&L'!4:4,FALSE),FALSE) -> -9.701 | E31: =VLOOKUP($A$31,'P&L'!1:1048576,MATCH(1:1,'P&L'!4:4,FALSE),FALSE) -> -8.443 | F31: =VLOOKUP($A$31,'P&L'!1:1048576,MATCH(1:1,'P&L'!4:4,FALSE),FALSE) -> -5.375 | G31: =VLOOKUP($A$31,'P&L'!1:1048576,MATCH(1:1,'P&L'!4:4,FALSE),FALSE) -> -3.336 | H31: =VLOOKUP($A$31,'P&L'!1:1048576,MATCH(1:1,'P&L'!4:4,FALSE),FALSE) -> -9 | I31: =VLOOKUP($A$31,'P&L'!1:1048576,MATCH(1:1,'P&L'!4:4,FALSE),FALSE) -> -16.1 | J31: =VLOOKUP($A$31,'P&L'!1:1048576,MATCH(1:1,'P&L'!4:4,FALSE),FALSE) -> -13.6 | K31: =VLOOKUP($A$31,'P&L'!1:1048576,MATCH(1:1,'P&L'!4:4,FALSE),FALSE) -> -35.3 | ... S31: =VLOOKUP($A$31,'P&L'!1:1048576,MATCH(1:1,'P&L'!4:4,FALSE),FALSE) -> -37.071549 | U31: Margins (%)
B32: Gross Cashflow | C32: A$m | D32: =SUM(D28:D31) -> 149.864 | E32: =SUM(E28:E31) -> 163.977 | F32: =SUM(F28:F31) -> 175.635 | G32: =SUM(G28:G31) -> 193.082 | H32: =SUM(H28:H31) -> 264.5 | I32: =SUM(I28:I31) -> 294.3 | J32: =SUM(J28:J31) -> 306 | K32: =SUM(K28:K31) -> 551.2 | ... S32: =SUM(S28:S31) -> 819.73886 | U32: Gross Margin | V32: % | W32: =+'P&L'!AG12 -> 0.21527203 | X32: =+'P&L'!AJ12 -> 0.21700052 | Y32: =+'P&L'!AM12 -> 0.21857154 | Z32: =+'P&L'!AP12 -> 0.21884315 | AA32: =+'P&L'!AS12 -> 0.21862799 | AB32: =+'P&L'!AV12 -> 0.21450768 | AC32: =+'P&L'!AY12 -> 0.21510014 | AD32: =+'P&L'!BB12 -> 0.21393123 | AE32: =+'P&L'!BE12 -> 0.22175615 | AF32: =VLOOKUP($AM32,'P&L'!$1:$1048576,MATCH(Summary!AF$1,'P&L'!$4:$4,0),FALSE) -> 0.22534662 | AG32: =VLOOKUP($AM32,'P&L'!$1:$1048576,MATCH(Summary!AG$1,'P&L'!$4:$4,0),FALSE) -> 0.22672027 | AH32: =VLOOKUP($AM32,'P&L'!$1:$1048576,MATCH(Summary!AH$1,'P&L'!$4:$4,0),FALSE) -> 0.22313498 | AI32: =VLOOKUP($AM32,'P&L'!$1:$1048576,MATCH(Summary!AI$1,'P&L'!$4:$4,0),FALSE) -> 0.22363285 | AJ32: =VLOOKUP($AM32,'P&L'!$1:$1048576,MATCH(Summary!AJ$1,'P&L'!$4:$4,0),FALSE) -> 0.22450152 | AK32: =VLOOKUP($AM32,'P&L'!$1:$1048576,MATCH(Summary!AK$1,'P&L'!$4:$4,0),FALSE) -> 0.22237293 | AL32: =VLOOKUP($AM32,'P&L'!$1:$1048576,MATCH(Summary!AL$1,'P&L'!$4:$4,0),FALSE) -> 0.22234797 | AM32: JBH_GM
A33: WORKCAP_CHG | B33: (Inc)/dec in working cap | C33: A$m | D33: =VLOOKUP($A$33,CFS!1:1048576,MATCH(1:1,CFS!4:4,FALSE),FALSE) -> -17.361 | E33: =VLOOKUP($A$33,CFS!1:1048576,MATCH(1:1,CFS!4:4,FALSE),FALSE) -> -123.165 | F33: =VLOOKUP($A$33,CFS!1:1048576,MATCH(1:1,CFS!4:4,FALSE),FALSE) -> -8.356 | G33: =VLOOKUP($A$33,CFS!1:1048576,MATCH(1:1,CFS!4:4,FALSE),FALSE) -> -24.835 | H33: =VLOOKUP($A$33,CFS!1:1048576,MATCH(1:1,CFS!4:4,FALSE),FALSE) -> -149.118 | I33: =VLOOKUP($A$33,CFS!1:1048576,MATCH(1:1,CFS!4:4,FALSE),FALSE) -> -21.8 | J33: =VLOOKUP($A$33,CFS!1:1048576,MATCH(1:1,CFS!4:4,FALSE),FALSE) -> -37.9 | K33: =VLOOKUP($A$33,CFS!1:1048576,MATCH(1:1,CFS!4:4,FALSE),FALSE) -> 362.9 | ... S33: =VLOOKUP($A$33,CFS!1:1048576,MATCH(1:1,CFS!4:4,FALSE),FALSE) -> -27.787275 | U33: CODB Margin | V33: % | W33: =+'P&L'!AG47 -> 0.15149952 | X33: =+'P&L'!AJ47 -> 0.15194179 | Y33: =+'P&L'!AM47 -> 0.15284809 | Z33: =+'P&L'!AP47 -> 0.15256974 | AA33: =+'P&L'!AS47 -> 0.1546088 | AB33: =+'P&L'!AV47 -> 0.1544432 | AC33: =+'P&L'!AY47 -> 0.15462348 | AD33: =+'P&L'!BB47 -> 0.1232747 | AE33: =+'P&L'!BE47 -> 0.1139063 | AF33: =VLOOKUP($AM33,'P&L'!$1:$1048576,MATCH(Summary!AF$1,'P&L'!$4:$4,0),FALSE) -> 0.1155221 | AG33: =VLOOKUP($AM33,'P&L'!$1:$1048576,MATCH(Summary!AG$1,'P&L'!$4:$4,0),FALSE) -> 0.12354567 | AH33: =VLOOKUP($AM33,'P&L'!$1:$1048576,MATCH(Summary!AH$1,'P&L'!$4:$4,0),FALSE) -> 0.13094742 | AI33: =VLOOKUP($AM33,'P&L'!$1:$1048576,MATCH(Summary!AI$1,'P&L'!$4:$4,0),FALSE) -> 0.13205366 | AJ33: =VLOOKUP($AM33,'P&L'!$1:$1048576,MATCH(Summary!AJ$1,'P&L'!$4:$4,0),FALSE) -> 0.13283201 | AK33: =VLOOKUP($AM33,'P&L'!$1:$1048576,MATCH(Summary!AK$1,'P&L'!$4:$4,0),FALSE) -> 0.13261086 | AL33: =VLOOKUP($AM33,'P&L'!$1:$1048576,MATCH(Summary!AL$1,'P&L'!$4:$4,0),FALSE) -> 0.1324629 | AM33: CODB_M_EX_D&A
B34: Others | C34: A$m | D34: =+CFS!M21 -> 13.751 | E34: =+CFS!N21 -> -8.331 | F34: =+CFS!O21 -> 6.69 | G34: =+CFS!P21 -> 13.036 | H34: =+CFS!Q21 -> 102.718 | I34: =+CFS!R21 -> 19.6 | J34: =+CFS!S21 -> 33.5 | K34: =+CFS!T21 -> 86.9 | ... M34: =+CFS!V21 -> 36.5 | N34: =+CFS!Y21 -> -51.8 | O34: =+CFS!AB21 -> 57.7 | P34: =+CFS!AE21 -> 81.2 | Q34: =+CFS!AH21 -> 26.5 | R34: =+CFS!AK21 -> 0 | S34: =+CFS!AL21 -> 0 | U34: EBITDA margin | V34: % | W34: =D12/D8 -> 0.063772518 | X34: =E12/E8 -> 0.065058737 | Y34: =F12/F8 -> 0.065723456 | Z34: =G12/G8 -> 0.066273407 | AA34: =H12/H8 -> 0.06401919 | AB34: =I12/I8 -> 0.060064485 | AC34: =J12/J8 -> 0.060476654 | AD34: =K12/K8 -> 0.090656531 | ... AL34: =S12/S8 -> 0.08988507
A35: OCF | B35: Operating cashflow | C35: A$m | D35: =SUM(D32:D34) -> 146.254 | E35: =SUM(E32:E34) -> 32.481 | F35: =SUM(F32:F34) -> 173.969 | G35: =SUM(G32:G34) -> 181.283 | H35: =SUM(H32:H34) -> 218.1 | I35: =SUM(I32:I34) -> 292.1 | J35: =SUM(J32:J34) -> 301.6 | K35: =SUM(K32:K34) -> 1001 | ... S35: =SUM(S32:S34) -> 791.95158 | U35: EBIT margin | V35: % | W35: =D17/D8 -> 0.053727784 | X35: =E17/E8 -> 0.05486003 | Y35: =F17/F8 -> 0.055010821 | Z35: =G17/G8 -> 0.05593042 | AA35: =H17/H8 -> 0.054442075 | AB35: =I17/I8 -> 0.051150373 | AC35: =J17/J8 -> 0.052555917 | AD35: =K17/K8 -> 0.063506295 | ... AL35: =S17/S8 -> 0.066572761
A36: CAPEX | B36: Capital expenditure | C36: A$m | D36: =VLOOKUP($A$36,CFS!1:1048576,MATCH(1:1,CFS!4:4,FALSE),FALSE) -> -35.307 | E36: =VLOOKUP($A$36,CFS!1:1048576,MATCH(1:1,CFS!4:4,FALSE),FALSE) -> -35.914 | F36: =VLOOKUP($A$36,CFS!1:1048576,MATCH(1:1,CFS!4:4,FALSE),FALSE) -> -42.466 | G36: =VLOOKUP($A$36,CFS!1:1048576,MATCH(1:1,CFS!4:4,FALSE),FALSE) -> -52.343 | H36: =VLOOKUP($A$36,CFS!1:1048576,MATCH(1:1,CFS!4:4,FALSE),FALSE) -> -49.1 | I36: =VLOOKUP($A$36,CFS!1:1048576,MATCH(1:1,CFS!4:4,FALSE),FALSE) -> -54.4 | J36: =VLOOKUP($A$36,CFS!1:1048576,MATCH(1:1,CFS!4:4,FALSE),FALSE) -> -59.3 | K36: =VLOOKUP($A$36,CFS!1:1048576,MATCH(1:1,CFS!4:4,FALSE),FALSE) -> -43.1 | ... S36: =VLOOKUP($A$36,CFS!1:1048576,MATCH(1:1,CFS!4:4,FALSE),FALSE) -> -102.91286 | U36: NPAT margin | V36: % | W36: =D21/D8 -> 0.035178032 | X36: =E21/E8 -> 0.036844802 | Y36: =F21/F8 -> 0.0373784 | Z36: =G21/G8 -> 0.038483315 | AA36: =H21/H8 -> 0.036447411 | AB36: =I21/I8 -> 0.034022438 | AC36: =J21/J8 -> 0.035206404 | AD36: =K21/K8 -> 0.04119259 | ... AL36: =S21/S8 -> 0.044343659
B37: Free cashflow | C37: A$m | D37: =SUM(D35:D36) -> 110.947 | E37: =SUM(E35:E36) -> -3.433 | F37: =SUM(F35:F36) -> 131.503 | G37: =SUM(G35:G36) -> 128.94 | H37: =SUM(H35:H36) -> 169 | I37: =SUM(I35:I36) -> 237.7 | J37: =SUM(J35:J36) -> 242.3 | K37: =SUM(K35:K36) -> 957.9 | ... S37: =SUM(S35:S36) -> 689.03872 | U37: Other Value Drivers
A38: DIVIDENDS | B38: Dividends paid | C38: A$m | D38: =VLOOKUP($A$38,CFS!1:1048576,MATCH(1:1,CFS!4:4,FALSE),FALSE) -> -65.263 | E38: =VLOOKUP($A$38,CFS!1:1048576,MATCH(1:1,CFS!4:4,FALSE),FALSE) -> -77.183 | F38: =VLOOKUP($A$38,CFS!1:1048576,MATCH(1:1,CFS!4:4,FALSE),FALSE) -> -87.174 | G38: =VLOOKUP($A$38,CFS!1:1048576,MATCH(1:1,CFS!4:4,FALSE),FALSE) -> -93.205 | H38: =VLOOKUP($A$38,CFS!1:1048576,MATCH(1:1,CFS!4:4,FALSE),FALSE) -> -119.1 | I38: =VLOOKUP($A$38,CFS!1:1048576,MATCH(1:1,CFS!4:4,FALSE),FALSE) -> -151.6 | J38: =VLOOKUP($A$38,CFS!1:1048576,MATCH(1:1,CFS!4:4,FALSE),FALSE) -> -157.4 | K38: =VLOOKUP($A$38,CFS!1:1048576,MATCH(1:1,CFS!4:4,FALSE),FALSE) -> -172.3 | ... S38: =VLOOKUP($A$38,CFS!1:1048576,MATCH(1:1,CFS!4:4,FALSE),FALSE) -> -406.9324 | U38: ROFE | V38: % | W38: =D17/AVERAGE(U20:W20) -> 0.59190231 | X38: =E17/AVERAGE(W20:X20) -> 0.52279358 | Y38: =F17/AVERAGE(X20:Y20) -> 0.46471289 | Z38: =G17/AVERAGE(Y20:Z20) -> 0.49349427 | AA38: =H17/AVERAGE(Z20:AA20) -> 0.3400564 | AB38: =I17/AVERAGE(AA20:AB20) -> 0.2612032 | AC38: =J17/AVERAGE(AB20:AC20) -> 0.27530454 | AD38: =K17/AVERAGE(AC20:AD20) -> 0.45343071 | AE38: =L17/AVERAGE(AD20:AE20) -> 0.78245762 | ... AL38: =S17/AVERAGE(AK20:AL20) -> 0.54907559
A39: TOTAL_CASH_FLOW | B39: Net free Cashflow | C39: A$m | D39: =SUM(D37:D38) -> 45.684 | E39: =SUM(E37:E38) -> -80.616 | F39: =SUM(F37:F38) -> 44.329 | G39: =SUM(G37:G38) -> 35.735 | H39: =SUM(H37:H38) -> 49.9 | I39: =SUM(I37:I38) -> 86.1 | J39: =SUM(J37:J38) -> 84.9 | K39: =SUM(K37:K38) -> 785.6 | ... S39: =SUM(S37:S38) -> 282.10632 | U39: EBIT to net interest | V39: x | W39: =D17/-D18 -> 18.323163 | X39: =E17/-E18 -> 22.636504 | Y39: =F17/-F18 -> 37.378047 | Z39: =G17/-G18 -> 66.29946 | AA39: =H17/-H18 -> 34.044444 | AB39: =I17/-I18 -> 21.776398 | AC39: =J17/-J18 -> 27.419118 | AD39: =K17/-K18 -> 14.246459 | ... AL39: =S17/-S18 -> 21.742354
A40: Proceeds_issue_shr | B40: Equity raised | C40: A$m | D40: =+CFS!M34 -> 1.082 | E40: =+CFS!N34 -> -4.307 | F40: =+CFS!O34 -> -1.845 | G40: =+CFS!P34 -> -7.226 | H40: =+CFS!Q34 -> 395.9 | I40: =+CFS!R34 -> 3 | J40: =+CFS!S34 -> 1.9 | K40: =+CFS!T34 -> 1.3 | L40: =VLOOKUP($A$40,CFS!$1:$1048576,MATCH(Summary!L$1,CFS!$4:$4,0),FALSE) -> 0 | M40: =VLOOKUP($A$40,CFS!$1:$1048576,MATCH(Summary!M$1,CFS!$4:$4,0),FALSE) -> 0 | N40: =VLOOKUP($A$40,CFS!$1:$1048576,MATCH(Summary!N$1,CFS!$4:$4,0),FALSE) -> 0 | O40: =VLOOKUP($A$40,CFS!$1:$1048576,MATCH(Summary!O$1,CFS!$4:$4,0),FALSE) -> 0 | P40: =VLOOKUP($A$40,CFS!$1:$1048576,MATCH(Summary!P$1,CFS!$4:$4,0),FALSE) -> 0 | Q40: =VLOOKUP($A$40,CFS!$1:$1048576,MATCH(Summary!Q$1,CFS!$4:$4,0),FALSE) -> 0 | R40: =VLOOKUP($A$40,CFS!$1:$1048576,MATCH(Summary!R$1,CFS!$4:$4,0),FALSE) -> 0 | S40: =VLOOKUP($A$40,CFS!$1:$1048576,MATCH(Summary!S$1,CFS!$4:$4,0),FALSE) -> 0 | U40: Capex-to-D&A | V40: x | W40: =D36/D13 -> 1.0624398 | X40: =E36/E13 -> 1.0108078 | Y40: =F36/F13 -> 1.0854207 | Z40: =G36/G13 -> 1.2797487 | AA40: =H36/H13 -> 0.9109462 | AB40: =I36/I13 -> 0.8903437 | AC40: =J36/J13 -> 1.0551601 | AD40: =K36/K13 -> 0.18796337 | ... AL40: =S36/S13 -> 0.36461424
B41: Other financing | C41: A$m | D41: =CFS!M36+CFS!M37 -> -0.632 | E41: =CFS!N36+CFS!N37 -> -0.182 | F41: =CFS!O36+CFS!O37 -> -0.508 | G41: =CFS!P36+CFS!P37 -> -0.134 | H41: =CFS!Q36+CFS!Q37 -> -10.9 | I41: =CFS!R36+CFS!R37 -> -0.8 | J41: =CFS!S36+CFS!S37 -> -9.4 | K41: =VLOOKUP($A$59,CFS!$1:$1048576,MATCH(Summary!K$1,CFS!$4:$4,0),FALSE)+VLOOKUP(Summary!$A$60,CFS!$1:$1048576,MATCH(Summary!K$1,CFS!$4:$4,0),FALSE)+VLOOKUP(Summary!$A$61,CFS!$1:$1048576,MATCH(Summary!K$1,CFS!$4:$4,0),FALSE) -> -194.8 | L41: =VLOOKUP($A$59,CFS!$1:$1048576,MATCH(Summary!L$1,CFS!$4:$4,0),FALSE)+VLOOKUP(Summary!$A$60,CFS!$1:$1048576,MATCH(Summary!L$1,CFS!$4:$4,0),FALSE)+VLOOKUP(Summary!$A$61,CFS!$1:$1048576,MATCH(Summary!L$1,CFS!$4:$4,0),FALSE) -> -179.1 | M41: =VLOOKUP($A$59,CFS!$1:$1048576,MATCH(Summary!M$1,CFS!$4:$4,0),FALSE)+VLOOKUP(Summary!$A$60,CFS!$1:$1048576,MATCH(Summary!M$1,CFS!$4:$4,0),FALSE)+VLOOKUP(Summary!$A$61,CFS!$1:$1048576,MATCH(Summary!M$1,CFS!$4:$4,0),FALSE) -> -456.4 | N41: =VLOOKUP($A$59,CFS!$1:$1048576,MATCH(Summary!N$1,CFS!$4:$4,0),FALSE)+VLOOKUP(Summary!$A$60,CFS!$1:$1048576,MATCH(Summary!N$1,CFS!$4:$4,0),FALSE)+VLOOKUP(Summary!$A$61,CFS!$1:$1048576,MATCH(Summary!N$1,CFS!$4:$4,0),FALSE) -> -200.4 | O41: =VLOOKUP($A$59,CFS!$1:$1048576,MATCH(Summary!O$1,CFS!$4:$4,0),FALSE)+VLOOKUP(Summary!$A$60,CFS!$1:$1048576,MATCH(Summary!O$1,CFS!$4:$4,0),FALSE)+VLOOKUP(Summary!$A$61,CFS!$1:$1048576,MATCH(Summary!O$1,CFS!$4:$4,0),FALSE) -> -204.6 | P41: =VLOOKUP($A$59,CFS!$1:$1048576,MATCH(Summary!P$1,CFS!$4:$4,0),FALSE)+VLOOKUP(Summary!$A$60,CFS!$1:$1048576,MATCH(Summary!P$1,CFS!$4:$4,0),FALSE)+VLOOKUP(Summary!$A$61,CFS!$1:$1048576,MATCH(Summary!P$1,CFS!$4:$4,0),FALSE) -> -220.1 | Q41: =VLOOKUP($A$59,CFS!$1:$1048576,MATCH(Summary!Q$1,CFS!$4:$4,0),FALSE)+VLOOKUP(Summary!$A$60,CFS!$1:$1048576,MATCH(Summary!Q$1,CFS!$4:$4,0),FALSE)+VLOOKUP(Summary!$A$61,CFS!$1:$1048576,MATCH(Summary!Q$1,CFS!$4:$4,0),FALSE) -> -232.076 | R41: =VLOOKUP($A$59,CFS!$1:$1048576,MATCH(Summary!R$1,CFS!$4:$4,0),FALSE)+VLOOKUP(Summary!$A$60,CFS!$1:$1048576,MATCH(Summary!R$1,CFS!$4:$4,0),FALSE)+VLOOKUP(Summary!$A$61,CFS!$1:$1048576,MATCH(Summary!R$1,CFS!$4:$4,0),FALSE) -> -211.33128 | S41: =VLOOKUP($A$59,CFS!$1:$1048576,MATCH(Summary!S$1,CFS!$4:$4,0),FALSE)+VLOOKUP(Summary!$A$60,CFS!$1:$1048576,MATCH(Summary!S$1,CFS!$4:$4,0),FALSE)+VLOOKUP(Summary!$A$61,CFS!$1:$1048576,MATCH(Summary!S$1,CFS!$4:$4,0),FALSE) -> -217.67122 | U41: Capex-to-sales | V41: % | W41: =-D36/D8 -> 0.010671926 | X41: =-E36/E8 -> 0.010308932 | Y41: =-F36/F8 -> 0.011627716 | Z41: =-G36/G8 -> 0.013236424 | AA41: =-H36/H8 -> 0.008724236 | AB41: =-I36/I8 -> 0.0079366237 | AC41: =-J36/J8 -> 0.0083576452 | AD41: =-K36/K8 -> 0.0054426751 | ... AL41: =-S36/S8 -> 0.0085
A42: CHG_DEBT | B42: Change in net debt | C42: A$m | D42: =VLOOKUP($A$42,CFS!1:1048576,MATCH(1:1,CFS!4:4,FALSE),FALSE) -> -26.21 | E42: =VLOOKUP($A$42,CFS!1:1048576,MATCH(1:1,CFS!4:4,FALSE),FALSE) -> 54.063 | F42: =VLOOKUP($A$42,CFS!1:1048576,MATCH(1:1,CFS!4:4,FALSE),FALSE) -> -40.113 | G42: =VLOOKUP($A$42,CFS!1:1048576,MATCH(1:1,CFS!4:4,FALSE),FALSE) -> -30 | H42: =VLOOKUP($A$42,CFS!1:1048576,MATCH(1:1,CFS!4:4,FALSE),FALSE) -> 450 | I42: =VLOOKUP($A$42,CFS!1:1048576,MATCH(1:1,CFS!4:4,FALSE),FALSE) -> -89.7 | J42: =VLOOKUP($A$42,CFS!1:1048576,MATCH(1:1,CFS!4:4,FALSE),FALSE) -> -30.5 | K42: =VLOOKUP($A$42,CFS!1:1048576,MATCH(1:1,CFS!4:4,FALSE),FALSE) -> -440 | ... S42: =VLOOKUP($A$42,CFS!1:1048576,MATCH(1:1,CFS!4:4,FALSE),FALSE) -> 0 | U42: D&A-to-sales | V42: % | W42: =-D13/D8 -> 0.010044735 | X42: =-E13/E8 -> 0.010198707 | Y42: =-F13/F8 -> 0.010712635 | Z42: =-G13/G8 -> 0.010342987 | AA42: =-H13/H8 -> 0.0095771144 | AB42: =-I13/I8 -> 0.0089141123 | AC42: =-J13/J8 -> 0.0079207363 | AD42: =-K13/K8 -> 0.028956042 | ... AL42: =-S13/S8 -> 0.02331231
B43: JB Hi Fi (Aus) metrics | D43: =W49 -> 2013a | E43: =X49 -> 2014a | F43: =Y49 -> 2015a | G43: =G27 -> 2016a | H43: =H27 -> 2017a | I43: =I27 -> 2018a | J43: =J27 -> 2019a | K43: =K27 -> 2020a | L43: =L27 -> 2021a | M43: =M27 -> 2022a | N43: =N27 -> 2023a | ... P43: =P27 -> 2025a | Q43: 2026e | R43: =+R27 -> 2027e | S43: =+S27 -> 2028e | U43: Net debt/equity | V43: x | W43: =W19/W18 -> 0.2340833 | X43: =X19/X18 -> 0.46229716 | Y43: =Y19/Y18 -> 0.26298551 | Z43: =Z19/Z18 -> 0.14294963 | AA43: =AA19/AA18 -> 0.56942004 | AB43: =AB19/AB18 -> 0.41937526 | AC43: =AC19/AC18 -> 0.30638828 | AD43: =AD19/AD18 -> -0.22745772 | ... AL43: =AL19/AL18 -> -0.21091746
A44: JBH_SalesG | B44: JB Hi Fi (Aus) LFL sales | C44: % | I44: =Drivers!U73 -> 0.062 | J44: =VLOOKUP($A44,Drivers!$1:$1048576,MATCH(Summary!J$1,Drivers!$2:$2,0),FALSE) -> 0.028 | K44: =VLOOKUP($A44,Drivers!$1:$1048576,MATCH(Summary!K$1,Drivers!$2:$2,0),FALSE) -> 0.122 | L44: =VLOOKUP($A44,Drivers!$1:$1048576,MATCH(Summary!L$1,Drivers!$2:$2,0),FALSE) -> 0.12 | M44: =VLOOKUP($A44,Drivers!$1:$1048576,MATCH(Summary!M$1,Drivers!$2:$2,0),FALSE) -> 0.034 | N44: =VLOOKUP($A44,Drivers!$1:$1048576,MATCH(Summary!N$1,Drivers!$2:$2,0),FALSE) -> 0.048 | O44: =VLOOKUP($A44,Drivers!$1:$1048576,MATCH(Summary!O$1,Drivers!$2:$2,0),FALSE) -> 0.006 | P44: =VLOOKUP($A44,Drivers!$1:$1048576,MATCH(Summary!P$1,Drivers!$2:$2,0),FALSE) -> 0.072 | Q44: =VLOOKUP($A44,Drivers!$1:$1048576,MATCH(Summary!Q$1,Drivers!$2:$2,0),FALSE) -> 0.0375 | ... S44: =VLOOKUP($A44,Drivers!$1:$1048576,MATCH(Summary!S$1,Drivers!$2:$2,0),FALSE) -> 0.04 | U44: Net debt/(Net debt + Equity) | V44: x | W44: =W19/(W18+W19) -> 0.18968193 | X44: =X19/(X18+X19) -> 0.31614447 | Y44: =Y19/(Y18+Y19) -> 0.20822528 | Z44: =Z19/(Z18+Z19) -> 0.1250708 | AA44: =AA19/(AA18+AA19) -> 0.36282195 | AB44: =AB19/(AB18+AB19) -> 0.29546468 | AC44: =AC19/(AC18+AC19) -> 0.23453079 | AD44: =AD19/(AD18+AD19) -> -0.29442753 | ... AL44: =AL19/(AL18+AL19) -> -0.26729455
...

Sheet P&L
B2: JBH Profit & Loss Statement
B4: (A$mn, Year ending June) | C4: FY03 | D4: 1H04 | E4: 2H04 | F4: FY04 | G4: 1H05 | H4: 2H05 | I4: FY05 | J4: 1H06 | K4: 2H06 | L4: FY06 | M4: 1H07 | N4: 2H07 | O4: FY07 | P4: 1H08 | Q4: 2H08 | R4: FY08 | S4: 1H09 | T4: 2H09 | U4: FY09 | V4: 1H10 | W4: 2H10 | X4: FY10 | Y4: 1H11 | Z4: 2H11 | AA4: FY11 | AB4: 1H12 | AC4: 2H12 | AD4: FY12 | AE4: 1H13 | AF4: 2H13 | AG4: FY13 | AH4: 1H14 | AI4: 2H14 | AJ4: FY14 | AK4: 1H15 | AL4: 2H15 | AM4: FY15 | AN4: 1H16 | AO4: 2H16 | AP4: FY16 | AQ4: 1H17 | AR4: 2H17 | AS4: FY17 | AT4: 1H18 | AU4: 2H18 | AV4: FY18 | AW4: 1H19 | AX4: 2H19 | AY4: FY19 | AZ4: 1H20 | BA4: 2H20 | BB4: FY20 | BC4: 1H21 | BD4: 2H21 | BE4: FY21 | BF4: 1H22 | BG4: 2H22 | BH4: FY22 | BI4: 1H23 | BJ4: 2H23 | BK4: FY23 | BL4: 1H24 | BM4: 2H24 | BN4: FY24 | BO4: 1H25 | BP4: 2H25 | BQ4: FY25 | BR4: 1H26E | BS4: 2H26E | BT4: =Drivers!AS2 -> FY26E | BU4: 1H27E | BV4: 2H27E | BW4: =Drivers!AV2 -> FY27E | BX4: 1H28E | BY4: 2H28E | BZ4: =Drivers!AY2 -> FY28E | CA4: 1H29E | CB4: 2H29E | CC4: =Drivers!BB2 -> FY29E
A6: JBH_Sales | B6: Sales | C6: =VLOOKUP($A$6,Drivers!1:1048576,MATCH('P&L'!C4,Drivers!2:2,FALSE),FALSE) -> 355.835 | D6: =VLOOKUP($A$6,Drivers!1:1048576,MATCH('P&L'!D4,Drivers!2:2,FALSE),FALSE) -> 234.599 | E6: =VLOOKUP($A$6,Drivers!1:1048576,MATCH('P&L'!E4,Drivers!2:2,FALSE),FALSE) -> 217.758 | F6: =VLOOKUP($A$6,Drivers!1:1048576,MATCH('P&L'!F4,Drivers!2:2,FALSE),FALSE) -> 452.357 | G6: =VLOOKUP($A$6,Drivers!1:1048576,MATCH('P&L'!G4,Drivers!2:2,FALSE),FALSE) -> 376.177 | H6: =VLOOKUP($A$6,Drivers!1:1048576,MATCH('P&L'!H4,Drivers!2:2,FALSE),FALSE) -> 317.766 | I6: =VLOOKUP($A$6,Drivers!1:1048576,MATCH('P&L'!I4,Drivers!2:2,FALSE),FALSE) -> 693.943 | J6: =VLOOKUP($A$6,Drivers!1:1048576,MATCH('P&L'!J4,Drivers!2:2,FALSE),FALSE) -> 509.836 | ... CC6: =VLOOKUP($A$6,Drivers!1:1048576,MATCH('P&L'!CC4,Drivers!2:2,FALSE),FALSE) -> 12616.76
B7: Reported Growth (%) | F7: =F6/C6-1 -> 0.27125494 | G7: =G6/D6-1 -> 0.60348936 | H7: =H6/E6-1 -> 0.45926212 | I7: =I6/F6-1 -> 0.53406049 | J7: =J6/G6-1 -> 0.3553088 | K7: =K6/H6-1 -> 0.37203162 | L7: =L6/I6-1 -> 0.36296641 | M7: =M6/J6-1 -> 0.29237245 | ... U7: =U6/R6-1 -> 0.27272876 | V7: =V6/T6-1 -> 0.45798306 | W7: =W6/U6-1 -> -0.49402174 | X7: =X6/U6-1 -> 0.17361745 | Y7: =Y6/V6-1 -> 0.082933554 | Z7: =Z6/W6-1 -> 0.084135142 | AA7: =AA6/X6-1 -> 0.083451591 | AB7: =AB6/Y6-1 -> 0.054732639 | AC7: =AC6/Z6-1 -> 0.059880043 | AD7: =AD6/AA6-1 -> 0.056953224 | AE7: =AE6/AB6-1 -> 0.023394558 | ... CC7: =CC6/BZ6-1 -> 0.04207057
BF8: =108.4/BF6 -> 0.022296269 | BI8: =108.4/BI6 -> 0.020536137 | BJ8: =(BJ6+BL6)/(BI6+BG6)-1 -> -0.014374994 | BK8: =108.4/BK6 -> 0.0112607 | BL8: =108.4/BL6 -> 0.020999206 | BM8: =(BM6+BO6)/(BL6+BJ6)-1 -> 0.062113565 | BN8: =108.4/BN6 -> 0.011300613 | BO8: =108.4/BO6 -> 0.019116817 | BQ8: =108.4/BQ6 -> 0.010270209
A10: COGS | B10: Cost of Sales | C10: =C11-C6 -> -275.901 | D10: =D11-D6 -> -180.068 | E10: =E11-E6 -> -166.353 | F10: =F11-F6 -> -346.421 | G10: =G11-G6 -> -289.641 | H10: =H11-H6 -> -245.621 | I10: =I11-I6 -> -535.262 | J10: =J11-J6 -> -395.024 | ... CC10: =CC11-CC6 -> -9812.3039
A11: JBH_GP | B11: Gross Profit | C11: =VLOOKUP($A$11,Drivers!1:1048576,MATCH('P&L'!C4,Drivers!2:2,FALSE),FALSE) -> 79.934 | D11: =VLOOKUP($A$11,Drivers!1:1048576,MATCH('P&L'!D4,Drivers!2:2,FALSE),FALSE) -> 54.531 | E11: =VLOOKUP($A$11,Drivers!1:1048576,MATCH('P&L'!E4,Drivers!2:2,FALSE),FALSE) -> 51.405 | F11: =VLOOKUP($A$11,Drivers!1:1048576,MATCH('P&L'!F4,Drivers!2:2,FALSE),FALSE) -> 105.936 | G11: =VLOOKUP($A$11,Drivers!1:1048576,MATCH('P&L'!G4,Drivers!2:2,FALSE),FALSE) -> 86.536 | H11: =VLOOKUP($A$11,Drivers!1:1048576,MATCH('P&L'!H4,Drivers!2:2,FALSE),FALSE) -> 72.145 | I11: =VLOOKUP($A$11,Drivers!1:1048576,MATCH('P&L'!I4,Drivers!2:2,FALSE),FALSE) -> 158.681 | J11: =VLOOKUP($A$11,Drivers!1:1048576,MATCH('P&L'!J4,Drivers!2:2,FALSE),FALSE) -> 114.812 | ... CC11: =VLOOKUP($A$11,Drivers!1:1048576,MATCH('P&L'!CC4,Drivers!2:2,FALSE),FALSE) -> 2804.4564
A12: JBH_GM | B12: Gross Margin | C12: =C11/C6 -> 0.22463782 | D12: =D11/D6 -> 0.23244345 | E12: =E11/E6 -> 0.23606481 | F12: =F11/F6 -> 0.23418672 | G12: =G11/G6 -> 0.23004065 | H12: =H11/H6 -> 0.22703813 | I12: =I11/I6 -> 0.22866575 | J12: =J11/J6 -> 0.22519398 | ... CC12: =CC11/CC6 -> 0.22228023
B13: YoY change | F13: =F12-C12 -> 0.0095488916 | G13: =G12-D12 -> -0.0024028003 | H13: =H12-E12 -> -0.0090266709 | I13: =I12-F12 -> -0.0055209604 | J13: =J12-G12 -> -0.0048466618 | K13: =K12-H12 -> -0.0031451111 | L13: =L12-I12 -> -0.0040714607 | M13: =M12-J12 -> -0.0037818686 | ... CC13: =CC12-BZ12 -> -6.7739412e-05
BG14: =(BG11+BI11)/(BG6+BI6) -> 0.2298548
B15: Group
B16: Operating costs | Y16: =Y17/(Y17+Z17) -> 0.51574316 | Z16: =1-Y16 -> 0.48425684 | AB16: =AB17/(AB17+AC17) -> 0.51897307 | AC16: =1-AB16 -> 0.48102693 | AE16: =AE17/(AE17+AF17) -> 0.49936021 | AF16: =1-AE16 -> 0.50063979 | AH16: =AH17/(AH17+AI17) -> 0.51271599 | AI16: =1-AH16 -> 0.48728401 | AK16: =AK17/(AK17+AL17) -> 0.50049989 | AL16: =1-AK16 -> 0.49950011
B17: Sales & Marketing | C17: 42.267 | F17: 56.025 | G17: 42.101 | H17: =I17-G17 -> 42.629 | I17: 84.73 | J17: 58.203 | K17: =L17-J17 -> 55.718 | L17: 113.921 | M17: 70.349 | N17: =O17-M17 -> 71.671 | O17: 142.02 | P17: 100.388 | Q17: =R17-P17 -> 93.048 | R17: 193.436 | S17: 116.14 | T17: =U17-S17 -> 114.271 | U17: 230.411 | V17: 139.024 | W17: =X17-V17 -> 126.118 | X17: 265.142 | Y17: 147.927 | Z17: =AA17-Y17 -> 138.896 | AA17: 286.823 | AB17: 160.604 | AC17: =AD17-AB17 -> 148.861 | AD17: 309.465 | AE17: 168.2 | AF17: =AG17-AE17 -> 168.631 | AG17: 336.831 | AH17: 182.37 | AI17: =AJ17-AH17 -> 173.324 | AJ17: 355.694 | AK17: 187.229 | AL17: =AM17-AK17 -> 186.855 | AM17: 374.084 | AN17: 202.786 | AO17: =AP17-AN17 -> 201.789 | AP17: 404.575 | AQ17: 249.3 | AR17: =AS17-AQ17 -> 330.8 | AS17: 580.1 | AT17: 357.4 | AU17: =AV17-AT17 -> 337.7 | AV17: 695.1 | AW17: 379.3 | AX17: =AY17-AW17 -> 351.7 | AY17: 731 | AZ17: 395.7 | BA17: =BB17-AZ17 -> 390.7 | BB17: 786.4 | BE17: 845.8 | BF17: 448.3 | BG17: =BH17-BF17 -> 432.8 | BH17: 881.1 | BI17: 504.5 | BJ17: =BK17-BI17 -> 473.8 | BK17: 978.3 | BL17: 532.7 | BM17: =BN17-BL17 -> 506.4 | BN17: 1039.1 | BO17: 595.2 | BP17: =BQ17-BO17 -> 571.8 | BQ17: 1167 | BR17: 644.6
B18: - % of sales | C18: =C17/Drivers!F90 -> 0.11878258 | F18: =F17/Drivers!G90 -> 0.12385129 | G18: =G17/Drivers!BM90 -> 0.11191806 | H18: =H17/Drivers!BN90 -> 0.13415217 | I18: =I17/Drivers!H90 -> 0.12209937 | J18: =J17/Drivers!BO90 -> 0.11416024 | K18: =K17/Drivers!BP90 -> 0.12779797 | L18: =L17/Drivers!I90 -> 0.12044668 | M18: =M17/Drivers!BQ90 -> 0.10676766 | N18: =N17/Drivers!BR90 -> 0.115053 | O18: =O17/Drivers!J90 -> 0.11079412 | P18: =P17/Drivers!BS90 -> 0.10155158 | Q18: =Q17/Drivers!BT90 -> 0.11076853 | R18: =R17/Drivers!K90 -> 0.10578574 | S18: =S17/Drivers!BU90 -> 0.092060258 | T18: =T17/Drivers!BV90 -> 0.10722614 | U18: =U17/Drivers!L90 -> 0.099005013 | V18: =V17/Drivers!BW90 -> 0.089475046 | W18: =W17/Drivers!BX90 -> 0.1071024 | X18: =X17/Drivers!M90 -> 0.097074675 | Y18: =Y17/Drivers!BY90 -> 0.087913949 | Z18: =Z17/Drivers!BZ90 -> 0.10879988 | AA18: =AA17/Drivers!N90 -> 0.096924122 | AB18: =AB17/Drivers!CA90 -> 0.090494943 | AC18: =AC17/Drivers!CB90 -> 0.11001779 | AD18: =AD17/Drivers!O90 -> 0.098940403 | AE18: =AE17/Drivers!CC90 -> 0.092608498 | AF18: =AF17/Drivers!CD90 -> 0.11301195 | AG18: =AG17/Drivers!P90 -> 0.10181085 | AH18: =AH17/Drivers!CE90 -> 0.0940116 | AI18: =AI17/Drivers!CF90 -> 0.11226317 | AJ18: =AJ17/Drivers!Q90 -> 0.10210016 | AK18: =AK17/Drivers!CG90 -> 0.095274758 | AL18: =AL17/Drivers!CH90 -> 0.1107625 | AM18: =AM17/Drivers!R90 -> 0.10242883 | AN18: =AN17/Drivers!CI90 -> 0.095797606 | AO18: =AO17/Drivers!CJ90 -> 0.10980818 | AP18: =AP17/Drivers!S90 -> 0.10230835 | AQ18: =AQ17/Drivers!CK90 -> 0.10594535 | AR18: =AR17/Drivers!CL90 -> 0.16404662 | AS18: =AS17/Drivers!T7 -> 0.10307392 | AT18: =AT17/Drivers!CM90 -> 0.13799228 | AU18: =AU17/Drivers!CN90 -> 0.15612575 | AV18: =AV17/Drivers!U7 -> 0.10141079 | AW18: =AW17/Drivers!V90 -> 0.13980833 | AX18: =AX17/Drivers!W90 -> 0.15740243 | AY18: =AY17/Drivers!X7 -> 0.10302595 | AZ18: =AZ17/Drivers!Y90 -> 0.13895424 | BA18: =BA17/Drivers!Z90 -> 0.14565315 | BB18: =BB17/Drivers!AA7 -> 0.099306722 | BE18: =BE17/Drivers!AD7 -> 0.094862103 | BF18: =BF17/Drivers!AE90 -> 0.13098995 | BG18: =BG17/Drivers!AF90 -> 0.14330177 | BH18: =BH17/Drivers!AG7 -> 0.095439775 | BI18: =BI17/Drivers!AH90 -> 0.13509171 | BJ18: =BJ17/Drivers!AI7 -> 0.10897215 | BK18: =BK17/Drivers!AJ7 -> 0.10162678 | BL18: =BL17/Drivers!AK90 -> 0.14125477 | BM18: =BM17/Drivers!AL7 -> 0.11430377 | BN18: =BN17/Drivers!AM7 -> 0.10832534 | BO18: =BO17/Drivers!AN90 -> 0.14662627 | BP18: =BP17/Drivers!AO7 -> 0.11706658 | BQ18: =BQ17/Drivers!AP7 -> 0.11056581
B19: - growth | F19: =F17/C17-1 -> 0.32550216 | I19: =I17/F17-1 -> 0.51236055 | J19: =J17/G17-1 -> 0.38246122 | K19: =K17/H17-1 -> 0.3070445 | L19: =L17/I17-1 -> 0.34451788 | M19: =M17/J17-1 -> 0.2086834 | N19: =N17/K17-1 -> 0.28631681 | O19: =O17/L17-1 -> 0.24665338 | P19: =P17/M17-1 -> 0.42699967 | ... BB19: =BB17/AY17-1 -> 0.075786594 | BE19: =BE17/BB17-1 -> 0.075534079 | BF19: =IFERROR(BF17/BC17-1,"NA") -> NA | BG19: =IFERROR(BG17/BD17-1,"NA") -> NA | BH19: =BH17/BE17-1 -> 0.041735635 | BI19: =IFERROR(BI17/BF17-1,"NA") -> 0.12536248 | BJ19: =BJ17/BG17-1 -> 0.094731978 | BK19: =BK17/BH17-1 -> 0.11031665 | BL19: =IFERROR(BL17/BI17-1,"NA") -> 0.055896928 | BM19: =BM17/BJ17-1 -> 0.068805403 | BN19: =BN17/BK17-1 -> 0.062148625 | BO19: =IFERROR(BO17/BL17-1,"NA") -> 0.11732683 | BP19: =BP17/BM17-1 -> 0.12914692 | BQ19: =BQ17/BN17-1 -> 0.12308729
AC20: =AC21/Z21-1 -> 0.12039594 | AE20: =AE21/AB21-1 -> 0.070290783 | AF20: =AF21/AC21-1 -> 0.098072241 | AH20: =AH21/AE21-1 -> 0.071306632 | AI20: =AI21/AF21-1 -> 0.049613743
B21: Occupancy | C21: 9.754 | F21: 14.496 | G21: 10.309 | H21: =I21-G21 -> 12.681 | I21: 22.99 | J21: 14.975 | K21: =L21-J21 -> 18.206 | L21: 33.181 | M21: 20.589 | N21: =O21-M21 -> 26.226 | O21: 46.815 | P21: 30.095 | Q21: =R21-P21 -> 34.985 | R21: 65.08 | S21: 40.339 | T21: =U21-S21 -> 44.212 | U21: 84.551 | V21: 49.199 | W21: =X21-V21 -> 51.868 | X21: 101.067 | Y21: 56.509 | Z21: =AA21-Y21 -> 58.291 | AA21: 114.8 | AB21: 64.034 | AC21: =AD21-AB21 -> 65.309 | AD21: 129.343 | AE21: 68.535 | AF21: =AG21-AE21 -> 71.714 | AG21: 140.249 | AH21: 73.422 | AI21: =AJ21-AH21 -> 75.272 | AJ21: 148.694 | AK21: 78.416 | AL21: =AM21-AK21 -> 81.8 | AM21: 160.216 | AN21: 84.904 | AO21: =AP21-AN21 -> 88.888 | AP21: 173.792 | AQ21: 101.2 | AR21: =AS21-AQ21 -> 147.4 | AS21: 248.6 | AT21: 148.4 | AU21: =AV21-AT21 -> 157.3 | AV21: 305.7 | AW21: 151.4 | AX21: =AY21-AW21 -> 155 | AY21: 306.4 | AZ21: 153.5 | BA21: =BB21-AZ21 -> 159.6 | BB21: 313.1 | BE21: 293.6 | BF21: 148.5 | BG21: =BH21-BF21 -> 154.3 | BH21: 302.8 | BI21: 160 | BJ21: =BK21-BI21 -> 161.8 | BK21: 321.8 | BL21: 166.6 | BM21: =BN21-BL21 -> 161.4 | BN21: 328 | BO21: 170.5 | BP21: =BQ21-BO21 -> 179.1 | BQ21: 349.6 | BR21: 184.7
