Workbook
Name A_ALL_SIG.AX: #REF!
Name Abnormals_PostTAX: #REF!
Name AEndDrinks_Sales: #REF!
Name Continuing_sales: #REF!
Name DCF_INF: #REF!
Name DPS: #REF!
Name E_ALL_SIG.AX: #REF!
Name EPS_Pre_Goodwill: #REF!
Name L_ALL_SIG.AX: #REF!
Name NET_PROFIT: #REF!
Name NPAT_post_Abn: #REF!
Name Sales_Aust_FL: #REF!
Name Sales_NZ_FL: #REF!
Name TOTAL_SALES: #REF!
Name V_ALL_SIG.AX: #REF!

Sheet Cover
B5: Sigma Healthcare (SIG.AX)
B6: Rating | C6: Buy
B7: Target Price/ Target price period/ Upside/downside to target price | C7: A$3.5/ 12 Month/ 19.9%
B8: M&A probability (1 = high, 3 = low) | C8: 3
B9: Market Cap (US$ mn) (price as of ______):
B10: Current shares outstanding (mn):
B11: Currency: | C11: AUD
B12: Current Publication Date: | C12: 46043
B13: Previous Publication Date:
B15: Team Contacts:
B16: Lead Analyst
B17: Peter Marks, peter.marks@gs.com, +61 2 9321 8846, Goldman Sachs Australia Pty Ltd
B18: Consumer Team
B19: James Leigh, james.leigh@gs.com, +61 2 , Goldman Sachs Australia Pty Ltd
B20: Consumer Team
B21: Rayanne Haidar, rayanne.haidar@gs.com +61 2 9321 8739, Goldman Sachs Australia Pty Ltd

Sheet Summary
D1: Sigma Healthcare (SIG.AX)
D6: Goldman Sachs | Sigma Healthcare | SIG-AU
D8: Price target | F8: =Valuation!E22 -> 3.5
D9: Current share price | F9: 2.92
D10: Upside / downside | F10: =F8/F9-1 -> 0.19863014
D11: Recommendation | F11: BUY
A13: Col D | B13: Col K | D13: P&L | E13: FY24 | F13: FY25 | G13: FY26E | H13: FY27E | I13: FY28E | K13: Balance Sheet | L13: =E$13 -> FY24 | M13: =F$13 -> FY25 | N13: =G$13 -> FY26E | O13: =H$13 -> FY27E | P13: =I$13 -> FY28E
B14: Cash | D14: Network Sales | K14: Cash | M14: =VLOOKUP($B14,BS!$1:$1048576,MATCH(F$37,BS!$3:$3,0),FALSE) -> 138.774 | N14: =VLOOKUP($B14,BS!$1:$1048576,MATCH(G$37,BS!$3:$3,0),FALSE) -> 262.54586 | O14: =VLOOKUP($B14,BS!$1:$1048576,MATCH(H$37,BS!$3:$3,0),FALSE) -> 477.70275 | P14: =VLOOKUP($B14,BS!$1:$1048576,MATCH(I$37,BS!$3:$3,0),FALSE) -> 723.6438
A15: Australia Sales | B15: TR | D15: Australia | E15: =VLOOKUP($A15,Model!$1:$1048576,MATCH(L$51,Model!$3:$3,0),FALSE) -> 7909.9 | F15: =VLOOKUP($A15,Model!$1:$1048576,MATCH(M$51,Model!$3:$3,0),FALSE) -> 8968.9 | G15: =VLOOKUP($A15,Model!$1:$1048576,MATCH(N$51,Model!$3:$3,0),FALSE) -> 10113.441 | H15: =VLOOKUP($A15,Model!$1:$1048576,MATCH(O$51,Model!$3:$3,0),FALSE) -> 11091.441 | I15: =VLOOKUP($A15,Model!$1:$1048576,MATCH(P$51,Model!$3:$3,0),FALSE) -> 11821.77 | K15: Trade receivables | M15: =VLOOKUP($B15,BS!$1:$1048576,MATCH(F$37,BS!$3:$3,0),FALSE) -> 1575.136 | N15: =VLOOKUP($B15,BS!$1:$1048576,MATCH(G$37,BS!$3:$3,0),FALSE) -> 1709.8835 | O15: =VLOOKUP($B15,BS!$1:$1048576,MATCH(H$37,BS!$3:$3,0),FALSE) -> 1838.0483 | P15: =VLOOKUP($B15,BS!$1:$1048576,MATCH(I$37,BS!$3:$3,0),FALSE) -> 1992.8447
A16: NZ Sales | B16: Inventories | D16: New Zealand | E16: =VLOOKUP($A16,Model!$1:$1048576,MATCH(L$51,Model!$3:$3,0),FALSE) -> 886 | F16: =VLOOKUP($A16,Model!$1:$1048576,MATCH(M$51,Model!$3:$3,0),FALSE) -> 1050 | G16: =VLOOKUP($A16,Model!$1:$1048576,MATCH(N$51,Model!$3:$3,0),FALSE) -> 1297.6967 | H16: =VLOOKUP($A16,Model!$1:$1048576,MATCH(O$51,Model!$3:$3,0),FALSE) -> 1533.3311 | I16: =VLOOKUP($A16,Model!$1:$1048576,MATCH(P$51,Model!$3:$3,0),FALSE) -> 1788.292 | K16: Inventories | M16: =VLOOKUP($B16,BS!$1:$1048576,MATCH(F$37,BS!$3:$3,0),FALSE) -> 1019.778 | N16: =VLOOKUP($B16,BS!$1:$1048576,MATCH(G$37,BS!$3:$3,0),FALSE) -> 1171.1085 | O16: =VLOOKUP($B16,BS!$1:$1048576,MATCH(H$37,BS!$3:$3,0),FALSE) -> 1247.247 | P16: =VLOOKUP($B16,BS!$1:$1048576,MATCH(I$37,BS!$3:$3,0),FALSE) -> 1281.1144
A17: Ireland Sales | B17: Lease CA | D17: Ireland | E17: =VLOOKUP($A17,Model!$1:$1048576,MATCH(L$51,Model!$3:$3,0),FALSE) -> 105.69921 | F17: =VLOOKUP($A17,Model!$1:$1048576,MATCH(M$51,Model!$3:$3,0),FALSE) -> 167.47139 | G17: =VLOOKUP($A17,Model!$1:$1048576,MATCH(N$51,Model!$3:$3,0),FALSE) -> 266.16179 | H17: =VLOOKUP($A17,Model!$1:$1048576,MATCH(O$51,Model!$3:$3,0),FALSE) -> 368.14378 | I17: =VLOOKUP($A17,Model!$1:$1048576,MATCH(P$51,Model!$3:$3,0),FALSE) -> 467.54261 | K17: Lease Receivables | M17: =VLOOKUP($B17,BS!$1:$1048576,MATCH(F$37,BS!$3:$3,0),FALSE) -> 139.656 | N17: =VLOOKUP($B17,BS!$1:$1048576,MATCH(G$37,BS!$3:$3,0),FALSE) -> 139.656 | O17: =VLOOKUP($B17,BS!$1:$1048576,MATCH(H$37,BS!$3:$3,0),FALSE) -> 139.656 | P17: =VLOOKUP($B17,BS!$1:$1048576,MATCH(I$37,BS!$3:$3,0),FALSE) -> 139.656
A18: China Sales | B18: Other CA | D18: China | E18: =VLOOKUP($A18,Model!$1:$1048576,MATCH(L$51,Model!$3:$3,0),FALSE) -> 100.30079 | F18: =VLOOKUP($A18,Model!$1:$1048576,MATCH(M$51,Model!$3:$3,0),FALSE) -> 72.128605 | G18: =VLOOKUP($A18,Model!$1:$1048576,MATCH(N$51,Model!$3:$3,0),FALSE) -> 80 | H18: =VLOOKUP($A18,Model!$1:$1048576,MATCH(O$51,Model!$3:$3,0),FALSE) -> 80 | I18: =VLOOKUP($A18,Model!$1:$1048576,MATCH(P$51,Model!$3:$3,0),FALSE) -> 80 | K18: Other current assets | M18: =VLOOKUP($B18,BS!$1:$1048576,MATCH(F$37,BS!$3:$3,0),FALSE) -> 34.573 | N18: =VLOOKUP($B18,BS!$1:$1048576,MATCH(G$37,BS!$3:$3,0),FALSE) -> 34.573 | O18: =VLOOKUP($B18,BS!$1:$1048576,MATCH(H$37,BS!$3:$3,0),FALSE) -> 34.573 | P18: =VLOOKUP($B18,BS!$1:$1048576,MATCH(I$37,BS!$3:$3,0),FALSE) -> 34.573
A19: Dubai Sales | B19: CA | D19: Dubai | E19: =VLOOKUP($A19,Model!$1:$1048576,MATCH(L$51,Model!$3:$3,0),FALSE) -> 0 | F19: =VLOOKUP($A19,Model!$1:$1048576,MATCH(M$51,Model!$3:$3,0),FALSE) -> 10 | G19: =VLOOKUP($A19,Model!$1:$1048576,MATCH(N$51,Model!$3:$3,0),FALSE) -> 35 | H19: =VLOOKUP($A19,Model!$1:$1048576,MATCH(O$51,Model!$3:$3,0),FALSE) -> 56 | I19: =VLOOKUP($A19,Model!$1:$1048576,MATCH(P$51,Model!$3:$3,0),FALSE) -> 77 | K19: Current assets | M19: =VLOOKUP($B19,BS!$1:$1048576,MATCH(F$37,BS!$3:$3,0),FALSE) -> 2908.429 | N19: =VLOOKUP($B19,BS!$1:$1048576,MATCH(G$37,BS!$3:$3,0),FALSE) -> 3318.2789 | O19: =VLOOKUP($B19,BS!$1:$1048576,MATCH(H$37,BS!$3:$3,0),FALSE) -> 3737.7391 | P19: =VLOOKUP($B19,BS!$1:$1048576,MATCH(I$37,BS!$3:$3,0),FALSE) -> 4172.3439
A20: Total network sales | B20: PPE | D20: Total Network Sales | E20: =VLOOKUP($A20,Model!$1:$1048576,MATCH(L$51,Model!$3:$3,0),FALSE) -> 9001.9 | F20: =VLOOKUP($A20,Model!$1:$1048576,MATCH(M$51,Model!$3:$3,0),FALSE) -> 10268.5 | G20: =VLOOKUP($A20,Model!$1:$1048576,MATCH(N$51,Model!$3:$3,0),FALSE) -> 11792.3 | H20: =VLOOKUP($A20,Model!$1:$1048576,MATCH(O$51,Model!$3:$3,0),FALSE) -> 13128.916 | I20: =VLOOKUP($A20,Model!$1:$1048576,MATCH(P$51,Model!$3:$3,0),FALSE) -> 14234.605 | K20: PPE | M20: =VLOOKUP($B20,BS!$1:$1048576,MATCH(F$37,BS!$3:$3,0),FALSE) -> 320.438 | N20: =VLOOKUP($B20,BS!$1:$1048576,MATCH(G$37,BS!$3:$3,0),FALSE) -> 340.93442 | O20: =VLOOKUP($B20,BS!$1:$1048576,MATCH(H$37,BS!$3:$3,0),FALSE) -> 364.10258 | P20: =VLOOKUP($B20,BS!$1:$1048576,MATCH(I$37,BS!$3:$3,0),FALSE) -> 390.17511
A21: Total network sales growth | B21: Lease NCA | D21: Growth % | E21: =VLOOKUP($A21,Model!$1:$1048576,MATCH(L$51,Model!$3:$3,0),FALSE) -> 0.1412145 | F21: =VLOOKUP($A21,Model!$1:$1048576,MATCH(M$51,Model!$3:$3,0),FALSE) -> 0.14070363 | G21: =VLOOKUP($A21,Model!$1:$1048576,MATCH(N$51,Model!$3:$3,0),FALSE) -> 0.14839558 | H21: =VLOOKUP($A21,Model!$1:$1048576,MATCH(O$51,Model!$3:$3,0),FALSE) -> 0.11334653 | I21: =VLOOKUP($A21,Model!$1:$1048576,MATCH(P$51,Model!$3:$3,0),FALSE) -> 0.0842178 | K21: Lease assets | M21: =VLOOKUP($B21,BS!$1:$1048576,MATCH(F$37,BS!$3:$3,0),FALSE) -> 821.668 | N21: =VLOOKUP($B21,BS!$1:$1048576,MATCH(G$37,BS!$3:$3,0),FALSE) -> 686.24127 | O21: =VLOOKUP($B21,BS!$1:$1048576,MATCH(H$37,BS!$3:$3,0),FALSE) -> 545.70053 | P21: =VLOOKUP($B21,BS!$1:$1048576,MATCH(I$37,BS!$3:$3,0),FALSE) -> 398.15169
A22: Total Revenue | B22: Intangibles | D22: Revenue | E22: =VLOOKUP($A22,Model!$1:$1048576,MATCH(L$51,Model!$3:$3,0),FALSE) -> 6655.7 | F22: =VLOOKUP($A22,Model!$1:$1048576,MATCH(M$51,Model!$3:$3,0),FALSE) -> 9591.3 | G22: =VLOOKUP($A22,Model!$1:$1048576,MATCH(N$51,Model!$3:$3,0),FALSE) -> 10928.785 | H22: =VLOOKUP($A22,Model!$1:$1048576,MATCH(O$51,Model!$3:$3,0),FALSE) -> 12084.819 | I22: =VLOOKUP($A22,Model!$1:$1048576,MATCH(P$51,Model!$3:$3,0),FALSE) -> 12985.047 | K22: Intangibles | M22: =VLOOKUP($B22,BS!$1:$1048576,MATCH(F$37,BS!$3:$3,0),FALSE) -> 3860.481 | N22: =VLOOKUP($B22,BS!$1:$1048576,MATCH(G$37,BS!$3:$3,0),FALSE) -> 3860.481 | O22: =VLOOKUP($B22,BS!$1:$1048576,MATCH(H$37,BS!$3:$3,0),FALSE) -> 3860.481 | P22: =VLOOKUP($B22,BS!$1:$1048576,MATCH(I$37,BS!$3:$3,0),FALSE) -> 3860.481
A23: Gross Profit | B23: Other NCA | D23: Gross Profit | E23: =VLOOKUP($A23,Model!$1:$1048576,MATCH(L$51,Model!$3:$3,0),FALSE) -> 1312.3 | F23: =VLOOKUP($A23,Model!$1:$1048576,MATCH(M$51,Model!$3:$3,0),FALSE) -> 1698.6 | G23: =VLOOKUP($A23,Model!$1:$1048576,MATCH(N$51,Model!$3:$3,0),FALSE) -> 1947.127 | H23: =VLOOKUP($A23,Model!$1:$1048576,MATCH(O$51,Model!$3:$3,0),FALSE) -> 2185.1573 | I23: =VLOOKUP($A23,Model!$1:$1048576,MATCH(P$51,Model!$3:$3,0),FALSE) -> 2390.5383 | K23: Other non current assets | M23: =VLOOKUP($B23,BS!$1:$1048576,MATCH(F$37,BS!$3:$3,0),FALSE) -> 6.781 | N23: =VLOOKUP($B23,BS!$1:$1048576,MATCH(G$37,BS!$3:$3,0),FALSE) -> 6.781 | O23: =VLOOKUP($B23,BS!$1:$1048576,MATCH(H$37,BS!$3:$3,0),FALSE) -> 6.781 | P23: =VLOOKUP($B23,BS!$1:$1048576,MATCH(I$37,BS!$3:$3,0),FALSE) -> 6.781
A24: CoDB | B24: NCA | D24: CoDB | E24: =VLOOKUP($A24,Model!$1:$1048576,MATCH(L$51,Model!$3:$3,0),FALSE) -> -705.4 | F24: =VLOOKUP($A24,Model!$1:$1048576,MATCH(M$51,Model!$3:$3,0),FALSE) -> -783 | G24: =VLOOKUP($A24,Model!$1:$1048576,MATCH(N$51,Model!$3:$3,0),FALSE) -> -841.67909 | H24: =VLOOKUP($A24,Model!$1:$1048576,MATCH(O$51,Model!$3:$3,0),FALSE) -> -901.83369 | I24: =VLOOKUP($A24,Model!$1:$1048576,MATCH(P$51,Model!$3:$3,0),FALSE) -> -944.87431 | K24: Non-current assets | M24: =VLOOKUP($B24,BS!$1:$1048576,MATCH(F$37,BS!$3:$3,0),FALSE) -> 5379.373 | N24: =VLOOKUP($B24,BS!$1:$1048576,MATCH(G$37,BS!$3:$3,0),FALSE) -> 5396.7423 | O24: =VLOOKUP($B24,BS!$1:$1048576,MATCH(H$37,BS!$3:$3,0),FALSE) -> 5416.2441 | P24: =VLOOKUP($B24,BS!$1:$1048576,MATCH(I$37,BS!$3:$3,0),FALSE) -> 5437.9115
A25: EBITDA | B25: TP | D25: EBITDA | E25: =VLOOKUP($A25,Model!$1:$1048576,MATCH(L$51,Model!$3:$3,0),FALSE) -> 675.1 | F25: =VLOOKUP($A25,Model!$1:$1048576,MATCH(M$51,Model!$3:$3,0),FALSE) -> 968.5 | G25: =VLOOKUP($A25,Model!$1:$1048576,MATCH(N$51,Model!$3:$3,0),FALSE) -> 1201.5729 | H25: =VLOOKUP($A25,Model!$1:$1048576,MATCH(O$51,Model!$3:$3,0),FALSE) -> 1424.6573 | I25: =VLOOKUP($A25,Model!$1:$1048576,MATCH(P$51,Model!$3:$3,0),FALSE) -> 1633.2645 | K25: Trade payables | M25: =VLOOKUP($B25,BS!$1:$1048576,MATCH(F$37,BS!$3:$3,0),FALSE) -> 1323.603 | N25: =VLOOKUP($B25,BS!$1:$1048576,MATCH(G$37,BS!$3:$3,0),FALSE) -> 1520.0198 | O25: =VLOOKUP($B25,BS!$1:$1048576,MATCH(H$37,BS!$3:$3,0),FALSE) -> 1692.3088 | P25: =VLOOKUP($B25,BS!$1:$1048576,MATCH(I$37,BS!$3:$3,0),FALSE) -> 1834.8313
A26: D&A | B26: Current Borrowings | D26: D&A | E26: =VLOOKUP($A26,Model!$1:$1048576,MATCH(L$51,Model!$3:$3,0),FALSE) -> -69.6 | F26: =VLOOKUP($A26,Model!$1:$1048576,MATCH(M$51,Model!$3:$3,0),FALSE) -> -65.1 | G26: =VLOOKUP($A26,Model!$1:$1048576,MATCH(N$51,Model!$3:$3,0),FALSE) -> -68.355 | H26: =VLOOKUP($A26,Model!$1:$1048576,MATCH(O$51,Model!$3:$3,0),FALSE) -> -71.77275 | I26: =VLOOKUP($A26,Model!$1:$1048576,MATCH(P$51,Model!$3:$3,0),FALSE) -> -75.361388 | K26: Borrowings | M26: =VLOOKUP($B26,BS!$1:$1048576,MATCH(F$37,BS!$3:$3,0),FALSE) -> 35.643 | N26: =VLOOKUP($B26,BS!$1:$1048576,MATCH(G$37,BS!$3:$3,0),FALSE) -> 35.643 | O26: =VLOOKUP($B26,BS!$1:$1048576,MATCH(H$37,BS!$3:$3,0),FALSE) -> 35.643 | P26: =VLOOKUP($B26,BS!$1:$1048576,MATCH(I$37,BS!$3:$3,0),FALSE) -> 35.643
A27: EBIT | B27: Lease CL | D27: Total EBIT | E27: =VLOOKUP($A27,Model!$1:$1048576,MATCH(L$51,Model!$3:$3,0),FALSE) -> 605.5 | F27: =VLOOKUP($A27,Model!$1:$1048576,MATCH(M$51,Model!$3:$3,0),FALSE) -> 903.4 | G27: =VLOOKUP($A27,Model!$1:$1048576,MATCH(N$51,Model!$3:$3,0),FALSE) -> 1133.2179 | H27: =VLOOKUP($A27,Model!$1:$1048576,MATCH(O$51,Model!$3:$3,0),FALSE) -> 1352.8846 | I27: =VLOOKUP($A27,Model!$1:$1048576,MATCH(P$51,Model!$3:$3,0),FALSE) -> 1557.9031 | K27: Lease liabilities | M27: =VLOOKUP($B27,BS!$1:$1048576,MATCH(F$37,BS!$3:$3,0),FALSE) -> 157.975 | N27: =VLOOKUP($B27,BS!$1:$1048576,MATCH(G$37,BS!$3:$3,0),FALSE) -> 157.975 | O27: =VLOOKUP($B27,BS!$1:$1048576,MATCH(H$37,BS!$3:$3,0),FALSE) -> 157.975 | P27: =VLOOKUP($B27,BS!$1:$1048576,MATCH(I$37,BS!$3:$3,0),FALSE) -> 157.975
A28: Net interest | B28: CL | D28: Net interest | F28: =VLOOKUP($A28,PL!$1:$1048576,MATCH(M$51,PL!$3:$3,0),FALSE) -> -24.1 | G28: =VLOOKUP($A28,PL!$1:$1048576,MATCH(N$51,PL!$3:$3,0),FALSE) -> -50 | H28: =VLOOKUP($A28,PL!$1:$1048576,MATCH(O$51,PL!$3:$3,0),FALSE) -> -46 | I28: =VLOOKUP($A28,PL!$1:$1048576,MATCH(P$51,PL!$3:$3,0),FALSE) -> -40 | K28: Current liabilities | M28: =VLOOKUP($B28,BS!$1:$1048576,MATCH(F$37,BS!$3:$3,0),FALSE) -> 1702.865 | N28: =VLOOKUP($B28,BS!$1:$1048576,MATCH(G$37,BS!$3:$3,0),FALSE) -> 1899.2818 | O28: =VLOOKUP($B28,BS!$1:$1048576,MATCH(H$37,BS!$3:$3,0),FALSE) -> 2071.5708 | P28: =VLOOKUP($B28,BS!$1:$1048576,MATCH(I$37,BS!$3:$3,0),FALSE) -> 2214.0933
A29: PBT | B29: Lease NCA | D29: PBT | F29: =VLOOKUP($A29,PL!$1:$1048576,MATCH(M$51,PL!$3:$3,0),FALSE) -> 879.3 | G29: =VLOOKUP($A29,PL!$1:$1048576,MATCH(N$51,PL!$3:$3,0),FALSE) -> 1083.2179 | H29: =VLOOKUP($A29,PL!$1:$1048576,MATCH(O$51,PL!$3:$3,0),FALSE) -> 1306.8846 | I29: =VLOOKUP($A29,PL!$1:$1048576,MATCH(P$51,PL!$3:$3,0),FALSE) -> 1517.9031 | K29: Lease liabilities | M29: =VLOOKUP($B29,BS!$1:$1048576,MATCH(F$37,BS!$3:$3,0),FALSE) -> 821.668 | N29: =VLOOKUP($B29,BS!$1:$1048576,MATCH(G$37,BS!$3:$3,0),FALSE) -> 686.24127 | O29: =VLOOKUP($B29,BS!$1:$1048576,MATCH(H$37,BS!$3:$3,0),FALSE) -> 545.70053 | P29: =VLOOKUP($B29,BS!$1:$1048576,MATCH(I$37,BS!$3:$3,0),FALSE) -> 398.15169
A30: Tax | B30: NC Borrowings | D30: Tax | F30: =VLOOKUP($A30,PL!$1:$1048576,MATCH(M$51,PL!$3:$3,0),FALSE) -> -254.997 | G30: =VLOOKUP($A30,PL!$1:$1048576,MATCH(N$51,PL!$3:$3,0),FALSE) -> -314.1332 | H30: =VLOOKUP($A30,PL!$1:$1048576,MATCH(O$51,PL!$3:$3,0),FALSE) -> -378.99653 | I30: =VLOOKUP($A30,PL!$1:$1048576,MATCH(P$51,PL!$3:$3,0),FALSE) -> -440.19191 | K30: Borrowings | M30: =VLOOKUP($B30,BS!$1:$1048576,MATCH(F$37,BS!$3:$3,0),FALSE) -> 855.292 | N30: =VLOOKUP($B30,BS!$1:$1048576,MATCH(G$37,BS!$3:$3,0),FALSE) -> 855.292 | O30: =VLOOKUP($B30,BS!$1:$1048576,MATCH(H$37,BS!$3:$3,0),FALSE) -> 855.292 | P30: =VLOOKUP($B30,BS!$1:$1048576,MATCH(I$37,BS!$3:$3,0),FALSE) -> 855.292
A31: Minorities | B31: Other NCL | D31: Minority interest | F31: =VLOOKUP($A31,PL!$1:$1048576,MATCH(M$51,PL!$3:$3,0),FALSE) -> -4.5 | G31: =VLOOKUP($A31,PL!$1:$1048576,MATCH(N$51,PL!$3:$3,0),FALSE) -> -7.8058614 | H31: =VLOOKUP($A31,PL!$1:$1048576,MATCH(O$51,PL!$3:$3,0),FALSE) -> -11.184447 | I31: =VLOOKUP($A31,PL!$1:$1048576,MATCH(P$51,PL!$3:$3,0),FALSE) -> -14.100187 | K31: Other non-current liabilities | M31: =VLOOKUP($B31,BS!$1:$1048576,MATCH(F$37,BS!$3:$3,0),FALSE) -> 17.104 | N31: =VLOOKUP($B31,BS!$1:$1048576,MATCH(G$37,BS!$3:$3,0),FALSE) -> 17.104 | O31: =VLOOKUP($B31,BS!$1:$1048576,MATCH(H$37,BS!$3:$3,0),FALSE) -> 17.104 | P31: =VLOOKUP($B31,BS!$1:$1048576,MATCH(I$37,BS!$3:$3,0),FALSE) -> 17.104
A32: NPAT | B32: NCL | D32: NPAT | F32: =VLOOKUP($A32,PL!$1:$1048576,MATCH(M$51,PL!$3:$3,0),FALSE) -> 619.803 | G32: =VLOOKUP($A32,PL!$1:$1048576,MATCH(N$51,PL!$3:$3,0),FALSE) -> 761.27888 | H32: =VLOOKUP($A32,PL!$1:$1048576,MATCH(O$51,PL!$3:$3,0),FALSE) -> 916.70362 | I32: =VLOOKUP($A32,PL!$1:$1048576,MATCH(P$51,PL!$3:$3,0),FALSE) -> 1063.611 | K32: Non-current liabilities | M32: =VLOOKUP($B32,BS!$1:$1048576,MATCH(F$37,BS!$3:$3,0),FALSE) -> 1924.342 | N32: =VLOOKUP($B32,BS!$1:$1048576,MATCH(G$37,BS!$3:$3,0),FALSE) -> 1926.0548 | O32: =VLOOKUP($B32,BS!$1:$1048576,MATCH(H$37,BS!$3:$3,0),FALSE) -> 1927.8323 | P32: =VLOOKUP($B32,BS!$1:$1048576,MATCH(I$37,BS!$3:$3,0),FALSE) -> 1929.6985
A33: Shares Diluted | B33: Contributed Equity | D33: Shares (m) | F33: =VLOOKUP($A33,PL!$1:$1048576,MATCH(M$51,PL!$3:$3,0),FALSE) -> 11540 | G33: =VLOOKUP($A33,PL!$1:$1048576,MATCH(N$51,PL!$3:$3,0),FALSE) -> 11540 | H33: =VLOOKUP($A33,PL!$1:$1048576,MATCH(O$51,PL!$3:$3,0),FALSE) -> 11540 | I33: =VLOOKUP($A33,PL!$1:$1048576,MATCH(P$51,PL!$3:$3,0),FALSE) -> 11540 | K33: Contributed equity | M33: =VLOOKUP($B33,BS!$1:$1048576,MATCH(F$37,BS!$3:$3,0),FALSE) -> 4403.299 | N33: =VLOOKUP($B33,BS!$1:$1048576,MATCH(G$37,BS!$3:$3,0),FALSE) -> 4403.299 | O33: =VLOOKUP($B33,BS!$1:$1048576,MATCH(H$37,BS!$3:$3,0),FALSE) -> 4403.299 | P33: =VLOOKUP($B33,BS!$1:$1048576,MATCH(I$37,BS!$3:$3,0),FALSE) -> 4403.299
A34: EPS | B34: Reserves | D34: EPS | F34: =VLOOKUP($A34,PL!$1:$1048576,MATCH(M$51,PL!$3:$3,0),FALSE) -> 0.053709099 | G34: =VLOOKUP($A34,PL!$1:$1048576,MATCH(N$51,PL!$3:$3,0),FALSE) -> 0.065968707 | H34: =VLOOKUP($A34,PL!$1:$1048576,MATCH(O$51,PL!$3:$3,0),FALSE) -> 0.079437055 | I34: =VLOOKUP($A34,PL!$1:$1048576,MATCH(P$51,PL!$3:$3,0),FALSE) -> 0.092167335 | K34: Reserves | M34: =VLOOKUP($B34,BS!$1:$1048576,MATCH(F$37,BS!$3:$3,0),FALSE) -> -6.023 | N34: =VLOOKUP($B34,BS!$1:$1048576,MATCH(G$37,BS!$3:$3,0),FALSE) -> -6.023 | O34: =VLOOKUP($B34,BS!$1:$1048576,MATCH(H$37,BS!$3:$3,0),FALSE) -> -6.023 | P34: =VLOOKUP($B34,BS!$1:$1048576,MATCH(I$37,BS!$3:$3,0),FALSE) -> -6.023
A35: DPS | B35: Retained Profits | D35: DPS total | G35: =VLOOKUP($A35,PL!$1:$1048576,MATCH(N$51,PL!$3:$3,0),FALSE) -> 0.046178095 | H35: =VLOOKUP($A35,PL!$1:$1048576,MATCH(O$51,PL!$3:$3,0),FALSE) -> 0.055605939 | I35: =VLOOKUP($A35,PL!$1:$1048576,MATCH(P$51,PL!$3:$3,0),FALSE) -> 0.064517134 | K35: Retained Profits | M35: =VLOOKUP($B35,BS!$1:$1048576,MATCH(F$37,BS!$3:$3,0),FALSE) -> 273.263 | N35: =VLOOKUP($B35,BS!$1:$1048576,MATCH(G$37,BS!$3:$3,0),FALSE) -> 494.54666 | O35: =VLOOKUP($B35,BS!$1:$1048576,MATCH(H$37,BS!$3:$3,0),FALSE) -> 748.25775 | P35: =VLOOKUP($B35,BS!$1:$1048576,MATCH(I$37,BS!$3:$3,0),FALSE) -> 1046.0411
B36: Minorities | K36: Minority Interests | M36: =VLOOKUP($B36,BS!$1:$1048576,MATCH(F$37,BS!$3:$3,0),FALSE) -> -9.944 | N36: =VLOOKUP($B36,BS!$1:$1048576,MATCH(G$37,BS!$3:$3,0),FALSE) -> -2.1381386 | O36: =VLOOKUP($B36,BS!$1:$1048576,MATCH(H$37,BS!$3:$3,0),FALSE) -> 9.0463083 | P36: =VLOOKUP($B36,BS!$1:$1048576,MATCH(I$37,BS!$3:$3,0),FALSE) -> 23.146495
B37: Equity | D37: Cash Flow | E37: FY24 | F37: FY25 | G37: FY26E | H37: FY27E | I37: FY28E | K37: Total Equity | M37: =VLOOKUP($B37,BS!$1:$1048576,MATCH(F$37,BS!$3:$3,0),FALSE) -> 4660.595 | N37: =VLOOKUP($B37,BS!$1:$1048576,MATCH(G$37,BS!$3:$3,0),FALSE) -> 4889.6845 | O37: =VLOOKUP($B37,BS!$1:$1048576,MATCH(H$37,BS!$3:$3,0),FALSE) -> 5154.5801 | P37: =VLOOKUP($B37,BS!$1:$1048576,MATCH(I$37,BS!$3:$3,0),FALSE) -> 5466.4636
A38: EBIT | B38: Net Debt | D38: EBIT | F38: =VLOOKUP($A38,CF!$1:$1048576,MATCH(F$37,CF!$3:$3,0),FALSE) -> 903.4 | G38: =VLOOKUP($A38,CF!$1:$1048576,MATCH(G$37,CF!$3:$3,0),FALSE) -> 1133.2179 | H38: =VLOOKUP($A38,CF!$1:$1048576,MATCH(H$37,CF!$3:$3,0),FALSE) -> 1352.8846 | I38: =VLOOKUP($A38,CF!$1:$1048576,MATCH(I$37,CF!$3:$3,0),FALSE) -> 1557.9031 | K38: Net debt ex leases | M38: =VLOOKUP($B38,BS!$1:$1048576,MATCH(F$37,BS!$3:$3,0),FALSE) -> 752.161 | N38: =VLOOKUP($B38,BS!$1:$1048576,MATCH(G$37,BS!$3:$3,0),FALSE) -> 628.38914 | O38: =VLOOKUP($B38,BS!$1:$1048576,MATCH(H$37,BS!$3:$3,0),FALSE) -> 413.23225 | P38: =VLOOKUP($B38,BS!$1:$1048576,MATCH(I$37,BS!$3:$3,0),FALSE) -> 167.2912
A39: D&A | D39: D&A | F39: =VLOOKUP($A39,CF!$1:$1048576,MATCH(F$37,CF!$3:$3,0),FALSE) -> 65.1 | G39: =VLOOKUP($A39,CF!$1:$1048576,MATCH(G$37,CF!$3:$3,0),FALSE) -> 68.355 | H39: =VLOOKUP($A39,CF!$1:$1048576,MATCH(H$37,CF!$3:$3,0),FALSE) -> 71.77275 | I39: =VLOOKUP($A39,CF!$1:$1048576,MATCH(I$37,CF!$3:$3,0),FALSE) -> 75.361388 | K39: Divisional Key Metrics | L39: =E$13 -> FY24 | M39: =F$13 -> FY25 | N39: =G$13 -> FY26E | O39: =H$13 -> FY27E | P39: =I$13 -> FY28E
A40: Net interest | D40: Net interest | F40: =VLOOKUP($A40,CF!$1:$1048576,MATCH(F$37,CF!$3:$3,0),FALSE) -> -24.1 | G40: =VLOOKUP($A40,CF!$1:$1048576,MATCH(G$37,CF!$3:$3,0),FALSE) -> -50 | H40: =VLOOKUP($A40,CF!$1:$1048576,MATCH(H$37,CF!$3:$3,0),FALSE) -> -46 | I40: =VLOOKUP($A40,CF!$1:$1048576,MATCH(I$37,CF!$3:$3,0),FALSE) -> -40 | K40: LFL Sales Growth
A41: Tax | B41: Australia LFL | D41: Tax | F41: =VLOOKUP($A41,CF!$1:$1048576,MATCH(F$37,CF!$3:$3,0),FALSE) -> -254.997 | G41: =VLOOKUP($A41,CF!$1:$1048576,MATCH(G$37,CF!$3:$3,0),FALSE) -> -314.1332 | H41: =VLOOKUP($A41,CF!$1:$1048576,MATCH(H$37,CF!$3:$3,0),FALSE) -> -378.99653 | I41: =VLOOKUP($A41,CF!$1:$1048576,MATCH(I$37,CF!$3:$3,0),FALSE) -> -440.19191 | K41: Australia LFL | L41: =VLOOKUP($B41,Model!$1:$1048576,MATCH(L$51,Model!$3:$3,0),FALSE) -> 0.098 | M41: =VLOOKUP($B41,Model!$1:$1048576,MATCH(M$51,Model!$3:$3,0),FALSE) -> 0.113 | N41: =VLOOKUP($B41,Model!$1:$1048576,MATCH(N$51,Model!$3:$3,0),FALSE) -> 0.11 | O41: =VLOOKUP($B41,Model!$1:$1048576,MATCH(O$51,Model!$3:$3,0),FALSE) -> 0.08 | P41: =VLOOKUP($B41,Model!$1:$1048576,MATCH(P$51,Model!$3:$3,0),FALSE) -> 0.05
A42: Chg WC | B42: International LFL | D42: Change in net working capital | F42: =VLOOKUP($A42,CF!$1:$1048576,MATCH(F$37,CF!$3:$3,0),FALSE) -> -722.22 | G42: =VLOOKUP($A42,CF!$1:$1048576,MATCH(G$37,CF!$3:$3,0),FALSE) -> -89.661211 | H42: =VLOOKUP($A42,CF!$1:$1048576,MATCH(H$37,CF!$3:$3,0),FALSE) -> -32.014301 | I42: =VLOOKUP($A42,CF!$1:$1048576,MATCH(I$37,CF!$3:$3,0),FALSE) -> -46.141237 | K42: International LFL | L42: =VLOOKUP($B42,Model!$1:$1048576,MATCH(L$51,Model!$3:$3,0),FALSE) -> 0.144 | M42: =VLOOKUP($B42,Model!$1:$1048576,MATCH(M$51,Model!$3:$3,0),FALSE) -> 0.081 | N42: =VLOOKUP($B42,Model!$1:$1048576,MATCH(N$51,Model!$3:$3,0),FALSE) -> 0.1 | O42: =VLOOKUP($B42,Model!$1:$1048576,MATCH(O$51,Model!$3:$3,0),FALSE) -> 0.08 | P42: =VLOOKUP($B42,Model!$1:$1048576,MATCH(P$51,Model!$3:$3,0),FALSE) -> 0.08
A43: Other | D43: Other | F43: =VLOOKUP($A43,CF!$1:$1048576,MATCH(F$37,CF!$3:$3,0),FALSE) -> 631.645 | G43: =VLOOKUP($A43,CF!$1:$1048576,MATCH(G$37,CF!$3:$3,0),FALSE) -> -7.1 | H43: =VLOOKUP($A43,CF!$1:$1048576,MATCH(H$37,CF!$3:$3,0),FALSE) -> -21.3 | I43: =VLOOKUP($A43,CF!$1:$1048576,MATCH(I$37,CF!$3:$3,0),FALSE) -> -21.3 | K43: Store Count
A44: OCF | B44: Australia Stores | D44: Operating cashflow | F44: =VLOOKUP($A44,CF!$1:$1048576,MATCH(F$37,CF!$3:$3,0),FALSE) -> 598.828 | G44: =VLOOKUP($A44,CF!$1:$1048576,MATCH(G$37,CF!$3:$3,0),FALSE) -> 740.67853 | H44: =VLOOKUP($A44,CF!$1:$1048576,MATCH(H$37,CF!$3:$3,0),FALSE) -> 946.34651 | I44: =VLOOKUP($A44,CF!$1:$1048576,MATCH(I$37,CF!$3:$3,0),FALSE) -> 1085.6314 | K44: Australia | L44: =VLOOKUP($B44,Model!$1:$1048576,MATCH(L$51,Model!$3:$3,0),FALSE) -> 567 | M44: =VLOOKUP($B44,Model!$1:$1048576,MATCH(M$51,Model!$3:$3,0),FALSE) -> 569 | N44: =VLOOKUP($B44,Model!$1:$1048576,MATCH(N$51,Model!$3:$3,0),FALSE) -> 587 | O44: =VLOOKUP($B44,Model!$1:$1048576,MATCH(O$51,Model!$3:$3,0),FALSE) -> 605 | P44: =VLOOKUP($B44,Model!$1:$1048576,MATCH(P$51,Model!$3:$3,0),FALSE) -> 623
A45: Capex | B45: NZ Stores | D45: Net capex | F45: =VLOOKUP($A45,CF!$1:$1048576,MATCH(F$37,CF!$3:$3,0),FALSE) -> -52.562 | G45: =VLOOKUP($A45,CF!$1:$1048576,MATCH(G$37,CF!$3:$3,0),FALSE) -> -60 | H45: =VLOOKUP($A45,CF!$1:$1048576,MATCH(H$37,CF!$3:$3,0),FALSE) -> -65 | I45: =VLOOKUP($A45,CF!$1:$1048576,MATCH(I$37,CF!$3:$3,0),FALSE) -> -70 | K45: New Zealand | L45: =VLOOKUP($B45,Model!$1:$1048576,MATCH(L$51,Model!$3:$3,0),FALSE) -> 50 | M45: =VLOOKUP($B45,Model!$1:$1048576,MATCH(M$51,Model!$3:$3,0),FALSE) -> 61 | N45: =VLOOKUP($B45,Model!$1:$1048576,MATCH(N$51,Model!$3:$3,0),FALSE) -> 76 | O45: =VLOOKUP($B45,Model!$1:$1048576,MATCH(O$51,Model!$3:$3,0),FALSE) -> 86 | P45: =VLOOKUP($B45,Model!$1:$1048576,MATCH(P$51,Model!$3:$3,0),FALSE) -> 96
A46: Acquisitions | B46: Ireland Stores | D46: Acquisitions | F46: =VLOOKUP($A46,CF!$1:$1048576,MATCH(F$37,CF!$3:$3,0),FALSE) -> -8.988 | G46: =VLOOKUP($A46,CF!$1:$1048576,MATCH(G$37,CF!$3:$3,0),FALSE) -> 0 | H46: =VLOOKUP($A46,CF!$1:$1048576,MATCH(H$37,CF!$3:$3,0),FALSE) -> 0 | I46: =VLOOKUP($A46,CF!$1:$1048576,MATCH(I$37,CF!$3:$3,0),FALSE) -> 0 | K46: Ireland | L46: =VLOOKUP($B46,Model!$1:$1048576,MATCH(L$51,Model!$3:$3,0),FALSE) -> 10 | M46: =VLOOKUP($B46,Model!$1:$1048576,MATCH(M$51,Model!$3:$3,0),FALSE) -> 14 | N46: =VLOOKUP($B46,Model!$1:$1048576,MATCH(N$51,Model!$3:$3,0),FALSE) -> 19 | O46: =VLOOKUP($B46,Model!$1:$1048576,MATCH(O$51,Model!$3:$3,0),FALSE) -> 24 | P46: =VLOOKUP($B46,Model!$1:$1048576,MATCH(P$51,Model!$3:$3,0),FALSE) -> 30
...

Sheet Australia Stores
J2: Australian Franchise Network stores, comprising Chemist Warehouse branded stores, My Chemist branded stores, and Pipeline Stores
C3: Australia Store Count Tracker
C5: Total Stores by state | D5: FY24 | E5: 1H25 | F5: FY25
C6: VIC | D6: =D28+D39+D50+D61+D72+D83 -> 313 | E6: =E28+E39+E50+E61+E72+E83 -> 321 | F6: =F28+F39+F50+F61+F72+F83 -> 323 | G6: =F6-E6 -> 2 | J6: 31. As at 30 June 2024, there were 567 Chemist Warehouse Australian Franchise Network stores, comprising 517 Chemist Warehouse branded stores, 21 My Chemist branded stores, and 29 Pipeline Stores, and 313 Sigma franchise stores, comprising 209 Amcal branded stores, and 104 Discount Drug Stores branded stores. In September 2022, Sigma began a retail brand consolidation process to simplify its retail strategy by seeking to convert Guardian and PharmaSave branded stores to Amcal and Discount Drug Stores. Sigma closed the Guardian brand with effect from 31 January 2024. Since September 2022, Sigma no longer offers the PharmaSave brand to new members. As at 30 June 2024, there were 37 PharmaSave branded stores, which are not included in the Merged Group’s Retail Network figures presented. Sigma continues to provide support to PharmaSave stores in accordance with existing agreements
C7: NSW | D7: =D29+D40+D51+D62+D73+D84 -> 203 | E7: =E29+E40+E51+E62+E73+E84 -> 199 | F7: =F29+F40+F51+F62+F73+F84 -> 196 | G7: =F7-E7 -> -3
C8: QLD | D8: =D30+D41+D52+D63+D74+D85 -> 192 | E8: =E30+E41+E52+E63+E74+E85 -> 188 | F8: =F30+F41+F52+F63+F74+F85 -> 184 | G8: =F8-E8 -> -4
C9: WA | D9: =D31+D42+D53+D64+D75+D86 -> 83 | E9: =E31+E42+E53+E64+E75+E86 -> 87 | F9: =F31+F42+F53+F64+F75+F86 -> 89 | G9: =F9-E9 -> 2 | J9: Rebranding My Chemist into Amcal and DDS (FY25 result)
C10: SA | D10: =D32+D43+D54+D65+D76+D87 -> 45 | E10: =E32+E43+E54+E65+E76+E87 -> 46 | F10: =F32+F43+F54+F65+F76+F87 -> 46 | G10: =F10-E10 -> 0
C11: TAS | D11: =D33+D44+D55+D66+D77+D88 -> 34 | E11: =E33+E44+E55+E66+E77+E88 -> 32 | F11: =F33+F44+F55+F66+F77+F88 -> 33 | G11: =F11-E11 -> 1
C12: ACT | D12: =D34+D45+D56+D67+D78+D89 -> 15 | E12: =E34+E45+E56+E67+E78+E89 -> 15 | F12: =F34+F45+F56+F67+F78+F89 -> 14 | G12: =F12-E12 -> -1
C13: NT | D13: =D35+D46+D57+D68+D79+D90 -> 11 | E13: =E35+E46+E57+E68+E79+E90 -> 10 | F13: =F35+F46+F57+F68+F79+F90 -> 9 | G13: =F13-E13 -> -1
C14: Total | D14: =SUM(D6:D13) -> 896 | E14: =SUM(E6:E13) -> 898 | F14: =SUM(F6:F13) -> 894 | G14: =F14-E14 -> -4
C16: CW + MyChemist + Pipeline Stores by state
C17: VIC | D17: =D28+D61+D83 -> 239 | E17: =E28+E61+E83 -> 245 | F17: =F28+F61+F83 -> 237 | G17: =F17-E17 -> -8 | H17: Driven by 11 MyChemist rebranding to Amcal and DDS (amcal +9 and DDS +1)
C18: NSW | D18: =D29+D62+D84 -> 129 | E18: =E29+E62+E84 -> 129 | F18: =F29+F62+F84 -> 129 | G18: =F18-E18 -> 0 | H18: 1 opening offset by one MyChemist decline
C19: QLD | D19: =D30+D63+D85 -> 96 | E19: =E30+E63+E85 -> 97 | F19: =F30+F63+F85 -> 97 | G19: =F19-E19 -> 0
C20: WA | D20: =D31+D64+D86 -> 40 | E20: =E31+E64+E86 -> 41 | F20: =F31+F64+F86 -> 43 | G20: =F20-E20 -> 2 | M20: Chemist Warehouse | N20: =F36 -> 537
C21: SA | D21: =D32+D65+D87 -> 30 | E21: =E32+E65+E87 -> 30 | F21: =F32+F65+F87 -> 31 | G21: =F21-E21 -> 1 | M21: Amcal | N21: =F47 -> 216
C22: TAS | D22: =D33+D66+D88 -> 18 | E22: =E33+E66+E88 -> 18 | F22: =F33+F66+F88 -> 18 | G22: =F22-E22 -> 0 | M22: Discount Drug Stores | N22: =F58 -> 89
C23: ACT | D23: =D34+D67+D89 -> 6 | E23: =E34+E67+E89 -> 6 | F23: =F34+F67+F89 -> 5 | G23: =F23-E23 -> -1 | M23: MyChemist | N23: =F69 -> 13
C24: NT | D24: =D35+D68+D90 -> 9 | E24: =E35+E68+E90 -> 9 | F24: =F35+F68+F90 -> 9 | G24: =F24-E24 -> 0 | M24: Ultra Beauty Stores | N24: =F80 -> 20
C25: Total | D25: =D36+D69+D91 -> 567 | E25: =E36+E69+E91 -> 575 | F25: =F36+F69+F91 -> 569 | G25: =F25-E25 -> -6 | M25: Pipeline | N25: =F91 -> 19
C27: CW Stores by state
C28: VIC | D28: 206 | E28: 209 | F28: 213 | G28: =F28-E28 -> 4
C29: NSW | D29: 120 | E29: 122 | F29: 123 | G29: =F29-E29 -> 1 | I29: Total stores | J29: 674
C30: QLD | D30: 90 | E30: 94 | F30: 96 | G30: =F30-E30 -> 2 | I30: NZ | J30: 61
C31: WA | D31: 40 | E31: 41 | F31: 43 | G31: =F31-E31 -> 2 | I31: Ireland | J31: 14
C32: SA | D32: 29 | E32: 29 | F32: 30 | G32: =F32-E32 -> 1 | I32: Dubai | J32: 2
C33: TAS | D33: 18 | E33: 18 | F33: 18 | G33: =F33-E33 -> 0 | I33: China | J33: 9
C34: ACT | D34: 5 | E34: 5 | F34: 5 | G34: =F34-E34 -> 0
C35: NT | D35: 9 | E35: 9 | F35: 9 | G35: =F35-E35 -> 0 | I35: Implied Aus stores | J35: =J29-SUM(J30:J33) -> 588
C36: Total | D36: =SUM(D28:D35) -> 517 | E36: =SUM(E28:E35) -> 527 | F36: =SUM(F28:F35) -> 537 | G36: =F36-E36 -> 10 | I36: CW | J36: =F36 -> 537
I37: Pipeline | J37: =F91 -> 19
C38: Amcal Stores by state | I38: MyChemist | J38: =F69 -> 13
C39: VIC | D39: 61 | E39: 61 | F39: 70 | G39: =F39-E39 -> 9 | I39: Implied other | J39: =J35-J36-J37-J38 -> 19
C40: NSW | D40: 42 | E40: 40 | F40: 39 | G40: =F40-E40 -> -1
C41: QLD | D41: 43 | E41: 41 | F41: 41 | G41: =F41-E41 -> 0
C42: WA | D42: 31 | E42: 35 | F42: 36 | G42: =F42-E42 -> 1
C43: SA | D43: 12 | E43: 13 | F43: 13 | G43: =F43-E43 -> 0
C44: TAS | D44: 15 | E44: 13 | F44: 14 | G44: =F44-E44 -> 1
...

Sheet Model
B1: Sigma Healthcare (SIG.AX) | W1: Pro-forma
B2: A$M | W2: Prospectus
C3: FY04 | D3: FY05 | E3: FY06 | F3: FY07 | G3: FY08 | H3: FY09 | I3: FY10 | J3: FY11 | K3: FY12 | L3: FY13 | M3: FY14 | N3: FY15 | O3: FY16 | P3: FY17 | Q3: FY18 | R3: FY19 | S3: FY20 | T3: FY21 | U3: FY22 | V3: FY23 | W3: FY24 | X3: FY25 | Y3: FY26E | Z3: FY27E | AA3: FY28E | AB3: FY29E | AC3: FY30E | AE3: 1H24 | AF3: 2H24 | AG3: 1H25 | AH3: 2H25 | AI3: 1H26E | AJ3: 2H26E
B5: Summary Network Performance
B6: Network Sales
A7: Australia Sales | B7: Australia | C7: =C19 -> 0 | D7: =D19 -> 0 | E7: =E19 -> 0 | F7: =F19 -> 0 | G7: =G19 -> 0 | H7: =H19 -> 0 | I7: =I19 -> 0 | J7: =J19 -> 0 | ... AC7: =AC19 -> 13399.861 | AE7: =AE19 -> 4011.7 | AF7: =AF19 -> 3898.2 | AG7: =AG19 -> 4505.9 | AH7: =AH19 -> 4463 | AI7: =AI19 -> 5178.9056 | AJ7: =AJ19 -> 4934.5359
A8: NZ Sales | B8: New Zealand | Q8: =Q86 -> 0 | R8: =R86 -> 80 | S8: =S86 -> 171 | T8: =T86 -> 306 | U8: =U86 -> 497 | V8: =V86 -> 652 | W8: =W86 -> 886 | X8: =X86 -> 1050 | ... AC8: =AC86 -> 2361.9021
A9: Ireland Sales | B9: Ireland | R9: =R96 -> 0 | S9: =S96 -> 0 | T9: =T96 -> 7.6347407 | U9: =U96 -> 29.946093 | V9: =V96 -> 59.297278 | W9: =W96 -> 105.69921 | X9: =X96 -> 167.47139 | Y9: =Y96 -> 266.16179 | ... AC9: =AC96 -> 645.17317
A10: China Sales | B10: China | T10: 50 | U10: =U13-SUM(U7:U9) -> 84.953907 | V10: =V13-SUM(V7:V9) -> 108.70272 | W10: =W13-SUM(W7:W9) -> 100.30079 | X10: =X13-SUM(X7:X9)-X11-X12 -> 72.128605 | Y10: 80 | Z10: 80 | AA10: 80 | AB10: 80 | AC10: 80
A11: Dubai Sales | B11: Dubai | X11: 10 | Y11: =Y37*7 -> 35 | Z11: =Z37*7 -> 56 | AA11: =AA37*7 -> 77 | AB11: =AB37*7 -> 105 | AC11: =AC37*7 -> 140
A12: Other Sales | B12: Other
A13: Total network sales | B13: Total | C13: 158 | D13: 238 | E13: 362 | F13: 511 | G13: 701 | H13: 951 | I13: 1231 | J13: 1518 | K13: 1847 | L13: 2183 | M13: 2542 | N13: 3133 | O13: 3825 | P13: 4388 | Q13: 4857 | R13: 5355 | S13: 5756 | T13: 5893 | U13: 6825 | V13: 7888 | W13: 9001.9 | X13: 10268.5 | Y13: =SUM(Y7:Y12) -> 11792.3 | Z13: =SUM(Z7:Z12) -> 13128.916 | AA13: =SUM(AA7:AA12) -> 14234.605 | AB13: =SUM(AB7:AB12) -> 15394.431 | AC13: =SUM(AC7:AC12) -> 16626.936 | AE13: 4559.4 | AF13: =W13-AE13 -> 4442.5 | AG13: 5154.2 | AH13: =X13-AG13 -> 5114.3 | AI13: =AI19+AI25 -> 5995.6835 | AJ13: =Y13-AI13 -> 5796.6164
A14: Total network sales growth | B14: Growth % | D14: =D13/C13-1 -> 0.50632911 | E14: =E13/D13-1 -> 0.5210084 | F14: =F13/E13-1 -> 0.41160221 | G14: =G13/F13-1 -> 0.37181996 | H14: =H13/G13-1 -> 0.35663338 | I14: =I13/H13-1 -> 0.29442692 | J14: =J13/I13-1 -> 0.23314379 | K14: =K13/J13-1 -> 0.21673254 | ... AC14: =AC13/AB13-1 -> 0.080061743 | AG14: =AG13/AE13-1 -> 0.13045576 | AH14: =AH13/AF13-1 -> 0.15122116 | AI14: =AI13/AG13-1 -> 0.16326172 | AJ14: =AJ13/AH13-1 -> 0.13341345
B15: Total LFL Sales Growth % | W15: 0.102 | X15: 0.109 | Y15: =Y7/Y13*Y21+Y25/Y13*Y27 -> 0.10857631 | Z15: =Z7/Z13*Z21+Z25/Z13*Z27 -> 0.08 | AA15: =AA7/AA13*AA21+AA25/AA13*AA27 -> 0.055085146 | AB15: =AB7/AB13*AB21+AB25/AB13*AB27 -> 0.055463932 | AC15: =AC7/AC13*AC21+AC25/AC13*AC27 -> 0.055822616 | AE15: 0.089 | AF15: =(W15-0.5*AE15)/0.5 -> 0.115 | AG15: 0.103 | AH15: =(X15-0.5*AG15)/0.5 -> 0.115 | AI15: =AI7/AI13*AI21+AI25/AI13*AI27 -> 0.12591317 | AJ15: =(Y15-0.5*AI15)/0.5 -> 0.091239449
B16: Store Growth % | W16: =W40 -> 0.059701493 | X16: =X40 -> 0.054773083 | Y16: =Y40 -> 0.060830861 | Z16: =Z40 -> 0.037762238 | AA16: =AA40 -> 0.049865229 | AB16: =AB40 -> 0.047496791 | AC16: =AC40 -> 0.046568627 | AG16: =AG40 -> 0.057877814 | AH16: =AH40 -> 0.054773083 | AI16: =AI40 -> 0.054711246 | AJ16: =AJ40 -> 0.060830861
B17: Other % | W17: =W14-SUM(W15:W16) -> -0.020486989 | X17: =X14-SUM(X15:X16) -> -0.023069454 | Y17: =Y14-SUM(Y15:Y16) -> -0.021011594 | Z17: =Z14-SUM(Z15:Z16) -> -0.0044157126 | AA17: =AA14-SUM(AA15:AA16) -> -0.020732574 | AB17: =AB14-SUM(AB15:AB16) -> -0.021481352 | AC17: =AC14-SUM(AC15:AC16) -> -0.022329501 | AG17: =AG14-SUM(AG15:AG16) -> -0.030422052 | AH17: =AH14-SUM(AH15:AH16) -> -0.018551924 | AI17: =AI14-SUM(AI15:AI16) -> -0.017362699 | AJ17: =AJ14-SUM(AJ15:AJ16) -> -0.018656855
F18: ='Australia Stores'!F28+'Australia Stores'!F61 -> 226
B19: Australia Network sales | U19: 6213.1 | V19: 7068 | W19: 7909.9 | X19: 8968.9 | Y19: =X19*(1+Y20) -> 10113.441 | Z19: =Y19*(1+Z20) -> 11091.441 | AA19: =Z19*(1+AA20) -> 11821.77 | AB19: =AA19*(1+AB20) -> 12590.627 | AC19: =AB19*(1+AC20) -> 13399.861 | AE19: 4011.7 | AF19: =W19-AE19 -> 3898.2 | AG19: 4505.9 | AH19: =X19-AG19 -> 4463 | AI19: =AG19*(1+AI20) -> 5178.9056 | AJ19: =Y19-AI19 -> 4934.5359
B20: Growth % | V20: =V19/U19-1 -> 0.13759637 | W20: =W19/V19-1 -> 0.11911432 | X20: =X19/W19-1 -> 0.13388286 | Y20: =Y21+Y23+Y22 -> 0.12761224 | Z20: =Z21+Z23+Z22 -> 0.09670297 | AA20: =AA21+AA23+AA22 -> 0.065846154 | AB20: =AB21+AB23+AB22 -> 0.065037383 | AC20: =AC21+AC23+AC22 -> 0.064272727 | AG20: =AG19/AE19-1 -> 0.12318967 | AH20: =AH19/AF19-1 -> 0.14488738 | AI20: =AI21+AI23+AI22 -> 0.14936097 | AJ20: =AJ19/AH19-1 -> 0.10565447
A21: Australia LFL | B21: Total LFL Sales Growth % | C21: =C14-C22 -> 0 | D21: =D14-D22 -> 0.16150153 | E21: =E14-E22 -> 0.34152122 | F21: =F14-F22 -> 0.23768917 | G21: =G14-G22 -> 0.01070885 | H21: =H14-H22 -> 0.20697352 | I21: =I14-I22 -> 0.12282929 | J21: =J14-J22 -> 0.066477119 | ... T21: =T14-T22 -> -0.018622992 | U21: 0.121 | V21: 0.118 | W21: 0.098 | X21: 0.113 | Y21: 0.11 | Z21: 0.08 | AA21: 0.05 | AB21: 0.05 | AC21: 0.05 | AE21: 0.087 | AF21: =(W21-0.5*AE21)/0.5 -> 0.109 | AG21: 0.104 | AH21: =(X21-0.5*AG21)/0.5 -> 0.122 | AI21: 0.13 | AJ21: =(Y21-0.5*AI21)/0.5 -> 0.09
B22: Store Growth % | D22: =D61 -> 0.34482759 | E22: =E61 -> 0.17948718 | F22: =F61 -> 0.17391304 | G22: =G61 -> 0.36111111 | H22: =H61 -> 0.14965986 | I22: =I61 -> 0.17159763 | J22: =J61 -> 0.16666667 | K22: =K61 -> 0.15151515 | ... V22: =V61 -> 0.035916824 | W22: =W43 -> 0.036429872 | X22: =X43 -> 0.033391916 | Y22: =Y43 -> 0.030612245 | Z22: =Z43 -> 0.02970297 | AA22: =AA43 -> 0.028846154 | AB22: =AB43 -> 0.028037383 | AC22: =AC43 -> 0.027272727 | AG22: =AG61 -> 0 | AH22: =AH43 -> 0.036906854 | AI22: =AI43 -> 0.029360967 | AJ22: =AJ43 -> 0.027118644
B23: Other % | V23: =V20-V21-V22 -> -0.016320455 | W23: =W20-W21-W22 -> -0.015315554 | X23: =X20-X21-X22 -> -0.01250906 | Y23: -0.013 | Z23: -0.013 | AA23: -0.013 | AB23: -0.013 | AC23: -0.013 | AG23: =AG20-AG21-AG22 -> 0.01918967 | AH23: =AH20-AH21-AH22 -> -0.01401947 | AI23: -0.01 | AJ23: =AJ20-AJ21-AJ22 -> -0.011464178
A25: International Sales | B25: Total International Network Sales | U25: =U13-U19 -> 611.9 | V25: =V13-V19 -> 820 | W25: =W13-W19 -> 1092 | X25: =X13-X19 -> 1299.6 | Y25: =SUM(Y8:Y12) -> 1678.8585 | Z25: =SUM(Z8:Z12) -> 2037.4749 | AA25: =SUM(AA8:AA12) -> 2412.8346 | AB25: =SUM(AB8:AB12) -> 2803.8042 | AC25: =SUM(AC8:AC12) -> 3227.0753 | AE25: =AE13-AE19 -> 547.7 | AF25: =AF13-AF19 -> 544.3 | AG25: =AG13-AG19 -> 648.3 | AH25: =AH13-AH19 -> 651.3 | AI25: =AG25*(1+AI26) -> 816.77796 | AJ25: =Y25-AI25 -> 862.08055
B26: Growth % | V26: =V25/U25-1 -> 0.34008825 | W26: =W25/V25-1 -> 0.33170732 | X26: =X25/W25-1 -> 0.19010989 | Y26: =Y25/X25-1 -> 0.29182711 | Z26: =Z25/Y25-1 -> 0.21360728 | AA26: =AA25/Z25-1 -> 0.18422789 | AB26: =AB25/AA25-1 -> 0.16203748 | AC26: =AC25/AB25-1 -> 0.15096313 | AG26: =AG25/AE25-1 -> 0.1836772 | AH26: =AH25/AF25-1 -> 0.19658277 | AI26: =SUM(AI27:AI29) -> 0.25987654 | AJ26: =AJ25/AH25-1 -> 0.32363051
A27: International LFL | B27: Total LFL Sales Growth % | U27: -0.065 | V27: 0.215 | W27: 0.144 | X27: 0.081 | Y27: =Y88 -> 0.1 | Z27: =Z88 -> 0.08 | AA27: =AA88 -> 0.08 | AB27: =AB88 -> 0.08 | AC27: =AC88 -> 0.08 | AE27: 0.106 | AF27: =(W27-0.5*AE27)/0.5 -> 0.182 | AG27: 0.09 | AH27: =(X27-0.5*AG27)/0.5 -> 0.072 | AI27: 0.1 | AJ27: =(Y27-0.5*AI27)/0.5 -> 0.1
B28: Store Growth % | R28: =R46 -> 0 | S28: =S46 -> 1.5 | T28: =T46 -> 1 | U28: =U46 -> 0.46666667 | V28: =V46 -> 0.22727273 | W28: =W46 -> 0.2962963 | X28: =X46 -> 0.22857143 | Y28: =Y46 -> 0.26744186 | ... AC28: =AC46 -> 0.12820513 | AG28: =AG46 -> 0 | AH28: =AH46 -> 0.19444444 | AI28: =AI46 -> 0.20987654 | AJ28: =AJ46 -> 0.26744186
B29: Other % | V29: =V26-V27-V28 -> -0.10218448 | W29: =W26-W27-W28 -> -0.10858898 | X29: =X26-X27-X28 -> -0.11946154 | Y29: =Y26-Y27-Y28 -> -0.07561475 | Z29: =Z26-Z27-Z28 -> 0.05103847 | AA29: =AA26-AA27-AA28 -> -0.056789063 | AB29: =AB26-AB27-AB28 -> -0.056648653 | AC29: =AC26-AC27-AC28 -> -0.057242001 | AG29: =AG26-AG27-AG28 -> 0.093677196 | AH29: =AH26-AH27-AH28 -> -0.069861678 | AI29: -0.05 | AJ29: =AJ26-AJ27-AJ28 -> -0.043811352
B31: Network Sales Modelling
B32: Group Store Count
A33: Australia Stores | B33: Australia | C33: =C60 -> 58 | D33: =D60 -> 78 | E33: =E60 -> 92 | F33: =F60 -> 108 | G33: =G60 -> 147 | H33: =H60 -> 169 | I33: =I60 -> 198 | J33: =J60 -> 231 | ... AC33: =AC60 -> 659 | AF33: =W33 -> 567 | AG33: =AG60 -> 575 | AH33: =X33 -> 569 | AI33: =AI60 -> 577 | AJ33: =Y33 -> 587
A34: NZ Stores | B34: New Zealand | J34: =J92 -> 0 | K34: =K92 -> 0 | L34: =L92 -> 0 | M34: =M92 -> 0 | N34: =N92 -> 0 | O34: =O92 -> 0 | P34: =P92 -> 0 | Q34: =Q92 -> 0 | ... AC34: =AC92 -> 116 | AF34: =W34 -> 50 | AG34: =AG92 -> 56 | AH34: =X34 -> 61 | AI34: =AI92 -> 70 | AJ34: =Y34 -> 76
A35: Ireland Stores | B35: Ireland | S35: =S102 -> 0 | T35: =T102 -> 2 | U35: =U102 -> 4 | V35: =V102 -> 6 | W35: =W102 -> 10 | X35: =X102 -> 14 | Y35: =Y102 -> 19 | Z35: =Z102 -> 24 | ... AC35: =AC102 -> 40 | AF35: =W35 -> 10 | AG35: =AG102 -> 12 | AH35: =X35 -> 14 | AI35: =AI102 -> 16 | AJ35: =Y35 -> 19
A36: China Stores | B36: China | S36: 1 | T36: 4 | U36: 5 | V36: 6 | W36: 10 | X36: 9 | Y36: =X36 -> 9 | Z36: 0 | AA36: =Z36 -> 0 | AB36: =AA36 -> 0 | AC36: =AB36 -> 0 | AF36: =W36 -> 10 | AG36: 11 | AH36: =X36 -> 9 | AI36: 9 | AJ36: =Y36 -> 9
A37: Dubai Stores | B37: Dubai | X37: 2 | Y37: 5 | Z37: 8 | AA37: 11 | AB37: 15 | AC37: 20 | AG37: 2 | AH37: =X37 -> 2 | AI37: 3 | AJ37: =Y37 -> 5
A38: Other Stores | B38: Other | R38: =R39-SUM(R33:R36) -> 0 | S38: =S39-SUM(S33:S36) -> 0 | T38: =T39-SUM(T33:T36) -> -3 | U38: =U39-SUM(U33:U36) -> 0 | V38: =V39-SUM(V33:V36) -> 1 | W38: =W39-SUM(W33:W36) -> 2 | X38: =X39-SUM(X33:X37) -> 19 | Y38: =X38 -> 19 | Z38: =Y38 -> 19 | AA38: =Z38 -> 19 | AB38: =AA38 -> 19 | AC38: =AB38 -> 19 | AF38: =AF39-SUM(AF33:AF36) -> 2 | AG38: =AG39-SUM(AG33:AG36) -> 4 | AH38: =AH39-SUM(AH33:AH36) -> 21 | AI38: 19 | AJ38: =Y38 -> 19
A39: Total Stores | B39: Total Stores | C39: 58 | D39: 78 | E39: 92 | F39: 108 | G39: 147 | H39: 169 | I39: 198 | J39: 231 | K39: 266 | L39: 297 | M39: 319 | N39: 341 | O39: 369 | P39: 412 | Q39: 446 | R39: 476 | S39: 510 | T39: 543 | U39: 573 | V39: 603 | W39: 639 | X39: 674 | Y39: =SUM(Y33:Y38) -> 715 | Z39: =SUM(Z33:Z38) -> 742 | AA39: =SUM(AA33:AA38) -> 779 | AB39: =SUM(AB33:AB38) -> 816 | AC39: =SUM(AC33:AC38) -> 854 | AE39: 622 | AF39: =W39 -> 639 | AG39: 658 | AH39: =X39 -> 674 | AI39: =SUM(AI33:AI38) -> 694 | AJ39: =SUM(AJ33:AJ38) -> 715
B40: Growth % | D40: =D39/C39-1 -> 0.34482759 | E40: =E39/D39-1 -> 0.17948718 | F40: =F39/E39-1 -> 0.17391304 | G40: =G39/F39-1 -> 0.36111111 | H40: =H39/G39-1 -> 0.14965986 | I40: =I39/H39-1 -> 0.17159763 | J40: =J39/I39-1 -> 0.16666667 | K40: =K39/J39-1 -> 0.15151515 | ... AC40: =AC39/AB39-1 -> 0.046568627 | AG40: =AG39/AE39-1 -> 0.057877814 | AH40: =AH39/AF39-1 -> 0.054773083 | AI40: =AI39/AG39-1 -> 0.054711246 | AJ40: =AJ39/AH39-1 -> 0.060830861
X41: =70/X7 -> 0.0078047475 | Z41: =X41*Z8 -> 11.967262 | AA41: =Z41/Z13 -> 0.00091151944
A42: Australia Stores inc. legacy MyChemist and Opt Warehouse | B42: Australia total adjusted for rebranding & Optometrist Warehouse | V42: =V33+V38 -> 549 | W42: =W33+W38 -> 569 | X42: =X33+X38 -> 588 | Y42: =Y33+Y38 -> 606 | Z42: =Z33+Z38 -> 624 | AA42: =AA33+AA38 -> 642 | AB42: =AB33+AB38 -> 660 | AC42: =AC33+AC38 -> 678 | AF42: =AF33+AF38 -> 569 | AG42: =AG33+AG38 -> 579 | AH42: =AH33+AH38 -> 590 | AI42: =AI33+AI38 -> 596 | AJ42: =AJ33+AJ38 -> 606
B43: Growth % | W43: =W42/V42-1 -> 0.036429872 | X43: =X42/W42-1 -> 0.033391916 | Y43: =Y42/X42-1 -> 0.030612245 | Z43: =Z42/Y42-1 -> 0.02970297 | AA43: =AA42/Z42-1 -> 0.028846154 | AB43: =AB42/AA42-1 -> 0.028037383 | AC43: =AC42/AB42-1 -> 0.027272727 | AH43: =AH42/AF42-1 -> 0.036906854 | AI43: =AI42/AG42-1 -> 0.029360967 | AJ43: =AJ42/AH42-1 -> 0.027118644
...

Sheet PL
B1: =Model!B1 -> Sigma Healthcare (SIG.AX)
B2: =Model!B2 -> A$M
C3: FY24 | D3: FY25 | E3: FY26E | F3: FY27E | G3: FY28E | H3: FY29E | I3: FY30E | K3: 1H25 | L3: 2H25 | M3: 1H26E | N3: 2H26E
B4: P&L
A5: Total network sales | B5: Network Sales | C5: =VLOOKUP($A5,Model!$1:$1048576,MATCH(C$3,Model!$3:$3,0),FALSE) -> 9001.9 | D5: =VLOOKUP($A5,Model!$1:$1048576,MATCH(D$3,Model!$3:$3,0),FALSE) -> 10268.5 | E5: =VLOOKUP($A5,Model!$1:$1048576,MATCH(E$3,Model!$3:$3,0),FALSE) -> 11792.3 | F5: =VLOOKUP($A5,Model!$1:$1048576,MATCH(F$3,Model!$3:$3,0),FALSE) -> 13128.916 | G5: =VLOOKUP($A5,Model!$1:$1048576,MATCH(G$3,Model!$3:$3,0),FALSE) -> 14234.605 | H5: =VLOOKUP($A5,Model!$1:$1048576,MATCH(H$3,Model!$3:$3,0),FALSE) -> 15394.431 | I5: =VLOOKUP($A5,Model!$1:$1048576,MATCH(I$3,Model!$3:$3,0),FALSE) -> 16626.936 | K5: =VLOOKUP($A5,Model!$1:$1048576,MATCH(K$3,Model!$3:$3,0),FALSE) -> 5154.2 | L5: =VLOOKUP($A5,Model!$1:$1048576,MATCH(L$3,Model!$3:$3,0),FALSE) -> 5114.3 | M5: =VLOOKUP($A5,Model!$1:$1048576,MATCH(M$3,Model!$3:$3,0),FALSE) -> 5995.6835 | N5: =VLOOKUP($A5,Model!$1:$1048576,MATCH(N$3,Model!$3:$3,0),FALSE) -> 5796.6164
A6: Network Sales Growth | B6: Growth % | D6: =D5/C5-1 -> 0.14070363 | E6: =E5/D5-1 -> 0.14839558 | F6: =F5/E5-1 -> 0.11334653 | G6: =G5/F5-1 -> 0.0842178 | H6: =H5/G5-1 -> 0.08147937 | I6: =I5/H5-1 -> 0.080061743 | M6: =M5/K5-1 -> 0.16326172 | N6: =N5/L5-1 -> 0.13341345
A8: Total revenue | B8: Revenue | C8: =VLOOKUP($A8,Model!$1:$1048576,MATCH(C$3,Model!$3:$3,0),FALSE) -> 6655.7 | D8: =VLOOKUP($A8,Model!$1:$1048576,MATCH(D$3,Model!$3:$3,0),FALSE) -> 9591.3 | E8: =VLOOKUP($A8,Model!$1:$1048576,MATCH(E$3,Model!$3:$3,0),FALSE) -> 10928.785 | F8: =VLOOKUP($A8,Model!$1:$1048576,MATCH(F$3,Model!$3:$3,0),FALSE) -> 12084.819 | G8: =VLOOKUP($A8,Model!$1:$1048576,MATCH(G$3,Model!$3:$3,0),FALSE) -> 12985.047 | H8: =VLOOKUP($A8,Model!$1:$1048576,MATCH(H$3,Model!$3:$3,0),FALSE) -> 13921.647 | I8: =VLOOKUP($A8,Model!$1:$1048576,MATCH(I$3,Model!$3:$3,0),FALSE) -> 14912.319 | K8: =VLOOKUP($A8,Model!$1:$1048576,MATCH(K$3,Model!$3:$3,0),FALSE) -> 0 | L8: =VLOOKUP($A8,Model!$1:$1048576,MATCH(L$3,Model!$3:$3,0),FALSE) -> 0 | M8: =VLOOKUP($A8,Model!$1:$1048576,MATCH(M$3,Model!$3:$3,0),FALSE) -> 5556.6373 | N8: =VLOOKUP($A8,Model!$1:$1048576,MATCH(N$3,Model!$3:$3,0),FALSE) -> 5372.1473
A9: Revenue Growth | B9: Growth % | D9: =D8/C8-1 -> 0.44106555 | E9: =E8/D8-1 -> 0.13944769 | F9: =F8/E8-1 -> 0.10577885 | G9: =G8/F8-1 -> 0.074492467 | H9: =H8/G8-1 -> 0.072129106 | I9: =I8/H8-1 -> 0.071160546
A11: EBITDA | B11: EBITDA Normalised | C11: =VLOOKUP($A11,Model!$1:$1048576,MATCH(C$3,Model!$3:$3,0),FALSE) -> 675.1 | D11: =VLOOKUP($A11,Model!$1:$1048576,MATCH(D$3,Model!$3:$3,0),FALSE) -> 968.5 | E11: =VLOOKUP($A11,Model!$1:$1048576,MATCH(E$3,Model!$3:$3,0),FALSE) -> 1201.5729 | F11: =VLOOKUP($A11,Model!$1:$1048576,MATCH(F$3,Model!$3:$3,0),FALSE) -> 1424.6573 | G11: =VLOOKUP($A11,Model!$1:$1048576,MATCH(G$3,Model!$3:$3,0),FALSE) -> 1633.2645 | H11: =VLOOKUP($A11,Model!$1:$1048576,MATCH(H$3,Model!$3:$3,0),FALSE) -> 1837.3141 | I11: =VLOOKUP($A11,Model!$1:$1048576,MATCH(I$3,Model!$3:$3,0),FALSE) -> 2061.6569 | K11: =VLOOKUP($A11,Model!$1:$1048576,MATCH(K$3,Model!$3:$3,0),FALSE) -> 0 | L11: =VLOOKUP($A11,Model!$1:$1048576,MATCH(L$3,Model!$3:$3,0),FALSE) -> 0 | M11: =VLOOKUP($A11,Model!$1:$1048576,MATCH(M$3,Model!$3:$3,0),FALSE) -> 656.1775 | N11: =VLOOKUP($A11,Model!$1:$1048576,MATCH(N$3,Model!$3:$3,0),FALSE) -> 545.39544
B12: Growth % | D12: =D11/C11-1 -> 0.43460228 | E12: =E11/D11-1 -> 0.24065353 | F12: =F11/E11-1 -> 0.18566031 | G12: =G11/F11-1 -> 0.14642621 | H12: =H11/G11-1 -> 0.12493357 | I12: =I11/H11-1 -> 0.12210365
B14: Lease D&A | C14: -18.875 | D14: -27.197 | E14: =D14*(1+Model!Y$16) -> -28.851417 | F14: =E14*(1+Model!Z16) -> -29.940911 | G14: =F14*(1+Model!AA16) -> -31.433921 | H14: =G14*(1+Model!AB16) -> -32.926932 | I14: =H14*(1+Model!AC16) -> -34.460294 | M14: =E14*0.5 -> -14.425708 | N14: =E14-M14 -> -14.425708
A15: D&A non lease | B15: Non Lease D&A | C15: =C16-C14 -> -50.725 | D15: =D16-D14 -> -37.903 | E15: =E16-E14 -> -39.503583 | F15: =F16-F14 -> -41.831839 | G15: =G16-G14 -> -43.927466 | H15: =H16-H14 -> -46.202525 | I15: =I16-I14 -> -48.625636 | M15: =M16-M14 -> -19.751792 | N15: =N16-N14 -> -19.751792
A16: D&A | B16: D&A | C16: =VLOOKUP($A16,Model!$1:$1048576,MATCH(C$3,Model!$3:$3,0),FALSE) -> -69.6 | D16: =VLOOKUP($A16,Model!$1:$1048576,MATCH(D$3,Model!$3:$3,0),FALSE) -> -65.1 | E16: =VLOOKUP($A16,Model!$1:$1048576,MATCH(E$3,Model!$3:$3,0),FALSE) -> -68.355 | F16: =VLOOKUP($A16,Model!$1:$1048576,MATCH(F$3,Model!$3:$3,0),FALSE) -> -71.77275 | G16: =VLOOKUP($A16,Model!$1:$1048576,MATCH(G$3,Model!$3:$3,0),FALSE) -> -75.361388 | H16: =VLOOKUP($A16,Model!$1:$1048576,MATCH(H$3,Model!$3:$3,0),FALSE) -> -79.129457 | I16: =VLOOKUP($A16,Model!$1:$1048576,MATCH(I$3,Model!$3:$3,0),FALSE) -> -83.08593 | K16: =VLOOKUP($A16,Model!$1:$1048576,MATCH(K$3,Model!$3:$3,0),FALSE) -> 0 | L16: =VLOOKUP($A16,Model!$1:$1048576,MATCH(L$3,Model!$3:$3,0),FALSE) -> 0 | M16: =VLOOKUP($A16,Model!$1:$1048576,MATCH(M$3,Model!$3:$3,0),FALSE) -> -34.1775 | N16: =VLOOKUP($A16,Model!$1:$1048576,MATCH(N$3,Model!$3:$3,0),FALSE) -> -34.1775
B17: Growth % | D17: =D16/C16-1 -> -0.064655172 | E17: =E16/D16-1 -> 0.05 | F17: =F16/E16-1 -> 0.05 | G17: =G16/F16-1 -> 0.05 | H17: =H16/G16-1 -> 0.05 | I17: =I16/H16-1 -> 0.05
A19: EBIT | B19: EBIT Normalised | C19: =VLOOKUP($A19,Model!$1:$1048576,MATCH(C$3,Model!$3:$3,0),FALSE) -> 605.5 | D19: =VLOOKUP($A19,Model!$1:$1048576,MATCH(D$3,Model!$3:$3,0),FALSE) -> 903.4 | E19: =VLOOKUP($A19,Model!$1:$1048576,MATCH(E$3,Model!$3:$3,0),FALSE) -> 1133.2179 | F19: =VLOOKUP($A19,Model!$1:$1048576,MATCH(F$3,Model!$3:$3,0),FALSE) -> 1352.8846 | G19: =VLOOKUP($A19,Model!$1:$1048576,MATCH(G$3,Model!$3:$3,0),FALSE) -> 1557.9031 | H19: =VLOOKUP($A19,Model!$1:$1048576,MATCH(H$3,Model!$3:$3,0),FALSE) -> 1758.1846 | I19: =VLOOKUP($A19,Model!$1:$1048576,MATCH(I$3,Model!$3:$3,0),FALSE) -> 1978.5709 | K19: =VLOOKUP($A19,Model!$1:$1048576,MATCH(K$3,Model!$3:$3,0),FALSE) -> 0 | L19: =VLOOKUP($A19,Model!$1:$1048576,MATCH(L$3,Model!$3:$3,0),FALSE) -> 0 | M19: =VLOOKUP($A19,Model!$1:$1048576,MATCH(M$3,Model!$3:$3,0),FALSE) -> 622 | N19: =VLOOKUP($A19,Model!$1:$1048576,MATCH(N$3,Model!$3:$3,0),FALSE) -> 511.21794
A20: EBIT Growth | B20: Growth % | D20: =D19/C19-1 -> 0.49199009 | E20: =E19/D19-1 -> 0.25439223 | F20: =F19/E19-1 -> 0.19384326 | G20: =G19/F19-1 -> 0.15154178 | H20: =H19/G19-1 -> 0.12855837 | I20: =I19/H19-1 -> 0.12534878
B22: Significant Items / Other | C22: =C24-C19 -> -23.964 | D22: =D24-D19 -> -135.5 | E22: -10 | F22: -30 | G22: -30 | H22: -30 | M22: -5 | N22: =E22-M22 -> -5
B24: EBIT Statutory | C24: =574.121+7.415 -> 581.536 | D24: 767.9 | E24: =E19+E22 -> 1123.2179 | F24: =F19+F22 -> 1322.8846 | G24: =G19+G22 -> 1527.9031 | H24: =H19+H22 -> 1728.1846 | I24: =I19+I22 -> 1978.5709 | M24: =M19+M22 -> 617 | N24: =N19+N22 -> 506.21794
A26: Interest leases | B26: Least Interest | C26: =-49.854+44.936 -> -4.918 | D26: =-58.619+50.476 -> -8.143 | E26: =D26*(1+Model!Y$16) -> -8.6383457 | F26: =E26*(1+Model!Z$16) -> -8.964549 | G26: =F26*(1+Model!AA$16) -> -9.4115682 | H26: =G26*(1+Model!AB$16) -> -9.8585875 | I26: =H26*(1+Model!AC$16) -> -10.317688
B27: Non-Lease Interest | C27: =C28-C26 -> -2.497 | D27: =D28-D26 -> -15.957 | E27: =E28-E26 -> -41.361654 | F27: =F28-F26 -> -37.035451 | G27: =G28-G26 -> -30.588432 | H27: =H28-H26 -> -30.141412 | I27: =I28-I26 -> -29.682312
A28: Net interest | B28: Net Interest Income / (Expense) | C28: -7.415 | D28: -24.1 | E28: -50 | F28: -46 | G28: -40 | H28: -40 | I28: -40 | M28: =E28*0.5 -> -25 | N28: =E28-M28 -> -25
B30: PBT Normalised | C30: =C19+C28 -> 598.085 | D30: =D19+D28 -> 879.3 | E30: =E19+E28 -> 1083.2179 | F30: =F19+F28 -> 1306.8846 | G30: =G19+G28 -> 1517.9031 | H30: =H19+H28 -> 1718.1846 | I30: =I19+I28 -> 1938.5709 | M30: =M19+M28 -> 597 | N30: =N19+N28 -> 486.21794
B31: Growth % | E31: =E30/D30-1 -> 0.23190941 | F31: =F30/E30-1 -> 0.20648352 | G31: =G30/F30-1 -> 0.16146685 | H31: =H30/G30-1 -> 0.13194616 | I31: =I30/H30-1 -> 0.12826694
B33: Income Tax Normalised | C33: =C51 -> -170.6 | D33: =D51 -> -254.997 | E33: =E51 -> -314.1332 | F33: =F51 -> -378.99653 | G33: =G51 -> -440.19191 | H33: =H51 -> -498.27354 | I33: =I51 -> -562.18557 | M33: =M51 -> -173.13 | N33: =N51 -> -141.0032
A35: Minorities | B35: Minority Interest | C35: -1.356 | D35: -4.5 | E35: =-4.5-'Ireland Model'!Y99 -> -7.8058614 | F35: =-4.5-'Ireland Model'!Z99 -> -11.184447 | G35: =-4.5-'Ireland Model'!AA99 -> -14.100187 | H35: =-4.5-'Ireland Model'!AB99 -> -17.533169 | I35: =-4.5-'Ireland Model'!AC99 -> -20.983628 | M35: =E35*0.5 -> -3.9029307 | N35: =E35-M35 -> -3.9029307
A37: NPAT | B37: NPAT Normalised | C37: =C30+C33+C35 -> 426.129 | D37: =D30+D33+D35 -> 619.803 | E37: =E30+E33+E35 -> 761.27888 | F37: =F30+F33+F35 -> 916.70362 | G37: =G30+G33+G35 -> 1063.611 | H37: =H30+H33+H35 -> 1202.3779 | I37: =I30+I33+I35 -> 1355.4017 | M37: =M30+M33+M35 -> 419.96707 | N37: =N30+N33+N35 -> 341.31181
A38: NPAT Growth | B38: Growth % | E38: =E37/D37-1 -> 0.22825943 | F38: =F37/E37-1 -> 0.20416269 | G38: =G37/F37-1 -> 0.16025618 | H38: =H37/G37-1 -> 0.13046769 | I38: =I37/H37-1 -> 0.12726765
B40: Significant Items / Other | C40: =C42-C37 -> 114.884 | D40: =D42-D37 -> -89.903 | E40: =E52+E22 -> -7.1 | F40: =F52+F22 -> -21.3 | G40: =G52+G22 -> -21.3 | H40: =H52+H22 -> -21.3 | I40: =I52+I22 -> 0 | M40: =M52+M22 -> -3.55 | N40: =N52+N22 -> -3.55
B42: NPAT Statutory | C42: 541.013 | D42: 529.9 | E42: =E37+E40 -> 754.17888 | F42: =F37+F40 -> 895.40362 | G42: =G37+G40 -> 1042.311 | H42: =H37+H40 -> 1181.0779 | I42: =I37+I40 -> 1355.4017 | M42: =M37+M40 -> 416.41707 | N42: =N37+N40 -> 337.76181
B43: Growth % | F43: =F42/E42-1 -> 0.18725629 | G43: =G42/F42-1 -> 0.16406838 | H43: =H42/G42-1 -> 0.13313385 | I43: =I42/H42-1 -> 0.14759721
A45: Shares Diluted | B45: Shares (Diluted) | D45: =D67 -> 11540 | E45: =E67 -> 11540 | F45: =F67 -> 11540 | G45: =G67 -> 11540 | H45: =H67 -> 11540 | I45: =I67 -> 11540 | M45: =M67 -> 11540 | N45: =N67 -> 11540
A47: EPS | B47: EPS Normalised (Diluted) | D47: =D37/D45 -> 0.053709099 | E47: =E37/E45 -> 0.065968707 | F47: =F37/F45 -> 0.079437055 | G47: =G37/G45 -> 0.092167335 | H47: =H37/H45 -> 0.10419219 | I47: =I37/I45 -> 0.11745249 | M47: =M37/M45 -> 0.036392294 | N47: =N37/N45 -> 0.029576413
A48: EPS Growth | B48: Growth % | E48: =E47/D47-1 -> 0.22825943 | F48: =F47/E47-1 -> 0.20416269 | G48: =G47/F47-1 -> 0.16025618 | H48: =H47/G47-1 -> 0.13046769 | I48: =I47/H47-1 -> 0.12726765
B50: Tax Modelling
A51: Tax | B51: Tax Normalised | C51: -170.6 | D51: =D61*-D56 -> -254.997 | E51: =E61*-E56 -> -314.1332 | F51: =F61*-F56 -> -378.99653 | G51: =G61*-G56 -> -440.19191 | H51: =H61*-H56 -> -498.27354 | I51: =I61*-I56 -> -562.18557 | M51: =M61*-M56 -> -173.13 | N51: =E51-M51 -> -141.0032
B52: Significant Items | E52: =E62*-E57 -> 2.9 | F52: =F62*-F57 -> 8.7 | G52: =G62*-G57 -> 8.7 | H52: =H62*-H57 -> 8.7 | I52: =I62*-I57 -> 0 | M52: =M62*-M57 -> 1.45 | N52: =E52-M52 -> 1.45
B53: Tax Statutory | C53: -34.464 | E53: =E51+E52 -> -311.2332 | F53: =F51+F52 -> -370.29653 | G53: =G51+G52 -> -431.49191 | H53: =H51+H52 -> -489.57354 | I53: =I51+I52 -> -562.18557 | M53: =M51+M52 -> -171.68 | N53: =E53-M53 -> -139.5532
B55: Tax Rates
B56: Tax Normalised | D56: 0.29 | E56: 0.29 | F56: 0.29 | G56: 0.29 | H56: 0.29 | I56: 0.29 | M56: 0.29 | N56: =N51/-N61 -> 0.29
B57: Significant items | E57: =E56 -> 0.29 | F57: =F56 -> 0.29 | G57: =G56 -> 0.29 | H57: =H56 -> 0.29 | I57: =I56 -> 0.29 | M57: 0.29 | N57: =N52/-N62 -> 0.29
...

Sheet CF
B1: =Model!B1 -> Sigma Healthcare (SIG.AX)
B2: =Model!B2 -> A$M
C3: FY24 | D3: FY25 | E3: FY26E | F3: FY27E | G3: FY28E | H3: FY29E | I3: FY30E
B4: CFS
B5: Operating Cash Flow
A6: EBIT | B6: EBIT | C6: =VLOOKUP($A6,PL!$1:$1048576,MATCH(C$3,PL!$3:$3,0),FALSE) -> 605.5 | D6: =VLOOKUP($A6,PL!$1:$1048576,MATCH(D$3,PL!$3:$3,0),FALSE) -> 903.4 | E6: =VLOOKUP($A6,PL!$1:$1048576,MATCH(E$3,PL!$3:$3,0),FALSE) -> 1133.2179 | F6: =VLOOKUP($A6,PL!$1:$1048576,MATCH(F$3,PL!$3:$3,0),FALSE) -> 1352.8846 | G6: =VLOOKUP($A6,PL!$1:$1048576,MATCH(G$3,PL!$3:$3,0),FALSE) -> 1557.9031 | H6: =VLOOKUP($A6,PL!$1:$1048576,MATCH(H$3,PL!$3:$3,0),FALSE) -> 1758.1846 | I6: =VLOOKUP($A6,PL!$1:$1048576,MATCH(I$3,PL!$3:$3,0),FALSE) -> 1978.5709
A7: D&A | B7: Depreciation and Amortisation | C7: =-VLOOKUP($A7,PL!$1:$1048576,MATCH(C$3,PL!$3:$3,0),FALSE) -> 69.6 | D7: =-VLOOKUP($A7,PL!$1:$1048576,MATCH(D$3,PL!$3:$3,0),FALSE) -> 65.1 | E7: =-VLOOKUP($A7,PL!$1:$1048576,MATCH(E$3,PL!$3:$3,0),FALSE) -> 68.355 | F7: =-VLOOKUP($A7,PL!$1:$1048576,MATCH(F$3,PL!$3:$3,0),FALSE) -> 71.77275 | G7: =-VLOOKUP($A7,PL!$1:$1048576,MATCH(G$3,PL!$3:$3,0),FALSE) -> 75.361388 | H7: =-VLOOKUP($A7,PL!$1:$1048576,MATCH(H$3,PL!$3:$3,0),FALSE) -> 79.129457 | I7: =-VLOOKUP($A7,PL!$1:$1048576,MATCH(I$3,PL!$3:$3,0),FALSE) -> 83.08593
A8: Chg WC | B8: Change in Net Working Capital | C8: =VLOOKUP($A8,BS!$1:$1048576,MATCH(C$3,BS!$3:$3,0),FALSE) -> 0 | D8: =VLOOKUP($A8,BS!$1:$1048576,MATCH(D$3,BS!$3:$3,0),FALSE) -> -722.22 | E8: =VLOOKUP($A8,BS!$1:$1048576,MATCH(E$3,BS!$3:$3,0),FALSE) -> -89.661211 | F8: =VLOOKUP($A8,BS!$1:$1048576,MATCH(F$3,BS!$3:$3,0),FALSE) -> -32.014301 | G8: =VLOOKUP($A8,BS!$1:$1048576,MATCH(G$3,BS!$3:$3,0),FALSE) -> -46.141237 | H8: =VLOOKUP($A8,BS!$1:$1048576,MATCH(H$3,BS!$3:$3,0),FALSE) -> -40.287066 | I8: =VLOOKUP($A8,BS!$1:$1048576,MATCH(I$3,BS!$3:$3,0),FALSE) -> -35.309847
A9: Tax | B9: Tax Paid | C9: =VLOOKUP($A9,PL!$1:$1048576,MATCH(C$3,PL!$3:$3,0),FALSE) -> -170.6 | D9: =VLOOKUP($A9,PL!$1:$1048576,MATCH(D$3,PL!$3:$3,0),FALSE) -> -254.997 | E9: =VLOOKUP($A9,PL!$1:$1048576,MATCH(E$3,PL!$3:$3,0),FALSE) -> -314.1332 | F9: =VLOOKUP($A9,PL!$1:$1048576,MATCH(F$3,PL!$3:$3,0),FALSE) -> -378.99653 | G9: =VLOOKUP($A9,PL!$1:$1048576,MATCH(G$3,PL!$3:$3,0),FALSE) -> -440.19191 | H9: =VLOOKUP($A9,PL!$1:$1048576,MATCH(H$3,PL!$3:$3,0),FALSE) -> -498.27354 | I9: =VLOOKUP($A9,PL!$1:$1048576,MATCH(I$3,PL!$3:$3,0),FALSE) -> -562.18557
A10: Net interest | B10: Net interest | C10: =VLOOKUP($A10,PL!$1:$1048576,MATCH(C$3,PL!$3:$3,0),FALSE) -> -7.415 | D10: =VLOOKUP($A10,PL!$1:$1048576,MATCH(D$3,PL!$3:$3,0),FALSE) -> -24.1 | E10: =VLOOKUP($A10,PL!$1:$1048576,MATCH(E$3,PL!$3:$3,0),FALSE) -> -50 | F10: =VLOOKUP($A10,PL!$1:$1048576,MATCH(F$3,PL!$3:$3,0),FALSE) -> -46 | G10: =VLOOKUP($A10,PL!$1:$1048576,MATCH(G$3,PL!$3:$3,0),FALSE) -> -40 | H10: =VLOOKUP($A10,PL!$1:$1048576,MATCH(H$3,PL!$3:$3,0),FALSE) -> -40 | I10: =VLOOKUP($A10,PL!$1:$1048576,MATCH(I$3,PL!$3:$3,0),FALSE) -> -40
A11: Other | B11: Other | D11: =D12-SUM(D6:D10) -> 631.645 | E11: =PL!E40 -> -7.1 | F11: =PL!F40 -> -21.3 | G11: =PL!G40 -> -21.3 | H11: =PL!H40 -> -21.3 | I11: =PL!I40 -> 0
A12: OCF | B12: Net Operating Cash Flow | C12: =C20 -> 273.177 | D12: =D20 -> 598.828 | E12: =SUM(E6:E11) -> 740.67853 | F12: =SUM(F6:F11) -> 946.34651 | G12: =SUM(G6:G11) -> 1085.6314 | H12: =SUM(H6:H11) -> 1237.4535 | I12: =SUM(I6:I11) -> 1424.1614
B14: Receipts from customers (inc. GST) | C14: 3291.324 | D14: 6448.08
B15: Payments to suppliers and employees (inc. GST) | C15: -2928.743 | D15: -5731.414
B16: Interest and other finance costs paid | C16: -64.227 | D16: -91.715
B17: Interest and other finance income received | C17: 56.812 | D17: 67.566
B18: Income taxes paid | C18: -81.989 | D18: -93.689
B20: Net Cash from Operating Activities | C20: =SUM(C14:C18) -> 273.177 | D20: =SUM(D14:D18) -> 598.828 | E20: =E12 -> 740.67853 | F20: =F12 -> 946.34651 | G20: =G12 -> 1085.6314 | H20: =H12 -> 1237.4535 | I20: =I12 -> 1424.1614
A22: Capex | B22: Payments for PPE | C22: -32.838 | D22: -52.562 | E22: -60 | F22: -65 | G22: -70 | H22: -75 | I22: -80
B23: Payments for financial assets at fair value through other comprehensive income | C23: -2.874 | D23: 0 | E23: 0 | F23: 0 | G23: 0 | H23: 0 | I23: 0
B24: Payments for financial assets at fair value through profit or loss | C24: 0 | D24: -2.762 | E24: 0 | F24: 0 | G24: 0 | H24: 0 | I24: 0
B25: Proceeds from acquisition of subsidiaries, net of acquired cash | C25: 0 | D25: 158.359 | E25: 0 | F25: 0 | G25: 0 | H25: 0 | I25: 0
B26: Payment for acquisition of associates | C26: 0 | D26: -3.988 | E26: 0 | F26: 0 | G26: 0 | H26: 0 | I26: 0
B27: Acquisition of intangibles | C27: -8.5 | D27: -5 | E27: 0 | F27: 0 | G27: 0 | H27: 0 | I27: 0
B28: Loans provided to other entities | C28: -10.072 | D28: -26.946 | E28: =D28 -> -26.946 | F28: =E28 -> -26.946 | G28: =F28 -> -26.946 | H28: =G28 -> -26.946 | I28: =H28 -> -26.946
B29: Loan repayments from other entities | C29: 0 | D29: 15.795 | E29: =D29 -> 15.795 | F29: =E29 -> 15.795 | G29: =F29 -> 15.795 | H29: =G29 -> 15.795 | I29: =H29 -> 15.795
A30: Proceeds from business sales | B30: Proceeds from sale of investment | C30: 3.974 | D30: 55.756 | E30: 0 | F30: 0 | G30: 0 | H30: 0 | I30: 0
B31: Distribution from associates | C31: 0.121 | D31: 0.153 | E31: 0 | F31: 0 | G31: 0 | H31: 0 | I31: 0
A32: Lease payments received | B32: Principal elements of lease receipts | C32: 109.478 | D32: 127.661 | E32: =D32*(1+Model!Y$16) -> 135.42673 | F32: =E32*(1+Model!Z$16) -> 140.54074 | G32: =F32*(1+Model!AA$16) -> 147.54884 | H32: =G32*(1+Model!AB$16) -> 154.55694 | I32: =H32*(1+Model!AC$16) -> 161.75444
B34: Net Cash from Investing Activities | C34: =SUM(C22:C32) -> 59.289 | D34: =SUM(D22:D32) -> 266.466 | E34: =SUM(E22:E32) -> 64.275728 | F34: =SUM(F22:F32) -> 64.389745 | G34: =SUM(G22:G32) -> 66.397841 | H34: =SUM(H22:H32) -> 68.405938 | I34: =SUM(I22:I32) -> 70.603442
B36: Proceeds from employee shares exercised | C36: 0 | D36: 7.182 | E36: 0 | F36: 0 | G36: 0 | H36: 0 | I36: 0
B37: Payment for issuance of shares | C37: 0 | D37: -6.416 | E37: 0 | F37: 0 | G37: 0 | H37: 0 | I37: 0
B38: Repayments of loans | C38: -778.039 | D38: -2678.916 | E38: 0 | F38: 0 | G38: 0 | H38: 0 | I38: 0
B39: Proceeds from loans | C39: 855.919 | D39: 3002.803 | E39: 0 | F39: 0 | G39: 0 | H39: 0 | I39: 0
