Workbook

Sheet Value
B2: Valuation | C2: TNE.AX
I3: DDM | J3: Units
C4: Current Price = | D4: 27.2 | F4: 38 | I4: Risk Free Rate | J4: % | K4: 0.04 | M4: 0.04
C5: Shares Outstanding = | D5: #NAME? | F5: #NAME? | I5: Beta | J5: x | K5: 0.9
C6: AS51 Index | I6: Market Premium | J6: % | K6: 0.06
C7: TARGET Relative Forward PE | I7: Ke | J7: % | K7: =K4+K5*K6 -> 0.094
C8: TARGET Forward PE | I8: ROE | J8: % p.a. | K8: 0.3
C9: PE Price Target = | E9: -1 | I9: LT Payout Ratio | J9: % p.a. | K9: 0.8 | M9: 0.034
I10: LT growth rate | J10: % p.a. | K10: =K8*(1-K9) -> 0.06 | M10: 0.06
J11: Dividend Discount Model | K11: =Annual!D251 -> 34.142188 | L11: =K11/D4-1 -> 0.2552275
I13: Implied 12M PE Ratio | J13: x | K13: 86.2x
B14: Notes | C14: Units | I14: Implied12M EV/EBITDA Ratio | J14: x | K14: #NAME?
B15: Actual Values | C15: 1000 | D15: (hard coded) | I15: EV- market | K15: #NAME?
B16: Formula | C16: 1000 | I16: ND/EV | K16: #NAME?
B17: Manual entry (assumption) | C17: 1000 | D17: (usually from guidance given by management)
C19: Actual ---> | E19: Forecast -----> | J19: Actual ---> | L19: Forecast -----> | Q19: Actual ---> | S19: Forecast ----->
C20: 2024 | D20: =C20+1 -> 2025 | E20: =D20+1 -> 2026 | F20: =E20+1 -> 2027 | G20: =F20+1 -> 2028 | J20: =C20 -> 2024 | K20: =D20 -> 2025 | L20: =E20 -> 2026 | M20: =F20 -> 2027 | N20: =G20 -> 2028 | Q20: =C20 -> 2024 | R20: =D20 -> 2025 | S20: =E20 -> 2026 | T20: =F20 -> 2027 | U20: =G20 -> 2028
B21: PE | I21: NPAT(AUDm) | P21: EBITDA (AUDm)
B22: Consensus | I22: Consensus | P22: Consensus
B23: Blackwattle | C23: =$D$4/C29 -> 75.507661 | D23: =$D$4/D29 -> 65.18426 | E23: =$D$4/E29 -> 54.855736 | F23: =$D$4/F29 -> 45.729443 | G23: =$D$4/G29 -> 37.342755 | H23: Underlying NPAT | I23: Blackwattle | J23: =INDEX(Annual!$A:$AC,MATCH(Value!$H23,Annual!$A:$A,0),MATCH(J$20,Annual!$A$1:$AC$1,0)) -> 118 | K23: =INDEX(Annual!$A:$AC,MATCH(Value!$H23,Annual!$A:$A,0),MATCH(K$20,Annual!$A$1:$AC$1,0)) -> 137.645 | L23: =INDEX(Annual!$A:$AC,MATCH(Value!$H23,Annual!$A:$A,0),MATCH(L$20,Annual!$A$1:$AC$1,0)) -> 162.63255 | M23: =INDEX(Annual!$A:$AC,MATCH(Value!$H23,Annual!$A:$A,0),MATCH(M$20,Annual!$A$1:$AC$1,0)) -> 195.08937 | N23: =INDEX(Annual!$A:$AC,MATCH(Value!$H23,Annual!$A:$A,0),MATCH(N$20,Annual!$A$1:$AC$1,0)) -> 238.90385 | O23: EBITDA-EBITDA | P23: Blackwattle | Q23: =INDEX(Annual!$A:$AC,MATCH($O23,Annual!$A:$A,0),MATCH(Q$20,Annual!$A$1:$AC$1,0)) -> 215.8 | R23: =INDEX(Annual!$A:$AC,MATCH($O23,Annual!$A:$A,0),MATCH(R$20,Annual!$A$1:$AC$1,0)) -> 255.7 | S23: =INDEX(Annual!$A:$AC,MATCH($O23,Annual!$A:$A,0),MATCH(S$20,Annual!$A$1:$AC$1,0)) -> 298.06663 | T23: =INDEX(Annual!$A:$AC,MATCH($O23,Annual!$A:$A,0),MATCH(T$20,Annual!$A$1:$AC$1,0)) -> 350.58886 | U23: =INDEX(Annual!$A:$AC,MATCH($O23,Annual!$A:$A,0),MATCH(U$20,Annual!$A$1:$AC$1,0)) -> 420.92194
B24: Difference | C24: #NAME? | D24: #NAME? | E24: #NAME? | F24: #NAME? | G24: #NAME? | I24: Difference | P24: Difference
B26: EPS (Acps) | I26: PBT (AUDm) | P26: Revenue (AUDm)
A27: =Annual!A96 -> YE Basic Shares Outstanding | B27: Shares Outstanding | D27: =INDEX(Annual!$A:$AC,MATCH($A27,Annual!$A:$A,0),MATCH(D$20,Annual!$A$1:$AC$1,0)) -> 327.36854 | E27: =INDEX(Annual!$A:$AC,MATCH($A27,Annual!$A:$A,0),MATCH(E$20,Annual!$A$1:$AC$1,0)) -> 327.36854 | F27: =INDEX(Annual!$A:$AC,MATCH($A27,Annual!$A:$A,0),MATCH(F$20,Annual!$A$1:$AC$1,0)) -> 327.36854 | G27: =INDEX(Annual!$A:$AC,MATCH($A27,Annual!$A:$A,0),MATCH(G$20,Annual!$A$1:$AC$1,0)) -> 327.36854 | I27: Consensus | P27: Consensus | S27: 687.91 | T27: 787.1
B28: Consensus | E28: 0.49 | F28: 0.59 | H28: PBT | I28: Blackwattle | J28: =INDEX(Annual!$A:$AC,MATCH(Value!$H28,Annual!$A:$A,0),MATCH(J$20,Annual!$A$1:$AC$1,0)) -> 152.9 | K28: =INDEX(Annual!$A:$AC,MATCH(Value!$H28,Annual!$A:$A,0),MATCH(K$20,Annual!$A$1:$AC$1,0)) -> 181.546 | L28: =INDEX(Annual!$A:$AC,MATCH(Value!$H28,Annual!$A:$A,0),MATCH(L$20,Annual!$A$1:$AC$1,0)) -> 214.54063 | M28: =INDEX(Annual!$A:$AC,MATCH(Value!$H28,Annual!$A:$A,0),MATCH(M$20,Annual!$A$1:$AC$1,0)) -> 257.36811 | N28: =INDEX(Annual!$A:$AC,MATCH(Value!$H28,Annual!$A:$A,0),MATCH(N$20,Annual!$A$1:$AC$1,0)) -> 315.19478 | O28: Rev-Total Revenue exc interest | P28: Blackwattle | Q28: =INDEX(Annual!$A:$AC,MATCH($O28,Annual!$A:$A,0),MATCH(Q$20,Annual!$A$1:$AC$1,0)) -> 515.4 | R28: =INDEX(Annual!$A:$AC,MATCH($O28,Annual!$A:$A,0),MATCH(R$20,Annual!$A$1:$AC$1,0)) -> 610.028 | S28: =INDEX(Annual!$A:$AC,MATCH($O28,Annual!$A:$A,0),MATCH(S$20,Annual!$A$1:$AC$1,0)) -> 694.604 | T28: =INDEX(Annual!$A:$AC,MATCH($O28,Annual!$A:$A,0),MATCH(T$20,Annual!$A$1:$AC$1,0)) -> 798.24446 | U28: =INDEX(Annual!$A:$AC,MATCH($O28,Annual!$A:$A,0),MATCH(U$20,Annual!$A$1:$AC$1,0)) -> 936.79645
A29: EPS | B29: Blackwattle | C29: =INDEX(Annual!$A:$AC,MATCH($A29,Annual!$A:$A,0),MATCH(C$20,Annual!$A$1:$AC$1,0)) -> 0.36022835 | D29: =INDEX(Annual!$A:$AC,MATCH($A29,Annual!$A:$A,0),MATCH(D$20,Annual!$A$1:$AC$1,0)) -> 0.41727865 | E29: =INDEX(Annual!$A:$AC,MATCH($A29,Annual!$A:$A,0),MATCH(E$20,Annual!$A$1:$AC$1,0)) -> 0.49584605 | F29: =INDEX(Annual!$A:$AC,MATCH($A29,Annual!$A:$A,0),MATCH(F$20,Annual!$A$1:$AC$1,0)) -> 0.59480279 | G29: =INDEX(Annual!$A:$AC,MATCH($A29,Annual!$A:$A,0),MATCH(G$20,Annual!$A$1:$AC$1,0)) -> 0.72838761 | I29: Difference | P29: Difference | S29: =S28/S27-1 -> 0.009730927 | T29: =T28/T27-1 -> 0.014158882 | U29: =U28/U27-1 -> #DIV/0!
B30: Difference | E30: =E29/E28-1 -> 0.011930713 | F30: =F29/F28-1 -> 0.0081403169 | I30: PBT margin (cons)
I31: EBIT (AUDm) | P31: EV / EBITDA
B32: DPS (Acps) | I32: Consensus | O32: Net debt | P32: Consensus
B33: Consensus | C33: #NAME? | D33: #NAME? | E33: #NAME? | F33: #NAME? | G33: #NAME? | H33: EBIT | I33: Blackwattle | J33: =INDEX(Annual!$A:$AC,MATCH(Value!$H33,Annual!$A:$A,0),MATCH(J$20,Annual!$A$1:$AC$1,0)) -> 147 | K33: =INDEX(Annual!$A:$AC,MATCH(Value!$H33,Annual!$A:$A,0),MATCH(K$20,Annual!$A$1:$AC$1,0)) -> 174.903 | L33: =INDEX(Annual!$A:$AC,MATCH(Value!$H33,Annual!$A:$A,0),MATCH(L$20,Annual!$A$1:$AC$1,0)) -> 205.74063 | M33: =INDEX(Annual!$A:$AC,MATCH(Value!$H33,Annual!$A:$A,0),MATCH(M$20,Annual!$A$1:$AC$1,0)) -> 246.26811 | N33: =INDEX(Annual!$A:$AC,MATCH(Value!$H33,Annual!$A:$A,0),MATCH(N$20,Annual!$A$1:$AC$1,0)) -> 301.49478 | O33: Net debt | P33: Blackwattle | Q33: =(INDEX(Annual!$A:$AC,MATCH($O33,Annual!$A:$A,0),MATCH(Q$20,Annual!$A$1:$AC$1,0))+$D$4*C27)/Q23 -> -1.2914736 | R33: =(INDEX(Annual!$A:$AC,MATCH($O33,Annual!$A:$A,0),MATCH(R$20,Annual!$A$1:$AC$1,0))+$D$4*D27)/R23 -> 33.573654 | S33: =(INDEX(Annual!$A:$AC,MATCH($O33,Annual!$A:$A,0),MATCH(S$20,Annual!$A$1:$AC$1,0))+$D$4*E27)/S23 -> 28.709139 | T33: =(INDEX(Annual!$A:$AC,MATCH($O33,Annual!$A:$A,0),MATCH(T$20,Annual!$A$1:$AC$1,0))+$D$4*F27)/T23 -> 24.206202 | U33: =(INDEX(Annual!$A:$AC,MATCH($O33,Annual!$A:$A,0),MATCH(U$20,Annual!$A$1:$AC$1,0))+$D$4*G27)/U23 -> 19.974314
A34: Dividends | B34: Blackwattle | C34: =INDEX(Annual!$A:$AC,MATCH($A34,Annual!$A:$A,0),MATCH(C$20,Annual!$A$1:$AC$1,0)) -> 0.22 | D34: =INDEX(Annual!$A:$AC,MATCH($A34,Annual!$A:$A,0),MATCH(D$20,Annual!$A$1:$AC$1,0)) -> 0.366 | E34: =INDEX(Annual!$A:$AC,MATCH($A34,Annual!$A:$A,0),MATCH(E$20,Annual!$A$1:$AC$1,0)) -> 0.30742455 | F34: =INDEX(Annual!$A:$AC,MATCH($A34,Annual!$A:$A,0),MATCH(F$20,Annual!$A$1:$AC$1,0)) -> 0.36877773 | G34: =INDEX(Annual!$A:$AC,MATCH($A34,Annual!$A:$A,0),MATCH(G$20,Annual!$A$1:$AC$1,0)) -> 0.45160032 | I34: Difference | P34: Difference
B35: Dividend Yield
B37: FY24 | C37: Consensus | D37: Blackwattle | E37: % Diff | F37: OLD | G37: % Diff | J37: PE | L37: EV/EBITDA | N37: EV/Sales | O37: EBITDA Growth | P37: EBITDA margin | Q37: Revenue Growth | R37: EBIT margin | S37: Rule of 40 (EBIT) | T37: Market Cap | U37: Dividend Yield | V37: Stock
B38: EBITDA | C38: #NAME? | D38: 257 | E38: #NAME? | G38: #DIV/0! | J38: FY1 | K38: FY2 | L38: FY1 | M38: FY2 | N38: NTM | O38: FY0-3 CAGR | P38: FY1 | Q38: FY0-3 CAGR | R38: FY3 | S38: FY3 | T38: AUDm | U38: NTM | V38: Code | Y38: 0.86521739
B39: D&A | C39: #NAME? | D39: 80 | E39: #NAME? | G39: #DIV/0! | I39: #NAME? | J39: #NAME? | K39: #NAME? | L39: #NAME? | M39: #NAME? | N39: #NAME? | O39: #NAME? | P39: #NAME? | Q39: #NAME? | R39: #NAME? | S39: #NAME? | T39: #NAME? | U39: #NAME? | V39: TNE.AX
B40: EBIT | C40: #NAME? | D40: 177 | E40: #NAME? | G40: #DIV/0!
B41: Net Interest | C41: #NAME? | D41: -7 | E41: #NAME? | G41: #DIV/0! | I41: Global SaaS
B42: PBT | C42: #NAME? | D42: 185 | E42: #NAME? | G42: #DIV/0! | I42: #NAME? | J42: #NAME? | K42: #NAME? | L42: #NAME? | M42: #NAME? | N42: #NAME? | O42: #NAME? | P42: #NAME? | Q42: #NAME? | R42: #NAME? | S42: #NAME? | T42: #NAME? | U42: #NAME? | V42: SAP.N
B43: Tax | C43: #NAME? | D43: 43 | E43: #NAME? | G43: #DIV/0! | I43: #NAME? | J43: #NAME? | K43: #NAME? | L43: #NAME? | M43: #NAME? | N43: #NAME? | O43: #NAME? | P43: #NAME? | Q43: #NAME? | R43: #NAME? | S43: #NAME? | T43: #NAME? | U43: #NAME? | V43: ORCL.K
B44: Tax Rate | C44: #NAME? | D44: 0.23 | E44: #NAME? | G44: #DIV/0! | I44: #NAME? | J44: #NAME? | K44: #NAME? | L44: #NAME? | M44: #NAME? | N44: #NAME? | O44: #NAME? | P44: #NAME? | Q44: #NAME? | R44: #NAME? | S44: #NAME? | T44: #NAME? | U44: #NAME? | V44: WDAY.O
B45: NPAT | C45: #NAME? | D45: 142 | E45: #NAME? | G45: #DIV/0! | I45: #NAME? | J45: #NAME? | K45: #NAME? | L45: #NAME? | M45: #NAME? | N45: #NAME? | O45: #NAME? | P45: #NAME? | Q45: #NAME? | R45: #NAME? | S45: #NAME? | T45: #NAME? | U45: #NAME? | V45: CRM.N
...

Sheet Annual
B1: TNE Model Summary | E1: 2012 | F1: 2013 | G1: 2014 | H1: 2015 | I1: 2016 | J1: 2017 | K1: 2018 | L1: 2019 | M1: 2020 | N1: 2021 | O1: 2022 | P1: 2023 | Q1: 2024 | R1: =Q1+1 -> 2025 | S1: 2026 | T1: 2027 | U1: 2028 | V1: 2029 | W1: 2030 | X1: 2031 | Y1: 2032 | Z1: 2033 | AA1: 2034 | AB1: 2035 | AD1: Earnings changes=> | AE1: 2025 | AF1: 2024 | AG1: 2026 | AH1: 2024
E2: Actual ----------> | S2: Forecast -----> | AF2: Forecast -----> | AG2: Forecast -----> | AH2: Forecast ----->
C3: Units | D3: Source | E3: FY12A | F3: FY13A | G3: FY14A | H3: FY15A | I3: FY16A | J3: FY17A | K3: FY18A | L3: FY19A | M3: FY20A | N3: FY21A | O3: FY22A | P3: FY23A | Q3: FY24A | R3: FY25A | S3: FY26E | T3: FY27E | U3: FY28E | V3: FY29E | W3: FY30E | X3: FY31E | Y3: FY32E | Z3: FY33E | AA3: FY34E | AB3: FY35E | AE3: FY25E | AF3: FY24E | AG3: FY26E | AH3: FY24E
B4: P &L
B5: Revenue | K5: *restated in FY19, with new revenue recognition
A6: Rev-SaaS fees | B6: SaaS fees | C6: AUDm | D6: AR | K6: 58.1 | L6: 81.5 | M6: 106.2 | N6: 151.1 | O6: 216.8 | P6: 316.2 | Q6: 407.4 | R6: 499.725 | S6: =INDEX(Segment!$A:$AR,MATCH(Annual!$A6,Segment!$A:$A,0),MATCH("1H"&RIGHT(Annual!S$1,2),Segment!$A$3:$AR$3,0))+INDEX(Segment!$A:$AR,MATCH(Annual!$A6,Segment!$A:$A,0),MATCH("2H"&RIGHT(Annual!S$1,2),Segment!$A$3:$AR$3,0)) -> 587.6793 | T6: =INDEX(Segment!$A:$AR,MATCH(Annual!$A6,Segment!$A:$A,0),MATCH("1H"&RIGHT(Annual!T$1,2),Segment!$A$3:$AR$3,0))+INDEX(Segment!$A:$AR,MATCH(Annual!$A6,Segment!$A:$A,0),MATCH("2H"&RIGHT(Annual!T$1,2),Segment!$A$3:$AR$3,0)) -> 695.66914 | U6: =INDEX(Segment!$A:$AR,MATCH(Annual!$A6,Segment!$A:$A,0),MATCH("1H"&RIGHT(Annual!U$1,2),Segment!$A$3:$AR$3,0))+INDEX(Segment!$A:$AR,MATCH(Annual!$A6,Segment!$A:$A,0),MATCH("2H"&RIGHT(Annual!U$1,2),Segment!$A$3:$AR$3,0)) -> 838.35305 | V6: =INDEX(Segment!$A:$AR,MATCH(Annual!$A6,Segment!$A:$A,0),MATCH("1H"&RIGHT(Annual!V$1,2),Segment!$A$3:$AR$3,0))+INDEX(Segment!$A:$AR,MATCH(Annual!$A6,Segment!$A:$A,0),MATCH("2H"&RIGHT(Annual!V$1,2),Segment!$A$3:$AR$3,0)) -> 1017.4705 | W6: =INDEX(Segment!$A:$AR,MATCH(Annual!$A6,Segment!$A:$A,0),MATCH("1H"&RIGHT(Annual!W$1,2),Segment!$A$3:$AR$3,0))+INDEX(Segment!$A:$AR,MATCH(Annual!$A6,Segment!$A:$A,0),MATCH("2H"&RIGHT(Annual!W$1,2),Segment!$A$3:$AR$3,0)) -> 1232.6543 | X6: =INDEX(Segment!$A:$AR,MATCH(Annual!$A6,Segment!$A:$A,0),MATCH("1H"&RIGHT(Annual!X$1,2),Segment!$A$3:$AR$3,0))+INDEX(Segment!$A:$AR,MATCH(Annual!$A6,Segment!$A:$A,0),MATCH("2H"&RIGHT(Annual!X$1,2),Segment!$A$3:$AR$3,0)) -> 1494.4905 | Y6: =INDEX(Segment!$A:$AR,MATCH(Annual!$A6,Segment!$A:$A,0),MATCH("1H"&RIGHT(Annual!Y$1,2),Segment!$A$3:$AR$3,0))+INDEX(Segment!$A:$AR,MATCH(Annual!$A6,Segment!$A:$A,0),MATCH("2H"&RIGHT(Annual!Y$1,2),Segment!$A$3:$AR$3,0)) -> 1813.5007 | Z6: =INDEX(Segment!$A:$AR,MATCH(Annual!$A6,Segment!$A:$A,0),MATCH("1H"&RIGHT(Annual!Z$1,2),Segment!$A$3:$AR$3,0))+INDEX(Segment!$A:$AR,MATCH(Annual!$A6,Segment!$A:$A,0),MATCH("2H"&RIGHT(Annual!Z$1,2),Segment!$A$3:$AR$3,0)) -> 2202.6851 | ... AB6: =INDEX(Segment!$A:$AR,MATCH(Annual!$A6,Segment!$A:$A,0),MATCH("1H"&RIGHT(Annual!AB$1,2),Segment!$A$3:$AR$3,0))+INDEX(Segment!$A:$AR,MATCH(Annual!$A6,Segment!$A:$A,0),MATCH("2H"&RIGHT(Annual!AB$1,2),Segment!$A$3:$AR$3,0)) -> 3259.7924 | AE6: 496.60116 | AF6: =IF(ISBLANK(AE6),"",INDEX($A6:$AB6,1,MATCH(AE$3,$A$3:$AB$3,0))-AE6) -> #N/A | AG6: 597.66026 | AH6: =IF(ISBLANK(AG6),"",INDEX($A6:$AB6,1,MATCH(AG$3,$A$3:$AB$3,0))-AG6) -> -9.9809589
A7: Rev-Annual licence fees | B7: Annual licence fees | C7: AUDm | D7: AR | K7: 103 | L7: 98.7 | M7: 101.1 | N7: 78 | O7: 69.2 | P7: 37 | Q7: 17.8 | R7: 7.211 | S7: =INDEX(Segment!$A:$AR,MATCH(Annual!$A7,Segment!$A:$A,0),MATCH("1H"&RIGHT(Annual!S$1,2),Segment!$A$3:$AR$3,0))+INDEX(Segment!$A:$AR,MATCH(Annual!$A7,Segment!$A:$A,0),MATCH("2H"&RIGHT(Annual!S$1,2),Segment!$A$3:$AR$3,0)) -> 7.211 | T7: =INDEX(Segment!$A:$AR,MATCH(Annual!$A7,Segment!$A:$A,0),MATCH("1H"&RIGHT(Annual!T$1,2),Segment!$A$3:$AR$3,0))+INDEX(Segment!$A:$AR,MATCH(Annual!$A7,Segment!$A:$A,0),MATCH("2H"&RIGHT(Annual!T$1,2),Segment!$A$3:$AR$3,0)) -> 7.211 | U7: =INDEX(Segment!$A:$AR,MATCH(Annual!$A7,Segment!$A:$A,0),MATCH("1H"&RIGHT(Annual!U$1,2),Segment!$A$3:$AR$3,0))+INDEX(Segment!$A:$AR,MATCH(Annual!$A7,Segment!$A:$A,0),MATCH("2H"&RIGHT(Annual!U$1,2),Segment!$A$3:$AR$3,0)) -> 7.211 | V7: =INDEX(Segment!$A:$AR,MATCH(Annual!$A7,Segment!$A:$A,0),MATCH("1H"&RIGHT(Annual!V$1,2),Segment!$A$3:$AR$3,0))+INDEX(Segment!$A:$AR,MATCH(Annual!$A7,Segment!$A:$A,0),MATCH("2H"&RIGHT(Annual!V$1,2),Segment!$A$3:$AR$3,0)) -> 7.211 | W7: =INDEX(Segment!$A:$AR,MATCH(Annual!$A7,Segment!$A:$A,0),MATCH("1H"&RIGHT(Annual!W$1,2),Segment!$A$3:$AR$3,0))+INDEX(Segment!$A:$AR,MATCH(Annual!$A7,Segment!$A:$A,0),MATCH("2H"&RIGHT(Annual!W$1,2),Segment!$A$3:$AR$3,0)) -> 7.211 | X7: =INDEX(Segment!$A:$AR,MATCH(Annual!$A7,Segment!$A:$A,0),MATCH("1H"&RIGHT(Annual!X$1,2),Segment!$A$3:$AR$3,0))+INDEX(Segment!$A:$AR,MATCH(Annual!$A7,Segment!$A:$A,0),MATCH("2H"&RIGHT(Annual!X$1,2),Segment!$A$3:$AR$3,0)) -> 7.211 | Y7: =INDEX(Segment!$A:$AR,MATCH(Annual!$A7,Segment!$A:$A,0),MATCH("1H"&RIGHT(Annual!Y$1,2),Segment!$A$3:$AR$3,0))+INDEX(Segment!$A:$AR,MATCH(Annual!$A7,Segment!$A:$A,0),MATCH("2H"&RIGHT(Annual!Y$1,2),Segment!$A$3:$AR$3,0)) -> 7.211 | Z7: =INDEX(Segment!$A:$AR,MATCH(Annual!$A7,Segment!$A:$A,0),MATCH("1H"&RIGHT(Annual!Z$1,2),Segment!$A$3:$AR$3,0))+INDEX(Segment!$A:$AR,MATCH(Annual!$A7,Segment!$A:$A,0),MATCH("2H"&RIGHT(Annual!Z$1,2),Segment!$A$3:$AR$3,0)) -> 7.211 | ... AB7: =INDEX(Segment!$A:$AR,MATCH(Annual!$A7,Segment!$A:$A,0),MATCH("1H"&RIGHT(Annual!AB$1,2),Segment!$A$3:$AR$3,0))+INDEX(Segment!$A:$AR,MATCH(Annual!$A7,Segment!$A:$A,0),MATCH("2H"&RIGHT(Annual!AB$1,2),Segment!$A$3:$AR$3,0)) -> 7.211 | AE7: 8.2 | AF7: =IF(ISBLANK(AE7),"",INDEX($A7:$AB7,1,MATCH(AE$3,$A$3:$AB$3,0))-AE7) -> #N/A | AG7: 8.2 | AH7: =IF(ISBLANK(AG7),"",INDEX($A7:$AB7,1,MATCH(AG$3,$A$3:$AB$3,0))-AG7) -> -0.989
A8: Rev-Consulting services | B8: Consulting services | C8: AUDm | D8: AR | K8: 63.2 | L8: 61.6 | M8: 62.5 | N8: 64.5 | O8: 72.7 | P8: 73.2 | Q8: 80.5 | R8: 91.566 | S8: =INDEX(Segment!$A:$AR,MATCH(Annual!$A8,Segment!$A:$A,0),MATCH("1H"&RIGHT(Annual!S$1,2),Segment!$A$3:$AR$3,0))+INDEX(Segment!$A:$AR,MATCH(Annual!$A8,Segment!$A:$A,0),MATCH("2H"&RIGHT(Annual!S$1,2),Segment!$A$3:$AR$3,0)) -> 86.9877 | T8: =INDEX(Segment!$A:$AR,MATCH(Annual!$A8,Segment!$A:$A,0),MATCH("1H"&RIGHT(Annual!T$1,2),Segment!$A$3:$AR$3,0))+INDEX(Segment!$A:$AR,MATCH(Annual!$A8,Segment!$A:$A,0),MATCH("2H"&RIGHT(Annual!T$1,2),Segment!$A$3:$AR$3,0)) -> 82.638315 | U8: =INDEX(Segment!$A:$AR,MATCH(Annual!$A8,Segment!$A:$A,0),MATCH("1H"&RIGHT(Annual!U$1,2),Segment!$A$3:$AR$3,0))+INDEX(Segment!$A:$AR,MATCH(Annual!$A8,Segment!$A:$A,0),MATCH("2H"&RIGHT(Annual!U$1,2),Segment!$A$3:$AR$3,0)) -> 78.506399 | V8: =INDEX(Segment!$A:$AR,MATCH(Annual!$A8,Segment!$A:$A,0),MATCH("1H"&RIGHT(Annual!V$1,2),Segment!$A$3:$AR$3,0))+INDEX(Segment!$A:$AR,MATCH(Annual!$A8,Segment!$A:$A,0),MATCH("2H"&RIGHT(Annual!V$1,2),Segment!$A$3:$AR$3,0)) -> 74.581079 | W8: =INDEX(Segment!$A:$AR,MATCH(Annual!$A8,Segment!$A:$A,0),MATCH("1H"&RIGHT(Annual!W$1,2),Segment!$A$3:$AR$3,0))+INDEX(Segment!$A:$AR,MATCH(Annual!$A8,Segment!$A:$A,0),MATCH("2H"&RIGHT(Annual!W$1,2),Segment!$A$3:$AR$3,0)) -> 70.852025 | X8: =INDEX(Segment!$A:$AR,MATCH(Annual!$A8,Segment!$A:$A,0),MATCH("1H"&RIGHT(Annual!X$1,2),Segment!$A$3:$AR$3,0))+INDEX(Segment!$A:$AR,MATCH(Annual!$A8,Segment!$A:$A,0),MATCH("2H"&RIGHT(Annual!X$1,2),Segment!$A$3:$AR$3,0)) -> 67.309424 | Y8: =INDEX(Segment!$A:$AR,MATCH(Annual!$A8,Segment!$A:$A,0),MATCH("1H"&RIGHT(Annual!Y$1,2),Segment!$A$3:$AR$3,0))+INDEX(Segment!$A:$AR,MATCH(Annual!$A8,Segment!$A:$A,0),MATCH("2H"&RIGHT(Annual!Y$1,2),Segment!$A$3:$AR$3,0)) -> 63.943953 | Z8: =INDEX(Segment!$A:$AR,MATCH(Annual!$A8,Segment!$A:$A,0),MATCH("1H"&RIGHT(Annual!Z$1,2),Segment!$A$3:$AR$3,0))+INDEX(Segment!$A:$AR,MATCH(Annual!$A8,Segment!$A:$A,0),MATCH("2H"&RIGHT(Annual!Z$1,2),Segment!$A$3:$AR$3,0)) -> 60.746755 | ... AB8: =INDEX(Segment!$A:$AR,MATCH(Annual!$A8,Segment!$A:$A,0),MATCH("1H"&RIGHT(Annual!AB$1,2),Segment!$A$3:$AR$3,0))+INDEX(Segment!$A:$AR,MATCH(Annual!$A8,Segment!$A:$A,0),MATCH("2H"&RIGHT(Annual!AB$1,2),Segment!$A$3:$AR$3,0)) -> 54.823947 | AE8: 89.01 | AF8: =IF(ISBLANK(AE8),"",INDEX($A8:$AB8,1,MATCH(AE$3,$A$3:$AB$3,0))-AE8) -> #N/A | AG8: 84.5595 | AH8: =IF(ISBLANK(AG8),"",INDEX($A8:$AB8,1,MATCH(AG$3,$A$3:$AB$3,0))-AG8) -> 2.4282
A9: Rev-Legacy licence services (initial fees) | B9: Legacy licence services (initial fees) | C9: AUDm | D9: AR | K9: 28.7 | L9: 43.2 | M9: 28.5 | N9: 17.7 | O9: 9.6 | P9: 3 | Q9: 0.8 | R9: 0 | S9: =INDEX(Segment!$A:$AR,MATCH(Annual!$A9,Segment!$A:$A,0),MATCH("1H"&RIGHT(Annual!S$1,2),Segment!$A$3:$AR$3,0))+INDEX(Segment!$A:$AR,MATCH(Annual!$A9,Segment!$A:$A,0),MATCH("2H"&RIGHT(Annual!S$1,2),Segment!$A$3:$AR$3,0)) -> 1.2 | T9: =INDEX(Segment!$A:$AR,MATCH(Annual!$A9,Segment!$A:$A,0),MATCH("1H"&RIGHT(Annual!T$1,2),Segment!$A$3:$AR$3,0))+INDEX(Segment!$A:$AR,MATCH(Annual!$A9,Segment!$A:$A,0),MATCH("2H"&RIGHT(Annual!T$1,2),Segment!$A$3:$AR$3,0)) -> 1.2 | U9: =INDEX(Segment!$A:$AR,MATCH(Annual!$A9,Segment!$A:$A,0),MATCH("1H"&RIGHT(Annual!U$1,2),Segment!$A$3:$AR$3,0))+INDEX(Segment!$A:$AR,MATCH(Annual!$A9,Segment!$A:$A,0),MATCH("2H"&RIGHT(Annual!U$1,2),Segment!$A$3:$AR$3,0)) -> 1.2 | V9: =INDEX(Segment!$A:$AR,MATCH(Annual!$A9,Segment!$A:$A,0),MATCH("1H"&RIGHT(Annual!V$1,2),Segment!$A$3:$AR$3,0))+INDEX(Segment!$A:$AR,MATCH(Annual!$A9,Segment!$A:$A,0),MATCH("2H"&RIGHT(Annual!V$1,2),Segment!$A$3:$AR$3,0)) -> 1.2 | W9: =INDEX(Segment!$A:$AR,MATCH(Annual!$A9,Segment!$A:$A,0),MATCH("1H"&RIGHT(Annual!W$1,2),Segment!$A$3:$AR$3,0))+INDEX(Segment!$A:$AR,MATCH(Annual!$A9,Segment!$A:$A,0),MATCH("2H"&RIGHT(Annual!W$1,2),Segment!$A$3:$AR$3,0)) -> 1.2 | X9: =INDEX(Segment!$A:$AR,MATCH(Annual!$A9,Segment!$A:$A,0),MATCH("1H"&RIGHT(Annual!X$1,2),Segment!$A$3:$AR$3,0))+INDEX(Segment!$A:$AR,MATCH(Annual!$A9,Segment!$A:$A,0),MATCH("2H"&RIGHT(Annual!X$1,2),Segment!$A$3:$AR$3,0)) -> 1.2 | Y9: =INDEX(Segment!$A:$AR,MATCH(Annual!$A9,Segment!$A:$A,0),MATCH("1H"&RIGHT(Annual!Y$1,2),Segment!$A$3:$AR$3,0))+INDEX(Segment!$A:$AR,MATCH(Annual!$A9,Segment!$A:$A,0),MATCH("2H"&RIGHT(Annual!Y$1,2),Segment!$A$3:$AR$3,0)) -> 1.2 | Z9: =INDEX(Segment!$A:$AR,MATCH(Annual!$A9,Segment!$A:$A,0),MATCH("1H"&RIGHT(Annual!Z$1,2),Segment!$A$3:$AR$3,0))+INDEX(Segment!$A:$AR,MATCH(Annual!$A9,Segment!$A:$A,0),MATCH("2H"&RIGHT(Annual!Z$1,2),Segment!$A$3:$AR$3,0)) -> 1.2 | ... AB9: =INDEX(Segment!$A:$AR,MATCH(Annual!$A9,Segment!$A:$A,0),MATCH("1H"&RIGHT(Annual!AB$1,2),Segment!$A$3:$AR$3,0))+INDEX(Segment!$A:$AR,MATCH(Annual!$A9,Segment!$A:$A,0),MATCH("2H"&RIGHT(Annual!AB$1,2),Segment!$A$3:$AR$3,0)) -> 1.2 | AE9: 0.6 | AF9: =IF(ISBLANK(AE9),"",INDEX($A9:$AB9,1,MATCH(AE$3,$A$3:$AB$3,0))-AE9) -> #N/A | AG9: 1.2 | AH9: =IF(ISBLANK(AG9),"",INDEX($A9:$AB9,1,MATCH(AG$3,$A$3:$AB$3,0))-AG9) -> 0
A10: Rev-Revenue from contracts with customers | B10: Revenue from contracts with customers | C10: AUDm | K10: 253 | L10: 285 | M10: 298.3 | N10: 311.3 | O10: 368.2 | P10: 429.4 | Q10: =SUM(Q6:Q9) -> 506.5 | R10: =SUM(R6:R9) -> 598.502 | S10: =INDEX(Segment!$A:$AR,MATCH(Annual!$A10,Segment!$A:$A,0),MATCH("1H"&RIGHT(Annual!S$1,2),Segment!$A$3:$AR$3,0))+INDEX(Segment!$A:$AR,MATCH(Annual!$A10,Segment!$A:$A,0),MATCH("2H"&RIGHT(Annual!S$1,2),Segment!$A$3:$AR$3,0)) -> 683.078 | T10: =INDEX(Segment!$A:$AR,MATCH(Annual!$A10,Segment!$A:$A,0),MATCH("1H"&RIGHT(Annual!T$1,2),Segment!$A$3:$AR$3,0))+INDEX(Segment!$A:$AR,MATCH(Annual!$A10,Segment!$A:$A,0),MATCH("2H"&RIGHT(Annual!T$1,2),Segment!$A$3:$AR$3,0)) -> 786.71846 | U10: =INDEX(Segment!$A:$AR,MATCH(Annual!$A10,Segment!$A:$A,0),MATCH("1H"&RIGHT(Annual!U$1,2),Segment!$A$3:$AR$3,0))+INDEX(Segment!$A:$AR,MATCH(Annual!$A10,Segment!$A:$A,0),MATCH("2H"&RIGHT(Annual!U$1,2),Segment!$A$3:$AR$3,0)) -> 925.27045 | V10: =INDEX(Segment!$A:$AR,MATCH(Annual!$A10,Segment!$A:$A,0),MATCH("1H"&RIGHT(Annual!V$1,2),Segment!$A$3:$AR$3,0))+INDEX(Segment!$A:$AR,MATCH(Annual!$A10,Segment!$A:$A,0),MATCH("2H"&RIGHT(Annual!V$1,2),Segment!$A$3:$AR$3,0)) -> 1100.4626 | W10: =INDEX(Segment!$A:$AR,MATCH(Annual!$A10,Segment!$A:$A,0),MATCH("1H"&RIGHT(Annual!W$1,2),Segment!$A$3:$AR$3,0))+INDEX(Segment!$A:$AR,MATCH(Annual!$A10,Segment!$A:$A,0),MATCH("2H"&RIGHT(Annual!W$1,2),Segment!$A$3:$AR$3,0)) -> 1311.9173 | X10: =INDEX(Segment!$A:$AR,MATCH(Annual!$A10,Segment!$A:$A,0),MATCH("1H"&RIGHT(Annual!X$1,2),Segment!$A$3:$AR$3,0))+INDEX(Segment!$A:$AR,MATCH(Annual!$A10,Segment!$A:$A,0),MATCH("2H"&RIGHT(Annual!X$1,2),Segment!$A$3:$AR$3,0)) -> 1570.2109 | Y10: =INDEX(Segment!$A:$AR,MATCH(Annual!$A10,Segment!$A:$A,0),MATCH("1H"&RIGHT(Annual!Y$1,2),Segment!$A$3:$AR$3,0))+INDEX(Segment!$A:$AR,MATCH(Annual!$A10,Segment!$A:$A,0),MATCH("2H"&RIGHT(Annual!Y$1,2),Segment!$A$3:$AR$3,0)) -> 1885.8557 | Z10: =INDEX(Segment!$A:$AR,MATCH(Annual!$A10,Segment!$A:$A,0),MATCH("1H"&RIGHT(Annual!Z$1,2),Segment!$A$3:$AR$3,0))+INDEX(Segment!$A:$AR,MATCH(Annual!$A10,Segment!$A:$A,0),MATCH("2H"&RIGHT(Annual!Z$1,2),Segment!$A$3:$AR$3,0)) -> 2271.8428 | ... AB10: =INDEX(Segment!$A:$AR,MATCH(Annual!$A10,Segment!$A:$A,0),MATCH("1H"&RIGHT(Annual!AB$1,2),Segment!$A$3:$AR$3,0))+INDEX(Segment!$A:$AR,MATCH(Annual!$A10,Segment!$A:$A,0),MATCH("2H"&RIGHT(Annual!AB$1,2),Segment!$A$3:$AR$3,0)) -> 3323.0273 | AE10: 594.41116 | AF10: =IF(ISBLANK(AE10),"",INDEX($A10:$AB10,1,MATCH(AE$3,$A$3:$AB$3,0))-AE10) -> #N/A | AG10: 691.61976 | AH10: =IF(ISBLANK(AG10),"",INDEX($A10:$AB10,1,MATCH(AG$3,$A$3:$AB$3,0))-AG10) -> -8.5417589
B11: Growth | C11: % YoY | K11: #DIV/0! | L11: 0.127 | M11: 0.047 | N11: 0.044 | O11: 0.183 | P11: 0.166 | Q11: =Q10/P10-1 -> 0.17955286 | R11: =R10/Q10-1 -> 0.18164265 | S11: =S10/R10-1 -> 0.14131281 | T11: =T10/S10-1 -> 0.15172565 | U11: =U10/T10-1 -> 0.17611382 | V11: =V10/U10-1 -> 0.18934156 | W11: =W10/V10-1 -> 0.19215078 | X11: =X10/W10-1 -> 0.19688249 | ... AB11: =AB10/AA10-1 -> 0.21090395 | AE11: 0.17356596 | AF11: =IF(ISBLANK(AE11),"",INDEX($A11:$AB11,1,MATCH(AE$3,$A$3:$AB$3,0))-AE11) -> #N/A | AG11: 0.16353765 | AH11: =IF(ISBLANK(AG11),"",INDEX($A11:$AB11,1,MATCH(AG$3,$A$3:$AB$3,0))-AG11) -> -0.022224836
AF12: =IF(ISBLANK(AE12),"",INDEX($A12:$AB12,1,MATCH(AE$3,$A$3:$AB$3,0))-AE12) | AH12: =IF(ISBLANK(AG12),"",INDEX($A12:$AB12,1,MATCH(AG$3,$A$3:$AB$3,0))-AG12)
B13: Traditional Consulting Model | AF13: =IF(ISBLANK(AE13),"",INDEX($A13:$AB13,1,MATCH(AE$3,$A$3:$AB$3,0))-AE13) | AH13: =IF(ISBLANK(AG13),"",INDEX($A13:$AB13,1,MATCH(AG$3,$A$3:$AB$3,0))-AG13)
B14: Revenue | AF14: =IF(ISBLANK(AE14),"",INDEX($A14:$AB14,1,MATCH(AE$3,$A$3:$AB$3,0))-AE14) | AH14: =IF(ISBLANK(AG14),"",INDEX($A14:$AB14,1,MATCH(AG$3,$A$3:$AB$3,0))-AG14)
A15: Rev-SaaS fees | B15: SaaS fees | C15: AUDm | D15: AR | K15: 58.1 | L15: 81.5 | M15: 106.2 | N15: 151.1 | O15: 216.8 | P15: 316.2 | Q15: =Q6 -> 407.4 | R15: =R6 -> 499.725 | AF15: =IF(ISBLANK(AE15),"",INDEX($A15:$AB15,1,MATCH(AE$3,$A$3:$AB$3,0))-AE15) | AH15: =IF(ISBLANK(AG15),"",INDEX($A15:$AB15,1,MATCH(AG$3,$A$3:$AB$3,0))-AG15)
B16: Growth from upgrades/implementations (Consulting:SaaS 1.6 ratio) | C16: AUDm | L16: 39.5 | M16: 38.5 | N16: 39.1 | O16: 40.3 | P16: =O22/1.6 -> 45.4375 | Q16: =P22/1.6 -> 45.75 | R16: =Q22/1.6 -> 50.3125 | AF16: =IF(ISBLANK(AE16),"",INDEX($A16:$AB16,1,MATCH(AE$3,$A$3:$AB$3,0))-AE16) | AH16: =IF(ISBLANK(AG16),"",INDEX($A16:$AB16,1,MATCH(AG$3,$A$3:$AB$3,0))-AG16)
B17: Saas Flip | L17: 4.3 | M17: -2.4 | N17: 23.1 | O17: 8.8 | P17: 32.2 | Q17: =-(Q7-P7) -> 19.2 | R17: =-(R7-Q7) -> 10.589 | AF17: =IF(ISBLANK(AE17),"",INDEX($A17:$AB17,1,MATCH(AE$3,$A$3:$AB$3,0))-AE17) | AH17: =IF(ISBLANK(AG17),"",INDEX($A17:$AB17,1,MATCH(AG$3,$A$3:$AB$3,0))-AG17)
B18: Other Growth | C18: AUDm | L18: -20.4 | M18: -11.4 | N18: -17.3 | O18: 16.6 | P18: 21.8 | Q18: =Q15-P15-Q16-Q17 -> 26.25 | R18: =R15-Q15-R16-R17 -> 31.4235 | AF18: =IF(ISBLANK(AE18),"",INDEX($A18:$AB18,1,MATCH(AE$3,$A$3:$AB$3,0))-AE18) | AH18: =IF(ISBLANK(AG18),"",INDEX($A18:$AB18,1,MATCH(AG$3,$A$3:$AB$3,0))-AG18)
B19: Other Growth % of pcp | C19: % | M19: -0.14 | N19: -0.16 | O19: 0.11 | P19: 0.1 | Q19: 0.08 | R19: 0.08 | AF19: =IF(ISBLANK(AE19),"",INDEX($A19:$AB19,1,MATCH(AE$3,$A$3:$AB$3,0))-AE19) | AH19: =IF(ISBLANK(AG19),"",INDEX($A19:$AB19,1,MATCH(AG$3,$A$3:$AB$3,0))-AG19)
AF20: =IF(ISBLANK(AE20),"",INDEX($A20:$AB20,1,MATCH(AE$3,$A$3:$AB$3,0))-AE20) | AH20: =IF(ISBLANK(AG20),"",INDEX($A20:$AB20,1,MATCH(AG$3,$A$3:$AB$3,0))-AG20)
B21: Annual license fees + Legacy | C21: AUDm | K21: 131.7 | L21: 141.9 | M21: 129.6 | N21: 95.7 | O21: 78.8 | P21: 40 | Q21: =Q7+Q9 -> 18.6 | R21: =R7+R9 -> 7.211 | AF21: =IF(ISBLANK(AE21),"",INDEX($A21:$AB21,1,MATCH(AE$3,$A$3:$AB$3,0))-AE21) | AH21: =IF(ISBLANK(AG21),"",INDEX($A21:$AB21,1,MATCH(AG$3,$A$3:$AB$3,0))-AG21)
A22: Rev-Consulting services | B22: Consulting services | C22: AUDm | D22: AR | K22: 63.2 | L22: 61.6 | M22: 62.5 | N22: 64.5 | O22: 72.7 | P22: 73.2 | Q22: =Q8 -> 80.5 | R22: =R8 -> 91.566 | AF22: =IF(ISBLANK(AE22),"",INDEX($A22:$AB22,1,MATCH(AE$3,$A$3:$AB$3,0))-AE22) | AH22: =IF(ISBLANK(AG22),"",INDEX($A22:$AB22,1,MATCH(AG$3,$A$3:$AB$3,0))-AG22)
B23: Growth | C23: % YoY | K23: #DIV/0! | L23: -0.025 | M23: 0.014 | N23: 0.032 | O23: 0.127 | P23: 0.007 | Q23: =Q22/P22-1 -> 0.099726776 | R23: =R22/Q22-1 -> 0.13746584 | AF23: =IF(ISBLANK(AE23),"",INDEX($A23:$AB23,1,MATCH(AE$3,$A$3:$AB$3,0))-AE23) | AH23: =IF(ISBLANK(AG23),"",INDEX($A23:$AB23,1,MATCH(AG$3,$A$3:$AB$3,0))-AG23)
B24: Total Revenue | C24: AUDm | K24: 253 | L24: 285 | M24: 298.3 | N24: 311.3 | O24: 368.2 | P24: 429.4 | Q24: =Q10 -> 506.5 | R24: =R10 -> 598.502 | AF24: =IF(ISBLANK(AE24),"",INDEX($A24:$AB24,1,MATCH(AE$3,$A$3:$AB$3,0))-AE24) | AH24: =IF(ISBLANK(AG24),"",INDEX($A24:$AB24,1,MATCH(AG$3,$A$3:$AB$3,0))-AG24)
AF25: =IF(ISBLANK(AE25),"",INDEX($A25:$AB25,1,MATCH(AE$3,$A$3:$AB$3,0))-AE25) | AH25: =IF(ISBLANK(AG25),"",INDEX($A25:$AB25,1,MATCH(AG$3,$A$3:$AB$3,0))-AG25)
A26: Rev-Other income exc interest | B26: Other income exc interest | C26: AUDm | K26: 0.8 | L26: 0.6 | M26: 0.4 | N26: 0.5 | O26: 0.7 | P26: 7.8 | Q26: 8.9 | R26: 11.526 | S26: =INDEX(Segment!$A:$AR,MATCH(Annual!$A26,Segment!$A:$A,0),MATCH("1H"&RIGHT(Annual!S$1,2),Segment!$A$3:$AR$3,0))+INDEX(Segment!$A:$AR,MATCH(Annual!$A26,Segment!$A:$A,0),MATCH("2H"&RIGHT(Annual!S$1,2),Segment!$A$3:$AR$3,0)) -> 11.526 | T26: =INDEX(Segment!$A:$AR,MATCH(Annual!$A26,Segment!$A:$A,0),MATCH("1H"&RIGHT(Annual!T$1,2),Segment!$A$3:$AR$3,0))+INDEX(Segment!$A:$AR,MATCH(Annual!$A26,Segment!$A:$A,0),MATCH("2H"&RIGHT(Annual!T$1,2),Segment!$A$3:$AR$3,0)) -> 11.526 | U26: =INDEX(Segment!$A:$AR,MATCH(Annual!$A26,Segment!$A:$A,0),MATCH("1H"&RIGHT(Annual!U$1,2),Segment!$A$3:$AR$3,0))+INDEX(Segment!$A:$AR,MATCH(Annual!$A26,Segment!$A:$A,0),MATCH("2H"&RIGHT(Annual!U$1,2),Segment!$A$3:$AR$3,0)) -> 11.526 | V26: =INDEX(Segment!$A:$AR,MATCH(Annual!$A26,Segment!$A:$A,0),MATCH("1H"&RIGHT(Annual!V$1,2),Segment!$A$3:$AR$3,0))+INDEX(Segment!$A:$AR,MATCH(Annual!$A26,Segment!$A:$A,0),MATCH("2H"&RIGHT(Annual!V$1,2),Segment!$A$3:$AR$3,0)) -> 11.526 | W26: =INDEX(Segment!$A:$AR,MATCH(Annual!$A26,Segment!$A:$A,0),MATCH("1H"&RIGHT(Annual!W$1,2),Segment!$A$3:$AR$3,0))+INDEX(Segment!$A:$AR,MATCH(Annual!$A26,Segment!$A:$A,0),MATCH("2H"&RIGHT(Annual!W$1,2),Segment!$A$3:$AR$3,0)) -> 11.526 | X26: =INDEX(Segment!$A:$AR,MATCH(Annual!$A26,Segment!$A:$A,0),MATCH("1H"&RIGHT(Annual!X$1,2),Segment!$A$3:$AR$3,0))+INDEX(Segment!$A:$AR,MATCH(Annual!$A26,Segment!$A:$A,0),MATCH("2H"&RIGHT(Annual!X$1,2),Segment!$A$3:$AR$3,0)) -> 11.526 | Y26: =INDEX(Segment!$A:$AR,MATCH(Annual!$A26,Segment!$A:$A,0),MATCH("1H"&RIGHT(Annual!Y$1,2),Segment!$A$3:$AR$3,0))+INDEX(Segment!$A:$AR,MATCH(Annual!$A26,Segment!$A:$A,0),MATCH("2H"&RIGHT(Annual!Y$1,2),Segment!$A$3:$AR$3,0)) -> 11.526 | Z26: =INDEX(Segment!$A:$AR,MATCH(Annual!$A26,Segment!$A:$A,0),MATCH("1H"&RIGHT(Annual!Z$1,2),Segment!$A$3:$AR$3,0))+INDEX(Segment!$A:$AR,MATCH(Annual!$A26,Segment!$A:$A,0),MATCH("2H"&RIGHT(Annual!Z$1,2),Segment!$A$3:$AR$3,0)) -> 11.526 | ... AB26: =INDEX(Segment!$A:$AR,MATCH(Annual!$A26,Segment!$A:$A,0),MATCH("1H"&RIGHT(Annual!AB$1,2),Segment!$A$3:$AR$3,0))+INDEX(Segment!$A:$AR,MATCH(Annual!$A26,Segment!$A:$A,0),MATCH("2H"&RIGHT(Annual!AB$1,2),Segment!$A$3:$AR$3,0)) -> 11.526 | AE26: 10.6 | AF26: =IF(ISBLANK(AE26),"",INDEX($A26:$AB26,1,MATCH(AE$3,$A$3:$AB$3,0))-AE26) -> #N/A | AG26: 10.6 | AH26: =IF(ISBLANK(AG26),"",INDEX($A26:$AB26,1,MATCH(AG$3,$A$3:$AB$3,0))-AG26) -> 0.926
A27: Rev-Total Revenue exc interest | B27: Total Revenue exc interest | C27: AUDm | D27: Preso | E27: 169.1 | F27: 180.6 | G27: 195.1 | H27: 218.7 | I27: 249 | J27: 273.3 | K27: 253.8 | L27: 285.6 | M27: 298.7 | N27: 311.8 | O27: 369 | P27: 437.2 | Q27: =Q10+Q26 -> 515.4 | R27: =R10+R26 -> 610.028 | S27: =S10+S26 -> 694.604 | T27: =T10+T26 -> 798.24446 | U27: =U10+U26 -> 936.79645 | V27: =V10+V26 -> 1111.9886 | W27: =W10+W26 -> 1323.4433 | X27: =X10+X26 -> 1581.7369 | ... AB27: =AB10+AB26 -> 3334.5533 | AE27: 605.01116 | AF27: =IF(ISBLANK(AE27),"",INDEX($A27:$AB27,1,MATCH(AE$3,$A$3:$AB$3,0))-AE27) -> #N/A | AG27: 702.21976 | AH27: =IF(ISBLANK(AG27),"",INDEX($A27:$AB27,1,MATCH(AG$3,$A$3:$AB$3,0))-AG27) -> -7.6157589
B28: Growth | C28: % YoY | F28: 0.068 | G28: 0.08 | H28: 0.121 | I28: 0.139 | J28: 0.097 | K28: -0.071 | L28: 0.126 | M28: 0.046 | N28: 0.044 | O28: 0.183 | P28: 0.185 | Q28: =Q27/P27-1 -> 0.17886551 | R28: =R27/Q27-1 -> 0.18360109 | S28: =S27/R27-1 -> 0.13864282 | T28: =T27/S27-1 -> 0.14920797 | U28: =U27/T27-1 -> 0.17357088 | V28: =V27/U27-1 -> 0.18701197 | W28: =W27/V27-1 -> 0.19015909 | X28: =X27/W27-1 -> 0.19516782 | ... AB28: =AB27/AA27-1 -> 0.21002184 | AE28: 0.1738672 | AF28: =IF(ISBLANK(AE28),"",INDEX($A28:$AB28,1,MATCH(AE$3,$A$3:$AB$3,0))-AE28) -> #N/A | AG28: 0.16067242 | AH28: =IF(ISBLANK(AG28),"",INDEX($A28:$AB28,1,MATCH(AG$3,$A$3:$AB$3,0))-AG28) -> -0.022029596
AF29: =IF(ISBLANK(AE29),"",INDEX($A29:$AB29,1,MATCH(AE$3,$A$3:$AB$3,0))-AE29) | AH29: =IF(ISBLANK(AG29),"",INDEX($A29:$AB29,1,MATCH(AG$3,$A$3:$AB$3,0))-AG29)
B30: Cost of Sales | AF30: =IF(ISBLANK(AE30),"",INDEX($A30:$AB30,1,MATCH(AE$3,$A$3:$AB$3,0))-AE30) | AH30: =IF(ISBLANK(AG30),"",INDEX($A30:$AB30,1,MATCH(AG$3,$A$3:$AB$3,0))-AG30)
A31: Costs-Variable costs | B31: Variable costs | C31: AUDm | D31: AR | K31: -24.5 | L31: -19.7 | M31: -19.1 | N31: -19.4 | O31: -20.7 | P31: -21 | Q31: -23.2 | R31: -23.03 | S31: =INDEX(Segment!$A:$AR,MATCH(Annual!$A31,Segment!$A:$A,0),MATCH("1H"&RIGHT(Annual!S$1,2),Segment!$A$3:$AR$3,0))+INDEX(Segment!$A:$AR,MATCH(Annual!$A31,Segment!$A:$A,0),MATCH("2H"&RIGHT(Annual!S$1,2),Segment!$A$3:$AR$3,0)) -> -26.237176 | T31: =INDEX(Segment!$A:$AR,MATCH(Annual!$A31,Segment!$A:$A,0),MATCH("1H"&RIGHT(Annual!T$1,2),Segment!$A$3:$AR$3,0))+INDEX(Segment!$A:$AR,MATCH(Annual!$A31,Segment!$A:$A,0),MATCH("2H"&RIGHT(Annual!T$1,2),Segment!$A$3:$AR$3,0)) -> -30.121113 | U31: =INDEX(Segment!$A:$AR,MATCH(Annual!$A31,Segment!$A:$A,0),MATCH("1H"&RIGHT(Annual!U$1,2),Segment!$A$3:$AR$3,0))+INDEX(Segment!$A:$AR,MATCH(Annual!$A31,Segment!$A:$A,0),MATCH("2H"&RIGHT(Annual!U$1,2),Segment!$A$3:$AR$3,0)) -> -35.296276 | V31: =INDEX(Segment!$A:$AR,MATCH(Annual!$A31,Segment!$A:$A,0),MATCH("1H"&RIGHT(Annual!V$1,2),Segment!$A$3:$AR$3,0))+INDEX(Segment!$A:$AR,MATCH(Annual!$A31,Segment!$A:$A,0),MATCH("2H"&RIGHT(Annual!V$1,2),Segment!$A$3:$AR$3,0)) -> -41.917711 | W31: =INDEX(Segment!$A:$AR,MATCH(Annual!$A31,Segment!$A:$A,0),MATCH("1H"&RIGHT(Annual!W$1,2),Segment!$A$3:$AR$3,0))+INDEX(Segment!$A:$AR,MATCH(Annual!$A31,Segment!$A:$A,0),MATCH("2H"&RIGHT(Annual!W$1,2),Segment!$A$3:$AR$3,0)) -> -49.890916 | X31: =INDEX(Segment!$A:$AR,MATCH(Annual!$A31,Segment!$A:$A,0),MATCH("1H"&RIGHT(Annual!X$1,2),Segment!$A$3:$AR$3,0))+INDEX(Segment!$A:$AR,MATCH(Annual!$A31,Segment!$A:$A,0),MATCH("2H"&RIGHT(Annual!X$1,2),Segment!$A$3:$AR$3,0)) -> -59.630427 | Y31: =INDEX(Segment!$A:$AR,MATCH(Annual!$A31,Segment!$A:$A,0),MATCH("1H"&RIGHT(Annual!Y$1,2),Segment!$A$3:$AR$3,0))+INDEX(Segment!$A:$AR,MATCH(Annual!$A31,Segment!$A:$A,0),MATCH("2H"&RIGHT(Annual!Y$1,2),Segment!$A$3:$AR$3,0)) -> -71.53278 | Z31: =INDEX(Segment!$A:$AR,MATCH(Annual!$A31,Segment!$A:$A,0),MATCH("1H"&RIGHT(Annual!Z$1,2),Segment!$A$3:$AR$3,0))+INDEX(Segment!$A:$AR,MATCH(Annual!$A31,Segment!$A:$A,0),MATCH("2H"&RIGHT(Annual!Z$1,2),Segment!$A$3:$AR$3,0)) -> -86.088034 | ... AB31: =INDEX(Segment!$A:$AR,MATCH(Annual!$A31,Segment!$A:$A,0),MATCH("1H"&RIGHT(Annual!AB$1,2),Segment!$A$3:$AR$3,0))+INDEX(Segment!$A:$AR,MATCH(Annual!$A31,Segment!$A:$A,0),MATCH("2H"&RIGHT(Annual!AB$1,2),Segment!$A$3:$AR$3,0)) -> -125.72947 | AE31: -27.106664 | AF31: =IF(ISBLANK(AE31),"",INDEX($A31:$AB31,1,MATCH(AE$3,$A$3:$AB$3,0))-AE31) -> #N/A | AG31: -31.461729 | AH31: =IF(ISBLANK(AG31),"",INDEX($A31:$AB31,1,MATCH(AG$3,$A$3:$AB$3,0))-AG31) -> 5.2245525
A32: Costs-Variable customer SaaS costs | B32: Variable customer SaaS costs | C32: AUDm | D32: AR | K32: -11.9 | L32: -17 | M32: -19.5 | N32: -21.9 | O32: -26.4 | P32: -34.9 | Q32: -38 | R32: -58.91 | S32: =INDEX(Segment!$A:$AR,MATCH(Annual!$A32,Segment!$A:$A,0),MATCH("1H"&RIGHT(Annual!S$1,2),Segment!$A$3:$AR$3,0))+INDEX(Segment!$A:$AR,MATCH(Annual!$A32,Segment!$A:$A,0),MATCH("2H"&RIGHT(Annual!S$1,2),Segment!$A$3:$AR$3,0)) -> -67.073374 | T32: =INDEX(Segment!$A:$AR,MATCH(Annual!$A32,Segment!$A:$A,0),MATCH("1H"&RIGHT(Annual!T$1,2),Segment!$A$3:$AR$3,0))+INDEX(Segment!$A:$AR,MATCH(Annual!$A32,Segment!$A:$A,0),MATCH("2H"&RIGHT(Annual!T$1,2),Segment!$A$3:$AR$3,0)) -> -77.090091 | U32: =INDEX(Segment!$A:$AR,MATCH(Annual!$A32,Segment!$A:$A,0),MATCH("1H"&RIGHT(Annual!U$1,2),Segment!$A$3:$AR$3,0))+INDEX(Segment!$A:$AR,MATCH(Annual!$A32,Segment!$A:$A,0),MATCH("2H"&RIGHT(Annual!U$1,2),Segment!$A$3:$AR$3,0)) -> -90.485856 | V32: =INDEX(Segment!$A:$AR,MATCH(Annual!$A32,Segment!$A:$A,0),MATCH("1H"&RIGHT(Annual!V$1,2),Segment!$A$3:$AR$3,0))+INDEX(Segment!$A:$AR,MATCH(Annual!$A32,Segment!$A:$A,0),MATCH("2H"&RIGHT(Annual!V$1,2),Segment!$A$3:$AR$3,0)) -> -107.40189 | W32: =INDEX(Segment!$A:$AR,MATCH(Annual!$A32,Segment!$A:$A,0),MATCH("1H"&RIGHT(Annual!W$1,2),Segment!$A$3:$AR$3,0))+INDEX(Segment!$A:$AR,MATCH(Annual!$A32,Segment!$A:$A,0),MATCH("2H"&RIGHT(Annual!W$1,2),Segment!$A$3:$AR$3,0)) -> -127.82472 | X32: =INDEX(Segment!$A:$AR,MATCH(Annual!$A32,Segment!$A:$A,0),MATCH("1H"&RIGHT(Annual!X$1,2),Segment!$A$3:$AR$3,0))+INDEX(Segment!$A:$AR,MATCH(Annual!$A32,Segment!$A:$A,0),MATCH("2H"&RIGHT(Annual!X$1,2),Segment!$A$3:$AR$3,0)) -> -152.7713 | Y32: =INDEX(Segment!$A:$AR,MATCH(Annual!$A32,Segment!$A:$A,0),MATCH("1H"&RIGHT(Annual!Y$1,2),Segment!$A$3:$AR$3,0))+INDEX(Segment!$A:$AR,MATCH(Annual!$A32,Segment!$A:$A,0),MATCH("2H"&RIGHT(Annual!Y$1,2),Segment!$A$3:$AR$3,0)) -> -183.25691 | Z32: =INDEX(Segment!$A:$AR,MATCH(Annual!$A32,Segment!$A:$A,0),MATCH("1H"&RIGHT(Annual!Z$1,2),Segment!$A$3:$AR$3,0))+INDEX(Segment!$A:$AR,MATCH(Annual!$A32,Segment!$A:$A,0),MATCH("2H"&RIGHT(Annual!Z$1,2),Segment!$A$3:$AR$3,0)) -> -220.53621 | ... AB32: =INDEX(Segment!$A:$AR,MATCH(Annual!$A32,Segment!$A:$A,0),MATCH("1H"&RIGHT(Annual!AB$1,2),Segment!$A$3:$AR$3,0))+INDEX(Segment!$A:$AR,MATCH(Annual!$A32,Segment!$A:$A,0),MATCH("2H"&RIGHT(Annual!AB$1,2),Segment!$A$3:$AR$3,0)) -> -322.06079 | AE32: -45.346885 | AF32: =IF(ISBLANK(AE32),"",INDEX($A32:$AB32,1,MATCH(AE$3,$A$3:$AB$3,0))-AE32) -> #N/A | AG32: -52.624196 | AH32: =IF(ISBLANK(AG32),"",INDEX($A32:$AB32,1,MATCH(AG$3,$A$3:$AB$3,0))-AG32) -> -14.449177
A33: Costs-Other | B33: Other | C33: AUDm | S33: =INDEX(Segment!$A:$AR,MATCH(Annual!$A33,Segment!$A:$A,0),MATCH("1H"&RIGHT(Annual!S$1,2),Segment!$A$3:$AR$3,0))+INDEX(Segment!$A:$AR,MATCH(Annual!$A33,Segment!$A:$A,0),MATCH("2H"&RIGHT(Annual!S$1,2),Segment!$A$3:$AR$3,0)) -> 0 | T33: =INDEX(Segment!$A:$AR,MATCH(Annual!$A33,Segment!$A:$A,0),MATCH("1H"&RIGHT(Annual!T$1,2),Segment!$A$3:$AR$3,0))+INDEX(Segment!$A:$AR,MATCH(Annual!$A33,Segment!$A:$A,0),MATCH("2H"&RIGHT(Annual!T$1,2),Segment!$A$3:$AR$3,0)) -> 0 | U33: =INDEX(Segment!$A:$AR,MATCH(Annual!$A33,Segment!$A:$A,0),MATCH("1H"&RIGHT(Annual!U$1,2),Segment!$A$3:$AR$3,0))+INDEX(Segment!$A:$AR,MATCH(Annual!$A33,Segment!$A:$A,0),MATCH("2H"&RIGHT(Annual!U$1,2),Segment!$A$3:$AR$3,0)) -> 0 | V33: =INDEX(Segment!$A:$AR,MATCH(Annual!$A33,Segment!$A:$A,0),MATCH("1H"&RIGHT(Annual!V$1,2),Segment!$A$3:$AR$3,0))+INDEX(Segment!$A:$AR,MATCH(Annual!$A33,Segment!$A:$A,0),MATCH("2H"&RIGHT(Annual!V$1,2),Segment!$A$3:$AR$3,0)) -> 0 | W33: =INDEX(Segment!$A:$AR,MATCH(Annual!$A33,Segment!$A:$A,0),MATCH("1H"&RIGHT(Annual!W$1,2),Segment!$A$3:$AR$3,0))+INDEX(Segment!$A:$AR,MATCH(Annual!$A33,Segment!$A:$A,0),MATCH("2H"&RIGHT(Annual!W$1,2),Segment!$A$3:$AR$3,0)) -> 0 | X33: =INDEX(Segment!$A:$AR,MATCH(Annual!$A33,Segment!$A:$A,0),MATCH("1H"&RIGHT(Annual!X$1,2),Segment!$A$3:$AR$3,0))+INDEX(Segment!$A:$AR,MATCH(Annual!$A33,Segment!$A:$A,0),MATCH("2H"&RIGHT(Annual!X$1,2),Segment!$A$3:$AR$3,0)) -> 0 | Y33: =INDEX(Segment!$A:$AR,MATCH(Annual!$A33,Segment!$A:$A,0),MATCH("1H"&RIGHT(Annual!Y$1,2),Segment!$A$3:$AR$3,0))+INDEX(Segment!$A:$AR,MATCH(Annual!$A33,Segment!$A:$A,0),MATCH("2H"&RIGHT(Annual!Y$1,2),Segment!$A$3:$AR$3,0)) -> 0 | Z33: =INDEX(Segment!$A:$AR,MATCH(Annual!$A33,Segment!$A:$A,0),MATCH("1H"&RIGHT(Annual!Z$1,2),Segment!$A$3:$AR$3,0))+INDEX(Segment!$A:$AR,MATCH(Annual!$A33,Segment!$A:$A,0),MATCH("2H"&RIGHT(Annual!Z$1,2),Segment!$A$3:$AR$3,0)) -> 0 | ... AB33: =INDEX(Segment!$A:$AR,MATCH(Annual!$A33,Segment!$A:$A,0),MATCH("1H"&RIGHT(Annual!AB$1,2),Segment!$A$3:$AR$3,0))+INDEX(Segment!$A:$AR,MATCH(Annual!$A33,Segment!$A:$A,0),MATCH("2H"&RIGHT(Annual!AB$1,2),Segment!$A$3:$AR$3,0)) -> 0 | AE33: 0 | AF33: =IF(ISBLANK(AE33),"",INDEX($A33:$AB33,1,MATCH(AE$3,$A$3:$AB$3,0))-AE33) -> #N/A | AG33: 0 | AH33: =IF(ISBLANK(AG33),"",INDEX($A33:$AB33,1,MATCH(AG$3,$A$3:$AB$3,0))-AG33) -> 0
B34: Cost of Sales | C34: AUDm | K34: -36.4 | L34: -36.7 | M34: -38.6 | N34: -41.4 | O34: -47.1 | P34: -55.9 | Q34: =SUM(Q31:Q33) -> -61.2 | R34: =SUM(R31:R33) -> -81.94 | S34: =SUM(S31:S33) -> -93.31055 | T34: =SUM(T31:T33) -> -107.2112 | U34: =SUM(U31:U33) -> -125.78213 | V34: =SUM(V31:V33) -> -149.3196 | W34: =SUM(W31:W33) -> -177.71563 | X34: =SUM(X31:X33) -> -212.40173 | ... AB34: =SUM(AB31:AB33) -> -447.79025 | AE34: -72.453549 | AF34: =IF(ISBLANK(AE34),"",INDEX($A34:$AB34,1,MATCH(AE$3,$A$3:$AB$3,0))-AE34) -> #N/A | AG34: -84.085925 | AH34: =IF(ISBLANK(AG34),"",INDEX($A34:$AB34,1,MATCH(AG$3,$A$3:$AB$3,0))-AG34) -> -9.2246249
AF35: =IF(ISBLANK(AE35),"",INDEX($A35:$AB35,1,MATCH(AE$3,$A$3:$AB$3,0))-AE35) | AH35: =IF(ISBLANK(AG35),"",INDEX($A35:$AB35,1,MATCH(AG$3,$A$3:$AB$3,0))-AG35)
A36: GP-Gross Profit | B36: Gross Profit | C36: AUDm | D36: Preso | K36: 217.4 | L36: 249 | M36: 260.1 | N36: 270.4 | O36: 321.9 | P36: 381.3 | Q36: =Q27+Q34 -> 454.2 | R36: =R27+R34 -> 528.088 | S36: =INDEX(Segment!$A:$AR,MATCH(Annual!$A36,Segment!$A:$A,0),MATCH("1H"&RIGHT(Annual!S$1,2),Segment!$A$3:$AR$3,0))+INDEX(Segment!$A:$AR,MATCH(Annual!$A36,Segment!$A:$A,0),MATCH("2H"&RIGHT(Annual!S$1,2),Segment!$A$3:$AR$3,0)) -> 601.29345 | T36: =INDEX(Segment!$A:$AR,MATCH(Annual!$A36,Segment!$A:$A,0),MATCH("1H"&RIGHT(Annual!T$1,2),Segment!$A$3:$AR$3,0))+INDEX(Segment!$A:$AR,MATCH(Annual!$A36,Segment!$A:$A,0),MATCH("2H"&RIGHT(Annual!T$1,2),Segment!$A$3:$AR$3,0)) -> 691.03325 | U36: =INDEX(Segment!$A:$AR,MATCH(Annual!$A36,Segment!$A:$A,0),MATCH("1H"&RIGHT(Annual!U$1,2),Segment!$A$3:$AR$3,0))+INDEX(Segment!$A:$AR,MATCH(Annual!$A36,Segment!$A:$A,0),MATCH("2H"&RIGHT(Annual!U$1,2),Segment!$A$3:$AR$3,0)) -> 811.01432 | V36: =INDEX(Segment!$A:$AR,MATCH(Annual!$A36,Segment!$A:$A,0),MATCH("1H"&RIGHT(Annual!V$1,2),Segment!$A$3:$AR$3,0))+INDEX(Segment!$A:$AR,MATCH(Annual!$A36,Segment!$A:$A,0),MATCH("2H"&RIGHT(Annual!V$1,2),Segment!$A$3:$AR$3,0)) -> 962.66899 | W36: =INDEX(Segment!$A:$AR,MATCH(Annual!$A36,Segment!$A:$A,0),MATCH("1H"&RIGHT(Annual!W$1,2),Segment!$A$3:$AR$3,0))+INDEX(Segment!$A:$AR,MATCH(Annual!$A36,Segment!$A:$A,0),MATCH("2H"&RIGHT(Annual!W$1,2),Segment!$A$3:$AR$3,0)) -> 1145.7277 | X36: =INDEX(Segment!$A:$AR,MATCH(Annual!$A36,Segment!$A:$A,0),MATCH("1H"&RIGHT(Annual!X$1,2),Segment!$A$3:$AR$3,0))+INDEX(Segment!$A:$AR,MATCH(Annual!$A36,Segment!$A:$A,0),MATCH("2H"&RIGHT(Annual!X$1,2),Segment!$A$3:$AR$3,0)) -> 1369.3352 | Y36: =INDEX(Segment!$A:$AR,MATCH(Annual!$A36,Segment!$A:$A,0),MATCH("1H"&RIGHT(Annual!Y$1,2),Segment!$A$3:$AR$3,0))+INDEX(Segment!$A:$AR,MATCH(Annual!$A36,Segment!$A:$A,0),MATCH("2H"&RIGHT(Annual!Y$1,2),Segment!$A$3:$AR$3,0)) -> 1642.592 | Z36: =INDEX(Segment!$A:$AR,MATCH(Annual!$A36,Segment!$A:$A,0),MATCH("1H"&RIGHT(Annual!Z$1,2),Segment!$A$3:$AR$3,0))+INDEX(Segment!$A:$AR,MATCH(Annual!$A36,Segment!$A:$A,0),MATCH("2H"&RIGHT(Annual!Z$1,2),Segment!$A$3:$AR$3,0)) -> 1976.7446 | ... AB36: =INDEX(Segment!$A:$AR,MATCH(Annual!$A36,Segment!$A:$A,0),MATCH("1H"&RIGHT(Annual!AB$1,2),Segment!$A$3:$AR$3,0))+INDEX(Segment!$A:$AR,MATCH(Annual!$A36,Segment!$A:$A,0),MATCH("2H"&RIGHT(Annual!AB$1,2),Segment!$A$3:$AR$3,0)) -> 2886.763 | AE36: 532.55761 | AF36: =IF(ISBLANK(AE36),"",INDEX($A36:$AB36,1,MATCH(AE$3,$A$3:$AB$3,0))-AE36) -> #N/A | AG36: 618.13384 | AH36: =IF(ISBLANK(AG36),"",INDEX($A36:$AB36,1,MATCH(AG$3,$A$3:$AB$3,0))-AG36) -> -16.840384
B37: Gross profit margin | C37: % | D37: #VALUE! | K37: 0.857 | L37: 0.872 | M37: 0.871 | N37: 0.867 | O37: 0.872 | P37: 0.872 | Q37: =Q36/Q$27 -> 0.88125728 | R37: =R36/R$27 -> 0.8656783 | S37: =S36/S27 -> 0.86566367 | T37: =T36/T27 -> 0.86569126 | U37: =U36/U27 -> 0.86573163 | V37: =V36/V27 -> 0.8657184 | W37: =W36/W27 -> 0.86571723 | X37: =X36/X27 -> 0.86571615 | Y37: =Y36/Y27 -> 0.86571511 | Z37: =Z36/Z27 -> 0.8657141 | ... AB37: =AB36/AB27 -> 0.86571207 | AE37: 0.88024428 | AF37: =IF(ISBLANK(AE37),"",INDEX($A37:$AB37,1,MATCH(AE$3,$A$3:$AB$3,0))-AE37) -> #N/A | AG37: 0.88025697 | AH37: =IF(ISBLANK(AG37),"",INDEX($A37:$AB37,1,MATCH(AG$3,$A$3:$AB$3,0))-AG37) -> -0.014593292
AF38: =IF(ISBLANK(AE38),"",INDEX($A38:$AB38,1,MATCH(AE$3,$A$3:$AB$3,0))-AE38) | AH38: =IF(ISBLANK(AG38),"",INDEX($A38:$AB38,1,MATCH(AG$3,$A$3:$AB$3,0))-AG38)
A39: Opex-Operating costs | B39: Operating costs | C39: AUDm | D39: Preso | K39: -133.7 | L39: -139.1 | M39: -126.8 | N39: -110.3 | O39: -127.9 | P39: -148.6 | Q39: =Q50-Q36-Q46 -> -180.1 | R39: =R50-R36-R46 -> -203.088 | S39: =INDEX(Segment!$A:$AR,MATCH(Annual!$A39,Segment!$A:$A,0),MATCH("1H"&RIGHT(Annual!S$1,2),Segment!$A$3:$AR$3,0))+INDEX(Segment!$A:$AR,MATCH(Annual!$A39,Segment!$A:$A,0),MATCH("2H"&RIGHT(Annual!S$1,2),Segment!$A$3:$AR$3,0)) -> -224.32787 | T39: =INDEX(Segment!$A:$AR,MATCH(Annual!$A39,Segment!$A:$A,0),MATCH("1H"&RIGHT(Annual!T$1,2),Segment!$A$3:$AR$3,0))+INDEX(Segment!$A:$AR,MATCH(Annual!$A39,Segment!$A:$A,0),MATCH("2H"&RIGHT(Annual!T$1,2),Segment!$A$3:$AR$3,0)) -> -249.75358 | U39: =INDEX(Segment!$A:$AR,MATCH(Annual!$A39,Segment!$A:$A,0),MATCH("1H"&RIGHT(Annual!U$1,2),Segment!$A$3:$AR$3,0))+INDEX(Segment!$A:$AR,MATCH(Annual!$A39,Segment!$A:$A,0),MATCH("2H"&RIGHT(Annual!U$1,2),Segment!$A$3:$AR$3,0)) -> -283.62681 | V39: =INDEX(Segment!$A:$AR,MATCH(Annual!$A39,Segment!$A:$A,0),MATCH("1H"&RIGHT(Annual!V$1,2),Segment!$A$3:$AR$3,0))+INDEX(Segment!$A:$AR,MATCH(Annual!$A39,Segment!$A:$A,0),MATCH("2H"&RIGHT(Annual!V$1,2),Segment!$A$3:$AR$3,0)) -> -331.15077 | W39: =INDEX(Segment!$A:$AR,MATCH(Annual!$A39,Segment!$A:$A,0),MATCH("1H"&RIGHT(Annual!W$1,2),Segment!$A$3:$AR$3,0))+INDEX(Segment!$A:$AR,MATCH(Annual!$A39,Segment!$A:$A,0),MATCH("2H"&RIGHT(Annual!W$1,2),Segment!$A$3:$AR$3,0)) -> -387.50935 | X39: =INDEX(Segment!$A:$AR,MATCH(Annual!$A39,Segment!$A:$A,0),MATCH("1H"&RIGHT(Annual!X$1,2),Segment!$A$3:$AR$3,0))+INDEX(Segment!$A:$AR,MATCH(Annual!$A39,Segment!$A:$A,0),MATCH("2H"&RIGHT(Annual!X$1,2),Segment!$A$3:$AR$3,0)) -> -455.23496 | Y39: =INDEX(Segment!$A:$AR,MATCH(Annual!$A39,Segment!$A:$A,0),MATCH("1H"&RIGHT(Annual!Y$1,2),Segment!$A$3:$AR$3,0))+INDEX(Segment!$A:$AR,MATCH(Annual!$A39,Segment!$A:$A,0),MATCH("2H"&RIGHT(Annual!Y$1,2),Segment!$A$3:$AR$3,0)) -> -536.59849 | Z39: =INDEX(Segment!$A:$AR,MATCH(Annual!$A39,Segment!$A:$A,0),MATCH("1H"&RIGHT(Annual!Z$1,2),Segment!$A$3:$AR$3,0))+INDEX(Segment!$A:$AR,MATCH(Annual!$A39,Segment!$A:$A,0),MATCH("2H"&RIGHT(Annual!Z$1,2),Segment!$A$3:$AR$3,0)) -> -634.34931 | ... AB39: =INDEX(Segment!$A:$AR,MATCH(Annual!$A39,Segment!$A:$A,0),MATCH("1H"&RIGHT(Annual!AB$1,2),Segment!$A$3:$AR$3,0))+INDEX(Segment!$A:$AR,MATCH(Annual!$A39,Segment!$A:$A,0),MATCH("2H"&RIGHT(Annual!AB$1,2),Segment!$A$3:$AR$3,0)) -> -893.0558 | AE39: -210.27387 | AF39: =IF(ISBLANK(AE39),"",INDEX($A39:$AB39,1,MATCH(AE$3,$A$3:$AB$3,0))-AE39) -> #N/A | AG39: -237.03649 | AH39: =IF(ISBLANK(AG39),"",INDEX($A39:$AB39,1,MATCH(AG$3,$A$3:$AB$3,0))-AG39) -> 12.708618
B40: % of sales | K40: -0.527 | L40: -0.487 | M40: -0.425 | N40: -0.354 | O40: -0.347 | P40: -0.34 | Q40: =Q39/Q$27 -> -0.34943733 | R40: =R39/R$27 -> -0.33291587 | S40: =S39/S$27 -> -0.32295793 | T40: =T39/T$27 -> -0.31287857 | U40: =U39/U$27 -> -0.30276247 | V40: =V39/V$27 -> -0.29780051 | W40: =W39/W$27 -> -0.29280388 | X40: =X39/X$27 -> -0.28780701 | ... AB40: =AB39/AB$27 -> -0.26781872 | AE40: -0.3475537 | AF40: =IF(ISBLANK(AE40),"",INDEX($A40:$AB40,1,MATCH(AE$3,$A$3:$AB$3,0))-AE40) -> #N/A | AG40: -0.33755314 | AH40: =IF(ISBLANK(AG40),"",INDEX($A40:$AB40,1,MATCH(AG$3,$A$3:$AB$3,0))-AG40) -> 0.014595215
...

Sheet Segment
B1: Segments | C1: 2019 | D1: 2016 | E1: 2016 | F1: 2017 | G1: 2017 | H1: 2018 | I1: 2018 | J1: 2019 | K1: 2019 | L1: 2020 | M1: 2020 | N1: 2021 | O1: 2021 | P1: 2022 | Q1: 2022 | R1: 2023 | S1: 2023 | T1: 2024 | U1: 2024 | V1: 2025 | W1: =U1+1 -> 2025 | X1: 2026 | Y1: 2026 | Z1: 2027 | AA1: 2027 | AB1: 2028 | AC1: 2028 | AD1: 2029 | AE1: 2029 | AF1: 2030 | AG1: 2030 | AH1: 2031 | AI1: 2031 | AJ1: 2032 | AK1: 2032 | AL1: 2033 | AM1: 2033 | AN1: 2034 | AO1: 2034 | AP1: 2035 | AQ1: 2035 | AS1: Earnings changes=> | AT1: 2025 | AU1: 2024 | AV1: 2025 | AW1: 2024
D2: Actual ----------> | X2: Forecast -----> | AT2: Forecast -----> | AU2: Forecast -----> | AW2: Forecast -----> | AY2: Seasonality- 5yr averages
C3: Units | D3: 1H16 | E3: 2H16 | F3: 1H17 | G3: 2H17 | H3: 1H18 | I3: 2H18 | J3: 1H19 | K3: 2H19 | L3: 1H20 | M3: 2H20 | N3: 1H21 | O3: 2H21 | P3: 1H22 | Q3: 2H22 | R3: 1H23 | S3: 2H23 | T3: 1H24 | U3: 2H24 | V3: 1H25 | W3: ="2H"&RIGHT(W1,2) -> 2H25 | X3: 1H26 | Y3: 2H26 | Z3: 1H27 | AA3: 2H27 | AB3: 1H28 | AC3: 2H28 | AD3: 1H29 | AE3: 2H29 | AF3: 1H30 | AG3: 2H30 | AH3: 1H31 | AI3: 2H31 | AJ3: 1H32 | AK3: 2H32 | AL3: 1H33 | AM3: 2H33 | AN3: 1H34 | AO3: 2H34 | AP3: 1H35 | AQ3: 2H35 | AT3: 1H25 | AU3: FY24E | AV3: 2H25 | AW3: FY24E | AY3: 1H | AZ3: 2H
B4: P &L
B6: Revenue | BA6: #REF!
A7: Rev-SaaS fees | B7: SaaS fees | C7: AUDm | D7: AR | J7: 37.6 | K7: 43.9 | L7: 51.1 | M7: 55.1 | N7: 68.8 | O7: 82.2 | P7: 96.2 | Q7: 120.6 | R7: 145 | S7: 171.2 | T7: 193.9 | U7: =INDEX(Annual!$A:$AC,MATCH(Segment!$A7,Annual!$A:$A,0),MATCH(Segment!U$1,Annual!$A$1:$AC$1,0))-T7 -> 213.5 | V7: 239 | W7: =INDEX(Annual!$A:$AC,MATCH(Segment!$A7,Annual!$A:$A,0),MATCH(Segment!W$1,Annual!$A$1:$AC$1,0))-V7 -> 260.725 | X7: =V7*(1+W88) -> 281.90004 | Y7: =W7*(1+X88) -> 305.77926 | Z7: =X7*(1+Y88) -> 331.42832 | AA7: =Y7*(1+Z88) -> 364.24082 | AB7: =Z7*(1+AA88) -> 395.67694 | AC7: =AA7*(1+AB88) -> 442.67611 | AD7: =AB7*(1+AC88) -> 481.68012 | AE7: =AC7*(1+AD88) -> 535.79039 | ... AQ7: =AO7*(1+AP88) -> 1714.1896 | AT7: 237.5 | AU7: 1.5 | AV7: 251.5 | AW7: 6.1
A8: Rev-Annual licence fees | B8: Annual licence fees | C8: AUDm | D8: AR | J8: 50.8 | K8: 47.9 | L8: 50.5 | M8: 50.6 | N8: 41.4 | O8: 36.6 | P8: 39.1 | Q8: 30.1 | R8: 21.3 | S8: 15.7 | T8: 10.4 | U8: =INDEX(Annual!$A:$AC,MATCH(Segment!$A8,Annual!$A:$A,0),MATCH(Segment!U$1,Annual!$A$1:$AC$1,0))-T8 -> 7.4 | V8: 4.1 | W8: =INDEX(Annual!$A:$AC,MATCH(Segment!$A8,Annual!$A:$A,0),MATCH(Segment!W$1,Annual!$A$1:$AC$1,0))-V8 -> 3.111 | X8: =V8 -> 4.1 | Y8: =W8 -> 3.111 | Z8: =X8 -> 4.1 | AA8: =Y8 -> 3.111 | AB8: =Z8 -> 4.1 | AC8: =AA8 -> 3.111 | AD8: =AB8 -> 4.1 | AE8: =AC8 -> 3.111 | ... AQ8: =AO8 -> 3.111 | AT8: 7.4 | AU8: -3.3 | AV8: 7.4 | AW8: -3.3
A9: Rev-Consulting services | B9: Consulting services | C9: AUDm | D9: AR | J9: 29.2 | K9: 32.4 | L9: 30.2 | M9: 32.3 | N9: 30.4 | O9: 34.2 | P9: 34.1 | Q9: 38.5 | R9: 33.7 | S9: 39.4 | T9: 36.3 | U9: =INDEX(Annual!$A:$AC,MATCH(Segment!$A9,Annual!$A:$A,0),MATCH(Segment!U$1,Annual!$A$1:$AC$1,0))-T9 -> 44.2 | V9: 42.6 | W9: =INDEX(Annual!$A:$AC,MATCH(Segment!$A9,Annual!$A:$A,0),MATCH(Segment!W$1,Annual!$A$1:$AC$1,0))-V9 -> 48.966 | X9: =V9*0.95 -> 40.47 | Y9: =W9*0.95 -> 46.5177 | Z9: =X9*0.95 -> 38.4465 | AA9: =Y9*0.95 -> 44.191815 | AB9: =Z9*0.95 -> 36.524175 | AC9: =AA9*0.95 -> 41.982224 | AD9: =AB9*0.95 -> 34.697966 | AE9: =AC9*0.95 -> 39.883113 | ... AQ9: =AO9*0.95 -> 29.317753 | AT9: 31.9 | AU9: 10.7 | AV9: 39 | AW9: 7.5
A10: Rev-Legacy licence services (initial fees) | B10: Legacy licence services (initial fees) | C10: AUDm | D10: AR | J10: 11 | K10: 32.2 | L10: 6.2 | M10: 22.3 | N10: 3.8 | O10: 14 | P10: 2.5 | Q10: 7.1 | R10: 1 | S10: 2 | T10: 0.3 | U10: =INDEX(Annual!$A:$AC,MATCH(Segment!$A10,Annual!$A:$A,0),MATCH(Segment!U$1,Annual!$A$1:$AC$1,0))-T10 -> 0.5 | V10: 0 | W10: =INDEX(Annual!$A:$AC,MATCH(Segment!$A10,Annual!$A:$A,0),MATCH(Segment!W$1,Annual!$A$1:$AC$1,0))-V10 -> 0 | X10: 0.6 | Y10: 0.6 | Z10: 0.6 | AA10: 0.6 | AB10: 0.6 | AC10: 0.6 | AD10: 0.6 | AE10: 0.6 | AF10: 0.6 | AG10: 0.6 | AH10: 0.6 | AI10: 0.6 | AJ10: 0.6 | AK10: 0.6 | AL10: 0.6 | AM10: 0.6 | AN10: 0.6 | AO10: 0.6 | AP10: 0.6 | AQ10: 0.6 | AT10: 0.3 | AU10: -0.3 | AV10: 0.6 | AW10: 0
A11: Rev-Revenue from contracts with customers | B11: Revenue from contracts with customers | C11: AUDm | J11: 128.5 | K11: 156.5 | L11: 138 | M11: 160.3 | N11: 144.3 | O11: 167 | P11: 172 | Q11: 196.2 | R11: 201 | S11: 228.4 | T11: 240.8 | U11: =INDEX(Annual!$A:$AC,MATCH(Segment!$A11,Annual!$A:$A,0),MATCH(Segment!U$1,Annual!$A$1:$AC$1,0))-T11 -> 265.7 | V11: =SUM(V7:V10) -> 285.7 | W11: =INDEX(Annual!$A:$AC,MATCH(Segment!$A11,Annual!$A:$A,0),MATCH(Segment!W$1,Annual!$A$1:$AC$1,0))-V11 -> 312.802 | X11: =SUM(X7:X10) -> 327.07004 | Y11: =SUM(Y7:Y10) -> 356.00796 | Z11: =SUM(Z7:Z10) -> 374.57482 | AA11: =SUM(AA7:AA10) -> 412.14364 | AB11: =SUM(AB7:AB10) -> 436.90111 | AC11: =SUM(AC7:AC10) -> 488.36934 | AD11: =SUM(AD7:AD10) -> 521.07809 | AE11: =SUM(AE7:AE10) -> 579.38451 | ... AQ11: =SUM(AQ7:AQ10) -> 1747.2184 | AT11: 277.1 | AU11: 8.6 | AV11: 298.4 | AW11: 10.3
B12: Growth | C12: % YoY | J12: #DIV/0! | K12: #DIV/0! | L12: 0.074 | M12: 0.024 | N12: 0.046 | O12: 0.042 | P12: 0.192 | Q12: 0.175 | R12: 0.169 | S12: 0.164 | T12: 0.198 | U12: =U11/S11-1 -> 0.16330998 | V12: =V11/T11-1 -> 0.18646179 | W12: =W11/U11-1 -> 0.17727512 | X12: =X11/V11-1 -> 0.14480239 | Y12: =Y11/W11-1 -> 0.13812559 | Z12: =Z11/X11-1 -> 0.14524344 | AA12: =AA11/Y11-1 -> 0.15768096 | AB12: =AB11/Z11-1 -> 0.1663921 | ... AQ12: =AQ11/AO11-1 -> 0.21065643 | AT12: 0.151 | AU12: 0.036 | AV12: 0.123 | AW12: 0.039
A14: Rev-Other income exc interest | B14: Other income exc interest | C14: AUDm | J14: 0.3 | K14: 0.3 | L14: 0.2 | M14: 0.2 | N14: 0.2 | O14: 0.3 | P14: 0.4 | Q14: 0.4 | R14: 7.7 | S14: 0.1 | T14: 3.9 | U14: =INDEX(Annual!$A:$AC,MATCH(Segment!$A14,Annual!$A:$A,0),MATCH(Segment!U$1,Annual!$A$1:$AC$1,0))-T14 -> 5 | V14: 5.6 | W14: =INDEX(Annual!$A:$AC,MATCH(Segment!$A14,Annual!$A:$A,0),MATCH(Segment!W$1,Annual!$A$1:$AC$1,0))-V14 -> 5.926 | X14: =V14 -> 5.6 | Y14: =W14 -> 5.926 | Z14: =X14 -> 5.6 | AA14: =Y14 -> 5.926 | AB14: =Z14 -> 5.6 | AC14: =AA14 -> 5.926 | AD14: =AB14 -> 5.6 | AE14: =AC14 -> 5.926 | ... AQ14: =AO14 -> 5.926 | AT14: 3.9 | AU14: 1.7 | AV14: 4.9 | AW14: 0
B15: Total Revenue exc interest | C15: AUDm | D15: Preso | J15: 128.8 | K15: 156.8 | L15: 138.2 | M15: 160.5 | N15: 144.5 | O15: 167.3 | P15: 172.4 | Q15: 196.6 | R15: 208.7 | S15: 228.5 | T15: 244.7 | U15: =U11+U14 -> 270.7 | V15: =V11+V14 -> 291.3 | W15: =W11+W14 -> 318.728 | X15: =X11+X14 -> 332.67004 | Y15: =Y11+Y14 -> 361.93396 | Z15: =Z11+Z14 -> 380.17482 | AA15: =AA11+AA14 -> 418.06964 | AB15: =AB11+AB14 -> 442.50111 | ... AQ15: =AQ11+AQ14 -> 1753.1444 | AT15: 281 | AU15: 10.2 | AV15: 303.4 | AW15: 10.3
B16: Growth | C16: % YoY | J16: #DIV/0! | K16: #DIV/0! | L16: 0.072 | M16: 0.024 | N16: 0.046 | O16: 0.042 | P16: 0.193 | Q16: 0.176 | R16: 0.211 | S16: 0.162 | T16: 0.173 | U16: =U15/S15-1 -> 0.18468271 | V16: =V15/T15-1 -> 0.19043727 | W16: =W15/U15-1 -> 0.1774215 | X16: =X15/V15-1 -> 0.14201868 | Y16: =Y15/W15-1 -> 0.13555746 | Z16: =Z15/X15-1 -> 0.14279848 | AA16: =AA15/Y15-1 -> 0.15509923 | AB16: =AB15/Z15-1 -> 0.16394114 | ... AQ16: =AQ15/AO15-1 -> 0.20979498 | AT16: 0.148 | AU16: 0.042 | AV16: 0.121 | AW16: 0.038
B18: Cost of Sales
A19: Costs-Variable costs | B19: Variable costs | C19: AUDm | D19: AR | J19: -9.8 | K19: -9.9 | L19: -7.1 | M19: -12 | N19: -8.7 | O19: -10.7 | P19: -10.3 | Q19: -10.4 | R19: -11.5 | S19: -9.5 | T19: -11.2 | U19: =INDEX(Annual!$A:$AC,MATCH(Segment!$A19,Annual!$A:$A,0),MATCH(Segment!U$1,Annual!$A$1:$AC$1,0))-T19 -> -12 | V19: -13.2 | W19: =INDEX(Annual!$A:$AC,MATCH(Segment!$A19,Annual!$A:$A,0),MATCH(Segment!W$1,Annual!$A$1:$AC$1,0))-V19 -> -9.83 | X19: =X$22/V$22*V19 -> -15.074647 | Y19: =Y$22/W$22*W19 -> -11.16253 | Z19: =Z$22/X$22*X19 -> -17.227283 | AA19: =AA$22/Y$22*Y19 -> -12.89383 | AB19: =AB$22/Z$22*Z19 -> -20.051544 | AC19: =AC$22/AA$22*AA19 -> -15.244733 | AD19: =AD$22/AB$22*AB19 -> -23.865948 | AE19: =AE$22/AC$22*AC19 -> -18.051763 | ... AQ19: =AQ$22/AO$22*AO19 -> -54.069329 | AT19: -12.9 | AU19: -0.3 | AV19: -13.4 | AW19: -0.5
A20: Costs-Variable customer SaaS costs | B20: Variable customer SaaS costs | C20: AUDm | D20: AR | J20: -7.9 | K20: -9.1 | L20: -10.3 | M20: -9.2 | N20: -13.1 | O20: -8.8 | P20: -12.3 | Q20: -14.1 | R20: -17.4 | S20: -17.5 | T20: -22.6 | U20: =INDEX(Annual!$A:$AC,MATCH(Segment!$A20,Annual!$A:$A,0),MATCH(Segment!U$1,Annual!$A$1:$AC$1,0))-T20 -> -15.4 | V20: -27.5 | W20: =INDEX(Annual!$A:$AC,MATCH(Segment!$A20,Annual!$A:$A,0),MATCH(Segment!W$1,Annual!$A$1:$AC$1,0))-V20 -> -31.41 | X20: =X$22/V$22*V20 -> -31.405514 | Y20: =Y$22/W$22*W20 -> -35.66786 | Z20: =Z$22/X$22*X20 -> -35.890173 | AA20: =AA$22/Y$22*Y20 -> -41.199917 | AB20: =AB$22/Z$22*Z20 -> -41.774049 | AC20: =AC$22/AA$22*AA20 -> -48.711806 | AD20: =AD$22/AB$22*AB20 -> -49.720726 | AE20: =AE$22/AC$22*AC20 -> -57.681167 | ... AQ20: =AQ$22/AO$22*AO20 -> -172.76883 | AT20: -25.9 | AU20: -1.6 | AV20: -17.3 | AW20: -0.6
A21: Costs-Other | B21: Other | C21: AUDm | J21: 0 | K21: 0 | L21: 0 | M21: 0 | N21: 0 | O21: 0 | P21: 0 | Q21: 0 | R21: 0 | S21: 0 | T21: 0 | U21: =INDEX(Annual!$A:$AC,MATCH(Segment!$A21,Annual!$A:$A,0),MATCH(Segment!U$1,Annual!$A$1:$AC$1,0))-T21 -> 0 | V21: 0 | W21: =INDEX(Annual!$A:$AC,MATCH(Segment!$A21,Annual!$A:$A,0),MATCH(Segment!W$1,Annual!$A$1:$AC$1,0))-V21 -> 0 | X21: =X$22/V$22*V21 -> 0 | Y21: =Y$22/W$22*W21 -> 0 | Z21: =Z$22/X$22*X21 -> 0 | AA21: =AA$22/Y$22*Y21 -> 0 | AB21: =AB$22/Z$22*Z21 -> 0 | AC21: =AC$22/AA$22*AA21 -> 0 | AD21: =AD$22/AB$22*AB21 -> 0 | AE21: =AE$22/AC$22*AC21 -> 0 | ... AQ21: =AQ$22/AO$22*AO21 -> 0 | AT21: 0 | AU21: 0 | AV21: 0 | AW21: 0
B22: Cost of Sales | C22: AUDm | J22: -17.6 | K22: -19 | L22: -17.5 | M22: -21.2 | N22: -21.8 | O22: -19.5 | P22: -22.6 | Q22: -24.4 | R22: -29 | S22: -26.9 | T22: -33.8 | U22: =SUM(U19:U21) -> -27.4 | V22: =SUM(V19:V21) -> -40.7 | W22: =SUM(W19:W21) -> -41.24 | X22: =X24-X15 -> -46.48016 | Y22: =Y24-Y15 -> -46.83039 | Z22: =Z24-Z15 -> -53.117457 | AA22: =AA24-AA15 -> -54.093747 | AB22: =AB24-AB15 -> -61.825593 | AC22: =AC24-AC15 -> -63.956539 | AD22: =AD24-AD15 -> -73.586674 | AE22: =AE24-AE15 -> -75.73293 | ... AQ22: =AQ24-AQ15 -> -226.83816 | AT22: -38.8 | AU22: -1.9 | AV22: -30.7 | AW22: -1
A24: GP-Gross Profit | B24: Gross Profit | C24: AUDm | D24: Preso | J24: 111.2 | K24: 137.8 | L24: 120.7 | M24: 139.4 | N24: 122.7 | O24: 147.7 | P24: 149.7 | Q24: 172.2 | R24: 179.8 | S24: 201.6 | T24: 210.9 | U24: =INDEX(Annual!$A:$AC,MATCH(Segment!$A24,Annual!$A:$A,0),MATCH(Segment!U$1,Annual!$A$1:$AC$1,0))-T24 -> 243.3 | V24: =V15+V22 -> 250.6 | W24: =INDEX(Annual!$A:$AC,MATCH(Segment!$A24,Annual!$A:$A,0),MATCH(Segment!W$1,Annual!$A$1:$AC$1,0))-V24 -> 277.488 | X24: =X15*X25 -> 286.18988 | Y24: =Y15*Y25 -> 315.10357 | Z24: =Z15*Z25 -> 327.05736 | AA24: =AA15*AA25 -> 363.97589 | AB24: =AB15*AB25 -> 380.67552 | AC24: =AC15*AC25 -> 430.3388 | AD24: =AD15*AD25 -> 453.09142 | AE24: =AE15*AE25 -> 509.57758 | ... AQ24: =AQ15*AQ25 -> 1526.3062 | AT24: 242.2 | AU24: 8.4 | AV24: 272.7 | AW24: 9.2
B25: Gross profit margin | C25: % | D25: #VALUE! | J25: 0.863 | K25: 0.879 | L25: 0.874 | M25: 0.868 | N25: 0.849 | O25: 0.883 | P25: 0.869 | Q25: 0.876 | R25: 0.861 | S25: 0.882 | T25: 0.862 | U25: =U24/U15 -> 0.89878094 | V25: =V24/V15 -> 0.8602815 | W25: =W24/W15 -> 0.87061068 | X25: =V25 -> 0.8602815 | Y25: =W25 -> 0.87061068 | Z25: =X25 -> 0.8602815 | AA25: =Y25 -> 0.87061068 | AB25: =Z25 -> 0.8602815 | AC25: =AA25 -> 0.87061068 | AD25: =AB25 -> 0.8602815 | AE25: =AC25 -> 0.87061068 | ... AQ25: =AO25 -> 0.87061068 | AT25: 0.862 | AU25: -0.002 | AV25: 0.899 | AW25: 0
A27: Opex-Operating costs | B27: Operating costs | C27: AUDm | D27: Preso | J27: -70.6 | K27: -68.4 | L27: -71.4 | M27: -55.4 | N27: -56 | O27: -54.3 | P27: -69.2 | Q27: -58.8 | R27: -78.4 | S27: -70.2 | T27: -90.3 | U27: =INDEX(Annual!$A:$AC,MATCH(Segment!$A27,Annual!$A:$A,0),MATCH(Segment!U$1,Annual!$A$1:$AC$1,0))-T27 -> -89.8 | V27: =V30-V24 -> -101.5 | W27: =INDEX(Annual!$A:$AC,MATCH(Segment!$A27,Annual!$A:$A,0),MATCH(Segment!W$1,Annual!$A$1:$AC$1,0))-V27 -> -101.588 | X27: =X28*X15 -> -112.5882 | Y27: =Y28*Y15 -> -111.73967 | Z27: =Z28*Z15 -> -124.86387 | AA27: =AA28*AA15 -> -124.88971 | AB27: =AB28*AB15 -> -140.90919 | AC27: =AC28*AC15 -> -142.71762 | AD27: =AD28*AD15 -> -165.08095 | AE27: =AE28*AE15 -> -166.06983 | ... AQ27: =AQ28*AQ15 -> -444.82435 | AT27: -100.9 | AU27: -0.6 | AV27: -97.7 | AW27: -11.1
B28: % of sales | J28: -0.548 | K28: -0.436 | L28: -0.517 | M28: -0.345 | N28: -0.388 | O28: -0.325 | P28: -0.401 | Q28: -0.299 | R28: -0.376 | S28: -0.307 | T28: -0.369 | U28: =U27/U15 -> -0.33173255 | V28: =V27/V15 -> -0.34843804 | W28: =W27/W15 -> -0.31872945 | X28: =V28+1% -> -0.33843804 | Y28: =W28+1% -> -0.30872945 | Z28: =X28+1% -> -0.32843804 | AA28: =Y28+1% -> -0.29872945 | AB28: =Z28+1% -> -0.31843804 | AC28: =AA28+1% -> -0.28872945 | AD28: =AB28+0.5% -> -0.31343804 | AE28: =AC28+0.5% -> -0.28372945 | AF28: =AD28+0.5% -> -0.30843804 | AG28: =AE28+0.5% -> -0.27872945 | AH28: =AF28+0.5% -> -0.30343804 | AI28: =AG28+0.5% -> -0.27372945 | AJ28: =AH28+0.5% -> -0.29843804 | AK28: =AI28+0.5% -> -0.26872945 | ... AQ28: =AO28+0.5% -> -0.25372945 | AT28: -0.359 | AU28: 0.01 | AV28: -0.322 | AW28: -0.025
