Workbook

Sheet Model
B2: Item | C2: Source/notes | D2: Units | E2: FY-5 | F2: FY-4 | G2: FY-3 | H2: FY-2 | I2: FY-1 | J2: FY0 | K2: FY1 | L2: FY2 | M2: FY3 | N2: FY4 | O2: FY5 | P2: FY6 | Q2: FY7 | R2: FY8 | S2: FY9 | T2: FY10 | V2: Guidance | Y2: FY-2 | Z2: FY-2 | AA2: FY-1 | AB2: FY-1 | AC2: FY0 | AD2: FY0 | AE2: ="FY"&RIGHT(AC2,1)+1 -> FY1 | AF2: ="FY"&RIGHT(AD2,1)+1 -> FY1 | AG2: ="FY"&RIGHT(AE2,1)+1 -> FY2 | AH2: ="FY"&RIGHT(AF2,1)+1 -> FY2 | AI2: ="FY"&RIGHT(AG2,1)+1 -> FY3 | AJ2: ="FY"&RIGHT(AH2,1)+1 -> FY3 | AK2: ="FY"&RIGHT(AI2,1)+1 -> FY4 | AL2: ="FY"&RIGHT(AJ2,1)+1 -> FY4 | ... AX2: ="FY"&RIGHT(AV2,1)+1 -> FY10
B3: FY end | D3: June | E3: 2019 | F3: =E3+1 -> 2020 | G3: =F3+1 -> 2021 | H3: =G3+1 -> 2022 | I3: =H3+1 -> 2023 | J3: =I3+1 -> 2024 | K3: =J3+1 -> 2025 | L3: =K3+1 -> 2026 | M3: =L3+1 -> 2027 | ... T3: =S3+1 -> 2034 | V3: 2025 | W3: LT taget | Y3: ="1H"&RIGHT(INDEX($B$3:$T$3,1,MATCH(Y$2,$B$2:$T$2,0)),2) -> 1H22 | Z3: ="2H"&RIGHT(INDEX($B$3:$T$3,1,MATCH(Z$2,$B$2:$T$2,0)),2) -> 2H22 | AA3: ="1H"&RIGHT(INDEX($B$3:$T$3,1,MATCH(AA$2,$B$2:$T$2,0)),2) -> 1H23 | AB3: ="2H"&RIGHT(INDEX($B$3:$T$3,1,MATCH(AB$2,$B$2:$T$2,0)),2) -> 2H23 | AC3: ="1H"&RIGHT(INDEX($B$3:$T$3,1,MATCH(AC$2,$B$2:$T$2,0)),2) -> 1H24 | AD3: ="2H"&RIGHT(INDEX($B$3:$T$3,1,MATCH(AD$2,$B$2:$T$2,0)),2) -> 2H24 | AE3: ="1H"&RIGHT(INDEX($B$3:$T$3,1,MATCH(AE$2,$B$2:$T$2,0)),2) -> 1H25 | AF3: ="2H"&RIGHT(INDEX($B$3:$T$3,1,MATCH(AF$2,$B$2:$T$2,0)),2) -> 2H25 | AG3: ="1H"&RIGHT(INDEX($B$3:$T$3,1,MATCH(AG$2,$B$2:$T$2,0)),2) -> 1H26 | AH3: ="2H"&RIGHT(INDEX($B$3:$T$3,1,MATCH(AH$2,$B$2:$T$2,0)),2) -> 2H26 | AI3: ="1H"&RIGHT(INDEX($B$3:$T$3,1,MATCH(AI$2,$B$2:$T$2,0)),2) -> 1H27 | AJ3: ="2H"&RIGHT(INDEX($B$3:$T$3,1,MATCH(AJ$2,$B$2:$T$2,0)),2) -> 2H27 | AK3: ="1H"&RIGHT(INDEX($B$3:$T$3,1,MATCH(AK$2,$B$2:$T$2,0)),2) -> 1H28 | AL3: ="2H"&RIGHT(INDEX($B$3:$T$3,1,MATCH(AL$2,$B$2:$T$2,0)),2) -> 2H28 | AM3: ="1H"&RIGHT(INDEX($B$3:$T$3,1,MATCH(AM$2,$B$2:$T$2,0)),2) -> 1H29 | AN3: ="2H"&RIGHT(INDEX($B$3:$T$3,1,MATCH(AN$2,$B$2:$T$2,0)),2) -> 2H29 | AO3: ="1H"&RIGHT(INDEX($B$3:$T$3,1,MATCH(AO$2,$B$2:$T$2,0)),2) -> 1H30 | AP3: ="2H"&RIGHT(INDEX($B$3:$T$3,1,MATCH(AP$2,$B$2:$T$2,0)),2) -> 2H30 | AQ3: ="1H"&RIGHT(INDEX($B$3:$T$3,1,MATCH(AQ$2,$B$2:$T$2,0)),2) -> 1H31 | AR3: ="2H"&RIGHT(INDEX($B$3:$T$3,1,MATCH(AR$2,$B$2:$T$2,0)),2) -> 2H31 | AS3: ="1H"&RIGHT(INDEX($B$3:$T$3,1,MATCH(AS$2,$B$2:$T$2,0)),2) -> 1H32 | AT3: ="2H"&RIGHT(INDEX($B$3:$T$3,1,MATCH(AT$2,$B$2:$T$2,0)),2) -> 2H32 | AU3: ="1H"&RIGHT(INDEX($B$3:$T$3,1,MATCH(AU$2,$B$2:$T$2,0)),2) -> 1H33 | AV3: ="2H"&RIGHT(INDEX($B$3:$T$3,1,MATCH(AV$2,$B$2:$T$2,0)),2) -> 2H33 | AW3: ="1H"&RIGHT(INDEX($B$3:$T$3,1,MATCH(AW$2,$B$2:$T$2,0)),2) -> 1H34 | AX3: ="2H"&RIGHT(INDEX($B$3:$T$3,1,MATCH(AX$2,$B$2:$T$2,0)),2) -> 2H34
B4: Default units | D4: USDm
B5: Power equipment | E5: 6791.514 | F5: 8729.841 | G5: 11960.891 | H5: 12329.071 | I5: 12794.548 | J5: 13722.888 | K5: =SUMIF($Y$2:$AX$2,K$2,$Y5:$AX5) -> 14834.058 | L5: =SUMIF($Y$2:$AX$2,L$2,$Y5:$AX5) -> 16725.1 | M5: =SUMIF($Y$2:$AX$2,M$2,$Y5:$AX5) -> 18391.925 | N5: =SUMIF($Y$2:$AX$2,N$2,$Y5:$AX5) -> 20317.049 | O5: =SUMIF($Y$2:$AX$2,O$2,$Y5:$AX5) -> 22513.408 | P5: =SUMIF($Y$2:$AX$2,P$2,$Y5:$AX5) -> 24999.973 | Q5: =SUMIF($Y$2:$AX$2,Q$2,$Y5:$AX5) -> 27801.278 | R5: =SUMIF($Y$2:$AX$2,R$2,$Y5:$AX5) -> 30947.203 | ... T5: =SUMIF($Y$2:$AX$2,T$2,$Y5:$AX5) -> 38419.231 | Y5: 6561.632 | Z5: 5767.439 | AA5: 6450.231 | AB5: 6344.317 | AC5: 6884.453 | AD5: 6838.435 | AE5: 7425.059 | AF5: =AF30 -> 7408.9987 | AG5: =AG30 -> 8354.5477 | AH5: =AH30 -> 8370.5522 | AI5: =AI30 -> 9174.3134 | AJ5: =AJ30 -> 9217.6114 | AK5: =AK30 -> 10122.992 | AL5: =AL30 -> 10194.057 | AM5: =AM30 -> 11206.482 | ... AX5: =AX30 -> 19362.633
B6: Floor care | E6: 875.207 | F6: 1082.1 | G6: 1242.27 | H6: 924.846 | I6: 936.863 | J6: 898.728 | K6: =SUMIF($Y$2:$AX$2,K$2,$Y6:$AX6) -> 832.0977 | L6: =SUMIF($Y$2:$AX$2,L$2,$Y6:$AX6) -> 790.49281 | M6: =SUMIF($Y$2:$AX$2,M$2,$Y6:$AX6) -> 750.96817 | N6: =SUMIF($Y$2:$AX$2,N$2,$Y6:$AX6) -> 713.41977 | O6: =SUMIF($Y$2:$AX$2,O$2,$Y6:$AX6) -> 677.74878 | P6: =SUMIF($Y$2:$AX$2,P$2,$Y6:$AX6) -> 643.86134 | Q6: =SUMIF($Y$2:$AX$2,Q$2,$Y6:$AX6) -> 611.66827 | R6: =SUMIF($Y$2:$AX$2,R$2,$Y6:$AX6) -> 581.08486 | ... T6: =SUMIF($Y$2:$AX$2,T$2,$Y6:$AX6) -> 524.42908 | Y6: 471.974 | Z6: 452.872 | AA6: 429.233 | AB6: 507.63 | AC6: 427.535 | AD6: 471.193 | AE6: 408.024 | AF6: =AF33 -> 424.0737 | AG6: =AG33 -> 387.6228 | AH6: =AH33 -> 402.87002 | AI6: =AI33 -> 368.24166 | AJ6: =AJ33 -> 382.72651 | AK6: =AK33 -> 349.82958 | AL6: =AL33 -> 363.59019 | AM6: =AM33 -> 332.3381 | ... AX6: =AX33 -> 267.2722
K7: =SUMIF($Y$2:$AX$2,K$2,$Y7:$AX7) -> 0 | L7: =SUMIF($Y$2:$AX$2,L$2,$Y7:$AX7) -> 0 | M7: =SUMIF($Y$2:$AX$2,M$2,$Y7:$AX7) -> 0 | N7: =SUMIF($Y$2:$AX$2,N$2,$Y7:$AX7) -> 0 | O7: =SUMIF($Y$2:$AX$2,O$2,$Y7:$AX7) -> 0 | P7: =SUMIF($Y$2:$AX$2,P$2,$Y7:$AX7) -> 0 | Q7: =SUMIF($Y$2:$AX$2,Q$2,$Y7:$AX7) -> 0 | R7: =SUMIF($Y$2:$AX$2,R$2,$Y7:$AX7) -> 0 | ... T7: =SUMIF($Y$2:$AX$2,T$2,$Y7:$AX7) -> 0
K8: =SUMIF($Y$2:$AX$2,K$2,$Y8:$AX8) -> 0 | L8: =SUMIF($Y$2:$AX$2,L$2,$Y8:$AX8) -> 0 | M8: =SUMIF($Y$2:$AX$2,M$2,$Y8:$AX8) -> 0 | N8: =SUMIF($Y$2:$AX$2,N$2,$Y8:$AX8) -> 0 | O8: =SUMIF($Y$2:$AX$2,O$2,$Y8:$AX8) -> 0 | P8: =SUMIF($Y$2:$AX$2,P$2,$Y8:$AX8) -> 0 | Q8: =SUMIF($Y$2:$AX$2,Q$2,$Y8:$AX8) -> 0 | R8: =SUMIF($Y$2:$AX$2,R$2,$Y8:$AX8) -> 0 | ... T8: =SUMIF($Y$2:$AX$2,T$2,$Y8:$AX8) -> 0
B11: Other | E11: =E12-SUM(E5:E10) -> 0 | F11: =F12-SUM(F5:F10) -> 0 | G11: =G12-SUM(G5:G10) -> 0 | H11: =H12-SUM(H5:H10) -> 0 | I11: =I12-SUM(I5:I10) -> 0 | J11: =J12-SUM(J5:J10) -> 0 | K11: =SUMIF($Y$2:$AX$2,K$2,$Y11:$AX11) -> 0 | L11: =SUMIF($Y$2:$AX$2,L$2,$Y11:$AX11) -> 0 | M11: =SUMIF($Y$2:$AX$2,M$2,$Y11:$AX11) -> 0 | N11: =SUMIF($Y$2:$AX$2,N$2,$Y11:$AX11) -> 0 | O11: =SUMIF($Y$2:$AX$2,O$2,$Y11:$AX11) -> 0 | P11: =SUMIF($Y$2:$AX$2,P$2,$Y11:$AX11) -> 0 | Q11: =SUMIF($Y$2:$AX$2,Q$2,$Y11:$AX11) -> 0 | R11: =SUMIF($Y$2:$AX$2,R$2,$Y11:$AX11) -> 0 | ... T11: =SUMIF($Y$2:$AX$2,T$2,$Y11:$AX11) -> 0 | Y11: =Y12-SUM(Y5:Y10) -> 0 | Z11: =Z12-SUM(Z5:Z10) -> 0 | AA11: =AA12-SUM(AA5:AA10) -> 0 | AB11: =AB12-SUM(AB5:AB10) -> 0 | AC11: =AC12-SUM(AC5:AC10) -> 0 | AD11: =AD12-SUM(AD5:AD10) -> 0 | AE11: =AE12-SUM(AE5:AE10) -> 0
B12: Revenue | E12: 7666.721 | F12: 9811.941 | G12: 13203.161 | H12: 13253.917 | I12: 13731.411 | J12: 14621.616 | K12: =SUMIF($Y$2:$AX$2,K$2,$Y12:$AX12) -> 15666.155 | L12: =SUMIF($Y$2:$AX$2,L$2,$Y12:$AX12) -> 17515.593 | M12: =SUMIF($Y$2:$AX$2,M$2,$Y12:$AX12) -> 19142.893 | N12: =SUMIF($Y$2:$AX$2,N$2,$Y12:$AX12) -> 21030.469 | O12: =SUMIF($Y$2:$AX$2,O$2,$Y12:$AX12) -> 23191.157 | P12: =SUMIF($Y$2:$AX$2,P$2,$Y12:$AX12) -> 25643.835 | Q12: =SUMIF($Y$2:$AX$2,Q$2,$Y12:$AX12) -> 28412.947 | R12: =SUMIF($Y$2:$AX$2,R$2,$Y12:$AX12) -> 31528.288 | ... T12: =SUMIF($Y$2:$AX$2,T$2,$Y12:$AX12) -> 38943.66 | Y12: 7033.606 | Z12: 6220.311 | AA12: 6879.464 | AB12: 6851.947 | AC12: 7311.988 | AD12: 7309.628 | AE12: 7833.083 | AF12: =SUM(AF5:AF11) -> 7833.0724 | AG12: =SUM(AG5:AG11) -> 8742.1705 | AH12: =SUM(AH5:AH11) -> 8773.4222 | AI12: =SUM(AI5:AI11) -> 9542.5551 | AJ12: =SUM(AJ5:AJ11) -> 9600.3379 | AK12: =SUM(AK5:AK11) -> 10472.822 | AL12: =SUM(AL5:AL11) -> 10557.648 | AM12: =SUM(AM5:AM11) -> 11538.82 | ... AX12: =SUM(AX5:AX11) -> 19629.905
B13: Growth | F13: =F12/E12-1 -> 0.27980932 | G13: =G12/F12-1 -> 0.34562173 | H13: =H12/G12-1 -> 0.0038442309 | I13: =I12/H12-1 -> 0.036026633 | J13: =J12/I12-1 -> 0.064829827 | K13: =K12/J12-1 -> 0.071438024 | L13: =L12/K12-1 -> 0.11805305 | M13: =M12/L12-1 -> 0.092905803 | ... T13: =T12/S12-1 -> 0.11188219 | AA13: =AA12/Y12-1 -> -0.021915075 | AB13: =AB12/Z12-1 -> 0.10154412 | AC13: =AC12/AA12-1 -> 0.062871759 | AD13: =AD12/AB12-1 -> 0.066795759 | AE13: =AE12/AC12-1 -> 0.071265845 | AF13: =AF12/AD12-1 -> 0.071610259 | AG13: =AG12/AE12-1 -> 0.11605743 | AH13: =AH12/AF12-1 -> 0.12004867 | ... AX13: =AX12/AV12-1 -> 0.11250684
B14: =B5 -> Power equipment | F14: =F5/E5-1 -> 0.28540426 | G14: =G5/F5-1 -> 0.37011556 | H14: =H5/G5-1 -> 0.030781988 | I14: =I5/H5-1 -> 0.037754426 | J14: =J5/I5-1 -> 0.072557467 | K14: =K5/J5-1 -> 0.080971998 | L14: =L5/K5-1 -> 0.12747977 | M14: =M5/L5-1 -> 0.099660083 | ... T14: =T5/S5-1 -> 0.11447448 | AA14: =AA5/Y5-1 -> -0.016977636 | AB14: =AB5/Z5-1 -> 0.10002325 | AC14: =AC5/AA5-1 -> 0.067318829 | AD14: =AD5/AB5-1 -> 0.077883561 | AE14: =AE5/AC5-1 -> 0.078525629 | AF14: =AF5/AD5-1 -> 0.083434829 | AG14: =AG5/AE5-1 -> 0.12518267 | AH14: =AH5/AF5-1 -> 0.12978185 | ... AX14: =AX5/AV5-1 -> 0.11513994
B15: =B6 -> Floor care | F15: =F6/E6-1 -> 0.23639322 | G15: =G6/F6-1 -> 0.14801774 | H15: =H6/G6-1 -> -0.25551933 | I15: =I6/H6-1 -> 0.012993515 | J15: =J6/I6-1 -> -0.040704991 | K15: =K6/J6-1 -> -0.074138449 | L15: =L6/K6-1 -> -0.05 | M15: =M6/L6-1 -> -0.05 | ... T15: =T6/S6-1 -> -0.05 | AA15: =AA6/Y6-1 -> -0.090557954 | AB15: =AB6/Z6-1 -> 0.12091275 | AC15: =AC6/AA6-1 -> -0.0039558934 | AD15: =AD6/AB6-1 -> -0.071778658 | AE15: =AE6/AC6-1 -> -0.04563603 | AF15: =AF6/AD6-1 -> -0.1 | AG15: =AG6/AE6-1 -> -0.05 | AH15: =AH6/AF6-1 -> -0.05 | ... AX15: =AX6/AV6-1 -> -0.05
B16: =B7 -> 0 | F16: =F7/E7-1 -> #DIV/0! | G16: =G7/F7-1 -> #DIV/0! | H16: =H7/G7-1 -> #DIV/0! | I16: =I7/H7-1 -> #DIV/0! | J16: =J7/I7-1 -> #DIV/0! | K16: =K7/J7-1 -> #DIV/0! | L16: =L7/K7-1 -> #DIV/0! | M16: =M7/L7-1 -> #DIV/0! | ... T16: =T7/S7-1 -> #DIV/0! | AA16: =AA7/Y7-1 -> #DIV/0! | AB16: =AB7/Z7-1 -> #DIV/0! | AC16: =AC7/AA7-1 -> #DIV/0! | AD16: =AD7/AB7-1 -> #DIV/0! | AE16: =AE7/AC7-1 -> #DIV/0! | AF16: =AF7/AD7-1 -> #DIV/0! | AG16: =AG7/AE7-1 -> #DIV/0! | AH16: =AH7/AF7-1 -> #DIV/0! | ... AX16: =AX7/AV7-1 -> #DIV/0!
B17: =B8 -> 0 | F17: =F8/E8-1 -> #DIV/0! | G17: =G8/F8-1 -> #DIV/0! | H17: =H8/G8-1 -> #DIV/0! | I17: =I8/H8-1 -> #DIV/0! | J17: =J8/I8-1 -> #DIV/0! | K17: =K8/J8-1 -> #DIV/0! | L17: =L8/K8-1 -> #DIV/0! | M17: =M8/L8-1 -> #DIV/0! | ... T17: =T8/S8-1 -> #DIV/0! | AA17: =AA8/Y8-1 -> #DIV/0! | AB17: =AB8/Z8-1 -> #DIV/0! | AC17: =AC8/AA8-1 -> #DIV/0! | AD17: =AD8/AB8-1 -> #DIV/0! | AE17: =AE8/AC8-1 -> #DIV/0! | AF17: =AF8/AD8-1 -> #DIV/0! | AG17: =AG8/AE8-1 -> #DIV/0! | AH17: =AH8/AF8-1 -> #DIV/0! | ... AX17: =AX8/AV8-1 -> #DIV/0!
B18: =B9 -> 0 | F18: =F9/E9-1 -> #DIV/0! | G18: =G9/F9-1 -> #DIV/0! | H18: =H9/G9-1 -> #DIV/0! | I18: =I9/H9-1 -> #DIV/0! | J18: =J9/I9-1 -> #DIV/0! | K18: =K9/J9-1 -> #DIV/0! | L18: =L9/K9-1 -> #DIV/0! | M18: =M9/L9-1 -> #DIV/0! | ... T18: =T9/S9-1 -> #DIV/0! | AA18: =AA9/Y9-1 -> #DIV/0! | AB18: =AB9/Z9-1 -> #DIV/0! | AC18: =AC9/AA9-1 -> #DIV/0! | AD18: =AD9/AB9-1 -> #DIV/0! | AE18: =AE9/AC9-1 -> #DIV/0! | AF18: =AF9/AD9-1 -> #DIV/0! | AG18: =AG9/AE9-1 -> #DIV/0! | AH18: =AH9/AF9-1 -> #DIV/0! | ... AX18: =AX9/AV9-1 -> #DIV/0!
E19: =E6/E12 -> 0.11415663 | F19: =F6/F12 -> 0.11028399 | G19: =G6/G12 -> 0.094088832 | H19: =H6/H12 -> 0.06977907 | I19: =I6/I12 -> 0.06822773 | J19: =J6/J12 -> 0.061465709
B20: Workings- Revenue
B21: Share of Total revenue
B22: Milwaukee Tools | J22: =1-J24-J23 -> 0.69166667 | AD22: =$J22 -> 0.69166667 | AE22: =1-AE24-AE23 -> 0.7
B23: Ryobi | J23: =111/360-J24 -> 0.16388889 | AD23: =$J23 -> 0.16388889 | AE23: =108/360-AE24 -> 0.1875
B24: Other | J24: =52/360 -> 0.14444444 | AD24: =$J24 -> 0.14444444 | AE24: =40.5/360 -> 0.1125
B26: Revenue
B27: Milwaukee Tools | E27: =F27/(1+F37) -> 3871.4476 | F27: =G27/(1+G37) -> 4870.2811 | G27: =H27/(1+H37) -> 6720.9879 | H27: =I27/(1+I37) -> 8186.1633 | I27: =J27/(1+J37) -> 9062.0828 | J27: =J22*J$12 -> 10113.284 | AA27: =AC27/(1+AC37) -> 4410.5197 | AC27: =AE27/(1+AE37) -> 4895.6769 | AD27: =INDEX($B27:$T27,MATCH(AD$2,$B$2:$T$2,0))-AC27 -> 5217.6075 | AE27: =AE22*AE$12 -> 5483.1581 | AF27: =AD27*(1+AF37) -> 5843.7204 | AG27: =AE27*(1+AG37) -> 6360.4634 | AH27: =AF27*(1+AH37) -> 6778.7157 | AI27: =AG27*(1+AI37) -> 7123.719 | AJ27: =AH27*(1+AJ37) -> 7592.1616 | AK27: =AI27*(1+AK37) -> 7978.5653 | AL27: =AJ27*(1+AL37) -> 8503.221 | AM27: =AK27*(1+AM37) -> 8935.9931 | ... AX27: =AV27*(1+AX37) -> 16783.85
B28: Ryobi | I28: =J28/(1+J38) -> 2252.1808 | J28: =J23*J$12 -> 2396.3204 | AC28: =AE28/(1+AE38) -> 1347.434 | AD28: =INDEX($B28:$T28,MATCH(AD$2,$B$2:$T$2,0))-AC28 -> 1048.8864 | AE28: =AE23*AE$12 -> 1468.7031 | AF28: =AD28*(1+AF38) -> 1143.2862 | AG28: =AE28*(1+AG38) -> 1644.9474 | AH28: =AF28*(1+AH38) -> 1280.4805 | AI28: =AG28*(1+AI38) -> 1792.9927 | AJ28: =AH28*(1+AJ38) -> 1395.7238 | AK28: =AI28*(1+AK38) -> 1954.362 | AL28: =AJ28*(1+AL38) -> 1521.3389 | AM28: =AK28*(1+AM38) -> 2130.2546 | ... AX28: =AV28*(1+AX38) -> 2551.4376
B29: Other Power tools | I29: =I30-I28-I27 -> 1480.2844 | J29: =J30-J28-J27 -> 1213.2832 | AC29: =AC30-AC28-AC27 -> 641.34212 | AD29: =AD30-AD28-AD27 -> 571.94108 | AE29: =AE30-AE28-AE27 -> 473.19784 | AF29: =AD29*(1+AF39) -> 421.99206 | AG29: =AE29*(1+AG39) -> 349.13689 | AH29: =AF29*(1+AH39) -> 311.35602 | AI29: =AG29*(1+AI39) -> 257.6017 | AJ29: =AH29*(1+AJ39) -> 229.72605 | AK29: =AI29*(1+AK39) -> 190.06481 | AL29: =AJ29*(1+AL39) -> 169.49748 | AM29: =AK29*(1+AM39) -> 140.23444 | ... AX29: =AV29*(1+AX39) -> 27.345203
B30: Total Power Tools | I30: =I5 -> 12794.548 | J30: =J5 -> 13722.888 | Y30: =Y5 -> 6561.632 | Z30: =Z5 -> 5767.439 | AA30: =AA5 -> 6450.231 | AB30: =AB5 -> 6344.317 | AC30: =AC5 -> 6884.453 | AD30: =AD5 -> 6838.435 | AE30: =AE5 -> 7425.059 | AF30: =SUM(AF27:AF29) -> 7408.9987 | AG30: =SUM(AG27:AG29) -> 8354.5477 | AH30: =SUM(AH27:AH29) -> 8370.5522 | AI30: =SUM(AI27:AI29) -> 9174.3134 | AJ30: =SUM(AJ27:AJ29) -> 9217.6114 | AK30: =SUM(AK27:AK29) -> 10122.992 | AL30: =SUM(AL27:AL29) -> 10194.057 | AM30: =SUM(AM27:AM29) -> 11206.482 | ... AX30: =SUM(AX27:AX29) -> 19362.633
B31: Growth | AA31: =AA30/Y30-1 -> -0.016977636 | AB31: =AB30/Z30-1 -> 0.10002325 | AC31: =AC30/AA30-1 -> 0.067318829 | AD31: =AD30/AB30-1 -> 0.077883561 | AE31: =AE30/AC30-1 -> 0.078525629 | AF31: =AF30/AD30-1 -> 0.083434829 | AG31: =AG30/AE30-1 -> 0.12518267 | AH31: =AH30/AF30-1 -> 0.12978185 | ... AX31: =AX30/AV30-1 -> 0.11513994
B33: Floor care | Y33: =Y6 -> 471.974 | Z33: =Z6 -> 452.872 | AA33: =AA6 -> 429.233 | AB33: =AB6 -> 507.63 | AC33: =AC6 -> 427.535 | AD33: =AD6 -> 471.193 | AE33: =AE6 -> 408.024 | AF33: =AD33*(1+AF34) -> 424.0737 | AG33: =AE33*(1+AG34) -> 387.6228 | AH33: =AF33*(1+AH34) -> 402.87002 | AI33: =AG33*(1+AI34) -> 368.24166 | AJ33: =AH33*(1+AJ34) -> 382.72651 | AK33: =AI33*(1+AK34) -> 349.82958 | AL33: =AJ33*(1+AL34) -> 363.59019 | AM33: =AK33*(1+AM34) -> 332.3381 | ... AX33: =AV33*(1+AX34) -> 267.2722
B34: Growth | Z34: =Z33/X33-1 -> #DIV/0! | AA34: =AA33/Y33-1 -> -0.090557954 | AB34: =AB33/Z33-1 -> 0.12091275 | AC34: =AC33/AA33-1 -> -0.0039558934 | AD34: =AD33/AB33-1 -> -0.071778658 | AE34: =AE33/AC33-1 -> -0.04563603 | AF34: -0.1 | AG34: -0.05 | AH34: =AG34 -> -0.05 | AI34: =AH34 -> -0.05 | AJ34: =AI34 -> -0.05 | AK34: =AJ34 -> -0.05 | AL34: =AK34 -> -0.05 | AM34: =AL34 -> -0.05 | AN34: =AM34 -> -0.05 | AO34: =AN34 -> -0.05 | ... AX34: =AW34 -> -0.05
B36: Growth rates | AG36: Strong US 2026
B37: Milwaukee Tools | E37: 0.217 | F37: 0.258 | G37: 0.38 | H37: 0.218 | I37: 0.107 | J37: 0.116 | AC37: 0.11 | AE37: 0.12 | AF37: =AE37 -> 0.12 | AG37: 0.16 | AH37: 0.16 | AI37: 0.12 | AJ37: 0.12 | AK37: =AJ37 -> 0.12 | AL37: =AK37 -> 0.12 | AM37: =AL37 -> 0.12 | AN37: =AM37 -> 0.12 | AO37: =AN37 -> 0.12 | AP37: =AO37 -> 0.12 | AQ37: =AP37 -> 0.12 | AR37: =AQ37 -> 0.12 | ... AX37: =AW37 -> 0.12
B38: Ryobi | J38: 0.064 | AE38: 0.09 | AF38: =AE38 -> 0.09 | AG38: 0.12 | AH38: 0.12 | AI38: 0.09 | AJ38: 0.09 | AK38: =AJ38 -> 0.09 | AL38: =AK38 -> 0.09 | AM38: =AL38 -> 0.09 | AN38: =AM38 -> 0.09 | AO38: =AN38 -> 0.09 | AP38: =AO38 -> 0.09 | AQ38: =AP38 -> 0.09 | AR38: =AQ38 -> 0.09 | ... AX38: =AW38 -> 0.09
B39: Other Power tools | J39: =J29/I29-1 -> -0.18037154 | AE39: =AE29/AC29-1 -> -0.26217565 | AF39: =AE39 -> -0.26217565 | AG39: =AF39 -> -0.26217565 | AH39: =AG39 -> -0.26217565 | AI39: =AH39 -> -0.26217565 | AJ39: =AI39 -> -0.26217565 | AK39: =AJ39 -> -0.26217565 | AL39: =AK39 -> -0.26217565 | AM39: =AL39 -> -0.26217565 | ... AX39: =AW39 -> -0.26217565
B40: Other | J40: -0.14 | AE40: -0.19
K45: =SUMIF($Y$2:$AX$2,K$2,$Y45:$AX45) -> 0 | L45: =SUMIF($Y$2:$AX$2,L$2,$Y45:$AX45) -> 0 | M45: =SUMIF($Y$2:$AX$2,M$2,$Y45:$AX45) -> 0 | N45: =SUMIF($Y$2:$AX$2,N$2,$Y45:$AX45) -> 0 | O45: =SUMIF($Y$2:$AX$2,O$2,$Y45:$AX45) -> 0 | P45: =SUMIF($Y$2:$AX$2,P$2,$Y45:$AX45) -> 0 | Q45: =SUMIF($Y$2:$AX$2,Q$2,$Y45:$AX45) -> 0 | R45: =SUMIF($Y$2:$AX$2,R$2,$Y45:$AX45) -> 0 | ... T45: =SUMIF($Y$2:$AX$2,T$2,$Y45:$AX45) -> 0
K46: =SUMIF($Y$2:$AX$2,K$2,$Y46:$AX46) -> 0 | L46: =SUMIF($Y$2:$AX$2,L$2,$Y46:$AX46) -> 0 | M46: =SUMIF($Y$2:$AX$2,M$2,$Y46:$AX46) -> 0 | N46: =SUMIF($Y$2:$AX$2,N$2,$Y46:$AX46) -> 0 | O46: =SUMIF($Y$2:$AX$2,O$2,$Y46:$AX46) -> 0 | P46: =SUMIF($Y$2:$AX$2,P$2,$Y46:$AX46) -> 0 | Q46: =SUMIF($Y$2:$AX$2,Q$2,$Y46:$AX46) -> 0 | R46: =SUMIF($Y$2:$AX$2,R$2,$Y46:$AX46) -> 0 | ... T46: =SUMIF($Y$2:$AX$2,T$2,$Y46:$AX46) -> 0
B49: Other | E49: =E50-SUM(E45:E48) -> 2892.656 | F49: =F50-SUM(F45:F48) -> 3753.082 | G49: =G50-SUM(G45:G48) -> 5121.613 | H49: =H50-SUM(H45:H48) -> 5212.577 | I49: =I50-SUM(I45:I48) -> 5419.636 | J49: =J50-SUM(J45:J48) -> 5895.556 | K49: =SUMIF($Y$2:$AX$2,K$2,$Y49:$AX49) -> 3155.807 | L49: =SUMIF($Y$2:$AX$2,L$2,$Y49:$AX49) -> 0 | M49: =SUMIF($Y$2:$AX$2,M$2,$Y49:$AX49) -> 0 | N49: =SUMIF($Y$2:$AX$2,N$2,$Y49:$AX49) -> 0 | O49: =SUMIF($Y$2:$AX$2,O$2,$Y49:$AX49) -> 0 | P49: =SUMIF($Y$2:$AX$2,P$2,$Y49:$AX49) -> 0 | Q49: =SUMIF($Y$2:$AX$2,Q$2,$Y49:$AX49) -> 0 | R49: =SUMIF($Y$2:$AX$2,R$2,$Y49:$AX49) -> 0 | ... T49: =SUMIF($Y$2:$AX$2,T$2,$Y49:$AX49) -> 0 | Y49: =Y50-SUM(Y45:Y48) -> 2746.745 | Z49: =Z50-SUM(Z45:Z48) -> 2465.832 | AA49: =AA50-SUM(AA45:AA48) -> 2701.664 | AB49: =AB50-SUM(AB45:AB48) -> 2717.972 | AC49: =AC50-SUM(AC45:AC48) -> 2920.717 | AD49: =AD50-SUM(AD45:AD48) -> 2974.839 | AE49: =AE50-SUM(AE45:AE48) -> 3155.807
B50: Gross Profit | E50: 2892.656 | F50: 3753.082 | G50: 5121.613 | H50: 5212.577 | I50: 5419.636 | J50: 5895.556 | K50: =SUMIF($Y$2:$AX$2,K$2,$Y50:$AX50) -> 6375.0073 | L50: =SUMIF($Y$2:$AX$2,L$2,$Y50:$AX50) -> 7197.7852 | M50: =SUMIF($Y$2:$AX$2,M$2,$Y50:$AX50) -> 7943.1684 | N50: =SUMIF($Y$2:$AX$2,N$2,$Y50:$AX50) -> 8810.6092 | O50: =SUMIF($Y$2:$AX$2,O$2,$Y50:$AX50) -> 9808.664 | P50: =SUMIF($Y$2:$AX$2,P$2,$Y50:$AX50) -> 10948.674 | Q50: =SUMIF($Y$2:$AX$2,Q$2,$Y50:$AX50) -> 12244.68 | R50: =SUMIF($Y$2:$AX$2,R$2,$Y50:$AX50) -> 13713.444 | ... T50: =SUMIF($Y$2:$AX$2,T$2,$Y50:$AX50) -> 17250.542 | Y50: 2746.745 | Z50: 2465.832 | AA50: 2701.664 | AB50: 2717.972 | AC50: 2920.717 | AD50: 2974.839 | AE50: 3155.807 | AF50: =AF$12*AF51 -> 3219.2003 | AG50: =AG12*AG51 -> 3557.0305 | AH50: =AH12*AH51 -> 3640.7547 | AI50: =AI12*AI51 -> 3920.8627 | AJ50: =AJ12*AJ51 -> 4022.3057 | AK50: =AK12*AK51 -> 4344.9837 | AL50: =AL12*AL51 -> 4465.6255 | AM50: =AM12*AM51 -> 4833.4024 | AN50: =AN12*AN51 -> 4975.2616 | ... AX50: =AX12*AX51 -> 8774.0854
B51: Gross Margin | E51: =E50/E$12 -> 0.37730028 | F51: =F50/F$12 -> 0.38250148 | G51: =G50/G$12 -> 0.38790809 | H51: =H50/H$12 -> 0.39328577 | I51: =I50/I$12 -> 0.39468894 | J51: =J50/J$12 -> 0.40320824 | K51: =K50/K$12 -> 0.40692864 | L51: =L50/L$12 -> 0.41093586 | ... T51: =T50/T$12 -> 0.44296149 | Y51: =Y50/Y$12 -> 0.39051732 | Z51: =Z50/Z$12 -> 0.39641619 | AA51: =AA50/AA$12 -> 0.39271432 | AB51: =AB50/AB$12 -> 0.39667149 | AC51: =AC50/AC$12 -> 0.39944226 | AD51: =AD50/AD$12 -> 0.40697543 | AE51: =AE50/AE$12 -> 0.40288185 | AF51: =AD51+0.4% -> 0.41097543 | AG51: =AE51+0.4% -> 0.40688185 | AH51: =AF51+0.4% -> 0.41497543 | AI51: =AG51+0.4% -> 0.41088185 | AJ51: =AH51+0.4% -> 0.41897543 | AK51: =AI51+0.4% -> 0.41488185 | AL51: =AJ51+0.4% -> 0.42297543 | AM51: =AK51+0.4% -> 0.41888185 | ... AX51: =AV51+0.4% -> 0.44697543
B52: =B45 -> 0 | E52: =E45/E7 -> #DIV/0! | F52: =F45/F7 -> #DIV/0! | G52: =G45/G7 -> #DIV/0! | H52: =H45/H7 -> #DIV/0! | I52: =I45/I7 -> #DIV/0! | J52: =J45/J7 -> #DIV/0! | K52: =K45/K7 -> #DIV/0! | L52: =L45/L7 -> #DIV/0! | ... T52: =T45/T7 -> #DIV/0! | Y52: =Y45/Y7 -> #DIV/0! | Z52: =Z45/Z7 -> #DIV/0! | AA52: =AA45/AA7 -> #DIV/0! | AB52: =AB45/AB7 -> #DIV/0! | AC52: =AC45/AC7 -> #DIV/0! | AD52: =AD45/AD7 -> #DIV/0! | AE52: =AE45/AE7 -> #DIV/0!
...

Sheet Sheet1
F6: FY24
F7: FY24 | T7: 1H25

Sheet Sheet2
A1: Item | B1: =Model!J2 -> FY0 | C1: =Model!K2 -> FY1 | D1: =Model!L2 -> FY2 | E1: =Model!M2 -> FY3
A2: FY | B2: =Model!J3 -> 2024 | C2: =Model!K3 -> 2025 | D2: =Model!L3 -> 2026 | E2: =Model!M3 -> 2027
A3: Consensus
A4: Revenue | C4: =Model!K137 -> 15449.482 | D4: =Model!L137 -> 16622.368 | E4: =Model!M137 -> 17998.838
A5: EBIT | C5: =Model!K138 -> 1372.5827 | D5: =Model!L138 -> 1548.0335 | E5: =Model!M138 -> 1733.6435
A6: NPAT | C6: =Model!K139 -> 1240.5462 | D6: =Model!L139 -> 1429.4038 | E6: =Model!M139 -> 1630.4367
A7: PW forecast
A8: Revenue | C8: =Model!K141 -> 15666.155 | D8: =Model!L141 -> 17515.593 | E8: =Model!M141 -> 19142.893
A9: EBIT | C9: =Model!K142 -> 1415.9426 | D9: =Model!L142 -> 1653.1776 | E9: =Model!M142 -> 1883.3513
A10: NPAT | C10: =Model!K143 -> 1269.3133 | D10: =Model!L143 -> 1483.6244 | E10: =Model!M143 -> 1691.9066
A11: PW vs Consensus
A12: Revenue | C12: =Model!K145 -> 0.014024668 | D12: =Model!L145 -> 0.053736337 | E12: =Model!M145 -> 0.063562694
A13: EBIT | C13: =Model!K146 -> 0.03159001 | D13: =Model!L146 -> 0.067921066 | E13: =Model!M146 -> 0.086354423
A14: NPAT | C14: =Model!K147 -> 0.023189092 | D14: =Model!L147 -> 0.037932291 | E14: =Model!M147 -> 0.037701494
