Workbook
Name _Model_Path: "Z:\CONSUMER_STAPLES\Mixuebingcheng\model\Mixue Group final-2025 Oct.xlsx"
Name add_factors: DCF!$D$118:$H$118
Name AddToExplicitPeriods: DCF!$H$133
Name Calculate: DCF!$D$130
Name changes_in_e: #REF!
Name chk_1: #REF!
Name CoE: DCF!$H$119
Name Company_IMPLICATION: #REF!
Name cu107.DPSSymbol: "Rmb"
Name Dashboard: DCF!#REF!
Name DB: "WIREUK"
Name DB: "WIREJPPROD"
Name dcf_mixue: DCF!$B$37:$O$58
Name DCFTitle: DCF!$B$3
Name Discount_rates: DCF!$B$38
Name end_date: #REF!
Name End_of_period_assumptions: DCF!$D$139
Name End_of_period_diluted_shares: DCF!$C$50
Name EntireDCF: DCF!$B$6:$AD$56
Name ExplicitPeriodChk: DCF!$D$133
Name F.2014.12: #REF!
Name F.2015.12: #REF!
Name F.2016.12: #REF!
Name F.2017.12: #REF!
Name F.2018.12: #REF!
Name F.2019.12: #REF!
Name F.2020.12: #REF!
Name F.2021.12: #REF!
Name F.2022.12: #REF!
Name F.2023.12: #REF!
Name FadeToTerminalPeriod: DCF!$H$137
Name FCFF: DCF!$B$33
Name financial_forecast: #REF!
Name financials: #REF!
Name forecastchanges: #REF!
Name FY5Period: DCF!$R$6
Name I1.2014.06: #REF!
Name I1.2015.06: #REF!
Name I1.2016.06: #REF!
Name I1.2017.06: #REF!
Name I1.2018.06: #REF!
Name I1.2019.06: #REF!
Name I1.2020.06: #REF!
Name I1.2021.06: #REF!
Name I1.2022.06: #REF!
Name I1.2023.06: #REF!
Name I2.2014.12: #REF!
Name I2.2015.12: #REF!
Name I2.2016.12: #REF!
Name I2.2017.12: #REF!
Name I2.2018.12: #REF!
Name I2.2019.12: #REF!
Name I2.2020.12: #REF!
Name I2.2021.12: #REF!
Name I2.2022.12: #REF!
Name I2.2023.12: #REF!
Name Inputs___Assumptions: DCF!$B$105
Name Japan_stock_MSCI: #REF!
Name Key_items: DCF!$B$150
Name KeyitemsFY5: DCF!$R$149

Sheet VA-Disclaimer

Sheet DCF
A1: 1 | B1: =A1+1 -> 2 | C1: =B1+1 -> 3 | D1: =C1+1 -> 4 | E1: =D1+1 -> 5 | F1: =E1+1 -> 6 | G1: =F1+1 -> 7 | H1: =G1+1 -> 8 | J1: =H1+1 -> 9 | K1: =J1+1 -> 10 | L1: =K1+1 -> 11 | M1: =L1+1 -> 12 | N1: =M1+1 -> 13 | O1: =N1+1 -> 14 | P1: =O1+1 -> 15 | Q1: =P1+1 -> 16 | R1: 17 | AK1: [+] CAGR =>
B2: ab | G2: ="PT is " &H111&" "&ROUND(H57,2) -> PT is HKD 493.78 | M2: ="Price Target as of "&TEXT(H54, "dd mmm yyyy")&" is: " -> Price Target as of 13 Nov 2026 is: | Q2: =H111&" "&ROUND(H57,2) -> HKD 493.78 | AV2: =COLUMN() -> 48
B3: =$H$107&" DCF Valuation ("&$H$110&$H$113&" unless specified)" -> Mixue DCF Valuation (RMBk unless specified) | M3: Midpoint of offer price | Q3: 200 | R3: =PT/Q3-1 -> 1.4688875
M4: Stage One | S4: Stage Two | X4: Fade to Terminal period
B6: Periods counter | J6: =K6-1 -> -3 | K6: =L6-1 -> -2 | L6: =M6-1 -> -1 | M6: 0 | N6: =M6+1 -> 1 | O6: =N6+1 -> 2 | P6: =O6+1 -> 3 | Q6: =P6+1 -> 4 | R6: =Q6+1 -> 5 | S6: =R6+1 -> 6 | T6: =S6+1 -> 7 | U6: =T6+1 -> 8 | ... AB6: =AA6+1 -> 15 | AC6: Last Forecast | AD6: Terminal | AF6: Term. period | AH6: Stage 1 | AI6: Stage 2 | AJ6: Fade | AK6: Valuation Summary
B7: Periods end dates | J7: =EOMONTH($H$108,12*J6) -> 44561 | K7: =EOMONTH($H$108,12*K6) -> 44926 | L7: =EOMONTH($H$108,12*L6) -> 45291 | M7: =EOMONTH($H$108,12*M6) -> 45657 | N7: =EOMONTH($H$108,12*N6) -> 46022 | O7: =EOMONTH($H$108,12*O6) -> 46387 | P7: =EOMONTH($H$108,12*P6) -> 46752 | Q7: =EOMONTH($H$108,12*Q6) -> 47118 | ... AB7: =EOMONTH($H$108,12*AB6) -> 51135 | AC7: Period | AD7: Period | AF7: YoY growth | AH7: CAGR | AI7: CAGR | AJ7: CAGR | AK7: Assumptions
AH8: 5 | AI8: 5 | AJ8: 6 | AK8: Model forecasts
B9: Operating model
C10: Revenue | L10: =L153 -> 20302465 | M10: =M153 -> 24828874 | N10: =N153 -> 32189782 | O10: =O153 -> 35717844 | P10: =P153 -> 41517893 | Q10: =Q153 -> 47649032 | R10: =R153 -> 53780423 | S10: =R10*(1+S11) -> 60413837 | T10: =S10*(1+T11) -> 67543087 | U10: =T10*(1+U11) -> 75153252 | V10: =U10*(1+V11) -> 83219874 | W10: =V10*(1+W11) -> 91708301 | X10: =W10*(1+X11) -> 99962048 | Y10: =X10*(1+Y11) -> 1.0775909e+08 | Z10: =Y10*(1+Z11) -> 1.1487119e+08 | ... AD10: =AC10*(1+AD11) -> 1.3384245e+08 | AF10: =AD10/AC10-1 -> 0.03 | AH10: =(R10/ M10) ^ (1 /AH8) - 1 -> 0.16716818 | AI10: =(W10/ R10) ^ (1 /AI8) - 1 -> 0.11264568 | AJ10: =(AC10/ W10) ^ (1 /AJ8) - 1 -> 0.059801841
D11: YoY growth | L11: =IFERROR(L10/K10-1,"") | M11: =IFERROR(M10/L10-1,"") -> 0.22294874 | N11: =IFERROR(N10/M10-1,"") -> 0.29646564 | O11: =IFERROR(O10/N10-1,"") -> 0.10960191 | P11: =IFERROR(P10/O10-1,"") -> 0.16238522 | Q11: =IFERROR(Q10/P10-1,"") -> 0.14767462 | R11: =IFERROR(R10/Q10-1,"") -> 0.12867817 | S11: =R11-(R11-St2GR)/5 -> 0.12334254 | T11: =S11-(R11-St2GR)/5 -> 0.1180069 | U11: =T11-(R11-St2GR)/5 -> 0.11267127 | V11: =U11-(R11-St2GR)/5 -> 0.10733563 | W11: =V11-(R11-St2GR)/5 -> 0.102 | X11: =W11-(W11-PenGR)/6 -> 0.09 | Y11: =X11-(W11-PenGR)/6 -> 0.078 | Z11: =Y11-(W11-PenGR)/6 -> 0.066 | AA11: =Z11-(W11-PenGR)/6 -> 0.054 | AB11: =AA11-(W11-PenGR)/6 -> 0.042 | AC11: =AD11 -> 0.03 | AD11: =H140 -> 0.03
C12: EBITDA | L12: =L154 -> 4268960 | M12: =M154 -> 6035889 | N12: =N154 -> 7641476.9 | O12: =O154 -> 8690498.7 | P12: =P154 -> 10484220 | Q12: =Q154 -> 11878807 | R12: =R154 -> 13251088 | S12: =S13*S10 -> 15068052 | T12: =T13*T10 -> 17050269 | U12: =U13*U10 -> 19198422 | V12: =V13*V10 -> 21510547 | W12: =W13*W10 -> 23981721 | X12: =X13*X10 -> 24282448 | Y12: =Y13*Y10 -> 24173955 | Z12: =Z13*Z10 -> 23634747 | ... AD12: =AD13*AD10 -> 20076368 | AF12: =AD12/AC12-1 -> 0.03 | AH12: =(R12/ M12) ^ (1 /AH8) - 1 -> 0.17031308 | AI12: =(W12/ R12) ^ (1 /AI8) - 1 -> 0.12596726 | AJ12: =(AC12/ W12) ^ (1 /AJ8) - 1 -> -0.033961139
D13: EBITDA margin | L13: =IFERROR(L12/L10,"") -> 0.21026806 | M13: =IFERROR(M12/M10,"") -> 0.24309959 | N13: =IFERROR(N12/N10,"") -> 0.23738828 | O13: =IFERROR(O12/O10,"") -> 0.24330973 | P13: =IFERROR(P12/P10,"") -> 0.25252294 | Q13: =IFERROR(Q12/Q10,"") -> 0.24929798 | R13: =IFERROR(R12/R10,"") -> 0.24639241 | S13: =R13-(R13-St2EBITDAMargin)/5 -> 0.24941393 | T13: =S13-(R13-St2EBITDAMargin)/5 -> 0.25243545 | U13: =T13-(R13-St2EBITDAMargin)/5 -> 0.25545696 | V13: =U13-(R13-St2EBITDAMargin)/5 -> 0.25847848 | W13: =V13-(R13-St2EBITDAMargin)/5 -> 0.2615 | X13: =W13-(W13-PenEBITDAMargin)/6 -> 0.24291667 | Y13: =X13-(W13-PenEBITDAMargin)/6 -> 0.22433333 | Z13: =Y13-(W13-PenEBITDAMargin)/6 -> 0.20575 | AA13: =Z13-(W13-PenEBITDAMargin)/6 -> 0.18716667 | AB13: =AA13-(W13-PenEBITDAMargin)/6 -> 0.16858333 | AC13: =AD13 -> 0.15 | AD13: =H141 -> 0.15
C14: EBIT | L14: =L155 -> 4001184 | M14: =M155 -> 5616534 | N14: =N155 -> 6890556.7 | O14: =O155 -> 7663217.7 | P14: =P155 -> 8906197 | Q14: =Q155 -> 10229302 | R14: =R155 -> 11556678 | S14: =S12-S21 -> 13274731 | T14: =T12-T21 -> 15166092 | U14: =U12-U21 -> 17233834 | V14: =V12-V21 -> 19478443 | W14: =W12-W21 -> 21897441 | X14: =X12-X21 -> 22010583 | Y14: =Y12-Y21 -> 21724885 | Z14: =Z12-Z21 -> 21024038 | ... AD14: =AD12-AD21 -> 17034494 | AF14: =AD14/AC14-1 -> 0.03 | AH14: =(R14/ M14) ^ (1 /AH8) - 1 -> 0.15524188 | AI14: =(W14/ R14) ^ (1 /AI8) - 1 -> 0.13634988 | AJ14: =(AC14/ W14) ^ (1 /AJ8) - 1 -> -0.04570399
D15: EBIT margin | L15: =IFERROR(L14/L10,"") -> 0.19707873 | M15: =IFERROR(M14/M10,"") -> 0.22620977 | N15: =IFERROR(N14/N10,"") -> 0.21406037 | O15: =IFERROR(O14/O10,"") -> 0.21454872 | P15: =IFERROR(P14/P10,"") -> 0.21451467 | Q15: =IFERROR(Q14/Q10,"") -> 0.21468017 | R15: =IFERROR(R14/R10,"") -> 0.21488634 | S15: =IFERROR(S14/S10,"") -> 0.21972998 | ... AE15: =IFERROR(AE14/AE10,"") | AK15: =IFERROR(AK14/AK10,"") | AL15: =IFERROR(AL14/AL10,"") | AM15: =IFERROR(AM14/AM10,"") | AN15: =IFERROR(AN14/AN10,"") | AO15: =IFERROR(AO14/AO10,"") | AP15: =IFERROR(AP14/AP10,"") | AQ15: =IFERROR(BF8/BF6,"") | AR15: =IFERROR(AR14/AR10,"") | AS15: =IFERROR(AS14/AS10,"") | AT15: =IFERROR(AT14/AT10,"") | AU15: =IFERROR(AU14/AU10,"") | AV15: =IFERROR(AV14/AV10,"") | AW15: =IFERROR(AW14/AW10,"") | AX15: =IFERROR(AX14/AX10,"") | AY15: =IFERROR(AY14/AY10,"") | ... BE15: =IFERROR(BE14/BE10,"") | BF15: =IFERROR(BF14/#REF!,"") | BG15: =IFERROR(BG14/BG10,"") | BH15: =IFERROR(BH14/BH10,"") | BI15: =IFERROR(BI14/BI10,"") | BJ15: =IFERROR(BJ14/BJ10,"") | BK15: =IFERROR(BK14/BK10,"") | BL15: =IFERROR(BL14/BL10,"") | BM15: =IFERROR(BM14/BM10,"") | BN15: =IFERROR(BN14/BN10,"") | ... AFZ15: =IFERROR(AFZ14/AFZ10,"")
C16: (-) Tax expense (net of interest tax shield benefit) | L16: =L156 -> -957621 | M16: =M156 -> -1331218 | N16: =N156 -> -1571811.3 | O16: =O156 -> -1744940.8 | P16: =P156 -> -2025287.2 | Q16: =Q156 -> -2323072.5 | R16: =R156 -> -2621249.5 | S16: =-S17*S14 -> -3072482.9 | T16: =-T17*T14 -> -3580564.4 | U16: =-U17*U14 -> -4148644.7 | V16: =-V17*V14 -> -4779296.4 | W16: =-W17*W14 -> -5474360.3 | X16: =-X17*X14 -> -5502645.7 | Y16: =-Y17*Y14 -> -5431221.3 | Z16: =-Z17*Z14 -> -5256009.5 | ... AD16: =-AD17*AD14 -> -4258623.5 | AF16: =AD16/AC16-1 -> 0.03 | AH16: =(R16/ M16) ^ (1 /AH8) - 1 -> 0.14512221 | AI16: =(W16/ R16) ^ (1 /AI8) - 1 -> 0.15868398 | AJ16: =(AC16/ W16) ^ (1 /AJ8) - 1 -> -0.04570399
D17: Implied tax rate | L17: =IFERROR(-L16/L14,"") -> 0.23933441 | M17: =IFERROR(-M16/M14,"") -> 0.23701771 | N17: =IFERROR(-N16/N14,"") -> 0.22811093 | O17: =IFERROR(-O16/O14,"") -> 0.22770341 | P17: =IFERROR(-P16/P14,"") -> 0.22740203 | Q17: =IFERROR(-Q16/Q14,"") -> 0.2270998 | R17: =IFERROR(-R16/R14,"") -> 0.22681687 | S17: =R17-(R17-St2TaxRate)/5 -> 0.2314535 | T17: =S17-(R17-St2TaxRate)/5 -> 0.23609012 | U17: =T17-(R17-St2TaxRate)/5 -> 0.24072675 | V17: =U17-(R17-St2TaxRate)/5 -> 0.24536337 | W17: =V17-(R17-St2TaxRate)/5 -> 0.25 | X17: =W17-(W17-PenTaxRate)/6 -> 0.25 | Y17: =X17-(W17-PenTaxRate)/6 -> 0.25 | Z17: =Y17-(W17-PenTaxRate)/6 -> 0.25 | AA17: =Z17-(W17-PenTaxRate)/6 -> 0.25 | AB17: =AA17-(W17-PenTaxRate)/6 -> 0.25 | AC17: =AD17 -> 0.25 | AD17: =H142 -> 0.25
C18: NOPAT | L18: =L14+L16 -> 3043563 | M18: =M14+M16 -> 4285316 | N18: =N14+N16 -> 5318745.3 | O18: =O14+O16 -> 5918277 | P18: =P14+P16 -> 6880909.8 | Q18: =Q14+Q16 -> 7906229.9 | R18: =R14+R16 -> 8935428.5 | S18: =S14+S16 -> 10202248 | ... AD18: =AD14+AD16 -> 12775871 | AF18: =AD18/AC18-1 -> 0.03 | AH18: =(R18/ M18) ^ (1 /AH8) - 1 -> 0.15831453 | AI18: =(W18/ R18) ^ (1 /AI8) - 1 -> 0.12945218 | AJ18: =(AC18/ W18) ^ (1 /AJ8) - 1 -> -0.04570399
B20: Reinvestments
C21: (+) Depreciation and amortisation | L21: =L157 -> 267776 | M21: =M157 -> 419355 | N21: =N157 -> 750920.21 | O21: =O157 -> 1027281 | P21: =P157 -> 1578023.4 | Q21: =Q157 -> 1649505 | R21: =R157 -> 1694410 | S21: =-S24/S23 -> 1793321.1 | T21: =-T24/T23 -> 1884177.5 | U21: =-U24/U23 -> 1964587.8 | V21: =-V24/V23 -> 2032104.1 | W21: =-W24/W23 -> 2084279.6 | X21: =-X24/X23 -> 2271864.7 | Y21: =-Y24/Y23 -> 2449070.2 | Z21: =-Z24/Z23 -> 2610708.8 | ... AD21: =-AD24/AD23 -> 3041874 | AF21: =AD21/AC21-1 -> 0.03 | AH21: =(R21/ M21) ^ (1 /AH8) - 1 -> 0.32217011 | AI21: =(W21/ R21) ^ (1 /AI8) - 1 -> 0.042287416 | AJ21: =(AC21/ W21) ^ (1 /AJ8) - 1 -> 0.059801841
D22: D&A as a % of sales | L22: =IFERROR(L21/L10,"") -> 0.013189334 | M22: =IFERROR(M21/M10,"") -> 0.016889811 | N22: =IFERROR(N21/N10,"") -> 0.023327906 | O22: =IFERROR(O21/O10,"") -> 0.028761003 | P22: =IFERROR(P21/P10,"") -> 0.038008273 | Q22: =IFERROR(Q21/Q10,"") -> 0.034617806 | R22: =IFERROR(R21/R10,"") -> 0.031506074 | S22: =IFERROR(S21/S10,"") -> 0.029683946 | ... AD22: =IFERROR(AD21/AD10,"") -> 0.022727273
D23: Capex / Depreciation ratio | L23: =IFERROR(-L24/L21,"") -> 6.6693356 | M23: =IFERROR(-M24/M21,"") -> 3.5175615 | N23: =IFERROR(-N24/N21,"") -> 2.6299478 | O23: =IFERROR(-O24/O21,"") -> 1.8850826 | P23: =IFERROR(-P24/P21,"") -> 1.2389675 | Q23: =IFERROR(-Q24/Q21,"") -> 1.1462404 | R23: =IFERROR(-R24/R21,"") -> 1.0499185 | S23: =R23-(R23-St2CapDepr)/5 -> 1.0599348 | T23: =S23-(R23-St2CapDepr)/5 -> 1.0699511 | U23: =T23-(R23-St2CapDepr)/5 -> 1.0799674 | V23: =U23-(R23-St2CapDepr)/5 -> 1.0899837 | W23: =V23-(R23-St2CapDepr)/5 -> 1.1 | X23: =W23-(W23-PenCapDepr)/6 -> 1.1 | Y23: =X23-(W23-PenCapDepr)/6 -> 1.1 | Z23: =Y23-(W23-PenCapDepr)/6 -> 1.1 | AA23: =Z23-(W23-PenCapDepr)/6 -> 1.1 | AB23: =AA23-(W23-PenCapDepr)/6 -> 1.1 | AC23: =AD23 -> 1.1 | AD23: =H143 -> 1.1
C24: (-) Capex | L24: =L158 -> -1785888 | M24: =M158 -> -1475107 | N24: =N158 -> -1974880.9 | O24: =O158 -> -1936509.6 | P24: =P158 -> -1955119.7 | Q24: =Q158 -> -1890729.3 | R24: =R158 -> -1778992.3 | S24: =-S25*S10 -> -1900803.4 | T24: =-T25*T10 -> -2015977.8 | U24: =-U25*U10 -> -2121690.8 | V24: =-V25*V10 -> -2214960.3 | W24: =-W25*W10 -> -2292707.5 | X24: =-X25*X10 -> -2499051.2 | Y24: =-Y25*Y10 -> -2693977.2 | Z24: =-Z25*Z10 -> -2871779.7 | ... AD24: =-AD25*AD10 -> -3346061.3 | AF24: =AD24/AC24-1 -> 0.03 | AH24: =(R24/ M24) ^ (1 /AH8) - 1 -> 0.038173909 | AI24: =(W24/ R24) ^ (1 /AI8) - 1 -> 0.052046453 | AJ24: =(AC24/ W24) ^ (1 /AJ8) - 1 -> 0.059801841
D25: Capex as a % of sales | L25: =IFERROR(-L24/L10,"") -> 0.087964097 | M25: =IFERROR(-M24/M10,"") -> 0.05941095 | N25: =IFERROR(-N24/N10,"") -> 0.061351174 | O25: =IFERROR(-O24/O10,"") -> 0.054216866 | P25: =IFERROR(-P24/P10,"") -> 0.047091015 | Q25: =IFERROR(-Q24/Q10,"") -> 0.039680329 | R25: =IFERROR(-R24/R10,"") -> 0.033078809 | S25: =R25-(R25-St2Cap_Sales)/5 -> 0.031463047 | T25: =S25-(R25-St2Cap_Sales)/5 -> 0.029847285 | U25: =T25-(R25-St2Cap_Sales)/5 -> 0.028231524 | V25: =U25-(R25-St2Cap_Sales)/5 -> 0.026615762 | W25: =V25-(R25-St2Cap_Sales)/5 -> 0.025 | X25: =W25-(W25-PenCap_Sales)/6 -> 0.025 | Y25: =X25-(W25-PenCap_Sales)/6 -> 0.025 | Z25: =Y25-(W25-PenCap_Sales)/6 -> 0.025 | AA25: =Z25-(W25-PenCap_Sales)/6 -> 0.025 | AB25: =AA25-(W25-PenCap_Sales)/6 -> 0.025 | AC25: =AD25 -> 0.025 | AD25: =H144 -> 0.025
C26: Change in net working capital | L26: =L159 -> 630433 | M26: =M159 -> 928522 | N26: =N159 -> 625416.21 | O26: =O159 -> 304746.04 | P26: =P159 -> 482505.42 | Q26: =Q159 -> 527604.27 | R26: =R159 -> 550157.63 | S26: =(R10-S10)*S27+((R27-S27)*R10) -> 73002.879 | T26: =(S10-T10)*T27+((S27-T27)*S10) -> 9686.6385 | U26: =(T10-U10)*U27+((T27-U27)*T10) -> -64937.317 | V26: =(U10-V10)*V27+((U27-V27)*U10) -> -150896.56 | W26: =(V10-W10)*W27+((V27-W27)*V10) -> -247908.18 | X26: =(W10-X10)*X27+((W27-X27)*W10) -> 330149.88 | Y26: =(X10-Y10)*Y27+((X27-Y27)*X10) -> 311881.59 | Z26: =(Y10-Z10)*Z27+((Y27-Z27)*Y10) -> 284483.99 | ... AD26: =(AC10-AD10)*AD27+((AC27-AD27)*AC10) -> 155932.96 | AF26: =AD26/AC26-1 -> 0.03 | AH26: =(R26/ M26) ^ (1 /AH8) - 1 -> -0.099385389 | AI26: =(W26/ R26) ^ (1 /AI8) - 1 -> -1.8526303 | AJ26: =(AC26/ W26) ^ (1 /AJ8) - 1 -> #NUM!
D27: Working capital turnover (%) | L27: =IFERROR(L182/L10,"") -> -0.031052042 | M27: =IFERROR(M182/M10,"") -> -0.062787986 | N27: =IFERROR(N182/N10,"") -> -0.067859149 | O27: =IFERROR(O182/O10,"") -> -0.069688341 | P27: =IFERROR(P182/P10,"") -> -0.071574505 | Q27: =IFERROR(Q182/Q10,"") -> -0.073437524 | R27: =IFERROR(R182/R10,"") -> -0.07529477 | S27: =R27-(R27-St2WC)/5 -> -0.068235816 | T27: =S27-(R27-St2WC)/5 -> -0.061176862 | U27: =T27-(R27-St2WC)/5 -> -0.054117908 | V27: =U27-(R27-St2WC)/5 -> -0.047058954 | W27: =V27-(R27-St2WC)/5 -> -0.04 | X27: =W27-(W27-PenWC)/5 -> -0.04 | Y27: =X27-(W27-PenWC)/5 -> -0.04 | Z27: =Y27-(W27-PenWC)/5 -> -0.04 | AA27: =Z27-(W27-PenWC)/5 -> -0.04 | AB27: =AC27 -> -0.04 | AC27: =AD27 -> -0.04 | AD27: =H145 -> -0.04
C28: (-) Net acquisitions | L28: =L160 -> 0 | M28: =M160 -> 0 | N28: =N160 -> 0 | O28: =O160 -> 0 | P28: =P160 -> 0 | Q28: =Q160 -> 0 | R28: =R160 -> 0 | S28: 0 | T28: 0 | U28: 0 | V28: 0 | W28: 0 | X28: 0 | Y28: 0 | Z28: 0 | AA28: 0 | AB28: 0 | AC28: 0 | AD28: 0
C29: Reinvestments | L29: =L21+L24+L26+L28 -> -887679 | M29: =M21+M24+M26+M28 -> -127230 | N29: =N21+N24+N26+N28 -> -598544.5 | O29: =O21+O24+O26+O28 -> -604482.52 | P29: =P21+P24+P26+P28 -> 105409.11 | Q29: =Q21+Q24+Q26+Q28 -> 286379.98 | R29: =R21+R24+R26+R28 -> 465575.28 | S29: =S21+S24+S26+S28 -> -34479.415 | ... AD29: =AD21+AD24+AD26+AD28 -> -148254.44 | AF29: =AD29/AC29-1 -> 0.03 | AH29: =(R29/ M29) ^ (1 /AH8) - 1 -> -2.2962241 | AI29: =(W29/ R29) ^ (1 /AI8) - 1 -> -1.9959992 | AJ29: =(AC29/ W29) ^ (1 /AJ8) - 1 -> -0.17494873
D30: Reinvestment as a % of NOPAT | L30: =IFERROR(-L29/L18,"") -> 0.29165784 | M30: =IFERROR(-M29/M18,"") -> 0.029689759 | N30: =IFERROR(-N29/N18,"") -> 0.1125349 | O30: =IFERROR(-O29/O18,"") -> 0.10213826 | P30: =IFERROR(-P29/P18,"") -> -0.015319066 | Q30: =IFERROR(-Q29/Q18,"") -> -0.036222065 | R30: =IFERROR(-R29/R18,"") -> -0.052104416 | S30: =-IFERROR(S29/S18,"") -> 0.0033795899 | T30: =-IFERROR(T29/T18,"") -> 0.010540186 | U30: =-IFERROR(U29/U18,"") -> 0.016968824 | V30: =-IFERROR(V29/V18,"") -> 0.02270559 | W30: =-IFERROR(W29/W18,"") -> 0.027786269 | X30: =-IFERROR(X29/X18,"") -> -0.0062372064 | Y30: =-IFERROR(Y29/Y18,"") -> -0.0041104673 | Z30: =-IFERROR(Z29/Z18,"") -> -0.0014848471 | ... AD30: =-IFERROR(AD29/AD18,"") -> 0.011604253
C31: Other (items not captured elsewhere) | L31: =L161 -> 98178 | M31: =M161 -> 103567 | N31: =N161 -> 115268.45 | O31: =O161 -> 124088.61 | P31: =P161 -> 138588.73 | Q31: =Q161 -> 153916.58 | R31: =R161 -> 169245.06 | S31: =R31*(1+S32) -> 148880.07 | T31: =S31*(1+T32) -> 98224.178 | U31: =T31*(1+U32) -> 43202.51 | V31: =U31*(1+V32) -> 9501.0053 | W31: =V31*(1+W32) -> 0 | X31: =W31*(1+X32) -> 0 | Y31: =X31*(1+Y32) -> 0 | Z31: =Y31*(1+Z32) -> 0 | ... AD31: =AC31*(1+AD32) -> 0
D32: YoY growth | L32: =IFERROR(L31/K31-1,0) -> 0 | M32: =IFERROR(M31/L31-1,0) -> 0.054890084 | N32: =IFERROR(N31/M31-1,0) -> 0.1129844 | O32: =IFERROR(O31/N31-1,0) -> 0.076518366 | P32: =IFERROR(P31/O31-1,0) -> 0.11685299 | Q32: =IFERROR(Q31/P31-1,0) -> 0.11059952 | R32: =IFERROR(R31/Q31-1,0) -> 0.099589506 | S32: =R32-(R32-St2OtherItems)/5 -> -0.12032839 | T32: =S32-(R32-St2OtherItems)/5 -> -0.3402463 | U32: =T32-(R32-St2OtherItems)/5 -> -0.5601642 | V32: =U32-(R32-St2OtherItems)/5 -> -0.7800821 | W32: =V32-(R32-St2OtherItems)/5 -> -1 | X32: =W32-(W32-PenOtherItemsGR)/6 -> -0.82833333 | Y32: =X32-(W32-PenOtherItemsGR)/6 -> -0.65666667 | Z32: =Y32-(W32-PenOtherItemsGR)/6 -> -0.485 | AA32: =Z32-(W32-PenOtherItemsGR)/6 -> -0.31333333 | AB32: =AA32-(W32-PenOtherItemsGR)/6 -> -0.14166667 | AC32: =AD32 -> 0.03 | AD32: =H140 -> 0.03
B33: FCFF | L33: =L18+L29+L31 -> 2254062 | M33: =M18+M29+M31 -> 4261653 | N33: =N18+N29+N31 -> 4835469.3 | O33: =O18+O29+O31 -> 5437883.1 | P33: =P18+P29+P31 -> 7124907.6 | Q33: =Q18+Q29+Q31 -> 8346526.5 | R33: =R18+R29+R31 -> 9570248.8 | S33: =S18+S29+S31 -> 10316649 | ... AD33: =AD18+AD29+AD31 -> 12627616 | AF33: =AD33/AC33-1 -> 0.03 | AH33: =(R33/ M33) ^ (1 /AH8) - 1 -> 0.17562558 | AI33: =(W33/ R33) ^ (1 /AI8) - 1 -> 0.10779304 | AJ33: =(AC33/ W33) ^ (1 /AJ8) - 1 -> -0.043074868
C35: Terminal value | AD35: =AD33/(WACC-H140) -> 1.9900112e+08
M36: Value as at
B37: DCF Valuation (Rmb '000) | M37: =M7 -> 45657 | N37: =N7 -> 46022 | O37: =O7 -> 46387 | P37: =P7 -> 46752 | Q37: =Q7 -> 47118 | R37: =R7 -> 47483
B38: Terminal value discount factor | M38: =1/(1+WACC)^COLUMNS(N7:$AC$7) -> 0.23943375 | N38: =1/(1+WACC)^COLUMNS(O7:$AC$7) -> 0.26181003 | O38: =1/(1+WACC)^COLUMNS(P7:$AC$7) -> 0.28627748 | P38: =1/(1+WACC)^COLUMNS(Q7:$AC$7) -> 0.31303155 | Q38: =1/(1+WACC)^COLUMNS(R7:$AC$7) -> 0.34228591 | R38: =1/(1+WACC)^COLUMNS(S7:$AC$7) -> 0.37427424
B39: PV of visible period FCFs | M39: =IFERROR(NPV(WACC,N33:$AC$33),"n/a") -> 85439235 | N39: =IFERROR(NPV(WACC,O33:$AC$33),"n/a") -> 88588490 | O39: =IFERROR(NPV(WACC,P33:$AC$33),"n/a") -> 91429644 | P39: =IFERROR(NPV(WACC,Q33:$AC$33),"n/a") -> 92849294 | Q39: =IFERROR(NPV(WACC,R33:$AC$33),"n/a") -> 93179998 | R39: =IFERROR(NPV(WACC,S33:$AC$33),"n/a") -> 92317886
B40: PV of Terminal Value | M40: =IFERROR($AD$35*M38,"n/a") -> 47647584 | N40: =IFERROR($AD$35*N38,"n/a") -> 52100489 | O40: =IFERROR($AD$35*O38,"n/a") -> 56969541 | P40: =IFERROR($AD$35*P38,"n/a") -> 62293629 | Q40: =IFERROR($AD$35*Q38,"n/a") -> 68115280 | R40: =IFERROR($AD$35*R38,"n/a") -> 74480994
B41: =$H$107&" Enterprise Value" -> Mixue Enterprise Value | M41: =IFERROR(SUM(M39:M40),"n/a") -> 1.3308682e+08 | N41: =IFERROR(SUM(N39:N40),"n/a") -> 1.4068898e+08 | O41: =IFERROR(SUM(O39:O40),"n/a") -> 1.4839918e+08 | P41: =IFERROR(SUM(P39:P40),"n/a") -> 1.5514292e+08 | Q41: =IFERROR(SUM(Q39:Q40),"n/a") -> 1.6129528e+08 | R41: =IFERROR(SUM(R39:R40),"n/a") -> 1.6679888e+08
B42: (- /+) Net (debt) / cash (Incl. finance leases if appl.) | M42: =M172 -> 7525301 | N42: =N172 -> 15571506 | O42: =O172 -> 20962270 | P42: =P172 -> 28096079 | Q42: =Q172 -> 36527232 | R42: =R172 -> 46273501
B43: (+) Associates / JV value | M43: =M174 -> 0 | N43: =N174 -> 0 | O43: =O174 -> 0 | P43: =P174 -> 0 | Q43: =Q174 -> 0 | R43: =R174 -> 0
...

Sheet FS
A1: UBS Equity Research
A2: Mixue Group
A3: Unit: Thousand RMB
G4: 2021 | H4: 9M22 | I4: 2022 | J4: 9M23 | K4: 2023 | L4: 9M24 | M4: 2024H1 | N4: 2024H2 | O4: 2024 | P4: 2025H1 | Q4: 2025H2E | R4: 2025E | S4: 2026E | T4: 2027E | U4: 2028E | V4: 2029E | W4: 2030E | AA4: 24-26E | AB4: 25-27E | AC4: 26-28E | AF4: Consensus
A6: Income Statement
A8: Total revenue | G8: 10350986 | H8: 10543240 | I8: 13575577 | J8: 15393328 | K8: 20302465 | L8: 18659671 | M8: 10677054 | N8: =O8-M8 -> 14151820 | O8: 24828874 | P8: 14874809 | Q8: =Assumption!Q18 -> 17314973 | R8: =Assumption!R18 -> 32189782 | S8: =Assumption!S18 -> 35717844 | T8: =Assumption!T18 -> 41517893 | U8: =Assumption!U18 -> 47649032 | V8: =Assumption!V18 -> 53780423 | W8: =Assumption!W18 -> 57634735 | AA8: =(S8/O8)^0.5-1 -> 0.19940016 | AB8: =(T8/R8)^0.5-1 -> 0.13568695 | AC8: =(U8/S8)^0.5-1 -> 0.1550065 | AF8: 14701.517 | AG8: =P8/1000/AF8-1 -> 0.011787365
B9: YoY % | I9: =I8/G8-1 -> 0.31152501 | J9: =J8/H8-1 -> 0.46001874 | K9: =K8/I8-1 -> 0.49551397 | L9: =L8/J8-1 -> 0.21219213 | O9: =O8/K8-1 -> 0.22294874 | P9: =P8/M8-1 -> 0.39315667 | Q9: =Q8/N8-1 -> 0.22351563 | R9: =R8/O8-1 -> 0.29646564 | S9: =S8/R8-1 -> 0.10960191 | T9: =T8/S8-1 -> 0.16238522 | U9: =U8/T8-1 -> 0.14767462 | V9: =V8/U8-1 -> 0.12867817 | W9: =W8/V8-1 -> 0.07166756
B10: Cost of sales | G10: -7107124 | H10: -7572013 | I10: -9728740 | J10: -10817689 | K10: -14303498 | L10: -12619249 | M10: -7274359 | N10: =O10-M10 -> -9494308 | O10: -16768667 | P10: =-10168436 -> -10168436 | Q10: =Assumption!Q49 -> -11796915 | R10: =Assumption!R49 -> -22131087 | S10: =Assumption!S49 -> -24539254 | T10: =Assumption!T49 -> -28525480 | U10: =Assumption!U49 -> -32730083 | V10: =Assumption!V49 -> -36930643 | W10: =Assumption!W49 -> -39524015
A11: Gross profit | G11: =SUM(G8,G10) -> 3243862 | H11: =SUM(H8,H10) -> 2971227 | I11: =SUM(I8,I10) -> 3846837 | J11: =SUM(J8,J10) -> 4575639 | K11: =SUM(K8,K10) -> 5998967 | L11: =SUM(L8,L10) -> 6040422 | M11: =SUM(M8,M10) -> 3402695 | N11: =O11-M11 -> 4657512 | O11: =SUM(O8,O10) -> 8060207 | P11: =SUM(P8,P10) -> 4706373 | Q11: =SUM(Q8,Q10) -> 5518058.3 | R11: =SUM(R8,R10) -> 10058695 | S11: =SUM(S8,S10) -> 11178590 | T11: =SUM(T8,T10) -> 12992414 | U11: =SUM(U8,U10) -> 14918949 | V11: =SUM(V8,V10) -> 16849780 | W11: =SUM(W8,W10) -> 18110719 | AA11: =(S11/O11)^0.5-1 -> 0.17766132 | AB11: =(T11/R11)^0.5-1 -> 0.1365122 | AC11: =(U11/S11)^0.5-1 -> 0.15524903 | AF11: 4431.174 | AG11: =P11/1000/AF11-1 -> 0.0621052
B12: YoY % | I12: =I11/G11-1 -> 0.18588183 | J12: =J11/H11-1 -> 0.53998298 | K12: =K11/I11-1 -> 0.55945443 | L12: =L11/J11-1 -> 0.32012643 | O12: =O11/K11-1 -> 0.34359916 | P12: =P11/M11-1 -> 0.38313102 | Q12: =Q11/N11-1 -> 0.18476523 | R12: =R11/O11-1 -> 0.24794496 | S12: =S11/R11-1 -> 0.11133602 | T12: =T11/S11-1 -> 0.16225872 | U12: =U11/T11-1 -> 0.1482816 | V12: =V11/U11-1 -> 0.12942136 | W12: =W11/V11-1 -> 0.074834162
B13: Selling and distribution expenses | G13: -405766 | H13: -528184 | I13: -774431 | J13: -992934 | K13: -1318588 | L13: -1097090 | M13: -651491 | N13: =O13-M13 -> -947983 | O13: -1599474 | P13: -913679 | Q13: =Assumption!Q180 -> -1159984.1 | R13: =Assumption!R180 -> -2073663.1 | S13: =Assumption!S180 -> -2300940.5 | T13: =Assumption!T180 -> -2674579.2 | U13: =Assumption!U180 -> -3069546.7 | V13: =Assumption!V180 -> -3464530.4 | W13: =Assumption!W180 -> -3712824.8
B14: Administrative expenses | G14: -374665 | H14: -337176 | I14: -496506 | J14: -429811 | K14: -610622 | L14: -433470 | M14: =-279515 -> -279515 | N14: =O14-M14 -> -475600 | O14: -755115 | P14: -437650 | Q14: =Assumption!Q181 -> -541330.65 | R14: =Assumption!R181 -> -978980.65 | S14: =Assumption!S181 -> -1086278.8 | T14: =Assumption!T181 -> -1262674.4 | U14: =Assumption!U181 -> -1449139.4 | V14: =Assumption!V181 -> -1635612 | W14: =Assumption!W181 -> -1752832.3
B15: Research and development expenses | G15: -17151 | H15: -23852 | I15: -32304 | J15: -51343 | K15: -85000 | L15: -64805 | M15: =-40327 -> -40327 | N15: =O15-M15 -> -64543 | O15: -104870 | P15: -41037 | Q15: =Assumption!Q182 -> -94923.352 | R15: =Assumption!R182 -> -135960.35 | S15: =Assumption!S182 -> -150861.87 | T15: =Assumption!T182 -> -175359.6 | U15: =Assumption!U182 -> -201255.76 | V15: =Assumption!V182 -> -227152.99 | W15: =Assumption!W182 -> -243432.49
C16: In opex: equity-settled shared based payment | G16: -22554 | H16: -19377 | I16: -24981 | J16: -8687 | K16: -16427 | L16: -8007 | M16: -6521 | N16: =O16-M16 -> -9265 | O16: -15786 | P16: -9266 | Q16: =R16-P16 -> -11200.007 | R16: =O16/O8*R8 -> -20466.007 | S16: =R16/R8*S8 -> -22709.12 | T16: =S16/S8*T8 -> -26396.745 | U16: =T16/T8*U8 -> -30294.875 | V16: =U16/U8*V8 -> -34193.164 | W16: =V16/V8*W8 -> -36643.704
A17: Adj. EBIT | G17: =G23-G18-G16 -> 2468834 | H17: =H23-H18-H16 -> 2101392 | I17: =I23-I18-I16 -> 2568577 | J17: =J23-J18-J16 -> 3110238 | K17: =K23-K18-K16 -> 4001184 | L17: =L23-L18-L16 -> 4453064 | M17: =M23-M18-M16 -> 2437883 | N17: =O17-M17 -> 3178651 | O17: =O23-O18-O16 -> 5616534 | P17: =P23-P18-P16 -> 3322119 | Q17: =Q23-Q18-Q16 -> 3733020.2 | R17: =R23-R18-R16 -> 6890556.7 | S17: =S23-S18-S16 -> 7663217.7 | T17: =T23-T18-T16 -> 8906197 | U17: =U23-U18-U16 -> 10229302 | V17: =V23-V18-V16 -> 11556678 | W17: =W23-W18-W16 -> 12438273 | AA17: =(S17/O17)^0.5-1 -> 0.16807677 | AB17: =(T17/R17)^0.5-1 -> 0.13689144 | AC17: =(U17/S17)^0.5-1 -> 0.15536026
B18: Non-operating gains/(losses) | G18: =G19+G20+G21+G22 -> 80346 | H18: =H19+H20+H21+H22 -> 43419 | I18: =I19+I20+I21+I22 -> 79315 | J18: =J19+J20+J21+J22 -> 57360 | K18: =K19+K20+K21+K22 -> 130141 | L18: =L19+L20+L21+L22 -> 51628 | M18: =M19+M20+M21+M22 -> 74796 | N18: =O18-M18 -> 34390.999 | O18: =O19+O20+O21+O22 -> 109187 | P18: =P19+P20+P21 -> 86864.412 | Q18: =Q19+Q20+Q21+Q22 -> 27303.041 | R18: =R19+R20+R21 -> 115268.45 | S18: =S19+S20+S21 -> 124088.61 | T18: =T19+T20+T21 -> 138588.73 | U18: =U19+U20+U21 -> 153916.58 | V18: =V19+V20+V21 -> 169245.06 | W18: =W19+W20+W21 -> 178880.83
C19: Other income and gains (net) | G19: =Assumption!G213 -> 96960 | H19: =Assumption!H213 -> 47113 | I19: =Assumption!I213 -> 83593 | J19: =Assumption!J213 -> 112843 | K19: =Assumption!K213 -> 193831 | L19: =Assumption!L213 -> 58168 | M19: 80889 | N19: =O19-M19 -> 31642.999 | O19: =Assumption!O213 -> 112532 | P19: =158602-P25 -> 87965.412 | Q19: =R19-P19 -> 27303.041 | R19: =Assumption!R213 -> 115268.45 | S19: =Assumption!S213 -> 124088.61 | T19: =Assumption!T213 -> 138588.73 | U19: =Assumption!U213 -> 153916.58 | V19: =Assumption!V213 -> 169245.06 | W19: =Assumption!W213 -> 178880.83
C20: (Impairment)/reversal on financial assets | G20: -1787 | H20: -3473 | I20: -4098 | J20: 4480 | K20: 1638 | L20: -3524 | M20: -3077 | N20: =O20-M20 -> 2748 | O20: -329 | P20: -1101 | Q20: =Assumption!Q192 -> 0 | R20: =Assumption!R192 -> 0 | S20: =Assumption!S192 -> 0 | T20: =Assumption!T192 -> 0 | U20: =Assumption!U192 -> 0 | V20: =Assumption!V192 -> 0 | W20: =Assumption!W192 -> 0
C21: Impairment of PP&E | G21: -14827 | H21: 0 | I21: 0 | J21: -59999 | K21: -65524 | L21: 0 | M21: 0 | N21: =O21-M21 -> 0 | O21: 0 | P21: 0 | Q21: =Assumption!Q193 -> 0 | R21: =Assumption!R193 -> 0 | S21: =Assumption!S193 -> 0 | T21: =Assumption!T193 -> 0 | U21: =Assumption!U193 -> 0 | V21: =Assumption!V193 -> 0 | W21: =Assumption!W193 -> 0
C22: Share of (losses)/profits of an associate | G22: 0 | H22: -221 | I22: -180 | J22: 36 | K22: 196 | L22: -3016 | M22: -3016 | N22: =O22-M22 -> 0 | O22: -3016 | P22: -1154 | Q22: =Assumption!Q197 -> 0 | R22: =Assumption!R197 -> 0 | S22: =Assumption!S197 -> 0 | T22: =Assumption!T197 -> 0 | U22: =Assumption!U197 -> 0 | V22: =Assumption!V197 -> 0 | W22: =Assumption!W197 -> 0
A23: EBIT | G23: =G11+G13+G14+G15+G18 -> 2526626 | H23: =H11+H13+H14+H15+H18 -> 2125434 | I23: =I11+I13+I14+I15+I18 -> 2622911 | J23: =J11+J13+J14+J15+J18 -> 3158911 | K23: =K11+K13+K14+K15+K18 -> 4114898 | L23: =L11+L13+L14+L15+L18 -> 4496685 | M23: =M11+M13+M14+M15+M18 -> 2506158 | N23: =O23-M23 -> 3203777 | O23: =O11+O13+O14+O15+O18 -> 5709935 | P23: =P11+P13+P14+P15+P18+P22 -> 3399717.4 | Q23: =Q11+Q13+Q14+Q15+Q18+Q22 -> 3749123.2 | R23: =R11+R13+R14+R15+R18+R22 -> 6985359.1 | S23: =S11+S13+S14+S15+S18+S22 -> 7764597.2 | T23: =T11+T13+T14+T15+T18+T22 -> 9018389 | U23: =U11+U13+U14+U15+U18+U22 -> 10352924 | V23: =V11+V13+V14+V15+V18+V22 -> 11691730 | W23: =W11+W13+W14+W15+W18+W22 -> 12580511 | AA23: =(S23/O23)^0.5-1 -> 0.16612172 | AB23: =(T23/R23)^0.5-1 -> 0.1362401 | AC23: =(U23/S23)^0.5-1 -> 0.15470767
B24: YoY % | I24: =I23/G23-1 -> 0.038108133 | J24: =J23/H23-1 -> 0.48624281 | K24: =K23/I23-1 -> 0.56882868 | L24: =L23/J23-1 -> 0.42349215 | O24: =O23/K23-1 -> 0.38762492 | P24: =P23/M23-1 -> 0.35654552 | Q24: =Q23/N23-1 -> 0.17021979 | R24: =R23/O23-1 -> 0.22336929 | S24: =S23/R23-1 -> 0.11155305 | T24: =T23/S23-1 -> 0.16147544 | U24: =U23/T23-1 -> 0.14797933 | V24: =V23/U23-1 -> 0.12931667 | W24: =W23/V23-1 -> 0.076017895
B25: Interest income | G25: =Assumption!G207 -> 38221 | H25: =Assumption!H207 -> 32715 | I25: =Assumption!I207 -> 44322 | J25: =Assumption!J207 -> 36781 | K25: =Assumption!K207 -> 53801 | L25: =Assumption!L207 -> 77339 | M25: 0 | N25: =O25-M25 -> 107015 | O25: =Assumption!O207 -> 107015 | P25: =Assumption!P368 -> 70636.588 | Q25: =Assumption!Q207 -> 70636.588 | R25: =Assumption!R207 -> 141273.18 | S25: =Assumption!S207 -> 246072.76 | T25: =Assumption!T207 -> 342792.83 | U25: =Assumption!U207 -> 470880.28 | V25: =Assumption!V207 -> 622362.75 | W25: =Assumption!W207 -> 797577.14
B26: Finance costs | G26: -5973 | H26: -6980 | I26: -9190 | J26: -11037 | K26: -14697 | L26: -5479 | M26: -4405 | N26: =O26-M26 -> -1962 | O26: -6367 | P26: -2072 | Q26: =R26-P26 -> -949.25453 | R26: =-Assumption!R365 -> -3021.2545 | S26: =-Assumption!S365 -> -2158.697 | T26: =-Assumption!T365 -> -1589.8308 | U26: =-Assumption!U365 -> -1007.4837 | V26: =-Assumption!V365 -> -502.80054 | W26: =-Assumption!W365 -> -106.63015
A27: Profit before tax | G27: =G23+G26+G25 -> 2558874 | H27: =H23+H26+H25 -> 2151169 | I27: =I23+I26+I25 -> 2658043 | J27: =J23+J26+J25 -> 3184655 | K27: =K23+K26+K25 -> 4154002 | L27: =L23+L26+L25 -> 4568545 | M27: =M23+M26+M25 -> 2501753 | N27: =O27-M27 -> 3308830 | O27: =O23+O26+O25 -> 5810583 | P27: =P23+P26+P25 -> 3468282 | Q27: =Q23+Q26+Q25 -> 3818810.6 | R27: =R23+R26+R25 -> 7123611 | S27: =S23+S26+S25 -> 8008511.3 | T27: =T23+T26+T25 -> 9359592 | U27: =U23+U26+U25 -> 10822797 | V27: =V23+V26+V25 -> 12313590 | W27: =W23+W26+W25 -> 13377981
B28: YoY % | I28: =I27/G27-1 -> 0.038754937 | J28: =J27/H27-1 -> 0.48042994 | K28: =K27/I27-1 -> 0.56280466 | L28: =L27/J27-1 -> 0.43454943 | O28: =O27/K27-1 -> 0.39879157 | P28: =P27/M27-1 -> 0.3863407 | Q28: =Q27/N27-1 -> 0.15412716 | R28: =R27/O27-1 -> 0.22597182 | S28: =S27/R27-1 -> 0.12422075 | T28: =T27/S27-1 -> 0.1687056 | U28: =U27/T27-1 -> 0.15633213 | V28: =V27/U27-1 -> 0.13774562 | W28: =W27/V27-1 -> 0.08644037
B29: Income tax expense | G29: -646932 | H29: -527751 | I29: -644952 | J29: -731876 | K29: -967397 | L29: -1077573 | M29: -614854 | N29: =O29-M29 -> -741526 | O29: -1356380 | P29: -750068 | Q29: =R29-P29 -> -856306.28 | R29: =-R27*R52 -> -1606374.3 | S29: =-S27*S52 -> -1805919.3 | T29: =-T27*T52 -> -2110588 | U29: =-U27*U52 -> -2440540.7 | V29: =-V27*V52 -> -2776714.5 | W29: =-W27*W52 -> -3016734.7
B30: Non-controlling interests | G30: -1581 | H30: -6462 | I30: -16376 | J30: -51926 | K30: -49264 | L30: -4907 | M30: -2441 | N30: =O30-M30 -> -15258 | O30: -17699 | P30: -25330 | Q30: =R30-P30 -> -13290.657 | R30: =-Assumption!R385 -> -38620.657 | S30: =-Assumption!S385 -> -43418.144 | T30: =-Assumption!T385 -> -50743.028 | U30: =-Assumption!U385 -> -58675.794 | V30: =-Assumption!V385 -> -66758.127 | W30: =-Assumption!W385 -> -72528.724
A31: Profit attributable to common equity shareholders | G31: =G27+G29+G30 -> 1910361 | H31: =H27+H29+H30 -> 1616956 | I31: =I27+I29+I30 -> 1996715 | J31: =J27+J29+J30 -> 2400853 | K31: =K27+K29+K30 -> 3137341 | L31: =L27+L29+L30 -> 3486065 | M31: =M27+M29+M30 -> 1884458 | N31: =O31-M31 -> 2552046 | O31: =O27+O29+O30 -> 4436504 | P31: =P27+P29+P30 -> 2692884 | Q31: =Q27+Q29+Q30 -> 2949213.6 | R31: =R27+R29+R30 -> 5478616.1 | S31: =S27+S29+S30 -> 6159173.9 | T31: =T27+T29+T30 -> 7198261 | U31: =U27+U29+U30 -> 8323580.4 | V31: =V27+V29+V30 -> 9470117.2 | W31: =W27+W29+W30 -> 10288718 | AA31: =(S31/O31)^0.5-1 -> 0.17825907 | AB31: =(T31/R31)^0.5-1 -> 0.14624739 | AC31: =(U31/S31)^0.5-1 -> 0.1625024 | AF31: 2393.9252 | AG31: =P31/1000/AF31-1 -> 0.12488225
B32: YoY % | I32: =I31/G31-1 -> 0.045202975 | J32: =J31/H31-1 -> 0.48479798 | K32: =K31/I31-1 -> 0.57125128 | L32: =L31/J31-1 -> 0.45201101 | O32: =O31/K31-1 -> 0.41409684 | P32: =P31/M31-1 -> 0.42899656 | Q32: =Q31/N31-1 -> 0.15562715 | R32: =R31/O31-1 -> 0.23489488 | S32: =S31/R31-1 -> 0.12422075 | T32: =T31/S31-1 -> 0.1687056 | U32: =U31/T31-1 -> 0.15633213 | V32: =V31/U31-1 -> 0.13774562 | W32: =W31/V31-1 -> 0.08644037 | AA32: =(60/44)^0.5-1 -> 0.16774842
A34: Total shares outstanding (basic) | G34: =G111 -> 360000 | I34: =I111 -> 360000 | J34: =J111 -> 360000 | K34: =K111 -> 360000 | L34: =L111 -> 360000 | M34: =O34 -> 360000 | N34: =O34 -> 360000 | O34: =O111 -> 360000 | P34: =P111 -> 379619 | Q34: =Q111 -> 379619 | R34: =R111 -> 379619 | S34: =S111 -> 379619 | T34: =T111 -> 379619 | U34: =U111 -> 379619 | V34: =V111 -> 379619 | W34: =W111 -> 379619
A35: Total shares outstanding (diluted) | G35: =G34 -> 360000 | I35: =I34 -> 360000 | J35: =J34 -> 360000 | K35: =K34 -> 360000 | L35: =L34 -> 360000 | M35: =M34 -> 360000 | N35: =O35 -> 360000 | O35: =O34 -> 360000 | P35: =P34 -> 379619 | Q35: =Q34 -> 379619 | R35: =R34 -> 379619 | S35: =S34 -> 379619 | T35: =T34 -> 379619 | U35: =U34 -> 379619 | V35: =V34 -> 379619 | W35: =W34 -> 379619
A36: EPS (Basic) | G36: =G$31/G34 -> 5.3065583 | I36: =I$31/I34 -> 5.5464306 | J36: =J$31/J34 -> 6.6690361 | K36: =K$31/K34 -> 8.7148361 | L36: =L$31/L34 -> 9.6835139 | M36: =M$31/M34 -> 5.2346056 | N36: =N$31/N34 -> 7.0890167 | O36: =O$31/O34 -> 12.323622 | P36: =P$31/P34 -> 7.0936492 | ... W36: =W$31/W34 -> 27.102747 | AB36: =(T36/R36)^0.5-1 -> 0.14624739
A37: EPS (Diluted) | G37: =G$31/G35 -> 5.3065583 | I37: =I$31/I35 -> 5.5464306 | J37: =J$31/J35 -> 6.6690361 | K37: =K$31/K35 -> 8.7148361 | L37: =L$31/L35 -> 9.6835139 | M37: =M$31/M35 -> 5.2346056 | N37: =N$31/N35 -> 7.0890167 | O37: =O$31/O35 -> 12.323622 | P37: =P$31/P35 -> 7.0936492 | ... W37: =W$31/W35 -> 27.102747
A38: Dividends | G38: =-Assumption!G377 -> 404400 | I38: =-Assumption!I377 -> 104400 | J38: =-Assumption!J377 -> 100000 | K38: =-Assumption!K377 -> 100000 | L38: =-Assumption!L377 -> 0 | M38: 0 | N38: 0 | O38: =O31*O55 -> 0 | P38: 0 | Q38: =R38-P38 -> 0 | R38: =R31*R55 -> 0 | S38: =S31*S55 -> 0 | T38: =T31*T55 -> 0 | U38: =U31*U55 -> 0 | V38: =V31*V55 -> 0 | W38: =W31*W55 -> 0
A39: DPS | G39: =G38/G34 -> 1.1233333 | I39: =I38/I34 -> 0.29 | J39: =J38/J34 -> 0.27777778 | K39: =K38/K34 -> 0.27777778 | L39: =L38/L34 -> 0 | M39: =M38/M34 -> 0 | N39: =N38/N34 -> 0 | O39: =O38/O34 -> 0 | P39: =P38/P34 -> 0 | ... W39: =W38/W34 -> 0
A41: Key metrics:
A42: Gross margin | G42: =IFERROR(G11/G$8,"") -> 0.31338676 | H42: =IFERROR(H11/H$8,"") -> 0.28181347 | I42: =IFERROR(I11/I$8,"") -> 0.28336453 | J42: =IFERROR(J11/J$8,"") -> 0.2972482 | K42: =IFERROR(K11/K$8,"") -> 0.29547974 | L42: =IFERROR(L11/L$8,"") -> 0.32371535 | M42: =IFERROR(M11/M$8,"") -> 0.31869231 | N42: =IFERROR(N11/N$8,"") -> 0.32911046 | ... W42: =IFERROR(W11/W$8,"") -> 0.31423272 | AF42: =IFERROR(AF11/AF$8,"") -> 0.30140931 | AG42: =(P42-AF42)*100 -> 1.4989577
A43: Operating costs as % of revenue
B44: Selling and distribution expenses | G44: =IFERROR(-G13/G$8,"") -> 0.03920071 | H44: =IFERROR(-H13/H$8,"") -> 0.050096934 | I44: =IFERROR(-I13/I$8,"") -> 0.057045899 | J44: =IFERROR(-J13/J$8,"") -> 0.06450418 | K44: =IFERROR(-K13/K$8,"") -> 0.064947187 | L44: =IFERROR(-L13/L$8,"") -> 0.058794713 | M44: =IFERROR(-M13/M$8,"") -> 0.061017861 | N44: =IFERROR(-N13/N$8,"") -> 0.066986649 | ... W44: =IFERROR(-W13/W$8,"") -> 0.064419917
...

Sheet Assumption
A1: UBS Equity Research
A2: Mixue Group
A3: Unit: Thousand RMB | I3: 2022 | J3: 9M23 | K3: 2023 | L3: 9M24 | M3: 2024H1 | N3: 2024H2 | O3: 2024 | P3: 2025H1 | Q3: 2025H2E | R3: 2025E | S3: 2026E | T3: 2027E
G4: 2021 | H4: 9M22 | I4: 2022 | J4: 9M23 | K4: 2023 | L4: 9M24 | M4: 2024H1 | N4: 2024H2 | O4: 2024 | P4: 2025H1 | Q4: 2025H2E | R4: 2025E | S4: 2026E | T4: 2027E | U4: 2028E | V4: 2029E | W4: 2030E
A6: Model Assumptions
A8: Revenues:
A10: Sales of goods & equipment | G10: =G12+G14 -> 10154604 | H10: =H12+H14 -> 10336970 | I10: =I12+I14 -> 13299430 | J10: =J12+J14 -> 15109557 | K10: =K12+K14 -> 19896747 | L10: =L12+L14 -> 18216311 | M10: =M12+M14 -> 10384198 | N10: =O10-M10 -> 13824631 | O10: =O12+O14 -> 24208829 | P10: =P12+P14 -> 14494688 | Q10: =R10-P10 -> 16857844 | R10: =R12+R14 -> 31352532 | S10: =S12+S14 -> 34787574 | T10: =T12+T14 -> 40436920 | U10: =U12+U14 -> 46406425 | V10: =V12+V14 -> 52375105 | W10: =W12+W14 -> 56115159
B11: YoY % | I11: =I10/G10-1 -> 0.3096946 | K11: =K10/I10-1 -> 0.49606013 | L11: =L10/J10-1 -> 0.20561516 | O11: =O10/K10-1 -> 0.21672296 | P11: =P10/M10-1 -> 0.39584087 | Q11: =Q10/N10-1 -> 0.21940643 | R11: =R10/O10-1 -> 0.29508668 | S11: =S10/R10-1 -> 0.10956186 | T11: =T10/S10-1 -> 0.16239553 | U11: =U10/T10-1 -> 0.14762512 | V11: =V10/U10-1 -> 0.12861753 | W11: =W10/V10-1 -> 0.071408994 | X11: =(U10/K10)^0.2-1 -> 0.18456585
B12: Sales of goods | G12: 9457660 | H12: 9776336 | I12: 12551043 | J12: 14504715 | K12: 19160210 | L12: 17595055 | M12: 9926304 | N12: =O12-M12 -> 13526153 | O12: 23452457 | P12: 13843184 | Q12: =R12-P12 -> 16647651 | R12: =R136*R91/10^3 -> 30490835 | S12: =S136*S91/10^3 -> 33878414 | T12: =T136*T91/10^3 -> 39366698 | U12: =U136*U91/10^3 -> 45253053 | V12: =V136*V91/10^3 -> 51178619 | W12: =W136*W91/10^3 -> 55339652
C13: YoY % | I13: =I12/G12-1 -> 0.32707699 | K13: =K12/I12-1 -> 0.52658309 | L13: =L12/J12-1 -> 0.21305762 | O13: =O12/K12-1 -> 0.22401879 | P13: =P12/M12-1 -> 0.39459601 | Q13: =Q12/N12-1 -> 0.23077503 | R13: =R12/O12-1 -> 0.30011262 | S13: =S12/R12-1 -> 0.11110154 | T13: =T12/S12-1 -> 0.16199942 | U13: =U12/T12-1 -> 0.14952628 | V13: =V12/U12-1 -> 0.13094288 | W13: =W12/V12-1 -> 0.08130413
B14: Sales of equipment | G14: 696944 | H14: 560634 | I14: 748387 | J14: 604842 | K14: 736537 | L14: 621256 | M14: 457894 | N14: =O14-M14 -> 298478 | O14: 756372 | P14: 651504 | Q14: =R14-P14 -> 210192.52 | R14: =R138*R75/10^3 -> 861696.52 | S14: =S138*S75/10^3 -> 909159.59 | T14: =T138*T75/10^3 -> 1070222.6 | U14: =U138*U75/10^3 -> 1153372 | V14: =V138*V75/10^3 -> 1196486.8 | W14: =W138*W75/10^3 -> 775507.35
C15: YoY % | I15: =I14/G14-1 -> 0.073812243 | K15: =K14/I14-1 -> -0.015834054 | L15: =L14/J14-1 -> 0.027137666 | O15: =O14/K14-1 -> 0.02693008 | P15: =P14/M14-1 -> 0.42282712 | Q15: =Q14/N14-1 -> -0.29578554 | R15: =R14/O14-1 -> 0.13924963 | S15: =S14/R14-1 -> 0.055080952 | T15: =T14/S14-1 -> 0.17715592 | U15: =U14/T14-1 -> 0.077693601 | V15: =V14/U14-1 -> 0.037381518 | W15: =W14/V14-1 -> -0.35184632
A16: Franchise and related services | G16: 196382 | H16: 206270 | I16: 276147 | J16: 283771 | K16: 405718 | L16: 443360 | M16: 292856 | N16: =O16-M16 -> 327189 | O16: 620045 | P16: 380121 | Q16: =R16-P16 -> 457129.08 | R16: =R27*R141 -> 837250.08 | S16: =S27*S141 -> 930269.85 | T16: =T27*T141 -> 1080973 | U16: =U27*U141 -> 1242606.9 | V16: =V27*V141 -> 1405317.4 | W16: =W27*W141 -> 1519575.5
B17: YoY % | I17: =I16/G16-1 -> 0.40617266 | K17: =K16/I16-1 -> 0.46921024 | O17: =O16/K16-1 -> 0.52826594 | P17: =P16/M16-1 -> 0.29797921 | Q17: =Q16/N16-1 -> 0.39714072 | R17: =R16/O16-1 -> 0.35030534 | S17: =S16/R16-1 -> 0.11110154 | T17: =T16/S16-1 -> 0.16199942 | U17: =U16/T16-1 -> 0.14952628 | V17: =V16/U16-1 -> 0.13094288 | W17: =W16/V16-1 -> 0.08130413
A18: Total revenue | G18: =G10+G16 -> 10350986 | H18: =H10+H16 -> 10543240 | I18: =I10+I16 -> 13575577 | J18: =J10+J16 -> 15393328 | K18: =K10+K16 -> 20302465 | L18: =L10+L16 -> 18659671 | M18: =M10+M16 -> 10677054 | N18: =O18-M18 -> 14151820 | O18: =O10+O16 -> 24828874 | P18: =P10+P16 -> 14874809 | Q18: =Q10+Q16 -> 17314973 | R18: =R10+R16 -> 32189782 | S18: =S10+S16 -> 35717844 | T18: =T10+T16 -> 41517893 | U18: =U10+U16 -> 47649032 | V18: =V10+V16 -> 53780423 | W18: =W10+W16 -> 57634735
B19: YoY % | I19: =I18/G18-1 -> 0.31152501 | K19: =K18/I18-1 -> 0.49551397 | O19: =O18/K18-1 -> 0.22294874 | R19: =R18/O18-1 -> 0.29646564 | S19: =S18/R18-1 -> 0.10960191 | T19: =T18/S18-1 -> 0.16238522 | U19: =U18/T18-1 -> 0.14767462 | V19: =V18/U18-1 -> 0.12867817 | W19: =W18/V18-1 -> 0.07166756
A21: GMV by region:
B22: In mainland China | G22: =G31*G27 -> 22689714 | I22: =I31*I27 -> 29477389 | K22: 44700000 | M22: =M27-M24 -> 23157668 | N22: =N27-N24 -> 32367369 | O22: =O27-O24 -> 55483722 | P22: =P27-P24 -> 32811843 | Q22: =R22-P22 -> 40205441 | R22: =R92*R109/1000 -> 73017284 | S22: =S92*S109/1000 -> 81540238 | T22: =T92*T109/1000 -> 94651198 | U22: =U92*U109/1000 -> 1.0801622e+08 | V22: =V92*V109/1000 -> 1.2085516e+08 | W22: =W92*W109/1000 -> 1.2879366e+08
C23: YoY % | I23: =I22/G22-1 -> 0.2991521 | K23: =K22/I22-1 -> 0.51641653 | O23: =O22/K22-1 -> 0.24124657 | P23: =P22/M22-1 -> 0.41688888 | Q23: =Q22/N22-1 -> 0.24215968 | R23: =R22/O22-1 -> 0.31601272 | S23: =S22/R22-1 -> 0.11672517 | T23: =T22/S22-1 -> 0.16079128 | U23: =U22/T22-1 -> 0.14120291 | V23: =V22/U22-1 -> 0.11886123 | W23: =W22/V22-1 -> 0.065686005 | X23: =(U22/K22)^0.2-1 -> 0.1929886
B24: Outside mainland China | G24: =G27-G22 -> 110286.42 | I24: =I27-I22 -> 1222610.9 | K24: 3142000 | M24: =K24/K27*M27 -> 1627771.7 | N24: =O24-M24 -> 1448013.5 | O24: =O93*O113/1000 -> 3075785.1 | P24: =P93*P113/1000 -> 1796117.2 | Q24: =R24-P24 -> 1413687.6 | R24: =R93*R113/1000 -> 3209804.8 | S24: =S93*S113/1000 -> 3155796.9 | T24: =T93*T113/1000 -> 3765546.5 | U24: =U93*U113/1000 -> 5116411.4 | V24: =V93*V113/1000 -> 7091382.9 | W24: =W93*W113/1000 -> 9555472.8
C25: YoY % | I25: =I24/G24-1 -> 10.085779 | K25: =K24/I24-1 -> 1.5699101 | O25: =O24/K24-1 -> -0.02107411 | P25: =P24/M24-1 -> 0.10342084 | Q25: =Q24/N24-1 -> -0.023705465 | R25: =R24/O24-1 -> 0.043572512 | S25: =S24/R24-1 -> -0.016825924 | T25: =T24/S24-1 -> 0.19321572 | U25: =U24/T24-1 -> 0.35874339 | V25: =V24/U24-1 -> 0.38600719 | W25: =W24/V24-1 -> 0.34747663 | X25: =(U24/K24)^0.2-1 -> 0.10243211
B26: Check | M26: =M22+M24 -> 24785440 | N26: =N22+N24 -> 33815382 | O26: =O22+O24 -> 58559507 | P26: =P22+P24 -> 34607960 | Q26: =Q22+Q24 -> 41619129 | R26: =R22+R24 -> 76227089 | S26: =S22+S24 -> 84696035 | T26: =T22+T24 -> 98416744 | ... W26: =W22+W24 -> 1.3834913e+08
B27: Total | G27: 22800000 | I27: 30700000 | K27: =K22+K24 -> 47842000 | L27: 44900000 | M27: =M12/M137 -> 24785440 | N27: =N12/N137 -> 33815382 | O27: =O12/O137 -> 58559507 | P27: =P12/P137 -> 34607960 | Q27: =R27-P27 -> 41619129 | R27: =R22+R24 -> 76227089 | S27: =S22+S24 -> 84696035 | T27: =T22+T24 -> 98416744 | U27: =U22+U24 -> 1.1313263e+08 | V27: =V22+V24 -> 1.2794655e+08 | W27: =W22+W24 -> 1.3834913e+08
A29: Revenue breakdown by GMV:
B30: In mainland China | G30: 10300917 | I30: 13034937 | J30: 14222007 | K30: 18815533 | L30: 17707309 | M30: =L30/L34*M18 -> 10132113 | N30: =O30-M30 -> 13392647 | O30: =O22/O27*O18 -> 23524760 | P30: =P22/P27*P18 -> 14102822 | Q30: =R30-P30 -> 16731498 | R30: =R22/R27*R18 -> 30834320 | S30: =S22/S27*S18 -> 34386987 | T30: =T22/T27*T18 -> 39929367 | U30: =U22/U27*U18 -> 45494110 | V30: =V22/V27*V18 -> 50799666 | W30: =W22/W27*W18 -> 53654029
C31: % of revenue | G31: =G30/G34 -> 0.99516288 | I31: =I30/I34 -> 0.96017554 | J31: =J30/J34 -> 0.92390723 | K31: =K30/K34 -> 0.92676101 | L31: =L30/L34 -> 0.94896148 | M31: =M30/M34 -> 0.94896148 | N31: =N30/N34 -> 0.94635509 | O31: =O30/O34 -> 0.9474759 | P31: =P30/P34 -> 0.94810104 | ... W31: =W30/W34 -> 0.93093218
B32: Outside mainland China | G32: 50069 | I32: 540640 | J32: 1171321 | K32: 1486932 | L32: 952362 | M32: =M18-M30 -> 544941.04 | N32: =O32-M32 -> 759173.12 | O32: =O18-O30 -> 1304114.2 | P32: =P18-P30 -> 771987.15 | Q32: =R32-P32 -> 583474.8 | R32: =R18-R30 -> 1355461.9 | S32: =S18-S30 -> 1330856.4 | T32: =T18-T30 -> 1588526 | U32: =U18-U30 -> 2154922.4 | V32: =V18-V30 -> 2980757.1 | W32: =W18-W30 -> 3980705.5 | X32: =(S32-O32)/(S18-O18) -> 0.0024559013 | Y32: =(T32/R32)^(0.5)-1 -> 0.082563794
C33: % of revenue | G33: =G32/G34 -> 0.0048371237 | I33: =I32/I34 -> 0.039824458 | J33: =J32/J34 -> 0.076092772 | K33: =K32/K34 -> 0.073238988 | L33: =L32/L34 -> 0.05103852 | M33: =M32/M34 -> 0.05103852 | N33: =N32/N34 -> 0.053644911 | O33: =O32/O34 -> 0.052524096 | P33: =P32/P34 -> 0.051898962 | ... W33: =W32/W34 -> 0.06906782
B34: Total | G34: =G30+G32 -> 10350986 | I34: =I30+I32 -> 13575577 | J34: =J30+J32 -> 15393328 | K34: =K30+K32 -> 20302465 | L34: =L30+L32 -> 18659671 | M34: =M30+M32 -> 10677054 | N34: =O34-M34 -> 14151820 | O34: =O30+O32 -> 24828874 | P34: =P30+P32 -> 14874809 | Q34: =R34-P34 -> 17314973 | R34: =R30+R32 -> 32189782 | S34: =S30+S32 -> 35717844 | T34: =T30+T32 -> 41517893 | U34: =U30+U32 -> 47649032 | V34: =V30+V32 -> 53780423 | W34: =W30+W32 -> 57634735 | Y34: =(T34/R34)^(0.5)-1 -> 0.13568695
A36: Freshly made beverages GMV (mn RMB) | G36: =360.5*1000 -> 360500 | I36: =421.3*1000 -> 421300 | K36: =517.5*1000 -> 517500 | O36: 627900 | P36: 627900 | Q36: =R36 -> 746400 | R36: 746400 | S36: 876200 | T36: 1016800 | U36: 1163400 | V36: 1163400 | W36: 1163400 | X36: =(U36/K36)^0.2-1 -> 0.175882
B37: Implied market share | G37: =G22/1000/G36 -> 0.062939566 | I37: =I22/1000/I36 -> 0.069967693 | K37: =K22/1000/K36 -> 0.086376812 | O37: =O22/1000/O36 -> 0.088363946 | P37: =P22/1000/P36 -> 0.052256478 | R37: =R22/1000/R36 -> 0.097825943 | S37: =S22/1000/S36 -> 0.093061217 | T37: =T22/1000/T36 -> 0.093087331 | U37: =U22/1000/U36 -> 0.0928453 | V37: =V22/1000/V36 -> 0.10388101 | W37: =W22/1000/W36 -> 0.11070454
A39: COGS:
A41: Sales of goods & equipment | G41: =SUM(G43,G45) -> -7051166 | H41: =SUM(H43,H45) -> -7529000 | I41: =SUM(I43,I45) -> -9668582 | J41: =SUM(J43,J45) -> -10762792 | K41: =SUM(K43,K45) -> -14210447 | L41: =SUM(L43,L45) -> -12541860 | M41: =SUM(M43,M45) -> -7217017.6 | N41: =O41-M41 -> -9430120.6 | O41: =SUM(O43,O45) -> -16647138 | P41: =SUM(P43,P45) -> -10268412 | Q41: =R41-P41 -> -11706570 | R41: =SUM(R43,R45) -> -21974981 | S41: =SUM(S43,S45) -> -24378317 | T41: =SUM(T43,T45) -> -28338471 | U41: =SUM(U43,U45) -> -32515112 | V41: =SUM(V43,V45) -> -36687523 | W41: =SUM(W43,W45) -> -39261129
B42: YoY % | I42: =I41/G41-1 -> 0.37120329 | K42: =K41/I41-1 -> 0.46975498 | L42: =L41/J41-1 -> 0.165298 | O42: =O41/K41-1 -> 0.17147186 | R42: =R41/O41-1 -> 0.32004558 | S42: =S41/R41-1 -> 0.10936691 | T42: =T41/S41-1 -> 0.16244577 | U42: =U41/T41-1 -> 0.14738412 | V42: =V41/U41-1 -> 0.1283222 | W42: =W41/V41-1 -> 0.07014935
B43: Sales of goods | G43: -6483793 | H43: -7068431 | I43: -9060836 | J43: -10295459 | K43: =K54-K12 -> -13642070 | L43: -12044122 | M43: =M54-M12 -> -6863666.2 | N43: =O43-M43 -> -9177814.4 | O43: =O54-O12 -> -16041481 | P43: =P54-P12 -> -9765653.6 | Q43: =-Q142*Q91/1000 -> -11528892 | R43: =P43+Q43 -> -21294546 | S43: =S91*S142/1000*-1 -> -23660402 | T43: =T91*T142/1000*-1 -> -27493374 | U43: =U91*U142/1000*-1 -> -31604356 | V43: =V91*V142/1000*-1 -> -35742721 | W43: =W91*W142/1000*-1 -> -38648752
C44: YoY % | I44: =I43/G43-1 -> 0.39745917 | K44: =K43/I43-1 -> 0.50560826 | L44: =L43/J43-1 -> 0.16984799 | O44: =O43/K43-1 -> 0.17588322 | R44: =R43/O43-1 -> 0.32746759 | S44: =S43/R43-1 -> 0.11110154 | T44: =T43/S43-1 -> 0.16199942 | U44: =U43/T43-1 -> 0.14952628 | V44: =V43/U43-1 -> 0.13094288 | W44: =W43/V43-1 -> 0.08130413
B45: Sales of equipment | G45: -567373 | H45: -460569 | I45: -607746 | J45: -467333 | K45: -568377 | L45: -497738 | M45: =M55-M14 -> -353351.45 | N45: =O45-M45 -> -252306.14 | O45: =O55-O14 -> -605657.59 | P45: =P55-P14 -> -502758.03 | Q45: =-Q75*Q144/1000 -> -177677.63 | R45: =P45+Q45 -> -680435.66 | S45: =S75*S144/1000*-1 -> -717914.7 | T45: =T75*T144/1000*-1 -> -845097.54 | U45: =U75*U144/1000*-1 -> -910756.22 | V45: =V75*V144/1000*-1 -> -944801.67 | W45: =W75*W144/1000*-1 -> -612376.68
C46: YoY % | I46: =I45/G45-1 -> 0.071157775 | K46: =K45/I45-1 -> -0.064778707 | L46: =L45/J45-1 -> 0.065060674 | O46: =O45/K45-1 -> 0.06559131 | R46: =R45/O45-1 -> 0.12346591 | S46: =S45/R45-1 -> 0.055080952 | T46: =T45/S45-1 -> 0.17715592 | U46: =U45/T45-1 -> 0.077693601 | V46: =V45/U45-1 -> 0.037381518 | W46: =W45/V45-1 -> -0.35184632
A47: Franchise and related services | G47: -55958 | H47: -43013 | I47: -60158 | J47: -54897 | K47: -82912 | L47: -77389 | M47: =M56-M16 -> -53592.648 | N47: =O47-M47 -> -67936.172 | O47: =O56-O16 -> -121528.82 | P47: =P56-P16 -> -65760.933 | Q47: =Q56-Q16 -> -90345.102 | R47: =P47+Q47 -> -156106.03 | S47: =S56-S16 -> -160936.68 | T47: =T56-T16 -> -187008.33 | U47: =U56-U16 -> -214970.99 | V47: =V56-V16 -> -243119.91 | W47: =W56-W16 -> -262886.57
B48: YoY % | I48: =I47/G47-1 -> 0.075056292 | K48: =K47/I47-1 -> 0.37823731 | L48: =L47/J47-1 -> 0.40971273 | O48: =O47/K47-1 -> 0.46575671 | R48: =R47/O47-1 -> 0.28451864 | S48: =S47/R47-1 -> 0.030944663 | T48: =T47/S47-1 -> 0.16199942 | U48: =U47/T47-1 -> 0.14952628 | V48: =V47/U47-1 -> 0.13094288 | W48: =W47/V47-1 -> 0.08130413
...
