Workbook
Name A_ALL_WOW.AX: #REF!
Name Abnormals_PostTAX: #REF!
Name AEndDrinks_Sales: #REF!
Name Continuing_sales: #REF!
Name DCF_INF: #REF!
Name DPS: #REF!
Name E_ALL_COL.AX: '[1]COL.AX_Exchange_Sheet'!$A$1:$AN$471
Name E_ALL_WOW.AX: #REF!
Name EPS_Pre_Goodwill: #REF!
Name L_ALL_COL.AX: #REF!
Name L_ALL_WOW.AX: #REF!
Name NET_PROFIT: #REF!
Name NPAT_post_Abn: #REF!
Name Sales_Aust_FL: #REF!
Name Sales_NZ_FL: #REF!
Name TOTAL_SALES: #REF!
Name V_ALL_COL.AX: #REF!
Name V_ALL_WOW.AX: #REF!

Sheet Cover
B5: Woolworths Group (WOW.AX)
B6: Rating | C6: Buy
B7: Target Price/ Target price period/ Upside/downside to target price | C7: A$37/ 12 Month/ 16.5%
B8: M&A probability (1 = high, 3 = low) | C8: 3
B9: Market Cap (US$ mn) (price as of ______):
B10: Current shares outstanding (mn):
B11: Currency: | C11: AUD
B12: Current Publication Date: | C12: 46066
B13: Previous Publication Date:
B15: Team Contacts:
B16: Lead Analyst
B17: Peter Marks, peter.marks@gs.com, +61 2 9321 8846, Goldman Sachs Australia Pty Ltd
B18: Consumer Team
B19: James Leigh, james.leigh@gs.com, +61 2 , Goldman Sachs Australia Pty Ltd
B20: Consumer Team
B21: Rayanne Haidar, rayanne.haidar@gs.com +61 2 9321 8739, Goldman Sachs Australia Pty Ltd

Sheet Summary
D1: Woolworths Group (WOW.AX)
D6: Goldman Sachs | Woolworths Group | WOW-AU
D8: Price target | F8: =Valuation!E26 -> 37
D9: Current share price | F9: 31.75
D10: Upside / downside | F10: =F8/F9-1 -> 0.16535433
D11: Recommendation | F11: BUY
A13: Col C | B13: Col K | D13: P&L | E13: FY23 | F13: FY24 | G13: FY25 | H13: FY26E | I13: FY27E | J13: FY28E | L13: Balance sheet | M13: =E$13 -> FY23 | N13: =F$13 -> FY24 | O13: =G$13 -> FY25 | P13: =H$13 -> FY26E | Q13: =I$13 -> FY27E | R13: =J$13 -> FY28E
A14: - | B14: Cash | D14: Sales | L14: Cash | M14: =VLOOKUP($B14,BS!$1:$1048576,MATCH(Summary!M$13,CF!$3:$3,0),FALSE) -> 1135 | N14: =VLOOKUP($B14,BS!$1:$1048576,MATCH(Summary!N$13,CF!$3:$3,0),FALSE) -> 1298 | O14: =VLOOKUP($B14,BS!$1:$1048576,MATCH(Summary!O$13,CF!$3:$3,0),FALSE) -> 1275 | P14: =VLOOKUP($B14,BS!$1:$1048576,MATCH(Summary!P$13,CF!$3:$3,0),FALSE) -> 1379.0612 | Q14: =VLOOKUP($B14,BS!$1:$1048576,MATCH(Summary!Q$13,CF!$3:$3,0),FALSE) -> 1635.9805 | R14: =VLOOKUP($B14,BS!$1:$1048576,MATCH(Summary!R$13,CF!$3:$3,0),FALSE) -> 2028.8967
A15: Aus Food Sales | B15: TR | D15: Australian Food | E15: =VLOOKUP($A15,Model!$1:$1048576,MATCH(Summary!E$13,Model!$3:$3,0),FALSE) -> 48047 | F15: =VLOOKUP($A15,Model!$1:$1048576,MATCH(Summary!F$13,Model!$3:$3,0),FALSE) -> 50823 | G15: =VLOOKUP($A15,Model!$1:$1048576,MATCH(Summary!G$13,Model!$3:$3,0),FALSE) -> 51488 | H15: =VLOOKUP($A15,Model!$1:$1048576,MATCH(Summary!H$13,Model!$3:$3,0),FALSE) -> 53350.775 | I15: =VLOOKUP($A15,Model!$1:$1048576,MATCH(Summary!I$13,Model!$3:$3,0),FALSE) -> 55498.191 | J15: =VLOOKUP($A15,Model!$1:$1048576,MATCH(Summary!J$13,Model!$3:$3,0),FALSE) -> 57722.425 | L15: Trade receivables | M15: =VLOOKUP($B15,BS!$1:$1048576,MATCH(Summary!M$13,CF!$3:$3,0),FALSE) -> 1016 | N15: =VLOOKUP($B15,BS!$1:$1048576,MATCH(Summary!N$13,CF!$3:$3,0),FALSE) -> 1062 | O15: =VLOOKUP($B15,BS!$1:$1048576,MATCH(Summary!O$13,CF!$3:$3,0),FALSE) -> 1034 | P15: =VLOOKUP($B15,BS!$1:$1048576,MATCH(Summary!P$13,CF!$3:$3,0),FALSE) -> 1065.0715 | Q15: =VLOOKUP($B15,BS!$1:$1048576,MATCH(Summary!Q$13,CF!$3:$3,0),FALSE) -> 1107.6623 | R15: =VLOOKUP($B15,BS!$1:$1048576,MATCH(Summary!R$13,CF!$3:$3,0),FALSE) -> 1153.0636
A16: Aus B2B Sales | B16: Inventory | D16: Aus B2B | E16: =VLOOKUP($A16,Model!$1:$1048576,MATCH(Summary!E$13,Model!$3:$3,0),FALSE) -> 4324 | F16: =VLOOKUP($A16,Model!$1:$1048576,MATCH(Summary!F$13,Model!$3:$3,0),FALSE) -> 5594 | G16: =VLOOKUP($A16,Model!$1:$1048576,MATCH(Summary!G$13,Model!$3:$3,0),FALSE) -> 5743 | H16: =VLOOKUP($A16,Model!$1:$1048576,MATCH(Summary!H$13,Model!$3:$3,0),FALSE) -> 5944.005 | I16: =VLOOKUP($A16,Model!$1:$1048576,MATCH(Summary!I$13,Model!$3:$3,0),FALSE) -> 6241.2052 | J16: =VLOOKUP($A16,Model!$1:$1048576,MATCH(Summary!J$13,Model!$3:$3,0),FALSE) -> 6553.2655 | L16: Inventories | M16: =VLOOKUP($B16,BS!$1:$1048576,MATCH(Summary!M$13,CF!$3:$3,0),FALSE) -> 3698 | N16: =VLOOKUP($B16,BS!$1:$1048576,MATCH(Summary!N$13,CF!$3:$3,0),FALSE) -> 4187 | O16: =VLOOKUP($B16,BS!$1:$1048576,MATCH(Summary!O$13,CF!$3:$3,0),FALSE) -> 4169 | P16: =VLOOKUP($B16,BS!$1:$1048576,MATCH(Summary!P$13,CF!$3:$3,0),FALSE) -> 4294.2775 | Q16: =VLOOKUP($B16,BS!$1:$1048576,MATCH(Summary!Q$13,CF!$3:$3,0),FALSE) -> 4466.0003 | R16: =VLOOKUP($B16,BS!$1:$1048576,MATCH(Summary!R$13,CF!$3:$3,0),FALSE) -> 4649.0544
A17: NZ Supermarkets Sales | D17: NZ Supermarkets | E17: =VLOOKUP($A17,Model!$1:$1048576,MATCH(Summary!E$13,Model!$3:$3,0),FALSE) -> 7240 | F17: =VLOOKUP($A17,Model!$1:$1048576,MATCH(Summary!F$13,Model!$3:$3,0),FALSE) -> 7551 | G17: =VLOOKUP($A17,Model!$1:$1048576,MATCH(Summary!G$13,Model!$3:$3,0),FALSE) -> 7557 | H17: =VLOOKUP($A17,Model!$1:$1048576,MATCH(Summary!H$13,Model!$3:$3,0),FALSE) -> 7510.5624 | I17: =VLOOKUP($A17,Model!$1:$1048576,MATCH(Summary!I$13,Model!$3:$3,0),FALSE) -> 7748.9411 | J17: =VLOOKUP($A17,Model!$1:$1048576,MATCH(Summary!J$13,Model!$3:$3,0),FALSE) -> 8064.7313 | L17: Other current assets | M17: =M18-SUM(M14:M16) -> 526 | N17: =N18-SUM(N14:N16) -> 444 | O17: =O18-SUM(O14:O16) -> 513 | P17: =P18-SUM(P14:P16) -> 513 | Q17: =Q18-SUM(Q14:Q16) -> 513 | R17: =R18-SUM(R14:R16) -> 513
A18: W Living Sales | B18: CA | D18: W Living | E18: =VLOOKUP($A18,Model!$1:$1048576,MATCH(Summary!E$13,Model!$3:$3,0),FALSE) -> 4785 | F18: =VLOOKUP($A18,Model!$1:$1048576,MATCH(Summary!F$13,Model!$3:$3,0),FALSE) -> 5220 | G18: =VLOOKUP($A18,Model!$1:$1048576,MATCH(Summary!G$13,Model!$3:$3,0),FALSE) -> 5597 | H18: =VLOOKUP($A18,Model!$1:$1048576,MATCH(Summary!H$13,Model!$3:$3,0),FALSE) -> 5630.8058 | I18: =VLOOKUP($A18,Model!$1:$1048576,MATCH(Summary!I$13,Model!$3:$3,0),FALSE) -> 5785.0025 | J18: =VLOOKUP($A18,Model!$1:$1048576,MATCH(Summary!J$13,Model!$3:$3,0),FALSE) -> 5957.6171 | L18: Current assets | M18: =VLOOKUP($B18,BS!$1:$1048576,MATCH(Summary!M$13,CF!$3:$3,0),FALSE) -> 6375 | N18: =VLOOKUP($B18,BS!$1:$1048576,MATCH(Summary!N$13,CF!$3:$3,0),FALSE) -> 6991 | O18: =VLOOKUP($B18,BS!$1:$1048576,MATCH(Summary!O$13,CF!$3:$3,0),FALSE) -> 6991 | P18: =VLOOKUP($B18,BS!$1:$1048576,MATCH(Summary!P$13,CF!$3:$3,0),FALSE) -> 7251.4102 | Q18: =VLOOKUP($B18,BS!$1:$1048576,MATCH(Summary!Q$13,CF!$3:$3,0),FALSE) -> 7722.6432 | R18: =VLOOKUP($B18,BS!$1:$1048576,MATCH(Summary!R$13,CF!$3:$3,0),FALSE) -> 8344.0148
A19: Others Sales | B19: Fixed Assets | D19: Other | E19: =VLOOKUP($A19,Model!$1:$1048576,MATCH(Summary!E$13,Model!$3:$3,0),FALSE) -> -102 | F19: =VLOOKUP($A19,Model!$1:$1048576,MATCH(Summary!F$13,Model!$3:$3,0),FALSE) -> 226 | G19: =VLOOKUP($A19,Model!$1:$1048576,MATCH(Summary!G$13,Model!$3:$3,0),FALSE) -> 246 | H19: =VLOOKUP($A19,Model!$1:$1048576,MATCH(Summary!H$13,Model!$3:$3,0),FALSE) -> 270.6 | I19: =VLOOKUP($A19,Model!$1:$1048576,MATCH(Summary!I$13,Model!$3:$3,0),FALSE) -> 278.718 | J19: =VLOOKUP($A19,Model!$1:$1048576,MATCH(Summary!J$13,Model!$3:$3,0),FALSE) -> 287.07954 | L19: PPE | M19: =VLOOKUP($B19,BS!$1:$1048576,MATCH(Summary!M$13,CF!$3:$3,0),FALSE) -> 8881 | N19: =VLOOKUP($B19,BS!$1:$1048576,MATCH(Summary!N$13,CF!$3:$3,0),FALSE) -> 9678 | O19: =VLOOKUP($B19,BS!$1:$1048576,MATCH(Summary!O$13,CF!$3:$3,0),FALSE) -> 10172 | P19: =VLOOKUP($B19,BS!$1:$1048576,MATCH(Summary!P$13,CF!$3:$3,0),FALSE) -> 10552.43 | Q19: =VLOOKUP($B19,BS!$1:$1048576,MATCH(Summary!Q$13,CF!$3:$3,0),FALSE) -> 10873.593 | R19: =VLOOKUP($B19,BS!$1:$1048576,MATCH(Summary!R$13,CF!$3:$3,0),FALSE) -> 11133.753
A20: Elimination Sales | B20: ROU | D20: Eliminations | E20: =VLOOKUP($A20,Model!$1:$1048576,MATCH(Summary!E$13,Model!$3:$3,0),FALSE) -> 0 | F20: =VLOOKUP($A20,Model!$1:$1048576,MATCH(Summary!F$13,Model!$3:$3,0),FALSE) -> -1492 | G20: =VLOOKUP($A20,Model!$1:$1048576,MATCH(Summary!G$13,Model!$3:$3,0),FALSE) -> -1554 | H20: =VLOOKUP($A20,Model!$1:$1048576,MATCH(Summary!H$13,Model!$3:$3,0),FALSE) -> -1554 | I20: =VLOOKUP($A20,Model!$1:$1048576,MATCH(Summary!I$13,Model!$3:$3,0),FALSE) -> -1554 | J20: =VLOOKUP($A20,Model!$1:$1048576,MATCH(Summary!J$13,Model!$3:$3,0),FALSE) -> -1554 | L20: Lease assets | M20: =VLOOKUP($B20,BS!$1:$1048576,MATCH(Summary!M$13,CF!$3:$3,0),FALSE) -> 9467 | N20: =VLOOKUP($B20,BS!$1:$1048576,MATCH(Summary!N$13,CF!$3:$3,0),FALSE) -> 9604 | O20: =VLOOKUP($B20,BS!$1:$1048576,MATCH(Summary!O$13,CF!$3:$3,0),FALSE) -> 9162 | P20: =VLOOKUP($B20,BS!$1:$1048576,MATCH(Summary!P$13,CF!$3:$3,0),FALSE) -> 9190.45 | Q20: =VLOOKUP($B20,BS!$1:$1048576,MATCH(Summary!Q$13,CF!$3:$3,0),FALSE) -> 9233.3225 | R20: =VLOOKUP($B20,BS!$1:$1048576,MATCH(Summary!R$13,CF!$3:$3,0),FALSE) -> 9292.1186
A21: Total Sales | B21: Intangibles | D21: Total sales | E21: =VLOOKUP($A21,Model!$1:$1048576,MATCH(Summary!E$13,Model!$3:$3,0),FALSE) -> 64294 | F21: =VLOOKUP($A21,Model!$1:$1048576,MATCH(Summary!F$13,Model!$3:$3,0),FALSE) -> 67922 | G21: =VLOOKUP($A21,Model!$1:$1048576,MATCH(Summary!G$13,Model!$3:$3,0),FALSE) -> 69077 | H21: =VLOOKUP($A21,Model!$1:$1048576,MATCH(Summary!H$13,Model!$3:$3,0),FALSE) -> 71152.749 | I21: =VLOOKUP($A21,Model!$1:$1048576,MATCH(Summary!I$13,Model!$3:$3,0),FALSE) -> 73998.058 | J21: =VLOOKUP($A21,Model!$1:$1048576,MATCH(Summary!J$13,Model!$3:$3,0),FALSE) -> 77031.119 | L21: Intangibles | M21: =VLOOKUP($B21,BS!$1:$1048576,MATCH(Summary!M$13,CF!$3:$3,0),FALSE) -> 2189 | N21: =VLOOKUP($B21,BS!$1:$1048576,MATCH(Summary!N$13,CF!$3:$3,0),FALSE) -> 2407 | O21: =VLOOKUP($B21,BS!$1:$1048576,MATCH(Summary!O$13,CF!$3:$3,0),FALSE) -> 2241 | P21: =VLOOKUP($B21,BS!$1:$1048576,MATCH(Summary!P$13,CF!$3:$3,0),FALSE) -> 2241 | Q21: =VLOOKUP($B21,BS!$1:$1048576,MATCH(Summary!Q$13,CF!$3:$3,0),FALSE) -> 2241 | R21: =VLOOKUP($B21,BS!$1:$1048576,MATCH(Summary!R$13,CF!$3:$3,0),FALSE) -> 2241
A22: EBITDA | D22: EBITDA | E22: =VLOOKUP($A22,PL!$1:$1048576,MATCH(Summary!E$13,PL!$3:$3,0),FALSE) -> 5694 | F22: =VLOOKUP($A22,PL!$1:$1048576,MATCH(Summary!F$13,PL!$3:$3,0),FALSE) -> 6001 | G22: =VLOOKUP($A22,PL!$1:$1048576,MATCH(Summary!G$13,PL!$3:$3,0),FALSE) -> 5707 | H22: =VLOOKUP($A22,PL!$1:$1048576,MATCH(Summary!H$13,PL!$3:$3,0),FALSE) -> 6122.2555 | I22: =VLOOKUP($A22,PL!$1:$1048576,MATCH(Summary!I$13,PL!$3:$3,0),FALSE) -> 6587.8421 | J22: =VLOOKUP($A22,PL!$1:$1048576,MATCH(Summary!J$13,PL!$3:$3,0),FALSE) -> 7087.1762 | L22: Other non current assets | M22: =M23-SUM(M19:M21) -> 6736 | N22: =N23-SUM(N19:N21) -> 5256 | O22: =O23-SUM(O19:O21) -> 5263 | P22: =P23-SUM(P19:P21) -> 5263 | Q22: =Q23-SUM(Q19:Q21) -> 5263 | R22: =R23-SUM(R19:R21) -> 5263
A23: D&A | B23: NCA | D23: D&A | E23: =VLOOKUP($A23,PL!$1:$1048576,MATCH(Summary!E$13,PL!$3:$3,0),FALSE) -> -2578 | F23: =VLOOKUP($A23,PL!$1:$1048576,MATCH(Summary!F$13,PL!$3:$3,0),FALSE) -> -2778 | G23: =VLOOKUP($A23,PL!$1:$1048576,MATCH(Summary!G$13,PL!$3:$3,0),FALSE) -> -2953 | H23: =VLOOKUP($A23,PL!$1:$1048576,MATCH(Summary!H$13,PL!$3:$3,0),FALSE) -> -3071.12 | I23: =VLOOKUP($A23,PL!$1:$1048576,MATCH(Summary!I$13,PL!$3:$3,0),FALSE) -> -3193.9648 | J23: =VLOOKUP($A23,PL!$1:$1048576,MATCH(Summary!J$13,PL!$3:$3,0),FALSE) -> -3321.7234 | L23: Non-current assets | M23: =VLOOKUP($B23,BS!$1:$1048576,MATCH(Summary!M$13,CF!$3:$3,0),FALSE) -> 27273 | N23: =VLOOKUP($B23,BS!$1:$1048576,MATCH(Summary!N$13,CF!$3:$3,0),FALSE) -> 26945 | O23: =VLOOKUP($B23,BS!$1:$1048576,MATCH(Summary!O$13,CF!$3:$3,0),FALSE) -> 26838 | P23: =VLOOKUP($B23,BS!$1:$1048576,MATCH(Summary!P$13,CF!$3:$3,0),FALSE) -> 27246.88 | Q23: =VLOOKUP($B23,BS!$1:$1048576,MATCH(Summary!Q$13,CF!$3:$3,0),FALSE) -> 27610.915 | R23: =VLOOKUP($B23,BS!$1:$1048576,MATCH(Summary!R$13,CF!$3:$3,0),FALSE) -> 27929.872
B24: TP | D24: EBIT | L24: Trade payables | M24: =VLOOKUP($B24,BS!$1:$1048576,MATCH(Summary!M$13,CF!$3:$3,0),FALSE) -> 7623 | N24: =VLOOKUP($B24,BS!$1:$1048576,MATCH(Summary!N$13,CF!$3:$3,0),FALSE) -> 7762 | O24: =VLOOKUP($B24,BS!$1:$1048576,MATCH(Summary!O$13,CF!$3:$3,0),FALSE) -> 8083 | P24: =VLOOKUP($B24,BS!$1:$1048576,MATCH(Summary!P$13,CF!$3:$3,0),FALSE) -> 8325.8924 | Q24: =VLOOKUP($B24,BS!$1:$1048576,MATCH(Summary!Q$13,CF!$3:$3,0),FALSE) -> 8658.8344 | R24: =VLOOKUP($B24,BS!$1:$1048576,MATCH(Summary!R$13,CF!$3:$3,0),FALSE) -> 9013.746
A25: Aus Food EBIT | B25: C Borrowings | D25: Australian Food | E25: =VLOOKUP($A25,Model!$1:$1048576,MATCH(Summary!E$13,Model!$3:$3,0),FALSE) -> 2865 | F25: =VLOOKUP($A25,Model!$1:$1048576,MATCH(Summary!F$13,Model!$3:$3,0),FALSE) -> 3150 | G25: =VLOOKUP($A25,Model!$1:$1048576,MATCH(Summary!G$13,Model!$3:$3,0),FALSE) -> 2721 | H25: =VLOOKUP($A25,Model!$1:$1048576,MATCH(Summary!H$13,Model!$3:$3,0),FALSE) -> 2936.1146 | I25: =VLOOKUP($A25,Model!$1:$1048576,MATCH(Summary!I$13,Model!$3:$3,0),FALSE) -> 3240.4219 | J25: =VLOOKUP($A25,Model!$1:$1048576,MATCH(Summary!J$13,Model!$3:$3,0),FALSE) -> 3583.8158 | L25: Borrowings | M25: =VLOOKUP($B25,BS!$1:$1048576,MATCH(Summary!M$13,CF!$3:$3,0),FALSE) -> 466 | N25: =VLOOKUP($B25,BS!$1:$1048576,MATCH(Summary!N$13,CF!$3:$3,0),FALSE) -> 712 | O25: =VLOOKUP($B25,BS!$1:$1048576,MATCH(Summary!O$13,CF!$3:$3,0),FALSE) -> 244 | P25: =VLOOKUP($B25,BS!$1:$1048576,MATCH(Summary!P$13,CF!$3:$3,0),FALSE) -> 244 | Q25: =VLOOKUP($B25,BS!$1:$1048576,MATCH(Summary!Q$13,CF!$3:$3,0),FALSE) -> 244 | R25: =VLOOKUP($B25,BS!$1:$1048576,MATCH(Summary!R$13,CF!$3:$3,0),FALSE) -> 244
A26: Aus B2B EBIT | D26: Aus B2B | E26: =VLOOKUP($A26,Model!$1:$1048576,MATCH(Summary!E$13,Model!$3:$3,0),FALSE) -> 63 | F26: =VLOOKUP($A26,Model!$1:$1048576,MATCH(Summary!F$13,Model!$3:$3,0),FALSE) -> 122 | G26: =VLOOKUP($A26,Model!$1:$1048576,MATCH(Summary!G$13,Model!$3:$3,0),FALSE) -> 137 | H26: =VLOOKUP($A26,Model!$1:$1048576,MATCH(Summary!H$13,Model!$3:$3,0),FALSE) -> 147.739 | I26: =VLOOKUP($A26,Model!$1:$1048576,MATCH(Summary!I$13,Model!$3:$3,0),FALSE) -> 161.36716 | J26: =VLOOKUP($A26,Model!$1:$1048576,MATCH(Summary!J$13,Model!$3:$3,0),FALSE) -> 169.43552 | L26: Other current liabilities | M26: =M27-SUM(M24:M25) -> 3797 | N26: =N27-SUM(N24:N25) -> 4345 | O26: =O27-SUM(O24:O25) -> 3970 | P26: =P27-SUM(P24:P25) -> 3970 | Q26: =Q27-SUM(Q24:Q25) -> 3970 | R26: =R27-SUM(R24:R25) -> 3970
A27: NZ Supermarkets EBIT | B27: CL | D27: NZ Supermarkets | E27: =VLOOKUP($A27,Model!$1:$1048576,MATCH(Summary!E$13,Model!$3:$3,0),FALSE) -> 228 | F27: =VLOOKUP($A27,Model!$1:$1048576,MATCH(Summary!F$13,Model!$3:$3,0),FALSE) -> 100 | G27: =VLOOKUP($A27,Model!$1:$1048576,MATCH(Summary!G$13,Model!$3:$3,0),FALSE) -> 138 | H27: =VLOOKUP($A27,Model!$1:$1048576,MATCH(Summary!H$13,Model!$3:$3,0),FALSE) -> 157.72181 | I27: =VLOOKUP($A27,Model!$1:$1048576,MATCH(Summary!I$13,Model!$3:$3,0),FALSE) -> 178.22565 | J27: =VLOOKUP($A27,Model!$1:$1048576,MATCH(Summary!J$13,Model!$3:$3,0),FALSE) -> 201.61828 | L27: Current liabilities | M27: =VLOOKUP($B27,BS!$1:$1048576,MATCH(Summary!M$13,CF!$3:$3,0),FALSE) -> 11886 | N27: =VLOOKUP($B27,BS!$1:$1048576,MATCH(Summary!N$13,CF!$3:$3,0),FALSE) -> 12819 | O27: =VLOOKUP($B27,BS!$1:$1048576,MATCH(Summary!O$13,CF!$3:$3,0),FALSE) -> 12297 | P27: =VLOOKUP($B27,BS!$1:$1048576,MATCH(Summary!P$13,CF!$3:$3,0),FALSE) -> 12539.892 | Q27: =VLOOKUP($B27,BS!$1:$1048576,MATCH(Summary!Q$13,CF!$3:$3,0),FALSE) -> 12872.834 | R27: =VLOOKUP($B27,BS!$1:$1048576,MATCH(Summary!R$13,CF!$3:$3,0),FALSE) -> 13227.746
A28: W Living EBIT | B28: NC Lease | D28: W Living | E28: =VLOOKUP($A28,Model!$1:$1048576,MATCH(Summary!E$13,Model!$3:$3,0),FALSE) -> 145 | F28: =VLOOKUP($A28,Model!$1:$1048576,MATCH(Summary!F$13,Model!$3:$3,0),FALSE) -> -29 | G28: =VLOOKUP($A28,Model!$1:$1048576,MATCH(Summary!G$13,Model!$3:$3,0),FALSE) -> -31 | H28: =VLOOKUP($A28,Model!$1:$1048576,MATCH(Summary!H$13,Model!$3:$3,0),FALSE) -> 49.560103 | I28: =VLOOKUP($A28,Model!$1:$1048576,MATCH(Summary!I$13,Model!$3:$3,0),FALSE) -> 61.062615 | J28: =VLOOKUP($A28,Model!$1:$1048576,MATCH(Summary!J$13,Model!$3:$3,0),FALSE) -> 65.199165 | L28: Lease liabilities | M28: =VLOOKUP($B28,BS!$1:$1048576,MATCH(Summary!M$13,CF!$3:$3,0),FALSE) -> 10343 | N28: =VLOOKUP($B28,BS!$1:$1048576,MATCH(Summary!N$13,CF!$3:$3,0),FALSE) -> 10545 | O28: =VLOOKUP($B28,BS!$1:$1048576,MATCH(Summary!O$13,CF!$3:$3,0),FALSE) -> 10175 | P28: =VLOOKUP($B28,BS!$1:$1048576,MATCH(Summary!P$13,CF!$3:$3,0),FALSE) -> 10190.85 | Q28: =VLOOKUP($B28,BS!$1:$1048576,MATCH(Summary!Q$13,CF!$3:$3,0),FALSE) -> 10220.493 | R28: =VLOOKUP($B28,BS!$1:$1048576,MATCH(Summary!R$13,CF!$3:$3,0),FALSE) -> 10265.397
A29: Others EBIT | B29: NC Borrowings | D29: Other | E29: =VLOOKUP($A29,Model!$1:$1048576,MATCH(Summary!E$13,Model!$3:$3,0),FALSE) -> -185 | F29: =VLOOKUP($A29,Model!$1:$1048576,MATCH(Summary!F$13,Model!$3:$3,0),FALSE) -> -120 | G29: =VLOOKUP($A29,Model!$1:$1048576,MATCH(Summary!G$13,Model!$3:$3,0),FALSE) -> -211 | H29: =VLOOKUP($A29,Model!$1:$1048576,MATCH(Summary!H$13,Model!$3:$3,0),FALSE) -> -240 | I29: =VLOOKUP($A29,Model!$1:$1048576,MATCH(Summary!I$13,Model!$3:$3,0),FALSE) -> -247.2 | J29: =VLOOKUP($A29,Model!$1:$1048576,MATCH(Summary!J$13,Model!$3:$3,0),FALSE) -> -254.616 | L29: Borrowings | M29: =VLOOKUP($B29,BS!$1:$1048576,MATCH(Summary!M$13,CF!$3:$3,0),FALSE) -> 3289 | N29: =VLOOKUP($B29,BS!$1:$1048576,MATCH(Summary!N$13,CF!$3:$3,0),FALSE) -> 3866 | O29: =VLOOKUP($B29,BS!$1:$1048576,MATCH(Summary!O$13,CF!$3:$3,0),FALSE) -> 5267 | P29: =VLOOKUP($B29,BS!$1:$1048576,MATCH(Summary!P$13,CF!$3:$3,0),FALSE) -> 5267 | Q29: =VLOOKUP($B29,BS!$1:$1048576,MATCH(Summary!Q$13,CF!$3:$3,0),FALSE) -> 5267 | R29: =VLOOKUP($B29,BS!$1:$1048576,MATCH(Summary!R$13,CF!$3:$3,0),FALSE) -> 5267
A30: Total EBIT | D30: Total EBIT | E30: =VLOOKUP($A30,Model!$1:$1048576,MATCH(Summary!E$13,Model!$3:$3,0),FALSE) -> 3116 | F30: =VLOOKUP($A30,Model!$1:$1048576,MATCH(Summary!F$13,Model!$3:$3,0),FALSE) -> 3223 | G30: =VLOOKUP($A30,Model!$1:$1048576,MATCH(Summary!G$13,Model!$3:$3,0),FALSE) -> 2754 | H30: =VLOOKUP($A30,Model!$1:$1048576,MATCH(Summary!H$13,Model!$3:$3,0),FALSE) -> 3051.1355 | I30: =VLOOKUP($A30,Model!$1:$1048576,MATCH(Summary!I$13,Model!$3:$3,0),FALSE) -> 3393.8773 | J30: =VLOOKUP($A30,Model!$1:$1048576,MATCH(Summary!J$13,Model!$3:$3,0),FALSE) -> 3765.4528 | L30: Other non-current liabilities | M30: =M31-SUM(M28:M29) -> 1565 | N30: =N31-SUM(N28:N29) -> 1136 | O30: =O31-SUM(O28:O29) -> 1128 | P30: =P31-SUM(P28:P29) -> 1128 | Q30: =Q31-SUM(Q28:Q29) -> 1128 | R30: =R31-SUM(R28:R29) -> 1128
A31: Net Interest | B31: NCL | D31: Net interest | E31: =VLOOKUP($A31,PL!$1:$1048576,MATCH(Summary!E$13,PL!$3:$3,0),FALSE) -> -677 | F31: =VLOOKUP($A31,PL!$1:$1048576,MATCH(Summary!F$13,PL!$3:$3,0),FALSE) -> -740 | G31: =VLOOKUP($A31,PL!$1:$1048576,MATCH(Summary!G$13,PL!$3:$3,0),FALSE) -> -811 | H31: =VLOOKUP($A31,PL!$1:$1048576,MATCH(Summary!H$13,PL!$3:$3,0),FALSE) -> -815 | I31: =VLOOKUP($A31,PL!$1:$1048576,MATCH(Summary!I$13,PL!$3:$3,0),FALSE) -> -833.3 | J31: =VLOOKUP($A31,PL!$1:$1048576,MATCH(Summary!J$13,PL!$3:$3,0),FALSE) -> -852.149 | L31: Non-current liabilities | M31: =VLOOKUP($B31,BS!$1:$1048576,MATCH(Summary!M$13,CF!$3:$3,0),FALSE) -> 15197 | N31: =VLOOKUP($B31,BS!$1:$1048576,MATCH(Summary!N$13,CF!$3:$3,0),FALSE) -> 15547 | O31: =VLOOKUP($B31,BS!$1:$1048576,MATCH(Summary!O$13,CF!$3:$3,0),FALSE) -> 16570 | P31: =VLOOKUP($B31,BS!$1:$1048576,MATCH(Summary!P$13,CF!$3:$3,0),FALSE) -> 16585.85 | Q31: =VLOOKUP($B31,BS!$1:$1048576,MATCH(Summary!Q$13,CF!$3:$3,0),FALSE) -> 16615.493 | R31: =VLOOKUP($B31,BS!$1:$1048576,MATCH(Summary!R$13,CF!$3:$3,0),FALSE) -> 16660.397
A32: PBT | B32: Contributed Equity | D32: PBT | E32: =VLOOKUP($A32,PL!$1:$1048576,MATCH(Summary!E$13,PL!$3:$3,0),FALSE) -> 2439 | F32: =VLOOKUP($A32,PL!$1:$1048576,MATCH(Summary!F$13,PL!$3:$3,0),FALSE) -> 2483 | G32: =VLOOKUP($A32,PL!$1:$1048576,MATCH(Summary!G$13,PL!$3:$3,0),FALSE) -> 1943 | H32: =VLOOKUP($A32,PL!$1:$1048576,MATCH(Summary!H$13,PL!$3:$3,0),FALSE) -> 2236.1355 | I32: =VLOOKUP($A32,PL!$1:$1048576,MATCH(Summary!I$13,PL!$3:$3,0),FALSE) -> 2560.5773 | J32: =VLOOKUP($A32,PL!$1:$1048576,MATCH(Summary!J$13,PL!$3:$3,0),FALSE) -> 2913.3038 | L32: Contributed equity | M32: =VLOOKUP($B32,BS!$1:$1048576,MATCH(Summary!M$13,CF!$3:$3,0),FALSE) -> 5406 | N32: =VLOOKUP($B32,BS!$1:$1048576,MATCH(Summary!N$13,CF!$3:$3,0),FALSE) -> 5604 | O32: =VLOOKUP($B32,BS!$1:$1048576,MATCH(Summary!O$13,CF!$3:$3,0),FALSE) -> 5627 | P32: =VLOOKUP($B32,BS!$1:$1048576,MATCH(Summary!P$13,CF!$3:$3,0),FALSE) -> 5627 | Q32: =VLOOKUP($B32,BS!$1:$1048576,MATCH(Summary!Q$13,CF!$3:$3,0),FALSE) -> 5627 | R32: =VLOOKUP($B32,BS!$1:$1048576,MATCH(Summary!R$13,CF!$3:$3,0),FALSE) -> 5627
A33: Tax | B33: Reserves | D33: Tax | E33: =VLOOKUP($A33,PL!$1:$1048576,MATCH(Summary!E$13,PL!$3:$3,0),FALSE) -> -707 | F33: =VLOOKUP($A33,PL!$1:$1048576,MATCH(Summary!F$13,PL!$3:$3,0),FALSE) -> -763 | G33: =VLOOKUP($A33,PL!$1:$1048576,MATCH(Summary!G$13,PL!$3:$3,0),FALSE) -> -568 | H33: =VLOOKUP($A33,PL!$1:$1048576,MATCH(Summary!H$13,PL!$3:$3,0),FALSE) -> -664.13224 | I33: =VLOOKUP($A33,PL!$1:$1048576,MATCH(Summary!I$13,PL!$3:$3,0),FALSE) -> -760.49145 | J33: =VLOOKUP($A33,PL!$1:$1048576,MATCH(Summary!J$13,PL!$3:$3,0),FALSE) -> -865.25123 | L33: Reserves | M33: =VLOOKUP($B33,BS!$1:$1048576,MATCH(Summary!M$13,CF!$3:$3,0),FALSE) -> -7567 | N33: =VLOOKUP($B33,BS!$1:$1048576,MATCH(Summary!N$13,CF!$3:$3,0),FALSE) -> -7609 | O33: =VLOOKUP($B33,BS!$1:$1048576,MATCH(Summary!O$13,CF!$3:$3,0),FALSE) -> -7479 | P33: =VLOOKUP($B33,BS!$1:$1048576,MATCH(Summary!P$13,CF!$3:$3,0),FALSE) -> -7479 | Q33: =VLOOKUP($B33,BS!$1:$1048576,MATCH(Summary!Q$13,CF!$3:$3,0),FALSE) -> -7479 | R33: =VLOOKUP($B33,BS!$1:$1048576,MATCH(Summary!R$13,CF!$3:$3,0),FALSE) -> -7479
A34: Minorities | B34: Retained Profits | D34: Minority Interest | E34: =VLOOKUP($A34,PL!$1:$1048576,MATCH(Summary!E$13,PL!$3:$3,0),FALSE) -> -11 | F34: =VLOOKUP($A34,PL!$1:$1048576,MATCH(Summary!F$13,PL!$3:$3,0),FALSE) -> -9 | G34: =VLOOKUP($A34,PL!$1:$1048576,MATCH(Summary!G$13,PL!$3:$3,0),FALSE) -> 10 | H34: =VLOOKUP($A34,PL!$1:$1048576,MATCH(Summary!H$13,PL!$3:$3,0),FALSE) -> 10 | I34: =VLOOKUP($A34,PL!$1:$1048576,MATCH(Summary!I$13,PL!$3:$3,0),FALSE) -> 10 | J34: =VLOOKUP($A34,PL!$1:$1048576,MATCH(Summary!J$13,PL!$3:$3,0),FALSE) -> 10 | L34: Retained Profits | M34: =VLOOKUP($B34,BS!$1:$1048576,MATCH(Summary!M$13,CF!$3:$3,0),FALSE) -> 8586 | N34: =VLOOKUP($B34,BS!$1:$1048576,MATCH(Summary!N$13,CF!$3:$3,0),FALSE) -> 7413 | O34: =VLOOKUP($B34,BS!$1:$1048576,MATCH(Summary!O$13,CF!$3:$3,0),FALSE) -> 6712 | P34: =VLOOKUP($B34,BS!$1:$1048576,MATCH(Summary!P$13,CF!$3:$3,0),FALSE) -> 7132.5478 | Q34: =VLOOKUP($B34,BS!$1:$1048576,MATCH(Summary!Q$13,CF!$3:$3,0),FALSE) -> 7615.2315 | R34: =VLOOKUP($B34,BS!$1:$1048576,MATCH(Summary!R$13,CF!$3:$3,0),FALSE) -> 8165.7435
A35: NPAT | B35: Minorities | D35: NPAT | E35: =VLOOKUP($A35,PL!$1:$1048576,MATCH(Summary!E$13,PL!$3:$3,0),FALSE) -> 1721 | F35: =VLOOKUP($A35,PL!$1:$1048576,MATCH(Summary!F$13,PL!$3:$3,0),FALSE) -> 1711 | G35: =VLOOKUP($A35,PL!$1:$1048576,MATCH(Summary!G$13,PL!$3:$3,0),FALSE) -> 1385 | H35: =VLOOKUP($A35,PL!$1:$1048576,MATCH(Summary!H$13,PL!$3:$3,0),FALSE) -> 1582.0033 | I35: =VLOOKUP($A35,PL!$1:$1048576,MATCH(Summary!I$13,PL!$3:$3,0),FALSE) -> 1810.0858 | J35: =VLOOKUP($A35,PL!$1:$1048576,MATCH(Summary!J$13,PL!$3:$3,0),FALSE) -> 2058.0526 | L35: Minority Interests | M35: =VLOOKUP($B35,BS!$1:$1048576,MATCH(Summary!M$13,CF!$3:$3,0),FALSE) -> 140 | N35: =VLOOKUP($B35,BS!$1:$1048576,MATCH(Summary!N$13,CF!$3:$3,0),FALSE) -> 162 | O35: =VLOOKUP($B35,BS!$1:$1048576,MATCH(Summary!O$13,CF!$3:$3,0),FALSE) -> 102 | P35: =VLOOKUP($B35,BS!$1:$1048576,MATCH(Summary!P$13,CF!$3:$3,0),FALSE) -> 92 | Q35: =VLOOKUP($B35,BS!$1:$1048576,MATCH(Summary!Q$13,CF!$3:$3,0),FALSE) -> 82 | R35: =VLOOKUP($B35,BS!$1:$1048576,MATCH(Summary!R$13,CF!$3:$3,0),FALSE) -> 72
A36: Shares | B36: Total Equity | D36: Shares (m) | E36: =VLOOKUP($A36,PL!$1:$1048576,MATCH(Summary!E$13,PL!$3:$3,0),FALSE) -> 1223.1 | F36: =VLOOKUP($A36,PL!$1:$1048576,MATCH(Summary!F$13,PL!$3:$3,0),FALSE) -> 1225.7 | G36: =VLOOKUP($A36,PL!$1:$1048576,MATCH(Summary!G$13,PL!$3:$3,0),FALSE) -> 1228.7 | H36: =VLOOKUP($A36,PL!$1:$1048576,MATCH(Summary!H$13,PL!$3:$3,0),FALSE) -> 1230.7 | I36: =VLOOKUP($A36,PL!$1:$1048576,MATCH(Summary!I$13,PL!$3:$3,0),FALSE) -> 1232.7 | J36: =VLOOKUP($A36,PL!$1:$1048576,MATCH(Summary!J$13,PL!$3:$3,0),FALSE) -> 1234.7 | L36: Total Equity | M36: =VLOOKUP($B36,BS!$1:$1048576,MATCH(Summary!M$13,CF!$3:$3,0),FALSE) -> 6565 | N36: =VLOOKUP($B36,BS!$1:$1048576,MATCH(Summary!N$13,CF!$3:$3,0),FALSE) -> 5570 | O36: =VLOOKUP($B36,BS!$1:$1048576,MATCH(Summary!O$13,CF!$3:$3,0),FALSE) -> 4962 | P36: =VLOOKUP($B36,BS!$1:$1048576,MATCH(Summary!P$13,CF!$3:$3,0),FALSE) -> 5372.5478 | Q36: =VLOOKUP($B36,BS!$1:$1048576,MATCH(Summary!Q$13,CF!$3:$3,0),FALSE) -> 5845.2315 | R36: =VLOOKUP($B36,BS!$1:$1048576,MATCH(Summary!R$13,CF!$3:$3,0),FALSE) -> 6385.7435
A37: EPS | B37: Net Debt | D37: EPS | E37: =VLOOKUP($A37,PL!$1:$1048576,MATCH(Summary!E$13,PL!$3:$3,0),FALSE) -> 1.4070804 | F37: =VLOOKUP($A37,PL!$1:$1048576,MATCH(Summary!F$13,PL!$3:$3,0),FALSE) -> 1.395937 | G37: =VLOOKUP($A37,PL!$1:$1048576,MATCH(Summary!G$13,PL!$3:$3,0),FALSE) -> 1.1272076 | H37: =VLOOKUP($A37,PL!$1:$1048576,MATCH(Summary!H$13,PL!$3:$3,0),FALSE) -> 1.28545 | I37: =VLOOKUP($A37,PL!$1:$1048576,MATCH(Summary!I$13,PL!$3:$3,0),FALSE) -> 1.4683912 | J37: =VLOOKUP($A37,PL!$1:$1048576,MATCH(Summary!J$13,PL!$3:$3,0),FALSE) -> 1.6668442 | L37: Net debt ex leases | M37: =VLOOKUP($B37,BS!$1:$1048576,MATCH(Summary!M$13,CF!$3:$3,0),FALSE) -> 2620 | N37: =VLOOKUP($B37,BS!$1:$1048576,MATCH(Summary!N$13,CF!$3:$3,0),FALSE) -> 3280 | O37: =VLOOKUP($B37,BS!$1:$1048576,MATCH(Summary!O$13,CF!$3:$3,0),FALSE) -> 4236 | P37: =VLOOKUP($B37,BS!$1:$1048576,MATCH(Summary!P$13,CF!$3:$3,0),FALSE) -> 4131.9388 | Q37: =VLOOKUP($B37,BS!$1:$1048576,MATCH(Summary!Q$13,CF!$3:$3,0),FALSE) -> 3875.0195 | R37: =VLOOKUP($B37,BS!$1:$1048576,MATCH(Summary!R$13,CF!$3:$3,0),FALSE) -> 3482.1033
A38: DPS | D38: DPS total | E38: =VLOOKUP($A38,PL!$1:$1048576,MATCH(Summary!E$13,PL!$3:$3,0),FALSE) -> 1.04 | F38: =VLOOKUP($A38,PL!$1:$1048576,MATCH(Summary!F$13,PL!$3:$3,0),FALSE) -> 1.44 | G38: =VLOOKUP($A38,PL!$1:$1048576,MATCH(Summary!G$13,PL!$3:$3,0),FALSE) -> 0.84 | H38: =VLOOKUP($A38,PL!$1:$1048576,MATCH(Summary!H$13,PL!$3:$3,0),FALSE) -> 0.95123296 | I38: =VLOOKUP($A38,PL!$1:$1048576,MATCH(Summary!I$13,PL!$3:$3,0),FALSE) -> 1.0866095 | J38: =VLOOKUP($A38,PL!$1:$1048576,MATCH(Summary!J$13,PL!$3:$3,0),FALSE) -> 1.2334647 | L38: Divisional Key Metrics | M38: =E$13 -> FY23 | N38: =F$13 -> FY24 | O38: =G$13 -> FY25 | P38: =H$13 -> FY26E | Q38: =I$13 -> FY27E | R38: =J$13 -> FY28E
B39: Aus Food Comp | L39: Aus Food LFL Sales Growth | M39: =VLOOKUP($B39,Model!$1:$1048576,MATCH(Summary!M$13,CF!$3:$3,0),FALSE) -> 0.042 | N39: =VLOOKUP($B39,Model!$1:$1048576,MATCH(Summary!N$13,CF!$3:$3,0),FALSE) -> 0.028 | O39: =VLOOKUP($B39,Model!$1:$1048576,MATCH(Summary!O$13,CF!$3:$3,0),FALSE) -> 0.024 | P39: =VLOOKUP($B39,Model!$1:$1048576,MATCH(Summary!P$13,CF!$3:$3,0),FALSE) -> 0.02975 | Q39: =VLOOKUP($B39,Model!$1:$1048576,MATCH(Summary!Q$13,CF!$3:$3,0),FALSE) -> 0.035 | R39: =VLOOKUP($B39,Model!$1:$1048576,MATCH(Summary!R$13,CF!$3:$3,0),FALSE) -> 0.035
B40: Aus Food EBIT Margin | D40: Cash Flow | E40: FY23 | F40: FY24 | G40: FY25 | H40: FY26E | I40: FY27E | J40: FY28E | L40: Aus Food EBIT Margin | M40: =VLOOKUP($B40,Model!$1:$1048576,MATCH(Summary!M$13,CF!$3:$3,0),FALSE) -> 0.059629113 | N40: =VLOOKUP($B40,Model!$1:$1048576,MATCH(Summary!N$13,CF!$3:$3,0),FALSE) -> 0.061979812 | O40: =VLOOKUP($B40,Model!$1:$1048576,MATCH(Summary!O$13,CF!$3:$3,0),FALSE) -> 0.052847265 | P40: =VLOOKUP($B40,Model!$1:$1048576,MATCH(Summary!P$13,CF!$3:$3,0),FALSE) -> 0.05503415 | Q40: =VLOOKUP($B40,Model!$1:$1048576,MATCH(Summary!Q$13,CF!$3:$3,0),FALSE) -> 0.058387882 | R40: =VLOOKUP($B40,Model!$1:$1048576,MATCH(Summary!R$13,CF!$3:$3,0),FALSE) -> 0.062087063
A41: EBIT | B41: NZ LFL | D41: EBIT | E41: =VLOOKUP($A41,CF!$1:$1048576,MATCH(Summary!E$13,CF!$3:$3,0),FALSE) -> 3116 | F41: =VLOOKUP($A41,CF!$1:$1048576,MATCH(Summary!F$13,CF!$3:$3,0),FALSE) -> 3223 | G41: =VLOOKUP($A41,CF!$1:$1048576,MATCH(Summary!G$13,CF!$3:$3,0),FALSE) -> 2754 | H41: =VLOOKUP($A41,CF!$1:$1048576,MATCH(Summary!H$13,CF!$3:$3,0),FALSE) -> 3051.1355 | I41: =VLOOKUP($A41,CF!$1:$1048576,MATCH(Summary!I$13,CF!$3:$3,0),FALSE) -> 3393.8773 | J41: =VLOOKUP($A41,CF!$1:$1048576,MATCH(Summary!J$13,CF!$3:$3,0),FALSE) -> 3765.4528 | L41: NZ Food LFL Sales Growth | M41: =VLOOKUP($B41,Model!$1:$1048576,MATCH(Summary!M$13,CF!$3:$3,0),FALSE) -> 0.035 | N41: =VLOOKUP($B41,Model!$1:$1048576,MATCH(Summary!N$13,CF!$3:$3,0),FALSE) -> 0.018 | O41: =VLOOKUP($B41,Model!$1:$1048576,MATCH(Summary!O$13,CF!$3:$3,0),FALSE) -> 0.038 | P41: =VLOOKUP($B41,Model!$1:$1048576,MATCH(Summary!P$13,CF!$3:$3,0),FALSE) -> 0.03425 | Q41: =VLOOKUP($B41,Model!$1:$1048576,MATCH(Summary!Q$13,CF!$3:$3,0),FALSE) -> 0.035 | R41: =VLOOKUP($B41,Model!$1:$1048576,MATCH(Summary!R$13,CF!$3:$3,0),FALSE) -> 0.035
A42: D&A | B42: NZ Food EBIT Margin | D42: D&A | E42: =VLOOKUP($A42,CF!$1:$1048576,MATCH(Summary!E$13,CF!$3:$3,0),FALSE) -> 2578 | F42: =VLOOKUP($A42,CF!$1:$1048576,MATCH(Summary!F$13,CF!$3:$3,0),FALSE) -> 2778 | G42: =VLOOKUP($A42,CF!$1:$1048576,MATCH(Summary!G$13,CF!$3:$3,0),FALSE) -> 2953 | H42: =VLOOKUP($A42,CF!$1:$1048576,MATCH(Summary!H$13,CF!$3:$3,0),FALSE) -> 3071.12 | I42: =VLOOKUP($A42,CF!$1:$1048576,MATCH(Summary!I$13,CF!$3:$3,0),FALSE) -> 3193.9648 | J42: =VLOOKUP($A42,CF!$1:$1048576,MATCH(Summary!J$13,CF!$3:$3,0),FALSE) -> 3321.7234 | L42: NZ Food EBIT Margin | M42: =VLOOKUP($B42,Model!$1:$1048576,MATCH(Summary!M$13,CF!$3:$3,0),FALSE) -> 0.031471183 | N42: =VLOOKUP($B42,Model!$1:$1048576,MATCH(Summary!N$13,CF!$3:$3,0),FALSE) -> 0.013225569 | O42: =VLOOKUP($B42,Model!$1:$1048576,MATCH(Summary!O$13,CF!$3:$3,0),FALSE) -> 0.018102824 | P42: =VLOOKUP($B42,Model!$1:$1048576,MATCH(Summary!P$13,CF!$3:$3,0),FALSE) -> 0.021 | Q42: =VLOOKUP($B42,Model!$1:$1048576,MATCH(Summary!Q$13,CF!$3:$3,0),FALSE) -> 0.023 | R42: =VLOOKUP($B42,Model!$1:$1048576,MATCH(Summary!R$13,CF!$3:$3,0),FALSE) -> 0.025
A43: Net interest | D43: Net interest | E43: =VLOOKUP($A43,CF!$1:$1048576,MATCH(Summary!E$13,CF!$3:$3,0),FALSE) -> -677 | F43: =VLOOKUP($A43,CF!$1:$1048576,MATCH(Summary!F$13,CF!$3:$3,0),FALSE) -> -740 | G43: =VLOOKUP($A43,CF!$1:$1048576,MATCH(Summary!G$13,CF!$3:$3,0),FALSE) -> -811 | H43: =VLOOKUP($A43,CF!$1:$1048576,MATCH(Summary!H$13,CF!$3:$3,0),FALSE) -> -815 | I43: =VLOOKUP($A43,CF!$1:$1048576,MATCH(Summary!I$13,CF!$3:$3,0),FALSE) -> -833.3 | J43: =VLOOKUP($A43,CF!$1:$1048576,MATCH(Summary!J$13,CF!$3:$3,0),FALSE) -> -852.149 | L43: Group Key Metrics | M43: =E$13 -> FY23 | N43: =F$13 -> FY24 | O43: =G$13 -> FY25 | P43: =H$13 -> FY26E | Q43: =I$13 -> FY27E | R43: =J$13 -> FY28E
A44: Tax | B44: Total Sales Growth | D44: Tax | E44: =VLOOKUP($A44,CF!$1:$1048576,MATCH(Summary!E$13,CF!$3:$3,0),FALSE) -> -707 | F44: =VLOOKUP($A44,CF!$1:$1048576,MATCH(Summary!F$13,CF!$3:$3,0),FALSE) -> -763 | G44: =VLOOKUP($A44,CF!$1:$1048576,MATCH(Summary!G$13,CF!$3:$3,0),FALSE) -> -568 | H44: =VLOOKUP($A44,CF!$1:$1048576,MATCH(Summary!H$13,CF!$3:$3,0),FALSE) -> -664.13224 | I44: =VLOOKUP($A44,CF!$1:$1048576,MATCH(Summary!I$13,CF!$3:$3,0),FALSE) -> -760.49145 | J44: =VLOOKUP($A44,CF!$1:$1048576,MATCH(Summary!J$13,CF!$3:$3,0),FALSE) -> -865.25123 | L44: Sales Growth | M44: =VLOOKUP($B44,PL!$1:$1048576,MATCH(Summary!M$13,CF!$3:$3,0),FALSE) -> 0.056615557 | N44: =VLOOKUP($B44,PL!$1:$1048576,MATCH(Summary!N$13,CF!$3:$3,0),FALSE) -> 0.056428283 | O44: =VLOOKUP($B44,PL!$1:$1048576,MATCH(Summary!O$13,CF!$3:$3,0),FALSE) -> 0.0170048 | P44: =VLOOKUP($B44,PL!$1:$1048576,MATCH(Summary!P$13,CF!$3:$3,0),FALSE) -> 0.03004978 | Q44: =VLOOKUP($B44,PL!$1:$1048576,MATCH(Summary!Q$13,CF!$3:$3,0),FALSE) -> 0.039988751 | R44: =VLOOKUP($B44,PL!$1:$1048576,MATCH(Summary!R$13,CF!$3:$3,0),FALSE) -> 0.04098838
A45: Chg WC | B45: Total EBIT Growth | D45: Change in net working capital | E45: =VLOOKUP($A45,CF!$1:$1048576,MATCH(Summary!E$13,CF!$3:$3,0),FALSE) -> 544 | F45: =VLOOKUP($A45,CF!$1:$1048576,MATCH(Summary!F$13,CF!$3:$3,0),FALSE) -> -396 | G45: =VLOOKUP($A45,CF!$1:$1048576,MATCH(Summary!G$13,CF!$3:$3,0),FALSE) -> 367 | H45: =VLOOKUP($A45,CF!$1:$1048576,MATCH(Summary!H$13,CF!$3:$3,0),FALSE) -> 86.543366 | I45: =VLOOKUP($A45,CF!$1:$1048576,MATCH(Summary!I$13,CF!$3:$3,0),FALSE) -> 118.62836 | J45: =VLOOKUP($A45,CF!$1:$1048576,MATCH(Summary!J$13,CF!$3:$3,0),FALSE) -> 126.45619 | L45: EBIT Growth | M45: =VLOOKUP($B45,PL!$1:$1048576,MATCH(Summary!M$13,CF!$3:$3,0),FALSE) -> 0.15836431 | N45: =VLOOKUP($B45,PL!$1:$1048576,MATCH(Summary!N$13,CF!$3:$3,0),FALSE) -> 0.034338896 | O45: =VLOOKUP($B45,PL!$1:$1048576,MATCH(Summary!O$13,CF!$3:$3,0),FALSE) -> -0.1455166 | P45: =VLOOKUP($B45,PL!$1:$1048576,MATCH(Summary!P$13,CF!$3:$3,0),FALSE) -> 0.10789234 | Q45: =VLOOKUP($B45,PL!$1:$1048576,MATCH(Summary!Q$13,CF!$3:$3,0),FALSE) -> 0.11233254 | R45: =VLOOKUP($B45,PL!$1:$1048576,MATCH(Summary!R$13,CF!$3:$3,0),FALSE) -> 0.10948407
A46: Other | B46: NPAT Growth | D46: Other | E46: =VLOOKUP($A46,CF!$1:$1048576,MATCH(Summary!E$13,CF!$3:$3,0),FALSE) -> -100 | F46: =VLOOKUP($A46,CF!$1:$1048576,MATCH(Summary!F$13,CF!$3:$3,0),FALSE) -> 257 | G46: =VLOOKUP($A46,CF!$1:$1048576,MATCH(Summary!G$13,CF!$3:$3,0),FALSE) -> -145 | H46: =VLOOKUP($A46,CF!$1:$1048576,MATCH(Summary!H$13,CF!$3:$3,0),FALSE) -> 0 | I46: =VLOOKUP($A46,CF!$1:$1048576,MATCH(Summary!I$13,CF!$3:$3,0),FALSE) -> 0 | J46: =VLOOKUP($A46,CF!$1:$1048576,MATCH(Summary!J$13,CF!$3:$3,0),FALSE) -> 0 | L46: NPAT Growth | M46: =VLOOKUP($B46,PL!$1:$1048576,MATCH(Summary!M$13,CF!$3:$3,0),FALSE) -> 0.13672391 | N46: =VLOOKUP($B46,PL!$1:$1048576,MATCH(Summary!N$13,CF!$3:$3,0),FALSE) -> -0.0058105752 | O46: =VLOOKUP($B46,PL!$1:$1048576,MATCH(Summary!O$13,CF!$3:$3,0),FALSE) -> -0.19053185 | P46: =VLOOKUP($B46,PL!$1:$1048576,MATCH(Summary!P$13,CF!$3:$3,0),FALSE) -> 0.14224062 | Q46: =VLOOKUP($B46,PL!$1:$1048576,MATCH(Summary!Q$13,CF!$3:$3,0),FALSE) -> 0.14417327 | R46: =VLOOKUP($B46,PL!$1:$1048576,MATCH(Summary!R$13,CF!$3:$3,0),FALSE) -> 0.1369917
...

Sheet Model
B1: Woolworths Group (WOW.AX)
B2: A$M
C3: FY17 | D3: FY18 | E3: FY19 | F3: FY20 | G3: FY21 | H3: FY22 | I3: FY23 | J3: FY24 | K3: FY25 | L3: FY26E | M3: FY27E | N3: FY28E | O3: FY29E | P3: FY30E | R3: 1H17 | S3: 2H17 | T3: 1H18 | U3: 2H18 | V3: 1H19 | W3: 2H19 | X3: 1H20 | Y3: 2H20 | Z3: 1H21 | AA3: 2H21 | AB3: 1H22 | AC3: 2H22 | AD3: 1H23 | AE3: 2H23 | AF3: 1H24 | AG3: 2H24 | AH3: 1H25 | AI3: 2H25 | AJ3: 1H26E | AK3: 2H26E
B4: Model Summary
B6: Sales
A7: Aus Food Sales | B7: Australian Food | C7: =C30 -> 35836 | D7: =D30 -> 37589 | E7: =E30 -> 39635 | F7: =F30 -> 42151 | G7: =G30 -> 43746 | H7: =H30 -> 45740 | I7: =I30 -> 48047 | J7: =J30 -> 50823 | ... P7: =P30 -> 62411.748 | R7: =R30 -> 18712.6 | S7: =S30 -> 17123.4 | T7: =T30 -> 19436 | U7: =U30 -> 18153 | V7: =V30 -> 19928 | W7: =W30 -> 19707 | X7: =X30 -> 21200 | Y7: =Y30 -> 20951 | ... AK7: =AK30 -> 25732.964
A8: Aus B2B Sales | B8: Aus B2B | G8: =G317 -> 985 | H8: =H317 -> 3684 | I8: =I317 -> 4324 | J8: =J317 -> 5594 | K8: =K317 -> 5743 | L8: =L317 -> 5944.005 | M8: =M317 -> 6241.2052 | N8: =N317 -> 6553.2655 | ... P8: =P317 -> 7224.9752 | Z8: =Z317 -> 631 | AA8: =AA317 -> 354 | AB8: =AB317 -> 1979 | AC8: =AC317 -> 1705 | AD8: =AD317 -> 2433 | AE8: =AE317 -> 1891 | AF8: =AF317 -> 2828 | AG8: =AG317 -> 2766 | ... AK8: =AK317 -> 2842.725
B9: Endeavour drinks | C9: =C340 -> 7913 | D9: =D340 -> 8271 | E9: =E340 -> 8590 | F9: =F340 -> 9275 | G9: =G340 -> 10167 | R9: =R340 -> 4319.3 | S9: =S340 -> 3593.7 | T9: =T340 -> 4513 | U9: =U340 -> 3758 | V9: =V340 -> 4560 | W9: =W340 -> 4030 | X9: =X340 -> 4775 | Y9: =Y340 -> 4500 | ... AA9: =AA340 -> 4484
A10: NZ Supermarkets Sales | B10: NZ Supermarkets | C10: =C183 -> 5843 | D10: =D183 -> 5898 | E10: =E183 -> 6291 | F10: =F183 -> 6823 | G10: =G183 -> 6652 | H10: =H183 -> 7092 | I10: =I183 -> 7240 | J10: =J183 -> 7551 | ... P10: =P183 -> 8732.5841 | R10: =R183 -> 3068.9 | S10: =S183 -> 2774.1 | T10: =T183 -> 3060 | U10: =U183 -> 2838 | V10: =V183 -> 3143 | W10: =W183 -> 3148 | X10: =X183 -> 3367 | Y10: =Y183 -> 3456 | ... AD10: =AD183 -> 3703 | AE10: =I10-AD10 -> 3537 | AF10: =AF183 -> 3858 | AG10: =AG183 -> 3693 | AH10: =AH183 -> 3895 | AI10: =AI183 -> 3662 | AJ10: =AJ183 -> 3916.7475 | AK10: =AK183 -> 3593.8149
B11: Hotels | C11: =C345 -> 1553 | D11: =D345 -> 1612 | E11: =E345 -> 1671 | F11: =F345 -> 1320 | G11: =G345 -> 1417 | R11: =R345 -> 828.5 | S11: =S345 -> 724.5 | T11: =T345 -> 861 | U11: =U345 -> 751 | V11: =V345 -> 865 | W11: =W345 -> 806 | X11: =X345 -> 919 | Y11: =Y345 -> 401 | ... AA11: =AA345 -> 750
A12: W Living Sales | B12: W Living (prior to FY24, Big W) | C12: =C207 -> 3542 | D12: =D207 -> 3566 | E12: =E207 -> 3797 | F12: =F207 -> 4106 | G12: =G207 -> 4583 | H12: =H207 -> 4431 | I12: =I207 -> 4785 | J12: =J194 -> 5220 | K12: =K194 -> 5597 | L12: =L194 -> 5630.8058 | M12: =M194 -> 5785.0025 | N12: =N194 -> 5957.6171 | O12: =O194 -> 6134.7613 | P12: =P194 -> 6316.5493 | R12: =R207 -> 2050.3 | S12: =S207 -> 1547.7 | T12: =T207 -> 2037 | U12: =U207 -> 1529 | V12: =V207 -> 2091 | W12: =W207 -> 1706 | X12: =X207 -> 2149 | Y12: =Y207 -> 1957 | ... AE12: =AE207 -> 2077 | AF12: =AF194 -> 2656 | AG12: =AG194 -> 2564 | AH12: =AH194 -> 3061 | AI12: =AI194 -> 2536 | AJ12: =AJ194 -> 3088.372 | AK12: =AK194 -> 2542.4338
A13: Others Sales | B13: Others | G13: =G332 -> -233 | H13: =H332 -> -98 | I13: =I332 -> -102 | J13: =J332 -> 226 | K13: =K332 -> 246 | L13: =L332 -> 270.6 | M13: =M332 -> 278.718 | N13: =N332 -> 287.07954 | ... P13: =P332 -> 304.56268 | Z13: =Z332 -> -130 | AA13: =AA332 -> -103 | AB13: =AB332 -> -51 | AC13: =AC332 -> -47 | AD13: =AD332 -> -60 | AE13: =AE332 -> -42 | AF13: =AF332 -> 112 | AG13: =AG332 -> 114 | ... AK13: =AK332 -> 138.6
A14: Elimination Sales | B14: Elimination/Reclass/Unallocated | C14: 154 | D14: 239 | J14: -1492 | K14: =-411-391-375-377 -> -1554 | L14: =K14*1 -> -1554 | M14: =L14*1 -> -1554 | N14: =M14*1 -> -1554 | O14: =N14*1 -> -1554 | P14: =O14*1 -> -1554 | R14: 78.9 | S14: =C14-R14 -> 75.1 | U14: =D14-T14 -> 239 | AF14: -764 | AG14: =J14-AF14 -> -728 | AH14: =-411-391 -> -802 | AI14: =K14-AH14 -> -752 | AJ14: =AH14*1 -> -802 | AK14: =M14-AJ14 -> -752
A15: Total Sales | B15: Sales from Continuing Ops. | C15: =SUM(C7:C14) -> 54841 | D15: =SUM(D7:D14) -> 57175 | E15: =SUM(E7:E14) -> 59984 | F15: =SUM(F7:F14) -> 63675 | G15: =SUM(G7:G14) -> 67317 | H15: =SUM(H7:H14) -> 60849 | I15: =SUM(I7:I14) -> 64294 | J15: =SUM(J7:J14) -> 67922 | ... P15: =SUM(P7:P14) -> 83436.419 | R15: =SUM(R7:R14) -> 29058.5 | S15: =SUM(S7:S14) -> 25838.5 | T15: =SUM(T7:T14) -> 29907 | U15: =SUM(U7:U14) -> 27268 | V15: =SUM(V7:V14) -> 30587 | W15: =SUM(W7:W14) -> 29397 | X15: =SUM(X7:X14) -> 32410 | Y15: =SUM(Y7:Y14) -> 31265 | ... AK15: =SUM(AK7:AK14) -> 34098.538
B16: Growth % | D16: =D15/C15-1 -> 0.042559399 | E16: =E15/D15-1 -> 0.049129864 | F16: =F15/E15-1 -> 0.061533075 | G16: =G15/F15-1 -> 0.057196702 | H16: =H15/G15-1 -> -0.096082713 | I16: =I15/H15-1 -> 0.056615557 | J16: =J15/I15-1 -> 0.056428283 | K16: =K15/J15-1 -> 0.0170048 | ... P16: =P15/O15-1 -> 0.040666986 | T16: =T15/R15-1 -> 0.029199718 | U16: =U15/S15-1 -> 0.055324419 | V16: =V15/T15-1 -> 0.022737152 | W16: =W15/U15-1 -> 0.078076867 | X16: =X15/V15-1 -> 0.059600484 | Y16: =Y15/W15-1 -> 0.063543899 | Z16: =Z15/X15-1 -> 0.10721999 | AA16: =AA15/Y15-1 -> 0.0053414361 | ... AK16: =AK15/AI15-1 -> 0.0287066
B18: EBIT
A19: Aus Food EBIT | B19: Australian Food | C19: =C57 -> 1603.1 | D19: =D57 -> 1757 | E19: =E57 -> 1827 | F19: =F57 -> 2232 | G19: =G57 -> 2397 | H19: =H57 -> 2406 | I19: =I57 -> 2865 | J19: =J57 -> 3150 | ... P19: =P57 -> 3932.0914 | R19: =R57 -> 811.6 | S19: =S57 -> 791.5 | T19: =T57 -> 901 | U19: =U57 -> 856 | V19: =V57 -> 933 | W19: =W57 -> 894 | X19: =X57 -> 1177 | Y19: =Y57 -> 1055 | ... AK19: =AK57 -> 1461.4692
A20: Aus B2B EBIT | B20: Aus B2B | G20: =G320 -> 28 | H20: =H320 -> 56 | I20: =I320 -> 63 | J20: =J320 -> 122 | K20: =K320 -> 137 | L20: =L320 -> 147.739 | M20: =M320 -> 161.36716 | N20: =N320 -> 169.43552 | ... P20: =P320 -> 186.80266 | Z20: =Z320 -> 9 | AA20: =AA320 -> 19 | AB20: =AB320 -> 18 | AC20: =AC320 -> 38 | AD20: =AD320 -> 38 | AE20: =AE320 -> 25 | AF20: =AF320 -> 71 | AG20: =AG320 -> 51 | ... AK20: =AK320 -> 63.517725
B21: Endeavour drinks | C21: =C342 -> 503 | D21: =D342 -> 516 | E21: =E342 -> 504 | F21: =F342 -> 569 | R21: =R342 -> 302.3 | S21: =S342 -> 200.7 | T21: =T342 -> 309 | U21: =U342 -> 207 | V21: =V342 -> 294 | W21: =W342 -> 210 | X21: =X342 -> 338 | Y21: =Y342 -> 231
A22: NZ Supermarkets EBIT | B22: NZ Supermarkets | C22: =C190 -> 292 | D22: =D190 -> 262 | E22: =E190 -> 277 | F22: =F190 -> 358 | G22: =G190 -> 336 | H22: =H190 -> 296 | I22: =I190 -> 228 | J22: =J190 -> 100 | ... P22: =P190 -> 305.64044 | R22: =R190 -> 154.9 | S22: =S190 -> 137.1 | T22: =T190 -> 139 | U22: =U190 -> 123 | V22: =V190 -> 137 | W22: =W190 -> 140 | X22: =X190 -> 175 | Y22: =Y190 -> 183 | ... AD22: =AD190 -> 111 | AE22: =I22-AD22 -> 117 | AF22: =AF190 -> 65 | AG22: =AG190 -> 35 | AH22: =AH190 -> 73 | AI22: =AI190 -> 65 | AJ22: =AJ190 -> 86.168446 | AK22: =AK190 -> 71.553365
B23: Hotels | C23: =C347 -> 232.9 | D23: =D347 -> 259 | E23: =E347 -> 261 | F23: =F347 -> 172 | R23: =R347 -> 139.3 | S23: =S347 -> 93.6 | T23: =T347 -> 163 | U23: =U347 -> 96 | V23: =V347 -> 161 | W23: =W347 -> 100 | X23: =X347 -> 224 | Y23: =Y347 -> -52
A24: W Living EBIT | B24: W Living (prior to FY24 Big W) | C24: =C233 -> -150.5 | D24: =D233 -> -110 | E24: =E233 -> -85 | F24: =F233 -> 39 | G24: =G233 -> 172 | H24: =H233 -> 55 | I24: =I233 -> 145 | J24: =J201 -> -29 | K24: =K201 -> -31 | L24: =L201 -> 49.560103 | M24: =M201 -> 61.062615 | N24: =N201 -> 65.199165 | O24: =O201 -> 69.473629 | P24: =P201 -> 73.88997 | R24: =R233 -> 8.1 | S24: =S233 -> -158.6 | T24: =T233 -> -10 | U24: =U233 -> -100 | V24: =V233 -> -8 | W24: =W233 -> -77 | X24: =X233 -> 50 | Y24: =Y233 -> -11 | ... AE24: =AE233 -> 11 | AF24: =AF201 -> 15 | AG24: =AG201 -> -44 | AH24: =AH201 -> 33 | AI24: =AI201 -> -64 | AJ24: =AJ201 -> 42.74672 | AK24: =AK201 -> 6.8133826
A25: Others EBIT | B25: Others | C25: =C337 -> -154.3 | D25: =D337 -> -136 | E25: =E337 -> -62 | F25: =F337 -> -151 | G25: =G337 -> -169 | H25: =H337 -> -123 | I25: =I337 -> -185 | J25: =J337 -> -120 | ... P25: =P337 -> -270.12211 | R25: =R337 -> -79.6 | S25: =S337 -> 0 | T25: =T337 -> -72 | U25: =U337 -> -64 | V25: =V337 -> -98 | W25: =W337 -> 36 | X25: =X337 -> -71 | Y25: =Y337 -> -80 | ... AK25: =AK337 -> -120
A26: Total EBIT | B26: EBIT from Continuing Ops | C26: =SUM(C19:C25) -> 2326.2 | D26: =SUM(D19:D25) -> 2548 | E26: =SUM(E19:E25) -> 2722 | F26: =SUM(F19:F25) -> 3219 | G26: =SUM(G19:G25) -> 2764 | H26: =SUM(H19:H25) -> 2690 | I26: =SUM(I19:I25) -> 3116 | J26: =SUM(J19:J25) -> 3223 | ... P26: =SUM(P19:P25) -> 4228.3024 | R26: =SUM(R19:R25) -> 1336.6 | S26: =SUM(S19:S25) -> 1064.3 | T26: =SUM(T19:T25) -> 1430 | U26: =SUM(U19:U25) -> 1118 | V26: =SUM(V19:V25) -> 1419 | W26: =SUM(W19:W25) -> 1303 | X26: =SUM(X19:X25) -> 1893 | Y26: =SUM(Y19:Y25) -> 1326 | ... AK26: =SUM(AK19:AK25) -> 1483.3537
B27: Growth % | D27: =D26/C26-1 -> 0.095348637 | E27: =E26/D26-1 -> 0.068288854 | F27: =F26/E26-1 -> 0.18258633 | G27: =G26/F26-1 -> -0.14134824 | H27: =H26/G26-1 -> -0.026772793 | I27: =I26/H26-1 -> 0.15836431 | J27: =J26/I26-1 -> 0.034338896 | K27: =K26/J26-1 -> -0.1455166 | ... P27: =P26/O26-1 -> 0.059057127 | T27: =T26/R26-1 -> 0.069878797 | U27: =U26/S26-1 -> 0.050455699 | V27: =V26/T26-1 -> -0.0076923077 | W27: =W26/U26-1 -> 0.16547406 | X27: =X26/V26-1 -> 0.33403805 | Y27: =Y26/W26-1 -> 0.017651573 | Z27: =Z26/X26-1 -> -0.17908082 | AA27: =AA26/Y26-1 -> -0.087481146 | ... AK27: =AK26/AI26-1 -> 0.13841417
L28: =240/K30 -> 0.0046612803
B29: Australian Food | J29: =J3 -> FY24 | K29: =K3 -> FY25 | L29: =L3 -> FY26E | M29: =M3 -> FY27E | N29: =N3 -> FY28E | O29: =O3 -> FY29E | P29: =P3 -> FY30E
B30: Sales | C30: 35836 | D30: 37589 | E30: 39635 | F30: =42151 -> 42151 | G30: 43746 | H30: 45740 | I30: 48047 | J30: 50823 | K30: =13605+13069+13060+11754 -> 51488 | L30: =K30*(1+L31) -> 53350.775 | M30: =L30*(1+M31) -> 55498.191 | N30: =M30*(1+N31) -> 57722.425 | O30: =N30*(1+O31) -> 60026.057 | P30: =O30*(1+P31) -> 62411.748 | R30: 18712.6 | S30: =C30-R30 -> 17123.4 | T30: 19436 | U30: =D30-T30 -> 18153 | V30: 19928 | W30: =E30-V30 -> 19707 | X30: 21200 | Y30: =F30-X30 -> 20951 | Z30: 22988 | AA30: =G30-Z30 -> 20758 | AB30: 23780 | AC30: =H30-AB30 -> 21960 | AD30: 24385 | AE30: =I30-AD30 -> 23662 | AF30: 25945 | AG30: =J30-AF30 -> 24878 | AH30: =13605+13069 -> 26674 | AI30: =K30-AH30 -> 24814 | AJ30: =AH30*(1+AJ31) -> 27617.811 | AK30: =L30-AJ30 -> 25732.964
A31: Aus Food Growth | B31: Growth % | D31: =D30/C30-1 -> 0.04891729 | E31: =E30/D30-1 -> 0.054430818 | F31: =F30/E30-1 -> 0.063479248 | G31: =G30/F30-1 -> 0.037840146 | H31: =H30/G30-1 -> 0.04558131 | I31: =I30/H30-1 -> 0.050437254 | J31: =J30/I30-1 -> 0.05777676 | K31: =K30/J30-1 -> 0.013084627 | L31: =SUM(L33:L35) -> 0.036178827 | M31: =SUM(M33:M35) -> 0.040250883 | N31: =SUM(N33:N35) -> 0.040077594 | O31: =SUM(O33:O35) -> 0.039908778 | P31: =SUM(P33:P35) -> 0.039744265 | T31: =T30/R30-1 -> 0.038658444 | U31: =U30/S30-1 -> 0.060128246 | V31: =V30/T30-1 -> 0.025313851 | W31: =W30/U30-1 -> 0.085605685 | X31: =X30/V30-1 -> 0.063829787 | Y31: =Y30/W30-1 -> 0.063124778 | Z31: =Z30/X30-1 -> 0.084339623 | AA31: =AA30/Y30-1 -> -0.0092119708 | ... AI31: =AI30/AG30-1 -> -0.0025725541 | AJ31: =SUM(AJ33:AJ35) -> 0.035383199 | AK31: =AK30/AI30-1 -> 0.037034094
A32: Aus Food Growth ex Tobacco | B32: Growth ex Tobacco % | H32: 0.06 | I32: 0.063 | J32: 0.047 | K32: 0.044
A33: Aus Food Comp | B33: LFL Sales Growth % | C33: 0.036 | D33: 0.043 | E33: 0.031 | F33: 0.073 | G33: 0.042 | H33: 0.035 | I33: 0.042 | J33: 0.028 | K33: 0.024 | L33: =VLOOKUP($A33,Quarterly!$1:$1048576,MATCH(Model!L$3,Quarterly!$3:$3,0),FALSE) -> 0.02975 | M33: 0.035 | N33: 0.035 | O33: 0.035 | P33: 0.035 | R33: 0.019 | T33: 0.049 | U33: =VLOOKUP($A33,Quarterly!$1:$1048576,MATCH(Model!U$3,Quarterly!$3:$3,0),FALSE) -> 0.0355 | V33: 0.023 | W33: =VLOOKUP($A33,Quarterly!$1:$1048576,MATCH(Model!W$3,Quarterly!$3:$3,0),FALSE) -> 0.039 | X33: 0.051 | Y33: =VLOOKUP($A33,Quarterly!$1:$1048576,MATCH(Model!Y$3,Quarterly!$3:$3,0),FALSE) -> 0.096 | Z33: 0.095 | AA33: =VLOOKUP($A33,Quarterly!$1:$1048576,MATCH(Model!AA$3,Quarterly!$3:$3,0),FALSE) -> -0.01 | AB33: 0.023 | AC33: =VLOOKUP($A33,Quarterly!$1:$1048576,MATCH(Model!AC$3,Quarterly!$3:$3,0),FALSE) -> 0.048 | AD33: 0.018 | AE33: =VLOOKUP($A33,Quarterly!$1:$1048576,MATCH(Model!AE$3,Quarterly!$3:$3,0),FALSE) -> 0.066 | AF33: 0.046 | AG33: =VLOOKUP($A33,Quarterly!$1:$1048576,MATCH(Model!AG$3,Quarterly!$3:$3,0),FALSE) -> 0.012 | AH33: 0.017120428 | AI33: =VLOOKUP($A33,Quarterly!$1:$1048576,MATCH(Model!AI$3,Quarterly!$3:$3,0),FALSE) -> 0.0295 | AJ33: =VLOOKUP($A33,Quarterly!$1:$1048576,MATCH(Model!AJ$3,Quarterly!$3:$3,0),FALSE) -> 0.0295 | AK33: =VLOOKUP($A33,Quarterly!$1:$1048576,MATCH(Model!AK$3,Quarterly!$3:$3,0),FALSE) -> 0.03
B34: Store Growth % | D34: =D76/C76-1 -> 0.01002004 | E34: =E76/D76-1 -> 0.015873016 | F34: =F76/E76-1 -> 0.026367188 | G34: =G76/F76-1 -> 0.02188392 | H34: =H76/G76-1 -> 0.010242086 | I34: =I76/H76-1 -> 0.0092165899 | J34: =J76/I76-1 -> 0.014611872 | K34: =K76/J76-1 -> 0.0054005401 | ... P34: =P76/O76-1 -> 0.012744265 | T34: =T76/R76-1 -> 0.012048193 | U34: =U76/S76-1 -> 0.010050251 | V34: =V76/T76-1 -> 0.0099206349 | W34: =W76/U76-1 -> 0.018905473 | X34: =X76/V76-1 -> 0.020628684 | Y34: =Y76/W76-1 -> 0.02734375 | Z34: =Z76/X76-1 -> 0.024061598 | AA34: =AA76/Y76-1 -> 0.019961977 | ... AK34: =AK76/AI76-1 -> 0.013428827
B35: Other | D35: =D31-SUM(D33:D34) -> -0.0041027502 | E35: =E31-SUM(E33:E34) -> 0.0075578017 | F35: =F31-SUM(F33:F34) -> -0.035887939 | G35: =G31-SUM(G33:G34) -> -0.026043774 | H35: =H31-SUM(H33:H34) -> 0.00033922463 | I35: =I31-SUM(I33:I34) -> -0.00077933582 | J35: =J31-SUM(J33:J34) -> 0.015164888 | K35: =K31-SUM(K33:K34) -> -0.016315913 | L35: -0.007 | M35: -0.008 | N35: -0.008 | O35: -0.008 | P35: -0.008 | T35: =T31-SUM(T33:T34) -> -0.022389749 | U35: =U31-SUM(U33:U34) -> 0.014577994 | V35: =V31-SUM(V33:V34) -> -0.0076067843 | W35: =W31-SUM(W33:W34) -> 0.027700212 | X35: =X31-SUM(X33:X34) -> -0.0077988965 | Y35: =Y31-SUM(Y33:Y34) -> -0.060218972 | Z35: =Z31-SUM(Z33:Z34) -> -0.034721975 | AA35: =AA31-SUM(AA33:AA34) -> -0.019173948 | ... AI35: =AI31-SUM(AI33:AI34) -> -0.037473094 | AJ35: -0.004 | AK35: =AK31-SUM(AK33:AK34) -> -0.0063947329
A37: Aus Food GP | B37: Gross Profit | C37: =C39*C30 -> 10059.165 | D37: =D39*D30 -> 10938.399 | E37: =E39*E30 -> 11375.245 | F37: =F39*F30 -> 12308.092 | G37: =G39*G30 -> 11723.928 | H37: =H39*H30 -> 12532.76 | I37: =I39*I30 -> 13501.207 | J37: =J39*J30 -> 14687.847 | ... P37: =P39*P30 -> 17912.172 | R37: =R39*R30 -> 5217.0729 | S37: =C37-R37 -> 4842.0923 | T37: =T39*T30 -> 5597.568 | U37: =D37-T37 -> 5340.831 | V37: =V39*V30 -> 5719.336 | W37: =E37-V37 -> 5655.909 | X37: =X39*X30 -> 6169.2 | Y37: =F37-X37 -> 6138.892 | Z37: =Z39*Z30 -> 6114.808 | AA37: =G37-Z37 -> 5609.12 | AB37: =AB39*AB30 -> 6468.16 | AC37: =H37-AB37 -> 6064.6 | AD37: =AD39*AD30 -> 6803.415 | AE37: =I37-AD37 -> 6697.792 | AF37: =AF39*AF30 -> 7498.105 | AG37: =J37-AF37 -> 7189.742 | AH37: =AH39*AH30 -> 7628.764 | AI37: =K37-AH37 -> 7096.804 | AJ37: =AJ39*AJ30 -> 7898.6941 | AK37: =L37-AJ37 -> 7359.6277
B38: Growth % | D38: =D37/C37-1 -> 0.087406239 | E38: =E37/D37-1 -> 0.039936923 | F38: =F37/E37-1 -> 0.082006761 | G38: =G37/F37-1 -> -0.047461784 | H38: =H37/G37-1 -> 0.068989847 | I38: =I37/H37-1 -> 0.077273242 | J38: =J37/I37-1 -> 0.087891401 | K38: =K37/J37-1 -> 0.0025681776 | ... P38: =P37/O37-1 -> 0.039744265 | T38: =T37/R37-1 -> 0.072932683 | U38: =U37/S37-1 -> 0.10300065 | V38: =V37/T37-1 -> 0.021753733 | W38: =W37/U37-1 -> 0.05899419 | X38: =X37/V37-1 -> 0.078656683 | Y38: =Y37/W37-1 -> 0.085394408 | Z38: =Z37/X37-1 -> -0.0088167023 | AA38: =AA37/Y37-1 -> -0.086297658 | ... AI38: =AI37/AG37-1 -> -0.012926472 | AJ38: =AJ37/AI37-1 -> 0.11299313 | AK38: =AK37/AI37-1 -> 0.037034094
A39: Aus Food GPM | B39: Gross Margin | C39: 0.2807 | D39: 0.291 | E39: 0.287 | F39: 0.292 | G39: 0.268 | H39: 0.274 | I39: 0.281 | J39: 0.289 | K39: 0.286 | L39: =K39+L40 -> 0.286 | M39: =L39+M40 -> 0.286 | N39: =M39+N40 -> 0.287 | O39: =N39+O40 -> 0.287 | P39: =O39+P40 -> 0.287 | R39: 0.2788 | S39: =S37/S30 -> 0.28277634 | T39: 0.288 | U39: =U37/U30 -> 0.29421203 | V39: 0.287 | W39: =W37/W30 -> 0.287 | X39: 0.291 | Y39: =Y37/Y30 -> 0.29301188 | Z39: 0.266 | AA39: =AA37/AA30 -> 0.27021486 | AB39: 0.272 | AC39: =AC37/AC30 -> 0.27616576 | AD39: 0.279 | AE39: =AE37/AE30 -> 0.28306111 | AF39: 0.289 | AG39: =AG37/AG30 -> 0.289 | AH39: 0.286 | AI39: =AI37/AI30 -> 0.286 | AJ39: =AH39+AJ40 -> 0.286 | AK39: =AK37/AK30 -> 0.286
B40: Change YoY % | C40: 0.007 | D40: 0.0063 | E40: -0.0024 | F40: 0.0047 | G40: 0.0021 | H40: 0.0074 | I40: 0.0076 | J40: 0.0076 | K40: -0.0025 | L40: 0 | M40: 0 | N40: 0.001 | O40: 0 | P40: 0 | R40: =50&" bp" -> 50 bp | T40: 0.0055 | U40: =U39-S39 -> 0.011435695 | V40: 0.0002 | W40: =W39-U39 -> -0.0072120311 | X40: 0.0038 | Y40: =Y39-W39 -> 0.0060118849 | Z40: 0.0011 | AA40: =AA39-Y39 -> -0.022797028 | AB40: 0.0079 | AC40: =AC39-AA39 -> 0.005950899 | AD40: 0.0048 | AE40: =AE39-AC39 -> 0.0068953547 | AF40: 0.0096 | AG40: =AG39-AE39 -> 0.0059388894 | AH40: -0.0032 | AI40: =AI39-AG39 -> -0.003 | AJ40: 0 | AK40: =AK39-AI39 -> 0
L41: =100/L30 -> 0.001874387
B42: CODB | G42: =G47-G37 -> -7783.928 | H42: =H47-H37 -> -8488.76 | I42: =I47-I37 -> -8850.207 | J42: =J47-J37 -> -9642.847 | K42: =K47-K37 -> -9959.568 | L42: =K42*(1+L43) -> -10208.557 | M42: =L42*(1+M43) -> -10412.728 | N42: =M42*(1+N43) -> -10652.221 | O42: =N42*(1+O43) -> -11025.049 | P42: =O42*(1+P43) -> -11410.926 | R42: =R47-R37 -> -4169.0729 | S42: =S47-S37 -> -3668.9923 | T42: =T47-T37 -> -4355.568 | U42: =U47-U37 -> -4152.831 | V42: =V47-V37 -> -4406.336 | W42: =W47-W37 -> -4385.909 | X42: =X47-X37 -> -4240.2 | Y42: =Y47-Y37 -> -4360.892 | ... AI42: =AI47-AI37 -> -4747.804 | AJ42: =AH42*(1+AJ43) -> -5346.7487 | AK42: =L42-AJ42 -> -4861.8085
B43: Growth % | H43: =H42/G42-1 -> 0.090549656 | I43: =I42/H42-1 -> 0.042579482 | J43: =J42/I42-1 -> 0.089561747 | K43: =K42/J42-1 -> 0.032845175 | L43: 0.025 | M43: 0.02 | N43: 0.023 | O43: 0.035 | P43: 0.035 | T43: =T42/R42-1 -> 0.044732996 | U43: =U42/S42-1 -> 0.13187236 | V43: =V42/T42-1 -> 0.011655885 | W43: =W42/U42-1 -> 0.056125087 | X43: =X42/V42-1 -> -0.037703888 | Y43: =Y42/W42-1 -> -0.0057039487 | Z43: =Z42/X42-1 -> -0.050561766 | AA43: =AA42/Y42-1 -> -0.13822218 | ... AI43: =AI42/AG42-1 -> 0.010011611 | AJ43: 0.0259 | AK43: =AK42/AI42-1 -> 0.024012051
...

Sheet PL
B1: Woolworths Group (WOW.AX)
B2: A$M
C3: =Model!C3 -> FY17 | D3: =Model!D3 -> FY18 | E3: =Model!E3 -> FY19 | F3: =Model!F3 -> FY20 | G3: =Model!G3 -> FY21 | H3: =Model!H3 -> FY22 | I3: =Model!I3 -> FY23 | J3: =Model!J3 -> FY24 | K3: =Model!K3 -> FY25 | L3: FY26E | M3: FY27E | N3: FY28E | O3: FY29E | P3: FY30E | R3: =Model!R3 -> 1H17 | S3: =Model!S3 -> 2H17 | T3: =Model!T3 -> 1H18 | U3: =Model!U3 -> 2H18 | V3: =Model!V3 -> 1H19 | W3: =Model!W3 -> 2H19 | X3: =Model!X3 -> 1H20 | Y3: =Model!Y3 -> 2H20 | ... AI3: =Model!AI3 -> 2H25 | AJ3: 1H26E | AK3: 2H26E
B4: P&L
A5: Total Sales | B5: Sales | C5: =VLOOKUP($A$5,Model!1:1048576,MATCH(PL!C3,Model!3:3,0),FALSE) -> 54841 | D5: =VLOOKUP($A$5,Model!1:1048576,MATCH(PL!D3,Model!3:3,0),FALSE) -> 57175 | E5: =VLOOKUP($A$5,Model!1:1048576,MATCH(PL!E3,Model!3:3,0),FALSE) -> 59984 | F5: =VLOOKUP($A$5,Model!1:1048576,MATCH(PL!F3,Model!3:3,0),FALSE) -> 63675 | G5: =VLOOKUP($A$5,Model!1:1048576,MATCH(PL!G3,Model!3:3,0),FALSE) -> 67317 | H5: =VLOOKUP($A$5,Model!1:1048576,MATCH(PL!H3,Model!3:3,0),FALSE) -> 60849 | I5: =VLOOKUP($A$5,Model!1:1048576,MATCH(PL!I3,Model!3:3,0),FALSE) -> 64294 | J5: =VLOOKUP($A$5,Model!1:1048576,MATCH(PL!J3,Model!3:3,0),FALSE) -> 67922 | ... P5: =VLOOKUP($A$5,Model!1:1048576,MATCH(PL!P3,Model!3:3,0),FALSE) -> 83436.419 | R5: =VLOOKUP($A$5,Model!1:1048576,MATCH(PL!R3,Model!3:3,0),FALSE) -> 29058.5 | S5: =VLOOKUP($A$5,Model!1:1048576,MATCH(PL!S3,Model!3:3,0),FALSE) -> 25838.5 | T5: =VLOOKUP($A$5,Model!1:1048576,MATCH(PL!T3,Model!3:3,0),FALSE) -> 29907 | U5: =VLOOKUP($A$5,Model!1:1048576,MATCH(PL!U3,Model!3:3,0),FALSE) -> 27268 | V5: =VLOOKUP($A$5,Model!1:1048576,MATCH(PL!V3,Model!3:3,0),FALSE) -> 30587 | W5: =VLOOKUP($A$5,Model!1:1048576,MATCH(PL!W3,Model!3:3,0),FALSE) -> 29397 | X5: =VLOOKUP($A$5,Model!1:1048576,MATCH(PL!X3,Model!3:3,0),FALSE) -> 32410 | Y5: =VLOOKUP($A$5,Model!1:1048576,MATCH(PL!Y3,Model!3:3,0),FALSE) -> 31265 | ... AK5: =VLOOKUP($A$5,Model!1:1048576,MATCH(PL!AK3,Model!3:3,0),FALSE) -> 34098.538
A6: Total Sales Growth | B6: Growth % | D6: =D5/C5-1 -> 0.042559399 | E6: =E5/D5-1 -> 0.049129864 | F6: =F5/E5-1 -> 0.061533075 | G6: =G5/F5-1 -> 0.057196702 | H6: =H5/G5-1 -> -0.096082713 | I6: =I5/H5-1 -> 0.056615557 | J6: =J5/I5-1 -> 0.056428283 | K6: =K5/J5-1 -> 0.0170048 | ... P6: =P5/O5-1 -> 0.040666986 | T6: =T5/R5-1 -> 0.029199718 | U6: =U5/S5-1 -> 0.055324419 | V6: =V5/T5-1 -> 0.022737152 | W6: =W5/U5-1 -> 0.078076867 | X6: =X5/V5-1 -> 0.059600484 | Y6: =Y5/W5-1 -> 0.063543899 | Z6: =Z5/X5-1 -> 0.10721999 | AA6: =AA5/Y5-1 -> 0.0053414361 | ... AK6: =AK5/AI5-1 -> 0.0287066
B8: Cost of Goods Sold | C8: =C9-C5 -> -38912.1 | D8: =D9-D5 -> -40466 | E8: =E9-E5 -> -42542 | F8: =F9-F5 -> -45105 | G8: =G9-G5 -> -49276.044 | H8: =H9-H5 -> -44906.562 | I8: -47118 | J8: -49370 | K8: -50262 | L8: =L9-L5 -> -52761.259 | M8: =M9-M5 -> -54862.321 | N8: =N9-N5 -> -57050.224 | O8: =O9-O5 -> -59376.258 | P8: =P9-P5 -> -61787.904 | R8: -20660.593 | S8: =C8-R8 -> -18251.506 | T8: =T9-T5 -> -21186 | U8: =U9-U5 -> -19280 | V8: =V9-V5 -> -21682 | W8: =W9-W5 -> -20860 | X8: =X9-X5 -> -22825 | Y8: =Y9-Y5 -> -22280 | Z8: =Z9-Z5 -> -26339.59 | AA8: =G8-Z8 -> -22936.454 | AB8: =AB9-AB5 -> -22491 | AC8: =H8-AB8 -> -22415.562 | AD8: =AD9-AD5 -> -23288 | AE8: =AE9-AE5 -> -23802 | AF8: -25154 | AG8: =AG9-AG5 -> -24216 | AH8: -26154 | AI8: =AI9-AI5 -> -24108 | AJ8: =AJ9-AJ5 -> -27473.263 | AK8: =L8-AJ8 -> -25287.995
A9: Gross Profit | B9: Gross Profit Reported | C9: 15928.9 | D9: 16709 | E9: 17442 | F9: 18570 | G9: =G5*G10 -> 18040.956 | H9: =H5*H10 -> 15942.438 | I9: 17204 | J9: 18552 | K9: 18815 | L9: =Model!L37+Model!L123/Model!L181+Model!L213 -> 18391.49 | M9: =Model!M37+Model!M123/Model!M181+Model!M213 -> 19135.737 | N9: =Model!N37+Model!N123/Model!N181+Model!N213 -> 19980.894 | O9: =Model!O37+Model!O123/Model!O181+Model!O213 -> 20799.649 | P9: =Model!P37+Model!P123/Model!P181+Model!P213 -> 21648.515 | R9: 8397.9065 | S9: =C9-R9 -> 7530.9935 | T9: 8721 | U9: =D9-T9 -> 7988 | V9: 8905 | W9: =E9-V9 -> 8537 | X9: 9585 | Y9: =F9-X9 -> 8985 | Z9: =Z5*Z10 -> 9545.41 | AA9: =G9-Z9 -> 8495.546 | AB9: 9403 | AC9: =H9-AB9 -> 6539.438 | AD9: 9881 | AE9: =I9-AD9 -> 7323 | AF9: =AF5+AF8 -> 9481 | AG9: =J9-AF9 -> 9071 | AH9: =AH5+AH8 -> 9776 | AI9: =K9-AH9 -> 9039 | AJ9: =Model!AJ37+Model!AJ123/Model!AJ181+Model!AJ213 -> 9580.9476 | AK9: =L9-AJ9 -> 8810.5423
B10: Gross Margin | C10: =C9/C5 -> 0.29045605 | D10: =D9/D5 -> 0.29224311 | E10: =E9/E5 -> 0.29077754 | F10: =F9/F5 -> 0.29163722 | G10: 0.268 | H10: 0.262 | I10: =I9/I5 -> 0.26758329 | J10: =J9/J5 -> 0.27313683 | K10: =K9/K5 -> 0.2723772 | T10: =T9/T5 -> 0.29160397 | U10: =U9/U5 -> 0.29294411 | V10: =V9/V5 -> 0.29113676 | W10: =W9/W5 -> 0.29040378 | X10: =X9/X5 -> 0.29574205 | Y10: =Y9/Y5 -> 0.28738206 | Z10: 0.266 | AA10: =AA9/AA5 -> 0.27028334 | AB10: =AB9/AB5 -> 0.29482034 | AC10: =AC9/AC5 -> 0.22584832 | AD10: =AD9/AD5 -> 0.29789864 | AE10: =AE9/AE5 -> 0.23527711 | AF10: =AF9/AF5 -> 0.27374044 | AG10: =AG9/AG5 -> 0.27250879 | AH10: =AH9/AH5 -> 0.27208461 | AI10: =AI9/AI5 -> 0.27269436
B11: Change YoY % | D11: =D10-C10 -> 0.0017870676 | E11: =E10-D10 -> -0.0014655726 | F11: =F10-E10 -> 0.00085967958 | G11: =G10-F10 -> -0.02363722 | H11: =H10-G10 -> -0.006 | I11: =I10-H10 -> 0.0055832893 | J11: =J10-I10 -> 0.0055535442 | K11: =K10-J10 -> -0.00075963117 | V11: =V10-T10 -> -0.00046721487 | W11: =W10-U10 -> -0.0025403276 | X11: =X10-V10 -> 0.0046052975 | Y11: =Y10-W10 -> -0.0030217261 | Z11: =Z10-X10 -> -0.029742055 | AA11: =AA10-Y10 -> -0.017098715 | AB11: =AB10-Z10 -> 0.028820342 | AC11: =AC10-AA10 -> -0.044435025 | ... AI11: =AI10-AG10 -> 0.00018557427
B13: Branch & Administration Expenses
B14: Employee Expenses | H14: 8557 | I14: 8762 | J14: 9519 | K14: 9993 | AD14: 5144 | AE14: =I14-AD14 -> 3618 | AF14: 4811 | AG14: =J14-AF14 -> 4708 | AH14: 5181 | AI14: =K14-AH14 -> 4812
B15: D&A | H15: 2132 | I15: 2309 | J15: 2452 | K15: 2574 | AD15: 1287 | AE15: =I15-AD15 -> 1022 | AF15: 1233 | AG15: =J15-AF15 -> 1219 | AH15: 1317 | AI15: =K15-AH15 -> 1257
B16: Occupancy Expenses | H16: 624 | I16: 611 | J16: 706 | K16: 750 | AD16: 321 | AE16: =I16-AD16 -> 290 | AF16: 367 | AG16: =J16-AF16 -> 339 | AH16: 385 | AI16: =K16-AH16 -> 365
B17: Contract Labour & Consultancy | H17: 745 | I17: 832 | J17: 825 | K17: 759 | AD17: 733 | AE17: =I17-AD17 -> 99 | AF17: 437 | AG17: =J17-AF17 -> 388 | AH17: 408 | AI17: =K17-AH17 -> 351
B18: Other | H18: =H19-SUM(H14:H17) -> 1519 | I18: =I19-SUM(I14:I17) -> 1940 | J18: =J19-SUM(J14:J17) -> 3744 | K18: =K19-SUM(K14:K17) -> 2827 | AD18: =AD19-SUM(AD14:AD17) -> 960 | AE18: =I18-AD18 -> 980 | AF18: =AF19-SUM(AF14:AF17) -> 2809 | AG18: =J18-AF18 -> 935 | AH18: =AH19-SUM(AH14:AH17) -> 1169 | AI18: =K18-AH18 -> 1658
B19: Total | H19: 13577 | I19: 14454 | J19: 17246 | K19: 16903 | AD19: 8445 | AE19: =I19-AD19 -> 6009 | AF19: 9657 | AG19: =J19-AF19 -> 7589 | AH19: 8460 | AI19: =K19-AH19 -> 8443
