Workbook

Sheet Value
B2: Valuation | C2: XYZ
I3: DDM | J3: Units
C4: Current Price (ASX)= | D4: =G4 -> 96.82 | F4: XYZ.AX | G4: 96.82 | I4: Risk Free Rate | J4: % | K4: 0.04
C5: Shares Outstanding = | D5: #VALUE! | F5: XYZ.N | G5: 62.75 | I5: Beta | J5: x | K5: 1.2
C6: AS51 Index | I6: Market Premium | J6: % | K6: 0.06
C7: TARGET Relative Forward PE | I7: Ke | J7: % | K7: =K4+K5*K6 -> 0.112
C8: TARGET Forward PE | I8: ROE | J8: % p.a. | K8: 0.3
C9: PE Price Target = | I9: LT Payout Ratio | J9: % p.a. | K9: 0.8
I10: LT growth rate | J10: % p.a. | K10: =(1-K9)*K8 -> 0.06
J11: Dividend Discount Model (Common shares, USD/sh) | K11: =Annual!D249 -> 116.18855 | L11: =K11/G5-1 -> 0.85161029
J12: Dividend Discount Model (Common shares, AUD/sh) | K12: =K11*G4/G5 -> 179.27291 | L12: =K12/G4-1 -> 0.85161029 | M12: =K11/K12 -> 0.64810989
B14: Notes | C14: Units
B15: Actual Values | C15: 1000 | D15: (hard coded)
B16: Formula | C16: 1000
B17: Manual entry (assumption) | C17: 1000 | D17: (usually from guidance given by management)
C19: Actual ---> | E19: Forecast ----->
C20: 2023 | D20: 2024 | E20: 2025 | F20: 2026 | G20: 2027 | J20: Actual ---> | L20: Forecast -----> | Q20: Actual ---> | S20: Forecast ----->
B21: PE | J21: 2023 | K21: 2024 | L21: 2025 | M21: 2026 | N21: 2027 | Q21: 2023 | R21: 2024 | S21: 2025 | T21: 2026 | U21: 2027
B22: Consensus | I22: NPAT(USDm) | P22: EBITDA (USDm)
B23: Blackwattle | C23: =$G$5/C29 -> 34.185223 | D23: =$G$5/D29 -> 18.653824 | E23: =$G$5/E29 -> 26.792326 | F23: =$G$5/F29 -> 18.679391 | G23: =$G$5/G29 -> 14.326722 | I23: Consensus | P23: Consensus
B24: Difference | H24: Adjusted NPAT (non-GAAP, pre-NCI) | I24: Blackwattle | J24: =INDEX(Annual!$A:$AA,MATCH($H24,Annual!$A:$A,0),MATCH(Value!J$21,Annual!$A$1:$AA$1,0))/1000 -> 1127.088 | K24: =INDEX(Annual!$A:$AA,MATCH($H24,Annual!$A:$A,0),MATCH(Value!K$21,Annual!$A$1:$AA$1,0))/1000 -> 2140.766 | L24: =INDEX(Annual!$A:$AA,MATCH($H24,Annual!$A:$A,0),MATCH(Value!L$21,Annual!$A$1:$AA$1,0))/1000 -> 1496.7819 | M24: =INDEX(Annual!$A:$AA,MATCH($H24,Annual!$A:$A,0),MATCH(Value!M$21,Annual!$A$1:$AA$1,0))/1000 -> 2146.8724 | N24: =INDEX(Annual!$A:$AA,MATCH($H24,Annual!$A:$A,0),MATCH(Value!N$21,Annual!$A$1:$AA$1,0))/1000 -> 2772.9032 | O24: UEBITDA-Adjusted EBITDA (Non-GAAP, as guided to) | P24: Blackwattle | Q24: =INDEX(Annual!$A:$AA,MATCH(Value!$O24,Annual!$A:$A,0),MATCH(Value!Q$21,Annual!$A$1:$AA$1,0))/1000 -> 1792.42 | R24: =INDEX(Annual!$A:$AA,MATCH(Value!$O24,Annual!$A:$A,0),MATCH(Value!R$21,Annual!$A$1:$AA$1,0))/1000 -> 3029.031 | S24: =INDEX(Annual!$A:$AA,MATCH(Value!$O24,Annual!$A:$A,0),MATCH(Value!S$21,Annual!$A$1:$AA$1,0))/1000 -> 3492.6452 | T24: =INDEX(Annual!$A:$AA,MATCH(Value!$O24,Annual!$A:$A,0),MATCH(Value!T$21,Annual!$A$1:$AA$1,0))/1000 -> 4660.1531 | U24: =INDEX(Annual!$A:$AA,MATCH(Value!$O24,Annual!$A:$A,0),MATCH(Value!U$21,Annual!$A$1:$AA$1,0))/1000 -> 5742.0905
I25: Difference | P25: Difference
B26: EPS (UScps)
A27: YE Basic Shares Outstanding | B27: Shares Outstanding | C27: =INDEX(Annual!$A:$AA,MATCH($A27,Annual!$A:$A,0),MATCH(C$20,Annual!$A$1:$AA$1,0)) -> 615.82 | D27: =INDEX(Annual!$A:$AA,MATCH($A27,Annual!$A:$A,0),MATCH(D$20,Annual!$A$1:$AA$1,0)) -> 619.68 | E27: =INDEX(Annual!$A:$AA,MATCH($A27,Annual!$A:$A,0),MATCH(E$20,Annual!$A$1:$AA$1,0)) -> 619.68 | F27: =INDEX(Annual!$A:$AA,MATCH($A27,Annual!$A:$A,0),MATCH(F$20,Annual!$A$1:$AA$1,0)) -> 619.68 | G27: =INDEX(Annual!$A:$AA,MATCH($A27,Annual!$A:$A,0),MATCH(G$20,Annual!$A$1:$AA$1,0)) -> 607.70686 | I27: Gross Profit | P27: Revenue (USDm)
B28: Consensus | H28: Gross profit/(loss) | I28: Consensus | O28: Visible Alpha | P28: Consensus
A29: EPS | B29: Blackwattle | C29: =INDEX(Annual!$A:$AA,MATCH($A29,Annual!$A:$A,0),MATCH(C$20,Annual!$A$1:$AA$1,0)) -> 1.8355884 | D29: =INDEX(Annual!$A:$AA,MATCH($A29,Annual!$A:$A,0),MATCH(D$20,Annual!$A$1:$AA$1,0)) -> 3.3639215 | E29: =INDEX(Annual!$A:$AA,MATCH($A29,Annual!$A:$A,0),MATCH(E$20,Annual!$A$1:$AA$1,0)) -> 2.3420885 | F29: =INDEX(Annual!$A:$AA,MATCH($A29,Annual!$A:$A,0),MATCH(F$20,Annual!$A$1:$AA$1,0)) -> 3.3593171 | G29: =INDEX(Annual!$A:$AA,MATCH($A29,Annual!$A:$A,0),MATCH(G$20,Annual!$A$1:$AA$1,0)) -> 4.3799274 | H29: GP-Total Gross Profit | I29: Blackwattle | J29: =INDEX(Annual!$A:$AA,MATCH($H29,Annual!$A:$A,0),MATCH(Value!J$21,Annual!$A$1:$AA$1,0))/1000 -> 7504.886 | K29: =INDEX(Annual!$A:$AA,MATCH($H29,Annual!$A:$A,0),MATCH(Value!K$21,Annual!$A$1:$AA$1,0))/1000 -> 8889.036 | L29: =INDEX(Annual!$A:$AA,MATCH($H29,Annual!$A:$A,0),MATCH(Value!L$21,Annual!$A$1:$AA$1,0))/1000 -> 10321.979 | M29: =INDEX(Annual!$A:$AA,MATCH($H29,Annual!$A:$A,0),MATCH(Value!M$21,Annual!$A$1:$AA$1,0))/1000 -> 12472.487 | N29: =INDEX(Annual!$A:$AA,MATCH($H29,Annual!$A:$A,0),MATCH(Value!N$21,Annual!$A$1:$AA$1,0))/1000 -> 14624.993 | O29: RevTotal Revenue | P29: Blackwattle | Q29: =INDEX(Annual!$A:$AA,MATCH(Value!$O29,Annual!$A:$A,0),MATCH(Value!Q$21,Annual!$A$1:$AA$1,0))/1000 -> 21915.623 | R29: =INDEX(Annual!$A:$AA,MATCH(Value!$O29,Annual!$A:$A,0),MATCH(Value!R$21,Annual!$A$1:$AA$1,0))/1000 -> 24121.053 | S29: =INDEX(Annual!$A:$AA,MATCH(Value!$O29,Annual!$A:$A,0),MATCH(Value!S$21,Annual!$A$1:$AA$1,0))/1000 -> 23989.907 | T29: =INDEX(Annual!$A:$AA,MATCH(Value!$O29,Annual!$A:$A,0),MATCH(Value!T$21,Annual!$A$1:$AA$1,0))/1000 -> 27383.528 | U29: =INDEX(Annual!$A:$AA,MATCH(Value!$O29,Annual!$A:$A,0),MATCH(Value!U$21,Annual!$A$1:$AA$1,0))/1000 -> 31112.66
B30: Difference | I30: Difference | P30: Difference
B32: DPS (UScps) | I32: Adj Operating Income (USDm) | J32: FY-2023 | K32: FY-2024 | L32: FY-2025E | M32: FY-2026E | N32: FY-2027E | O32: Visible Alpha | P32: EV / EBITDA
B33: Consensus | H33: Operating income/(loss), Operating | I33: Consensus | O33: Net debt | P33: Consensus
A34: Dividends | B34: Blackwattle | C34: =INDEX(Annual!$A:$AA,MATCH($A34,Annual!$A:$A,0),MATCH(C$20,Annual!$A$1:$AA$1,0)) -> 0 | D34: =INDEX(Annual!$A:$AA,MATCH($A34,Annual!$A:$A,0),MATCH(D$20,Annual!$A$1:$AA$1,0)) -> 0 | E34: =INDEX(Annual!$A:$AA,MATCH($A34,Annual!$A:$A,0),MATCH(E$20,Annual!$A$1:$AA$1,0)) -> 0 | F34: =INDEX(Annual!$A:$AA,MATCH($A34,Annual!$A:$A,0),MATCH(F$20,Annual!$A$1:$AA$1,0)) -> 0 | G34: =INDEX(Annual!$A:$AA,MATCH($A34,Annual!$A:$A,0),MATCH(G$20,Annual!$A$1:$AA$1,0)) -> 0 | H34: EBITAdjusted Operating Income, EBITA (non-GAAP, as guided to) | I34: Blackwattle | J34: =INDEX(Annual!$A:$AA,MATCH($H34,Annual!$A:$A,0),MATCH(Value!J$21,Annual!$A$1:$AA$1,0))/1000 -> 351.351 | K34: =INDEX(Annual!$A:$AA,MATCH($H34,Annual!$A:$A,0),MATCH(Value!K$21,Annual!$A$1:$AA$1,0))/1000 -> 1608.79 | L34: =INDEX(Annual!$A:$AA,MATCH($H34,Annual!$A:$A,0),MATCH(Value!L$21,Annual!$A$1:$AA$1,0))/1000 -> 2101.7236 | M34: =INDEX(Annual!$A:$AA,MATCH($H34,Annual!$A:$A,0),MATCH(Value!M$21,Annual!$A$1:$AA$1,0))/1000 -> 3048.705 | N34: =INDEX(Annual!$A:$AA,MATCH($H34,Annual!$A:$A,0),MATCH(Value!N$21,Annual!$A$1:$AA$1,0))/1000 -> 3888.2195 | O34: Net debt | P34: Blackwattle | Q34: =(INDEX(Annual!$A:$AA,MATCH(Value!$O34,Annual!$A:$A,0),MATCH(Value!Q$21,Annual!$A$1:$AA$1,0))/1000+C27*$G$5)/Q24 -> 20.594743 | R34: =(INDEX(Annual!$A:$AA,MATCH(Value!$O34,Annual!$A:$A,0),MATCH(Value!R$21,Annual!$A$1:$AA$1,0))/1000+D27*$G$5)/R24 -> 11.723943 | S34: =(INDEX(Annual!$A:$AA,MATCH(Value!$O34,Annual!$A:$A,0),MATCH(Value!S$21,Annual!$A$1:$AA$1,0))/1000+E27*$G$5)/S24 -> 9.7708398 | T34: =(INDEX(Annual!$A:$AA,MATCH(Value!$O34,Annual!$A:$A,0),MATCH(Value!T$21,Annual!$A$1:$AA$1,0))/1000+F27*$G$5)/T24 -> 7.1964628 | U34: =(INDEX(Annual!$A:$AA,MATCH(Value!$O34,Annual!$A:$A,0),MATCH(Value!U$21,Annual!$A$1:$AA$1,0))/1000+G27*$G$5)/U24 -> 5.7067189
B35: Dividend Yield | I35: Difference | P35: Difference
J38: PE | L38: EV/EBITDA | N38: EV/Sales | O38: EBITDA Growth | P38: EBITDA margin | Q38: EBITDA margin | R38: Revenue Growth | S38: EBIT margin | T38: Rule of 40 | U38: Market Cap | V38: Dividend Yield | W38: Stock
J39: FY1 | K39: FY2 | L39: FY1 | M39: FY2 | N39: NTM | O39: FY0-3 CAGR | P39: FY1 | Q39: FY3 | R39: FY0-3 CAGR | S39: FY3 | T39: FY3 | U39: AUDm | V39: NTM | W39: Code
I40: Block Inc | J40: 27.9x | K40: 19.9x | L40: 12.5x | M40: 10.2x | N40: 1.6x | O40: 0.203 | P40: #VALUE! | Q40: #VALUE! | R40: #VALUE! | S40: #VALUE! | T40: #VALUE! | U40: 66828 | V40: 0 | W40: XYZ
I41: Zip Co Ltd | J41: 58.9x | K41: 38.4x | L41: 39.8x | M41: 29.7x | N41: 5.9x | O41: 0.431 | P41: #VALUE! | Q41: #VALUE! | R41: #VALUE! | S41: #VALUE! | T41: #VALUE! | U41: 5835 | V41: 0 | W41: ZIP.AX
I43: US fintech neobanks
I44: Chime Financial Inc | J44: NULL | K44: NULL | L44: 93.9x | M44: 30.8x | N44: 3.1x | O44: #VALUE! | P44: #VALUE! | Q44: #VALUE! | R44: #VALUE! | S44: #VALUE! | T44: #VALUE! | U44: 13198 | V44: 0 | W44: CHYM.O
I45: SoFi Technologies Inc | J45: 85.0x | K45: 48.3x | L45: 34.4x | M45: 23.7x | N45: 8.3x | O45: 0.411 | P45: #VALUE! | Q45: #VALUE! | R45: #VALUE! | S45: #VALUE! | T45: #VALUE! | U45: 47406 | V45: 0 | W45: SOFI.O
I46: eToro Group Ltd | J46: 19.9x | K46: 18.1x | L46: 2.9x | M46: 2.6x | N46: 1.0x | O46: #VALUE! | P46: #VALUE! | Q46: #VALUE! | R46: #VALUE! | S46: #VALUE! | T46: #VALUE! | U46: 3017 | V46: 0 | W46: ETOR.O
I47: Robinhood Markets Inc | J47: 69.5x | K47: 55.0x | L47: 44.2x | M47: 34.6x | N47: 21.1x | O47: 0.341 | P47: #VALUE! | Q47: #VALUE! | R47: #VALUE! | S47: #VALUE! | T47: #VALUE! | U47: 153790 | V47: 0 | W47: HOOD.O
...

Sheet Annual
B1: XYZ Model Summary | E1: 2014 | F1: 2015 | G1: 2016 | H1: 2017 | I1: 2018 | J1: 2019 | K1: 2020 | L1: 2021 | M1: 2022 | N1: 2023 | O1: 2024 | P1: 2025 | Q1: 2026 | R1: 2027 | S1: 2028 | T1: 2029 | U1: 2030 | V1: 2031 | W1: 2032 | X1: 2033 | Y1: 2034 | Z1: 2035 | AB1: Earnings changes=>
E2: Actual ----------> | P2: Forecast -----> | AC2: Forecast ----->
C3: Units | E3: FY14A | F3: FY15A | G3: FY16A | H3: FY17A | I3: FY18A | J3: FY19A | K3: FY20A | L3: FY21A | M3: FY22A | N3: FY23A | O3: FY24A | P3: FY25E | Q3: FY26E | R3: FY27E | S3: FY28E | T3: FY29E | U3: FY30E | V3: FY31E | W3: FY32E | X3: FY33E | Y3: FY34E | Z3: FY35E | AC3: FY25E | AE3: FY26E
B4: P &L | I4: Dec-YE | J4: Dec-YE | K4: Dec-YE | L4: Dec-YE | M4: Dec-YE | N4: Dec-YE | O4: Dec-YE | P4: Dec-YE | Q4: Dec-YE | R4: Dec-YE | S4: Dec-YE | T4: Dec-YE | U4: Dec-YE | V4: Dec-YE | W4: Dec-YE | X4: Dec-YE | Y4: Dec-YE | Z4: Dec-YE | AC4: Dec-YE | AE4: Dec-YE
B6: Revenue (GAAP, as per guidance) | N6: 0 | O6: 0
A7: RevSquare | B7: Square | J7: 3461988 | K7: 3529192 | L7: 5193347 | M7: 6294138 | N7: 7033383 | O7: =INDEX(Qrtly!$A:$BH,MATCH(Annual!$A7,Qrtly!$A:$A,0),MATCH("1Q"&RIGHT(Annual!O$1,2),Qrtly!$A$3:$BH$3,0))+INDEX(Qrtly!$A:$BH,MATCH(Annual!$A7,Qrtly!$A:$A,0),MATCH("2Q"&RIGHT(Annual!O$1,2),Qrtly!$A$3:$BH$3,0))+INDEX(Qrtly!$A:$BH,MATCH(Annual!$A7,Qrtly!$A:$A,0),MATCH("3Q"&RIGHT(Annual!O$1,2),Qrtly!$A$3:$BH$3,0))+INDEX(Qrtly!$A:$BH,MATCH(Annual!$A7,Qrtly!$A:$A,0),MATCH("4Q"&RIGHT(Annual!O$1,2),Qrtly!$A$3:$BH$3,0)) -> 7681656 | P7: =INDEX(Qrtly!$A:$BH,MATCH(Annual!$A7,Qrtly!$A:$A,0),MATCH("1Q"&RIGHT(Annual!P$1,2),Qrtly!$A$3:$BH$3,0))+INDEX(Qrtly!$A:$BH,MATCH(Annual!$A7,Qrtly!$A:$A,0),MATCH("2Q"&RIGHT(Annual!P$1,2),Qrtly!$A$3:$BH$3,0))+INDEX(Qrtly!$A:$BH,MATCH(Annual!$A7,Qrtly!$A:$A,0),MATCH("3Q"&RIGHT(Annual!P$1,2),Qrtly!$A$3:$BH$3,0))+INDEX(Qrtly!$A:$BH,MATCH(Annual!$A7,Qrtly!$A:$A,0),MATCH("4Q"&RIGHT(Annual!P$1,2),Qrtly!$A$3:$BH$3,0)) -> 8477414.6 | Q7: =INDEX(Qrtly!$A:$BH,MATCH(Annual!$A7,Qrtly!$A:$A,0),MATCH("1Q"&RIGHT(Annual!Q$1,2),Qrtly!$A$3:$BH$3,0))+INDEX(Qrtly!$A:$BH,MATCH(Annual!$A7,Qrtly!$A:$A,0),MATCH("2Q"&RIGHT(Annual!Q$1,2),Qrtly!$A$3:$BH$3,0))+INDEX(Qrtly!$A:$BH,MATCH(Annual!$A7,Qrtly!$A:$A,0),MATCH("3Q"&RIGHT(Annual!Q$1,2),Qrtly!$A$3:$BH$3,0))+INDEX(Qrtly!$A:$BH,MATCH(Annual!$A7,Qrtly!$A:$A,0),MATCH("4Q"&RIGHT(Annual!Q$1,2),Qrtly!$A$3:$BH$3,0)) -> 9638032.8 | R7: =INDEX(Qrtly!$A:$BH,MATCH(Annual!$A7,Qrtly!$A:$A,0),MATCH("1Q"&RIGHT(Annual!R$1,2),Qrtly!$A$3:$BH$3,0))+INDEX(Qrtly!$A:$BH,MATCH(Annual!$A7,Qrtly!$A:$A,0),MATCH("2Q"&RIGHT(Annual!R$1,2),Qrtly!$A$3:$BH$3,0))+INDEX(Qrtly!$A:$BH,MATCH(Annual!$A7,Qrtly!$A:$A,0),MATCH("3Q"&RIGHT(Annual!R$1,2),Qrtly!$A$3:$BH$3,0))+INDEX(Qrtly!$A:$BH,MATCH(Annual!$A7,Qrtly!$A:$A,0),MATCH("4Q"&RIGHT(Annual!R$1,2),Qrtly!$A$3:$BH$3,0)) -> 10908141 | S7: =INDEX(Qrtly!$A:$BH,MATCH(Annual!$A7,Qrtly!$A:$A,0),MATCH("1Q"&RIGHT(Annual!S$1,2),Qrtly!$A$3:$BH$3,0))+INDEX(Qrtly!$A:$BH,MATCH(Annual!$A7,Qrtly!$A:$A,0),MATCH("2Q"&RIGHT(Annual!S$1,2),Qrtly!$A$3:$BH$3,0))+INDEX(Qrtly!$A:$BH,MATCH(Annual!$A7,Qrtly!$A:$A,0),MATCH("3Q"&RIGHT(Annual!S$1,2),Qrtly!$A$3:$BH$3,0))+INDEX(Qrtly!$A:$BH,MATCH(Annual!$A7,Qrtly!$A:$A,0),MATCH("4Q"&RIGHT(Annual!S$1,2),Qrtly!$A$3:$BH$3,0)) -> 12360525 | T7: =INDEX(Qrtly!$A:$BH,MATCH(Annual!$A7,Qrtly!$A:$A,0),MATCH("1Q"&RIGHT(Annual!T$1,2),Qrtly!$A$3:$BH$3,0))+INDEX(Qrtly!$A:$BH,MATCH(Annual!$A7,Qrtly!$A:$A,0),MATCH("2Q"&RIGHT(Annual!T$1,2),Qrtly!$A$3:$BH$3,0))+INDEX(Qrtly!$A:$BH,MATCH(Annual!$A7,Qrtly!$A:$A,0),MATCH("3Q"&RIGHT(Annual!T$1,2),Qrtly!$A$3:$BH$3,0))+INDEX(Qrtly!$A:$BH,MATCH(Annual!$A7,Qrtly!$A:$A,0),MATCH("4Q"&RIGHT(Annual!T$1,2),Qrtly!$A$3:$BH$3,0)) -> 13761987 | U7: =INDEX(Qrtly!$A:$BH,MATCH(Annual!$A7,Qrtly!$A:$A,0),MATCH("1Q"&RIGHT(Annual!U$1,2),Qrtly!$A$3:$BH$3,0))+INDEX(Qrtly!$A:$BH,MATCH(Annual!$A7,Qrtly!$A:$A,0),MATCH("2Q"&RIGHT(Annual!U$1,2),Qrtly!$A$3:$BH$3,0))+INDEX(Qrtly!$A:$BH,MATCH(Annual!$A7,Qrtly!$A:$A,0),MATCH("3Q"&RIGHT(Annual!U$1,2),Qrtly!$A$3:$BH$3,0))+INDEX(Qrtly!$A:$BH,MATCH(Annual!$A7,Qrtly!$A:$A,0),MATCH("4Q"&RIGHT(Annual!U$1,2),Qrtly!$A$3:$BH$3,0)) -> 15346426 | V7: =INDEX(Qrtly!$A:$BH,MATCH(Annual!$A7,Qrtly!$A:$A,0),MATCH("1Q"&RIGHT(Annual!V$1,2),Qrtly!$A$3:$BH$3,0))+INDEX(Qrtly!$A:$BH,MATCH(Annual!$A7,Qrtly!$A:$A,0),MATCH("2Q"&RIGHT(Annual!V$1,2),Qrtly!$A$3:$BH$3,0))+INDEX(Qrtly!$A:$BH,MATCH(Annual!$A7,Qrtly!$A:$A,0),MATCH("3Q"&RIGHT(Annual!V$1,2),Qrtly!$A$3:$BH$3,0))+INDEX(Qrtly!$A:$BH,MATCH(Annual!$A7,Qrtly!$A:$A,0),MATCH("4Q"&RIGHT(Annual!V$1,2),Qrtly!$A$3:$BH$3,0)) -> 17141516 | ... Z7: =INDEX(Qrtly!$A:$BH,MATCH(Annual!$A7,Qrtly!$A:$A,0),MATCH("1Q"&RIGHT(Annual!Z$1,2),Qrtly!$A$3:$BH$3,0))+INDEX(Qrtly!$A:$BH,MATCH(Annual!$A7,Qrtly!$A:$A,0),MATCH("2Q"&RIGHT(Annual!Z$1,2),Qrtly!$A$3:$BH$3,0))+INDEX(Qrtly!$A:$BH,MATCH(Annual!$A7,Qrtly!$A:$A,0),MATCH("3Q"&RIGHT(Annual!Z$1,2),Qrtly!$A$3:$BH$3,0))+INDEX(Qrtly!$A:$BH,MATCH(Annual!$A7,Qrtly!$A:$A,0),MATCH("4Q"&RIGHT(Annual!Z$1,2),Qrtly!$A$3:$BH$3,0)) -> 27165836 | AC7: 8438950 | AD7: =IF(ISBLANK(AC7),"",INDEX($A7:$AA7,1,MATCH(AC$3,$A$3:$AA$3,0))-AC7) -> 38464.596 | AE7: 9453980.2 | AF7: =IF(ISBLANK(AE7),"",INDEX($A7:$AA7,1,MATCH(AE$3,$A$3:$AA$3,0))-AE7) -> 184052.69
A8: RevCash App | B8: Cash App | J8: 1105599 | K8: 5968386 | L8: 12315498 | M8: 11031802 | N8: 14681687 | O8: =INDEX(Qrtly!$A:$BH,MATCH(Annual!$A8,Qrtly!$A:$A,0),MATCH("1Q"&RIGHT(Annual!O$1,2),Qrtly!$A$3:$BH$3,0))+INDEX(Qrtly!$A:$BH,MATCH(Annual!$A8,Qrtly!$A:$A,0),MATCH("2Q"&RIGHT(Annual!O$1,2),Qrtly!$A$3:$BH$3,0))+INDEX(Qrtly!$A:$BH,MATCH(Annual!$A8,Qrtly!$A:$A,0),MATCH("3Q"&RIGHT(Annual!O$1,2),Qrtly!$A$3:$BH$3,0))+INDEX(Qrtly!$A:$BH,MATCH(Annual!$A8,Qrtly!$A:$A,0),MATCH("4Q"&RIGHT(Annual!O$1,2),Qrtly!$A$3:$BH$3,0)) -> 16247880 | P8: =INDEX(Qrtly!$A:$BH,MATCH(Annual!$A8,Qrtly!$A:$A,0),MATCH("1Q"&RIGHT(Annual!P$1,2),Qrtly!$A$3:$BH$3,0))+INDEX(Qrtly!$A:$BH,MATCH(Annual!$A8,Qrtly!$A:$A,0),MATCH("2Q"&RIGHT(Annual!P$1,2),Qrtly!$A$3:$BH$3,0))+INDEX(Qrtly!$A:$BH,MATCH(Annual!$A8,Qrtly!$A:$A,0),MATCH("3Q"&RIGHT(Annual!P$1,2),Qrtly!$A$3:$BH$3,0))+INDEX(Qrtly!$A:$BH,MATCH(Annual!$A8,Qrtly!$A:$A,0),MATCH("4Q"&RIGHT(Annual!P$1,2),Qrtly!$A$3:$BH$3,0)) -> 15266139 | Q8: =INDEX(Qrtly!$A:$BH,MATCH(Annual!$A8,Qrtly!$A:$A,0),MATCH("1Q"&RIGHT(Annual!Q$1,2),Qrtly!$A$3:$BH$3,0))+INDEX(Qrtly!$A:$BH,MATCH(Annual!$A8,Qrtly!$A:$A,0),MATCH("2Q"&RIGHT(Annual!Q$1,2),Qrtly!$A$3:$BH$3,0))+INDEX(Qrtly!$A:$BH,MATCH(Annual!$A8,Qrtly!$A:$A,0),MATCH("3Q"&RIGHT(Annual!Q$1,2),Qrtly!$A$3:$BH$3,0))+INDEX(Qrtly!$A:$BH,MATCH(Annual!$A8,Qrtly!$A:$A,0),MATCH("4Q"&RIGHT(Annual!Q$1,2),Qrtly!$A$3:$BH$3,0)) -> 17382453 | R8: =INDEX(Qrtly!$A:$BH,MATCH(Annual!$A8,Qrtly!$A:$A,0),MATCH("1Q"&RIGHT(Annual!R$1,2),Qrtly!$A$3:$BH$3,0))+INDEX(Qrtly!$A:$BH,MATCH(Annual!$A8,Qrtly!$A:$A,0),MATCH("2Q"&RIGHT(Annual!R$1,2),Qrtly!$A$3:$BH$3,0))+INDEX(Qrtly!$A:$BH,MATCH(Annual!$A8,Qrtly!$A:$A,0),MATCH("3Q"&RIGHT(Annual!R$1,2),Qrtly!$A$3:$BH$3,0))+INDEX(Qrtly!$A:$BH,MATCH(Annual!$A8,Qrtly!$A:$A,0),MATCH("4Q"&RIGHT(Annual!R$1,2),Qrtly!$A$3:$BH$3,0)) -> 19768868 | S8: =INDEX(Qrtly!$A:$BH,MATCH(Annual!$A8,Qrtly!$A:$A,0),MATCH("1Q"&RIGHT(Annual!S$1,2),Qrtly!$A$3:$BH$3,0))+INDEX(Qrtly!$A:$BH,MATCH(Annual!$A8,Qrtly!$A:$A,0),MATCH("2Q"&RIGHT(Annual!S$1,2),Qrtly!$A$3:$BH$3,0))+INDEX(Qrtly!$A:$BH,MATCH(Annual!$A8,Qrtly!$A:$A,0),MATCH("3Q"&RIGHT(Annual!S$1,2),Qrtly!$A$3:$BH$3,0))+INDEX(Qrtly!$A:$BH,MATCH(Annual!$A8,Qrtly!$A:$A,0),MATCH("4Q"&RIGHT(Annual!S$1,2),Qrtly!$A$3:$BH$3,0)) -> 22486290 | T8: =INDEX(Qrtly!$A:$BH,MATCH(Annual!$A8,Qrtly!$A:$A,0),MATCH("1Q"&RIGHT(Annual!T$1,2),Qrtly!$A$3:$BH$3,0))+INDEX(Qrtly!$A:$BH,MATCH(Annual!$A8,Qrtly!$A:$A,0),MATCH("2Q"&RIGHT(Annual!T$1,2),Qrtly!$A$3:$BH$3,0))+INDEX(Qrtly!$A:$BH,MATCH(Annual!$A8,Qrtly!$A:$A,0),MATCH("3Q"&RIGHT(Annual!T$1,2),Qrtly!$A$3:$BH$3,0))+INDEX(Qrtly!$A:$BH,MATCH(Annual!$A8,Qrtly!$A:$A,0),MATCH("4Q"&RIGHT(Annual!T$1,2),Qrtly!$A$3:$BH$3,0)) -> 25581080 | U8: =INDEX(Qrtly!$A:$BH,MATCH(Annual!$A8,Qrtly!$A:$A,0),MATCH("1Q"&RIGHT(Annual!U$1,2),Qrtly!$A$3:$BH$3,0))+INDEX(Qrtly!$A:$BH,MATCH(Annual!$A8,Qrtly!$A:$A,0),MATCH("2Q"&RIGHT(Annual!U$1,2),Qrtly!$A$3:$BH$3,0))+INDEX(Qrtly!$A:$BH,MATCH(Annual!$A8,Qrtly!$A:$A,0),MATCH("3Q"&RIGHT(Annual!U$1,2),Qrtly!$A$3:$BH$3,0))+INDEX(Qrtly!$A:$BH,MATCH(Annual!$A8,Qrtly!$A:$A,0),MATCH("4Q"&RIGHT(Annual!U$1,2),Qrtly!$A$3:$BH$3,0)) -> 29106153 | V8: =INDEX(Qrtly!$A:$BH,MATCH(Annual!$A8,Qrtly!$A:$A,0),MATCH("1Q"&RIGHT(Annual!V$1,2),Qrtly!$A$3:$BH$3,0))+INDEX(Qrtly!$A:$BH,MATCH(Annual!$A8,Qrtly!$A:$A,0),MATCH("2Q"&RIGHT(Annual!V$1,2),Qrtly!$A$3:$BH$3,0))+INDEX(Qrtly!$A:$BH,MATCH(Annual!$A8,Qrtly!$A:$A,0),MATCH("3Q"&RIGHT(Annual!V$1,2),Qrtly!$A$3:$BH$3,0))+INDEX(Qrtly!$A:$BH,MATCH(Annual!$A8,Qrtly!$A:$A,0),MATCH("4Q"&RIGHT(Annual!V$1,2),Qrtly!$A$3:$BH$3,0)) -> 33121913 | ... Z8: =INDEX(Qrtly!$A:$BH,MATCH(Annual!$A8,Qrtly!$A:$A,0),MATCH("1Q"&RIGHT(Annual!Z$1,2),Qrtly!$A$3:$BH$3,0))+INDEX(Qrtly!$A:$BH,MATCH(Annual!$A8,Qrtly!$A:$A,0),MATCH("2Q"&RIGHT(Annual!Z$1,2),Qrtly!$A$3:$BH$3,0))+INDEX(Qrtly!$A:$BH,MATCH(Annual!$A8,Qrtly!$A:$A,0),MATCH("3Q"&RIGHT(Annual!Z$1,2),Qrtly!$A$3:$BH$3,0))+INDEX(Qrtly!$A:$BH,MATCH(Annual!$A8,Qrtly!$A:$A,0),MATCH("4Q"&RIGHT(Annual!Z$1,2),Qrtly!$A$3:$BH$3,0)) -> 55626213 | AC8: 17223573 | AD8: =IF(ISBLANK(AC8),"",INDEX($A8:$AA8,1,MATCH(AC$3,$A$3:$AA$3,0))-AC8) -> -1957433.9 | AE8: 20980789 | AF8: =IF(ISBLANK(AE8),"",INDEX($A8:$AA8,1,MATCH(AE$3,$A$3:$AA$3,0))-AE8) -> -3598336.1
A9: RevCorporate & Other | B9: Corporate & Other | J9: 145913 | K9: 0 | L9: 152358 | M9: 205647 | N9: 200554 | O9: =INDEX(Qrtly!$A:$BH,MATCH(Annual!$A9,Qrtly!$A:$A,0),MATCH("1Q"&RIGHT(Annual!O$1,2),Qrtly!$A$3:$BH$3,0))+INDEX(Qrtly!$A:$BH,MATCH(Annual!$A9,Qrtly!$A:$A,0),MATCH("2Q"&RIGHT(Annual!O$1,2),Qrtly!$A$3:$BH$3,0))+INDEX(Qrtly!$A:$BH,MATCH(Annual!$A9,Qrtly!$A:$A,0),MATCH("3Q"&RIGHT(Annual!O$1,2),Qrtly!$A$3:$BH$3,0))+INDEX(Qrtly!$A:$BH,MATCH(Annual!$A9,Qrtly!$A:$A,0),MATCH("4Q"&RIGHT(Annual!O$1,2),Qrtly!$A$3:$BH$3,0)) -> 191517 | P9: =INDEX(Qrtly!$A:$BH,MATCH(Annual!$A9,Qrtly!$A:$A,0),MATCH("1Q"&RIGHT(Annual!P$1,2),Qrtly!$A$3:$BH$3,0))+INDEX(Qrtly!$A:$BH,MATCH(Annual!$A9,Qrtly!$A:$A,0),MATCH("2Q"&RIGHT(Annual!P$1,2),Qrtly!$A$3:$BH$3,0))+INDEX(Qrtly!$A:$BH,MATCH(Annual!$A9,Qrtly!$A:$A,0),MATCH("3Q"&RIGHT(Annual!P$1,2),Qrtly!$A$3:$BH$3,0))+INDEX(Qrtly!$A:$BH,MATCH(Annual!$A9,Qrtly!$A:$A,0),MATCH("4Q"&RIGHT(Annual!P$1,2),Qrtly!$A$3:$BH$3,0)) -> 246353 | Q9: =INDEX(Qrtly!$A:$BH,MATCH(Annual!$A9,Qrtly!$A:$A,0),MATCH("1Q"&RIGHT(Annual!Q$1,2),Qrtly!$A$3:$BH$3,0))+INDEX(Qrtly!$A:$BH,MATCH(Annual!$A9,Qrtly!$A:$A,0),MATCH("2Q"&RIGHT(Annual!Q$1,2),Qrtly!$A$3:$BH$3,0))+INDEX(Qrtly!$A:$BH,MATCH(Annual!$A9,Qrtly!$A:$A,0),MATCH("3Q"&RIGHT(Annual!Q$1,2),Qrtly!$A$3:$BH$3,0))+INDEX(Qrtly!$A:$BH,MATCH(Annual!$A9,Qrtly!$A:$A,0),MATCH("4Q"&RIGHT(Annual!Q$1,2),Qrtly!$A$3:$BH$3,0)) -> 363042.6 | R9: =INDEX(Qrtly!$A:$BH,MATCH(Annual!$A9,Qrtly!$A:$A,0),MATCH("1Q"&RIGHT(Annual!R$1,2),Qrtly!$A$3:$BH$3,0))+INDEX(Qrtly!$A:$BH,MATCH(Annual!$A9,Qrtly!$A:$A,0),MATCH("2Q"&RIGHT(Annual!R$1,2),Qrtly!$A$3:$BH$3,0))+INDEX(Qrtly!$A:$BH,MATCH(Annual!$A9,Qrtly!$A:$A,0),MATCH("3Q"&RIGHT(Annual!R$1,2),Qrtly!$A$3:$BH$3,0))+INDEX(Qrtly!$A:$BH,MATCH(Annual!$A9,Qrtly!$A:$A,0),MATCH("4Q"&RIGHT(Annual!R$1,2),Qrtly!$A$3:$BH$3,0)) -> 435651.12 | S9: =INDEX(Qrtly!$A:$BH,MATCH(Annual!$A9,Qrtly!$A:$A,0),MATCH("1Q"&RIGHT(Annual!S$1,2),Qrtly!$A$3:$BH$3,0))+INDEX(Qrtly!$A:$BH,MATCH(Annual!$A9,Qrtly!$A:$A,0),MATCH("2Q"&RIGHT(Annual!S$1,2),Qrtly!$A$3:$BH$3,0))+INDEX(Qrtly!$A:$BH,MATCH(Annual!$A9,Qrtly!$A:$A,0),MATCH("3Q"&RIGHT(Annual!S$1,2),Qrtly!$A$3:$BH$3,0))+INDEX(Qrtly!$A:$BH,MATCH(Annual!$A9,Qrtly!$A:$A,0),MATCH("4Q"&RIGHT(Annual!S$1,2),Qrtly!$A$3:$BH$3,0)) -> 503800.78 | T9: =INDEX(Qrtly!$A:$BH,MATCH(Annual!$A9,Qrtly!$A:$A,0),MATCH("1Q"&RIGHT(Annual!T$1,2),Qrtly!$A$3:$BH$3,0))+INDEX(Qrtly!$A:$BH,MATCH(Annual!$A9,Qrtly!$A:$A,0),MATCH("2Q"&RIGHT(Annual!T$1,2),Qrtly!$A$3:$BH$3,0))+INDEX(Qrtly!$A:$BH,MATCH(Annual!$A9,Qrtly!$A:$A,0),MATCH("3Q"&RIGHT(Annual!T$1,2),Qrtly!$A$3:$BH$3,0))+INDEX(Qrtly!$A:$BH,MATCH(Annual!$A9,Qrtly!$A:$A,0),MATCH("4Q"&RIGHT(Annual!T$1,2),Qrtly!$A$3:$BH$3,0)) -> 528990.81 | U9: =INDEX(Qrtly!$A:$BH,MATCH(Annual!$A9,Qrtly!$A:$A,0),MATCH("1Q"&RIGHT(Annual!U$1,2),Qrtly!$A$3:$BH$3,0))+INDEX(Qrtly!$A:$BH,MATCH(Annual!$A9,Qrtly!$A:$A,0),MATCH("2Q"&RIGHT(Annual!U$1,2),Qrtly!$A$3:$BH$3,0))+INDEX(Qrtly!$A:$BH,MATCH(Annual!$A9,Qrtly!$A:$A,0),MATCH("3Q"&RIGHT(Annual!U$1,2),Qrtly!$A$3:$BH$3,0))+INDEX(Qrtly!$A:$BH,MATCH(Annual!$A9,Qrtly!$A:$A,0),MATCH("4Q"&RIGHT(Annual!U$1,2),Qrtly!$A$3:$BH$3,0)) -> 555440.36 | V9: =INDEX(Qrtly!$A:$BH,MATCH(Annual!$A9,Qrtly!$A:$A,0),MATCH("1Q"&RIGHT(Annual!V$1,2),Qrtly!$A$3:$BH$3,0))+INDEX(Qrtly!$A:$BH,MATCH(Annual!$A9,Qrtly!$A:$A,0),MATCH("2Q"&RIGHT(Annual!V$1,2),Qrtly!$A$3:$BH$3,0))+INDEX(Qrtly!$A:$BH,MATCH(Annual!$A9,Qrtly!$A:$A,0),MATCH("3Q"&RIGHT(Annual!V$1,2),Qrtly!$A$3:$BH$3,0))+INDEX(Qrtly!$A:$BH,MATCH(Annual!$A9,Qrtly!$A:$A,0),MATCH("4Q"&RIGHT(Annual!V$1,2),Qrtly!$A$3:$BH$3,0)) -> 583212.37 | ... Z9: =INDEX(Qrtly!$A:$BH,MATCH(Annual!$A9,Qrtly!$A:$A,0),MATCH("1Q"&RIGHT(Annual!Z$1,2),Qrtly!$A$3:$BH$3,0))+INDEX(Qrtly!$A:$BH,MATCH(Annual!$A9,Qrtly!$A:$A,0),MATCH("2Q"&RIGHT(Annual!Z$1,2),Qrtly!$A$3:$BH$3,0))+INDEX(Qrtly!$A:$BH,MATCH(Annual!$A9,Qrtly!$A:$A,0),MATCH("3Q"&RIGHT(Annual!Z$1,2),Qrtly!$A$3:$BH$3,0))+INDEX(Qrtly!$A:$BH,MATCH(Annual!$A9,Qrtly!$A:$A,0),MATCH("4Q"&RIGHT(Annual!Z$1,2),Qrtly!$A$3:$BH$3,0)) -> 708898.28 | AC9: 258464 | AD9: =IF(ISBLANK(AC9),"",INDEX($A9:$AA9,1,MATCH(AC$3,$A$3:$AA$3,0))-AC9) -> -12111 | AE9: 377575.8 | AF9: =IF(ISBLANK(AE9),"",INDEX($A9:$AA9,1,MATCH(AE$3,$A$3:$AA$3,0))-AE9) -> -14533.2
A10: RevTotal Revenue | B10: Total Revenue | C10: USDk | F10: 1267118 | G10: 1708721 | H10: 2214253 | I10: 3298177 | J10: 4713500 | K10: 9497578 | L10: 17661203 | M10: 17531587 | N10: 21915623 | O10: =INDEX(Qrtly!$A:$BH,MATCH(Annual!$A10,Qrtly!$A:$A,0),MATCH("1Q"&RIGHT(Annual!O$1,2),Qrtly!$A$3:$BH$3,0))+INDEX(Qrtly!$A:$BH,MATCH(Annual!$A10,Qrtly!$A:$A,0),MATCH("2Q"&RIGHT(Annual!O$1,2),Qrtly!$A$3:$BH$3,0))+INDEX(Qrtly!$A:$BH,MATCH(Annual!$A10,Qrtly!$A:$A,0),MATCH("3Q"&RIGHT(Annual!O$1,2),Qrtly!$A$3:$BH$3,0))+INDEX(Qrtly!$A:$BH,MATCH(Annual!$A10,Qrtly!$A:$A,0),MATCH("4Q"&RIGHT(Annual!O$1,2),Qrtly!$A$3:$BH$3,0)) -> 24121053 | P10: =INDEX(Qrtly!$A:$BH,MATCH(Annual!$A10,Qrtly!$A:$A,0),MATCH("1Q"&RIGHT(Annual!P$1,2),Qrtly!$A$3:$BH$3,0))+INDEX(Qrtly!$A:$BH,MATCH(Annual!$A10,Qrtly!$A:$A,0),MATCH("2Q"&RIGHT(Annual!P$1,2),Qrtly!$A$3:$BH$3,0))+INDEX(Qrtly!$A:$BH,MATCH(Annual!$A10,Qrtly!$A:$A,0),MATCH("3Q"&RIGHT(Annual!P$1,2),Qrtly!$A$3:$BH$3,0))+INDEX(Qrtly!$A:$BH,MATCH(Annual!$A10,Qrtly!$A:$A,0),MATCH("4Q"&RIGHT(Annual!P$1,2),Qrtly!$A$3:$BH$3,0)) -> 23989907 | Q10: =INDEX(Qrtly!$A:$BH,MATCH(Annual!$A10,Qrtly!$A:$A,0),MATCH("1Q"&RIGHT(Annual!Q$1,2),Qrtly!$A$3:$BH$3,0))+INDEX(Qrtly!$A:$BH,MATCH(Annual!$A10,Qrtly!$A:$A,0),MATCH("2Q"&RIGHT(Annual!Q$1,2),Qrtly!$A$3:$BH$3,0))+INDEX(Qrtly!$A:$BH,MATCH(Annual!$A10,Qrtly!$A:$A,0),MATCH("3Q"&RIGHT(Annual!Q$1,2),Qrtly!$A$3:$BH$3,0))+INDEX(Qrtly!$A:$BH,MATCH(Annual!$A10,Qrtly!$A:$A,0),MATCH("4Q"&RIGHT(Annual!Q$1,2),Qrtly!$A$3:$BH$3,0)) -> 27383528 | R10: =INDEX(Qrtly!$A:$BH,MATCH(Annual!$A10,Qrtly!$A:$A,0),MATCH("1Q"&RIGHT(Annual!R$1,2),Qrtly!$A$3:$BH$3,0))+INDEX(Qrtly!$A:$BH,MATCH(Annual!$A10,Qrtly!$A:$A,0),MATCH("2Q"&RIGHT(Annual!R$1,2),Qrtly!$A$3:$BH$3,0))+INDEX(Qrtly!$A:$BH,MATCH(Annual!$A10,Qrtly!$A:$A,0),MATCH("3Q"&RIGHT(Annual!R$1,2),Qrtly!$A$3:$BH$3,0))+INDEX(Qrtly!$A:$BH,MATCH(Annual!$A10,Qrtly!$A:$A,0),MATCH("4Q"&RIGHT(Annual!R$1,2),Qrtly!$A$3:$BH$3,0)) -> 31112660 | S10: =INDEX(Qrtly!$A:$BH,MATCH(Annual!$A10,Qrtly!$A:$A,0),MATCH("1Q"&RIGHT(Annual!S$1,2),Qrtly!$A$3:$BH$3,0))+INDEX(Qrtly!$A:$BH,MATCH(Annual!$A10,Qrtly!$A:$A,0),MATCH("2Q"&RIGHT(Annual!S$1,2),Qrtly!$A$3:$BH$3,0))+INDEX(Qrtly!$A:$BH,MATCH(Annual!$A10,Qrtly!$A:$A,0),MATCH("3Q"&RIGHT(Annual!S$1,2),Qrtly!$A$3:$BH$3,0))+INDEX(Qrtly!$A:$BH,MATCH(Annual!$A10,Qrtly!$A:$A,0),MATCH("4Q"&RIGHT(Annual!S$1,2),Qrtly!$A$3:$BH$3,0)) -> 35350615 | T10: =INDEX(Qrtly!$A:$BH,MATCH(Annual!$A10,Qrtly!$A:$A,0),MATCH("1Q"&RIGHT(Annual!T$1,2),Qrtly!$A$3:$BH$3,0))+INDEX(Qrtly!$A:$BH,MATCH(Annual!$A10,Qrtly!$A:$A,0),MATCH("2Q"&RIGHT(Annual!T$1,2),Qrtly!$A$3:$BH$3,0))+INDEX(Qrtly!$A:$BH,MATCH(Annual!$A10,Qrtly!$A:$A,0),MATCH("3Q"&RIGHT(Annual!T$1,2),Qrtly!$A$3:$BH$3,0))+INDEX(Qrtly!$A:$BH,MATCH(Annual!$A10,Qrtly!$A:$A,0),MATCH("4Q"&RIGHT(Annual!T$1,2),Qrtly!$A$3:$BH$3,0)) -> 39872057 | U10: =INDEX(Qrtly!$A:$BH,MATCH(Annual!$A10,Qrtly!$A:$A,0),MATCH("1Q"&RIGHT(Annual!U$1,2),Qrtly!$A$3:$BH$3,0))+INDEX(Qrtly!$A:$BH,MATCH(Annual!$A10,Qrtly!$A:$A,0),MATCH("2Q"&RIGHT(Annual!U$1,2),Qrtly!$A$3:$BH$3,0))+INDEX(Qrtly!$A:$BH,MATCH(Annual!$A10,Qrtly!$A:$A,0),MATCH("3Q"&RIGHT(Annual!U$1,2),Qrtly!$A$3:$BH$3,0))+INDEX(Qrtly!$A:$BH,MATCH(Annual!$A10,Qrtly!$A:$A,0),MATCH("4Q"&RIGHT(Annual!U$1,2),Qrtly!$A$3:$BH$3,0)) -> 45008020 | V10: =INDEX(Qrtly!$A:$BH,MATCH(Annual!$A10,Qrtly!$A:$A,0),MATCH("1Q"&RIGHT(Annual!V$1,2),Qrtly!$A$3:$BH$3,0))+INDEX(Qrtly!$A:$BH,MATCH(Annual!$A10,Qrtly!$A:$A,0),MATCH("2Q"&RIGHT(Annual!V$1,2),Qrtly!$A$3:$BH$3,0))+INDEX(Qrtly!$A:$BH,MATCH(Annual!$A10,Qrtly!$A:$A,0),MATCH("3Q"&RIGHT(Annual!V$1,2),Qrtly!$A$3:$BH$3,0))+INDEX(Qrtly!$A:$BH,MATCH(Annual!$A10,Qrtly!$A:$A,0),MATCH("4Q"&RIGHT(Annual!V$1,2),Qrtly!$A$3:$BH$3,0)) -> 50846642 | ... Z10: =INDEX(Qrtly!$A:$BH,MATCH(Annual!$A10,Qrtly!$A:$A,0),MATCH("1Q"&RIGHT(Annual!Z$1,2),Qrtly!$A$3:$BH$3,0))+INDEX(Qrtly!$A:$BH,MATCH(Annual!$A10,Qrtly!$A:$A,0),MATCH("2Q"&RIGHT(Annual!Z$1,2),Qrtly!$A$3:$BH$3,0))+INDEX(Qrtly!$A:$BH,MATCH(Annual!$A10,Qrtly!$A:$A,0),MATCH("3Q"&RIGHT(Annual!Z$1,2),Qrtly!$A$3:$BH$3,0))+INDEX(Qrtly!$A:$BH,MATCH(Annual!$A10,Qrtly!$A:$A,0),MATCH("4Q"&RIGHT(Annual!Z$1,2),Qrtly!$A$3:$BH$3,0)) -> 83500947 | AC10: 25920987 | AD10: =IF(ISBLANK(AC10),"",INDEX($A10:$AA10,1,MATCH(AC$3,$A$3:$AA$3,0))-AC10) -> -1931080.3 | AE10: 30812345 | AF10: =IF(ISBLANK(AE10),"",INDEX($A10:$AA10,1,MATCH(AE$3,$A$3:$AA$3,0))-AE10) -> -3428816.6
B11: Growth | C11: % YoY | I11: 0.49 | J11: 0.429 | K11: 1.015 | L11: 0.86 | M11: -0.007 | N11: 0.25 | O11: =O10/N10-1 -> 0.10063278 | P11: =P10/O10-1 -> -0.0054370058 | Q11: =Q10/P10-1 -> 0.14146038 | R11: =R10/Q10-1 -> 0.13618158 | S11: =S10/R10-1 -> 0.1362132 | T11: =T10/S10-1 -> 0.12790279 | U11: =U10/T10-1 -> 0.12881107 | V11: =V10/U10-1 -> 0.12972403 | ... Z11: =Z10/Y10-1 -> 0.13342026 | AC11: 0.074620871 | AD11: =IF(ISBLANK(AC11),"",INDEX($A11:$AA11,1,MATCH(AC$3,$A$3:$AA$3,0))-AC11) -> -0.080057877 | AE11: 0.1887026 | AF11: =IF(ISBLANK(AE11),"",INDEX($A11:$AA11,1,MATCH(AE$3,$A$3:$AA$3,0))-AE11) -> -0.04724222
B12: Initial Guidance | C12: USDk | G12: 610000 | H12: 2120000 | I12: 2850000 | J12: 4380000 | K12: 5930000 | AD12: =IF(ISBLANK(AC12),"",INDEX($A12:$AA12,1,MATCH(AC$3,$A$3:$AA$3,0))-AC12) | AF12: =IF(ISBLANK(AE12),"",INDEX($A12:$AA12,1,MATCH(AE$3,$A$3:$AA$3,0))-AE12)
B13: vs guidance | G13: 1.8 | H13: 0.04 | I13: 0.16 | J13: 0.08 | K13: 0.6 | AD13: =IF(ISBLANK(AC13),"",INDEX($A13:$AA13,1,MATCH(AC$3,$A$3:$AA$3,0))-AC13) | AF13: =IF(ISBLANK(AE13),"",INDEX($A13:$AA13,1,MATCH(AE$3,$A$3:$AA$3,0))-AE13)
AD14: =IF(ISBLANK(AC14),"",INDEX($A14:$AA14,1,MATCH(AC$3,$A$3:$AA$3,0))-AC14) | AF14: =IF(ISBLANK(AE14),"",INDEX($A14:$AA14,1,MATCH(AE$3,$A$3:$AA$3,0))-AE14)
B15: Gross Profit (GAAP) | AD15: =IF(ISBLANK(AC15),"",INDEX($A15:$AA15,1,MATCH(AC$3,$A$3:$AA$3,0))-AC15) | AF15: =IF(ISBLANK(AE15),"",INDEX($A15:$AA15,1,MATCH(AE$3,$A$3:$AA$3,0))-AE15)
A16: GP-Square | B16: Square | J16: 1390427 | K16: 1507831 | L16: 2316670 | M16: 2706902 | N16: 3128649 | O16: =INDEX(Qrtly!$A:$BH,MATCH(Annual!$A16,Qrtly!$A:$A,0),MATCH("1Q"&RIGHT(Annual!O$1,2),Qrtly!$A$3:$BH$3,0))+INDEX(Qrtly!$A:$BH,MATCH(Annual!$A16,Qrtly!$A:$A,0),MATCH("2Q"&RIGHT(Annual!O$1,2),Qrtly!$A$3:$BH$3,0))+INDEX(Qrtly!$A:$BH,MATCH(Annual!$A16,Qrtly!$A:$A,0),MATCH("3Q"&RIGHT(Annual!O$1,2),Qrtly!$A$3:$BH$3,0))+INDEX(Qrtly!$A:$BH,MATCH(Annual!$A16,Qrtly!$A:$A,0),MATCH("4Q"&RIGHT(Annual!O$1,2),Qrtly!$A$3:$BH$3,0)) -> 3598912 | P16: =INDEX(Qrtly!$A:$BH,MATCH(Annual!$A16,Qrtly!$A:$A,0),MATCH("1Q"&RIGHT(Annual!P$1,2),Qrtly!$A$3:$BH$3,0))+INDEX(Qrtly!$A:$BH,MATCH(Annual!$A16,Qrtly!$A:$A,0),MATCH("2Q"&RIGHT(Annual!P$1,2),Qrtly!$A$3:$BH$3,0))+INDEX(Qrtly!$A:$BH,MATCH(Annual!$A16,Qrtly!$A:$A,0),MATCH("3Q"&RIGHT(Annual!P$1,2),Qrtly!$A$3:$BH$3,0))+INDEX(Qrtly!$A:$BH,MATCH(Annual!$A16,Qrtly!$A:$A,0),MATCH("4Q"&RIGHT(Annual!P$1,2),Qrtly!$A$3:$BH$3,0)) -> 3964136.9 | Q16: =INDEX(Qrtly!$A:$BH,MATCH(Annual!$A16,Qrtly!$A:$A,0),MATCH("1Q"&RIGHT(Annual!Q$1,2),Qrtly!$A$3:$BH$3,0))+INDEX(Qrtly!$A:$BH,MATCH(Annual!$A16,Qrtly!$A:$A,0),MATCH("2Q"&RIGHT(Annual!Q$1,2),Qrtly!$A$3:$BH$3,0))+INDEX(Qrtly!$A:$BH,MATCH(Annual!$A16,Qrtly!$A:$A,0),MATCH("3Q"&RIGHT(Annual!Q$1,2),Qrtly!$A$3:$BH$3,0))+INDEX(Qrtly!$A:$BH,MATCH(Annual!$A16,Qrtly!$A:$A,0),MATCH("4Q"&RIGHT(Annual!Q$1,2),Qrtly!$A$3:$BH$3,0)) -> 4503213.6 | R16: =INDEX(Qrtly!$A:$BH,MATCH(Annual!$A16,Qrtly!$A:$A,0),MATCH("1Q"&RIGHT(Annual!R$1,2),Qrtly!$A$3:$BH$3,0))+INDEX(Qrtly!$A:$BH,MATCH(Annual!$A16,Qrtly!$A:$A,0),MATCH("2Q"&RIGHT(Annual!R$1,2),Qrtly!$A$3:$BH$3,0))+INDEX(Qrtly!$A:$BH,MATCH(Annual!$A16,Qrtly!$A:$A,0),MATCH("3Q"&RIGHT(Annual!R$1,2),Qrtly!$A$3:$BH$3,0))+INDEX(Qrtly!$A:$BH,MATCH(Annual!$A16,Qrtly!$A:$A,0),MATCH("4Q"&RIGHT(Annual!R$1,2),Qrtly!$A$3:$BH$3,0)) -> 5161113.4 | S16: =INDEX(Qrtly!$A:$BH,MATCH(Annual!$A16,Qrtly!$A:$A,0),MATCH("1Q"&RIGHT(Annual!S$1,2),Qrtly!$A$3:$BH$3,0))+INDEX(Qrtly!$A:$BH,MATCH(Annual!$A16,Qrtly!$A:$A,0),MATCH("2Q"&RIGHT(Annual!S$1,2),Qrtly!$A$3:$BH$3,0))+INDEX(Qrtly!$A:$BH,MATCH(Annual!$A16,Qrtly!$A:$A,0),MATCH("3Q"&RIGHT(Annual!S$1,2),Qrtly!$A$3:$BH$3,0))+INDEX(Qrtly!$A:$BH,MATCH(Annual!$A16,Qrtly!$A:$A,0),MATCH("4Q"&RIGHT(Annual!S$1,2),Qrtly!$A$3:$BH$3,0)) -> 5927203.9 | T16: =INDEX(Qrtly!$A:$BH,MATCH(Annual!$A16,Qrtly!$A:$A,0),MATCH("1Q"&RIGHT(Annual!T$1,2),Qrtly!$A$3:$BH$3,0))+INDEX(Qrtly!$A:$BH,MATCH(Annual!$A16,Qrtly!$A:$A,0),MATCH("2Q"&RIGHT(Annual!T$1,2),Qrtly!$A$3:$BH$3,0))+INDEX(Qrtly!$A:$BH,MATCH(Annual!$A16,Qrtly!$A:$A,0),MATCH("3Q"&RIGHT(Annual!T$1,2),Qrtly!$A$3:$BH$3,0))+INDEX(Qrtly!$A:$BH,MATCH(Annual!$A16,Qrtly!$A:$A,0),MATCH("4Q"&RIGHT(Annual!T$1,2),Qrtly!$A$3:$BH$3,0)) -> 6711355.8 | U16: =INDEX(Qrtly!$A:$BH,MATCH(Annual!$A16,Qrtly!$A:$A,0),MATCH("1Q"&RIGHT(Annual!U$1,2),Qrtly!$A$3:$BH$3,0))+INDEX(Qrtly!$A:$BH,MATCH(Annual!$A16,Qrtly!$A:$A,0),MATCH("2Q"&RIGHT(Annual!U$1,2),Qrtly!$A$3:$BH$3,0))+INDEX(Qrtly!$A:$BH,MATCH(Annual!$A16,Qrtly!$A:$A,0),MATCH("3Q"&RIGHT(Annual!U$1,2),Qrtly!$A$3:$BH$3,0))+INDEX(Qrtly!$A:$BH,MATCH(Annual!$A16,Qrtly!$A:$A,0),MATCH("4Q"&RIGHT(Annual!U$1,2),Qrtly!$A$3:$BH$3,0)) -> 7612981.9 | V16: =INDEX(Qrtly!$A:$BH,MATCH(Annual!$A16,Qrtly!$A:$A,0),MATCH("1Q"&RIGHT(Annual!V$1,2),Qrtly!$A$3:$BH$3,0))+INDEX(Qrtly!$A:$BH,MATCH(Annual!$A16,Qrtly!$A:$A,0),MATCH("2Q"&RIGHT(Annual!V$1,2),Qrtly!$A$3:$BH$3,0))+INDEX(Qrtly!$A:$BH,MATCH(Annual!$A16,Qrtly!$A:$A,0),MATCH("3Q"&RIGHT(Annual!V$1,2),Qrtly!$A$3:$BH$3,0))+INDEX(Qrtly!$A:$BH,MATCH(Annual!$A16,Qrtly!$A:$A,0),MATCH("4Q"&RIGHT(Annual!V$1,2),Qrtly!$A$3:$BH$3,0)) -> 8651724.8 | ... Z16: =INDEX(Qrtly!$A:$BH,MATCH(Annual!$A16,Qrtly!$A:$A,0),MATCH("1Q"&RIGHT(Annual!Z$1,2),Qrtly!$A$3:$BH$3,0))+INDEX(Qrtly!$A:$BH,MATCH(Annual!$A16,Qrtly!$A:$A,0),MATCH("2Q"&RIGHT(Annual!Z$1,2),Qrtly!$A$3:$BH$3,0))+INDEX(Qrtly!$A:$BH,MATCH(Annual!$A16,Qrtly!$A:$A,0),MATCH("3Q"&RIGHT(Annual!Z$1,2),Qrtly!$A$3:$BH$3,0))+INDEX(Qrtly!$A:$BH,MATCH(Annual!$A16,Qrtly!$A:$A,0),MATCH("4Q"&RIGHT(Annual!Z$1,2),Qrtly!$A$3:$BH$3,0)) -> 14710033 | AA16: -0.01 | AB16: -0.01 | AC16: 3991241.3 | AD16: =IF(ISBLANK(AC16),"",INDEX($A16:$AA16,1,MATCH(AC$3,$A$3:$AA$3,0))-AC16) -> -27104.401 | AE16: 4525935.8 | AF16: =IF(ISBLANK(AE16),"",INDEX($A16:$AA16,1,MATCH(AE$3,$A$3:$AA$3,0))-AE16) -> -22722.236
A17: GP-Cash App | B17: Cash App | J17: 457668 | K17: 1225578 | L17: 2070847 | M17: 3245042 | N17: 4323463 | O17: =INDEX(Qrtly!$A:$BH,MATCH(Annual!$A17,Qrtly!$A:$A,0),MATCH("1Q"&RIGHT(Annual!O$1,2),Qrtly!$A$3:$BH$3,0))+INDEX(Qrtly!$A:$BH,MATCH(Annual!$A17,Qrtly!$A:$A,0),MATCH("2Q"&RIGHT(Annual!O$1,2),Qrtly!$A$3:$BH$3,0))+INDEX(Qrtly!$A:$BH,MATCH(Annual!$A17,Qrtly!$A:$A,0),MATCH("3Q"&RIGHT(Annual!O$1,2),Qrtly!$A$3:$BH$3,0))+INDEX(Qrtly!$A:$BH,MATCH(Annual!$A17,Qrtly!$A:$A,0),MATCH("4Q"&RIGHT(Annual!O$1,2),Qrtly!$A$3:$BH$3,0)) -> 5239011 | P17: =INDEX(Qrtly!$A:$BH,MATCH(Annual!$A17,Qrtly!$A:$A,0),MATCH("1Q"&RIGHT(Annual!P$1,2),Qrtly!$A$3:$BH$3,0))+INDEX(Qrtly!$A:$BH,MATCH(Annual!$A17,Qrtly!$A:$A,0),MATCH("2Q"&RIGHT(Annual!P$1,2),Qrtly!$A$3:$BH$3,0))+INDEX(Qrtly!$A:$BH,MATCH(Annual!$A17,Qrtly!$A:$A,0),MATCH("3Q"&RIGHT(Annual!P$1,2),Qrtly!$A$3:$BH$3,0))+INDEX(Qrtly!$A:$BH,MATCH(Annual!$A17,Qrtly!$A:$A,0),MATCH("4Q"&RIGHT(Annual!P$1,2),Qrtly!$A$3:$BH$3,0)) -> 6284206.9 | Q17: =INDEX(Qrtly!$A:$BH,MATCH(Annual!$A17,Qrtly!$A:$A,0),MATCH("1Q"&RIGHT(Annual!Q$1,2),Qrtly!$A$3:$BH$3,0))+INDEX(Qrtly!$A:$BH,MATCH(Annual!$A17,Qrtly!$A:$A,0),MATCH("2Q"&RIGHT(Annual!Q$1,2),Qrtly!$A$3:$BH$3,0))+INDEX(Qrtly!$A:$BH,MATCH(Annual!$A17,Qrtly!$A:$A,0),MATCH("3Q"&RIGHT(Annual!Q$1,2),Qrtly!$A$3:$BH$3,0))+INDEX(Qrtly!$A:$BH,MATCH(Annual!$A17,Qrtly!$A:$A,0),MATCH("4Q"&RIGHT(Annual!Q$1,2),Qrtly!$A$3:$BH$3,0)) -> 7825132.4 | R17: =INDEX(Qrtly!$A:$BH,MATCH(Annual!$A17,Qrtly!$A:$A,0),MATCH("1Q"&RIGHT(Annual!R$1,2),Qrtly!$A$3:$BH$3,0))+INDEX(Qrtly!$A:$BH,MATCH(Annual!$A17,Qrtly!$A:$A,0),MATCH("2Q"&RIGHT(Annual!R$1,2),Qrtly!$A$3:$BH$3,0))+INDEX(Qrtly!$A:$BH,MATCH(Annual!$A17,Qrtly!$A:$A,0),MATCH("3Q"&RIGHT(Annual!R$1,2),Qrtly!$A$3:$BH$3,0))+INDEX(Qrtly!$A:$BH,MATCH(Annual!$A17,Qrtly!$A:$A,0),MATCH("4Q"&RIGHT(Annual!R$1,2),Qrtly!$A$3:$BH$3,0)) -> 9281980.2 | S17: =INDEX(Qrtly!$A:$BH,MATCH(Annual!$A17,Qrtly!$A:$A,0),MATCH("1Q"&RIGHT(Annual!S$1,2),Qrtly!$A$3:$BH$3,0))+INDEX(Qrtly!$A:$BH,MATCH(Annual!$A17,Qrtly!$A:$A,0),MATCH("2Q"&RIGHT(Annual!S$1,2),Qrtly!$A$3:$BH$3,0))+INDEX(Qrtly!$A:$BH,MATCH(Annual!$A17,Qrtly!$A:$A,0),MATCH("3Q"&RIGHT(Annual!S$1,2),Qrtly!$A$3:$BH$3,0))+INDEX(Qrtly!$A:$BH,MATCH(Annual!$A17,Qrtly!$A:$A,0),MATCH("4Q"&RIGHT(Annual!S$1,2),Qrtly!$A$3:$BH$3,0)) -> 10803008 | T17: =INDEX(Qrtly!$A:$BH,MATCH(Annual!$A17,Qrtly!$A:$A,0),MATCH("1Q"&RIGHT(Annual!T$1,2),Qrtly!$A$3:$BH$3,0))+INDEX(Qrtly!$A:$BH,MATCH(Annual!$A17,Qrtly!$A:$A,0),MATCH("2Q"&RIGHT(Annual!T$1,2),Qrtly!$A$3:$BH$3,0))+INDEX(Qrtly!$A:$BH,MATCH(Annual!$A17,Qrtly!$A:$A,0),MATCH("3Q"&RIGHT(Annual!T$1,2),Qrtly!$A$3:$BH$3,0))+INDEX(Qrtly!$A:$BH,MATCH(Annual!$A17,Qrtly!$A:$A,0),MATCH("4Q"&RIGHT(Annual!T$1,2),Qrtly!$A$3:$BH$3,0)) -> 12453690 | U17: =INDEX(Qrtly!$A:$BH,MATCH(Annual!$A17,Qrtly!$A:$A,0),MATCH("1Q"&RIGHT(Annual!U$1,2),Qrtly!$A$3:$BH$3,0))+INDEX(Qrtly!$A:$BH,MATCH(Annual!$A17,Qrtly!$A:$A,0),MATCH("2Q"&RIGHT(Annual!U$1,2),Qrtly!$A$3:$BH$3,0))+INDEX(Qrtly!$A:$BH,MATCH(Annual!$A17,Qrtly!$A:$A,0),MATCH("3Q"&RIGHT(Annual!U$1,2),Qrtly!$A$3:$BH$3,0))+INDEX(Qrtly!$A:$BH,MATCH(Annual!$A17,Qrtly!$A:$A,0),MATCH("4Q"&RIGHT(Annual!U$1,2),Qrtly!$A$3:$BH$3,0)) -> 14382454 | V17: =INDEX(Qrtly!$A:$BH,MATCH(Annual!$A17,Qrtly!$A:$A,0),MATCH("1Q"&RIGHT(Annual!V$1,2),Qrtly!$A$3:$BH$3,0))+INDEX(Qrtly!$A:$BH,MATCH(Annual!$A17,Qrtly!$A:$A,0),MATCH("2Q"&RIGHT(Annual!V$1,2),Qrtly!$A$3:$BH$3,0))+INDEX(Qrtly!$A:$BH,MATCH(Annual!$A17,Qrtly!$A:$A,0),MATCH("3Q"&RIGHT(Annual!V$1,2),Qrtly!$A$3:$BH$3,0))+INDEX(Qrtly!$A:$BH,MATCH(Annual!$A17,Qrtly!$A:$A,0),MATCH("4Q"&RIGHT(Annual!V$1,2),Qrtly!$A$3:$BH$3,0)) -> 16641613 | ... Z17: =INDEX(Qrtly!$A:$BH,MATCH(Annual!$A17,Qrtly!$A:$A,0),MATCH("1Q"&RIGHT(Annual!Z$1,2),Qrtly!$A$3:$BH$3,0))+INDEX(Qrtly!$A:$BH,MATCH(Annual!$A17,Qrtly!$A:$A,0),MATCH("2Q"&RIGHT(Annual!Z$1,2),Qrtly!$A$3:$BH$3,0))+INDEX(Qrtly!$A:$BH,MATCH(Annual!$A17,Qrtly!$A:$A,0),MATCH("3Q"&RIGHT(Annual!Z$1,2),Qrtly!$A$3:$BH$3,0))+INDEX(Qrtly!$A:$BH,MATCH(Annual!$A17,Qrtly!$A:$A,0),MATCH("4Q"&RIGHT(Annual!Z$1,2),Qrtly!$A$3:$BH$3,0)) -> 30464680 | AA17: 0.03 | AB17: 0.08 | AC17: 6143549.1 | AD17: =IF(ISBLANK(AC17),"",INDEX($A17:$AA17,1,MATCH(AC$3,$A$3:$AA$3,0))-AC17) -> 140657.78 | AE17: 7660639.7 | AF17: =IF(ISBLANK(AE17),"",INDEX($A17:$AA17,1,MATCH(AE$3,$A$3:$AA$3,0))-AE17) -> 164492.67
A18: GP-Corporate & Other | B18: Corporate & Other | J18: 41590 | K18: 0 | L18: 32305 | M18: 39949 | N18: 52775 | O18: =INDEX(Qrtly!$A:$BH,MATCH(Annual!$A18,Qrtly!$A:$A,0),MATCH("1Q"&RIGHT(Annual!O$1,2),Qrtly!$A$3:$BH$3,0))+INDEX(Qrtly!$A:$BH,MATCH(Annual!$A18,Qrtly!$A:$A,0),MATCH("2Q"&RIGHT(Annual!O$1,2),Qrtly!$A$3:$BH$3,0))+INDEX(Qrtly!$A:$BH,MATCH(Annual!$A18,Qrtly!$A:$A,0),MATCH("3Q"&RIGHT(Annual!O$1,2),Qrtly!$A$3:$BH$3,0))+INDEX(Qrtly!$A:$BH,MATCH(Annual!$A18,Qrtly!$A:$A,0),MATCH("4Q"&RIGHT(Annual!O$1,2),Qrtly!$A$3:$BH$3,0)) -> 51113 | P18: =INDEX(Qrtly!$A:$BH,MATCH(Annual!$A18,Qrtly!$A:$A,0),MATCH("1Q"&RIGHT(Annual!P$1,2),Qrtly!$A$3:$BH$3,0))+INDEX(Qrtly!$A:$BH,MATCH(Annual!$A18,Qrtly!$A:$A,0),MATCH("2Q"&RIGHT(Annual!P$1,2),Qrtly!$A$3:$BH$3,0))+INDEX(Qrtly!$A:$BH,MATCH(Annual!$A18,Qrtly!$A:$A,0),MATCH("3Q"&RIGHT(Annual!P$1,2),Qrtly!$A$3:$BH$3,0))+INDEX(Qrtly!$A:$BH,MATCH(Annual!$A18,Qrtly!$A:$A,0),MATCH("4Q"&RIGHT(Annual!P$1,2),Qrtly!$A$3:$BH$3,0)) -> 73635 | Q18: =INDEX(Qrtly!$A:$BH,MATCH(Annual!$A18,Qrtly!$A:$A,0),MATCH("1Q"&RIGHT(Annual!Q$1,2),Qrtly!$A$3:$BH$3,0))+INDEX(Qrtly!$A:$BH,MATCH(Annual!$A18,Qrtly!$A:$A,0),MATCH("2Q"&RIGHT(Annual!Q$1,2),Qrtly!$A$3:$BH$3,0))+INDEX(Qrtly!$A:$BH,MATCH(Annual!$A18,Qrtly!$A:$A,0),MATCH("3Q"&RIGHT(Annual!Q$1,2),Qrtly!$A$3:$BH$3,0))+INDEX(Qrtly!$A:$BH,MATCH(Annual!$A18,Qrtly!$A:$A,0),MATCH("4Q"&RIGHT(Annual!Q$1,2),Qrtly!$A$3:$BH$3,0)) -> 144141 | R18: =INDEX(Qrtly!$A:$BH,MATCH(Annual!$A18,Qrtly!$A:$A,0),MATCH("1Q"&RIGHT(Annual!R$1,2),Qrtly!$A$3:$BH$3,0))+INDEX(Qrtly!$A:$BH,MATCH(Annual!$A18,Qrtly!$A:$A,0),MATCH("2Q"&RIGHT(Annual!R$1,2),Qrtly!$A$3:$BH$3,0))+INDEX(Qrtly!$A:$BH,MATCH(Annual!$A18,Qrtly!$A:$A,0),MATCH("3Q"&RIGHT(Annual!R$1,2),Qrtly!$A$3:$BH$3,0))+INDEX(Qrtly!$A:$BH,MATCH(Annual!$A18,Qrtly!$A:$A,0),MATCH("4Q"&RIGHT(Annual!R$1,2),Qrtly!$A$3:$BH$3,0)) -> 181899 | S18: =INDEX(Qrtly!$A:$BH,MATCH(Annual!$A18,Qrtly!$A:$A,0),MATCH("1Q"&RIGHT(Annual!S$1,2),Qrtly!$A$3:$BH$3,0))+INDEX(Qrtly!$A:$BH,MATCH(Annual!$A18,Qrtly!$A:$A,0),MATCH("2Q"&RIGHT(Annual!S$1,2),Qrtly!$A$3:$BH$3,0))+INDEX(Qrtly!$A:$BH,MATCH(Annual!$A18,Qrtly!$A:$A,0),MATCH("3Q"&RIGHT(Annual!S$1,2),Qrtly!$A$3:$BH$3,0))+INDEX(Qrtly!$A:$BH,MATCH(Annual!$A18,Qrtly!$A:$A,0),MATCH("4Q"&RIGHT(Annual!S$1,2),Qrtly!$A$3:$BH$3,0)) -> 217156 | T18: =INDEX(Qrtly!$A:$BH,MATCH(Annual!$A18,Qrtly!$A:$A,0),MATCH("1Q"&RIGHT(Annual!T$1,2),Qrtly!$A$3:$BH$3,0))+INDEX(Qrtly!$A:$BH,MATCH(Annual!$A18,Qrtly!$A:$A,0),MATCH("2Q"&RIGHT(Annual!T$1,2),Qrtly!$A$3:$BH$3,0))+INDEX(Qrtly!$A:$BH,MATCH(Annual!$A18,Qrtly!$A:$A,0),MATCH("3Q"&RIGHT(Annual!T$1,2),Qrtly!$A$3:$BH$3,0))+INDEX(Qrtly!$A:$BH,MATCH(Annual!$A18,Qrtly!$A:$A,0),MATCH("4Q"&RIGHT(Annual!T$1,2),Qrtly!$A$3:$BH$3,0)) -> 228013 | U18: =INDEX(Qrtly!$A:$BH,MATCH(Annual!$A18,Qrtly!$A:$A,0),MATCH("1Q"&RIGHT(Annual!U$1,2),Qrtly!$A$3:$BH$3,0))+INDEX(Qrtly!$A:$BH,MATCH(Annual!$A18,Qrtly!$A:$A,0),MATCH("2Q"&RIGHT(Annual!U$1,2),Qrtly!$A$3:$BH$3,0))+INDEX(Qrtly!$A:$BH,MATCH(Annual!$A18,Qrtly!$A:$A,0),MATCH("3Q"&RIGHT(Annual!U$1,2),Qrtly!$A$3:$BH$3,0))+INDEX(Qrtly!$A:$BH,MATCH(Annual!$A18,Qrtly!$A:$A,0),MATCH("4Q"&RIGHT(Annual!U$1,2),Qrtly!$A$3:$BH$3,0)) -> 239415 | V18: =INDEX(Qrtly!$A:$BH,MATCH(Annual!$A18,Qrtly!$A:$A,0),MATCH("1Q"&RIGHT(Annual!V$1,2),Qrtly!$A$3:$BH$3,0))+INDEX(Qrtly!$A:$BH,MATCH(Annual!$A18,Qrtly!$A:$A,0),MATCH("2Q"&RIGHT(Annual!V$1,2),Qrtly!$A$3:$BH$3,0))+INDEX(Qrtly!$A:$BH,MATCH(Annual!$A18,Qrtly!$A:$A,0),MATCH("3Q"&RIGHT(Annual!V$1,2),Qrtly!$A$3:$BH$3,0))+INDEX(Qrtly!$A:$BH,MATCH(Annual!$A18,Qrtly!$A:$A,0),MATCH("4Q"&RIGHT(Annual!V$1,2),Qrtly!$A$3:$BH$3,0)) -> 251385 | ... Z18: =INDEX(Qrtly!$A:$BH,MATCH(Annual!$A18,Qrtly!$A:$A,0),MATCH("1Q"&RIGHT(Annual!Z$1,2),Qrtly!$A$3:$BH$3,0))+INDEX(Qrtly!$A:$BH,MATCH(Annual!$A18,Qrtly!$A:$A,0),MATCH("2Q"&RIGHT(Annual!Z$1,2),Qrtly!$A$3:$BH$3,0))+INDEX(Qrtly!$A:$BH,MATCH(Annual!$A18,Qrtly!$A:$A,0),MATCH("3Q"&RIGHT(Annual!Z$1,2),Qrtly!$A$3:$BH$3,0))+INDEX(Qrtly!$A:$BH,MATCH(Annual!$A18,Qrtly!$A:$A,0),MATCH("4Q"&RIGHT(Annual!Z$1,2),Qrtly!$A$3:$BH$3,0)) -> 305559 | AA18: -0.04 | AB18: -0.02 | AC18: 85633 | AD18: =IF(ISBLANK(AC18),"",INDEX($A18:$AA18,1,MATCH(AC$3,$A$3:$AA$3,0))-AC18) -> -11998 | AE18: 144141 | AF18: =IF(ISBLANK(AE18),"",INDEX($A18:$AA18,1,MATCH(AE$3,$A$3:$AA$3,0))-AE18) -> 0
A19: GP-Total Gross Profit | B19: Total Gross Profit | C19: USDk | F19: 370030 | G19: 576038 | H19: 839306 | I19: 1303700 | J19: 1889685 | K19: 2733409 | L19: 4419822 | M19: 5991892 | N19: 7504886 | O19: =INDEX(Qrtly!$A:$BH,MATCH(Annual!$A19,Qrtly!$A:$A,0),MATCH("1Q"&RIGHT(Annual!O$1,2),Qrtly!$A$3:$BH$3,0))+INDEX(Qrtly!$A:$BH,MATCH(Annual!$A19,Qrtly!$A:$A,0),MATCH("2Q"&RIGHT(Annual!O$1,2),Qrtly!$A$3:$BH$3,0))+INDEX(Qrtly!$A:$BH,MATCH(Annual!$A19,Qrtly!$A:$A,0),MATCH("3Q"&RIGHT(Annual!O$1,2),Qrtly!$A$3:$BH$3,0))+INDEX(Qrtly!$A:$BH,MATCH(Annual!$A19,Qrtly!$A:$A,0),MATCH("4Q"&RIGHT(Annual!O$1,2),Qrtly!$A$3:$BH$3,0)) -> 8889036 | P19: =INDEX(Qrtly!$A:$BH,MATCH(Annual!$A19,Qrtly!$A:$A,0),MATCH("1Q"&RIGHT(Annual!P$1,2),Qrtly!$A$3:$BH$3,0))+INDEX(Qrtly!$A:$BH,MATCH(Annual!$A19,Qrtly!$A:$A,0),MATCH("2Q"&RIGHT(Annual!P$1,2),Qrtly!$A$3:$BH$3,0))+INDEX(Qrtly!$A:$BH,MATCH(Annual!$A19,Qrtly!$A:$A,0),MATCH("3Q"&RIGHT(Annual!P$1,2),Qrtly!$A$3:$BH$3,0))+INDEX(Qrtly!$A:$BH,MATCH(Annual!$A19,Qrtly!$A:$A,0),MATCH("4Q"&RIGHT(Annual!P$1,2),Qrtly!$A$3:$BH$3,0)) -> 10321979 | Q19: =INDEX(Qrtly!$A:$BH,MATCH(Annual!$A19,Qrtly!$A:$A,0),MATCH("1Q"&RIGHT(Annual!Q$1,2),Qrtly!$A$3:$BH$3,0))+INDEX(Qrtly!$A:$BH,MATCH(Annual!$A19,Qrtly!$A:$A,0),MATCH("2Q"&RIGHT(Annual!Q$1,2),Qrtly!$A$3:$BH$3,0))+INDEX(Qrtly!$A:$BH,MATCH(Annual!$A19,Qrtly!$A:$A,0),MATCH("3Q"&RIGHT(Annual!Q$1,2),Qrtly!$A$3:$BH$3,0))+INDEX(Qrtly!$A:$BH,MATCH(Annual!$A19,Qrtly!$A:$A,0),MATCH("4Q"&RIGHT(Annual!Q$1,2),Qrtly!$A$3:$BH$3,0)) -> 12472487 | R19: =INDEX(Qrtly!$A:$BH,MATCH(Annual!$A19,Qrtly!$A:$A,0),MATCH("1Q"&RIGHT(Annual!R$1,2),Qrtly!$A$3:$BH$3,0))+INDEX(Qrtly!$A:$BH,MATCH(Annual!$A19,Qrtly!$A:$A,0),MATCH("2Q"&RIGHT(Annual!R$1,2),Qrtly!$A$3:$BH$3,0))+INDEX(Qrtly!$A:$BH,MATCH(Annual!$A19,Qrtly!$A:$A,0),MATCH("3Q"&RIGHT(Annual!R$1,2),Qrtly!$A$3:$BH$3,0))+INDEX(Qrtly!$A:$BH,MATCH(Annual!$A19,Qrtly!$A:$A,0),MATCH("4Q"&RIGHT(Annual!R$1,2),Qrtly!$A$3:$BH$3,0)) -> 14624993 | S19: =INDEX(Qrtly!$A:$BH,MATCH(Annual!$A19,Qrtly!$A:$A,0),MATCH("1Q"&RIGHT(Annual!S$1,2),Qrtly!$A$3:$BH$3,0))+INDEX(Qrtly!$A:$BH,MATCH(Annual!$A19,Qrtly!$A:$A,0),MATCH("2Q"&RIGHT(Annual!S$1,2),Qrtly!$A$3:$BH$3,0))+INDEX(Qrtly!$A:$BH,MATCH(Annual!$A19,Qrtly!$A:$A,0),MATCH("3Q"&RIGHT(Annual!S$1,2),Qrtly!$A$3:$BH$3,0))+INDEX(Qrtly!$A:$BH,MATCH(Annual!$A19,Qrtly!$A:$A,0),MATCH("4Q"&RIGHT(Annual!S$1,2),Qrtly!$A$3:$BH$3,0)) -> 16947368 | T19: =INDEX(Qrtly!$A:$BH,MATCH(Annual!$A19,Qrtly!$A:$A,0),MATCH("1Q"&RIGHT(Annual!T$1,2),Qrtly!$A$3:$BH$3,0))+INDEX(Qrtly!$A:$BH,MATCH(Annual!$A19,Qrtly!$A:$A,0),MATCH("2Q"&RIGHT(Annual!T$1,2),Qrtly!$A$3:$BH$3,0))+INDEX(Qrtly!$A:$BH,MATCH(Annual!$A19,Qrtly!$A:$A,0),MATCH("3Q"&RIGHT(Annual!T$1,2),Qrtly!$A$3:$BH$3,0))+INDEX(Qrtly!$A:$BH,MATCH(Annual!$A19,Qrtly!$A:$A,0),MATCH("4Q"&RIGHT(Annual!T$1,2),Qrtly!$A$3:$BH$3,0)) -> 19393059 | U19: =INDEX(Qrtly!$A:$BH,MATCH(Annual!$A19,Qrtly!$A:$A,0),MATCH("1Q"&RIGHT(Annual!U$1,2),Qrtly!$A$3:$BH$3,0))+INDEX(Qrtly!$A:$BH,MATCH(Annual!$A19,Qrtly!$A:$A,0),MATCH("2Q"&RIGHT(Annual!U$1,2),Qrtly!$A$3:$BH$3,0))+INDEX(Qrtly!$A:$BH,MATCH(Annual!$A19,Qrtly!$A:$A,0),MATCH("3Q"&RIGHT(Annual!U$1,2),Qrtly!$A$3:$BH$3,0))+INDEX(Qrtly!$A:$BH,MATCH(Annual!$A19,Qrtly!$A:$A,0),MATCH("4Q"&RIGHT(Annual!U$1,2),Qrtly!$A$3:$BH$3,0)) -> 22234851 | V19: =INDEX(Qrtly!$A:$BH,MATCH(Annual!$A19,Qrtly!$A:$A,0),MATCH("1Q"&RIGHT(Annual!V$1,2),Qrtly!$A$3:$BH$3,0))+INDEX(Qrtly!$A:$BH,MATCH(Annual!$A19,Qrtly!$A:$A,0),MATCH("2Q"&RIGHT(Annual!V$1,2),Qrtly!$A$3:$BH$3,0))+INDEX(Qrtly!$A:$BH,MATCH(Annual!$A19,Qrtly!$A:$A,0),MATCH("3Q"&RIGHT(Annual!V$1,2),Qrtly!$A$3:$BH$3,0))+INDEX(Qrtly!$A:$BH,MATCH(Annual!$A19,Qrtly!$A:$A,0),MATCH("4Q"&RIGHT(Annual!V$1,2),Qrtly!$A$3:$BH$3,0)) -> 25544723 | ... Z19: =INDEX(Qrtly!$A:$BH,MATCH(Annual!$A19,Qrtly!$A:$A,0),MATCH("1Q"&RIGHT(Annual!Z$1,2),Qrtly!$A$3:$BH$3,0))+INDEX(Qrtly!$A:$BH,MATCH(Annual!$A19,Qrtly!$A:$A,0),MATCH("2Q"&RIGHT(Annual!Z$1,2),Qrtly!$A$3:$BH$3,0))+INDEX(Qrtly!$A:$BH,MATCH(Annual!$A19,Qrtly!$A:$A,0),MATCH("3Q"&RIGHT(Annual!Z$1,2),Qrtly!$A$3:$BH$3,0))+INDEX(Qrtly!$A:$BH,MATCH(Annual!$A19,Qrtly!$A:$A,0),MATCH("4Q"&RIGHT(Annual!Z$1,2),Qrtly!$A$3:$BH$3,0)) -> 45480272 | AA19: 0.01 | AB19: 0.04 | AC19: 10220423 | AD19: =IF(ISBLANK(AC19),"",INDEX($A19:$AA19,1,MATCH(AC$3,$A$3:$AA$3,0))-AC19) -> 101555.38 | AE19: 12330717 | AF19: =IF(ISBLANK(AE19),"",INDEX($A19:$AA19,1,MATCH(AE$3,$A$3:$AA$3,0))-AE19) -> 141770.43
B20: Growth | C20: % YoY | I20: 0.553 | J20: 0.449 | K20: 0.446 | L20: 0.617 | M20: 0.356 | N20: 0.253 | O20: =O19/N19-1 -> 0.18443318 | P20: =P19/O19-1 -> 0.1612034 | Q20: =Q19/P19-1 -> 0.20834263 | R20: =R19/Q19-1 -> 0.17258031 | S20: =S19/R19-1 -> 0.158795 | T20: =T19/S19-1 -> 0.14431092 | U20: =U19/T19-1 -> 0.1465366 | V20: =V19/U19-1 -> 0.14885963 | ... Z20: =Z19/Y19-1 -> 0.15907227 | AC20: 0.14977861 | AD20: =IF(ISBLANK(AC20),"",INDEX($A20:$AA20,1,MATCH(AC$3,$A$3:$AA$3,0))-AC20) -> 0.011424791 | AE20: 0.20647805 | AF20: =IF(ISBLANK(AE20),"",INDEX($A20:$AA20,1,MATCH(AE$3,$A$3:$AA$3,0))-AE20) -> 0.0018645746
B21: Initial Guidance | C21: USDk | K21: 2457500 | M21: NR | N21: NR | O21: 8650000 | P21: 10220000 | AC21: 10220000 | AD21: =IF(ISBLANK(AC21),"",INDEX($A21:$AA21,1,MATCH(AC$3,$A$3:$AA$3,0))-AC21) -> 0 | AF21: =IF(ISBLANK(AE21),"",INDEX($A21:$AA21,1,MATCH(AE$3,$A$3:$AA$3,0))-AE21)
B22: Latest Guidance | P22: 10243000 | R22: 10243000 | AC22: 10170000 | AD22: =IF(ISBLANK(AC22),"",INDEX($A22:$AA22,1,MATCH(AC$3,$A$3:$AA$3,0))-AC22) -> 73000 | AF22: =IF(ISBLANK(AE22),"",INDEX($A22:$AA22,1,MATCH(AE$3,$A$3:$AA$3,0))-AE22)
B23: vs guidance | K23: 0.11 | O23: 0.03 | P23: 0 | R23: =R22/P22-1 -> 0 | AA23: 0.6 | AC23: 0 | AD23: =IF(ISBLANK(AC23),"",INDEX($A23:$AA23,1,MATCH(AC$3,$A$3:$AA$3,0))-AC23) -> 0 | AF23: =IF(ISBLANK(AE23),"",INDEX($A23:$AA23,1,MATCH(AE$3,$A$3:$AA$3,0))-AE23)
P24: 0.14 | AC24: 0.14 | AD24: =IF(ISBLANK(AC24),"",INDEX($A24:$AA24,1,MATCH(AC$3,$A$3:$AA$3,0))-AC24) -> 0 | AF24: =IF(ISBLANK(AE24),"",INDEX($A24:$AA24,1,MATCH(AE$3,$A$3:$AA$3,0))-AE24)
B25: Operating Expenses (Non- GAAP) | AD25: =IF(ISBLANK(AC25),"",INDEX($A25:$AA25,1,MATCH(AC$3,$A$3:$AA$3,0))-AC25) | AF25: =IF(ISBLANK(AE25),"",INDEX($A25:$AA25,1,MATCH(AE$3,$A$3:$AA$3,0))-AE25)
A26: Opex-Non-GAAP product development | B26: Non-GAAP product development | F26: 133553 | G26: 163943 | H26: 206623 | I26: 319845 | J26: 417018 | K26: 546019 | L26: 859594 | M26: 1311170 | N26: =INDEX(Qrtly!$A:$BH,MATCH(Annual!$A26,Qrtly!$A:$A,0),MATCH("1Q"&RIGHT(Annual!N$1,2),Qrtly!$A$3:$BH$3,0))+INDEX(Qrtly!$A:$BH,MATCH(Annual!$A26,Qrtly!$A:$A,0),MATCH("2Q"&RIGHT(Annual!N$1,2),Qrtly!$A$3:$BH$3,0))+INDEX(Qrtly!$A:$BH,MATCH(Annual!$A26,Qrtly!$A:$A,0),MATCH("3Q"&RIGHT(Annual!N$1,2),Qrtly!$A$3:$BH$3,0))+INDEX(Qrtly!$A:$BH,MATCH(Annual!$A26,Qrtly!$A:$A,0),MATCH("4Q"&RIGHT(Annual!N$1,2),Qrtly!$A$3:$BH$3,0)) -> 1668712 | O26: =INDEX(Qrtly!$A:$BH,MATCH(Annual!$A26,Qrtly!$A:$A,0),MATCH("1Q"&RIGHT(Annual!O$1,2),Qrtly!$A$3:$BH$3,0))+INDEX(Qrtly!$A:$BH,MATCH(Annual!$A26,Qrtly!$A:$A,0),MATCH("2Q"&RIGHT(Annual!O$1,2),Qrtly!$A$3:$BH$3,0))+INDEX(Qrtly!$A:$BH,MATCH(Annual!$A26,Qrtly!$A:$A,0),MATCH("3Q"&RIGHT(Annual!O$1,2),Qrtly!$A$3:$BH$3,0))+INDEX(Qrtly!$A:$BH,MATCH(Annual!$A26,Qrtly!$A:$A,0),MATCH("4Q"&RIGHT(Annual!O$1,2),Qrtly!$A$3:$BH$3,0)) -> 2849128 | P26: =INDEX(Qrtly!$A:$BH,MATCH(Annual!$A26,Qrtly!$A:$A,0),MATCH("1Q"&RIGHT(Annual!P$1,2),Qrtly!$A$3:$BH$3,0))+INDEX(Qrtly!$A:$BH,MATCH(Annual!$A26,Qrtly!$A:$A,0),MATCH("2Q"&RIGHT(Annual!P$1,2),Qrtly!$A$3:$BH$3,0))+INDEX(Qrtly!$A:$BH,MATCH(Annual!$A26,Qrtly!$A:$A,0),MATCH("3Q"&RIGHT(Annual!P$1,2),Qrtly!$A$3:$BH$3,0))+INDEX(Qrtly!$A:$BH,MATCH(Annual!$A26,Qrtly!$A:$A,0),MATCH("4Q"&RIGHT(Annual!P$1,2),Qrtly!$A$3:$BH$3,0)) -> 2883152.2 | Q26: =INDEX(Qrtly!$A:$BH,MATCH(Annual!$A26,Qrtly!$A:$A,0),MATCH("1Q"&RIGHT(Annual!Q$1,2),Qrtly!$A$3:$BH$3,0))+INDEX(Qrtly!$A:$BH,MATCH(Annual!$A26,Qrtly!$A:$A,0),MATCH("2Q"&RIGHT(Annual!Q$1,2),Qrtly!$A$3:$BH$3,0))+INDEX(Qrtly!$A:$BH,MATCH(Annual!$A26,Qrtly!$A:$A,0),MATCH("3Q"&RIGHT(Annual!Q$1,2),Qrtly!$A$3:$BH$3,0))+INDEX(Qrtly!$A:$BH,MATCH(Annual!$A26,Qrtly!$A:$A,0),MATCH("4Q"&RIGHT(Annual!Q$1,2),Qrtly!$A$3:$BH$3,0)) -> 2940815.3 | R26: =INDEX(Qrtly!$A:$BH,MATCH(Annual!$A26,Qrtly!$A:$A,0),MATCH("1Q"&RIGHT(Annual!R$1,2),Qrtly!$A$3:$BH$3,0))+INDEX(Qrtly!$A:$BH,MATCH(Annual!$A26,Qrtly!$A:$A,0),MATCH("2Q"&RIGHT(Annual!R$1,2),Qrtly!$A$3:$BH$3,0))+INDEX(Qrtly!$A:$BH,MATCH(Annual!$A26,Qrtly!$A:$A,0),MATCH("3Q"&RIGHT(Annual!R$1,2),Qrtly!$A$3:$BH$3,0))+INDEX(Qrtly!$A:$BH,MATCH(Annual!$A26,Qrtly!$A:$A,0),MATCH("4Q"&RIGHT(Annual!R$1,2),Qrtly!$A$3:$BH$3,0)) -> 3058447.9 | S26: =INDEX(Qrtly!$A:$BH,MATCH(Annual!$A26,Qrtly!$A:$A,0),MATCH("1Q"&RIGHT(Annual!S$1,2),Qrtly!$A$3:$BH$3,0))+INDEX(Qrtly!$A:$BH,MATCH(Annual!$A26,Qrtly!$A:$A,0),MATCH("2Q"&RIGHT(Annual!S$1,2),Qrtly!$A$3:$BH$3,0))+INDEX(Qrtly!$A:$BH,MATCH(Annual!$A26,Qrtly!$A:$A,0),MATCH("3Q"&RIGHT(Annual!S$1,2),Qrtly!$A$3:$BH$3,0))+INDEX(Qrtly!$A:$BH,MATCH(Annual!$A26,Qrtly!$A:$A,0),MATCH("4Q"&RIGHT(Annual!S$1,2),Qrtly!$A$3:$BH$3,0)) -> 3180785.8 | T26: =INDEX(Qrtly!$A:$BH,MATCH(Annual!$A26,Qrtly!$A:$A,0),MATCH("1Q"&RIGHT(Annual!T$1,2),Qrtly!$A$3:$BH$3,0))+INDEX(Qrtly!$A:$BH,MATCH(Annual!$A26,Qrtly!$A:$A,0),MATCH("2Q"&RIGHT(Annual!T$1,2),Qrtly!$A$3:$BH$3,0))+INDEX(Qrtly!$A:$BH,MATCH(Annual!$A26,Qrtly!$A:$A,0),MATCH("3Q"&RIGHT(Annual!T$1,2),Qrtly!$A$3:$BH$3,0))+INDEX(Qrtly!$A:$BH,MATCH(Annual!$A26,Qrtly!$A:$A,0),MATCH("4Q"&RIGHT(Annual!T$1,2),Qrtly!$A$3:$BH$3,0)) -> 3308017.2 | U26: =INDEX(Qrtly!$A:$BH,MATCH(Annual!$A26,Qrtly!$A:$A,0),MATCH("1Q"&RIGHT(Annual!U$1,2),Qrtly!$A$3:$BH$3,0))+INDEX(Qrtly!$A:$BH,MATCH(Annual!$A26,Qrtly!$A:$A,0),MATCH("2Q"&RIGHT(Annual!U$1,2),Qrtly!$A$3:$BH$3,0))+INDEX(Qrtly!$A:$BH,MATCH(Annual!$A26,Qrtly!$A:$A,0),MATCH("3Q"&RIGHT(Annual!U$1,2),Qrtly!$A$3:$BH$3,0))+INDEX(Qrtly!$A:$BH,MATCH(Annual!$A26,Qrtly!$A:$A,0),MATCH("4Q"&RIGHT(Annual!U$1,2),Qrtly!$A$3:$BH$3,0)) -> 3440337.9 | ... Z26: =INDEX(Qrtly!$A:$BH,MATCH(Annual!$A26,Qrtly!$A:$A,0),MATCH("1Q"&RIGHT(Annual!Z$1,2),Qrtly!$A$3:$BH$3,0))+INDEX(Qrtly!$A:$BH,MATCH(Annual!$A26,Qrtly!$A:$A,0),MATCH("2Q"&RIGHT(Annual!Z$1,2),Qrtly!$A$3:$BH$3,0))+INDEX(Qrtly!$A:$BH,MATCH(Annual!$A26,Qrtly!$A:$A,0),MATCH("3Q"&RIGHT(Annual!Z$1,2),Qrtly!$A$3:$BH$3,0))+INDEX(Qrtly!$A:$BH,MATCH(Annual!$A26,Qrtly!$A:$A,0),MATCH("4Q"&RIGHT(Annual!Z$1,2),Qrtly!$A$3:$BH$3,0)) -> 4185697.1 | AC26: 2897119.9 | AD26: =IF(ISBLANK(AC26),"",INDEX($A26:$AA26,1,MATCH(AC$3,$A$3:$AA$3,0))-AC26) -> -13967.66 | AE26: 2955062.3 | AF26: =IF(ISBLANK(AE26),"",INDEX($A26:$AA26,1,MATCH(AE$3,$A$3:$AA$3,0))-AE26) -> -14247.013
A27: Opex-Non-GAAP sales and marketing | B27: Non-GAAP sales and marketing | F27: 138195 | G27: 159651 | H27: 234029 | I27: 383708 | J27: 593439 | K27: 1068893 | L27: 1554977 | M27: 1946279 | N27: =INDEX(Qrtly!$A:$BH,MATCH(Annual!$A27,Qrtly!$A:$A,0),MATCH("1Q"&RIGHT(Annual!N$1,2),Qrtly!$A$3:$BH$3,0))+INDEX(Qrtly!$A:$BH,MATCH(Annual!$A27,Qrtly!$A:$A,0),MATCH("2Q"&RIGHT(Annual!N$1,2),Qrtly!$A$3:$BH$3,0))+INDEX(Qrtly!$A:$BH,MATCH(Annual!$A27,Qrtly!$A:$A,0),MATCH("3Q"&RIGHT(Annual!N$1,2),Qrtly!$A$3:$BH$3,0))+INDEX(Qrtly!$A:$BH,MATCH(Annual!$A27,Qrtly!$A:$A,0),MATCH("4Q"&RIGHT(Annual!N$1,2),Qrtly!$A$3:$BH$3,0)) -> 1879759 | O27: =INDEX(Qrtly!$A:$BH,MATCH(Annual!$A27,Qrtly!$A:$A,0),MATCH("1Q"&RIGHT(Annual!O$1,2),Qrtly!$A$3:$BH$3,0))+INDEX(Qrtly!$A:$BH,MATCH(Annual!$A27,Qrtly!$A:$A,0),MATCH("2Q"&RIGHT(Annual!O$1,2),Qrtly!$A$3:$BH$3,0))+INDEX(Qrtly!$A:$BH,MATCH(Annual!$A27,Qrtly!$A:$A,0),MATCH("3Q"&RIGHT(Annual!O$1,2),Qrtly!$A$3:$BH$3,0))+INDEX(Qrtly!$A:$BH,MATCH(Annual!$A27,Qrtly!$A:$A,0),MATCH("4Q"&RIGHT(Annual!O$1,2),Qrtly!$A$3:$BH$3,0)) -> 1983062 | P27: =INDEX(Qrtly!$A:$BH,MATCH(Annual!$A27,Qrtly!$A:$A,0),MATCH("1Q"&RIGHT(Annual!P$1,2),Qrtly!$A$3:$BH$3,0))+INDEX(Qrtly!$A:$BH,MATCH(Annual!$A27,Qrtly!$A:$A,0),MATCH("2Q"&RIGHT(Annual!P$1,2),Qrtly!$A$3:$BH$3,0))+INDEX(Qrtly!$A:$BH,MATCH(Annual!$A27,Qrtly!$A:$A,0),MATCH("3Q"&RIGHT(Annual!P$1,2),Qrtly!$A$3:$BH$3,0))+INDEX(Qrtly!$A:$BH,MATCH(Annual!$A27,Qrtly!$A:$A,0),MATCH("4Q"&RIGHT(Annual!P$1,2),Qrtly!$A$3:$BH$3,0)) -> 2250471.5 | Q27: =INDEX(Qrtly!$A:$BH,MATCH(Annual!$A27,Qrtly!$A:$A,0),MATCH("1Q"&RIGHT(Annual!Q$1,2),Qrtly!$A$3:$BH$3,0))+INDEX(Qrtly!$A:$BH,MATCH(Annual!$A27,Qrtly!$A:$A,0),MATCH("2Q"&RIGHT(Annual!Q$1,2),Qrtly!$A$3:$BH$3,0))+INDEX(Qrtly!$A:$BH,MATCH(Annual!$A27,Qrtly!$A:$A,0),MATCH("3Q"&RIGHT(Annual!Q$1,2),Qrtly!$A$3:$BH$3,0))+INDEX(Qrtly!$A:$BH,MATCH(Annual!$A27,Qrtly!$A:$A,0),MATCH("4Q"&RIGHT(Annual!Q$1,2),Qrtly!$A$3:$BH$3,0)) -> 2602673.9 | R27: =INDEX(Qrtly!$A:$BH,MATCH(Annual!$A27,Qrtly!$A:$A,0),MATCH("1Q"&RIGHT(Annual!R$1,2),Qrtly!$A$3:$BH$3,0))+INDEX(Qrtly!$A:$BH,MATCH(Annual!$A27,Qrtly!$A:$A,0),MATCH("2Q"&RIGHT(Annual!R$1,2),Qrtly!$A$3:$BH$3,0))+INDEX(Qrtly!$A:$BH,MATCH(Annual!$A27,Qrtly!$A:$A,0),MATCH("3Q"&RIGHT(Annual!R$1,2),Qrtly!$A$3:$BH$3,0))+INDEX(Qrtly!$A:$BH,MATCH(Annual!$A27,Qrtly!$A:$A,0),MATCH("4Q"&RIGHT(Annual!R$1,2),Qrtly!$A$3:$BH$3,0)) -> 2957089.4 | S27: =INDEX(Qrtly!$A:$BH,MATCH(Annual!$A27,Qrtly!$A:$A,0),MATCH("1Q"&RIGHT(Annual!S$1,2),Qrtly!$A$3:$BH$3,0))+INDEX(Qrtly!$A:$BH,MATCH(Annual!$A27,Qrtly!$A:$A,0),MATCH("2Q"&RIGHT(Annual!S$1,2),Qrtly!$A$3:$BH$3,0))+INDEX(Qrtly!$A:$BH,MATCH(Annual!$A27,Qrtly!$A:$A,0),MATCH("3Q"&RIGHT(Annual!S$1,2),Qrtly!$A$3:$BH$3,0))+INDEX(Qrtly!$A:$BH,MATCH(Annual!$A27,Qrtly!$A:$A,0),MATCH("4Q"&RIGHT(Annual!S$1,2),Qrtly!$A$3:$BH$3,0)) -> 3359755 | T27: =INDEX(Qrtly!$A:$BH,MATCH(Annual!$A27,Qrtly!$A:$A,0),MATCH("1Q"&RIGHT(Annual!T$1,2),Qrtly!$A$3:$BH$3,0))+INDEX(Qrtly!$A:$BH,MATCH(Annual!$A27,Qrtly!$A:$A,0),MATCH("2Q"&RIGHT(Annual!T$1,2),Qrtly!$A$3:$BH$3,0))+INDEX(Qrtly!$A:$BH,MATCH(Annual!$A27,Qrtly!$A:$A,0),MATCH("3Q"&RIGHT(Annual!T$1,2),Qrtly!$A$3:$BH$3,0))+INDEX(Qrtly!$A:$BH,MATCH(Annual!$A27,Qrtly!$A:$A,0),MATCH("4Q"&RIGHT(Annual!T$1,2),Qrtly!$A$3:$BH$3,0)) -> 3789370.4 | U27: =INDEX(Qrtly!$A:$BH,MATCH(Annual!$A27,Qrtly!$A:$A,0),MATCH("1Q"&RIGHT(Annual!U$1,2),Qrtly!$A$3:$BH$3,0))+INDEX(Qrtly!$A:$BH,MATCH(Annual!$A27,Qrtly!$A:$A,0),MATCH("2Q"&RIGHT(Annual!U$1,2),Qrtly!$A$3:$BH$3,0))+INDEX(Qrtly!$A:$BH,MATCH(Annual!$A27,Qrtly!$A:$A,0),MATCH("3Q"&RIGHT(Annual!U$1,2),Qrtly!$A$3:$BH$3,0))+INDEX(Qrtly!$A:$BH,MATCH(Annual!$A27,Qrtly!$A:$A,0),MATCH("4Q"&RIGHT(Annual!U$1,2),Qrtly!$A$3:$BH$3,0)) -> 4277366 | ... Z27: =INDEX(Qrtly!$A:$BH,MATCH(Annual!$A27,Qrtly!$A:$A,0),MATCH("1Q"&RIGHT(Annual!Z$1,2),Qrtly!$A$3:$BH$3,0))+INDEX(Qrtly!$A:$BH,MATCH(Annual!$A27,Qrtly!$A:$A,0),MATCH("2Q"&RIGHT(Annual!Z$1,2),Qrtly!$A$3:$BH$3,0))+INDEX(Qrtly!$A:$BH,MATCH(Annual!$A27,Qrtly!$A:$A,0),MATCH("3Q"&RIGHT(Annual!Z$1,2),Qrtly!$A$3:$BH$3,0))+INDEX(Qrtly!$A:$BH,MATCH(Annual!$A27,Qrtly!$A:$A,0),MATCH("4Q"&RIGHT(Annual!Z$1,2),Qrtly!$A$3:$BH$3,0)) -> 7934586.1 | AC27: 2253781.2 | AD27: =IF(ISBLANK(AC27),"",INDEX($A27:$AA27,1,MATCH(AC$3,$A$3:$AA$3,0))-AC27) -> -3309.7814 | AE27: 2679045.8 | AF27: =IF(ISBLANK(AE27),"",INDEX($A27:$AA27,1,MATCH(AE$3,$A$3:$AA$3,0))-AE27) -> -76371.856
