Workbook

Sheet Value
B2: DCF Valuation
B4: Current Share Price (NZD) | C4: 7.91
B5: Shares Outstanding (#m) | C5: =Annual!G79 -> 146.53
B6: Market Cap (NZDm) | C6: =C4*C5 -> 1159.0523
B7: Net Debt (NZDm) | C7: =Annual!F131 -> 232.3
B8: Market EV (NZDm) | C8: =C6+C7 -> 1391.3523
B9: Valuation Date | C9: 46022
B11: WACC Inputs
B12: Risk-free Rate | C12: 0.04
B13: Equity Risk Premium | C13: 0.06
B14: Beta | C14: 1
B15: Cost of Equity | C15: =C12+C13*C14 -> 0.1
B16: Pre-tax Cost of Debt | C16: 0.06
B17: Tax Rate | C17: 0.28
B18: After-tax Cost of Debt | C18: =C16*(1-C17) -> 0.0432
B19: Debt Weight (D/(D+E)) | C19: 0.3
B20: WACC | C20: =C15*(1-C19)+C18*C19 -> 0.08296
B21: Terminal Growth Rate | C21: 0.025
B22: Stub Period | C22: =(Annual!G4-C9)/365.25 -> 0.49555099
B24: FCF Projection | D24: FY26E | E24: FY27E | F24: FY28E | G24: FY29E | H24: FY30E | I24: FY31E | J24: FY32E | K24: FY33E | L24: FY34E | M24: FY35E
B25: EBITDA | C25: NZDm | D25: =Annual!G38 -> 134.80708 | E25: =Annual!H38 -> 157.62309 | F25: =Annual!I38 -> 172.77767 | G25: =Annual!J38 -> 188.93631 | H25: =Annual!K38 -> 206.15894 | I25: =Annual!L38 -> 224.50898 | J25: =Annual!M38 -> 244.05344 | K25: =Annual!N38 -> 264.86321 | ... M25: =Annual!P38 -> 310.58269
B26: less D&A | C26: NZDm | D26: =Annual!G50 -> -52.837036 | E26: =Annual!H50 -> -54.612869 | F26: =Annual!I50 -> -55.881845 | G26: =Annual!J50 -> -57.216272 | H26: =Annual!K50 -> -58.620468 | I26: =Annual!L50 -> -60.098911 | J26: =Annual!M50 -> -61.656251 | K26: =Annual!N50 -> -63.297335 | ... M26: =Annual!P50 -> -66.8512
B27: EBIT | C27: NZDm | D27: =Annual!G54 -> 81.970047 | E27: =Annual!H54 -> 103.01022 | F27: =Annual!I54 -> 116.89583 | G27: =Annual!J54 -> 131.72004 | H27: =Annual!K54 -> 147.53848 | I27: =Annual!L54 -> 164.41007 | J27: =Annual!M54 -> 182.39719 | K27: =Annual!N54 -> 201.56588 | ... M27: =Annual!P54 -> 243.73149
B28: less Tax on EBIT | C28: NZDm | D28: =-D27*$C$17 -> -22.951613 | E28: =-E27*$C$17 -> -28.842861 | F28: =-F27*$C$17 -> -32.730832 | G28: =-G27*$C$17 -> -36.88161 | H28: =-H27*$C$17 -> -41.310773 | I28: =-I27*$C$17 -> -46.034819 | J28: =-J27*$C$17 -> -51.071213 | K28: =-K27*$C$17 -> -56.438446 | ... M28: =-M27*$C$17 -> -68.244818
B29: NOPAT | C29: NZDm | D29: =D27+D28 -> 59.018434 | E29: =E27+E28 -> 74.167356 | F29: =F27+F28 -> 84.164997 | G29: =G27+G28 -> 94.838426 | H29: =H27+H28 -> 106.2277 | I29: =I27+I28 -> 118.37525 | J29: =J27+J28 -> 131.32598 | K29: =K27+K28 -> 145.12743 | ... M29: =M27+M28 -> 175.48667
B30: plus D&A | C30: NZDm | D30: =-D26 -> 52.837036 | E30: =-E26 -> 54.612869 | F30: =-F26 -> 55.881845 | G30: =-G26 -> 57.216272 | H30: =-H26 -> 58.620468 | I30: =-I26 -> 60.098911 | J30: =-J26 -> 61.656251 | K30: =-K26 -> 63.297335 | ... M30: =-M26 -> 66.8512
B31: less Capex | C31: NZDm | D31: =Annual!G160+Annual!G162 -> -24.161453 | E31: =Annual!H160+Annual!H162 -> -26.252216 | F31: =Annual!I160+Annual!I162 -> -27.715777 | G31: =Annual!J160+Annual!J162 -> -29.260932 | H31: =Annual!K160+Annual!K162 -> -30.892228 | I31: =Annual!L160+Annual!L162 -> -32.61447 | J31: =Annual!M160+Annual!M162 -> -34.432727 | K31: =Annual!N160+Annual!N162 -> -36.352351 | ... M31: =Annual!P160+Annual!P162 -> -40.518624
B32: less WC Change | C32: NZDm | D32: =Annual!G149 -> -43.177045 | E32: =Annual!H149 -> -31.54794 | F32: =Annual!I149 -> -22.083968 | G32: =Annual!J149 -> -23.315149 | H32: =Annual!K149 -> -24.614969 | I32: =Annual!L149 -> -25.987253 | J32: =Annual!M149 -> -27.436043 | K32: =Annual!N149 -> -28.965602 | ... M32: =Annual!P149 -> -32.285294
B33: FCFF | C33: NZDm | D33: =D29+D30+D31+D32 -> 44.516971 | E33: =E29+E30+E31+E32 -> 70.980068 | F33: =F29+F30+F31+F32 -> 90.247097 | G33: =G29+G30+G31+G32 -> 99.478618 | H33: =H29+H30+H31+H32 -> 109.34097 | I33: =I29+I30+I31+I32 -> 119.87244 | J33: =J29+J30+J31+J32 -> 131.11346 | K33: =K29+K30+K31+K32 -> 143.10681 | ... M33: =M29+M30+M31+M32 -> 169.53396
B34: Normalised FCFF (capex=D&A) | C34: NZDm | M34: =M29+M32 -> 143.20138
B35: Terminal Value | M35: =M34*(1+$C$21)/($C$20-$C$21) -> 2532.4606
B37: Discount Factor | D37: =1/(1+$C$20)^($C$22+0) -> 0.9612753 | E37: =1/(1+$C$20)^($C$22+1) -> 0.88763694 | F37: =1/(1+$C$20)^($C$22+2) -> 0.81963963 | G37: =1/(1+$C$20)^($C$22+3) -> 0.75685125 | H37: =1/(1+$C$20)^($C$22+4) -> 0.69887277 | I37: =1/(1+$C$20)^($C$22+5) -> 0.64533572 | J37: =1/(1+$C$20)^($C$22+6) -> 0.59589987 | K37: =1/(1+$C$20)^($C$22+7) -> 0.55025104 | L37: =1/(1+$C$20)^($C$22+8) -> 0.50809914 | M37: =1/(1+$C$20)^($C$22+9) -> 0.46917627
B38: PV of FCFF | D38: =D33*D37 -> 42.793065 | E38: =E33*E37 -> 63.004531 | F38: =F33*F37 -> 73.970098 | G38: =G33*G37 -> 75.290517 | H38: =H33*H37 -> 76.415429 | I38: =I33*I37 -> 77.357964 | J38: =J33*J37 -> 78.130492 | K38: =K33*K37 -> 78.744673 | ... M38: =M33*M37 -> 79.54131
B39: PV of Terminal Value | M39: =M35*M37 -> 1188.1704
B41: Sum of PV of FCFs | C41: =SUM(D38:M38) -> 724.45957
B42: PV of Terminal Value | C42: =M39 -> 1188.1704
B43: Enterprise Value | C43: =C41+C42 -> 1912.63
B45: less Net Debt | C45: =-C7 -> -232.3
B46: less Lease Liabilities | C46: =-Annual!F127 -> -295.3
B47: Equity Value | C47: =C43+C45+C46 -> 1385.03
...

Sheet Annual
D1: 2023 | E1: 2024 | F1: 2025 | G1: 2026 | H1: 2027 | I1: 2028 | J1: 2029 | K1: 2030 | L1: 2031 | M1: 2032 | N1: 2033 | O1: 2034 | P1: 2035
B2: VSL Model Summary | D2: Actual ----------> | G2: Forecast ----->
B3: Vulcan Steel (VSL.NZ) | C3: Units | D3: FY23A | E3: FY24A | F3: FY25A | G3: FY26E | H3: FY27E | I3: FY28E | J3: FY29E | K3: FY30E | L3: FY31E | M3: FY32E | N3: FY33E | O3: FY34E | P3: FY35E
D4: 45107 | E4: 45473 | F4: 45838 | G4: 46203 | H4: 46568 | I4: 46934 | J4: 47299 | K4: 47664 | L4: 48029 | M4: 48395 | N4: 48760 | O4: 49125 | P4: 49490
B5: P&L
B6: Revenue
A7: Rev-Steel Revenue | B7: Steel Revenue | C7: NZDm | D7: 596.3 | E7: 471.3 | F7: 409.7 | G7: =INDEX('HY & Segments'!$A:$AG,MATCH($A7,'HY & Segments'!$A:$A,0),MATCH("1H"&RIGHT(G$1,2),'HY & Segments'!$3:$3,0))+INDEX('HY & Segments'!$A:$AG,MATCH($A7,'HY & Segments'!$A:$A,0),MATCH("2H"&RIGHT(G$1,2),'HY & Segments'!$3:$3,0)) -> 533.03528 | H7: =INDEX('HY & Segments'!$A:$AG,MATCH($A7,'HY & Segments'!$A:$A,0),MATCH("1H"&RIGHT(H$1,2),'HY & Segments'!$3:$3,0))+INDEX('HY & Segments'!$A:$AG,MATCH($A7,'HY & Segments'!$A:$A,0),MATCH("2H"&RIGHT(H$1,2),'HY & Segments'!$3:$3,0)) -> 595.85812 | I7: =INDEX('HY & Segments'!$A:$AG,MATCH($A7,'HY & Segments'!$A:$A,0),MATCH("1H"&RIGHT(I$1,2),'HY & Segments'!$3:$3,0))+INDEX('HY & Segments'!$A:$AG,MATCH($A7,'HY & Segments'!$A:$A,0),MATCH("2H"&RIGHT(I$1,2),'HY & Segments'!$3:$3,0)) -> 629.07721 | J7: =INDEX('HY & Segments'!$A:$AG,MATCH($A7,'HY & Segments'!$A:$A,0),MATCH("1H"&RIGHT(J$1,2),'HY & Segments'!$3:$3,0))+INDEX('HY & Segments'!$A:$AG,MATCH($A7,'HY & Segments'!$A:$A,0),MATCH("2H"&RIGHT(J$1,2),'HY & Segments'!$3:$3,0)) -> 664.14826 | K7: =INDEX('HY & Segments'!$A:$AG,MATCH($A7,'HY & Segments'!$A:$A,0),MATCH("1H"&RIGHT(K$1,2),'HY & Segments'!$3:$3,0))+INDEX('HY & Segments'!$A:$AG,MATCH($A7,'HY & Segments'!$A:$A,0),MATCH("2H"&RIGHT(K$1,2),'HY & Segments'!$3:$3,0)) -> 701.17453 | L7: =INDEX('HY & Segments'!$A:$AG,MATCH($A7,'HY & Segments'!$A:$A,0),MATCH("1H"&RIGHT(L$1,2),'HY & Segments'!$3:$3,0))+INDEX('HY & Segments'!$A:$AG,MATCH($A7,'HY & Segments'!$A:$A,0),MATCH("2H"&RIGHT(L$1,2),'HY & Segments'!$3:$3,0)) -> 740.26501 | M7: =INDEX('HY & Segments'!$A:$AG,MATCH($A7,'HY & Segments'!$A:$A,0),MATCH("1H"&RIGHT(M$1,2),'HY & Segments'!$3:$3,0))+INDEX('HY & Segments'!$A:$AG,MATCH($A7,'HY & Segments'!$A:$A,0),MATCH("2H"&RIGHT(M$1,2),'HY & Segments'!$3:$3,0)) -> 781.53478 | N7: =INDEX('HY & Segments'!$A:$AG,MATCH($A7,'HY & Segments'!$A:$A,0),MATCH("1H"&RIGHT(N$1,2),'HY & Segments'!$3:$3,0))+INDEX('HY & Segments'!$A:$AG,MATCH($A7,'HY & Segments'!$A:$A,0),MATCH("2H"&RIGHT(N$1,2),'HY & Segments'!$3:$3,0)) -> 825.10535 | ... P7: =INDEX('HY & Segments'!$A:$AG,MATCH($A7,'HY & Segments'!$A:$A,0),MATCH("1H"&RIGHT(P$1,2),'HY & Segments'!$3:$3,0))+INDEX('HY & Segments'!$A:$AG,MATCH($A7,'HY & Segments'!$A:$A,0),MATCH("2H"&RIGHT(P$1,2),'HY & Segments'!$3:$3,0)) -> 919.66907
A8: Rev-Metals Revenue | B8: Metals Revenue | C8: NZDm | D8: 648.6 | E8: 593 | F8: 538.4 | G8: =INDEX('HY & Segments'!$A:$AG,MATCH($A8,'HY & Segments'!$A:$A,0),MATCH("1H"&RIGHT(G$1,2),'HY & Segments'!$3:$3,0))+INDEX('HY & Segments'!$A:$AG,MATCH($A8,'HY & Segments'!$A:$A,0),MATCH("2H"&RIGHT(G$1,2),'HY & Segments'!$3:$3,0)) -> 542.43297 | H8: =INDEX('HY & Segments'!$A:$AG,MATCH($A8,'HY & Segments'!$A:$A,0),MATCH("1H"&RIGHT(H$1,2),'HY & Segments'!$3:$3,0))+INDEX('HY & Segments'!$A:$AG,MATCH($A8,'HY & Segments'!$A:$A,0),MATCH("2H"&RIGHT(H$1,2),'HY & Segments'!$3:$3,0)) -> 572.67361 | I8: =INDEX('HY & Segments'!$A:$AG,MATCH($A8,'HY & Segments'!$A:$A,0),MATCH("1H"&RIGHT(I$1,2),'HY & Segments'!$3:$3,0))+INDEX('HY & Segments'!$A:$AG,MATCH($A8,'HY & Segments'!$A:$A,0),MATCH("2H"&RIGHT(I$1,2),'HY & Segments'!$3:$3,0)) -> 604.60017 | J8: =INDEX('HY & Segments'!$A:$AG,MATCH($A8,'HY & Segments'!$A:$A,0),MATCH("1H"&RIGHT(J$1,2),'HY & Segments'!$3:$3,0))+INDEX('HY & Segments'!$A:$AG,MATCH($A8,'HY & Segments'!$A:$A,0),MATCH("2H"&RIGHT(J$1,2),'HY & Segments'!$3:$3,0)) -> 638.30663 | K8: =INDEX('HY & Segments'!$A:$AG,MATCH($A8,'HY & Segments'!$A:$A,0),MATCH("1H"&RIGHT(K$1,2),'HY & Segments'!$3:$3,0))+INDEX('HY & Segments'!$A:$AG,MATCH($A8,'HY & Segments'!$A:$A,0),MATCH("2H"&RIGHT(K$1,2),'HY & Segments'!$3:$3,0)) -> 673.89222 | L8: =INDEX('HY & Segments'!$A:$AG,MATCH($A8,'HY & Segments'!$A:$A,0),MATCH("1H"&RIGHT(L$1,2),'HY & Segments'!$3:$3,0))+INDEX('HY & Segments'!$A:$AG,MATCH($A8,'HY & Segments'!$A:$A,0),MATCH("2H"&RIGHT(L$1,2),'HY & Segments'!$3:$3,0)) -> 711.46171 | M8: =INDEX('HY & Segments'!$A:$AG,MATCH($A8,'HY & Segments'!$A:$A,0),MATCH("1H"&RIGHT(M$1,2),'HY & Segments'!$3:$3,0))+INDEX('HY & Segments'!$A:$AG,MATCH($A8,'HY & Segments'!$A:$A,0),MATCH("2H"&RIGHT(M$1,2),'HY & Segments'!$3:$3,0)) -> 751.1257 | N8: =INDEX('HY & Segments'!$A:$AG,MATCH($A8,'HY & Segments'!$A:$A,0),MATCH("1H"&RIGHT(N$1,2),'HY & Segments'!$3:$3,0))+INDEX('HY & Segments'!$A:$AG,MATCH($A8,'HY & Segments'!$A:$A,0),MATCH("2H"&RIGHT(N$1,2),'HY & Segments'!$3:$3,0)) -> 793.00096 | ... P8: =INDEX('HY & Segments'!$A:$AG,MATCH($A8,'HY & Segments'!$A:$A,0),MATCH("1H"&RIGHT(P$1,2),'HY & Segments'!$3:$3,0))+INDEX('HY & Segments'!$A:$AG,MATCH($A8,'HY & Segments'!$A:$A,0),MATCH("2H"&RIGHT(P$1,2),'HY & Segments'!$3:$3,0)) -> 883.88526
A9: Rev-Total Revenue | B9: Total Revenue | C9: NZDm | D9: =D7+D8 -> 1244.9 | E9: =E7+E8 -> 1064.3 | F9: =F7+F8 -> 948.1 | G9: =G7+G8 -> 1075.4683 | H9: =H7+H8 -> 1168.5317 | I9: =I7+I8 -> 1233.6774 | J9: =J7+J8 -> 1302.4549 | K9: =K7+K8 -> 1375.0668 | ... P9: =P7+P8 -> 1803.5543
B10: Revenue Growth | C10: % YoY | E10: =IF(D9=0,"",E9/D9-1) -> -0.14507189 | F10: =IF(E9=0,"",F9/E9-1) -> -0.10917974 | G10: =IF(F9=0,"",G9/F9-1) -> 0.13434053 | H10: =IF(G9=0,"",H9/G9-1) -> 0.086532986 | I10: =IF(H9=0,"",I9/H9-1) -> 0.05575 | J10: =IF(I9=0,"",J9/I9-1) -> 0.05575 | K10: =IF(J9=0,"",K9/J9-1) -> 0.05575 | L10: =IF(K9=0,"",L9/K9-1) -> 0.05575 | ... P10: =IF(O9=0,"",P9/O9-1) -> 0.05575
B12: COGS
A13: COGS-Steel COGS | B13: Steel COGS | C13: NZDm | D13: -410.2544 | E13: -327.6 | F13: -290.5 | G13: =INDEX('HY & Segments'!$A:$AG,MATCH($A13,'HY & Segments'!$A:$A,0),MATCH("1H"&RIGHT(G$1,2),'HY & Segments'!$3:$3,0))+INDEX('HY & Segments'!$A:$AG,MATCH($A13,'HY & Segments'!$A:$A,0),MATCH("2H"&RIGHT(G$1,2),'HY & Segments'!$3:$3,0)) -> -374.71591 | H13: =INDEX('HY & Segments'!$A:$AG,MATCH($A13,'HY & Segments'!$A:$A,0),MATCH("1H"&RIGHT(H$1,2),'HY & Segments'!$3:$3,0))+INDEX('HY & Segments'!$A:$AG,MATCH($A13,'HY & Segments'!$A:$A,0),MATCH("2H"&RIGHT(H$1,2),'HY & Segments'!$3:$3,0)) -> -418.81371 | I13: =INDEX('HY & Segments'!$A:$AG,MATCH($A13,'HY & Segments'!$A:$A,0),MATCH("1H"&RIGHT(I$1,2),'HY & Segments'!$3:$3,0))+INDEX('HY & Segments'!$A:$AG,MATCH($A13,'HY & Segments'!$A:$A,0),MATCH("2H"&RIGHT(I$1,2),'HY & Segments'!$3:$3,0)) -> -442.16257 | J13: =INDEX('HY & Segments'!$A:$AG,MATCH($A13,'HY & Segments'!$A:$A,0),MATCH("1H"&RIGHT(J$1,2),'HY & Segments'!$3:$3,0))+INDEX('HY & Segments'!$A:$AG,MATCH($A13,'HY & Segments'!$A:$A,0),MATCH("2H"&RIGHT(J$1,2),'HY & Segments'!$3:$3,0)) -> -466.81314 | K13: =INDEX('HY & Segments'!$A:$AG,MATCH($A13,'HY & Segments'!$A:$A,0),MATCH("1H"&RIGHT(K$1,2),'HY & Segments'!$3:$3,0))+INDEX('HY & Segments'!$A:$AG,MATCH($A13,'HY & Segments'!$A:$A,0),MATCH("2H"&RIGHT(K$1,2),'HY & Segments'!$3:$3,0)) -> -492.83797 | L13: =INDEX('HY & Segments'!$A:$AG,MATCH($A13,'HY & Segments'!$A:$A,0),MATCH("1H"&RIGHT(L$1,2),'HY & Segments'!$3:$3,0))+INDEX('HY & Segments'!$A:$AG,MATCH($A13,'HY & Segments'!$A:$A,0),MATCH("2H"&RIGHT(L$1,2),'HY & Segments'!$3:$3,0)) -> -520.31369 | M13: =INDEX('HY & Segments'!$A:$AG,MATCH($A13,'HY & Segments'!$A:$A,0),MATCH("1H"&RIGHT(M$1,2),'HY & Segments'!$3:$3,0))+INDEX('HY & Segments'!$A:$AG,MATCH($A13,'HY & Segments'!$A:$A,0),MATCH("2H"&RIGHT(M$1,2),'HY & Segments'!$3:$3,0)) -> -549.32117 | N13: =INDEX('HY & Segments'!$A:$AG,MATCH($A13,'HY & Segments'!$A:$A,0),MATCH("1H"&RIGHT(N$1,2),'HY & Segments'!$3:$3,0))+INDEX('HY & Segments'!$A:$AG,MATCH($A13,'HY & Segments'!$A:$A,0),MATCH("2H"&RIGHT(N$1,2),'HY & Segments'!$3:$3,0)) -> -579.94583 | ... P13: =INDEX('HY & Segments'!$A:$AG,MATCH($A13,'HY & Segments'!$A:$A,0),MATCH("1H"&RIGHT(P$1,2),'HY & Segments'!$3:$3,0))+INDEX('HY & Segments'!$A:$AG,MATCH($A13,'HY & Segments'!$A:$A,0),MATCH("2H"&RIGHT(P$1,2),'HY & Segments'!$3:$3,0)) -> -646.4123
A14: COGS-Metals COGS | B14: Metals COGS | C14: NZDm | D14: -391.1058 | E14: -375.4 | F14: -332.7 | G14: =INDEX('HY & Segments'!$A:$AG,MATCH($A14,'HY & Segments'!$A:$A,0),MATCH("1H"&RIGHT(G$1,2),'HY & Segments'!$3:$3,0))+INDEX('HY & Segments'!$A:$AG,MATCH($A14,'HY & Segments'!$A:$A,0),MATCH("2H"&RIGHT(G$1,2),'HY & Segments'!$3:$3,0)) -> -341.93503 | H14: =INDEX('HY & Segments'!$A:$AG,MATCH($A14,'HY & Segments'!$A:$A,0),MATCH("1H"&RIGHT(H$1,2),'HY & Segments'!$3:$3,0))+INDEX('HY & Segments'!$A:$AG,MATCH($A14,'HY & Segments'!$A:$A,0),MATCH("2H"&RIGHT(H$1,2),'HY & Segments'!$3:$3,0)) -> -360.99791 | I14: =INDEX('HY & Segments'!$A:$AG,MATCH($A14,'HY & Segments'!$A:$A,0),MATCH("1H"&RIGHT(I$1,2),'HY & Segments'!$3:$3,0))+INDEX('HY & Segments'!$A:$AG,MATCH($A14,'HY & Segments'!$A:$A,0),MATCH("2H"&RIGHT(I$1,2),'HY & Segments'!$3:$3,0)) -> -381.12354 | J14: =INDEX('HY & Segments'!$A:$AG,MATCH($A14,'HY & Segments'!$A:$A,0),MATCH("1H"&RIGHT(J$1,2),'HY & Segments'!$3:$3,0))+INDEX('HY & Segments'!$A:$AG,MATCH($A14,'HY & Segments'!$A:$A,0),MATCH("2H"&RIGHT(J$1,2),'HY & Segments'!$3:$3,0)) -> -402.37118 | K14: =INDEX('HY & Segments'!$A:$AG,MATCH($A14,'HY & Segments'!$A:$A,0),MATCH("1H"&RIGHT(K$1,2),'HY & Segments'!$3:$3,0))+INDEX('HY & Segments'!$A:$AG,MATCH($A14,'HY & Segments'!$A:$A,0),MATCH("2H"&RIGHT(K$1,2),'HY & Segments'!$3:$3,0)) -> -424.80337 | L14: =INDEX('HY & Segments'!$A:$AG,MATCH($A14,'HY & Segments'!$A:$A,0),MATCH("1H"&RIGHT(L$1,2),'HY & Segments'!$3:$3,0))+INDEX('HY & Segments'!$A:$AG,MATCH($A14,'HY & Segments'!$A:$A,0),MATCH("2H"&RIGHT(L$1,2),'HY & Segments'!$3:$3,0)) -> -448.48616 | M14: =INDEX('HY & Segments'!$A:$AG,MATCH($A14,'HY & Segments'!$A:$A,0),MATCH("1H"&RIGHT(M$1,2),'HY & Segments'!$3:$3,0))+INDEX('HY & Segments'!$A:$AG,MATCH($A14,'HY & Segments'!$A:$A,0),MATCH("2H"&RIGHT(M$1,2),'HY & Segments'!$3:$3,0)) -> -473.48926 | N14: =INDEX('HY & Segments'!$A:$AG,MATCH($A14,'HY & Segments'!$A:$A,0),MATCH("1H"&RIGHT(N$1,2),'HY & Segments'!$3:$3,0))+INDEX('HY & Segments'!$A:$AG,MATCH($A14,'HY & Segments'!$A:$A,0),MATCH("2H"&RIGHT(N$1,2),'HY & Segments'!$3:$3,0)) -> -499.88629 | ... P14: =INDEX('HY & Segments'!$A:$AG,MATCH($A14,'HY & Segments'!$A:$A,0),MATCH("1H"&RIGHT(P$1,2),'HY & Segments'!$3:$3,0))+INDEX('HY & Segments'!$A:$AG,MATCH($A14,'HY & Segments'!$A:$A,0),MATCH("2H"&RIGHT(P$1,2),'HY & Segments'!$3:$3,0)) -> -557.17729
A15: COGS-Other COGS | B15: Other COGS | C15: NZDm | D15: 0 | E15: 0 | F15: 0 | G15: =INDEX('HY & Segments'!$A:$AG,MATCH($A15,'HY & Segments'!$A:$A,0),MATCH("1H"&RIGHT(G$1,2),'HY & Segments'!$3:$3,0))+INDEX('HY & Segments'!$A:$AG,MATCH($A15,'HY & Segments'!$A:$A,0),MATCH("2H"&RIGHT(G$1,2),'HY & Segments'!$3:$3,0)) -> 0 | H15: =INDEX('HY & Segments'!$A:$AG,MATCH($A15,'HY & Segments'!$A:$A,0),MATCH("1H"&RIGHT(H$1,2),'HY & Segments'!$3:$3,0))+INDEX('HY & Segments'!$A:$AG,MATCH($A15,'HY & Segments'!$A:$A,0),MATCH("2H"&RIGHT(H$1,2),'HY & Segments'!$3:$3,0)) -> 0 | I15: =INDEX('HY & Segments'!$A:$AG,MATCH($A15,'HY & Segments'!$A:$A,0),MATCH("1H"&RIGHT(I$1,2),'HY & Segments'!$3:$3,0))+INDEX('HY & Segments'!$A:$AG,MATCH($A15,'HY & Segments'!$A:$A,0),MATCH("2H"&RIGHT(I$1,2),'HY & Segments'!$3:$3,0)) -> 0 | J15: =INDEX('HY & Segments'!$A:$AG,MATCH($A15,'HY & Segments'!$A:$A,0),MATCH("1H"&RIGHT(J$1,2),'HY & Segments'!$3:$3,0))+INDEX('HY & Segments'!$A:$AG,MATCH($A15,'HY & Segments'!$A:$A,0),MATCH("2H"&RIGHT(J$1,2),'HY & Segments'!$3:$3,0)) -> 0 | K15: =INDEX('HY & Segments'!$A:$AG,MATCH($A15,'HY & Segments'!$A:$A,0),MATCH("1H"&RIGHT(K$1,2),'HY & Segments'!$3:$3,0))+INDEX('HY & Segments'!$A:$AG,MATCH($A15,'HY & Segments'!$A:$A,0),MATCH("2H"&RIGHT(K$1,2),'HY & Segments'!$3:$3,0)) -> 0 | L15: =INDEX('HY & Segments'!$A:$AG,MATCH($A15,'HY & Segments'!$A:$A,0),MATCH("1H"&RIGHT(L$1,2),'HY & Segments'!$3:$3,0))+INDEX('HY & Segments'!$A:$AG,MATCH($A15,'HY & Segments'!$A:$A,0),MATCH("2H"&RIGHT(L$1,2),'HY & Segments'!$3:$3,0)) -> 0 | M15: =INDEX('HY & Segments'!$A:$AG,MATCH($A15,'HY & Segments'!$A:$A,0),MATCH("1H"&RIGHT(M$1,2),'HY & Segments'!$3:$3,0))+INDEX('HY & Segments'!$A:$AG,MATCH($A15,'HY & Segments'!$A:$A,0),MATCH("2H"&RIGHT(M$1,2),'HY & Segments'!$3:$3,0)) -> 0 | N15: =INDEX('HY & Segments'!$A:$AG,MATCH($A15,'HY & Segments'!$A:$A,0),MATCH("1H"&RIGHT(N$1,2),'HY & Segments'!$3:$3,0))+INDEX('HY & Segments'!$A:$AG,MATCH($A15,'HY & Segments'!$A:$A,0),MATCH("2H"&RIGHT(N$1,2),'HY & Segments'!$3:$3,0)) -> 0 | ... P15: =INDEX('HY & Segments'!$A:$AG,MATCH($A15,'HY & Segments'!$A:$A,0),MATCH("1H"&RIGHT(P$1,2),'HY & Segments'!$3:$3,0))+INDEX('HY & Segments'!$A:$AG,MATCH($A15,'HY & Segments'!$A:$A,0),MATCH("2H"&RIGHT(P$1,2),'HY & Segments'!$3:$3,0)) -> 0
A16: COGS-Total COGS | B16: Total COGS | C16: NZDm | D16: =SUM(D13:D15) -> -801.3602 | E16: =SUM(E13:E15) -> -703 | F16: =SUM(F13:F15) -> -623.2 | G16: =SUM(G13:G15) -> -716.65094 | H16: =SUM(H13:H15) -> -779.81162 | I16: =SUM(I13:I15) -> -823.28612 | J16: =SUM(J13:J15) -> -869.18432 | K16: =SUM(K13:K15) -> -917.64134 | ... P16: =SUM(P13:P15) -> -1203.5896
B18: Gross Profit
A19: GP-Steel GP | B19: Steel GP | C19: NZDm | D19: =D7+D13 -> 186.0456 | E19: =E7+E13 -> 143.7 | F19: =F7+F13 -> 119.2 | G19: =INDEX('HY & Segments'!$A:$AG,MATCH($A19,'HY & Segments'!$A:$A,0),MATCH("1H"&RIGHT(G$1,2),'HY & Segments'!$3:$3,0))+INDEX('HY & Segments'!$A:$AG,MATCH($A19,'HY & Segments'!$A:$A,0),MATCH("2H"&RIGHT(G$1,2),'HY & Segments'!$3:$3,0)) -> 158.31937 | H19: =INDEX('HY & Segments'!$A:$AG,MATCH($A19,'HY & Segments'!$A:$A,0),MATCH("1H"&RIGHT(H$1,2),'HY & Segments'!$3:$3,0))+INDEX('HY & Segments'!$A:$AG,MATCH($A19,'HY & Segments'!$A:$A,0),MATCH("2H"&RIGHT(H$1,2),'HY & Segments'!$3:$3,0)) -> 177.04441 | I19: =INDEX('HY & Segments'!$A:$AG,MATCH($A19,'HY & Segments'!$A:$A,0),MATCH("1H"&RIGHT(I$1,2),'HY & Segments'!$3:$3,0))+INDEX('HY & Segments'!$A:$AG,MATCH($A19,'HY & Segments'!$A:$A,0),MATCH("2H"&RIGHT(I$1,2),'HY & Segments'!$3:$3,0)) -> 186.91464 | J19: =INDEX('HY & Segments'!$A:$AG,MATCH($A19,'HY & Segments'!$A:$A,0),MATCH("1H"&RIGHT(J$1,2),'HY & Segments'!$3:$3,0))+INDEX('HY & Segments'!$A:$AG,MATCH($A19,'HY & Segments'!$A:$A,0),MATCH("2H"&RIGHT(J$1,2),'HY & Segments'!$3:$3,0)) -> 197.33513 | K19: =INDEX('HY & Segments'!$A:$AG,MATCH($A19,'HY & Segments'!$A:$A,0),MATCH("1H"&RIGHT(K$1,2),'HY & Segments'!$3:$3,0))+INDEX('HY & Segments'!$A:$AG,MATCH($A19,'HY & Segments'!$A:$A,0),MATCH("2H"&RIGHT(K$1,2),'HY & Segments'!$3:$3,0)) -> 208.33656 | L19: =INDEX('HY & Segments'!$A:$AG,MATCH($A19,'HY & Segments'!$A:$A,0),MATCH("1H"&RIGHT(L$1,2),'HY & Segments'!$3:$3,0))+INDEX('HY & Segments'!$A:$AG,MATCH($A19,'HY & Segments'!$A:$A,0),MATCH("2H"&RIGHT(L$1,2),'HY & Segments'!$3:$3,0)) -> 219.95132 | M19: =INDEX('HY & Segments'!$A:$AG,MATCH($A19,'HY & Segments'!$A:$A,0),MATCH("1H"&RIGHT(M$1,2),'HY & Segments'!$3:$3,0))+INDEX('HY & Segments'!$A:$AG,MATCH($A19,'HY & Segments'!$A:$A,0),MATCH("2H"&RIGHT(M$1,2),'HY & Segments'!$3:$3,0)) -> 232.21361 | N19: =INDEX('HY & Segments'!$A:$AG,MATCH($A19,'HY & Segments'!$A:$A,0),MATCH("1H"&RIGHT(N$1,2),'HY & Segments'!$3:$3,0))+INDEX('HY & Segments'!$A:$AG,MATCH($A19,'HY & Segments'!$A:$A,0),MATCH("2H"&RIGHT(N$1,2),'HY & Segments'!$3:$3,0)) -> 245.15952 | ... P19: =INDEX('HY & Segments'!$A:$AG,MATCH($A19,'HY & Segments'!$A:$A,0),MATCH("1H"&RIGHT(P$1,2),'HY & Segments'!$3:$3,0))+INDEX('HY & Segments'!$A:$AG,MATCH($A19,'HY & Segments'!$A:$A,0),MATCH("2H"&RIGHT(P$1,2),'HY & Segments'!$3:$3,0)) -> 273.25678
A20: GP-Metals GP | B20: Metals GP | C20: NZDm | D20: =D8+D14 -> 257.4942 | E20: =E8+E14 -> 217.6 | F20: =F8+F14 -> 205.7 | G20: =INDEX('HY & Segments'!$A:$AG,MATCH($A20,'HY & Segments'!$A:$A,0),MATCH("1H"&RIGHT(G$1,2),'HY & Segments'!$3:$3,0))+INDEX('HY & Segments'!$A:$AG,MATCH($A20,'HY & Segments'!$A:$A,0),MATCH("2H"&RIGHT(G$1,2),'HY & Segments'!$3:$3,0)) -> 200.49794 | H20: =INDEX('HY & Segments'!$A:$AG,MATCH($A20,'HY & Segments'!$A:$A,0),MATCH("1H"&RIGHT(H$1,2),'HY & Segments'!$3:$3,0))+INDEX('HY & Segments'!$A:$AG,MATCH($A20,'HY & Segments'!$A:$A,0),MATCH("2H"&RIGHT(H$1,2),'HY & Segments'!$3:$3,0)) -> 211.67571 | I20: =INDEX('HY & Segments'!$A:$AG,MATCH($A20,'HY & Segments'!$A:$A,0),MATCH("1H"&RIGHT(I$1,2),'HY & Segments'!$3:$3,0))+INDEX('HY & Segments'!$A:$AG,MATCH($A20,'HY & Segments'!$A:$A,0),MATCH("2H"&RIGHT(I$1,2),'HY & Segments'!$3:$3,0)) -> 223.47663 | J20: =INDEX('HY & Segments'!$A:$AG,MATCH($A20,'HY & Segments'!$A:$A,0),MATCH("1H"&RIGHT(J$1,2),'HY & Segments'!$3:$3,0))+INDEX('HY & Segments'!$A:$AG,MATCH($A20,'HY & Segments'!$A:$A,0),MATCH("2H"&RIGHT(J$1,2),'HY & Segments'!$3:$3,0)) -> 235.93545 | K20: =INDEX('HY & Segments'!$A:$AG,MATCH($A20,'HY & Segments'!$A:$A,0),MATCH("1H"&RIGHT(K$1,2),'HY & Segments'!$3:$3,0))+INDEX('HY & Segments'!$A:$AG,MATCH($A20,'HY & Segments'!$A:$A,0),MATCH("2H"&RIGHT(K$1,2),'HY & Segments'!$3:$3,0)) -> 249.08885 | L20: =INDEX('HY & Segments'!$A:$AG,MATCH($A20,'HY & Segments'!$A:$A,0),MATCH("1H"&RIGHT(L$1,2),'HY & Segments'!$3:$3,0))+INDEX('HY & Segments'!$A:$AG,MATCH($A20,'HY & Segments'!$A:$A,0),MATCH("2H"&RIGHT(L$1,2),'HY & Segments'!$3:$3,0)) -> 262.97555 | M20: =INDEX('HY & Segments'!$A:$AG,MATCH($A20,'HY & Segments'!$A:$A,0),MATCH("1H"&RIGHT(M$1,2),'HY & Segments'!$3:$3,0))+INDEX('HY & Segments'!$A:$AG,MATCH($A20,'HY & Segments'!$A:$A,0),MATCH("2H"&RIGHT(M$1,2),'HY & Segments'!$3:$3,0)) -> 277.63644 | N20: =INDEX('HY & Segments'!$A:$AG,MATCH($A20,'HY & Segments'!$A:$A,0),MATCH("1H"&RIGHT(N$1,2),'HY & Segments'!$3:$3,0))+INDEX('HY & Segments'!$A:$AG,MATCH($A20,'HY & Segments'!$A:$A,0),MATCH("2H"&RIGHT(N$1,2),'HY & Segments'!$3:$3,0)) -> 293.11467 | ... P20: =INDEX('HY & Segments'!$A:$AG,MATCH($A20,'HY & Segments'!$A:$A,0),MATCH("1H"&RIGHT(P$1,2),'HY & Segments'!$3:$3,0))+INDEX('HY & Segments'!$A:$AG,MATCH($A20,'HY & Segments'!$A:$A,0),MATCH("2H"&RIGHT(P$1,2),'HY & Segments'!$3:$3,0)) -> 326.70798
A21: GP-Corporate GP | B21: Corporate/Elim | C21: NZDm | D21: =D22-D19-D20 -> 0 | E21: =E22-E19-E20 -> 0 | F21: =F22-F19-F20 -> 0 | G21: =INDEX('HY & Segments'!$A:$AG,MATCH($A21,'HY & Segments'!$A:$A,0),MATCH("1H"&RIGHT(G$1,2),'HY & Segments'!$3:$3,0))+INDEX('HY & Segments'!$A:$AG,MATCH($A21,'HY & Segments'!$A:$A,0),MATCH("2H"&RIGHT(G$1,2),'HY & Segments'!$3:$3,0)) -> 0 | H21: =INDEX('HY & Segments'!$A:$AG,MATCH($A21,'HY & Segments'!$A:$A,0),MATCH("1H"&RIGHT(H$1,2),'HY & Segments'!$3:$3,0))+INDEX('HY & Segments'!$A:$AG,MATCH($A21,'HY & Segments'!$A:$A,0),MATCH("2H"&RIGHT(H$1,2),'HY & Segments'!$3:$3,0)) -> 0 | I21: =INDEX('HY & Segments'!$A:$AG,MATCH($A21,'HY & Segments'!$A:$A,0),MATCH("1H"&RIGHT(I$1,2),'HY & Segments'!$3:$3,0))+INDEX('HY & Segments'!$A:$AG,MATCH($A21,'HY & Segments'!$A:$A,0),MATCH("2H"&RIGHT(I$1,2),'HY & Segments'!$3:$3,0)) -> 0 | J21: =INDEX('HY & Segments'!$A:$AG,MATCH($A21,'HY & Segments'!$A:$A,0),MATCH("1H"&RIGHT(J$1,2),'HY & Segments'!$3:$3,0))+INDEX('HY & Segments'!$A:$AG,MATCH($A21,'HY & Segments'!$A:$A,0),MATCH("2H"&RIGHT(J$1,2),'HY & Segments'!$3:$3,0)) -> 0 | K21: =INDEX('HY & Segments'!$A:$AG,MATCH($A21,'HY & Segments'!$A:$A,0),MATCH("1H"&RIGHT(K$1,2),'HY & Segments'!$3:$3,0))+INDEX('HY & Segments'!$A:$AG,MATCH($A21,'HY & Segments'!$A:$A,0),MATCH("2H"&RIGHT(K$1,2),'HY & Segments'!$3:$3,0)) -> 0 | L21: =INDEX('HY & Segments'!$A:$AG,MATCH($A21,'HY & Segments'!$A:$A,0),MATCH("1H"&RIGHT(L$1,2),'HY & Segments'!$3:$3,0))+INDEX('HY & Segments'!$A:$AG,MATCH($A21,'HY & Segments'!$A:$A,0),MATCH("2H"&RIGHT(L$1,2),'HY & Segments'!$3:$3,0)) -> 0 | M21: =INDEX('HY & Segments'!$A:$AG,MATCH($A21,'HY & Segments'!$A:$A,0),MATCH("1H"&RIGHT(M$1,2),'HY & Segments'!$3:$3,0))+INDEX('HY & Segments'!$A:$AG,MATCH($A21,'HY & Segments'!$A:$A,0),MATCH("2H"&RIGHT(M$1,2),'HY & Segments'!$3:$3,0)) -> 0 | N21: =INDEX('HY & Segments'!$A:$AG,MATCH($A21,'HY & Segments'!$A:$A,0),MATCH("1H"&RIGHT(N$1,2),'HY & Segments'!$3:$3,0))+INDEX('HY & Segments'!$A:$AG,MATCH($A21,'HY & Segments'!$A:$A,0),MATCH("2H"&RIGHT(N$1,2),'HY & Segments'!$3:$3,0)) -> 0 | ... P21: =INDEX('HY & Segments'!$A:$AG,MATCH($A21,'HY & Segments'!$A:$A,0),MATCH("1H"&RIGHT(P$1,2),'HY & Segments'!$3:$3,0))+INDEX('HY & Segments'!$A:$AG,MATCH($A21,'HY & Segments'!$A:$A,0),MATCH("2H"&RIGHT(P$1,2),'HY & Segments'!$3:$3,0)) -> 0
A22: GP-Gross Profit | B22: Gross Profit | C22: NZDm | D22: =D9+D16 -> 443.5398 | E22: =E9+E16 -> 361.3 | F22: =F9+F16 -> 324.9 | G22: =G9+G16 -> 358.81732 | H22: =H9+H16 -> 388.72012 | I22: =I9+I16 -> 410.39126 | J22: =J9+J16 -> 433.27057 | K22: =K9+K16 -> 457.42541 | ... P22: =P9+P16 -> 599.96475
B23: GP Growth | C23: % YoY | E23: =IF(D22=0,"",E22/D22-1) -> -0.18541696 | F23: =IF(E22=0,"",F22/E22-1) -> -0.1007473 | G23: =IF(F22=0,"",G22/F22-1) -> 0.1043931 | H23: =IF(G22=0,"",H22/G22-1) -> 0.083337105 | I23: =IF(H22=0,"",I22/H22-1) -> 0.05575 | J23: =IF(I22=0,"",J22/I22-1) -> 0.05575 | K23: =IF(J22=0,"",K22/J22-1) -> 0.05575 | L23: =IF(K22=0,"",L22/K22-1) -> 0.05575 | ... P23: =IF(O22=0,"",P22/O22-1) -> 0.05575
B24: GP Margin | C24: % | D24: =IF(D9=0,"",D22/D9) -> 0.35628548 | E24: =IF(E9=0,"",E22/E9) -> 0.33947195 | F24: =IF(F9=0,"",F22/F9) -> 0.34268537 | G24: =IF(G9=0,"",G22/G9) -> 0.33363822 | H24: =IF(H9=0,"",H22/H9) -> 0.33265688 | I24: =IF(I9=0,"",I22/I9) -> 0.33265688 | J24: =IF(J9=0,"",J22/J9) -> 0.33265688 | K24: =IF(K9=0,"",K22/K9) -> 0.33265688 | ... P24: =IF(P9=0,"",P22/P9) -> 0.33265688
B26: Operating Expenses
A27: OPEX-Employee Benefits | B27: Employee Benefits | C27: NZDm | D27: -142.2 | E27: -139.3 | F27: -146.4 | G27: =INDEX('HY & Segments'!$A:$AG,MATCH($A27,'HY & Segments'!$A:$A,0),MATCH("1H"&RIGHT(G$1,2),'HY & Segments'!$3:$3,0))+INDEX('HY & Segments'!$A:$AG,MATCH($A27,'HY & Segments'!$A:$A,0),MATCH("2H"&RIGHT(G$1,2),'HY & Segments'!$3:$3,0)) -> -164.17509 | H27: =INDEX('HY & Segments'!$A:$AG,MATCH($A27,'HY & Segments'!$A:$A,0),MATCH("1H"&RIGHT(H$1,2),'HY & Segments'!$3:$3,0))+INDEX('HY & Segments'!$A:$AG,MATCH($A27,'HY & Segments'!$A:$A,0),MATCH("2H"&RIGHT(H$1,2),'HY & Segments'!$3:$3,0)) -> -169.40565 | I27: =INDEX('HY & Segments'!$A:$AG,MATCH($A27,'HY & Segments'!$A:$A,0),MATCH("1H"&RIGHT(I$1,2),'HY & Segments'!$3:$3,0))+INDEX('HY & Segments'!$A:$AG,MATCH($A27,'HY & Segments'!$A:$A,0),MATCH("2H"&RIGHT(I$1,2),'HY & Segments'!$3:$3,0)) -> -174.18104 | J27: =INDEX('HY & Segments'!$A:$AG,MATCH($A27,'HY & Segments'!$A:$A,0),MATCH("1H"&RIGHT(J$1,2),'HY & Segments'!$3:$3,0))+INDEX('HY & Segments'!$A:$AG,MATCH($A27,'HY & Segments'!$A:$A,0),MATCH("2H"&RIGHT(J$1,2),'HY & Segments'!$3:$3,0)) -> -179.10592 | K27: =INDEX('HY & Segments'!$A:$AG,MATCH($A27,'HY & Segments'!$A:$A,0),MATCH("1H"&RIGHT(K$1,2),'HY & Segments'!$3:$3,0))+INDEX('HY & Segments'!$A:$AG,MATCH($A27,'HY & Segments'!$A:$A,0),MATCH("2H"&RIGHT(K$1,2),'HY & Segments'!$3:$3,0)) -> -184.18573 | L27: =INDEX('HY & Segments'!$A:$AG,MATCH($A27,'HY & Segments'!$A:$A,0),MATCH("1H"&RIGHT(L$1,2),'HY & Segments'!$3:$3,0))+INDEX('HY & Segments'!$A:$AG,MATCH($A27,'HY & Segments'!$A:$A,0),MATCH("2H"&RIGHT(L$1,2),'HY & Segments'!$3:$3,0)) -> -189.4261 | M27: =INDEX('HY & Segments'!$A:$AG,MATCH($A27,'HY & Segments'!$A:$A,0),MATCH("1H"&RIGHT(M$1,2),'HY & Segments'!$3:$3,0))+INDEX('HY & Segments'!$A:$AG,MATCH($A27,'HY & Segments'!$A:$A,0),MATCH("2H"&RIGHT(M$1,2),'HY & Segments'!$3:$3,0)) -> -194.83293 | N27: =INDEX('HY & Segments'!$A:$AG,MATCH($A27,'HY & Segments'!$A:$A,0),MATCH("1H"&RIGHT(N$1,2),'HY & Segments'!$3:$3,0))+INDEX('HY & Segments'!$A:$AG,MATCH($A27,'HY & Segments'!$A:$A,0),MATCH("2H"&RIGHT(N$1,2),'HY & Segments'!$3:$3,0)) -> -200.41234 | ... P27: =INDEX('HY & Segments'!$A:$AG,MATCH($A27,'HY & Segments'!$A:$A,0),MATCH("1H"&RIGHT(P$1,2),'HY & Segments'!$3:$3,0))+INDEX('HY & Segments'!$A:$AG,MATCH($A27,'HY & Segments'!$A:$A,0),MATCH("2H"&RIGHT(P$1,2),'HY & Segments'!$3:$3,0)) -> -212.11481
A28: OPEX-Selling & Distribution | B28: Selling & Distribution | C28: NZDm | D28: -26.7 | E28: -27.5 | F28: -22.5 | G28: =INDEX('HY & Segments'!$A:$AG,MATCH($A28,'HY & Segments'!$A:$A,0),MATCH("1H"&RIGHT(G$1,2),'HY & Segments'!$3:$3,0))+INDEX('HY & Segments'!$A:$AG,MATCH($A28,'HY & Segments'!$A:$A,0),MATCH("2H"&RIGHT(G$1,2),'HY & Segments'!$3:$3,0)) -> -23.64729 | H28: =INDEX('HY & Segments'!$A:$AG,MATCH($A28,'HY & Segments'!$A:$A,0),MATCH("1H"&RIGHT(H$1,2),'HY & Segments'!$3:$3,0))+INDEX('HY & Segments'!$A:$AG,MATCH($A28,'HY & Segments'!$A:$A,0),MATCH("2H"&RIGHT(H$1,2),'HY & Segments'!$3:$3,0)) -> -24.397053 | I28: =INDEX('HY & Segments'!$A:$AG,MATCH($A28,'HY & Segments'!$A:$A,0),MATCH("1H"&RIGHT(I$1,2),'HY & Segments'!$3:$3,0))+INDEX('HY & Segments'!$A:$AG,MATCH($A28,'HY & Segments'!$A:$A,0),MATCH("2H"&RIGHT(I$1,2),'HY & Segments'!$3:$3,0)) -> -25.084442 | J28: =INDEX('HY & Segments'!$A:$AG,MATCH($A28,'HY & Segments'!$A:$A,0),MATCH("1H"&RIGHT(J$1,2),'HY & Segments'!$3:$3,0))+INDEX('HY & Segments'!$A:$AG,MATCH($A28,'HY & Segments'!$A:$A,0),MATCH("2H"&RIGHT(J$1,2),'HY & Segments'!$3:$3,0)) -> -25.793334 | K28: =INDEX('HY & Segments'!$A:$AG,MATCH($A28,'HY & Segments'!$A:$A,0),MATCH("1H"&RIGHT(K$1,2),'HY & Segments'!$3:$3,0))+INDEX('HY & Segments'!$A:$AG,MATCH($A28,'HY & Segments'!$A:$A,0),MATCH("2H"&RIGHT(K$1,2),'HY & Segments'!$3:$3,0)) -> -26.524508 | L28: =INDEX('HY & Segments'!$A:$AG,MATCH($A28,'HY & Segments'!$A:$A,0),MATCH("1H"&RIGHT(L$1,2),'HY & Segments'!$3:$3,0))+INDEX('HY & Segments'!$A:$AG,MATCH($A28,'HY & Segments'!$A:$A,0),MATCH("2H"&RIGHT(L$1,2),'HY & Segments'!$3:$3,0)) -> -27.278775 | M28: =INDEX('HY & Segments'!$A:$AG,MATCH($A28,'HY & Segments'!$A:$A,0),MATCH("1H"&RIGHT(M$1,2),'HY & Segments'!$3:$3,0))+INDEX('HY & Segments'!$A:$AG,MATCH($A28,'HY & Segments'!$A:$A,0),MATCH("2H"&RIGHT(M$1,2),'HY & Segments'!$3:$3,0)) -> -28.056981 | N28: =INDEX('HY & Segments'!$A:$AG,MATCH($A28,'HY & Segments'!$A:$A,0),MATCH("1H"&RIGHT(N$1,2),'HY & Segments'!$3:$3,0))+INDEX('HY & Segments'!$A:$AG,MATCH($A28,'HY & Segments'!$A:$A,0),MATCH("2H"&RIGHT(N$1,2),'HY & Segments'!$3:$3,0)) -> -28.860007 | ... P28: =INDEX('HY & Segments'!$A:$AG,MATCH($A28,'HY & Segments'!$A:$A,0),MATCH("1H"&RIGHT(P$1,2),'HY & Segments'!$3:$3,0))+INDEX('HY & Segments'!$A:$AG,MATCH($A28,'HY & Segments'!$A:$A,0),MATCH("2H"&RIGHT(P$1,2),'HY & Segments'!$3:$3,0)) -> -30.544237
A29: OPEX-Occupancy Costs | B29: Occupancy Costs | C29: NZDm | D29: -11 | E29: -12.8 | F29: -14.2 | G29: =INDEX('HY & Segments'!$A:$AG,MATCH($A29,'HY & Segments'!$A:$A,0),MATCH("1H"&RIGHT(G$1,2),'HY & Segments'!$3:$3,0))+INDEX('HY & Segments'!$A:$AG,MATCH($A29,'HY & Segments'!$A:$A,0),MATCH("2H"&RIGHT(G$1,2),'HY & Segments'!$3:$3,0)) -> -15.58725 | H29: =INDEX('HY & Segments'!$A:$AG,MATCH($A29,'HY & Segments'!$A:$A,0),MATCH("1H"&RIGHT(H$1,2),'HY & Segments'!$3:$3,0))+INDEX('HY & Segments'!$A:$AG,MATCH($A29,'HY & Segments'!$A:$A,0),MATCH("2H"&RIGHT(H$1,2),'HY & Segments'!$3:$3,0)) -> -16.082928 | I29: =INDEX('HY & Segments'!$A:$AG,MATCH($A29,'HY & Segments'!$A:$A,0),MATCH("1H"&RIGHT(I$1,2),'HY & Segments'!$3:$3,0))+INDEX('HY & Segments'!$A:$AG,MATCH($A29,'HY & Segments'!$A:$A,0),MATCH("2H"&RIGHT(I$1,2),'HY & Segments'!$3:$3,0)) -> -16.536204 | J29: =INDEX('HY & Segments'!$A:$AG,MATCH($A29,'HY & Segments'!$A:$A,0),MATCH("1H"&RIGHT(J$1,2),'HY & Segments'!$3:$3,0))+INDEX('HY & Segments'!$A:$AG,MATCH($A29,'HY & Segments'!$A:$A,0),MATCH("2H"&RIGHT(J$1,2),'HY & Segments'!$3:$3,0)) -> -17.003666 | K29: =INDEX('HY & Segments'!$A:$AG,MATCH($A29,'HY & Segments'!$A:$A,0),MATCH("1H"&RIGHT(K$1,2),'HY & Segments'!$3:$3,0))+INDEX('HY & Segments'!$A:$AG,MATCH($A29,'HY & Segments'!$A:$A,0),MATCH("2H"&RIGHT(K$1,2),'HY & Segments'!$3:$3,0)) -> -17.485828 | L29: =INDEX('HY & Segments'!$A:$AG,MATCH($A29,'HY & Segments'!$A:$A,0),MATCH("1H"&RIGHT(L$1,2),'HY & Segments'!$3:$3,0))+INDEX('HY & Segments'!$A:$AG,MATCH($A29,'HY & Segments'!$A:$A,0),MATCH("2H"&RIGHT(L$1,2),'HY & Segments'!$3:$3,0)) -> -17.983226 | M29: =INDEX('HY & Segments'!$A:$AG,MATCH($A29,'HY & Segments'!$A:$A,0),MATCH("1H"&RIGHT(M$1,2),'HY & Segments'!$3:$3,0))+INDEX('HY & Segments'!$A:$AG,MATCH($A29,'HY & Segments'!$A:$A,0),MATCH("2H"&RIGHT(M$1,2),'HY & Segments'!$3:$3,0)) -> -18.496418 | N29: =INDEX('HY & Segments'!$A:$AG,MATCH($A29,'HY & Segments'!$A:$A,0),MATCH("1H"&RIGHT(N$1,2),'HY & Segments'!$3:$3,0))+INDEX('HY & Segments'!$A:$AG,MATCH($A29,'HY & Segments'!$A:$A,0),MATCH("2H"&RIGHT(N$1,2),'HY & Segments'!$3:$3,0)) -> -19.025986 | ... P29: =INDEX('HY & Segments'!$A:$AG,MATCH($A29,'HY & Segments'!$A:$A,0),MATCH("1H"&RIGHT(P$1,2),'HY & Segments'!$3:$3,0))+INDEX('HY & Segments'!$A:$AG,MATCH($A29,'HY & Segments'!$A:$A,0),MATCH("2H"&RIGHT(P$1,2),'HY & Segments'!$3:$3,0)) -> -20.136705
A30: OPEX-General & Admin | B30: General & Admin | C30: NZDm | D30: -45.5 | E30: -34.2 | F30: -29.4 | G30: =INDEX('HY & Segments'!$A:$AG,MATCH($A30,'HY & Segments'!$A:$A,0),MATCH("1H"&RIGHT(G$1,2),'HY & Segments'!$3:$3,0))+INDEX('HY & Segments'!$A:$AG,MATCH($A30,'HY & Segments'!$A:$A,0),MATCH("2H"&RIGHT(G$1,2),'HY & Segments'!$3:$3,0)) -> -20.5298 | H30: =INDEX('HY & Segments'!$A:$AG,MATCH($A30,'HY & Segments'!$A:$A,0),MATCH("1H"&RIGHT(H$1,2),'HY & Segments'!$3:$3,0))+INDEX('HY & Segments'!$A:$AG,MATCH($A30,'HY & Segments'!$A:$A,0),MATCH("2H"&RIGHT(H$1,2),'HY & Segments'!$3:$3,0)) -> -21.211395 | I30: =INDEX('HY & Segments'!$A:$AG,MATCH($A30,'HY & Segments'!$A:$A,0),MATCH("1H"&RIGHT(I$1,2),'HY & Segments'!$3:$3,0))+INDEX('HY & Segments'!$A:$AG,MATCH($A30,'HY & Segments'!$A:$A,0),MATCH("2H"&RIGHT(I$1,2),'HY & Segments'!$3:$3,0)) -> -21.811905 | J30: =INDEX('HY & Segments'!$A:$AG,MATCH($A30,'HY & Segments'!$A:$A,0),MATCH("1H"&RIGHT(J$1,2),'HY & Segments'!$3:$3,0))+INDEX('HY & Segments'!$A:$AG,MATCH($A30,'HY & Segments'!$A:$A,0),MATCH("2H"&RIGHT(J$1,2),'HY & Segments'!$3:$3,0)) -> -22.431341 | K30: =INDEX('HY & Segments'!$A:$AG,MATCH($A30,'HY & Segments'!$A:$A,0),MATCH("1H"&RIGHT(K$1,2),'HY & Segments'!$3:$3,0))+INDEX('HY & Segments'!$A:$AG,MATCH($A30,'HY & Segments'!$A:$A,0),MATCH("2H"&RIGHT(K$1,2),'HY & Segments'!$3:$3,0)) -> -23.070398 | L30: =INDEX('HY & Segments'!$A:$AG,MATCH($A30,'HY & Segments'!$A:$A,0),MATCH("1H"&RIGHT(L$1,2),'HY & Segments'!$3:$3,0))+INDEX('HY & Segments'!$A:$AG,MATCH($A30,'HY & Segments'!$A:$A,0),MATCH("2H"&RIGHT(L$1,2),'HY & Segments'!$3:$3,0)) -> -23.729794 | M30: =INDEX('HY & Segments'!$A:$AG,MATCH($A30,'HY & Segments'!$A:$A,0),MATCH("1H"&RIGHT(M$1,2),'HY & Segments'!$3:$3,0))+INDEX('HY & Segments'!$A:$AG,MATCH($A30,'HY & Segments'!$A:$A,0),MATCH("2H"&RIGHT(M$1,2),'HY & Segments'!$3:$3,0)) -> -24.410282 | N30: =INDEX('HY & Segments'!$A:$AG,MATCH($A30,'HY & Segments'!$A:$A,0),MATCH("1H"&RIGHT(N$1,2),'HY & Segments'!$3:$3,0))+INDEX('HY & Segments'!$A:$AG,MATCH($A30,'HY & Segments'!$A:$A,0),MATCH("2H"&RIGHT(N$1,2),'HY & Segments'!$3:$3,0)) -> -25.112646 | ... P30: =INDEX('HY & Segments'!$A:$AG,MATCH($A30,'HY & Segments'!$A:$A,0),MATCH("1H"&RIGHT(P$1,2),'HY & Segments'!$3:$3,0))+INDEX('HY & Segments'!$A:$AG,MATCH($A30,'HY & Segments'!$A:$A,0),MATCH("2H"&RIGHT(P$1,2),'HY & Segments'!$3:$3,0)) -> -26.58631
A31: OPEX-Total OpEx | B31: Total Operating Expenses | C31: NZDm | D31: =SUM(D27:D30) -> -225.4 | E31: =SUM(E27:E30) -> -213.8 | F31: =SUM(F27:F30) -> -212.5 | G31: =SUM(G27:G30) -> -223.93944 | H31: =SUM(H27:H30) -> -231.09703 | I31: =SUM(I27:I30) -> -237.61359 | J31: =SUM(J27:J30) -> -244.33427 | K31: =SUM(K27:K30) -> -251.26646 | ... P31: =SUM(P27:P30) -> -289.38206
B32: OpEx Growth | C32: % YoY | E32: =IF(D31=0,"",E31/D31-1) -> -0.051464064 | F32: =IF(E31=0,"",F31/E31-1) -> -0.006080449 | G32: =IF(F31=0,"",G31/F31-1) -> 0.053832637 | H32: =IF(G31=0,"",H31/G31-1) -> 0.031962188 | I32: =IF(H31=0,"",I31/H31-1) -> 0.028198362 | J32: =IF(I31=0,"",J31/I31-1) -> 0.028284066 | K32: =IF(J31=0,"",K31/J31-1) -> 0.028371784 | L32: =IF(K31=0,"",L31/K31-1) -> 0.028461551 | ... P32: =IF(O31=0,"",P31/O31-1) -> 0.028841728
B34: EBITDA
A35: EBITDA-Steel EBITDA | B35: Steel EBITDA | C35: NZDm | D35: 113.2 | E35: 68.8 | F35: 44.1 | G35: =INDEX('HY & Segments'!$A:$AG,MATCH($A35,'HY & Segments'!$A:$A,0),MATCH("1H"&RIGHT(G$1,2),'HY & Segments'!$3:$3,0))+INDEX('HY & Segments'!$A:$AG,MATCH($A35,'HY & Segments'!$A:$A,0),MATCH("2H"&RIGHT(G$1,2),'HY & Segments'!$3:$3,0)) -> 75.951706 | H35: =INDEX('HY & Segments'!$A:$AG,MATCH($A35,'HY & Segments'!$A:$A,0),MATCH("1H"&RIGHT(H$1,2),'HY & Segments'!$3:$3,0))+INDEX('HY & Segments'!$A:$AG,MATCH($A35,'HY & Segments'!$A:$A,0),MATCH("2H"&RIGHT(H$1,2),'HY & Segments'!$3:$3,0)) -> 92.617551 | I35: =INDEX('HY & Segments'!$A:$AG,MATCH($A35,'HY & Segments'!$A:$A,0),MATCH("1H"&RIGHT(I$1,2),'HY & Segments'!$3:$3,0))+INDEX('HY & Segments'!$A:$AG,MATCH($A35,'HY & Segments'!$A:$A,0),MATCH("2H"&RIGHT(I$1,2),'HY & Segments'!$3:$3,0)) -> 100.3771 | J35: =INDEX('HY & Segments'!$A:$AG,MATCH($A35,'HY & Segments'!$A:$A,0),MATCH("1H"&RIGHT(J$1,2),'HY & Segments'!$3:$3,0))+INDEX('HY & Segments'!$A:$AG,MATCH($A35,'HY & Segments'!$A:$A,0),MATCH("2H"&RIGHT(J$1,2),'HY & Segments'!$3:$3,0)) -> 108.63416 | K35: =INDEX('HY & Segments'!$A:$AG,MATCH($A35,'HY & Segments'!$A:$A,0),MATCH("1H"&RIGHT(K$1,2),'HY & Segments'!$3:$3,0))+INDEX('HY & Segments'!$A:$AG,MATCH($A35,'HY & Segments'!$A:$A,0),MATCH("2H"&RIGHT(K$1,2),'HY & Segments'!$3:$3,0)) -> 117.41807 | L35: =INDEX('HY & Segments'!$A:$AG,MATCH($A35,'HY & Segments'!$A:$A,0),MATCH("1H"&RIGHT(L$1,2),'HY & Segments'!$3:$3,0))+INDEX('HY & Segments'!$A:$AG,MATCH($A35,'HY & Segments'!$A:$A,0),MATCH("2H"&RIGHT(L$1,2),'HY & Segments'!$3:$3,0)) -> 126.75987 | M35: =INDEX('HY & Segments'!$A:$AG,MATCH($A35,'HY & Segments'!$A:$A,0),MATCH("1H"&RIGHT(M$1,2),'HY & Segments'!$3:$3,0))+INDEX('HY & Segments'!$A:$AG,MATCH($A35,'HY & Segments'!$A:$A,0),MATCH("2H"&RIGHT(M$1,2),'HY & Segments'!$3:$3,0)) -> 136.69237 | N35: =INDEX('HY & Segments'!$A:$AG,MATCH($A35,'HY & Segments'!$A:$A,0),MATCH("1H"&RIGHT(N$1,2),'HY & Segments'!$3:$3,0))+INDEX('HY & Segments'!$A:$AG,MATCH($A35,'HY & Segments'!$A:$A,0),MATCH("2H"&RIGHT(N$1,2),'HY & Segments'!$3:$3,0)) -> 147.25025 | ... P35: =INDEX('HY & Segments'!$A:$AG,MATCH($A35,'HY & Segments'!$A:$A,0),MATCH("1H"&RIGHT(P$1,2),'HY & Segments'!$3:$3,0))+INDEX('HY & Segments'!$A:$AG,MATCH($A35,'HY & Segments'!$A:$A,0),MATCH("2H"&RIGHT(P$1,2),'HY & Segments'!$3:$3,0)) -> 170.39085
A36: EBITDA-Metals EBITDA | B36: Metals EBITDA | C36: NZDm | D36: 131 | E36: 99.5 | F36: 84.9 | G36: =INDEX('HY & Segments'!$A:$AG,MATCH($A36,'HY & Segments'!$A:$A,0),MATCH("1H"&RIGHT(G$1,2),'HY & Segments'!$3:$3,0))+INDEX('HY & Segments'!$A:$AG,MATCH($A36,'HY & Segments'!$A:$A,0),MATCH("2H"&RIGHT(G$1,2),'HY & Segments'!$3:$3,0)) -> 80.855645 | H36: =INDEX('HY & Segments'!$A:$AG,MATCH($A36,'HY & Segments'!$A:$A,0),MATCH("1H"&RIGHT(H$1,2),'HY & Segments'!$3:$3,0))+INDEX('HY & Segments'!$A:$AG,MATCH($A36,'HY & Segments'!$A:$A,0),MATCH("2H"&RIGHT(H$1,2),'HY & Segments'!$3:$3,0)) -> 89.042348 | I36: =INDEX('HY & Segments'!$A:$AG,MATCH($A36,'HY & Segments'!$A:$A,0),MATCH("1H"&RIGHT(I$1,2),'HY & Segments'!$3:$3,0))+INDEX('HY & Segments'!$A:$AG,MATCH($A36,'HY & Segments'!$A:$A,0),MATCH("2H"&RIGHT(I$1,2),'HY & Segments'!$3:$3,0)) -> 97.777435 | J36: =INDEX('HY & Segments'!$A:$AG,MATCH($A36,'HY & Segments'!$A:$A,0),MATCH("1H"&RIGHT(J$1,2),'HY & Segments'!$3:$3,0))+INDEX('HY & Segments'!$A:$AG,MATCH($A36,'HY & Segments'!$A:$A,0),MATCH("2H"&RIGHT(J$1,2),'HY & Segments'!$3:$3,0)) -> 107.09378 | K36: =INDEX('HY & Segments'!$A:$AG,MATCH($A36,'HY & Segments'!$A:$A,0),MATCH("1H"&RIGHT(K$1,2),'HY & Segments'!$3:$3,0))+INDEX('HY & Segments'!$A:$AG,MATCH($A36,'HY & Segments'!$A:$A,0),MATCH("2H"&RIGHT(K$1,2),'HY & Segments'!$3:$3,0)) -> 117.02614 | L36: =INDEX('HY & Segments'!$A:$AG,MATCH($A36,'HY & Segments'!$A:$A,0),MATCH("1H"&RIGHT(L$1,2),'HY & Segments'!$3:$3,0))+INDEX('HY & Segments'!$A:$AG,MATCH($A36,'HY & Segments'!$A:$A,0),MATCH("2H"&RIGHT(L$1,2),'HY & Segments'!$3:$3,0)) -> 127.61127 | M36: =INDEX('HY & Segments'!$A:$AG,MATCH($A36,'HY & Segments'!$A:$A,0),MATCH("1H"&RIGHT(M$1,2),'HY & Segments'!$3:$3,0))+INDEX('HY & Segments'!$A:$AG,MATCH($A36,'HY & Segments'!$A:$A,0),MATCH("2H"&RIGHT(M$1,2),'HY & Segments'!$3:$3,0)) -> 138.88805 | N36: =INDEX('HY & Segments'!$A:$AG,MATCH($A36,'HY & Segments'!$A:$A,0),MATCH("1H"&RIGHT(N$1,2),'HY & Segments'!$3:$3,0))+INDEX('HY & Segments'!$A:$AG,MATCH($A36,'HY & Segments'!$A:$A,0),MATCH("2H"&RIGHT(N$1,2),'HY & Segments'!$3:$3,0)) -> 150.89757 | ... P36: =INDEX('HY & Segments'!$A:$AG,MATCH($A36,'HY & Segments'!$A:$A,0),MATCH("1H"&RIGHT(P$1,2),'HY & Segments'!$3:$3,0))+INDEX('HY & Segments'!$A:$AG,MATCH($A36,'HY & Segments'!$A:$A,0),MATCH("2H"&RIGHT(P$1,2),'HY & Segments'!$3:$3,0)) -> 177.29114
A37: EBITDA-Corporate EBITDA | B37: Corporate EBITDA | C37: NZDm | D37: -25.3 | E37: -20.7 | F37: -17 | G37: =INDEX('HY & Segments'!$A:$AG,MATCH($A37,'HY & Segments'!$A:$A,0),MATCH("1H"&RIGHT(G$1,2),'HY & Segments'!$3:$3,0))+INDEX('HY & Segments'!$A:$AG,MATCH($A37,'HY & Segments'!$A:$A,0),MATCH("2H"&RIGHT(G$1,2),'HY & Segments'!$3:$3,0)) -> -22.000268 | H37: =INDEX('HY & Segments'!$A:$AG,MATCH($A37,'HY & Segments'!$A:$A,0),MATCH("1H"&RIGHT(H$1,2),'HY & Segments'!$3:$3,0))+INDEX('HY & Segments'!$A:$AG,MATCH($A37,'HY & Segments'!$A:$A,0),MATCH("2H"&RIGHT(H$1,2),'HY & Segments'!$3:$3,0)) -> -24.036813 | I37: =INDEX('HY & Segments'!$A:$AG,MATCH($A37,'HY & Segments'!$A:$A,0),MATCH("1H"&RIGHT(I$1,2),'HY & Segments'!$3:$3,0))+INDEX('HY & Segments'!$A:$AG,MATCH($A37,'HY & Segments'!$A:$A,0),MATCH("2H"&RIGHT(I$1,2),'HY & Segments'!$3:$3,0)) -> -25.376865 | J37: =INDEX('HY & Segments'!$A:$AG,MATCH($A37,'HY & Segments'!$A:$A,0),MATCH("1H"&RIGHT(J$1,2),'HY & Segments'!$3:$3,0))+INDEX('HY & Segments'!$A:$AG,MATCH($A37,'HY & Segments'!$A:$A,0),MATCH("2H"&RIGHT(J$1,2),'HY & Segments'!$3:$3,0)) -> -26.791626 | K37: =INDEX('HY & Segments'!$A:$AG,MATCH($A37,'HY & Segments'!$A:$A,0),MATCH("1H"&RIGHT(K$1,2),'HY & Segments'!$3:$3,0))+INDEX('HY & Segments'!$A:$AG,MATCH($A37,'HY & Segments'!$A:$A,0),MATCH("2H"&RIGHT(K$1,2),'HY & Segments'!$3:$3,0)) -> -28.285259 | L37: =INDEX('HY & Segments'!$A:$AG,MATCH($A37,'HY & Segments'!$A:$A,0),MATCH("1H"&RIGHT(L$1,2),'HY & Segments'!$3:$3,0))+INDEX('HY & Segments'!$A:$AG,MATCH($A37,'HY & Segments'!$A:$A,0),MATCH("2H"&RIGHT(L$1,2),'HY & Segments'!$3:$3,0)) -> -29.862162 | M37: =INDEX('HY & Segments'!$A:$AG,MATCH($A37,'HY & Segments'!$A:$A,0),MATCH("1H"&RIGHT(M$1,2),'HY & Segments'!$3:$3,0))+INDEX('HY & Segments'!$A:$AG,MATCH($A37,'HY & Segments'!$A:$A,0),MATCH("2H"&RIGHT(M$1,2),'HY & Segments'!$3:$3,0)) -> -31.526978 | N37: =INDEX('HY & Segments'!$A:$AG,MATCH($A37,'HY & Segments'!$A:$A,0),MATCH("1H"&RIGHT(N$1,2),'HY & Segments'!$3:$3,0))+INDEX('HY & Segments'!$A:$AG,MATCH($A37,'HY & Segments'!$A:$A,0),MATCH("2H"&RIGHT(N$1,2),'HY & Segments'!$3:$3,0)) -> -33.284607 | ... P37: =INDEX('HY & Segments'!$A:$AG,MATCH($A37,'HY & Segments'!$A:$A,0),MATCH("1H"&RIGHT(P$1,2),'HY & Segments'!$3:$3,0))+INDEX('HY & Segments'!$A:$AG,MATCH($A37,'HY & Segments'!$A:$A,0),MATCH("2H"&RIGHT(P$1,2),'HY & Segments'!$3:$3,0)) -> -37.099291
A38: EBITDA-Underlying EBITDA | B38: Underlying EBITDA | C38: NZDm | D38: =SUM(D35:D37) -> 218.9 | E38: =SUM(E35:E37) -> 147.6 | F38: =SUM(F35:F37) -> 112 | G38: =SUM(G35:G37) -> 134.80708 | H38: =SUM(H35:H37) -> 157.62309 | I38: =SUM(I35:I37) -> 172.77767 | J38: =SUM(J35:J37) -> 188.93631 | K38: =SUM(K35:K37) -> 206.15894 | ... P38: =SUM(P35:P37) -> 310.58269
B39: EBITDA Growth | C39: % YoY | E39: =IF(D38=0,"",E38/D38-1) -> -0.32571951 | F39: =IF(E38=0,"",F38/E38-1) -> -0.24119241 | G39: =IF(F38=0,"",G38/F38-1) -> 0.20363467 | H39: =IF(G38=0,"",H38/G38-1) -> 0.16924928 | I39: =IF(H38=0,"",I38/H38-1) -> 0.096144474 | J39: =IF(I38=0,"",J38/I38-1) -> 0.0935227 | K39: =IF(J38=0,"",K38/J38-1) -> 0.091155774 | L39: =IF(K38=0,"",L38/K38-1) -> 0.089009154 | ... P39: =IF(O38=0,"",P38/O38-1) -> 0.082119806
B40: EBITDA Margin | C40: % | D40: =IF(D9=0,"",D38/D9) -> 0.17583742 | E40: =IF(E9=0,"",E38/E9) -> 0.1386827 | F40: =IF(F9=0,"",F38/F9) -> 0.118131 | G40: =IF(G9=0,"",G38/G9) -> 0.12534734 | H40: =IF(H9=0,"",H38/H9) -> 0.13488986 | I40: =IF(I9=0,"",I38/I9) -> 0.14005094 | J40: =IF(J9=0,"",J38/J9) -> 0.14506169 | K40: =IF(K9=0,"",K38/K9) -> 0.1499265 | ... P40: =IF(P9=0,"",P38/P9) -> 0.1722059
B42: Statutory EBITDA Adjustments
A43: Stat-SBP | B43: Share-based payments | C43: NZDm | D43: 0 | E43: 0 | F43: 0 | G43: =0 -> 0 | H43: =0 -> 0 | I43: =0 -> 0 | J43: =0 -> 0 | K43: =0 -> 0 | L43: =0 -> 0 | M43: =0 -> 0 | N43: =0 -> 0 | ... P43: =0 -> 0
A44: Stat-Significant Items | B44: Significant items | C44: NZDm | D44: -10.2 | E44: 0 | F44: -3.1 | G44: =INDEX('HY & Segments'!$A:$AG,MATCH($A44,'HY & Segments'!$A:$A,0),MATCH("1H"&RIGHT(G$1,2),'HY & Segments'!$3:$3,0))+INDEX('HY & Segments'!$A:$AG,MATCH($A44,'HY & Segments'!$A:$A,0),MATCH("2H"&RIGHT(G$1,2),'HY & Segments'!$3:$3,0)) -> -1 | H44: =INDEX('HY & Segments'!$A:$AG,MATCH($A44,'HY & Segments'!$A:$A,0),MATCH("1H"&RIGHT(H$1,2),'HY & Segments'!$3:$3,0))+INDEX('HY & Segments'!$A:$AG,MATCH($A44,'HY & Segments'!$A:$A,0),MATCH("2H"&RIGHT(H$1,2),'HY & Segments'!$3:$3,0)) -> 0 | I44: =INDEX('HY & Segments'!$A:$AG,MATCH($A44,'HY & Segments'!$A:$A,0),MATCH("1H"&RIGHT(I$1,2),'HY & Segments'!$3:$3,0))+INDEX('HY & Segments'!$A:$AG,MATCH($A44,'HY & Segments'!$A:$A,0),MATCH("2H"&RIGHT(I$1,2),'HY & Segments'!$3:$3,0)) -> 0 | J44: =INDEX('HY & Segments'!$A:$AG,MATCH($A44,'HY & Segments'!$A:$A,0),MATCH("1H"&RIGHT(J$1,2),'HY & Segments'!$3:$3,0))+INDEX('HY & Segments'!$A:$AG,MATCH($A44,'HY & Segments'!$A:$A,0),MATCH("2H"&RIGHT(J$1,2),'HY & Segments'!$3:$3,0)) -> 0 | K44: =INDEX('HY & Segments'!$A:$AG,MATCH($A44,'HY & Segments'!$A:$A,0),MATCH("1H"&RIGHT(K$1,2),'HY & Segments'!$3:$3,0))+INDEX('HY & Segments'!$A:$AG,MATCH($A44,'HY & Segments'!$A:$A,0),MATCH("2H"&RIGHT(K$1,2),'HY & Segments'!$3:$3,0)) -> 0 | L44: =INDEX('HY & Segments'!$A:$AG,MATCH($A44,'HY & Segments'!$A:$A,0),MATCH("1H"&RIGHT(L$1,2),'HY & Segments'!$3:$3,0))+INDEX('HY & Segments'!$A:$AG,MATCH($A44,'HY & Segments'!$A:$A,0),MATCH("2H"&RIGHT(L$1,2),'HY & Segments'!$3:$3,0)) -> 0 | M44: =INDEX('HY & Segments'!$A:$AG,MATCH($A44,'HY & Segments'!$A:$A,0),MATCH("1H"&RIGHT(M$1,2),'HY & Segments'!$3:$3,0))+INDEX('HY & Segments'!$A:$AG,MATCH($A44,'HY & Segments'!$A:$A,0),MATCH("2H"&RIGHT(M$1,2),'HY & Segments'!$3:$3,0)) -> 0 | N44: =INDEX('HY & Segments'!$A:$AG,MATCH($A44,'HY & Segments'!$A:$A,0),MATCH("1H"&RIGHT(N$1,2),'HY & Segments'!$3:$3,0))+INDEX('HY & Segments'!$A:$AG,MATCH($A44,'HY & Segments'!$A:$A,0),MATCH("2H"&RIGHT(N$1,2),'HY & Segments'!$3:$3,0)) -> 0 | ... P44: =INDEX('HY & Segments'!$A:$AG,MATCH($A44,'HY & Segments'!$A:$A,0),MATCH("1H"&RIGHT(P$1,2),'HY & Segments'!$3:$3,0))+INDEX('HY & Segments'!$A:$AG,MATCH($A44,'HY & Segments'!$A:$A,0),MATCH("2H"&RIGHT(P$1,2),'HY & Segments'!$3:$3,0)) -> 0
A45: Stat-Statutory EBITDA | B45: Statutory EBITDA | C45: NZDm | D45: =D38+D43+D44 -> 208.7 | E45: =E38+E43+E44 -> 147.6 | F45: =F38+F43+F44 -> 108.9 | G45: =G38+G43+G44 -> 133.80708 | H45: =H38+H43+H44 -> 157.62309 | I45: =I38+I43+I44 -> 172.77767 | J45: =J38+J43+J44 -> 188.93631 | K45: =K38+K43+K44 -> 206.15894 | ... P45: =P38+P43+P44 -> 310.58269
...

Sheet HY & Segments
D1: 2023 | E1: 2023 | F1: 2024 | G1: 2024 | H1: 2025 | I1: 2025 | J1: 2026 | K1: 2026 | L1: 2027 | M1: 2027 | N1: 2028 | O1: 2028 | P1: 2029 | Q1: 2029 | R1: 2030 | S1: 2030 | T1: 2031 | U1: 2031 | V1: 2032 | W1: 2032 | X1: 2033 | Y1: 2033 | Z1: 2034 | AA1: 2034 | AB1: 2035 | AC1: 2035
B2: VSL Segments (Half-Year) | D2: Actual ----------> | K2: Forecast ----->
B3: Vulcan Steel (VSL.NZ) | C3: Units | D3: 1H23 | E3: 2H23 | F3: 1H24 | G3: 2H24 | H3: 1H25 | I3: 2H25 | J3: 1H26 | K3: 2H26 | L3: 1H27 | M3: 2H27 | N3: 1H28 | O3: 2H28 | P3: 1H29 | Q3: 2H29 | R3: 1H30 | S3: 2H30 | T3: 1H31 | U3: 2H31 | V3: 1H32 | W3: 2H32 | X3: 1H33 | Y3: 2H33 | Z3: 1H34 | AA3: 2H34 | AB3: 1H35 | AC3: 2H35
D4: 44926 | E4: 45107 | F4: 45291 | G4: 45473 | H4: 45657 | I4: 45838 | J4: 46022 | K4: 46203 | L4: 46387 | M4: 46568 | N4: 46752 | O4: 46934 | P4: 47118 | Q4: 47299 | R4: 47483 | S4: 47664 | T4: 47848 | U4: 48029 | V4: 48213 | W4: 48395 | X4: 48579 | Y4: 48760 | Z4: 48944 | AA4: 49125 | AB4: 49309 | AC4: 49490
B5: P&L
B6: Revenue
A7: Rev-Steel Revenue | B7: Steel Revenue | C7: NZDm | D7: 316.5 | E7: =INDEX(Annual!$A:$R,MATCH($A7,Annual!$A:$A,0),MATCH(E$1,Annual!$A$1:$R$1,0))-D7 -> 279.8 | F7: 252.3 | G7: =INDEX(Annual!$A:$R,MATCH($A7,Annual!$A:$A,0),MATCH(G$1,Annual!$A$1:$R$1,0))-F7 -> 219 | H7: 209.9 | I7: =INDEX(Annual!$A:$R,MATCH($A7,Annual!$A:$A,0),MATCH(I$1,Annual!$A$1:$R$1,0))-H7 -> 199.8 | J7: 262.5 | K7: =K97 -> 270.53528 | L7: =L97 -> 310.2405 | M7: =M97 -> 285.61762 | N7: =N97 -> 327.53641 | O7: =O97 -> 301.5408 | P7: =P97 -> 345.79656 | Q7: =Q97 -> 318.3517 | R7: =R97 -> 365.07472 | ... AC7: =AC97 -> 440.83261
A8: Rev-Metals Revenue | B8: Metals Revenue | C8: NZDm | D8: 321.4 | E8: =INDEX(Annual!$A:$R,MATCH($A8,Annual!$A:$A,0),MATCH(E$1,Annual!$A$1:$R$1,0))-D8 -> 327.2 | F8: 311.7 | G8: =INDEX(Annual!$A:$R,MATCH($A8,Annual!$A:$A,0),MATCH(G$1,Annual!$A$1:$R$1,0))-F8 -> 281.3 | H8: 283.1 | I8: =INDEX(Annual!$A:$R,MATCH($A8,Annual!$A:$A,0),MATCH(I$1,Annual!$A$1:$R$1,0))-H8 -> 255.3 | J8: 272.9 | K8: =K110 -> 269.53297 | L8: =L110 -> 288.11417 | M8: =M110 -> 284.55944 | N8: =N110 -> 304.17654 | O8: =O110 -> 300.42363 | P8: =P110 -> 321.13438 | Q8: =Q110 -> 317.17224 | R8: =R110 -> 339.03762 | ... AC8: =AC110 -> 439.19938
A9: Rev-Total Revenue | B9: Total Revenue | C9: NZDm | D9: =D7+D8 -> 637.9 | E9: =E7+E8 -> 607 | F9: =F7+F8 -> 564 | G9: =G7+G8 -> 500.3 | H9: =H7+H8 -> 493 | I9: =I7+I8 -> 455.1 | J9: =J7+J8 -> 535.4 | K9: =K7+K8 -> 540.06825 | ... AC9: =AC7+AC8 -> 880.03199
B10: Revenue Growth (YoY) | C10: % YoY | F10: =IF(D9=0,"",F9/D9-1) -> -0.11584888 | G10: =IF(E9=0,"",G9/E9-1) -> -0.17578254 | H10: =IF(F9=0,"",H9/F9-1) -> -0.12588652 | I10: =IF(G9=0,"",I9/G9-1) -> -0.090345793 | J10: =IF(H9=0,"",J9/H9-1) -> 0.086004057 | K10: =IF(I9=0,"",K9/I9-1) -> 0.18670238 | L10: =IF(J9=0,"",L9/J9-1) -> 0.11758437 | M10: =IF(K9=0,"",M9/K9-1) -> 0.05575 | ... AC10: =IF(AA9=0,"",AC9/AA9-1) -> 0.05575
B12: COGS
A13: COGS-Steel COGS | B13: Steel COGS | C13: NZDm | D13: =-D7*(1-Inputs!D6) -> -214.587 | E13: =INDEX(Annual!$A:$R,MATCH($A13,Annual!$A:$A,0),MATCH(E$1,Annual!$A$1:$R$1,0))-D13 -> -195.6674 | F13: =-F7*(1-Inputs!E6) -> -162.9858 | G13: =INDEX(Annual!$A:$R,MATCH($A13,Annual!$A:$A,0),MATCH(G$1,Annual!$A$1:$R$1,0))-F13 -> -164.6142 | H13: =-H7*(1-Inputs!F6) -> -149.6587 | I13: =INDEX(Annual!$A:$R,MATCH($A13,Annual!$A:$A,0),MATCH(I$1,Annual!$A$1:$R$1,0))-H13 -> -140.8413 | J13: =-J7*(1-Inputs!G6) -> -184.0125 | K13: =-K7*(1-K98) -> -190.70341 | L13: =-L7*(1-L98) -> -217.47859 | M13: =-M7*(1-M98) -> -201.33512 | N13: =-N7*(1-N98) -> -229.60302 | O13: =-O7*(1-O98) -> -212.55955 | P13: =-P7*(1-P98) -> -242.40339 | Q13: =-Q7*(1-Q98) -> -224.40975 | R13: =-R7*(1-R98) -> -255.91738 | ... AC13: =-AC7*(1-AC98) -> -310.74794
A14: COGS-Metals COGS | B14: Metals COGS | C14: NZDm | D14: =-D8*(1-Inputs!D7) -> -194.1256 | E14: =INDEX(Annual!$A:$R,MATCH($A14,Annual!$A:$A,0),MATCH(E$1,Annual!$A$1:$R$1,0))-D14 -> -196.9802 | F14: =-F8*(1-Inputs!E7) -> -201.3582 | G14: =INDEX(Annual!$A:$R,MATCH($A14,Annual!$A:$A,0),MATCH(G$1,Annual!$A$1:$R$1,0))-F14 -> -174.0418 | H14: =-H8*(1-Inputs!F7) -> -169.86 | I14: =INDEX(Annual!$A:$R,MATCH($A14,Annual!$A:$A,0),MATCH(I$1,Annual!$A$1:$R$1,0))-H14 -> -162.84 | J14: =-J8*(1-Inputs!G7) -> -170.0167 | K14: =-K8*(1-K111) -> -171.91833 | L14: =-L8*(1-L111) -> -179.49513 | M14: =-M8*(1-M111) -> -181.50278 | N14: =-N8*(1-N111) -> -189.50198 | O14: =-O8*(1-O111) -> -191.62156 | P14: =-P8*(1-P111) -> -200.06672 | Q14: =-Q8*(1-Q111) -> -202.30446 | R14: =-R8*(1-R111) -> -211.22044 | ... AC14: =-AC8*(1-AC111) -> -280.13798
A15: COGS-Other COGS | B15: Other COGS | C15: NZDm | D15: 0 | E15: =INDEX(Annual!$A:$R,MATCH($A15,Annual!$A:$A,0),MATCH(E$1,Annual!$A$1:$R$1,0))-D15 -> 0 | F15: 0 | G15: =INDEX(Annual!$A:$R,MATCH($A15,Annual!$A:$A,0),MATCH(G$1,Annual!$A$1:$R$1,0))-F15 -> 0 | H15: 0 | I15: =INDEX(Annual!$A:$R,MATCH($A15,Annual!$A:$A,0),MATCH(I$1,Annual!$A$1:$R$1,0))-H15 -> 0 | J15: 0 | K15: =0 -> 0 | L15: =0 -> 0 | M15: =0 -> 0 | N15: =0 -> 0 | O15: =0 -> 0 | P15: =0 -> 0 | Q15: =0 -> 0 | R15: =0 -> 0 | ... AC15: =0 -> 0
A16: COGS-Total COGS | B16: Total COGS | C16: NZDm | D16: =SUM(D13:D15) -> -408.7126 | E16: =SUM(E13:E15) -> -392.6476 | F16: =SUM(F13:F15) -> -364.344 | G16: =SUM(G13:G15) -> -338.656 | H16: =SUM(H13:H15) -> -319.5187 | I16: =SUM(I13:I15) -> -303.6813 | J16: =SUM(J13:J15) -> -354.0292 | K16: =SUM(K13:K15) -> -362.62174 | ... AC16: =SUM(AC13:AC15) -> -590.88592
B18: Gross Profit
A19: GP-Steel GP | B19: Steel GP | C19: NZDm | D19: =D7+D13 -> 101.913 | E19: =E7+E13 -> 84.1326 | F19: =F7+F13 -> 89.3142 | G19: =G7+G13 -> 54.3858 | H19: =H7+H13 -> 60.2413 | I19: =I7+I13 -> 58.9587 | J19: =J7+J13 -> 78.4875 | K19: =K7+K13 -> 79.831874 | ... AC19: =AC7+AC13 -> 130.08467
A20: GP-Metals GP | B20: Metals GP | C20: NZDm | D20: =D8+D14 -> 127.2744 | E20: =E8+E14 -> 130.2198 | F20: =F8+F14 -> 110.3418 | G20: =G8+G14 -> 107.2582 | H20: =H8+H14 -> 113.24 | I20: =I8+I14 -> 92.46 | J20: =J8+J14 -> 102.8833 | K20: =K8+K14 -> 97.614645 | ... AC20: =AC8+AC14 -> 159.0614
A21: GP-Corporate GP | B21: Corporate/Elim | C21: NZDm | D21: =D22-D19-D20 -> 0 | E21: =E22-E19-E20 -> 0 | F21: =F22-F19-F20 -> 0 | G21: =G22-G19-G20 -> 0 | H21: =H22-H19-H20 -> 0 | I21: =I22-I19-I20 -> 0 | J21: =J22-J19-J20 -> 0 | K21: =K22-K19-K20 -> 0 | ... AC21: =AC22-AC19-AC20 -> 0
A22: GP-Gross Profit | B22: Gross Profit | C22: NZDm | D22: =D9+D16 -> 229.1874 | E22: =E9+E16 -> 214.3524 | F22: =F9+F16 -> 199.656 | G22: =G9+G16 -> 161.644 | H22: =H9+H16 -> 173.4813 | I22: =I9+I16 -> 151.4187 | J22: =J9+J16 -> 181.3708 | K22: =K9+K16 -> 177.44652 | ... AC22: =AC9+AC16 -> 289.14607
B23: GP Growth (YoY) | C23: % YoY | F23: =IF(D22=0,"",F22/D22-1) -> -0.12885263 | G23: =IF(E22=0,"",G22/E22-1) -> -0.24589601 | H23: =IF(F22=0,"",H22/F22-1) -> -0.13109899 | I23: =IF(G22=0,"",I22/G22-1) -> -0.063258148 | J23: =IF(H22=0,"",J22/H22-1) -> 0.045477524 | K23: =IF(I22=0,"",K22/I22-1) -> 0.17189303 | L23: =IF(J22=0,"",L22/J22-1) -> 0.11032731 | M23: =IF(K22=0,"",M22/K22-1) -> 0.05575 | ... AC23: =IF(AA22=0,"",AC22/AA22-1) -> 0.05575
B24: GP Margin | C24: % | D24: =IF(D9=0,"",D22/D9) -> 0.35928421 | E24: =IF(E9=0,"",E22/E9) -> 0.3531341 | F24: =IF(F9=0,"",F22/F9) -> 0.354 | G24: =IF(G9=0,"",G22/G9) -> 0.32309414 | H24: =IF(H9=0,"",H22/H9) -> 0.35188905 | I24: =IF(I9=0,"",I22/I9) -> 0.33271523 | J24: =IF(J9=0,"",J22/J9) -> 0.33875756 | K24: =IF(K9=0,"",K22/K9) -> 0.32856314 | ... AC24: =IF(AC9=0,"",AC22/AC9) -> 0.32856314
B25: Steel GP Margin | C25: % | D25: =IF(D7=0,"",D19/D7) -> 0.322 | E25: =IF(E7=0,"",E19/E7) -> 0.30068835 | F25: =IF(F7=0,"",F19/F7) -> 0.354 | G25: =IF(G7=0,"",G19/G7) -> 0.24833699 | H25: =IF(H7=0,"",H19/H7) -> 0.287 | I25: =IF(I7=0,"",I19/I7) -> 0.29508859 | J25: =IF(J7=0,"",J19/J7) -> 0.299 | K25: =IF(K7=0,"",K19/K7) -> 0.29508859 | ... AC25: =IF(AC7=0,"",AC19/AC7) -> 0.29508859
B26: Metals GP Margin | C26: % | D26: =IF(D8=0,"",D20/D8) -> 0.396 | E26: =IF(E8=0,"",E20/E8) -> 0.39798227 | F26: =IF(F8=0,"",F20/F8) -> 0.354 | G26: =IF(G8=0,"",G20/G8) -> 0.3812947 | H26: =IF(H8=0,"",H20/H8) -> 0.4 | I26: =IF(I8=0,"",I20/I8) -> 0.36216216 | J26: =IF(J8=0,"",J20/J8) -> 0.377 | K26: =IF(K8=0,"",K20/K8) -> 0.36216216 | ... AC26: =IF(AC8=0,"",AC20/AC8) -> 0.36216216
B28: Operating Expenses
A29: OPEX-Employee Benefits | B29: Employee Benefits | C29: NZDm | D29: -70.7 | E29: =INDEX(Annual!$A:$R,MATCH($A29,Annual!$A:$A,0),MATCH(E$1,Annual!$A$1:$R$1,0))-D29 -> -71.5 | F29: -71.5 | G29: =INDEX(Annual!$A:$R,MATCH($A29,Annual!$A:$A,0),MATCH(G$1,Annual!$A$1:$R$1,0))-F29 -> -67.8 | H29: -73.9 | I29: =INDEX(Annual!$A:$R,MATCH($A29,Annual!$A:$A,0),MATCH(I$1,Annual!$A$1:$R$1,0))-H29 -> -72.5 | J29: -88.7 | K29: =IF(I33=0,0,K33*I29/I33) -> -75.475094 | L29: =IF(J33=0,0,L33*J29/J33) -> -91.836994 | M29: =IF(K33=0,0,M33*K29/K33) -> -77.56866 | N29: =IF(L33=0,0,N33*L29/L33) -> -94.45495 | O29: =IF(M33=0,0,O33*M29/M33) -> -79.726087 | P29: =IF(N33=0,0,P33*N29/N33) -> -97.156309 | Q29: =IF(O33=0,0,Q33*O29/O33) -> -81.949615 | R29: =IF(P33=0,0,R33*P29/P33) -> -99.944156 | ... AC29: =IF(AA33=0,0,AC33*AA29/AA33) -> -96.816409
A30: OPEX-Selling & Distribution | B30: Selling & Distribution | C30: NZDm | D30: -13.3 | E30: =INDEX(Annual!$A:$R,MATCH($A30,Annual!$A:$A,0),MATCH(E$1,Annual!$A$1:$R$1,0))-D30 -> -13.4 | F30: -15 | G30: =INDEX(Annual!$A:$R,MATCH($A30,Annual!$A:$A,0),MATCH(G$1,Annual!$A$1:$R$1,0))-F30 -> -12.5 | H30: -11.6 | I30: =INDEX(Annual!$A:$R,MATCH($A30,Annual!$A:$A,0),MATCH(I$1,Annual!$A$1:$R$1,0))-H30 -> -10.9 | J30: -12.3 | K30: =IF(I33=0,0,K33*I30/I33) -> -11.34729 | L30: =IF(J33=0,0,L33*J30/J33) -> -12.735006 | M30: =IF(K33=0,0,M33*K30/K33) -> -11.662047 | N30: =IF(L33=0,0,N33*L30/L33) -> -13.098037 | O30: =IF(M33=0,0,O33*M30/M33) -> -11.986405 | P30: =IF(N33=0,0,P33*N30/N33) -> -13.472634 | Q30: =IF(O33=0,0,Q33*O30/O33) -> -12.320701 | R30: =IF(P33=0,0,R33*P30/P33) -> -13.859223 | ... AC30: =IF(AA33=0,0,AC33*AA30/AA33) -> -14.555846
A31: OPEX-Occupancy Costs | B31: Occupancy Costs | C31: NZDm | D31: -4.9 | E31: =INDEX(Annual!$A:$R,MATCH($A31,Annual!$A:$A,0),MATCH(E$1,Annual!$A$1:$R$1,0))-D31 -> -6.1 | F31: -7 | G31: =INDEX(Annual!$A:$R,MATCH($A31,Annual!$A:$A,0),MATCH(G$1,Annual!$A$1:$R$1,0))-F31 -> -5.8 | H31: -7.2 | I31: =INDEX(Annual!$A:$R,MATCH($A31,Annual!$A:$A,0),MATCH(I$1,Annual!$A$1:$R$1,0))-H31 -> -7 | J31: -8.3 | K31: =IF(I33=0,0,K33*I31/I33) -> -7.2872505 | L31: =IF(J33=0,0,L33*J31/J33) -> -8.5935406 | M31: =IF(K33=0,0,M33*K31/K33) -> -7.4893878 | N31: =IF(L33=0,0,N33*L31/L33) -> -8.8385128 | O31: =IF(M33=0,0,O33*M31/M33) -> -7.6976911 | P31: =IF(N33=0,0,P33*N31/N33) -> -9.0912894 | Q31: =IF(O33=0,0,Q33*O31/O33) -> -7.9123766 | R31: =IF(P33=0,0,R33*P31/P33) -> -9.3521589 | ... AC31: =IF(AA33=0,0,AC33*AA31/AA33) -> -9.3477912
A32: OPEX-General & Admin | B32: General & Admin | C32: NZDm | D32: -25.1 | E32: =INDEX(Annual!$A:$R,MATCH($A32,Annual!$A:$A,0),MATCH(E$1,Annual!$A$1:$R$1,0))-D32 -> -20.4 | F32: -24.5 | G32: =INDEX(Annual!$A:$R,MATCH($A32,Annual!$A:$A,0),MATCH(G$1,Annual!$A$1:$R$1,0))-F32 -> -9.7 | H32: -23.8 | I32: =INDEX(Annual!$A:$R,MATCH($A32,Annual!$A:$A,0),MATCH(I$1,Annual!$A$1:$R$1,0))-H32 -> -5.6 | J32: -14.7 | K32: =IF(I33=0,0,K33*I32/I33) -> -5.8298004 | L32: =IF(J33=0,0,L33*J32/J33) -> -15.219885 | M32: =IF(K33=0,0,M33*K32/K33) -> -5.9915103 | N32: =IF(L33=0,0,N33*L32/L33) -> -15.653752 | O32: =IF(M33=0,0,O33*M32/M33) -> -6.1581529 | P32: =IF(N33=0,0,P33*N32/N33) -> -16.10144 | Q32: =IF(O33=0,0,Q33*O32/O33) -> -6.3299013 | R32: =IF(P33=0,0,R33*P32/P33) -> -16.563462 | ... AC32: =IF(AA33=0,0,AC33*AA32/AA33) -> -7.478233
