Workbook

Sheet Value
B2: DCF Valuation
B4: Current Share Price (A$) | C4: 7.91
B5: Shares Outstanding (#m) | C5: =INDEX(Annual!$D:$P,MATCH("EPS-YE Shares",Annual!$A:$A,0),MATCH($D$24,Annual!$D$3:$P$3,0)-1)
B6: Market Cap (A$m) | C6: =C4*C5
B7: Net Debt (A$m) | C7: =INDEX(Annual!$D:$P,MATCH("BS-Total Banking Debt",Annual!$A:$A,0),MATCH($D$24,Annual!$D$3:$P$3,0)-1)-INDEX(Annual!$D:$P,MATCH("BS-Cash",Annual!$A:$A,0),MATCH($D$24,Annual!$D$3:$P$3,0)-1)
B8: Market EV (A$m) | C8: =C6+C7
B9: Valuation Date | C9: 46022
B11: WACC Inputs
B12: Risk-free Rate | C12: 0.04
B13: Equity Risk Premium | C13: 0.06
B14: Beta | C14: 1
B15: Cost of Equity | C15: =C12+C13*C14
B16: Pre-tax Cost of Debt | C16: 0.06
B17: Tax Rate | C17: 0.3
B18: After-tax Cost of Debt | C18: =C16*(1-C17)
B19: Debt Weight (D/(D+E)) | C19: 0.3
B20: WACC | C20: =C15*(1-C19)+C18*C19
B21: Terminal Growth Rate | C21: 0.025
B22: Stub Period | C22: =(INDEX(Annual!$D:$P,4,MATCH($D$24,Annual!$D$3:$P$3,0))-C9)/365.25
B24: FCF Projection | D24: FY26E | E24: FY27E | F24: FY28E | G24: FY29E | H24: FY30E | I24: FY31E | J24: FY32E | K24: FY33E | L24: FY34E | M24: FY35E
B25: EBITDA | C25: A$m | D25: =INDEX(Annual!$D:$P,MATCH("EBITDA-Statutory EBITDA",Annual!$A:$A,0),MATCH(D$24,Annual!$D$3:$P$3,0)) | E25: =INDEX(Annual!$D:$P,MATCH("EBITDA-Statutory EBITDA",Annual!$A:$A,0),MATCH(E$24,Annual!$D$3:$P$3,0)) | F25: =INDEX(Annual!$D:$P,MATCH("EBITDA-Statutory EBITDA",Annual!$A:$A,0),MATCH(F$24,Annual!$D$3:$P$3,0)) | G25: =INDEX(Annual!$D:$P,MATCH("EBITDA-Statutory EBITDA",Annual!$A:$A,0),MATCH(G$24,Annual!$D$3:$P$3,0)) | H25: =INDEX(Annual!$D:$P,MATCH("EBITDA-Statutory EBITDA",Annual!$A:$A,0),MATCH(H$24,Annual!$D$3:$P$3,0)) | I25: =INDEX(Annual!$D:$P,MATCH("EBITDA-Statutory EBITDA",Annual!$A:$A,0),MATCH(I$24,Annual!$D$3:$P$3,0)) | J25: =INDEX(Annual!$D:$P,MATCH("EBITDA-Statutory EBITDA",Annual!$A:$A,0),MATCH(J$24,Annual!$D$3:$P$3,0)) | K25: =INDEX(Annual!$D:$P,MATCH("EBITDA-Statutory EBITDA",Annual!$A:$A,0),MATCH(K$24,Annual!$D$3:$P$3,0)) | ... M25: =INDEX(Annual!$D:$P,MATCH("EBITDA-Statutory EBITDA",Annual!$A:$A,0),MATCH(M$24,Annual!$D$3:$P$3,0))
B26: less D&A | C26: A$m | D26: =INDEX(Annual!$D:$P,MATCH("DA-Total DA",Annual!$A:$A,0),MATCH(D$24,Annual!$D$3:$P$3,0)) | E26: =INDEX(Annual!$D:$P,MATCH("DA-Total DA",Annual!$A:$A,0),MATCH(E$24,Annual!$D$3:$P$3,0)) | F26: =INDEX(Annual!$D:$P,MATCH("DA-Total DA",Annual!$A:$A,0),MATCH(F$24,Annual!$D$3:$P$3,0)) | G26: =INDEX(Annual!$D:$P,MATCH("DA-Total DA",Annual!$A:$A,0),MATCH(G$24,Annual!$D$3:$P$3,0)) | H26: =INDEX(Annual!$D:$P,MATCH("DA-Total DA",Annual!$A:$A,0),MATCH(H$24,Annual!$D$3:$P$3,0)) | I26: =INDEX(Annual!$D:$P,MATCH("DA-Total DA",Annual!$A:$A,0),MATCH(I$24,Annual!$D$3:$P$3,0)) | J26: =INDEX(Annual!$D:$P,MATCH("DA-Total DA",Annual!$A:$A,0),MATCH(J$24,Annual!$D$3:$P$3,0)) | K26: =INDEX(Annual!$D:$P,MATCH("DA-Total DA",Annual!$A:$A,0),MATCH(K$24,Annual!$D$3:$P$3,0)) | ... M26: =INDEX(Annual!$D:$P,MATCH("DA-Total DA",Annual!$A:$A,0),MATCH(M$24,Annual!$D$3:$P$3,0))
B27: EBIT | C27: A$m | D27: =INDEX(Annual!$D:$P,MATCH("EBIT-EBIT",Annual!$A:$A,0),MATCH(D$24,Annual!$D$3:$P$3,0)) | E27: =INDEX(Annual!$D:$P,MATCH("EBIT-EBIT",Annual!$A:$A,0),MATCH(E$24,Annual!$D$3:$P$3,0)) | F27: =INDEX(Annual!$D:$P,MATCH("EBIT-EBIT",Annual!$A:$A,0),MATCH(F$24,Annual!$D$3:$P$3,0)) | G27: =INDEX(Annual!$D:$P,MATCH("EBIT-EBIT",Annual!$A:$A,0),MATCH(G$24,Annual!$D$3:$P$3,0)) | H27: =INDEX(Annual!$D:$P,MATCH("EBIT-EBIT",Annual!$A:$A,0),MATCH(H$24,Annual!$D$3:$P$3,0)) | I27: =INDEX(Annual!$D:$P,MATCH("EBIT-EBIT",Annual!$A:$A,0),MATCH(I$24,Annual!$D$3:$P$3,0)) | J27: =INDEX(Annual!$D:$P,MATCH("EBIT-EBIT",Annual!$A:$A,0),MATCH(J$24,Annual!$D$3:$P$3,0)) | K27: =INDEX(Annual!$D:$P,MATCH("EBIT-EBIT",Annual!$A:$A,0),MATCH(K$24,Annual!$D$3:$P$3,0)) | ... M27: =INDEX(Annual!$D:$P,MATCH("EBIT-EBIT",Annual!$A:$A,0),MATCH(M$24,Annual!$D$3:$P$3,0))
B28: less Tax on EBIT | C28: A$m | D28: =-D27*$C$17 | E28: =-E27*$C$17 | F28: =-F27*$C$17 | G28: =-G27*$C$17 | H28: =-H27*$C$17 | I28: =-I27*$C$17 | J28: =-J27*$C$17 | K28: =-K27*$C$17 | ... M28: =-M27*$C$17
B29: NOPAT | C29: A$m | D29: =D27+D28 | E29: =E27+E28 | F29: =F27+F28 | G29: =G27+G28 | H29: =H27+H28 | I29: =I27+I28 | J29: =J27+J28 | K29: =K27+K28 | ... M29: =M27+M28
B30: plus D&A | C30: A$m | D30: =-D26 | E30: =-E26 | F30: =-F26 | G30: =-G26 | H30: =-H26 | I30: =-I26 | J30: =-J26 | K30: =-K26 | ... M30: =-M26
B31: less Capex | C31: A$m | D31: =INDEX(Annual!$D:$P,MATCH("CF-Capex PPE",Annual!$A:$A,0),MATCH(D$24,Annual!$D$3:$P$3,0))+INDEX(Annual!$D:$P,MATCH("CF-Capex Intang",Annual!$A:$A,0),MATCH(D$24,Annual!$D$3:$P$3,0)) | E31: =INDEX(Annual!$D:$P,MATCH("CF-Capex PPE",Annual!$A:$A,0),MATCH(E$24,Annual!$D$3:$P$3,0))+INDEX(Annual!$D:$P,MATCH("CF-Capex Intang",Annual!$A:$A,0),MATCH(E$24,Annual!$D$3:$P$3,0)) | F31: =INDEX(Annual!$D:$P,MATCH("CF-Capex PPE",Annual!$A:$A,0),MATCH(F$24,Annual!$D$3:$P$3,0))+INDEX(Annual!$D:$P,MATCH("CF-Capex Intang",Annual!$A:$A,0),MATCH(F$24,Annual!$D$3:$P$3,0)) | G31: =INDEX(Annual!$D:$P,MATCH("CF-Capex PPE",Annual!$A:$A,0),MATCH(G$24,Annual!$D$3:$P$3,0))+INDEX(Annual!$D:$P,MATCH("CF-Capex Intang",Annual!$A:$A,0),MATCH(G$24,Annual!$D$3:$P$3,0)) | H31: =INDEX(Annual!$D:$P,MATCH("CF-Capex PPE",Annual!$A:$A,0),MATCH(H$24,Annual!$D$3:$P$3,0))+INDEX(Annual!$D:$P,MATCH("CF-Capex Intang",Annual!$A:$A,0),MATCH(H$24,Annual!$D$3:$P$3,0)) | I31: =INDEX(Annual!$D:$P,MATCH("CF-Capex PPE",Annual!$A:$A,0),MATCH(I$24,Annual!$D$3:$P$3,0))+INDEX(Annual!$D:$P,MATCH("CF-Capex Intang",Annual!$A:$A,0),MATCH(I$24,Annual!$D$3:$P$3,0)) | J31: =INDEX(Annual!$D:$P,MATCH("CF-Capex PPE",Annual!$A:$A,0),MATCH(J$24,Annual!$D$3:$P$3,0))+INDEX(Annual!$D:$P,MATCH("CF-Capex Intang",Annual!$A:$A,0),MATCH(J$24,Annual!$D$3:$P$3,0)) | K31: =INDEX(Annual!$D:$P,MATCH("CF-Capex PPE",Annual!$A:$A,0),MATCH(K$24,Annual!$D$3:$P$3,0))+INDEX(Annual!$D:$P,MATCH("CF-Capex Intang",Annual!$A:$A,0),MATCH(K$24,Annual!$D$3:$P$3,0)) | ... M31: =INDEX(Annual!$D:$P,MATCH("CF-Capex PPE",Annual!$A:$A,0),MATCH(M$24,Annual!$D$3:$P$3,0))+INDEX(Annual!$D:$P,MATCH("CF-Capex Intang",Annual!$A:$A,0),MATCH(M$24,Annual!$D$3:$P$3,0))
B32: less WC Change | C32: A$m | D32: =INDEX(Annual!$D:$P,MATCH("CF-WC Change",Annual!$A:$A,0),MATCH(D$24,Annual!$D$3:$P$3,0)) | E32: =INDEX(Annual!$D:$P,MATCH("CF-WC Change",Annual!$A:$A,0),MATCH(E$24,Annual!$D$3:$P$3,0)) | F32: =INDEX(Annual!$D:$P,MATCH("CF-WC Change",Annual!$A:$A,0),MATCH(F$24,Annual!$D$3:$P$3,0)) | G32: =INDEX(Annual!$D:$P,MATCH("CF-WC Change",Annual!$A:$A,0),MATCH(G$24,Annual!$D$3:$P$3,0)) | H32: =INDEX(Annual!$D:$P,MATCH("CF-WC Change",Annual!$A:$A,0),MATCH(H$24,Annual!$D$3:$P$3,0)) | I32: =INDEX(Annual!$D:$P,MATCH("CF-WC Change",Annual!$A:$A,0),MATCH(I$24,Annual!$D$3:$P$3,0)) | J32: =INDEX(Annual!$D:$P,MATCH("CF-WC Change",Annual!$A:$A,0),MATCH(J$24,Annual!$D$3:$P$3,0)) | K32: =INDEX(Annual!$D:$P,MATCH("CF-WC Change",Annual!$A:$A,0),MATCH(K$24,Annual!$D$3:$P$3,0)) | ... M32: =INDEX(Annual!$D:$P,MATCH("CF-WC Change",Annual!$A:$A,0),MATCH(M$24,Annual!$D$3:$P$3,0))
B33: FCFF | C33: A$m | D33: =D29+D30+D31+D32 | E33: =E29+E30+E31+E32 | F33: =F29+F30+F31+F32 | G33: =G29+G30+G31+G32 | H33: =H29+H30+H31+H32 | I33: =I29+I30+I31+I32 | J33: =J29+J30+J31+J32 | K33: =K29+K30+K31+K32 | ... M33: =M29+M30+M31+M32
B34: Normalised FCFF (capex=D&A) | C34: A$m | M34: =M29+M32
B35: Terminal Value | M35: =M34*(1+$C$21)/($C$20-$C$21)
B37: Discount Factor | D37: =1/(1+$C$20)^($C$22+0) | E37: =1/(1+$C$20)^($C$22+1) | F37: =1/(1+$C$20)^($C$22+2) | G37: =1/(1+$C$20)^($C$22+3) | H37: =1/(1+$C$20)^($C$22+4) | I37: =1/(1+$C$20)^($C$22+5) | J37: =1/(1+$C$20)^($C$22+6) | K37: =1/(1+$C$20)^($C$22+7) | L37: =1/(1+$C$20)^($C$22+8) | M37: =1/(1+$C$20)^($C$22+9)
B38: PV of FCFF | D38: =D33*D37 | E38: =E33*E37 | F38: =F33*F37 | G38: =G33*G37 | H38: =H33*H37 | I38: =I33*I37 | J38: =J33*J37 | K38: =K33*K37 | ... M38: =M33*M37
B39: PV of Terminal Value | M39: =M35*M37
B41: Sum of PV of FCFs | C41: =SUM(D38:M38)
B42: PV of Terminal Value | C42: =M39
B43: Enterprise Value | C43: =C41+C42
B45: less Net Debt | C45: =-C7
B46: less Lease Liabilities | C46: =-INDEX(Annual!$D:$P,MATCH("BS-Lease Liabilities",Annual!$A:$A,0),MATCH($D$24,Annual!$D$3:$P$3,0)-1)
B47: Equity Value | C47: =C43+C45+C46
...

Sheet Annual
D1: 2023 | E1: 2024 | F1: 2025 | G1: 2026 | H1: 2027 | I1: 2028 | J1: 2029 | K1: 2030 | L1: 2031 | M1: 2032 | N1: 2033 | O1: 2034 | P1: 2035
B2: GYG Model Summary | D2: Actual ----------> | G2: Forecast ----->
B3: Guzman y Gomez (GYG.AX) | C3: Units | D3: FY23A | E3: FY24A | F3: FY25A | G3: FY26E | H3: FY27E | I3: FY28E | J3: FY29E | K3: FY30E | L3: FY31E | M3: FY32E | N3: FY33E | O3: FY34E | P3: FY35E
D4: 45107 | E4: 45473 | F4: 45838 | G4: 46203 | H4: 46568 | I4: 46934 | J4: 47299 | K4: 47664 | L4: 48029 | M4: 48395 | N4: 48760 | O4: 49125 | P4: 49490
B5: P&L
B6: Revenue
A7: Rev-Corp Restaurant Sales Aus | B7: Corp Restaurant Sales - Australia | C7: A$m | D7: 211.975 | E7: 278.877 | F7: 359.722 | G7: =INDEX('HY & Segments'!$A:$AG,MATCH($A7,'HY & Segments'!$A:$A,0),MATCH("1H"&RIGHT(G$1,2),'HY & Segments'!$3:$3,0))+INDEX('HY & Segments'!$A:$AG,MATCH($A7,'HY & Segments'!$A:$A,0),MATCH("2H"&RIGHT(G$1,2),'HY & Segments'!$3:$3,0)) | H7: =INDEX('HY & Segments'!$A:$AG,MATCH($A7,'HY & Segments'!$A:$A,0),MATCH("1H"&RIGHT(H$1,2),'HY & Segments'!$3:$3,0))+INDEX('HY & Segments'!$A:$AG,MATCH($A7,'HY & Segments'!$A:$A,0),MATCH("2H"&RIGHT(H$1,2),'HY & Segments'!$3:$3,0)) | I7: =INDEX('HY & Segments'!$A:$AG,MATCH($A7,'HY & Segments'!$A:$A,0),MATCH("1H"&RIGHT(I$1,2),'HY & Segments'!$3:$3,0))+INDEX('HY & Segments'!$A:$AG,MATCH($A7,'HY & Segments'!$A:$A,0),MATCH("2H"&RIGHT(I$1,2),'HY & Segments'!$3:$3,0)) | J7: =INDEX('HY & Segments'!$A:$AG,MATCH($A7,'HY & Segments'!$A:$A,0),MATCH("1H"&RIGHT(J$1,2),'HY & Segments'!$3:$3,0))+INDEX('HY & Segments'!$A:$AG,MATCH($A7,'HY & Segments'!$A:$A,0),MATCH("2H"&RIGHT(J$1,2),'HY & Segments'!$3:$3,0)) | K7: =INDEX('HY & Segments'!$A:$AG,MATCH($A7,'HY & Segments'!$A:$A,0),MATCH("1H"&RIGHT(K$1,2),'HY & Segments'!$3:$3,0))+INDEX('HY & Segments'!$A:$AG,MATCH($A7,'HY & Segments'!$A:$A,0),MATCH("2H"&RIGHT(K$1,2),'HY & Segments'!$3:$3,0)) | L7: =INDEX('HY & Segments'!$A:$AG,MATCH($A7,'HY & Segments'!$A:$A,0),MATCH("1H"&RIGHT(L$1,2),'HY & Segments'!$3:$3,0))+INDEX('HY & Segments'!$A:$AG,MATCH($A7,'HY & Segments'!$A:$A,0),MATCH("2H"&RIGHT(L$1,2),'HY & Segments'!$3:$3,0)) | M7: =INDEX('HY & Segments'!$A:$AG,MATCH($A7,'HY & Segments'!$A:$A,0),MATCH("1H"&RIGHT(M$1,2),'HY & Segments'!$3:$3,0))+INDEX('HY & Segments'!$A:$AG,MATCH($A7,'HY & Segments'!$A:$A,0),MATCH("2H"&RIGHT(M$1,2),'HY & Segments'!$3:$3,0)) | N7: =INDEX('HY & Segments'!$A:$AG,MATCH($A7,'HY & Segments'!$A:$A,0),MATCH("1H"&RIGHT(N$1,2),'HY & Segments'!$3:$3,0))+INDEX('HY & Segments'!$A:$AG,MATCH($A7,'HY & Segments'!$A:$A,0),MATCH("2H"&RIGHT(N$1,2),'HY & Segments'!$3:$3,0)) | ... P7: =INDEX('HY & Segments'!$A:$AG,MATCH($A7,'HY & Segments'!$A:$A,0),MATCH("1H"&RIGHT(P$1,2),'HY & Segments'!$3:$3,0))+INDEX('HY & Segments'!$A:$AG,MATCH($A7,'HY & Segments'!$A:$A,0),MATCH("2H"&RIGHT(P$1,2),'HY & Segments'!$3:$3,0))
A8: Rev-Corp Restaurant Sales US | B8: Corp Restaurant Sales - US | C8: A$m | D8: 5.959 | E8: 10.834 | F8: 8.869 | G8: =INDEX('HY & Segments'!$A:$AG,MATCH($A8,'HY & Segments'!$A:$A,0),MATCH("1H"&RIGHT(G$1,2),'HY & Segments'!$3:$3,0))+INDEX('HY & Segments'!$A:$AG,MATCH($A8,'HY & Segments'!$A:$A,0),MATCH("2H"&RIGHT(G$1,2),'HY & Segments'!$3:$3,0)) | H8: =INDEX('HY & Segments'!$A:$AG,MATCH($A8,'HY & Segments'!$A:$A,0),MATCH("1H"&RIGHT(H$1,2),'HY & Segments'!$3:$3,0))+INDEX('HY & Segments'!$A:$AG,MATCH($A8,'HY & Segments'!$A:$A,0),MATCH("2H"&RIGHT(H$1,2),'HY & Segments'!$3:$3,0)) | I8: =INDEX('HY & Segments'!$A:$AG,MATCH($A8,'HY & Segments'!$A:$A,0),MATCH("1H"&RIGHT(I$1,2),'HY & Segments'!$3:$3,0))+INDEX('HY & Segments'!$A:$AG,MATCH($A8,'HY & Segments'!$A:$A,0),MATCH("2H"&RIGHT(I$1,2),'HY & Segments'!$3:$3,0)) | J8: =INDEX('HY & Segments'!$A:$AG,MATCH($A8,'HY & Segments'!$A:$A,0),MATCH("1H"&RIGHT(J$1,2),'HY & Segments'!$3:$3,0))+INDEX('HY & Segments'!$A:$AG,MATCH($A8,'HY & Segments'!$A:$A,0),MATCH("2H"&RIGHT(J$1,2),'HY & Segments'!$3:$3,0)) | K8: =INDEX('HY & Segments'!$A:$AG,MATCH($A8,'HY & Segments'!$A:$A,0),MATCH("1H"&RIGHT(K$1,2),'HY & Segments'!$3:$3,0))+INDEX('HY & Segments'!$A:$AG,MATCH($A8,'HY & Segments'!$A:$A,0),MATCH("2H"&RIGHT(K$1,2),'HY & Segments'!$3:$3,0)) | L8: =INDEX('HY & Segments'!$A:$AG,MATCH($A8,'HY & Segments'!$A:$A,0),MATCH("1H"&RIGHT(L$1,2),'HY & Segments'!$3:$3,0))+INDEX('HY & Segments'!$A:$AG,MATCH($A8,'HY & Segments'!$A:$A,0),MATCH("2H"&RIGHT(L$1,2),'HY & Segments'!$3:$3,0)) | M8: =INDEX('HY & Segments'!$A:$AG,MATCH($A8,'HY & Segments'!$A:$A,0),MATCH("1H"&RIGHT(M$1,2),'HY & Segments'!$3:$3,0))+INDEX('HY & Segments'!$A:$AG,MATCH($A8,'HY & Segments'!$A:$A,0),MATCH("2H"&RIGHT(M$1,2),'HY & Segments'!$3:$3,0)) | N8: =INDEX('HY & Segments'!$A:$AG,MATCH($A8,'HY & Segments'!$A:$A,0),MATCH("1H"&RIGHT(N$1,2),'HY & Segments'!$3:$3,0))+INDEX('HY & Segments'!$A:$AG,MATCH($A8,'HY & Segments'!$A:$A,0),MATCH("2H"&RIGHT(N$1,2),'HY & Segments'!$3:$3,0)) | ... P8: =INDEX('HY & Segments'!$A:$AG,MATCH($A8,'HY & Segments'!$A:$A,0),MATCH("1H"&RIGHT(P$1,2),'HY & Segments'!$3:$3,0))+INDEX('HY & Segments'!$A:$AG,MATCH($A8,'HY & Segments'!$A:$A,0),MATCH("2H"&RIGHT(P$1,2),'HY & Segments'!$3:$3,0))
A9: Rev-Total Corp Restaurant Sales | B9: Total Corp Restaurant Sales | C9: A$m | D9: 217.934 | E9: 289.711 | F9: 368.591 | G9: =G7+G8 | H9: =H7+H8 | I9: =I7+I8 | J9: =J7+J8 | K9: =K7+K8 | L9: =L7+L8 | M9: =M7+M8 | N9: =N7+N8 | ... P9: =P7+P8
A10: Rev-Franchise Royalty Revenue | B10: Franchise Royalty Revenue | C10: A$m | D10: 40.51 | E10: 51.858 | F10: 66.761 | G10: =INDEX('HY & Segments'!$A:$AG,MATCH($A10,'HY & Segments'!$A:$A,0),MATCH("1H"&RIGHT(G$1,2),'HY & Segments'!$3:$3,0))+INDEX('HY & Segments'!$A:$AG,MATCH($A10,'HY & Segments'!$A:$A,0),MATCH("2H"&RIGHT(G$1,2),'HY & Segments'!$3:$3,0)) | H10: =INDEX('HY & Segments'!$A:$AG,MATCH($A10,'HY & Segments'!$A:$A,0),MATCH("1H"&RIGHT(H$1,2),'HY & Segments'!$3:$3,0))+INDEX('HY & Segments'!$A:$AG,MATCH($A10,'HY & Segments'!$A:$A,0),MATCH("2H"&RIGHT(H$1,2),'HY & Segments'!$3:$3,0)) | I10: =INDEX('HY & Segments'!$A:$AG,MATCH($A10,'HY & Segments'!$A:$A,0),MATCH("1H"&RIGHT(I$1,2),'HY & Segments'!$3:$3,0))+INDEX('HY & Segments'!$A:$AG,MATCH($A10,'HY & Segments'!$A:$A,0),MATCH("2H"&RIGHT(I$1,2),'HY & Segments'!$3:$3,0)) | J10: =INDEX('HY & Segments'!$A:$AG,MATCH($A10,'HY & Segments'!$A:$A,0),MATCH("1H"&RIGHT(J$1,2),'HY & Segments'!$3:$3,0))+INDEX('HY & Segments'!$A:$AG,MATCH($A10,'HY & Segments'!$A:$A,0),MATCH("2H"&RIGHT(J$1,2),'HY & Segments'!$3:$3,0)) | K10: =INDEX('HY & Segments'!$A:$AG,MATCH($A10,'HY & Segments'!$A:$A,0),MATCH("1H"&RIGHT(K$1,2),'HY & Segments'!$3:$3,0))+INDEX('HY & Segments'!$A:$AG,MATCH($A10,'HY & Segments'!$A:$A,0),MATCH("2H"&RIGHT(K$1,2),'HY & Segments'!$3:$3,0)) | L10: =INDEX('HY & Segments'!$A:$AG,MATCH($A10,'HY & Segments'!$A:$A,0),MATCH("1H"&RIGHT(L$1,2),'HY & Segments'!$3:$3,0))+INDEX('HY & Segments'!$A:$AG,MATCH($A10,'HY & Segments'!$A:$A,0),MATCH("2H"&RIGHT(L$1,2),'HY & Segments'!$3:$3,0)) | M10: =INDEX('HY & Segments'!$A:$AG,MATCH($A10,'HY & Segments'!$A:$A,0),MATCH("1H"&RIGHT(M$1,2),'HY & Segments'!$3:$3,0))+INDEX('HY & Segments'!$A:$AG,MATCH($A10,'HY & Segments'!$A:$A,0),MATCH("2H"&RIGHT(M$1,2),'HY & Segments'!$3:$3,0)) | N10: =INDEX('HY & Segments'!$A:$AG,MATCH($A10,'HY & Segments'!$A:$A,0),MATCH("1H"&RIGHT(N$1,2),'HY & Segments'!$3:$3,0))+INDEX('HY & Segments'!$A:$AG,MATCH($A10,'HY & Segments'!$A:$A,0),MATCH("2H"&RIGHT(N$1,2),'HY & Segments'!$3:$3,0)) | ... P10: =INDEX('HY & Segments'!$A:$AG,MATCH($A10,'HY & Segments'!$A:$A,0),MATCH("1H"&RIGHT(P$1,2),'HY & Segments'!$3:$3,0))+INDEX('HY & Segments'!$A:$AG,MATCH($A10,'HY & Segments'!$A:$A,0),MATCH("2H"&RIGHT(P$1,2),'HY & Segments'!$3:$3,0))
A11: Rev-Franchise Fee Revenue | B11: Franchise Fee Revenue | C11: A$m | D11: 0.6 | E11: 0.645 | F11: 0.63 | G11: =INDEX('HY & Segments'!$A:$AG,MATCH($A11,'HY & Segments'!$A:$A,0),MATCH("1H"&RIGHT(G$1,2),'HY & Segments'!$3:$3,0))+INDEX('HY & Segments'!$A:$AG,MATCH($A11,'HY & Segments'!$A:$A,0),MATCH("2H"&RIGHT(G$1,2),'HY & Segments'!$3:$3,0)) | H11: =INDEX('HY & Segments'!$A:$AG,MATCH($A11,'HY & Segments'!$A:$A,0),MATCH("1H"&RIGHT(H$1,2),'HY & Segments'!$3:$3,0))+INDEX('HY & Segments'!$A:$AG,MATCH($A11,'HY & Segments'!$A:$A,0),MATCH("2H"&RIGHT(H$1,2),'HY & Segments'!$3:$3,0)) | I11: =INDEX('HY & Segments'!$A:$AG,MATCH($A11,'HY & Segments'!$A:$A,0),MATCH("1H"&RIGHT(I$1,2),'HY & Segments'!$3:$3,0))+INDEX('HY & Segments'!$A:$AG,MATCH($A11,'HY & Segments'!$A:$A,0),MATCH("2H"&RIGHT(I$1,2),'HY & Segments'!$3:$3,0)) | J11: =INDEX('HY & Segments'!$A:$AG,MATCH($A11,'HY & Segments'!$A:$A,0),MATCH("1H"&RIGHT(J$1,2),'HY & Segments'!$3:$3,0))+INDEX('HY & Segments'!$A:$AG,MATCH($A11,'HY & Segments'!$A:$A,0),MATCH("2H"&RIGHT(J$1,2),'HY & Segments'!$3:$3,0)) | K11: =INDEX('HY & Segments'!$A:$AG,MATCH($A11,'HY & Segments'!$A:$A,0),MATCH("1H"&RIGHT(K$1,2),'HY & Segments'!$3:$3,0))+INDEX('HY & Segments'!$A:$AG,MATCH($A11,'HY & Segments'!$A:$A,0),MATCH("2H"&RIGHT(K$1,2),'HY & Segments'!$3:$3,0)) | L11: =INDEX('HY & Segments'!$A:$AG,MATCH($A11,'HY & Segments'!$A:$A,0),MATCH("1H"&RIGHT(L$1,2),'HY & Segments'!$3:$3,0))+INDEX('HY & Segments'!$A:$AG,MATCH($A11,'HY & Segments'!$A:$A,0),MATCH("2H"&RIGHT(L$1,2),'HY & Segments'!$3:$3,0)) | M11: =INDEX('HY & Segments'!$A:$AG,MATCH($A11,'HY & Segments'!$A:$A,0),MATCH("1H"&RIGHT(M$1,2),'HY & Segments'!$3:$3,0))+INDEX('HY & Segments'!$A:$AG,MATCH($A11,'HY & Segments'!$A:$A,0),MATCH("2H"&RIGHT(M$1,2),'HY & Segments'!$3:$3,0)) | N11: =INDEX('HY & Segments'!$A:$AG,MATCH($A11,'HY & Segments'!$A:$A,0),MATCH("1H"&RIGHT(N$1,2),'HY & Segments'!$3:$3,0))+INDEX('HY & Segments'!$A:$AG,MATCH($A11,'HY & Segments'!$A:$A,0),MATCH("2H"&RIGHT(N$1,2),'HY & Segments'!$3:$3,0)) | ... P11: =INDEX('HY & Segments'!$A:$AG,MATCH($A11,'HY & Segments'!$A:$A,0),MATCH("1H"&RIGHT(P$1,2),'HY & Segments'!$3:$3,0))+INDEX('HY & Segments'!$A:$AG,MATCH($A11,'HY & Segments'!$A:$A,0),MATCH("2H"&RIGHT(P$1,2),'HY & Segments'!$3:$3,0))
A12: Rev-Total Revenue | B12: Total Revenue | C12: A$m | D12: 259.044 | E12: 342.214 | F12: 435.982 | G12: =SUM(G9:G11) | H12: =SUM(H9:H11) | I12: =SUM(I9:I11) | J12: =SUM(J9:J11) | K12: =SUM(K9:K11) | L12: =SUM(L9:L11) | M12: =SUM(M9:M11) | N12: =SUM(N9:N11) | ... P12: =SUM(P9:P11)
B13: Revenue Growth | C13: % YoY | E13: =IF(D12=0,"",E12/D12-1) | F13: =IF(E12=0,"",F12/E12-1) | G13: =IF(F12=0,"",G12/F12-1) | H13: =IF(G12=0,"",H12/G12-1) | I13: =IF(H12=0,"",I12/H12-1) | J13: =IF(I12=0,"",J12/I12-1) | K13: =IF(J12=0,"",K12/J12-1) | L13: =IF(K12=0,"",L12/K12-1) | ... P13: =IF(O12=0,"",P12/O12-1)
B15: Other Revenue
A16: OthRev-Marketing Levy | B16: Marketing Levy Revenue | C16: A$m | D16: 13.252 | E16: 16.382 | F16: 19.688 | G16: =INDEX('HY & Segments'!$A:$AG,MATCH($A16,'HY & Segments'!$A:$A,0),MATCH("1H"&RIGHT(G$1,2),'HY & Segments'!$3:$3,0))+INDEX('HY & Segments'!$A:$AG,MATCH($A16,'HY & Segments'!$A:$A,0),MATCH("2H"&RIGHT(G$1,2),'HY & Segments'!$3:$3,0)) | H16: =INDEX('HY & Segments'!$A:$AG,MATCH($A16,'HY & Segments'!$A:$A,0),MATCH("1H"&RIGHT(H$1,2),'HY & Segments'!$3:$3,0))+INDEX('HY & Segments'!$A:$AG,MATCH($A16,'HY & Segments'!$A:$A,0),MATCH("2H"&RIGHT(H$1,2),'HY & Segments'!$3:$3,0)) | I16: =INDEX('HY & Segments'!$A:$AG,MATCH($A16,'HY & Segments'!$A:$A,0),MATCH("1H"&RIGHT(I$1,2),'HY & Segments'!$3:$3,0))+INDEX('HY & Segments'!$A:$AG,MATCH($A16,'HY & Segments'!$A:$A,0),MATCH("2H"&RIGHT(I$1,2),'HY & Segments'!$3:$3,0)) | J16: =INDEX('HY & Segments'!$A:$AG,MATCH($A16,'HY & Segments'!$A:$A,0),MATCH("1H"&RIGHT(J$1,2),'HY & Segments'!$3:$3,0))+INDEX('HY & Segments'!$A:$AG,MATCH($A16,'HY & Segments'!$A:$A,0),MATCH("2H"&RIGHT(J$1,2),'HY & Segments'!$3:$3,0)) | K16: =INDEX('HY & Segments'!$A:$AG,MATCH($A16,'HY & Segments'!$A:$A,0),MATCH("1H"&RIGHT(K$1,2),'HY & Segments'!$3:$3,0))+INDEX('HY & Segments'!$A:$AG,MATCH($A16,'HY & Segments'!$A:$A,0),MATCH("2H"&RIGHT(K$1,2),'HY & Segments'!$3:$3,0)) | L16: =INDEX('HY & Segments'!$A:$AG,MATCH($A16,'HY & Segments'!$A:$A,0),MATCH("1H"&RIGHT(L$1,2),'HY & Segments'!$3:$3,0))+INDEX('HY & Segments'!$A:$AG,MATCH($A16,'HY & Segments'!$A:$A,0),MATCH("2H"&RIGHT(L$1,2),'HY & Segments'!$3:$3,0)) | M16: =INDEX('HY & Segments'!$A:$AG,MATCH($A16,'HY & Segments'!$A:$A,0),MATCH("1H"&RIGHT(M$1,2),'HY & Segments'!$3:$3,0))+INDEX('HY & Segments'!$A:$AG,MATCH($A16,'HY & Segments'!$A:$A,0),MATCH("2H"&RIGHT(M$1,2),'HY & Segments'!$3:$3,0)) | N16: =INDEX('HY & Segments'!$A:$AG,MATCH($A16,'HY & Segments'!$A:$A,0),MATCH("1H"&RIGHT(N$1,2),'HY & Segments'!$3:$3,0))+INDEX('HY & Segments'!$A:$AG,MATCH($A16,'HY & Segments'!$A:$A,0),MATCH("2H"&RIGHT(N$1,2),'HY & Segments'!$3:$3,0)) | ... P16: =INDEX('HY & Segments'!$A:$AG,MATCH($A16,'HY & Segments'!$A:$A,0),MATCH("1H"&RIGHT(P$1,2),'HY & Segments'!$3:$3,0))+INDEX('HY & Segments'!$A:$AG,MATCH($A16,'HY & Segments'!$A:$A,0),MATCH("2H"&RIGHT(P$1,2),'HY & Segments'!$3:$3,0))
A17: OthRev-Other Franchise Revenue | B17: Other Franchise Revenue | C17: A$m | D17: 1.813 | E17: 6.164 | F17: 8.942 | G17: =INDEX('HY & Segments'!$A:$AG,MATCH($A17,'HY & Segments'!$A:$A,0),MATCH("1H"&RIGHT(G$1,2),'HY & Segments'!$3:$3,0))+INDEX('HY & Segments'!$A:$AG,MATCH($A17,'HY & Segments'!$A:$A,0),MATCH("2H"&RIGHT(G$1,2),'HY & Segments'!$3:$3,0)) | H17: =INDEX('HY & Segments'!$A:$AG,MATCH($A17,'HY & Segments'!$A:$A,0),MATCH("1H"&RIGHT(H$1,2),'HY & Segments'!$3:$3,0))+INDEX('HY & Segments'!$A:$AG,MATCH($A17,'HY & Segments'!$A:$A,0),MATCH("2H"&RIGHT(H$1,2),'HY & Segments'!$3:$3,0)) | I17: =INDEX('HY & Segments'!$A:$AG,MATCH($A17,'HY & Segments'!$A:$A,0),MATCH("1H"&RIGHT(I$1,2),'HY & Segments'!$3:$3,0))+INDEX('HY & Segments'!$A:$AG,MATCH($A17,'HY & Segments'!$A:$A,0),MATCH("2H"&RIGHT(I$1,2),'HY & Segments'!$3:$3,0)) | J17: =INDEX('HY & Segments'!$A:$AG,MATCH($A17,'HY & Segments'!$A:$A,0),MATCH("1H"&RIGHT(J$1,2),'HY & Segments'!$3:$3,0))+INDEX('HY & Segments'!$A:$AG,MATCH($A17,'HY & Segments'!$A:$A,0),MATCH("2H"&RIGHT(J$1,2),'HY & Segments'!$3:$3,0)) | K17: =INDEX('HY & Segments'!$A:$AG,MATCH($A17,'HY & Segments'!$A:$A,0),MATCH("1H"&RIGHT(K$1,2),'HY & Segments'!$3:$3,0))+INDEX('HY & Segments'!$A:$AG,MATCH($A17,'HY & Segments'!$A:$A,0),MATCH("2H"&RIGHT(K$1,2),'HY & Segments'!$3:$3,0)) | L17: =INDEX('HY & Segments'!$A:$AG,MATCH($A17,'HY & Segments'!$A:$A,0),MATCH("1H"&RIGHT(L$1,2),'HY & Segments'!$3:$3,0))+INDEX('HY & Segments'!$A:$AG,MATCH($A17,'HY & Segments'!$A:$A,0),MATCH("2H"&RIGHT(L$1,2),'HY & Segments'!$3:$3,0)) | M17: =INDEX('HY & Segments'!$A:$AG,MATCH($A17,'HY & Segments'!$A:$A,0),MATCH("1H"&RIGHT(M$1,2),'HY & Segments'!$3:$3,0))+INDEX('HY & Segments'!$A:$AG,MATCH($A17,'HY & Segments'!$A:$A,0),MATCH("2H"&RIGHT(M$1,2),'HY & Segments'!$3:$3,0)) | N17: =INDEX('HY & Segments'!$A:$AG,MATCH($A17,'HY & Segments'!$A:$A,0),MATCH("1H"&RIGHT(N$1,2),'HY & Segments'!$3:$3,0))+INDEX('HY & Segments'!$A:$AG,MATCH($A17,'HY & Segments'!$A:$A,0),MATCH("2H"&RIGHT(N$1,2),'HY & Segments'!$3:$3,0)) | ... P17: =INDEX('HY & Segments'!$A:$AG,MATCH($A17,'HY & Segments'!$A:$A,0),MATCH("1H"&RIGHT(P$1,2),'HY & Segments'!$3:$3,0))+INDEX('HY & Segments'!$A:$AG,MATCH($A17,'HY & Segments'!$A:$A,0),MATCH("2H"&RIGHT(P$1,2),'HY & Segments'!$3:$3,0))
A18: OthRev-Other Income | B18: Other Income | C18: A$m | D18: 2.66 | E18: 0.228 | F18: 3.394 | G18: =INDEX('HY & Segments'!$A:$AG,MATCH($A18,'HY & Segments'!$A:$A,0),MATCH("1H"&RIGHT(G$1,2),'HY & Segments'!$3:$3,0))+INDEX('HY & Segments'!$A:$AG,MATCH($A18,'HY & Segments'!$A:$A,0),MATCH("2H"&RIGHT(G$1,2),'HY & Segments'!$3:$3,0)) | H18: =INDEX('HY & Segments'!$A:$AG,MATCH($A18,'HY & Segments'!$A:$A,0),MATCH("1H"&RIGHT(H$1,2),'HY & Segments'!$3:$3,0))+INDEX('HY & Segments'!$A:$AG,MATCH($A18,'HY & Segments'!$A:$A,0),MATCH("2H"&RIGHT(H$1,2),'HY & Segments'!$3:$3,0)) | I18: =INDEX('HY & Segments'!$A:$AG,MATCH($A18,'HY & Segments'!$A:$A,0),MATCH("1H"&RIGHT(I$1,2),'HY & Segments'!$3:$3,0))+INDEX('HY & Segments'!$A:$AG,MATCH($A18,'HY & Segments'!$A:$A,0),MATCH("2H"&RIGHT(I$1,2),'HY & Segments'!$3:$3,0)) | J18: =INDEX('HY & Segments'!$A:$AG,MATCH($A18,'HY & Segments'!$A:$A,0),MATCH("1H"&RIGHT(J$1,2),'HY & Segments'!$3:$3,0))+INDEX('HY & Segments'!$A:$AG,MATCH($A18,'HY & Segments'!$A:$A,0),MATCH("2H"&RIGHT(J$1,2),'HY & Segments'!$3:$3,0)) | K18: =INDEX('HY & Segments'!$A:$AG,MATCH($A18,'HY & Segments'!$A:$A,0),MATCH("1H"&RIGHT(K$1,2),'HY & Segments'!$3:$3,0))+INDEX('HY & Segments'!$A:$AG,MATCH($A18,'HY & Segments'!$A:$A,0),MATCH("2H"&RIGHT(K$1,2),'HY & Segments'!$3:$3,0)) | L18: =INDEX('HY & Segments'!$A:$AG,MATCH($A18,'HY & Segments'!$A:$A,0),MATCH("1H"&RIGHT(L$1,2),'HY & Segments'!$3:$3,0))+INDEX('HY & Segments'!$A:$AG,MATCH($A18,'HY & Segments'!$A:$A,0),MATCH("2H"&RIGHT(L$1,2),'HY & Segments'!$3:$3,0)) | M18: =INDEX('HY & Segments'!$A:$AG,MATCH($A18,'HY & Segments'!$A:$A,0),MATCH("1H"&RIGHT(M$1,2),'HY & Segments'!$3:$3,0))+INDEX('HY & Segments'!$A:$AG,MATCH($A18,'HY & Segments'!$A:$A,0),MATCH("2H"&RIGHT(M$1,2),'HY & Segments'!$3:$3,0)) | N18: =INDEX('HY & Segments'!$A:$AG,MATCH($A18,'HY & Segments'!$A:$A,0),MATCH("1H"&RIGHT(N$1,2),'HY & Segments'!$3:$3,0))+INDEX('HY & Segments'!$A:$AG,MATCH($A18,'HY & Segments'!$A:$A,0),MATCH("2H"&RIGHT(N$1,2),'HY & Segments'!$3:$3,0)) | ... P18: =INDEX('HY & Segments'!$A:$AG,MATCH($A18,'HY & Segments'!$A:$A,0),MATCH("1H"&RIGHT(P$1,2),'HY & Segments'!$3:$3,0))+INDEX('HY & Segments'!$A:$AG,MATCH($A18,'HY & Segments'!$A:$A,0),MATCH("2H"&RIGHT(P$1,2),'HY & Segments'!$3:$3,0))
A19: OthRev-Total Other Revenue | B19: Total Other Revenue & Income | C19: A$m | D19: 17.725 | E19: 22.774 | F19: 32.024 | G19: =SUM(G16:G18) | H19: =SUM(H16:H18) | I19: =SUM(I16:I18) | J19: =SUM(J16:J18) | K19: =SUM(K16:K18) | L19: =SUM(L16:L18) | M19: =SUM(M16:M18) | N19: =SUM(N16:N18) | ... P19: =SUM(P16:P18)
B21: Total Revenue & Other Income | C21: A$m | D21: =D12+D19 | E21: =E12+E19 | F21: =F12+F19 | G21: =G12+G19 | H21: =H12+H19 | I21: =I12+I19 | J21: =J12+J19 | K21: =K12+K19 | ... P21: =P12+P19
B23: Segment EBITDA Bridge
A24: SegEBITDA-Australia | B24: Australia Segment EBITDA | C24: A$m | D24: 33.306 | E24: 47.536 | F24: 66.029 | G24: =INDEX('HY & Segments'!$A:$AG,MATCH($A24,'HY & Segments'!$A:$A,0),MATCH("1H"&RIGHT(G$1,2),'HY & Segments'!$3:$3,0))+INDEX('HY & Segments'!$A:$AG,MATCH($A24,'HY & Segments'!$A:$A,0),MATCH("2H"&RIGHT(G$1,2),'HY & Segments'!$3:$3,0)) | H24: =INDEX('HY & Segments'!$A:$AG,MATCH($A24,'HY & Segments'!$A:$A,0),MATCH("1H"&RIGHT(H$1,2),'HY & Segments'!$3:$3,0))+INDEX('HY & Segments'!$A:$AG,MATCH($A24,'HY & Segments'!$A:$A,0),MATCH("2H"&RIGHT(H$1,2),'HY & Segments'!$3:$3,0)) | I24: =INDEX('HY & Segments'!$A:$AG,MATCH($A24,'HY & Segments'!$A:$A,0),MATCH("1H"&RIGHT(I$1,2),'HY & Segments'!$3:$3,0))+INDEX('HY & Segments'!$A:$AG,MATCH($A24,'HY & Segments'!$A:$A,0),MATCH("2H"&RIGHT(I$1,2),'HY & Segments'!$3:$3,0)) | J24: =INDEX('HY & Segments'!$A:$AG,MATCH($A24,'HY & Segments'!$A:$A,0),MATCH("1H"&RIGHT(J$1,2),'HY & Segments'!$3:$3,0))+INDEX('HY & Segments'!$A:$AG,MATCH($A24,'HY & Segments'!$A:$A,0),MATCH("2H"&RIGHT(J$1,2),'HY & Segments'!$3:$3,0)) | K24: =INDEX('HY & Segments'!$A:$AG,MATCH($A24,'HY & Segments'!$A:$A,0),MATCH("1H"&RIGHT(K$1,2),'HY & Segments'!$3:$3,0))+INDEX('HY & Segments'!$A:$AG,MATCH($A24,'HY & Segments'!$A:$A,0),MATCH("2H"&RIGHT(K$1,2),'HY & Segments'!$3:$3,0)) | L24: =INDEX('HY & Segments'!$A:$AG,MATCH($A24,'HY & Segments'!$A:$A,0),MATCH("1H"&RIGHT(L$1,2),'HY & Segments'!$3:$3,0))+INDEX('HY & Segments'!$A:$AG,MATCH($A24,'HY & Segments'!$A:$A,0),MATCH("2H"&RIGHT(L$1,2),'HY & Segments'!$3:$3,0)) | M24: =INDEX('HY & Segments'!$A:$AG,MATCH($A24,'HY & Segments'!$A:$A,0),MATCH("1H"&RIGHT(M$1,2),'HY & Segments'!$3:$3,0))+INDEX('HY & Segments'!$A:$AG,MATCH($A24,'HY & Segments'!$A:$A,0),MATCH("2H"&RIGHT(M$1,2),'HY & Segments'!$3:$3,0)) | N24: =INDEX('HY & Segments'!$A:$AG,MATCH($A24,'HY & Segments'!$A:$A,0),MATCH("1H"&RIGHT(N$1,2),'HY & Segments'!$3:$3,0))+INDEX('HY & Segments'!$A:$AG,MATCH($A24,'HY & Segments'!$A:$A,0),MATCH("2H"&RIGHT(N$1,2),'HY & Segments'!$3:$3,0)) | ... P24: =INDEX('HY & Segments'!$A:$AG,MATCH($A24,'HY & Segments'!$A:$A,0),MATCH("1H"&RIGHT(P$1,2),'HY & Segments'!$3:$3,0))+INDEX('HY & Segments'!$A:$AG,MATCH($A24,'HY & Segments'!$A:$A,0),MATCH("2H"&RIGHT(P$1,2),'HY & Segments'!$3:$3,0))
A25: SegEBITDA-US | B25: US Segment EBITDA | C25: A$m | D25: -4.296 | E25: -6.544 | F25: -13.223 | G25: =INDEX('HY & Segments'!$A:$AG,MATCH($A25,'HY & Segments'!$A:$A,0),MATCH("1H"&RIGHT(G$1,2),'HY & Segments'!$3:$3,0))+INDEX('HY & Segments'!$A:$AG,MATCH($A25,'HY & Segments'!$A:$A,0),MATCH("2H"&RIGHT(G$1,2),'HY & Segments'!$3:$3,0)) | H25: =INDEX('HY & Segments'!$A:$AG,MATCH($A25,'HY & Segments'!$A:$A,0),MATCH("1H"&RIGHT(H$1,2),'HY & Segments'!$3:$3,0))+INDEX('HY & Segments'!$A:$AG,MATCH($A25,'HY & Segments'!$A:$A,0),MATCH("2H"&RIGHT(H$1,2),'HY & Segments'!$3:$3,0)) | I25: =INDEX('HY & Segments'!$A:$AG,MATCH($A25,'HY & Segments'!$A:$A,0),MATCH("1H"&RIGHT(I$1,2),'HY & Segments'!$3:$3,0))+INDEX('HY & Segments'!$A:$AG,MATCH($A25,'HY & Segments'!$A:$A,0),MATCH("2H"&RIGHT(I$1,2),'HY & Segments'!$3:$3,0)) | J25: =INDEX('HY & Segments'!$A:$AG,MATCH($A25,'HY & Segments'!$A:$A,0),MATCH("1H"&RIGHT(J$1,2),'HY & Segments'!$3:$3,0))+INDEX('HY & Segments'!$A:$AG,MATCH($A25,'HY & Segments'!$A:$A,0),MATCH("2H"&RIGHT(J$1,2),'HY & Segments'!$3:$3,0)) | K25: =INDEX('HY & Segments'!$A:$AG,MATCH($A25,'HY & Segments'!$A:$A,0),MATCH("1H"&RIGHT(K$1,2),'HY & Segments'!$3:$3,0))+INDEX('HY & Segments'!$A:$AG,MATCH($A25,'HY & Segments'!$A:$A,0),MATCH("2H"&RIGHT(K$1,2),'HY & Segments'!$3:$3,0)) | L25: =INDEX('HY & Segments'!$A:$AG,MATCH($A25,'HY & Segments'!$A:$A,0),MATCH("1H"&RIGHT(L$1,2),'HY & Segments'!$3:$3,0))+INDEX('HY & Segments'!$A:$AG,MATCH($A25,'HY & Segments'!$A:$A,0),MATCH("2H"&RIGHT(L$1,2),'HY & Segments'!$3:$3,0)) | M25: =INDEX('HY & Segments'!$A:$AG,MATCH($A25,'HY & Segments'!$A:$A,0),MATCH("1H"&RIGHT(M$1,2),'HY & Segments'!$3:$3,0))+INDEX('HY & Segments'!$A:$AG,MATCH($A25,'HY & Segments'!$A:$A,0),MATCH("2H"&RIGHT(M$1,2),'HY & Segments'!$3:$3,0)) | N25: =INDEX('HY & Segments'!$A:$AG,MATCH($A25,'HY & Segments'!$A:$A,0),MATCH("1H"&RIGHT(N$1,2),'HY & Segments'!$3:$3,0))+INDEX('HY & Segments'!$A:$AG,MATCH($A25,'HY & Segments'!$A:$A,0),MATCH("2H"&RIGHT(N$1,2),'HY & Segments'!$3:$3,0)) | ... P25: =INDEX('HY & Segments'!$A:$AG,MATCH($A25,'HY & Segments'!$A:$A,0),MATCH("1H"&RIGHT(P$1,2),'HY & Segments'!$3:$3,0))+INDEX('HY & Segments'!$A:$AG,MATCH($A25,'HY & Segments'!$A:$A,0),MATCH("2H"&RIGHT(P$1,2),'HY & Segments'!$3:$3,0))
A26: SegEBITDA-Total Segment EBITDA | B26: Total Segment Underlying EBITDA | C26: A$m | D26: 29.01 | E26: 40.992 | F26: 52.806 | G26: =G24+G25 | H26: =H24+H25 | I26: =I24+I25 | J26: =J24+J25 | K26: =K24+K25 | L26: =L24+L25 | M26: =M24+M25 | N26: =N24+N25 | ... P26: =P24+P25
A27: Bridge-Cash Rent | B27: Cash Rent Addback | C27: A$m | D27: 11.213 | E27: 17.084 | F27: 18.473 | G27: =INDEX('HY & Segments'!$A:$AG,MATCH($A27,'HY & Segments'!$A:$A,0),MATCH("1H"&RIGHT(G$1,2),'HY & Segments'!$3:$3,0))+INDEX('HY & Segments'!$A:$AG,MATCH($A27,'HY & Segments'!$A:$A,0),MATCH("2H"&RIGHT(G$1,2),'HY & Segments'!$3:$3,0)) | H27: =INDEX('HY & Segments'!$A:$AG,MATCH($A27,'HY & Segments'!$A:$A,0),MATCH("1H"&RIGHT(H$1,2),'HY & Segments'!$3:$3,0))+INDEX('HY & Segments'!$A:$AG,MATCH($A27,'HY & Segments'!$A:$A,0),MATCH("2H"&RIGHT(H$1,2),'HY & Segments'!$3:$3,0)) | I27: =INDEX('HY & Segments'!$A:$AG,MATCH($A27,'HY & Segments'!$A:$A,0),MATCH("1H"&RIGHT(I$1,2),'HY & Segments'!$3:$3,0))+INDEX('HY & Segments'!$A:$AG,MATCH($A27,'HY & Segments'!$A:$A,0),MATCH("2H"&RIGHT(I$1,2),'HY & Segments'!$3:$3,0)) | J27: =INDEX('HY & Segments'!$A:$AG,MATCH($A27,'HY & Segments'!$A:$A,0),MATCH("1H"&RIGHT(J$1,2),'HY & Segments'!$3:$3,0))+INDEX('HY & Segments'!$A:$AG,MATCH($A27,'HY & Segments'!$A:$A,0),MATCH("2H"&RIGHT(J$1,2),'HY & Segments'!$3:$3,0)) | K27: =INDEX('HY & Segments'!$A:$AG,MATCH($A27,'HY & Segments'!$A:$A,0),MATCH("1H"&RIGHT(K$1,2),'HY & Segments'!$3:$3,0))+INDEX('HY & Segments'!$A:$AG,MATCH($A27,'HY & Segments'!$A:$A,0),MATCH("2H"&RIGHT(K$1,2),'HY & Segments'!$3:$3,0)) | L27: =INDEX('HY & Segments'!$A:$AG,MATCH($A27,'HY & Segments'!$A:$A,0),MATCH("1H"&RIGHT(L$1,2),'HY & Segments'!$3:$3,0))+INDEX('HY & Segments'!$A:$AG,MATCH($A27,'HY & Segments'!$A:$A,0),MATCH("2H"&RIGHT(L$1,2),'HY & Segments'!$3:$3,0)) | M27: =INDEX('HY & Segments'!$A:$AG,MATCH($A27,'HY & Segments'!$A:$A,0),MATCH("1H"&RIGHT(M$1,2),'HY & Segments'!$3:$3,0))+INDEX('HY & Segments'!$A:$AG,MATCH($A27,'HY & Segments'!$A:$A,0),MATCH("2H"&RIGHT(M$1,2),'HY & Segments'!$3:$3,0)) | N27: =INDEX('HY & Segments'!$A:$AG,MATCH($A27,'HY & Segments'!$A:$A,0),MATCH("1H"&RIGHT(N$1,2),'HY & Segments'!$3:$3,0))+INDEX('HY & Segments'!$A:$AG,MATCH($A27,'HY & Segments'!$A:$A,0),MATCH("2H"&RIGHT(N$1,2),'HY & Segments'!$3:$3,0)) | ... P27: =INDEX('HY & Segments'!$A:$AG,MATCH($A27,'HY & Segments'!$A:$A,0),MATCH("1H"&RIGHT(P$1,2),'HY & Segments'!$3:$3,0))+INDEX('HY & Segments'!$A:$AG,MATCH($A27,'HY & Segments'!$A:$A,0),MATCH("2H"&RIGHT(P$1,2),'HY & Segments'!$3:$3,0))
A28: Bridge-SBP | B28: Share-Based Payments | C28: A$m | D28: -4.24 | E28: -11.142 | F28: -9.018 | G28: =INDEX('HY & Segments'!$A:$AG,MATCH($A28,'HY & Segments'!$A:$A,0),MATCH("1H"&RIGHT(G$1,2),'HY & Segments'!$3:$3,0))+INDEX('HY & Segments'!$A:$AG,MATCH($A28,'HY & Segments'!$A:$A,0),MATCH("2H"&RIGHT(G$1,2),'HY & Segments'!$3:$3,0)) | H28: =INDEX('HY & Segments'!$A:$AG,MATCH($A28,'HY & Segments'!$A:$A,0),MATCH("1H"&RIGHT(H$1,2),'HY & Segments'!$3:$3,0))+INDEX('HY & Segments'!$A:$AG,MATCH($A28,'HY & Segments'!$A:$A,0),MATCH("2H"&RIGHT(H$1,2),'HY & Segments'!$3:$3,0)) | I28: =INDEX('HY & Segments'!$A:$AG,MATCH($A28,'HY & Segments'!$A:$A,0),MATCH("1H"&RIGHT(I$1,2),'HY & Segments'!$3:$3,0))+INDEX('HY & Segments'!$A:$AG,MATCH($A28,'HY & Segments'!$A:$A,0),MATCH("2H"&RIGHT(I$1,2),'HY & Segments'!$3:$3,0)) | J28: =INDEX('HY & Segments'!$A:$AG,MATCH($A28,'HY & Segments'!$A:$A,0),MATCH("1H"&RIGHT(J$1,2),'HY & Segments'!$3:$3,0))+INDEX('HY & Segments'!$A:$AG,MATCH($A28,'HY & Segments'!$A:$A,0),MATCH("2H"&RIGHT(J$1,2),'HY & Segments'!$3:$3,0)) | K28: =INDEX('HY & Segments'!$A:$AG,MATCH($A28,'HY & Segments'!$A:$A,0),MATCH("1H"&RIGHT(K$1,2),'HY & Segments'!$3:$3,0))+INDEX('HY & Segments'!$A:$AG,MATCH($A28,'HY & Segments'!$A:$A,0),MATCH("2H"&RIGHT(K$1,2),'HY & Segments'!$3:$3,0)) | L28: =INDEX('HY & Segments'!$A:$AG,MATCH($A28,'HY & Segments'!$A:$A,0),MATCH("1H"&RIGHT(L$1,2),'HY & Segments'!$3:$3,0))+INDEX('HY & Segments'!$A:$AG,MATCH($A28,'HY & Segments'!$A:$A,0),MATCH("2H"&RIGHT(L$1,2),'HY & Segments'!$3:$3,0)) | M28: =INDEX('HY & Segments'!$A:$AG,MATCH($A28,'HY & Segments'!$A:$A,0),MATCH("1H"&RIGHT(M$1,2),'HY & Segments'!$3:$3,0))+INDEX('HY & Segments'!$A:$AG,MATCH($A28,'HY & Segments'!$A:$A,0),MATCH("2H"&RIGHT(M$1,2),'HY & Segments'!$3:$3,0)) | N28: =INDEX('HY & Segments'!$A:$AG,MATCH($A28,'HY & Segments'!$A:$A,0),MATCH("1H"&RIGHT(N$1,2),'HY & Segments'!$3:$3,0))+INDEX('HY & Segments'!$A:$AG,MATCH($A28,'HY & Segments'!$A:$A,0),MATCH("2H"&RIGHT(N$1,2),'HY & Segments'!$3:$3,0)) | ... P28: =INDEX('HY & Segments'!$A:$AG,MATCH($A28,'HY & Segments'!$A:$A,0),MATCH("1H"&RIGHT(P$1,2),'HY & Segments'!$3:$3,0))+INDEX('HY & Segments'!$A:$AG,MATCH($A28,'HY & Segments'!$A:$A,0),MATCH("2H"&RIGHT(P$1,2),'HY & Segments'!$3:$3,0))
A29: Bridge-Other | B29: Other Income/(Costs) | C29: A$m | D29: -6.362 | E29: -19.661 | F29: 2.858 | G29: =INDEX('HY & Segments'!$A:$AG,MATCH($A29,'HY & Segments'!$A:$A,0),MATCH("1H"&RIGHT(G$1,2),'HY & Segments'!$3:$3,0))+INDEX('HY & Segments'!$A:$AG,MATCH($A29,'HY & Segments'!$A:$A,0),MATCH("2H"&RIGHT(G$1,2),'HY & Segments'!$3:$3,0)) | H29: =INDEX('HY & Segments'!$A:$AG,MATCH($A29,'HY & Segments'!$A:$A,0),MATCH("1H"&RIGHT(H$1,2),'HY & Segments'!$3:$3,0))+INDEX('HY & Segments'!$A:$AG,MATCH($A29,'HY & Segments'!$A:$A,0),MATCH("2H"&RIGHT(H$1,2),'HY & Segments'!$3:$3,0)) | I29: =INDEX('HY & Segments'!$A:$AG,MATCH($A29,'HY & Segments'!$A:$A,0),MATCH("1H"&RIGHT(I$1,2),'HY & Segments'!$3:$3,0))+INDEX('HY & Segments'!$A:$AG,MATCH($A29,'HY & Segments'!$A:$A,0),MATCH("2H"&RIGHT(I$1,2),'HY & Segments'!$3:$3,0)) | J29: =INDEX('HY & Segments'!$A:$AG,MATCH($A29,'HY & Segments'!$A:$A,0),MATCH("1H"&RIGHT(J$1,2),'HY & Segments'!$3:$3,0))+INDEX('HY & Segments'!$A:$AG,MATCH($A29,'HY & Segments'!$A:$A,0),MATCH("2H"&RIGHT(J$1,2),'HY & Segments'!$3:$3,0)) | K29: =INDEX('HY & Segments'!$A:$AG,MATCH($A29,'HY & Segments'!$A:$A,0),MATCH("1H"&RIGHT(K$1,2),'HY & Segments'!$3:$3,0))+INDEX('HY & Segments'!$A:$AG,MATCH($A29,'HY & Segments'!$A:$A,0),MATCH("2H"&RIGHT(K$1,2),'HY & Segments'!$3:$3,0)) | L29: =INDEX('HY & Segments'!$A:$AG,MATCH($A29,'HY & Segments'!$A:$A,0),MATCH("1H"&RIGHT(L$1,2),'HY & Segments'!$3:$3,0))+INDEX('HY & Segments'!$A:$AG,MATCH($A29,'HY & Segments'!$A:$A,0),MATCH("2H"&RIGHT(L$1,2),'HY & Segments'!$3:$3,0)) | M29: =INDEX('HY & Segments'!$A:$AG,MATCH($A29,'HY & Segments'!$A:$A,0),MATCH("1H"&RIGHT(M$1,2),'HY & Segments'!$3:$3,0))+INDEX('HY & Segments'!$A:$AG,MATCH($A29,'HY & Segments'!$A:$A,0),MATCH("2H"&RIGHT(M$1,2),'HY & Segments'!$3:$3,0)) | N29: =INDEX('HY & Segments'!$A:$AG,MATCH($A29,'HY & Segments'!$A:$A,0),MATCH("1H"&RIGHT(N$1,2),'HY & Segments'!$3:$3,0))+INDEX('HY & Segments'!$A:$AG,MATCH($A29,'HY & Segments'!$A:$A,0),MATCH("2H"&RIGHT(N$1,2),'HY & Segments'!$3:$3,0)) | ... P29: =INDEX('HY & Segments'!$A:$AG,MATCH($A29,'HY & Segments'!$A:$A,0),MATCH("1H"&RIGHT(P$1,2),'HY & Segments'!$3:$3,0))+INDEX('HY & Segments'!$A:$AG,MATCH($A29,'HY & Segments'!$A:$A,0),MATCH("2H"&RIGHT(P$1,2),'HY & Segments'!$3:$3,0))
A30: EBITDA-Statutory EBITDA | B30: EBITDA | C30: A$m | D30: 29.621 | E30: 27.273 | F30: 65.119 | G30: =SUM(G26:G29) | H30: =SUM(H26:H29) | I30: =SUM(I26:I29) | J30: =SUM(J26:J29) | K30: =SUM(K26:K29) | L30: =SUM(L26:L29) | M30: =SUM(M26:M29) | N30: =SUM(N26:N29) | ... P30: =SUM(P26:P29)
B31: EBITDA Margin | C31: % | D31: =IF(D21=0,"",D30/D21) | E31: =IF(E21=0,"",E30/E21) | F31: =IF(F21=0,"",F30/F21) | G31: =IF(G21=0,"",G30/G21) | H31: =IF(H21=0,"",H30/H21) | I31: =IF(I21=0,"",I30/I21) | J31: =IF(J21=0,"",J30/J21) | K31: =IF(K21=0,"",K30/K21) | ... P31: =IF(P21=0,"",P30/P21)
B33: Expenses (Memo)
A34: Exp-Food & Packaging | B34: Cost of Food & Packaging | C34: A$m | D34: -70.428 | E34: -87.58 | F34: -113.948 | G34: =INDEX('HY & Segments'!$A:$AG,MATCH($A34,'HY & Segments'!$A:$A,0),MATCH("1H"&RIGHT(G$1,2),'HY & Segments'!$3:$3,0))+INDEX('HY & Segments'!$A:$AG,MATCH($A34,'HY & Segments'!$A:$A,0),MATCH("2H"&RIGHT(G$1,2),'HY & Segments'!$3:$3,0)) | H34: =INDEX('HY & Segments'!$A:$AG,MATCH($A34,'HY & Segments'!$A:$A,0),MATCH("1H"&RIGHT(H$1,2),'HY & Segments'!$3:$3,0))+INDEX('HY & Segments'!$A:$AG,MATCH($A34,'HY & Segments'!$A:$A,0),MATCH("2H"&RIGHT(H$1,2),'HY & Segments'!$3:$3,0)) | I34: =INDEX('HY & Segments'!$A:$AG,MATCH($A34,'HY & Segments'!$A:$A,0),MATCH("1H"&RIGHT(I$1,2),'HY & Segments'!$3:$3,0))+INDEX('HY & Segments'!$A:$AG,MATCH($A34,'HY & Segments'!$A:$A,0),MATCH("2H"&RIGHT(I$1,2),'HY & Segments'!$3:$3,0)) | J34: =INDEX('HY & Segments'!$A:$AG,MATCH($A34,'HY & Segments'!$A:$A,0),MATCH("1H"&RIGHT(J$1,2),'HY & Segments'!$3:$3,0))+INDEX('HY & Segments'!$A:$AG,MATCH($A34,'HY & Segments'!$A:$A,0),MATCH("2H"&RIGHT(J$1,2),'HY & Segments'!$3:$3,0)) | K34: =INDEX('HY & Segments'!$A:$AG,MATCH($A34,'HY & Segments'!$A:$A,0),MATCH("1H"&RIGHT(K$1,2),'HY & Segments'!$3:$3,0))+INDEX('HY & Segments'!$A:$AG,MATCH($A34,'HY & Segments'!$A:$A,0),MATCH("2H"&RIGHT(K$1,2),'HY & Segments'!$3:$3,0)) | L34: =INDEX('HY & Segments'!$A:$AG,MATCH($A34,'HY & Segments'!$A:$A,0),MATCH("1H"&RIGHT(L$1,2),'HY & Segments'!$3:$3,0))+INDEX('HY & Segments'!$A:$AG,MATCH($A34,'HY & Segments'!$A:$A,0),MATCH("2H"&RIGHT(L$1,2),'HY & Segments'!$3:$3,0)) | M34: =INDEX('HY & Segments'!$A:$AG,MATCH($A34,'HY & Segments'!$A:$A,0),MATCH("1H"&RIGHT(M$1,2),'HY & Segments'!$3:$3,0))+INDEX('HY & Segments'!$A:$AG,MATCH($A34,'HY & Segments'!$A:$A,0),MATCH("2H"&RIGHT(M$1,2),'HY & Segments'!$3:$3,0)) | N34: =INDEX('HY & Segments'!$A:$AG,MATCH($A34,'HY & Segments'!$A:$A,0),MATCH("1H"&RIGHT(N$1,2),'HY & Segments'!$3:$3,0))+INDEX('HY & Segments'!$A:$AG,MATCH($A34,'HY & Segments'!$A:$A,0),MATCH("2H"&RIGHT(N$1,2),'HY & Segments'!$3:$3,0)) | ... P34: =INDEX('HY & Segments'!$A:$AG,MATCH($A34,'HY & Segments'!$A:$A,0),MATCH("1H"&RIGHT(P$1,2),'HY & Segments'!$3:$3,0))+INDEX('HY & Segments'!$A:$AG,MATCH($A34,'HY & Segments'!$A:$A,0),MATCH("2H"&RIGHT(P$1,2),'HY & Segments'!$3:$3,0))
A35: Exp-Employee Benefits | B35: Employee Benefit Expenses | C35: A$m | D35: -113.725 | E35: -153.733 | F35: -184.656 | G35: =INDEX('HY & Segments'!$A:$AG,MATCH($A35,'HY & Segments'!$A:$A,0),MATCH("1H"&RIGHT(G$1,2),'HY & Segments'!$3:$3,0))+INDEX('HY & Segments'!$A:$AG,MATCH($A35,'HY & Segments'!$A:$A,0),MATCH("2H"&RIGHT(G$1,2),'HY & Segments'!$3:$3,0)) | H35: =INDEX('HY & Segments'!$A:$AG,MATCH($A35,'HY & Segments'!$A:$A,0),MATCH("1H"&RIGHT(H$1,2),'HY & Segments'!$3:$3,0))+INDEX('HY & Segments'!$A:$AG,MATCH($A35,'HY & Segments'!$A:$A,0),MATCH("2H"&RIGHT(H$1,2),'HY & Segments'!$3:$3,0)) | I35: =INDEX('HY & Segments'!$A:$AG,MATCH($A35,'HY & Segments'!$A:$A,0),MATCH("1H"&RIGHT(I$1,2),'HY & Segments'!$3:$3,0))+INDEX('HY & Segments'!$A:$AG,MATCH($A35,'HY & Segments'!$A:$A,0),MATCH("2H"&RIGHT(I$1,2),'HY & Segments'!$3:$3,0)) | J35: =INDEX('HY & Segments'!$A:$AG,MATCH($A35,'HY & Segments'!$A:$A,0),MATCH("1H"&RIGHT(J$1,2),'HY & Segments'!$3:$3,0))+INDEX('HY & Segments'!$A:$AG,MATCH($A35,'HY & Segments'!$A:$A,0),MATCH("2H"&RIGHT(J$1,2),'HY & Segments'!$3:$3,0)) | K35: =INDEX('HY & Segments'!$A:$AG,MATCH($A35,'HY & Segments'!$A:$A,0),MATCH("1H"&RIGHT(K$1,2),'HY & Segments'!$3:$3,0))+INDEX('HY & Segments'!$A:$AG,MATCH($A35,'HY & Segments'!$A:$A,0),MATCH("2H"&RIGHT(K$1,2),'HY & Segments'!$3:$3,0)) | L35: =INDEX('HY & Segments'!$A:$AG,MATCH($A35,'HY & Segments'!$A:$A,0),MATCH("1H"&RIGHT(L$1,2),'HY & Segments'!$3:$3,0))+INDEX('HY & Segments'!$A:$AG,MATCH($A35,'HY & Segments'!$A:$A,0),MATCH("2H"&RIGHT(L$1,2),'HY & Segments'!$3:$3,0)) | M35: =INDEX('HY & Segments'!$A:$AG,MATCH($A35,'HY & Segments'!$A:$A,0),MATCH("1H"&RIGHT(M$1,2),'HY & Segments'!$3:$3,0))+INDEX('HY & Segments'!$A:$AG,MATCH($A35,'HY & Segments'!$A:$A,0),MATCH("2H"&RIGHT(M$1,2),'HY & Segments'!$3:$3,0)) | N35: =INDEX('HY & Segments'!$A:$AG,MATCH($A35,'HY & Segments'!$A:$A,0),MATCH("1H"&RIGHT(N$1,2),'HY & Segments'!$3:$3,0))+INDEX('HY & Segments'!$A:$AG,MATCH($A35,'HY & Segments'!$A:$A,0),MATCH("2H"&RIGHT(N$1,2),'HY & Segments'!$3:$3,0)) | ... P35: =INDEX('HY & Segments'!$A:$AG,MATCH($A35,'HY & Segments'!$A:$A,0),MATCH("1H"&RIGHT(P$1,2),'HY & Segments'!$3:$3,0))+INDEX('HY & Segments'!$A:$AG,MATCH($A35,'HY & Segments'!$A:$A,0),MATCH("2H"&RIGHT(P$1,2),'HY & Segments'!$3:$3,0))
A36: Exp-Admin | B36: Administrative Expenses | C36: A$m | D36: -35.282 | E36: -60.595 | F36: -53.615 | G36: =INDEX('HY & Segments'!$A:$AG,MATCH($A36,'HY & Segments'!$A:$A,0),MATCH("1H"&RIGHT(G$1,2),'HY & Segments'!$3:$3,0))+INDEX('HY & Segments'!$A:$AG,MATCH($A36,'HY & Segments'!$A:$A,0),MATCH("2H"&RIGHT(G$1,2),'HY & Segments'!$3:$3,0)) | H36: =INDEX('HY & Segments'!$A:$AG,MATCH($A36,'HY & Segments'!$A:$A,0),MATCH("1H"&RIGHT(H$1,2),'HY & Segments'!$3:$3,0))+INDEX('HY & Segments'!$A:$AG,MATCH($A36,'HY & Segments'!$A:$A,0),MATCH("2H"&RIGHT(H$1,2),'HY & Segments'!$3:$3,0)) | I36: =INDEX('HY & Segments'!$A:$AG,MATCH($A36,'HY & Segments'!$A:$A,0),MATCH("1H"&RIGHT(I$1,2),'HY & Segments'!$3:$3,0))+INDEX('HY & Segments'!$A:$AG,MATCH($A36,'HY & Segments'!$A:$A,0),MATCH("2H"&RIGHT(I$1,2),'HY & Segments'!$3:$3,0)) | J36: =INDEX('HY & Segments'!$A:$AG,MATCH($A36,'HY & Segments'!$A:$A,0),MATCH("1H"&RIGHT(J$1,2),'HY & Segments'!$3:$3,0))+INDEX('HY & Segments'!$A:$AG,MATCH($A36,'HY & Segments'!$A:$A,0),MATCH("2H"&RIGHT(J$1,2),'HY & Segments'!$3:$3,0)) | K36: =INDEX('HY & Segments'!$A:$AG,MATCH($A36,'HY & Segments'!$A:$A,0),MATCH("1H"&RIGHT(K$1,2),'HY & Segments'!$3:$3,0))+INDEX('HY & Segments'!$A:$AG,MATCH($A36,'HY & Segments'!$A:$A,0),MATCH("2H"&RIGHT(K$1,2),'HY & Segments'!$3:$3,0)) | L36: =INDEX('HY & Segments'!$A:$AG,MATCH($A36,'HY & Segments'!$A:$A,0),MATCH("1H"&RIGHT(L$1,2),'HY & Segments'!$3:$3,0))+INDEX('HY & Segments'!$A:$AG,MATCH($A36,'HY & Segments'!$A:$A,0),MATCH("2H"&RIGHT(L$1,2),'HY & Segments'!$3:$3,0)) | M36: =INDEX('HY & Segments'!$A:$AG,MATCH($A36,'HY & Segments'!$A:$A,0),MATCH("1H"&RIGHT(M$1,2),'HY & Segments'!$3:$3,0))+INDEX('HY & Segments'!$A:$AG,MATCH($A36,'HY & Segments'!$A:$A,0),MATCH("2H"&RIGHT(M$1,2),'HY & Segments'!$3:$3,0)) | N36: =INDEX('HY & Segments'!$A:$AG,MATCH($A36,'HY & Segments'!$A:$A,0),MATCH("1H"&RIGHT(N$1,2),'HY & Segments'!$3:$3,0))+INDEX('HY & Segments'!$A:$AG,MATCH($A36,'HY & Segments'!$A:$A,0),MATCH("2H"&RIGHT(N$1,2),'HY & Segments'!$3:$3,0)) | ... P36: =INDEX('HY & Segments'!$A:$AG,MATCH($A36,'HY & Segments'!$A:$A,0),MATCH("1H"&RIGHT(P$1,2),'HY & Segments'!$3:$3,0))+INDEX('HY & Segments'!$A:$AG,MATCH($A36,'HY & Segments'!$A:$A,0),MATCH("2H"&RIGHT(P$1,2),'HY & Segments'!$3:$3,0))
A37: Exp-Marketing | B37: Marketing Expenses | C37: A$m | D37: -13.718 | E37: -17.938 | F37: -21.287 | G37: =INDEX('HY & Segments'!$A:$AG,MATCH($A37,'HY & Segments'!$A:$A,0),MATCH("1H"&RIGHT(G$1,2),'HY & Segments'!$3:$3,0))+INDEX('HY & Segments'!$A:$AG,MATCH($A37,'HY & Segments'!$A:$A,0),MATCH("2H"&RIGHT(G$1,2),'HY & Segments'!$3:$3,0)) | H37: =INDEX('HY & Segments'!$A:$AG,MATCH($A37,'HY & Segments'!$A:$A,0),MATCH("1H"&RIGHT(H$1,2),'HY & Segments'!$3:$3,0))+INDEX('HY & Segments'!$A:$AG,MATCH($A37,'HY & Segments'!$A:$A,0),MATCH("2H"&RIGHT(H$1,2),'HY & Segments'!$3:$3,0)) | I37: =INDEX('HY & Segments'!$A:$AG,MATCH($A37,'HY & Segments'!$A:$A,0),MATCH("1H"&RIGHT(I$1,2),'HY & Segments'!$3:$3,0))+INDEX('HY & Segments'!$A:$AG,MATCH($A37,'HY & Segments'!$A:$A,0),MATCH("2H"&RIGHT(I$1,2),'HY & Segments'!$3:$3,0)) | J37: =INDEX('HY & Segments'!$A:$AG,MATCH($A37,'HY & Segments'!$A:$A,0),MATCH("1H"&RIGHT(J$1,2),'HY & Segments'!$3:$3,0))+INDEX('HY & Segments'!$A:$AG,MATCH($A37,'HY & Segments'!$A:$A,0),MATCH("2H"&RIGHT(J$1,2),'HY & Segments'!$3:$3,0)) | K37: =INDEX('HY & Segments'!$A:$AG,MATCH($A37,'HY & Segments'!$A:$A,0),MATCH("1H"&RIGHT(K$1,2),'HY & Segments'!$3:$3,0))+INDEX('HY & Segments'!$A:$AG,MATCH($A37,'HY & Segments'!$A:$A,0),MATCH("2H"&RIGHT(K$1,2),'HY & Segments'!$3:$3,0)) | L37: =INDEX('HY & Segments'!$A:$AG,MATCH($A37,'HY & Segments'!$A:$A,0),MATCH("1H"&RIGHT(L$1,2),'HY & Segments'!$3:$3,0))+INDEX('HY & Segments'!$A:$AG,MATCH($A37,'HY & Segments'!$A:$A,0),MATCH("2H"&RIGHT(L$1,2),'HY & Segments'!$3:$3,0)) | M37: =INDEX('HY & Segments'!$A:$AG,MATCH($A37,'HY & Segments'!$A:$A,0),MATCH("1H"&RIGHT(M$1,2),'HY & Segments'!$3:$3,0))+INDEX('HY & Segments'!$A:$AG,MATCH($A37,'HY & Segments'!$A:$A,0),MATCH("2H"&RIGHT(M$1,2),'HY & Segments'!$3:$3,0)) | N37: =INDEX('HY & Segments'!$A:$AG,MATCH($A37,'HY & Segments'!$A:$A,0),MATCH("1H"&RIGHT(N$1,2),'HY & Segments'!$3:$3,0))+INDEX('HY & Segments'!$A:$AG,MATCH($A37,'HY & Segments'!$A:$A,0),MATCH("2H"&RIGHT(N$1,2),'HY & Segments'!$3:$3,0)) | ... P37: =INDEX('HY & Segments'!$A:$AG,MATCH($A37,'HY & Segments'!$A:$A,0),MATCH("1H"&RIGHT(P$1,2),'HY & Segments'!$3:$3,0))+INDEX('HY & Segments'!$A:$AG,MATCH($A37,'HY & Segments'!$A:$A,0),MATCH("2H"&RIGHT(P$1,2),'HY & Segments'!$3:$3,0))
A38: Exp-Other Expenses | B38: Other Expenses | C38: A$m | D38: -13.995 | E38: -17.868 | F38: -29.381 | G38: =INDEX('HY & Segments'!$A:$AG,MATCH($A38,'HY & Segments'!$A:$A,0),MATCH("1H"&RIGHT(G$1,2),'HY & Segments'!$3:$3,0))+INDEX('HY & Segments'!$A:$AG,MATCH($A38,'HY & Segments'!$A:$A,0),MATCH("2H"&RIGHT(G$1,2),'HY & Segments'!$3:$3,0)) | H38: =INDEX('HY & Segments'!$A:$AG,MATCH($A38,'HY & Segments'!$A:$A,0),MATCH("1H"&RIGHT(H$1,2),'HY & Segments'!$3:$3,0))+INDEX('HY & Segments'!$A:$AG,MATCH($A38,'HY & Segments'!$A:$A,0),MATCH("2H"&RIGHT(H$1,2),'HY & Segments'!$3:$3,0)) | I38: =INDEX('HY & Segments'!$A:$AG,MATCH($A38,'HY & Segments'!$A:$A,0),MATCH("1H"&RIGHT(I$1,2),'HY & Segments'!$3:$3,0))+INDEX('HY & Segments'!$A:$AG,MATCH($A38,'HY & Segments'!$A:$A,0),MATCH("2H"&RIGHT(I$1,2),'HY & Segments'!$3:$3,0)) | J38: =INDEX('HY & Segments'!$A:$AG,MATCH($A38,'HY & Segments'!$A:$A,0),MATCH("1H"&RIGHT(J$1,2),'HY & Segments'!$3:$3,0))+INDEX('HY & Segments'!$A:$AG,MATCH($A38,'HY & Segments'!$A:$A,0),MATCH("2H"&RIGHT(J$1,2),'HY & Segments'!$3:$3,0)) | K38: =INDEX('HY & Segments'!$A:$AG,MATCH($A38,'HY & Segments'!$A:$A,0),MATCH("1H"&RIGHT(K$1,2),'HY & Segments'!$3:$3,0))+INDEX('HY & Segments'!$A:$AG,MATCH($A38,'HY & Segments'!$A:$A,0),MATCH("2H"&RIGHT(K$1,2),'HY & Segments'!$3:$3,0)) | L38: =INDEX('HY & Segments'!$A:$AG,MATCH($A38,'HY & Segments'!$A:$A,0),MATCH("1H"&RIGHT(L$1,2),'HY & Segments'!$3:$3,0))+INDEX('HY & Segments'!$A:$AG,MATCH($A38,'HY & Segments'!$A:$A,0),MATCH("2H"&RIGHT(L$1,2),'HY & Segments'!$3:$3,0)) | M38: =INDEX('HY & Segments'!$A:$AG,MATCH($A38,'HY & Segments'!$A:$A,0),MATCH("1H"&RIGHT(M$1,2),'HY & Segments'!$3:$3,0))+INDEX('HY & Segments'!$A:$AG,MATCH($A38,'HY & Segments'!$A:$A,0),MATCH("2H"&RIGHT(M$1,2),'HY & Segments'!$3:$3,0)) | N38: =INDEX('HY & Segments'!$A:$AG,MATCH($A38,'HY & Segments'!$A:$A,0),MATCH("1H"&RIGHT(N$1,2),'HY & Segments'!$3:$3,0))+INDEX('HY & Segments'!$A:$AG,MATCH($A38,'HY & Segments'!$A:$A,0),MATCH("2H"&RIGHT(N$1,2),'HY & Segments'!$3:$3,0)) | ... P38: =INDEX('HY & Segments'!$A:$AG,MATCH($A38,'HY & Segments'!$A:$A,0),MATCH("1H"&RIGHT(P$1,2),'HY & Segments'!$3:$3,0))+INDEX('HY & Segments'!$A:$AG,MATCH($A38,'HY & Segments'!$A:$A,0),MATCH("2H"&RIGHT(P$1,2),'HY & Segments'!$3:$3,0))
A39: Exp-Total Expenses | B39: Total Expenses (excl D&A) | C39: A$m | D39: =SUM(D34:D38) | E39: =SUM(E34:E38) | F39: =SUM(F34:F38) | G39: =SUM(G34:G38) | H39: =SUM(H34:H38) | I39: =SUM(I34:I38) | J39: =SUM(J34:J38) | K39: =SUM(K34:K38) | ... P39: =SUM(P34:P38)
B41: Depreciation & Amortisation
A42: DA-ROU Depreciation | B42: Depreciation - ROU Assets | C42: A$m | D42: -10.332 | E42: -11.247 | F42: -13.874 | G42: =INDEX('HY & Segments'!$A:$AG,MATCH($A42,'HY & Segments'!$A:$A,0),MATCH("1H"&RIGHT(G$1,2),'HY & Segments'!$3:$3,0))+INDEX('HY & Segments'!$A:$AG,MATCH($A42,'HY & Segments'!$A:$A,0),MATCH("2H"&RIGHT(G$1,2),'HY & Segments'!$3:$3,0)) | H42: =INDEX('HY & Segments'!$A:$AG,MATCH($A42,'HY & Segments'!$A:$A,0),MATCH("1H"&RIGHT(H$1,2),'HY & Segments'!$3:$3,0))+INDEX('HY & Segments'!$A:$AG,MATCH($A42,'HY & Segments'!$A:$A,0),MATCH("2H"&RIGHT(H$1,2),'HY & Segments'!$3:$3,0)) | I42: =INDEX('HY & Segments'!$A:$AG,MATCH($A42,'HY & Segments'!$A:$A,0),MATCH("1H"&RIGHT(I$1,2),'HY & Segments'!$3:$3,0))+INDEX('HY & Segments'!$A:$AG,MATCH($A42,'HY & Segments'!$A:$A,0),MATCH("2H"&RIGHT(I$1,2),'HY & Segments'!$3:$3,0)) | J42: =INDEX('HY & Segments'!$A:$AG,MATCH($A42,'HY & Segments'!$A:$A,0),MATCH("1H"&RIGHT(J$1,2),'HY & Segments'!$3:$3,0))+INDEX('HY & Segments'!$A:$AG,MATCH($A42,'HY & Segments'!$A:$A,0),MATCH("2H"&RIGHT(J$1,2),'HY & Segments'!$3:$3,0)) | K42: =INDEX('HY & Segments'!$A:$AG,MATCH($A42,'HY & Segments'!$A:$A,0),MATCH("1H"&RIGHT(K$1,2),'HY & Segments'!$3:$3,0))+INDEX('HY & Segments'!$A:$AG,MATCH($A42,'HY & Segments'!$A:$A,0),MATCH("2H"&RIGHT(K$1,2),'HY & Segments'!$3:$3,0)) | L42: =INDEX('HY & Segments'!$A:$AG,MATCH($A42,'HY & Segments'!$A:$A,0),MATCH("1H"&RIGHT(L$1,2),'HY & Segments'!$3:$3,0))+INDEX('HY & Segments'!$A:$AG,MATCH($A42,'HY & Segments'!$A:$A,0),MATCH("2H"&RIGHT(L$1,2),'HY & Segments'!$3:$3,0)) | M42: =INDEX('HY & Segments'!$A:$AG,MATCH($A42,'HY & Segments'!$A:$A,0),MATCH("1H"&RIGHT(M$1,2),'HY & Segments'!$3:$3,0))+INDEX('HY & Segments'!$A:$AG,MATCH($A42,'HY & Segments'!$A:$A,0),MATCH("2H"&RIGHT(M$1,2),'HY & Segments'!$3:$3,0)) | N42: =INDEX('HY & Segments'!$A:$AG,MATCH($A42,'HY & Segments'!$A:$A,0),MATCH("1H"&RIGHT(N$1,2),'HY & Segments'!$3:$3,0))+INDEX('HY & Segments'!$A:$AG,MATCH($A42,'HY & Segments'!$A:$A,0),MATCH("2H"&RIGHT(N$1,2),'HY & Segments'!$3:$3,0)) | ... P42: =INDEX('HY & Segments'!$A:$AG,MATCH($A42,'HY & Segments'!$A:$A,0),MATCH("1H"&RIGHT(P$1,2),'HY & Segments'!$3:$3,0))+INDEX('HY & Segments'!$A:$AG,MATCH($A42,'HY & Segments'!$A:$A,0),MATCH("2H"&RIGHT(P$1,2),'HY & Segments'!$3:$3,0))
A43: DA-PPE Depreciation | B43: Depreciation - PPE | C43: A$m | D43: -8.39 | E43: -12.96 | F43: -19.296 | G43: =INDEX('HY & Segments'!$A:$AG,MATCH($A43,'HY & Segments'!$A:$A,0),MATCH("1H"&RIGHT(G$1,2),'HY & Segments'!$3:$3,0))+INDEX('HY & Segments'!$A:$AG,MATCH($A43,'HY & Segments'!$A:$A,0),MATCH("2H"&RIGHT(G$1,2),'HY & Segments'!$3:$3,0)) | H43: =INDEX('HY & Segments'!$A:$AG,MATCH($A43,'HY & Segments'!$A:$A,0),MATCH("1H"&RIGHT(H$1,2),'HY & Segments'!$3:$3,0))+INDEX('HY & Segments'!$A:$AG,MATCH($A43,'HY & Segments'!$A:$A,0),MATCH("2H"&RIGHT(H$1,2),'HY & Segments'!$3:$3,0)) | I43: =INDEX('HY & Segments'!$A:$AG,MATCH($A43,'HY & Segments'!$A:$A,0),MATCH("1H"&RIGHT(I$1,2),'HY & Segments'!$3:$3,0))+INDEX('HY & Segments'!$A:$AG,MATCH($A43,'HY & Segments'!$A:$A,0),MATCH("2H"&RIGHT(I$1,2),'HY & Segments'!$3:$3,0)) | J43: =INDEX('HY & Segments'!$A:$AG,MATCH($A43,'HY & Segments'!$A:$A,0),MATCH("1H"&RIGHT(J$1,2),'HY & Segments'!$3:$3,0))+INDEX('HY & Segments'!$A:$AG,MATCH($A43,'HY & Segments'!$A:$A,0),MATCH("2H"&RIGHT(J$1,2),'HY & Segments'!$3:$3,0)) | K43: =INDEX('HY & Segments'!$A:$AG,MATCH($A43,'HY & Segments'!$A:$A,0),MATCH("1H"&RIGHT(K$1,2),'HY & Segments'!$3:$3,0))+INDEX('HY & Segments'!$A:$AG,MATCH($A43,'HY & Segments'!$A:$A,0),MATCH("2H"&RIGHT(K$1,2),'HY & Segments'!$3:$3,0)) | L43: =INDEX('HY & Segments'!$A:$AG,MATCH($A43,'HY & Segments'!$A:$A,0),MATCH("1H"&RIGHT(L$1,2),'HY & Segments'!$3:$3,0))+INDEX('HY & Segments'!$A:$AG,MATCH($A43,'HY & Segments'!$A:$A,0),MATCH("2H"&RIGHT(L$1,2),'HY & Segments'!$3:$3,0)) | M43: =INDEX('HY & Segments'!$A:$AG,MATCH($A43,'HY & Segments'!$A:$A,0),MATCH("1H"&RIGHT(M$1,2),'HY & Segments'!$3:$3,0))+INDEX('HY & Segments'!$A:$AG,MATCH($A43,'HY & Segments'!$A:$A,0),MATCH("2H"&RIGHT(M$1,2),'HY & Segments'!$3:$3,0)) | N43: =INDEX('HY & Segments'!$A:$AG,MATCH($A43,'HY & Segments'!$A:$A,0),MATCH("1H"&RIGHT(N$1,2),'HY & Segments'!$3:$3,0))+INDEX('HY & Segments'!$A:$AG,MATCH($A43,'HY & Segments'!$A:$A,0),MATCH("2H"&RIGHT(N$1,2),'HY & Segments'!$3:$3,0)) | ... P43: =INDEX('HY & Segments'!$A:$AG,MATCH($A43,'HY & Segments'!$A:$A,0),MATCH("1H"&RIGHT(P$1,2),'HY & Segments'!$3:$3,0))+INDEX('HY & Segments'!$A:$AG,MATCH($A43,'HY & Segments'!$A:$A,0),MATCH("2H"&RIGHT(P$1,2),'HY & Segments'!$3:$3,0))
A44: DA-Amortisation Reacquired | B44: Amortisation - Reacquired Rights | C44: A$m | D44: -2.747 | E44: -2.935 | F44: -3.668 | G44: =INDEX('HY & Segments'!$A:$AG,MATCH($A44,'HY & Segments'!$A:$A,0),MATCH("1H"&RIGHT(G$1,2),'HY & Segments'!$3:$3,0))+INDEX('HY & Segments'!$A:$AG,MATCH($A44,'HY & Segments'!$A:$A,0),MATCH("2H"&RIGHT(G$1,2),'HY & Segments'!$3:$3,0)) | H44: =INDEX('HY & Segments'!$A:$AG,MATCH($A44,'HY & Segments'!$A:$A,0),MATCH("1H"&RIGHT(H$1,2),'HY & Segments'!$3:$3,0))+INDEX('HY & Segments'!$A:$AG,MATCH($A44,'HY & Segments'!$A:$A,0),MATCH("2H"&RIGHT(H$1,2),'HY & Segments'!$3:$3,0)) | I44: =INDEX('HY & Segments'!$A:$AG,MATCH($A44,'HY & Segments'!$A:$A,0),MATCH("1H"&RIGHT(I$1,2),'HY & Segments'!$3:$3,0))+INDEX('HY & Segments'!$A:$AG,MATCH($A44,'HY & Segments'!$A:$A,0),MATCH("2H"&RIGHT(I$1,2),'HY & Segments'!$3:$3,0)) | J44: =INDEX('HY & Segments'!$A:$AG,MATCH($A44,'HY & Segments'!$A:$A,0),MATCH("1H"&RIGHT(J$1,2),'HY & Segments'!$3:$3,0))+INDEX('HY & Segments'!$A:$AG,MATCH($A44,'HY & Segments'!$A:$A,0),MATCH("2H"&RIGHT(J$1,2),'HY & Segments'!$3:$3,0)) | K44: =INDEX('HY & Segments'!$A:$AG,MATCH($A44,'HY & Segments'!$A:$A,0),MATCH("1H"&RIGHT(K$1,2),'HY & Segments'!$3:$3,0))+INDEX('HY & Segments'!$A:$AG,MATCH($A44,'HY & Segments'!$A:$A,0),MATCH("2H"&RIGHT(K$1,2),'HY & Segments'!$3:$3,0)) | L44: =INDEX('HY & Segments'!$A:$AG,MATCH($A44,'HY & Segments'!$A:$A,0),MATCH("1H"&RIGHT(L$1,2),'HY & Segments'!$3:$3,0))+INDEX('HY & Segments'!$A:$AG,MATCH($A44,'HY & Segments'!$A:$A,0),MATCH("2H"&RIGHT(L$1,2),'HY & Segments'!$3:$3,0)) | M44: =INDEX('HY & Segments'!$A:$AG,MATCH($A44,'HY & Segments'!$A:$A,0),MATCH("1H"&RIGHT(M$1,2),'HY & Segments'!$3:$3,0))+INDEX('HY & Segments'!$A:$AG,MATCH($A44,'HY & Segments'!$A:$A,0),MATCH("2H"&RIGHT(M$1,2),'HY & Segments'!$3:$3,0)) | N44: =INDEX('HY & Segments'!$A:$AG,MATCH($A44,'HY & Segments'!$A:$A,0),MATCH("1H"&RIGHT(N$1,2),'HY & Segments'!$3:$3,0))+INDEX('HY & Segments'!$A:$AG,MATCH($A44,'HY & Segments'!$A:$A,0),MATCH("2H"&RIGHT(N$1,2),'HY & Segments'!$3:$3,0)) | ... P44: =INDEX('HY & Segments'!$A:$AG,MATCH($A44,'HY & Segments'!$A:$A,0),MATCH("1H"&RIGHT(P$1,2),'HY & Segments'!$3:$3,0))+INDEX('HY & Segments'!$A:$AG,MATCH($A44,'HY & Segments'!$A:$A,0),MATCH("2H"&RIGHT(P$1,2),'HY & Segments'!$3:$3,0))
A45: DA-Amortisation Other | B45: Amortisation - Other | C45: A$m | D45: -4.086 | E45: -3.981 | F45: -2.843 | G45: =INDEX('HY & Segments'!$A:$AG,MATCH($A45,'HY & Segments'!$A:$A,0),MATCH("1H"&RIGHT(G$1,2),'HY & Segments'!$3:$3,0))+INDEX('HY & Segments'!$A:$AG,MATCH($A45,'HY & Segments'!$A:$A,0),MATCH("2H"&RIGHT(G$1,2),'HY & Segments'!$3:$3,0)) | H45: =INDEX('HY & Segments'!$A:$AG,MATCH($A45,'HY & Segments'!$A:$A,0),MATCH("1H"&RIGHT(H$1,2),'HY & Segments'!$3:$3,0))+INDEX('HY & Segments'!$A:$AG,MATCH($A45,'HY & Segments'!$A:$A,0),MATCH("2H"&RIGHT(H$1,2),'HY & Segments'!$3:$3,0)) | I45: =INDEX('HY & Segments'!$A:$AG,MATCH($A45,'HY & Segments'!$A:$A,0),MATCH("1H"&RIGHT(I$1,2),'HY & Segments'!$3:$3,0))+INDEX('HY & Segments'!$A:$AG,MATCH($A45,'HY & Segments'!$A:$A,0),MATCH("2H"&RIGHT(I$1,2),'HY & Segments'!$3:$3,0)) | J45: =INDEX('HY & Segments'!$A:$AG,MATCH($A45,'HY & Segments'!$A:$A,0),MATCH("1H"&RIGHT(J$1,2),'HY & Segments'!$3:$3,0))+INDEX('HY & Segments'!$A:$AG,MATCH($A45,'HY & Segments'!$A:$A,0),MATCH("2H"&RIGHT(J$1,2),'HY & Segments'!$3:$3,0)) | K45: =INDEX('HY & Segments'!$A:$AG,MATCH($A45,'HY & Segments'!$A:$A,0),MATCH("1H"&RIGHT(K$1,2),'HY & Segments'!$3:$3,0))+INDEX('HY & Segments'!$A:$AG,MATCH($A45,'HY & Segments'!$A:$A,0),MATCH("2H"&RIGHT(K$1,2),'HY & Segments'!$3:$3,0)) | L45: =INDEX('HY & Segments'!$A:$AG,MATCH($A45,'HY & Segments'!$A:$A,0),MATCH("1H"&RIGHT(L$1,2),'HY & Segments'!$3:$3,0))+INDEX('HY & Segments'!$A:$AG,MATCH($A45,'HY & Segments'!$A:$A,0),MATCH("2H"&RIGHT(L$1,2),'HY & Segments'!$3:$3,0)) | M45: =INDEX('HY & Segments'!$A:$AG,MATCH($A45,'HY & Segments'!$A:$A,0),MATCH("1H"&RIGHT(M$1,2),'HY & Segments'!$3:$3,0))+INDEX('HY & Segments'!$A:$AG,MATCH($A45,'HY & Segments'!$A:$A,0),MATCH("2H"&RIGHT(M$1,2),'HY & Segments'!$3:$3,0)) | N45: =INDEX('HY & Segments'!$A:$AG,MATCH($A45,'HY & Segments'!$A:$A,0),MATCH("1H"&RIGHT(N$1,2),'HY & Segments'!$3:$3,0))+INDEX('HY & Segments'!$A:$AG,MATCH($A45,'HY & Segments'!$A:$A,0),MATCH("2H"&RIGHT(N$1,2),'HY & Segments'!$3:$3,0)) | ... P45: =INDEX('HY & Segments'!$A:$AG,MATCH($A45,'HY & Segments'!$A:$A,0),MATCH("1H"&RIGHT(P$1,2),'HY & Segments'!$3:$3,0))+INDEX('HY & Segments'!$A:$AG,MATCH($A45,'HY & Segments'!$A:$A,0),MATCH("2H"&RIGHT(P$1,2),'HY & Segments'!$3:$3,0))
...

Sheet HY & Segments
D1: 2023 | E1: 2023 | F1: 2024 | G1: 2024 | H1: 2025 | I1: 2025 | J1: 2026 | K1: 2026 | L1: 2027 | M1: 2027 | N1: 2028 | O1: 2028 | P1: 2029 | Q1: 2029 | R1: 2030 | S1: 2030 | T1: 2031 | U1: 2031 | V1: 2032 | W1: 2032 | X1: 2033 | Y1: 2033 | Z1: 2034 | AA1: 2034 | AB1: 2035 | AC1: 2035
B2: GYG Segments (Half-Year) | D2: Actual ----------> | K2: Forecast ----->
B3: Guzman y Gomez (GYG.AX) | C3: Units | D3: 1H23 | E3: 2H23 | F3: 1H24 | G3: 2H24 | H3: 1H25 | I3: 2H25 | J3: 1H26 | K3: 2H26 | L3: 1H27 | M3: 2H27 | N3: 1H28 | O3: 2H28 | P3: 1H29 | Q3: 2H29 | R3: 1H30 | S3: 2H30 | T3: 1H31 | U3: 2H31 | V3: 1H32 | W3: 2H32 | X3: 1H33 | Y3: 2H33 | Z3: 1H34 | AA3: 2H34 | AB3: 1H35 | AC3: 2H35
D4: 44926 | E4: 45107 | F4: 45291 | G4: 45473 | H4: 45657 | I4: 45838 | J4: 46022 | K4: 46203 | L4: 46387 | M4: 46568 | N4: 46752 | O4: 46934 | P4: 47118 | Q4: 47299 | R4: 47483 | S4: 47664 | T4: 47848 | U4: 48029 | V4: 48213 | W4: 48395 | X4: 48579 | Y4: 48760 | Z4: 48944 | AA4: 49125 | AB4: 49309 | AC4: 49490
B5: P&L
B6: Revenue
A7: Rev-Corp Restaurant Sales Aus | B7: Corp Restaurant Sales - Australia | C7: A$m | F7: 136.155 | G7: 142.722 | H7: 176.051 | I7: 183.671 | J7: 215.116 | K7: =K90 | L7: =L90 | M7: =M90 | N7: =N90 | O7: =O90 | P7: =P90 | Q7: =Q90 | R7: =R90 | ... AC7: =AC90
