Workbook

Sheet Value
B2: DCF Valuation
B4: Current Share Price (AUD) | C4: 28
B5: Shares Outstanding (#m) | C5: 101
B6: Market Cap (AUDm) | C6: =C4*C5
B7: Net Cash (AUDm) | C7: =-INDEX(Annual!D:P,MATCH("BS-Cash",Annual!A:A,0),MATCH(2025,Annual!$1:$1,0))
B8: Market EV (AUDm) | C8: =C6-C7
B9: Valuation Date | C9: 46022
B11: WACC Inputs
B12: Risk-free Rate | C12: 0.04
B13: Equity Risk Premium | C13: 0.06
B14: Beta | C14: 1.2
B15: Cost of Equity | C15: =C12+C13*C14
B16: Pre-tax Cost of Debt | C16: 0
B17: Tax Rate | C17: 0.3
B18: After-tax Cost of Debt | C18: =C16*(1-C17)
B19: Debt Weight (D/(D+E)) | C19: 0
B20: WACC | C20: =C15*(1-C19)+C18*C19
B21: Terminal Growth Rate | C21: 0.025
B22: Stub Period | C22: =(DATE(2026,6,30)-C9)/365.25
B24: FCF Projection | D24: FY26E | E24: FY27E | F24: FY28E | G24: FY29E | H24: FY30E | I24: FY31E | J24: FY32E | K24: FY33E | L24: FY34E | M24: FY35E
B25: EBITDA | C25: AUDm | D25: =INDEX(Annual!$D:$P,MATCH("Stat-Statutory EBITDA",Annual!$A:$A,0),MATCH(2026,Annual!$1:$1,0)) | E25: =INDEX(Annual!$D:$P,MATCH("Stat-Statutory EBITDA",Annual!$A:$A,0),MATCH(2027,Annual!$1:$1,0)) | F25: =INDEX(Annual!$D:$P,MATCH("Stat-Statutory EBITDA",Annual!$A:$A,0),MATCH(2028,Annual!$1:$1,0)) | G25: =INDEX(Annual!$D:$P,MATCH("Stat-Statutory EBITDA",Annual!$A:$A,0),MATCH(2029,Annual!$1:$1,0)) | H25: =INDEX(Annual!$D:$P,MATCH("Stat-Statutory EBITDA",Annual!$A:$A,0),MATCH(2030,Annual!$1:$1,0)) | I25: =INDEX(Annual!$D:$P,MATCH("Stat-Statutory EBITDA",Annual!$A:$A,0),MATCH(2031,Annual!$1:$1,0)) | J25: =INDEX(Annual!$D:$P,MATCH("Stat-Statutory EBITDA",Annual!$A:$A,0),MATCH(2032,Annual!$1:$1,0)) | K25: =INDEX(Annual!$D:$P,MATCH("Stat-Statutory EBITDA",Annual!$A:$A,0),MATCH(2033,Annual!$1:$1,0)) | L25: =INDEX(Annual!$D:$P,MATCH("Stat-Statutory EBITDA",Annual!$A:$A,0),MATCH(2034,Annual!$1:$1,0)) | M25: =INDEX(Annual!$D:$P,MATCH("Stat-Statutory EBITDA",Annual!$A:$A,0),MATCH(2035,Annual!$1:$1,0))
B26: less D&A | C26: AUDm | D26: =INDEX(Annual!$D:$P,MATCH("DA-Total DA",Annual!$A:$A,0),MATCH(2026,Annual!$1:$1,0)) | E26: =INDEX(Annual!$D:$P,MATCH("DA-Total DA",Annual!$A:$A,0),MATCH(2027,Annual!$1:$1,0)) | F26: =INDEX(Annual!$D:$P,MATCH("DA-Total DA",Annual!$A:$A,0),MATCH(2028,Annual!$1:$1,0)) | G26: =INDEX(Annual!$D:$P,MATCH("DA-Total DA",Annual!$A:$A,0),MATCH(2029,Annual!$1:$1,0)) | H26: =INDEX(Annual!$D:$P,MATCH("DA-Total DA",Annual!$A:$A,0),MATCH(2030,Annual!$1:$1,0)) | I26: =INDEX(Annual!$D:$P,MATCH("DA-Total DA",Annual!$A:$A,0),MATCH(2031,Annual!$1:$1,0)) | J26: =INDEX(Annual!$D:$P,MATCH("DA-Total DA",Annual!$A:$A,0),MATCH(2032,Annual!$1:$1,0)) | K26: =INDEX(Annual!$D:$P,MATCH("DA-Total DA",Annual!$A:$A,0),MATCH(2033,Annual!$1:$1,0)) | L26: =INDEX(Annual!$D:$P,MATCH("DA-Total DA",Annual!$A:$A,0),MATCH(2034,Annual!$1:$1,0)) | M26: =INDEX(Annual!$D:$P,MATCH("DA-Total DA",Annual!$A:$A,0),MATCH(2035,Annual!$1:$1,0))
B27: EBIT | C27: AUDm | D27: =D25+D26 | E27: =E25+E26 | F27: =F25+F26 | G27: =G25+G26 | H27: =H25+H26 | I27: =I25+I26 | J27: =J25+J26 | K27: =K25+K26 | ... M27: =M25+M26
B28: less Tax on EBIT | C28: AUDm | D28: =IF(D27>0,-D27*$C$17,0) | E28: =IF(E27>0,-E27*$C$17,0) | F28: =IF(F27>0,-F27*$C$17,0) | G28: =IF(G27>0,-G27*$C$17,0) | H28: =IF(H27>0,-H27*$C$17,0) | I28: =IF(I27>0,-I27*$C$17,0) | J28: =IF(J27>0,-J27*$C$17,0) | K28: =IF(K27>0,-K27*$C$17,0) | ... M28: =IF(M27>0,-M27*$C$17,0)
B29: NOPAT | C29: AUDm | D29: =D27+D28 | E29: =E27+E28 | F29: =F27+F28 | G29: =G27+G28 | H29: =H27+H28 | I29: =I27+I28 | J29: =J27+J28 | K29: =K27+K28 | ... M29: =M27+M28
B30: plus D&A | C30: AUDm | D30: =-D26 | E30: =-E26 | F30: =-F26 | G30: =-G26 | H30: =-H26 | I30: =-I26 | J30: =-J26 | K30: =-K26 | ... M30: =-M26
B31: less Capex | C31: AUDm | D31: =INDEX(Annual!$D:$P,MATCH("CF-Capex PPE",Annual!$A:$A,0),MATCH(2026,Annual!$1:$1,0)) | E31: =INDEX(Annual!$D:$P,MATCH("CF-Capex PPE",Annual!$A:$A,0),MATCH(2027,Annual!$1:$1,0)) | F31: =INDEX(Annual!$D:$P,MATCH("CF-Capex PPE",Annual!$A:$A,0),MATCH(2028,Annual!$1:$1,0)) | G31: =INDEX(Annual!$D:$P,MATCH("CF-Capex PPE",Annual!$A:$A,0),MATCH(2029,Annual!$1:$1,0)) | H31: =INDEX(Annual!$D:$P,MATCH("CF-Capex PPE",Annual!$A:$A,0),MATCH(2030,Annual!$1:$1,0)) | I31: =INDEX(Annual!$D:$P,MATCH("CF-Capex PPE",Annual!$A:$A,0),MATCH(2031,Annual!$1:$1,0)) | J31: =INDEX(Annual!$D:$P,MATCH("CF-Capex PPE",Annual!$A:$A,0),MATCH(2032,Annual!$1:$1,0)) | K31: =INDEX(Annual!$D:$P,MATCH("CF-Capex PPE",Annual!$A:$A,0),MATCH(2033,Annual!$1:$1,0)) | L31: =INDEX(Annual!$D:$P,MATCH("CF-Capex PPE",Annual!$A:$A,0),MATCH(2034,Annual!$1:$1,0)) | M31: =INDEX(Annual!$D:$P,MATCH("CF-Capex PPE",Annual!$A:$A,0),MATCH(2035,Annual!$1:$1,0))
B32: less WC Change | C32: AUDm | D32: =INDEX(Annual!$D:$P,MATCH("CF-WC Change",Annual!$A:$A,0),MATCH(2026,Annual!$1:$1,0)) | E32: =INDEX(Annual!$D:$P,MATCH("CF-WC Change",Annual!$A:$A,0),MATCH(2027,Annual!$1:$1,0)) | F32: =INDEX(Annual!$D:$P,MATCH("CF-WC Change",Annual!$A:$A,0),MATCH(2028,Annual!$1:$1,0)) | G32: =INDEX(Annual!$D:$P,MATCH("CF-WC Change",Annual!$A:$A,0),MATCH(2029,Annual!$1:$1,0)) | H32: =INDEX(Annual!$D:$P,MATCH("CF-WC Change",Annual!$A:$A,0),MATCH(2030,Annual!$1:$1,0)) | I32: =INDEX(Annual!$D:$P,MATCH("CF-WC Change",Annual!$A:$A,0),MATCH(2031,Annual!$1:$1,0)) | J32: =INDEX(Annual!$D:$P,MATCH("CF-WC Change",Annual!$A:$A,0),MATCH(2032,Annual!$1:$1,0)) | K32: =INDEX(Annual!$D:$P,MATCH("CF-WC Change",Annual!$A:$A,0),MATCH(2033,Annual!$1:$1,0)) | L32: =INDEX(Annual!$D:$P,MATCH("CF-WC Change",Annual!$A:$A,0),MATCH(2034,Annual!$1:$1,0)) | M32: =INDEX(Annual!$D:$P,MATCH("CF-WC Change",Annual!$A:$A,0),MATCH(2035,Annual!$1:$1,0))
B33: FCFF | C33: AUDm | D33: =D29+D30+D31+D32 | E33: =E29+E30+E31+E32 | F33: =F29+F30+F31+F32 | G33: =G29+G30+G31+G32 | H33: =H29+H30+H31+H32 | I33: =I29+I30+I31+I32 | J33: =J29+J30+J31+J32 | K33: =K29+K30+K31+K32 | ... M33: =M29+M30+M31+M32
B34: Normalised FCFF (capex=D&A) | C34: AUDm | M34: =M29
B35: Terminal Value | M35: =M34*(1+$C$21)/($C$20-$C$21)
B37: Discount Factor | D37: =1/(1+$C$20)^($C$22+0) | E37: =1/(1+$C$20)^($C$22+1) | F37: =1/(1+$C$20)^($C$22+2) | G37: =1/(1+$C$20)^($C$22+3) | H37: =1/(1+$C$20)^($C$22+4) | I37: =1/(1+$C$20)^($C$22+5) | J37: =1/(1+$C$20)^($C$22+6) | K37: =1/(1+$C$20)^($C$22+7) | L37: =1/(1+$C$20)^($C$22+8) | M37: =1/(1+$C$20)^($C$22+9)
B38: PV of FCFF | D38: =D33*D37 | E38: =E33*E37 | F38: =F33*F37 | G38: =G33*G37 | H38: =H33*H37 | I38: =I33*I37 | J38: =J33*J37 | K38: =K33*K37 | ... M38: =M33*M37
B39: PV of Terminal Value | M39: =M35*M37
B41: Sum of PV of FCFs | C41: =SUM(D38:M38)
B42: PV of Terminal Value | C42: =M39
B43: Enterprise Value | C43: =C41+C42
B45: less Net Debt | C45: =C7
B46: less Lease Liabilities | C46: =-INDEX(Annual!D:P,MATCH("BS-Lease Liabilities",Annual!A:A,0),MATCH(2025,Annual!$1:$1,0))
B47: Equity Value | C47: =C43+C45+C46
...

Sheet Annual
D1: 2023 | E1: 2024 | F1: 2025 | G1: 2026 | H1: 2027 | I1: 2028 | J1: 2029 | K1: 2030 | L1: 2031 | M1: 2032 | N1: 2033 | O1: 2034 | P1: 2035
B2: GYG Model Summary | D2: Actual ----------> | G2: Forecast ----->
B3: Guzman y Gomez (GYG.AX) | C3: Units | D3: FY23A | E3: FY24A | F3: FY25A | G3: FY26E | H3: FY27E | I3: FY28E | J3: FY29E | K3: FY30E | L3: FY31E | M3: FY32E | N3: FY33E | O3: FY34E | P3: FY35E
D4: 45107 | E4: 45473 | F4: 45838 | G4: 46203 | H4: 46568 | I4: 46934 | J4: 47299 | K4: 47664 | L4: 48029 | M4: 48395 | N4: 48760 | O4: 49125 | P4: 49490
B5: P&L
B6: Revenue
A7: Rev-Total Revenue | B7: Total Revenue | C7: AUDm | D7: 259.044 | E7: 342.214 | F7: 435.982 | G7: =INDEX('HY & Segments'!$A:$AG,MATCH($A7,'HY & Segments'!$A:$A,0),MATCH("1H"&RIGHT(G$1,2),'HY & Segments'!$3:$3,0))+INDEX('HY & Segments'!$A:$AG,MATCH($A7,'HY & Segments'!$A:$A,0),MATCH("2H"&RIGHT(G$1,2),'HY & Segments'!$3:$3,0)) | H7: =INDEX('HY & Segments'!$A:$AG,MATCH($A7,'HY & Segments'!$A:$A,0),MATCH("1H"&RIGHT(H$1,2),'HY & Segments'!$3:$3,0))+INDEX('HY & Segments'!$A:$AG,MATCH($A7,'HY & Segments'!$A:$A,0),MATCH("2H"&RIGHT(H$1,2),'HY & Segments'!$3:$3,0)) | I7: =INDEX('HY & Segments'!$A:$AG,MATCH($A7,'HY & Segments'!$A:$A,0),MATCH("1H"&RIGHT(I$1,2),'HY & Segments'!$3:$3,0))+INDEX('HY & Segments'!$A:$AG,MATCH($A7,'HY & Segments'!$A:$A,0),MATCH("2H"&RIGHT(I$1,2),'HY & Segments'!$3:$3,0)) | J7: =INDEX('HY & Segments'!$A:$AG,MATCH($A7,'HY & Segments'!$A:$A,0),MATCH("1H"&RIGHT(J$1,2),'HY & Segments'!$3:$3,0))+INDEX('HY & Segments'!$A:$AG,MATCH($A7,'HY & Segments'!$A:$A,0),MATCH("2H"&RIGHT(J$1,2),'HY & Segments'!$3:$3,0)) | K7: =INDEX('HY & Segments'!$A:$AG,MATCH($A7,'HY & Segments'!$A:$A,0),MATCH("1H"&RIGHT(K$1,2),'HY & Segments'!$3:$3,0))+INDEX('HY & Segments'!$A:$AG,MATCH($A7,'HY & Segments'!$A:$A,0),MATCH("2H"&RIGHT(K$1,2),'HY & Segments'!$3:$3,0)) | L7: =INDEX('HY & Segments'!$A:$AG,MATCH($A7,'HY & Segments'!$A:$A,0),MATCH("1H"&RIGHT(L$1,2),'HY & Segments'!$3:$3,0))+INDEX('HY & Segments'!$A:$AG,MATCH($A7,'HY & Segments'!$A:$A,0),MATCH("2H"&RIGHT(L$1,2),'HY & Segments'!$3:$3,0)) | M7: =INDEX('HY & Segments'!$A:$AG,MATCH($A7,'HY & Segments'!$A:$A,0),MATCH("1H"&RIGHT(M$1,2),'HY & Segments'!$3:$3,0))+INDEX('HY & Segments'!$A:$AG,MATCH($A7,'HY & Segments'!$A:$A,0),MATCH("2H"&RIGHT(M$1,2),'HY & Segments'!$3:$3,0)) | N7: =INDEX('HY & Segments'!$A:$AG,MATCH($A7,'HY & Segments'!$A:$A,0),MATCH("1H"&RIGHT(N$1,2),'HY & Segments'!$3:$3,0))+INDEX('HY & Segments'!$A:$AG,MATCH($A7,'HY & Segments'!$A:$A,0),MATCH("2H"&RIGHT(N$1,2),'HY & Segments'!$3:$3,0)) | ... P7: =INDEX('HY & Segments'!$A:$AG,MATCH($A7,'HY & Segments'!$A:$A,0),MATCH("1H"&RIGHT(P$1,2),'HY & Segments'!$3:$3,0))+INDEX('HY & Segments'!$A:$AG,MATCH($A7,'HY & Segments'!$A:$A,0),MATCH("2H"&RIGHT(P$1,2),'HY & Segments'!$3:$3,0))
A8: Rev-Other Revenue | B8: Other Revenue & Income | C8: AUDm | D8: 17.725 | E8: 22.774 | F8: 32.024 | G8: =F8*1.15 | H8: =G8*1.15 | I8: =H8*1.15 | J8: =I8*1.15 | K8: =J8*1.15 | L8: =K8*1.15 | M8: =L8*1.15 | N8: =M8*1.15 | ... P8: =O8*1.15
A9: Rev-Total Rev Incl Other | B9: Total Revenue (incl Other) | C9: AUDm | D9: =D7+D8 | E9: =E7+E8 | F9: =F7+F8 | G9: =G7+G8 | H9: =H7+H8 | I9: =I7+I8 | J9: =J7+J8 | K9: =K7+K8 | ... P9: =P7+P8
B10: Revenue Growth | C10: % YoY | E10: =E7/D7-1 | F10: =F7/E7-1 | G10: =IF(F7=0,"",G7/F7-1) | H10: =IF(G7=0,"",H7/G7-1) | I10: =IF(H7=0,"",I7/H7-1) | J10: =IF(I7=0,"",J7/I7-1) | K10: =IF(J7=0,"",K7/J7-1) | L10: =IF(K7=0,"",L7/K7-1) | M10: =IF(L7=0,"",M7/L7-1) | N10: =IF(M7=0,"",N7/M7-1) | ... P10: =IF(O7=0,"",P7/O7-1)
B12: COGS
A13: COGS-Food & Packaging | B13: Cost of Food & Packaging | C13: AUDm | D13: -70.428 | E13: -87.58 | F13: -113.948 | G13: =G7*-0.261 | H13: =H7*-0.261 | I13: =I7*-0.261 | J13: =J7*-0.261 | K13: =K7*-0.261 | L13: =L7*-0.261 | M13: =M7*-0.261 | N13: =N7*-0.261 | ... P13: =P7*-0.261
A14: COGS-Employee Benefits | B14: Employee Benefits | C14: AUDm | D14: -113.725 | E14: -153.733 | F14: -184.656 | G14: =G7*-0.424 | H14: =H7*-0.424 | I14: =I7*-0.424 | J14: =J7*-0.424 | K14: =K7*-0.424 | L14: =L7*-0.424 | M14: =M7*-0.424 | N14: =N7*-0.424 | ... P14: =P7*-0.424
A15: COGS-Other Costs | B15: Admin, Marketing & Other Expenses | C15: AUDm | D15: -62.995 | E15: -96.401 | F15: -104.283 | G15: =G7*-0.235 | H15: =H7*-0.230 | I15: =I7*-0.225 | J15: =J7*-0.225 | K15: =K7*-0.225 | L15: =L7*-0.225 | M15: =M7*-0.225 | N15: =N7*-0.225 | O15: =O7*-0.225 | P15: =P7*-0.225
A16: COGS-Total Costs | B16: Total Operating Costs (excl D&A) | C16: AUDm | D16: =D13+D14+D15 | E16: =E13+E14+E15 | F16: =F13+F14+F15 | G16: =G13+G14+G15 | H16: =H13+H14+H15 | I16: =I13+I14+I15 | J16: =J13+J14+J15 | K16: =K13+K14+K15 | ... P16: =P13+P14+P15
B18: Statutory EBITDA
A19: GP-Statutory EBITDA | B19: Statutory EBITDA | C19: AUDm | D19: =D9+D16 | E19: =E9+E16 | F19: =F9+F16 | G19: =G9+G16 | H19: =H9+H16 | I19: =I9+I16 | J19: =J9+J16 | K19: =K9+K16 | ... P19: =P9+P16
B20: Statutory EBITDA Margin | C20: % | D20: =IF(D7=0,"",D19/D7) | E20: =IF(E7=0,"",E19/E7) | F20: =IF(F7=0,"",F19/F7) | G20: =IF(G7=0,"",G19/G7) | H20: =IF(H7=0,"",H19/H7) | I20: =IF(I7=0,"",I19/I7) | J20: =IF(J7=0,"",J19/J7) | K20: =IF(K7=0,"",K19/K7) | ... P20: =IF(P7=0,"",P19/P7)
B26: Segment EBITDA
B34: EBITDA
A35: EBITDA-Australia EBITDA | B35: Australia Segment Underlying EBITDA | C35: AUDm | D35: 30.7 | E35: 45.6 | F35: 66 | G35: =INDEX('HY & Segments'!$A:$AG,MATCH($A35,'HY & Segments'!$A:$A,0),MATCH("1H"&RIGHT(G$1,2),'HY & Segments'!$3:$3,0))+INDEX('HY & Segments'!$A:$AG,MATCH($A35,'HY & Segments'!$A:$A,0),MATCH("2H"&RIGHT(G$1,2),'HY & Segments'!$3:$3,0)) | H35: =INDEX('HY & Segments'!$A:$AG,MATCH($A35,'HY & Segments'!$A:$A,0),MATCH("1H"&RIGHT(H$1,2),'HY & Segments'!$3:$3,0))+INDEX('HY & Segments'!$A:$AG,MATCH($A35,'HY & Segments'!$A:$A,0),MATCH("2H"&RIGHT(H$1,2),'HY & Segments'!$3:$3,0)) | I35: =INDEX('HY & Segments'!$A:$AG,MATCH($A35,'HY & Segments'!$A:$A,0),MATCH("1H"&RIGHT(I$1,2),'HY & Segments'!$3:$3,0))+INDEX('HY & Segments'!$A:$AG,MATCH($A35,'HY & Segments'!$A:$A,0),MATCH("2H"&RIGHT(I$1,2),'HY & Segments'!$3:$3,0)) | J35: =INDEX('HY & Segments'!$A:$AG,MATCH($A35,'HY & Segments'!$A:$A,0),MATCH("1H"&RIGHT(J$1,2),'HY & Segments'!$3:$3,0))+INDEX('HY & Segments'!$A:$AG,MATCH($A35,'HY & Segments'!$A:$A,0),MATCH("2H"&RIGHT(J$1,2),'HY & Segments'!$3:$3,0)) | K35: =INDEX('HY & Segments'!$A:$AG,MATCH($A35,'HY & Segments'!$A:$A,0),MATCH("1H"&RIGHT(K$1,2),'HY & Segments'!$3:$3,0))+INDEX('HY & Segments'!$A:$AG,MATCH($A35,'HY & Segments'!$A:$A,0),MATCH("2H"&RIGHT(K$1,2),'HY & Segments'!$3:$3,0)) | L35: =INDEX('HY & Segments'!$A:$AG,MATCH($A35,'HY & Segments'!$A:$A,0),MATCH("1H"&RIGHT(L$1,2),'HY & Segments'!$3:$3,0))+INDEX('HY & Segments'!$A:$AG,MATCH($A35,'HY & Segments'!$A:$A,0),MATCH("2H"&RIGHT(L$1,2),'HY & Segments'!$3:$3,0)) | M35: =INDEX('HY & Segments'!$A:$AG,MATCH($A35,'HY & Segments'!$A:$A,0),MATCH("1H"&RIGHT(M$1,2),'HY & Segments'!$3:$3,0))+INDEX('HY & Segments'!$A:$AG,MATCH($A35,'HY & Segments'!$A:$A,0),MATCH("2H"&RIGHT(M$1,2),'HY & Segments'!$3:$3,0)) | N35: =INDEX('HY & Segments'!$A:$AG,MATCH($A35,'HY & Segments'!$A:$A,0),MATCH("1H"&RIGHT(N$1,2),'HY & Segments'!$3:$3,0))+INDEX('HY & Segments'!$A:$AG,MATCH($A35,'HY & Segments'!$A:$A,0),MATCH("2H"&RIGHT(N$1,2),'HY & Segments'!$3:$3,0)) | ... P35: =INDEX('HY & Segments'!$A:$AG,MATCH($A35,'HY & Segments'!$A:$A,0),MATCH("1H"&RIGHT(P$1,2),'HY & Segments'!$3:$3,0))+INDEX('HY & Segments'!$A:$AG,MATCH($A35,'HY & Segments'!$A:$A,0),MATCH("2H"&RIGHT(P$1,2),'HY & Segments'!$3:$3,0))
A36: EBITDA-US EBITDA | B36: US Segment Underlying EBITDA | C36: AUDm | D36: -4.3 | E36: -6.5 | F36: -13.2 | G36: =INDEX('HY & Segments'!$A:$AG,MATCH($A36,'HY & Segments'!$A:$A,0),MATCH("1H"&RIGHT(G$1,2),'HY & Segments'!$3:$3,0))+INDEX('HY & Segments'!$A:$AG,MATCH($A36,'HY & Segments'!$A:$A,0),MATCH("2H"&RIGHT(G$1,2),'HY & Segments'!$3:$3,0)) | H36: =INDEX('HY & Segments'!$A:$AG,MATCH($A36,'HY & Segments'!$A:$A,0),MATCH("1H"&RIGHT(H$1,2),'HY & Segments'!$3:$3,0))+INDEX('HY & Segments'!$A:$AG,MATCH($A36,'HY & Segments'!$A:$A,0),MATCH("2H"&RIGHT(H$1,2),'HY & Segments'!$3:$3,0)) | I36: =INDEX('HY & Segments'!$A:$AG,MATCH($A36,'HY & Segments'!$A:$A,0),MATCH("1H"&RIGHT(I$1,2),'HY & Segments'!$3:$3,0))+INDEX('HY & Segments'!$A:$AG,MATCH($A36,'HY & Segments'!$A:$A,0),MATCH("2H"&RIGHT(I$1,2),'HY & Segments'!$3:$3,0)) | J36: =INDEX('HY & Segments'!$A:$AG,MATCH($A36,'HY & Segments'!$A:$A,0),MATCH("1H"&RIGHT(J$1,2),'HY & Segments'!$3:$3,0))+INDEX('HY & Segments'!$A:$AG,MATCH($A36,'HY & Segments'!$A:$A,0),MATCH("2H"&RIGHT(J$1,2),'HY & Segments'!$3:$3,0)) | K36: =INDEX('HY & Segments'!$A:$AG,MATCH($A36,'HY & Segments'!$A:$A,0),MATCH("1H"&RIGHT(K$1,2),'HY & Segments'!$3:$3,0))+INDEX('HY & Segments'!$A:$AG,MATCH($A36,'HY & Segments'!$A:$A,0),MATCH("2H"&RIGHT(K$1,2),'HY & Segments'!$3:$3,0)) | L36: =INDEX('HY & Segments'!$A:$AG,MATCH($A36,'HY & Segments'!$A:$A,0),MATCH("1H"&RIGHT(L$1,2),'HY & Segments'!$3:$3,0))+INDEX('HY & Segments'!$A:$AG,MATCH($A36,'HY & Segments'!$A:$A,0),MATCH("2H"&RIGHT(L$1,2),'HY & Segments'!$3:$3,0)) | M36: =INDEX('HY & Segments'!$A:$AG,MATCH($A36,'HY & Segments'!$A:$A,0),MATCH("1H"&RIGHT(M$1,2),'HY & Segments'!$3:$3,0))+INDEX('HY & Segments'!$A:$AG,MATCH($A36,'HY & Segments'!$A:$A,0),MATCH("2H"&RIGHT(M$1,2),'HY & Segments'!$3:$3,0)) | N36: =INDEX('HY & Segments'!$A:$AG,MATCH($A36,'HY & Segments'!$A:$A,0),MATCH("1H"&RIGHT(N$1,2),'HY & Segments'!$3:$3,0))+INDEX('HY & Segments'!$A:$AG,MATCH($A36,'HY & Segments'!$A:$A,0),MATCH("2H"&RIGHT(N$1,2),'HY & Segments'!$3:$3,0)) | ... P36: =INDEX('HY & Segments'!$A:$AG,MATCH($A36,'HY & Segments'!$A:$A,0),MATCH("1H"&RIGHT(P$1,2),'HY & Segments'!$3:$3,0))+INDEX('HY & Segments'!$A:$AG,MATCH($A36,'HY & Segments'!$A:$A,0),MATCH("2H"&RIGHT(P$1,2),'HY & Segments'!$3:$3,0))
A37: EBITDA-Corporate EBITDA | B37: Corporate / Eliminations | C37: AUDm | D37: 0 | E37: 0 | F37: 0 | G37: 0 | H37: 0 | I37: 0 | J37: 0 | K37: 0 | L37: 0 | M37: 0 | N37: 0 | O37: 0 | P37: 0
A38: EBITDA-Underlying EBITDA | B38: Group Segment Underlying EBITDA | C38: AUDm | D38: =SUM(D35:D37) | E38: =SUM(E35:E37) | F38: =SUM(F35:F37) | G38: =SUM(G35:G37) | H38: =SUM(H35:H37) | I38: =SUM(I35:I37) | J38: =SUM(J35:J37) | K38: =SUM(K35:K37) | ... P38: =SUM(P35:P37)
B39: Seg EBITDA Growth | C39: % YoY | E39: =E38/D38-1 | F39: =F38/E38-1 | G39: =IF(F38=0,"",G38/F38-1) | H39: =IF(G38=0,"",H38/G38-1) | I39: =IF(H38=0,"",I38/H38-1) | J39: =IF(I38=0,"",J38/I38-1) | K39: =IF(J38=0,"",K38/J38-1) | L39: =IF(K38=0,"",L38/K38-1) | M39: =IF(L38=0,"",M38/L38-1) | N39: =IF(M38=0,"",N38/M38-1) | ... P39: =IF(O38=0,"",P38/O38-1)
B40: Seg EBITDA Margin (% NS) | C40: % | D40: =IF(D7=0,"",D38/D7) | E40: =IF(E7=0,"",E38/E7) | F40: =IF(F7=0,"",F38/F7) | G40: =IF(G7=0,"",G38/G7) | H40: =IF(H7=0,"",H38/H7) | I40: =IF(I7=0,"",I38/I7) | J40: =IF(J7=0,"",J38/J7) | K40: =IF(K7=0,"",K38/K7) | ... P40: =IF(P7=0,"",P38/P7)
A42: Stat-AASB16 | B42: AASB 16 Lease Impact | C42: AUDm | D42: 3.2 | E42: 12 | F42: 18.5 | G42: =F42*1.12 | H42: =G42*1.12 | I42: =H42*1.12 | J42: =I42*1.12 | K42: =J42*1.12 | L42: =K42*1.12 | M42: =L42*1.12 | N42: =M42*1.12 | ... P42: =O42*1.12
A43: Stat-SBP | B43: Share-Based Payments | C43: AUDm | D43: 0 | E43: -5.5 | F43: -9 | G43: =F43 | H43: =G43 | I43: =H43 | J43: =I43 | K43: =J43 | L43: =K43 | M43: =L43 | N43: =M43 | ... P43: =O43
A44: Stat-Other Adj | B44: Other Adjustments | C44: AUDm | D44: 0 | E44: -18.3 | F44: 2.9 | G44: =F44 | H44: =G44 | I44: =H44 | J44: =I44 | K44: =J44 | L44: =K44 | M44: =L44 | N44: =M44 | ... P44: =O44
A45: Stat-Statutory EBITDA | B45: Statutory EBITDA | C45: AUDm | D45: =D38+D42+D43+D44 | E45: =E38+E42+E43+E44 | F45: =F38+F42+F43+F44 | G45: =G38+G42+G43+G44 | H45: =H38+H42+H43+H44 | I45: =I38+I42+I43+I44 | J45: =J38+J42+J43+J44 | K45: =K38+K42+K43+K44 | ... P45: =P38+P42+P43+P44
B47: D&A
A48: DA-Total DA | B48: Depreciation & Amortisation | C48: AUDm | D48: -25.555 | E48: -31.123 | F48: -39.681 | G48: =F48*1.14 | H48: =G48*1.14 | I48: =H48*1.14 | J48: =I48*1.08 | K48: =J48*1.08 | L48: =K48*1.08 | M48: =L48*1.08 | N48: =M48*1.08 | O48: =N48*1.08 | P48: =O48*1.08
B51: D&A / Revenue | C51: % | D51: =IF(D7=0,"",D48/D7) | E51: =IF(E7=0,"",E48/E7) | F51: =IF(F7=0,"",F48/F7) | G51: =IF(G7=0,"",G48/G7) | H51: =IF(H7=0,"",H48/H7) | I51: =IF(I7=0,"",I48/I7) | J51: =IF(J7=0,"",J48/J7) | K51: =IF(K7=0,"",K48/K7) | ... P51: =IF(P7=0,"",P48/P7)
B53: EBIT
A54: EBIT-EBIT | B54: EBIT (Operating Profit) | C54: AUDm | D54: =D45+D48 | E54: =E45+E48 | F54: =F45+F48 | G54: =G45+G48 | H54: =H45+H48 | I54: =I45+I48 | J54: =J45+J48 | K54: =K45+K48 | ... P54: =P45+P48
B55: EBIT Growth | C55: % YoY | E55: =IF(D54=0,"",E54/D54-1) | F55: =IF(E54=0,"",F54/E54-1) | G55: =IF(F54=0,"",G54/F54-1) | H55: =IF(G54=0,"",H54/G54-1) | I55: =IF(H54=0,"",I54/H54-1) | J55: =IF(I54=0,"",J54/I54-1) | K55: =IF(J54=0,"",K54/J54-1) | L55: =IF(K54=0,"",L54/K54-1) | ... P55: =IF(O54=0,"",P54/O54-1)
B56: EBIT Margin | C56: % | D56: =IF(D7=0,"",D54/D7) | E56: =IF(E7=0,"",E54/E7) | F56: =IF(F7=0,"",F54/F7) | G56: =IF(G7=0,"",G54/G7) | H56: =IF(H7=0,"",H54/H7) | I56: =IF(I7=0,"",I54/I7) | J56: =IF(J7=0,"",J54/J7) | K56: =IF(K7=0,"",K54/K7) | ... P56: =IF(P7=0,"",P54/P7)
B58: Interest
A59: Int-Finance Income | B59: Finance Income | C59: AUDm | D59: 4.593 | E59: 6.012 | F59: 22.674 | G59: =F59*1.0 | H59: =G59*1.0 | I59: =H59*1.0 | J59: =I59*1.0 | K59: =J59*1.0 | L59: =K59*1.0 | M59: =L59*1.0 | N59: =M59*1.0 | ... P59: =O59*1.0
A60: Int-Finance Costs | B60: Finance Costs | C60: AUDm | D60: -8.503 | E60: -13.724 | F60: -18.902 | G60: =F60*1.10 | H60: =G60*1.10 | I60: =H60*1.10 | J60: =I60*1.10 | K60: =J60*1.10 | L60: =K60*1.10 | M60: =L60*1.10 | N60: =M60*1.10 | ... P60: =O60*1.10
...

Sheet HY & Segments
D1: 2023 | E1: 2023 | F1: 2024 | G1: 2024 | H1: 2025 | I1: 2025 | J1: 2026 | K1: 2026 | L1: 2027 | M1: 2027 | N1: 2028 | O1: 2028 | P1: 2029 | Q1: 2029 | R1: 2030 | S1: 2030 | T1: 2031 | U1: 2031 | V1: 2032 | W1: 2032 | X1: 2033 | Y1: 2033 | Z1: 2034 | AA1: 2034 | AB1: 2035 | AC1: 2035
B2: GYG Segments (Half-Year) | D2: Actual ----------> | K2: Forecast ----->
B3: Guzman y Gomez (GYG.AX) | C3: Units | D3: 1H23 | E3: 2H23 | F3: 1H24 | G3: 2H24 | H3: 1H25 | I3: 2H25 | J3: 1H26 | K3: 2H26 | L3: 1H27 | M3: 2H27 | N3: 1H28 | O3: 2H28 | P3: 1H29 | Q3: 2H29 | R3: 1H30 | S3: 2H30 | T3: 1H31 | U3: 2H31 | V3: 1H32 | W3: 2H32 | X3: 1H33 | Y3: 2H33 | Z3: 1H34 | AA3: 2H34 | AB3: 1H35 | AC3: 2H35
D4: 44926 | E4: 45107 | F4: 45291 | G4: 45473 | H4: 45657 | I4: 45838 | J4: 46022 | K4: 46203 | L4: 46387 | M4: 46568 | N4: 46752 | O4: 46934 | P4: 47118 | Q4: 47299 | R4: 47483 | S4: 47664 | T4: 47848 | U4: 48029 | V4: 48213 | W4: 48395 | X4: 48579 | Y4: 48760 | Z4: 48944 | AA4: 49125 | AB4: 49309 | AC4: 49490
B5: P&L
B6: Revenue
A7: Rev-Total Revenue | B7: Total Revenue | C7: AUDm | D7: 124 | E7: 135.044 | F7: 167.287 | G7: 174.927 | H7: 212.419 | I7: 223.563 | J7: 261.201 | K7: =K104+K109+K118+K121 | L7: =L104+L109+L118+L121 | M7: =M104+M109+M118+M121 | N7: =N104+N109+N118+N121 | O7: =O104+O109+O118+O121 | P7: =P104+P109+P118+P121 | Q7: =Q104+Q109+Q118+Q121 | R7: =R104+R109+R118+R121 | ... AC7: =AC104+AC109+AC118+AC121
A8: Rev-Other Revenue | B8: Other Revenue & Income | C8: AUDm | D8: 8.5 | E8: 9.225 | F8: 11.568 | G8: 11.206 | H8: 14.711 | I8: 17.313 | J8: 17.363 | K8: =I8*1.075 | L8: =J8*1.075 | M8: =K8*1.075 | N8: =L8*1.075 | O8: =M8*1.075 | P8: =N8*1.075 | Q8: =O8*1.075 | R8: =P8*1.075 | ... AC8: =AA8*1.075
A9: Rev-Total Rev Incl Other | B9: Total Revenue (incl Other) | C9: AUDm | D9: =D7+D8 | E9: =E7+E8 | F9: =F7+F8 | G9: =G7+G8 | H9: =H7+H8 | I9: =I7+I8 | J9: =J7+J8 | K9: =K7+K8 | ... AC9: =AC7+AC8
B10: Revenue Growth (YoY) | C10: % YoY | F10: =IF(D7=0,"",F7/D7-1) | G10: =IF(E7=0,"",G7/E7-1) | H10: =IF(F7=0,"",H7/F7-1) | I10: =IF(G7=0,"",I7/G7-1) | J10: =IF(H7=0,"",J7/H7-1) | K10: =IF(I7=0,"",K7/I7-1) | L10: =IF(J7=0,"",L7/J7-1) | M10: =IF(K7=0,"",M7/K7-1) | ... AC10: =IF(AA7=0,"",AC7/AA7-1)
B12: COGS
A13: COGS-Food & Packaging | B13: Cost of Food & Packaging | C13: AUDm | D13: -33.7 | E13: -36.728 | F13: -43.192 | G13: -44.388 | H13: -55.071 | I13: -58.877 | J13: -67.126 | K13: =K7*-0.261 | L13: =L7*-0.261 | M13: =M7*-0.261 | N13: =N7*-0.261 | O13: =O7*-0.261 | P13: =P7*-0.261 | Q13: =Q7*-0.261 | R13: =R7*-0.261 | ... AC13: =AC7*-0.261
A14: COGS-Employee Benefits | B14: Employee Benefits | C14: AUDm | D14: -54.5 | E14: -59.225 | F14: -73.326 | G14: -80.407 | H14: -89.003 | I14: -95.653 | J14: -110.669 | K14: =K7*-0.424 | L14: =L7*-0.424 | M14: =M7*-0.424 | N14: =N7*-0.424 | O14: =O7*-0.424 | P14: =P7*-0.424 | Q14: =Q7*-0.424 | R14: =R7*-0.424 | ... AC14: =AC7*-0.424
A15: COGS-Other Costs | B15: Admin, Marketing & Other | C15: AUDm | D15: -30.2 | E15: -32.795 | F15: -43.433 | G15: -52.968 | H15: -51.478 | I15: -52.805 | J15: -59.831 | K15: =K7*-0.230 | L15: =L7*-0.230 | M15: =M7*-0.230 | N15: =N7*-0.230 | O15: =O7*-0.230 | P15: =P7*-0.230 | Q15: =Q7*-0.230 | R15: =R7*-0.230 | ... AC15: =AC7*-0.230
A16: COGS-Total Costs | B16: Total Operating Costs | C16: AUDm | D16: =D13+D14+D15 | E16: =E13+E14+E15 | F16: =F13+F14+F15 | G16: =G13+G14+G15 | H16: =H13+H14+H15 | I16: =I13+I14+I15 | J16: =J13+J14+J15 | K16: =K13+K14+K15 | ... AC16: =AC13+AC14+AC15
B18: Statutory EBITDA
A19: GP-Statutory EBITDA | B19: Statutory EBITDA | C19: AUDm | D19: =D9+D16 | E19: =E9+E16 | F19: =F9+F16 | G19: =G9+G16 | H19: =H9+H16 | I19: =I9+I16 | J19: =J9+J16 | K19: =K9+K16 | ... AC19: =AC9+AC16
B28: Segment EBITDA
B37: Segment EBITDA
A38: EBITDA-Australia EBITDA | B38: Australia Segment EBITDA | C38: AUDm | D38: 15 | E38: 15.7 | F38: 23.1 | G38: 22.5 | H38: 31.8 | I38: 34.2 | J38: 41.3 | K38: =K112 | L38: =L112 | M38: =M112 | N38: =N112 | O38: =O112 | P38: =P112 | Q38: =Q112 | R38: =R112 | ... AC38: =AC112
A39: EBITDA-US EBITDA | B39: US Segment EBITDA | C39: AUDm | D39: -2 | E39: -2.3 | F39: -3.1 | G39: -3.4 | H39: -5 | I39: -8.2 | J39: -8.3 | K39: =K123 | L39: =L123 | M39: =M123 | N39: =N123 | O39: =O123 | P39: =P123 | Q39: =Q123 | R39: =R123 | ... AC39: =AC123
A40: EBITDA-Corporate EBITDA | B40: Corporate / Eliminations | C40: AUDm | D40: 0 | E40: 0 | F40: 0 | G40: 0 | H40: 0 | I40: 0 | J40: 0 | K40: 0 | L40: 0 | M40: 0 | N40: 0 | O40: 0 | P40: 0 | Q40: 0 | R40: 0 | S40: 0 | T40: 0 | U40: 0 | V40: 0 | W40: 0 | X40: 0 | Y40: 0 | Z40: 0 | AA40: 0 | AB40: 0 | AC40: 0
A42: EBITDA-Underlying EBITDA | B42: Group Segment Underlying EBITDA | C42: AUDm | D42: =SUM(D38:D40) | E42: =SUM(E38:E40) | F42: =SUM(F38:F40) | G42: =SUM(G38:G40) | H42: =SUM(H38:H40) | I42: =SUM(I38:I40) | J42: =SUM(J38:J40) | K42: =SUM(K38:K40) | ... AC42: =SUM(AC38:AC40)
B43: Seg EBITDA Growth (YoY) | C43: % YoY | F43: =IF(D42=0,"",F42/D42-1) | G43: =IF(E42=0,"",G42/E42-1) | H43: =IF(F42=0,"",H42/F42-1) | I43: =IF(G42=0,"",I42/G42-1) | J43: =IF(H42=0,"",J42/H42-1) | K43: =IF(I42=0,"",K42/I42-1) | L43: =IF(J42=0,"",L42/J42-1) | M43: =IF(K42=0,"",M42/K42-1) | ... AC43: =IF(AA42=0,"",AC42/AA42-1)
B44: Seg EBITDA Margin | C44: % | D44: =IF(D7=0,"",D42/D7) | E44: =IF(E7=0,"",E42/E7) | F44: =IF(F7=0,"",F42/F7) | G44: =IF(G7=0,"",G42/G7) | H44: =IF(H7=0,"",H42/H7) | I44: =IF(I7=0,"",I42/I7) | J44: =IF(J7=0,"",J42/J7) | K44: =IF(K7=0,"",K42/K7) | ... AC44: =IF(AC7=0,"",AC42/AC7)
A48: Stat-AASB16 | B48: AASB 16 / SBP / Other Adjustments | C48: AUDm | D48: 1.5 | E48: 1.7 | F48: 2.5 | G48: -9 | H48: 4.8 | I48: 7.5 | J48: 7.9 | K48: =I48*1.05 | L48: =J48*1.05 | M48: =K48*1.05 | N48: =L48*1.05 | O48: =M48*1.05 | P48: =N48*1.05 | Q48: =O48*1.05 | R48: =P48*1.05 | ... AC48: =AA48*1.05
A49: Stat-Statutory EBITDA | B49: Statutory EBITDA | C49: AUDm | D49: =D42+D48 | E49: =E42+E48 | F49: =F42+F48 | G49: =G42+G48 | H49: =H42+H48 | I49: =I42+I48 | J49: =J42+J48 | K49: =K42+K48 | ... AC49: =AC42+AC48
B51: D&A
A52: DA-Total DA | B52: Depreciation & Amortisation | C52: AUDm | D52: -12.2 | E52: -13.355 | F52: -15.9 | G52: -15.223 | H52: -19.08 | I52: -20.601 | J52: -21.181 | K52: =I52*1.06 | L52: =J52*1.06 | M52: =K52*1.06 | N52: =L52*1.06 | O52: =M52*1.06 | P52: =N52*1.06 | Q52: =O52*1.06 | R52: =P52*1.06 | ... AC52: =AA52*1.06
B55: D&A / Revenue | C55: % | D55: =IF(D7=0,"",D52/D7) | E55: =IF(E7=0,"",E52/E7) | F55: =IF(F7=0,"",F52/F7) | G55: =IF(G7=0,"",G52/G7) | H55: =IF(H7=0,"",H52/H7) | I55: =IF(I7=0,"",I52/I7) | J55: =IF(J7=0,"",J52/J7) | K55: =IF(K7=0,"",K52/K7) | ... AC55: =IF(AC7=0,"",AC52/AC7)
B57: EBIT
A58: EBIT-EBIT | B58: EBIT (Operating Profit) | C58: AUDm | D58: =D49+D52 | E58: =E49+E52 | F58: =F49+F52 | G58: =G49+G52 | H58: =H49+H52 | I58: =I49+I52 | J58: =J49+J52 | K58: =K49+K52 | ... AC58: =AC49+AC52
B59: EBIT Growth (YoY) | C59: % YoY | F59: =IF(D58=0,"",F58/D58-1) | G59: =IF(E58=0,"",G58/E58-1) | H59: =IF(F58=0,"",H58/F58-1) | I59: =IF(G58=0,"",I58/G58-1) | J59: =IF(H58=0,"",J58/H58-1) | K59: =IF(I58=0,"",K58/I58-1) | L59: =IF(J58=0,"",L58/J58-1) | M59: =IF(K58=0,"",M58/K58-1) | ... AC59: =IF(AA58=0,"",AC58/AA58-1)
B60: EBIT Margin | C60: % | D60: =IF(D7=0,"",D58/D7) | E60: =IF(E7=0,"",E58/E7) | F60: =IF(F7=0,"",F58/F7) | G60: =IF(G7=0,"",G58/G7) | H60: =IF(H7=0,"",H58/H7) | I60: =IF(I7=0,"",I58/I7) | J60: =IF(J7=0,"",J58/J7) | K60: =IF(K7=0,"",K58/K7) | ... AC60: =IF(AC7=0,"",AC58/AC7)
B62: Interest
A63: Int-Finance Income | B63: Finance Income | C63: AUDm | D63: 2.2 | E63: 2.393 | F63: 2.327 | G63: 3.685 | H63: 11.445 | I63: 11.229 | J63: 11.432 | K63: =I63*1.0 | L63: =J63*1.0 | M63: =K63*1.0 | N63: =L63*1.0 | O63: =M63*1.0 | P63: =N63*1.0 | Q63: =O63*1.0 | R63: =P63*1.0 | ... AC63: =AA63*1.0
A64: Int-Finance Costs | B64: Finance Costs | C64: AUDm | D64: -4.1 | E64: -4.403 | F64: -6.41 | G64: -7.314 | H64: -8.752 | I64: -10.15 | J64: -12.014 | K64: =I64*1.05 | L64: =J64*1.05 | M64: =K64*1.05 | N64: =L64*1.05 | O64: =M64*1.05 | P64: =N64*1.05 | Q64: =O64*1.05 | R64: =P64*1.05 | ... AC64: =AA64*1.05
A66: Int-Net Finance Costs | B66: Net Finance Costs | C66: AUDm | D66: =D63+D64 | E66: =E63+E64 | F66: =F63+F64 | G66: =G63+G64 | H66: =H63+H64 | I66: =I63+I64 | J66: =J63+J64 | K66: =K63+K64 | ... AC66: =AC63+AC64
A71: PBT-PBT | B71: PBT | C71: AUDm | D71: =D58+D66 | E71: =E58+E66 | F71: =F58+F66 | G71: =G58+G66 | H71: =H58+H66 | I71: =I58+I66 | J71: =J58+J66 | K71: =K58+K66 | ... AC71: =AC58+AC66
A72: Tax-Tax Expense | B72: Tax Expense | C72: AUDm | D72: -1.2 | E72: -1.223 | F72: -2.881 | G72: 0.694 | H72: -7.89 | I72: -6.844 | J72: -8.595 | K72: =IF(K71>0,-K71*0.35,0) | L72: =IF(L71>0,-L71*0.35,0) | M72: =IF(M71>0,-M71*0.35,0) | N72: =IF(N71>0,-N71*0.35,0) | O72: =IF(O71>0,-O71*0.35,0) | P72: =IF(P71>0,-P71*0.35,0) | Q72: =IF(Q71>0,-Q71*0.35,0) | R72: =IF(R71>0,-R71*0.35,0) | ... AC72: =IF(AC71>0,-AC71*0.35,0)
...
